Workbook

Sheet Decision
A2: Public method and A1 experimental release
A3: Pass 209 | PFP-4 | federated physical-truth architecture | Verdict: CLOSE
A6: Decision
A7: Constitute six A0 public requirement packages and issue twenty-four root-distinct A1 development warrants through a federated physical-truth architecture. Each A0 contains four receiver states and twelve method cards. Every decisive method must be realized through two unlike emulator lineages. Shared public seams define meaning and evidence; no common runtime, estimator, controller, safeing implementation or build compiler may enter a candidate root.
A12: Program control | B12: Value | C12: Unit | E12: Financial boundary | F12: Value | G12: Unit
A13: Selected architecture | B13: =COUNTIFS('Architecture Test'!O7:O11,"SELECT") -> 1 | C13: architecture | E13: Selected-field T1 ceiling | F13: =Finance!B23 -> 27.5 | G13: USD billions
A14: A0 packages | B14: =COUNTA('A0 Packages'!A7:A12) -> 6 | C14: packages | E14: Private stageable options | F14: =Finance!B24 -> 14.347651 | G14: USD billions
A15: Receiver states | B15: =COUNTA('Receiver States'!A7:A30) -> 24 | C15: states | E15: Evidence-held mission authority | F15: =Finance!B25 -> 13.152349 | G15: USD billions
A16: Public method cards | B16: =COUNTA('Public Methods'!A7:A78) -> 72 | C16: cards | E16: A0 public-method reservation | F16: =Finance!D15 -> 12 | G16: USD billions
A17: Method realization lineages | B17: =SUM('Public Methods'!M7:M78) -> 144 | C17: lineages | E17: Private payment through MAKE | F17: =Finance!D19 -> 7.1738256 | G17: USD billions
A18: A1 development warrants | B18: =COUNTA('A1 Releases'!A7:A30) -> 24 | C18: warrants | E18: Remaining stageable after MAKE | F18: =Finance!D20 -> 7.1738256 | G18: USD billions
A19: Decisive ancestry declarations | B19: =COUNTA('Ancestry Firewall'!A7:A174) -> 168 | C19: exclusive domains | E19: Current private obligations | F19: =Finance!E21 -> 0 | G19: USD billions
A20: Planned method-article cells | B20: =COUNTA('Experiment Plan'!A7:A294) -> 288 | C20: cells | E20: Current public obligations | F20: =Finance!E22 -> 0 | G20: USD billions
A21: Planned physical event slots | B21: =SUM('Experiment Plan'!K7:K294) -> 1152 | C21: events | E21: Accepted physical events | F21: =SUM('Experiment Plan'!M7:M294) -> 0 | G21: events
A22: Public seams | B22: =COUNTA('Public Seams'!A7:A18) -> 12 | C22: semantics | E22: Current field credit | F22: =SUM('A1 Releases'!P7:P30) -> 0 | G22: fields
A23: Current awards | B23: =COUNTIFS('A1 Releases'!M7:M30,"<>UNASSIGNED") -> 0 | C23: awards
A24: Production credit | B24: =SUM('A1 Releases'!Q7:Q30) -> 0 | C24: USD billions
A26: Nonconversion boundary
A27: A0 FROZEN FOR ISSUE means the public method can govern a competition. A1 ISSUE AUTHORIZED means a root-distinct development warrant may be competed. Neither status identifies a firm, accepts an article, records an event, pays a milestone, proves a field, completes a root or opens production. All supplier, site, lineage, serial and observed-result identities remain source-empty.

Sheet Architecture Test
A2: Public test architecture selection
A3: All twelve gates are noncompensatory. The selected design separates public semantics, physical state realization, root execution and evidence judgment.
A6: Candidate | B6: Public method | C6: Service native | D6: Physical truth | E6: Dual realization | F6: Root-isolated runtime | G6: Blind allocation | H6: Rights stop | I6: Missingness law | J6: Cold replay | K6: Portable receiver | L6: Inside USD 12B | M6: Zero credit | N6: Passed gates | O6: Result | P6: Governing reason
A7: Federated physical-truth grid | B7: 1 | C7: 1 | D7: 1 | E7: 1 | F7: 1 | G7: 1 | H7: 1 | I7: 1 | J7: 1 | K7: 1 | L7: 1 | M7: 1 | N7: =SUM(B7:M7) -> 12 | O7: =IF(N7=12,"SELECT","REJECT") -> SELECT | P7: Public semantics are common; two unlike physical realization lineages challenge each root-distinct runtime under separated validity and disposition.
A8: National integrated range | B8: 1 | C8: 1 | D8: 1 | E8: 0 | F8: 0 | G8: 1 | H8: 1 | I8: 1 | J8: 1 | K8: 0 | L8: 1 | M8: 1 | N8: =SUM(B8:M8) -> 9 | O8: =IF(N8=12,"SELECT","REJECT") -> REJECT | P8: One center and common orchestration stack create a correlated measurement and control authority across all roots.
A9: Six system-owned ranges | B9: 1 | C9: 1 | D9: 1 | E9: 0 | F9: 1 | G9: 0 | H9: 1 | I9: 1 | J9: 0 | K9: 0 | L9: 1 | M9: 1 | N9: =SUM(B9:M9) -> 8 | O9: =IF(N9=12,"SELECT","REJECT") -> REJECT | P9: System ownership preserves domain knowledge but permits one implementation lineage and sponsor-controlled allocation.
A10: Twenty-four root-owned labs | B10: 0 | C10: 1 | D10: 1 | E10: 1 | F10: 1 | G10: 0 | H10: 0 | I10: 0 | J10: 0 | K10: 0 | L10: 0 | M10: 1 | N10: =SUM(B10:M10) -> 5 | O10: =IF(N10=12,"SELECT","REJECT") -> REJECT | P10: Root separation survives, but builders define their own receiver truth, missingness and safety boundary.
A11: Simulation-first qualification | B11: 1 | C11: 1 | D11: 0 | E11: 1 | F11: 1 | G11: 1 | H11: 1 | I11: 1 | J11: 1 | K11: 1 | L11: 1 | M11: 1 | N11: =SUM(B11:M11) -> 11 | O11: =IF(N11=12,"SELECT","REJECT") -> REJECT | P11: Simulation is useful for design but cannot establish full-scale physical state, residual custody or human-service burden.

Sheet A0 Packages
A2: A0 Packages
A3: A0 is a public measurement instrument: subject, denominator, state space, challenge, controls, metrology, uncertainty, rights, evidence and amendment law are frozen before results.
A6: Package | B6: Version | C6: System | D6: Mission system | E6: Problem field | F6: Public subject | G6: Primary floor | H6: Unit | I6: Vector coordinates | J6: Receiver states | K6: Method cards | L6: Lineages per method | M6: Event slots | N6: Status | O6: Observed events | P6: Field credit | Q6: Kill proposition
A7: A0-ET | B7: A0.1 | C7: MS-ET | D7: Enter a broken theater | E7: No-pier heavy transfer | F7: accepted formation and cargo custody from water or air interface through dry staging | G7: 5630 | H7: accepted tonnes/day | I7: 8 | J7: 4 | K7: 12 | L7: 2 | M7: 192 | N7: FROZEN FOR ISSUE | O7: 0 | P7: 0 | Q7: No-pier entry cannot preserve accepted custody after largest-path loss.
A8: A0-CT | B8: A0.1 | C8: MS-CT | D8: Reach occupied civil terrain | E8: Building and vertical access | F8: lawful person and household reach through occupied damaged structures | G8: 105000 | H8: people by hour 168 | I8: 8 | J8: 4 | K8: 12 | L8: 2 | M8: 192 | N8: FROZEN FOR ISSUE | O8: 0 | P8: 0 | Q8: Access cannot close every case or exception without intact cores or networks.
A9: A0-HC | B9: A0.1 | C9: MS-HC | D9: Control an active hazard | E9: Persistent fire control | F9: measured edge control with responder safety and intervention residual custody | G9: 1 | H9: protected kilometre | I9: 8 | J9: 4 | K9: 12 | L9: 2 | M9: 192 | N9: FROZEN FOR ISSUE | O9: 0 | P9: 0 | Q9: A registered crossing, uncontrolled residual or shifted responder risk occurs.
A10: A0-LF | B10: A0.1 | C10: MS-LF | D10: Produce and distribute lifelines | E10: Strategic water-energy carriers | F10: water, firm power, thermal service, storage and residual acceptance | G10: 2000000 | H10: people served | I10: 8 | J10: 4 | K10: 12 | L10: 2 | M10: 192 | N10: FROZEN FOR ISSUE | O10: 0 | P10: 0 | Q10: Source, conversion, corridor, point-of-use or residual closure depends on host service.
A11: A0-HU | B11: A0.1 | C11: MS-HU | D11: Preserve care and human continuity | E11: Distributed definitive care | F11: completed appropriate clinical episodes across ten unlike care lines | G11: 100000 | H11: people for 30 days | I11: 8 | J11: 4 | K11: 12 | L11: 2 | M11: 192 | N11: FROZEN FOR ISSUE | O11: 0 | P11: 0 | Q11: Any care line disappears after one island and one utility-family loss.
A12: A0-RT | B12: A0.1 | C12: MS-RT | D12: Sustain, transfer and regenerate | E12: Field regeneration | F12: critical articles returned to a known configuration with independent release | G12: 99 | H12: controlled positions | I12: 8 | J12: 4 | K12: 12 | L12: 2 | M12: 192 | N12: FROZEN FOR ISSUE | O12: 0 | P12: 0 | Q12: A critical class is missing or physical repair lacks sovereign recertification.

Sheet Receiver States
A2: Receiver States
A3: Four receiver-state classes per system preserve the complete path from physical interface to public acceptance, burden and reset.
A6: System | B6: State | C6: Receiver state | D6: Physical boundary | E6: Primary denial | F6: Required reset | G6: Rights or residual guard | H6: Implementation identity | I6: Accepted realization
A7: MS-ET | B7: ET-S1 | C7: Moving interface | D7: wave, wind, motion and heavy-load exchange boundary | E7: largest transfer path and primary time absent | F7: empty, dry and surveyed load interface | G7: no people or cargo exposed to unbounded motion | H7: SOURCE EMPTY | I7: 0
A8: MS-ET | B8: ET-S2 | C8: Shore transition | D8: surf, beach, shallow-water or austere landing transition | E8: one medium and one approach geometry denied | F8: route reopened or isolated with state preserved | G8: no unmeasured seabed, shore or environmental burden | H8: SOURCE EMPTY | I8: 0
A9: MS-ET | B9: ET-S3 | C9: Dry staging | D9: hazard segregation, inspection, cross-dock and custody | E9: host handling, grid and network absent | F9: all cargo dispositioned and stage cleared | G9: no accepted flow before identity and hazard closure | H9: SOURCE EMPTY | I9: 0
A10: MS-ET | B10: ET-S4 | C10: Onward handoff | D10: formation-complete cargo reaches a damaged inland receiver | E10: largest onward route and central dispatcher lost | F10: receiver acceptance or explicit exception | G10: no discharge-only credit or receiver labor subsidy | H10: SOURCE EMPTY | I10: 0
A11: MS-CT | B11: CT-S1 | C11: District approach | D11: blocked, flooded, heated or contaminated street edge | E11: commercial network and primary approach denied | F11: safe alternate access established | G11: no path created by transferring hazard to residents | H11: SOURCE EMPTY | I11: 0
A12: MS-CT | B12: CT-S2 | C12: Occupied low-rise | D12: people remain inside cluttered damaged buildings | E12: normal power, lighting and one egress absent | F12: every case closed or retained in exception queue | G12: consent, accessibility and refusal remain visible | H12: SOURCE EMPTY | I12: 0
A13: MS-CT | B13: CT-S3 | C13: High-rise vertical | D13: core, lift or stair function is partially lost | E13: one vertical system and exterior access face denied | F13: protected ascent, descent and refuge reset | G13: no unsafe facade load or abandonment above reach | H13: SOURCE EMPTY | I13: 0
A14: MS-CT | B14: CT-S4 | C14: Refuge and egress | D14: mixed mobility, medical and household needs share constrained paths | E14: one operator company and one utility family absent | F14: lawful destination and return state recorded | G14: no speed credit from separating people from supports | H14: SOURCE EMPTY | I14: 0
A15: MS-HC | B15: HC-S1 | C15: Advancing edge | D15: heat release, wind and fuel create a moving control boundary | E15: normal water, grid and network denied | F15: edge held or declared crossed | G15: no output credit without attributed boundary effect | H15: SOURCE EMPTY | I15: 0
A16: MS-HC | B16: HC-S2 | C16: Ember and interface | D16: spotting challenges structures and access routes | E16: primary sensing sector and one placement mode lost | F16: all registered crossings dispositioned | G16: no suppression success that hides structure loss | H16: SOURCE EMPTY | I16: 0
A17: MS-HC | B17: HC-S3 | C17: Plume and airspace | D17: smoke, turbulence and mixed crewed-uncrewed traffic interact | E17: central air picture and one navigation source denied | F17: safe local separation and mission state restored | G17: no responder or public risk shifted out of score | H17: SOURCE EMPTY | I17: 0
A18: MS-HC | B18: HC-S4 | C18: Residual and re-ignition | D18: water, agent, runoff and heat remain after first control | E18: drainage unavailable and ignition recurs | F18: residual accepted and hold period completed | G18: no contaminated runoff or unobserved re-ignition | H18: SOURCE EMPTY | I18: 0
... A30: MS-RT | B30: RT-S4 | C30: Calibration and release | D30: metrology, safe state, documentation and cold reconstruction establish fitness | E30: primary reference lab and vendor key absent | F30: independent release or explicit rejection | G30: no physical repair without reproducible sovereign credential | H30: SOURCE EMPTY | I30: 0

Sheet Public Methods
A2: Public Methods
A3: Each system has four receiver states and three method modes per state. Every card requires two unlike physical realization lineages before it may generate decisive evidence.
A6: Method | B6: Version | C6: System | D6: Receiver state | E6: State name | F6: Mode | G6: Method family | H6: Registered question | I6: Physical boundary | J6: Denial | K6: Reset | L6: Rights or residual guard | M6: Required lineages | N6: Accepted lineages | O6: Status
A7: MS-ET-M01 | B7: A0.1 | C7: MS-ET | D7: ET-S1 | E7: Moving interface | F7: L | G7: Load and quality | H7: measure capacity, quality and state transition at the registered service floor | I7: wave, wind, motion and heavy-load exchange boundary | J7: largest transfer path and primary time absent | K7: empty, dry and surveyed load interface | L7: no people or cargo exposed to unbounded motion | M7: 2 | N7: 0 | O7: FROZEN FOR ISSUE
A8: MS-ET-M02 | B8: A0.1 | C8: MS-ET | D8: ET-S1 | E8: Moving interface | F8: D | G8: Denied condition | H8: apply the declared loss and distinguish candidate failure from invalid emulator state | I8: wave, wind, motion and heavy-load exchange boundary | J8: largest transfer path and primary time absent | K8: empty, dry and surveyed load interface | L8: no people or cargo exposed to unbounded motion | M8: 2 | N8: 0 | O8: FROZEN FOR ISSUE
A9: MS-ET-M03 | B9: A0.1 | C9: MS-ET | D9: ET-S1 | E9: Moving interface | F9: R | G9: Recovery and burden | H9: measure reset, receiver burden, residual custody and return to a known state | I9: wave, wind, motion and heavy-load exchange boundary | J9: largest transfer path and primary time absent | K9: empty, dry and surveyed load interface | L9: no people or cargo exposed to unbounded motion | M9: 2 | N9: 0 | O9: FROZEN FOR ISSUE
A10: MS-ET-M04 | B10: A0.1 | C10: MS-ET | D10: ET-S2 | E10: Shore transition | F10: L | G10: Load and quality | H10: measure capacity, quality and state transition at the registered service floor | I10: surf, beach, shallow-water or austere landing transition | J10: one medium and one approach geometry denied | K10: route reopened or isolated with state preserved | L10: no unmeasured seabed, shore or environmental burden | M10: 2 | N10: 0 | O10: FROZEN FOR ISSUE
A11: MS-ET-M05 | B11: A0.1 | C11: MS-ET | D11: ET-S2 | E11: Shore transition | F11: D | G11: Denied condition | H11: apply the declared loss and distinguish candidate failure from invalid emulator state | I11: surf, beach, shallow-water or austere landing transition | J11: one medium and one approach geometry denied | K11: route reopened or isolated with state preserved | L11: no unmeasured seabed, shore or environmental burden | M11: 2 | N11: 0 | O11: FROZEN FOR ISSUE
A12: MS-ET-M06 | B12: A0.1 | C12: MS-ET | D12: ET-S2 | E12: Shore transition | F12: R | G12: Recovery and burden | H12: measure reset, receiver burden, residual custody and return to a known state | I12: surf, beach, shallow-water or austere landing transition | J12: one medium and one approach geometry denied | K12: route reopened or isolated with state preserved | L12: no unmeasured seabed, shore or environmental burden | M12: 2 | N12: 0 | O12: FROZEN FOR ISSUE
A13: MS-ET-M07 | B13: A0.1 | C13: MS-ET | D13: ET-S3 | E13: Dry staging | F13: L | G13: Load and quality | H13: measure capacity, quality and state transition at the registered service floor | I13: hazard segregation, inspection, cross-dock and custody | J13: host handling, grid and network absent | K13: all cargo dispositioned and stage cleared | L13: no accepted flow before identity and hazard closure | M13: 2 | N13: 0 | O13: FROZEN FOR ISSUE
A14: MS-ET-M08 | B14: A0.1 | C14: MS-ET | D14: ET-S3 | E14: Dry staging | F14: D | G14: Denied condition | H14: apply the declared loss and distinguish candidate failure from invalid emulator state | I14: hazard segregation, inspection, cross-dock and custody | J14: host handling, grid and network absent | K14: all cargo dispositioned and stage cleared | L14: no accepted flow before identity and hazard closure | M14: 2 | N14: 0 | O14: FROZEN FOR ISSUE
A15: MS-ET-M09 | B15: A0.1 | C15: MS-ET | D15: ET-S3 | E15: Dry staging | F15: R | G15: Recovery and burden | H15: measure reset, receiver burden, residual custody and return to a known state | I15: hazard segregation, inspection, cross-dock and custody | J15: host handling, grid and network absent | K15: all cargo dispositioned and stage cleared | L15: no accepted flow before identity and hazard closure | M15: 2 | N15: 0 | O15: FROZEN FOR ISSUE
A16: MS-ET-M10 | B16: A0.1 | C16: MS-ET | D16: ET-S4 | E16: Onward handoff | F16: L | G16: Load and quality | H16: measure capacity, quality and state transition at the registered service floor | I16: formation-complete cargo reaches a damaged inland receiver | J16: largest onward route and central dispatcher lost | K16: receiver acceptance or explicit exception | L16: no discharge-only credit or receiver labor subsidy | M16: 2 | N16: 0 | O16: FROZEN FOR ISSUE
A17: MS-ET-M11 | B17: A0.1 | C17: MS-ET | D17: ET-S4 | E17: Onward handoff | F17: D | G17: Denied condition | H17: apply the declared loss and distinguish candidate failure from invalid emulator state | I17: formation-complete cargo reaches a damaged inland receiver | J17: largest onward route and central dispatcher lost | K17: receiver acceptance or explicit exception | L17: no discharge-only credit or receiver labor subsidy | M17: 2 | N17: 0 | O17: FROZEN FOR ISSUE
A18: MS-ET-M12 | B18: A0.1 | C18: MS-ET | D18: ET-S4 | E18: Onward handoff | F18: R | G18: Recovery and burden | H18: measure reset, receiver burden, residual custody and return to a known state | I18: formation-complete cargo reaches a damaged inland receiver | J18: largest onward route and central dispatcher lost | K18: receiver acceptance or explicit exception | L18: no discharge-only credit or receiver labor subsidy | M18: 2 | N18: 0 | O18: FROZEN FOR ISSUE
... A78: MS-RT-M12 | B78: A0.1 | C78: MS-RT | D78: RT-S4 | E78: Calibration and release | F78: R | G78: Recovery and burden | H78: measure reset, receiver burden, residual custody and return to a known state | I78: metrology, safe state, documentation and cold reconstruction establish fitness | J78: primary reference lab and vendor key absent | K78: independent release or explicit rejection | L78: no physical repair without reproducible sovereign credential | M78: 2 | N78: 0 | O78: FROZEN FOR ISSUE

Sheet A1 Releases
A2: A1 Releases
A3: These are public development warrants, not accepted articles. Four unlike mechanism hypotheses remain open in every selected problem field.
A6: Release | B6: Root slot | C6: System | D6: Problem field | E6: Root thesis | F6: Mechanism hypothesis | G6: A0 version | H6: Method cards | I6: Emulator lineages | J6: Planned events | K6: Exclusive domains | L6: Release state | M6: Root House identity | N6: Article serial | O6: Accepted evidence | P6: Field credit | Q6: Production credit | R6: Kill trigger
A7: A1-ET-A | B7: ET-A | C7: MS-ET | D7: No-pier heavy transfer | E7: Oceanic mass bridge | F7: stabilized offshore exchange and shallow modular connectors | G7: A0.1 | H7: 12 | I7: 2 | J7: 48 | K7: 7 | L7: ISSUE AUTHORIZED | M7: UNASSIGNED | N7: NONE | O7: 0 | P7: 0 | Q7: 0 | R7: No-pier entry cannot preserve accepted custody after largest-path loss.
A8: A1-ET-B | B8: ET-B | C8: MS-ET | D8: No-pier heavy transfer | E8: Buoyant air bridge | F8: buoyant heavy carriage and prepared-runway-free load exchange | G8: A0.1 | H8: 12 | I8: 2 | J8: 48 | K8: 7 | L8: ISSUE AUTHORIZED | M8: UNASSIGNED | N8: NONE | O8: 0 | P8: 0 | Q8: 0 | R8: No-pier entry cannot preserve accepted custody after largest-path loss.
A9: A1-ET-C | B9: ET-C | C9: MS-ET | D9: No-pier heavy transfer | E9: Austere surface bridge | F9: machine-laid causeway, dry terminal and robotic cargo motion | G9: A0.1 | H9: 12 | I9: 2 | J9: 48 | K9: 7 | L9: ISSUE AUTHORIZED | M9: UNASSIGNED | N9: NONE | O9: 0 | P9: 0 | Q9: 0 | R9: No-pier entry cannot preserve accepted custody after largest-path loss.
A10: A1-ET-D | B10: ET-D | C10: MS-ET | D10: No-pier heavy transfer | E10: Amphibious autonomous mesh | F10: distributed shallow-water lighters and independent cross-dock paths | G10: A0.1 | H10: 12 | I10: 2 | J10: 48 | K10: 7 | L10: ISSUE AUTHORIZED | M10: UNASSIGNED | N10: NONE | O10: 0 | P10: 0 | Q10: 0 | R10: No-pier entry cannot preserve accepted custody after largest-path loss.
A11: A1-CT-A | B11: CT-A | C11: MS-CT | D11: Building and vertical access | E11: Civic edge grid | F11: prepared civic interfaces, powered refuge and accessible building adapters | G11: A0.1 | H11: 12 | I11: 2 | J11: 48 | K11: 7 | L11: ISSUE AUTHORIZED | M11: UNASSIGNED | N11: NONE | O11: 0 | P11: 0 | Q11: 0 | R11: Access cannot close every case or exception without intact cores or networks.
A12: A1-CT-B | B12: CT-B | C12: MS-CT | D12: Building and vertical access | E12: Air-and-skin reach | F12: exterior-climbing systems and protected envelope docking | G12: A0.1 | H12: 12 | I12: 2 | J12: 48 | K12: 7 | L12: ISSUE AUTHORIZED | M12: UNASSIGNED | N12: NONE | O12: 0 | P12: 0 | Q12: 0 | R12: Access cannot close every case or exception without intact cores or networks.
A13: A1-CT-C | B13: CT-C | C13: MS-CT | D13: Building and vertical access | E13: Building utility spine | F13: temporary lift, stair, power and water spine outside failed cores | G13: A0.1 | H13: 12 | I13: 2 | J13: 48 | K13: 7 | L13: ISSUE AUTHORIZED | M13: UNASSIGNED | N13: NONE | O13: 0 | P13: 0 | Q13: 0 | R13: Access cannot close every case or exception without intact cores or networks.
A14: A1-CT-D | B14: CT-D | C14: MS-CT | D14: Building and vertical access | E14: Neighborhood machine swarm | F14: human-safe occupied-space robotics under local control | G14: A0.1 | H14: 12 | I14: 2 | J14: 48 | K14: 7 | L14: ISSUE AUTHORIZED | M14: UNASSIGNED | N14: NONE | O14: 0 | P14: 0 | Q14: 0 | R14: Access cannot close every case or exception without intact cores or networks.
A15: A1-HC-A | B15: HC-A | C15: MS-HC | D15: Persistent fire control | E15: Atmospheric control wing | F15: purpose-built endurance flight and precision multi-agent placement | G15: A0.1 | H15: 12 | I15: 2 | J15: 48 | K15: 7 | L15: ISSUE AUTHORIZED | M15: UNASSIGNED | N15: NONE | O15: 0 | P15: 0 | Q15: 0 | R15: A registered crossing, uncontrolled residual or shifted responder risk occurs.
A16: A1-HC-B | B16: HC-B | C16: MS-HC | D16: Persistent fire control | E16: Fluid intervention lattice | F16: closed-loop hydraulic pulse, deployable towers and return control | G16: A0.1 | H16: 12 | I16: 2 | J16: 48 | K16: 7 | L16: ISSUE AUTHORIZED | M16: UNASSIGNED | N16: NONE | O16: 0 | P16: 0 | Q16: 0 | R16: A registered crossing, uncontrolled residual or shifted responder risk occurs.
A17: A1-HC-C | B17: HC-C | C17: MS-HC | D17: Persistent fire control | E17: Autonomous terrain corps | F17: optionally crewed earthwork, treatment and hold machines | G17: A0.1 | H17: 12 | I17: 2 | J17: 48 | K17: 7 | L17: ISSUE AUTHORIZED | M17: UNASSIGNED | N17: NONE | O17: 0 | P17: 0 | Q17: 0 | R17: A registered crossing, uncontrolled residual or shifted responder risk occurs.
A18: A1-HC-D | B18: HC-D | C18: MS-HC | D18: Persistent fire control | E18: Distributed control field | F18: fault-contained sensing and local boundary actuators | G18: A0.1 | H18: 12 | I18: 2 | J18: 48 | K18: 7 | L18: ISSUE AUTHORIZED | M18: UNASSIGNED | N18: NONE | O18: 0 | P18: 0 | Q18: 0 | R18: A registered crossing, uncontrolled residual or shifted responder risk occurs.
... A30: A1-RT-D | B30: RT-D | C30: MS-RT | D30: Field regeneration | E30: Closed-loop sustainment fleet | F30: mobile decontamination, residual processing and sovereign metrology | G30: A0.1 | H30: 12 | I30: 2 | J30: 48 | K30: 7 | L30: ISSUE AUTHORIZED | M30: UNASSIGNED | N30: NONE | O30: 0 | P30: 0 | Q30: 0 | R30: A critical class is missing or physical repair lacks sovereign recertification.

Sheet Ancestry Firewall
A2: Ancestry Firewall
A3: Seven decisive execution domains are exclusive to one complete root. A shared public reference may test a domain but cannot implement it inside a candidate.
A6: Release | B6: Root | C6: System | D6: Decisive domain | E6: Required treatment | F6: Collision condition | G6: Shared runtime allowed | H6: Declared provider | I6: Accepted declaration | J6: State
A7: A1-ET-A | B7: ET-A | C7: MS-ET | D7: mission control and planning | E7: EXCLUSIVE TO ONE ROOT | F7: common planner, orchestration model or dispatch runtime | G7: No | H7: SOURCE EMPTY | I7: 0 | J7: OPEN
A8: A1-ET-A | B8: ET-A | C8: MS-ET | D8: state estimation and world model | E8: EXCLUSIVE TO ONE ROOT | F8: shared estimator, training weights or state fusion service | G8: No | H8: SOURCE EMPTY | I8: 0 | J8: OPEN
A9: A1-ET-A | B9: ET-A | C9: MS-ET | D9: sensing, time and calibration | E9: EXCLUSIVE TO ONE ROOT | F9: shared decisive sensor chain, clock dependency or calibration authority | G9: No | H9: SOURCE EMPTY | I9: 0 | J9: OPEN
A10: A1-ET-A | B10: ET-A | C10: MS-ET | D10: actuation and low-level control | E10: EXCLUSIVE TO ONE ROOT | F10: shared flight, drive, valve, robotic or plant-control implementation | G10: No | H10: SOURCE EMPTY | I10: 0 | J10: OPEN
A11: A1-ET-A | B11: ET-A | C11: MS-ET | D11: safeing and human override | E11: EXCLUSIVE TO ONE ROOT | F11: shared safe-state logic, inhibit path or override authority | G11: No | H11: SOURCE EMPTY | I11: 0 | J11: OPEN
A12: A1-ET-A | B12: ET-A | C12: MS-ET | D12: energy and power management | E12: EXCLUSIVE TO ONE ROOT | F12: shared decisive conversion, storage or power-control dependency | G12: No | H12: SOURCE EMPTY | I12: 0 | J12: OPEN
A13: A1-ET-A | B13: ET-A | C13: MS-ET | D13: build, repair and recertification compiler | E13: EXCLUSIVE TO ONE ROOT | F13: shared build key, recovery toolchain or release implementation | G13: No | H13: SOURCE EMPTY | I13: 0 | J13: OPEN
A14: A1-ET-B | B14: ET-B | C14: MS-ET | D14: mission control and planning | E14: EXCLUSIVE TO ONE ROOT | F14: common planner, orchestration model or dispatch runtime | G14: No | H14: SOURCE EMPTY | I14: 0 | J14: OPEN
A15: A1-ET-B | B15: ET-B | C15: MS-ET | D15: state estimation and world model | E15: EXCLUSIVE TO ONE ROOT | F15: shared estimator, training weights or state fusion service | G15: No | H15: SOURCE EMPTY | I15: 0 | J15: OPEN
A16: A1-ET-B | B16: ET-B | C16: MS-ET | D16: sensing, time and calibration | E16: EXCLUSIVE TO ONE ROOT | F16: shared decisive sensor chain, clock dependency or calibration authority | G16: No | H16: SOURCE EMPTY | I16: 0 | J16: OPEN
A17: A1-ET-B | B17: ET-B | C17: MS-ET | D17: actuation and low-level control | E17: EXCLUSIVE TO ONE ROOT | F17: shared flight, drive, valve, robotic or plant-control implementation | G17: No | H17: SOURCE EMPTY | I17: 0 | J17: OPEN
A18: A1-ET-B | B18: ET-B | C18: MS-ET | D18: safeing and human override | E18: EXCLUSIVE TO ONE ROOT | F18: shared safe-state logic, inhibit path or override authority | G18: No | H18: SOURCE EMPTY | I18: 0 | J18: OPEN
... A174: A1-RT-D | B174: RT-D | C174: MS-RT | D174: build, repair and recertification compiler | E174: EXCLUSIVE TO ONE ROOT | F174: shared build key, recovery toolchain or release implementation | G174: No | H174: SOURCE EMPTY | I174: 0 | J174: OPEN

Sheet Experiment Plan
A2: Experiment Plan
A3: One row is one article-method cell. Two unlike emulator lineages each execute a matched challenge and control, creating four physical event slots per cell.
A6: Release | B6: Root | C6: System | D6: Method | E6: Receiver state | F6: Mode | G6: Primary lineage | H6: Witness lineage | I6: Lineages | J6: Events per lineage | K6: Event slots | L6: Blind tokens | M6: Observed events | N6: Valid events | O6: Invalid events | P6: Adverse events | Q6: State
A7: A1-ET-A | B7: ET-A | C7: MS-ET | D7: MS-ET-M01 | E7: ET-S1 | F7: L | G7: LINEAGE 1 UNASSIGNED | H7: LINEAGE 2 UNASSIGNED | I7: 2 | J7: 2 | K7: 4 | L7: 4 | M7: 0 | N7: 0 | O7: 0 | P7: 0 | Q7: PLANNED; SOURCE EMPTY
A8: A1-ET-A | B8: ET-A | C8: MS-ET | D8: MS-ET-M02 | E8: ET-S1 | F8: D | G8: LINEAGE 1 UNASSIGNED | H8: LINEAGE 2 UNASSIGNED | I8: 2 | J8: 2 | K8: 4 | L8: 4 | M8: 0 | N8: 0 | O8: 0 | P8: 0 | Q8: PLANNED; SOURCE EMPTY
A9: A1-ET-A | B9: ET-A | C9: MS-ET | D9: MS-ET-M03 | E9: ET-S1 | F9: R | G9: LINEAGE 1 UNASSIGNED | H9: LINEAGE 2 UNASSIGNED | I9: 2 | J9: 2 | K9: 4 | L9: 4 | M9: 0 | N9: 0 | O9: 0 | P9: 0 | Q9: PLANNED; SOURCE EMPTY
A10: A1-ET-A | B10: ET-A | C10: MS-ET | D10: MS-ET-M04 | E10: ET-S2 | F10: L | G10: LINEAGE 1 UNASSIGNED | H10: LINEAGE 2 UNASSIGNED | I10: 2 | J10: 2 | K10: 4 | L10: 4 | M10: 0 | N10: 0 | O10: 0 | P10: 0 | Q10: PLANNED; SOURCE EMPTY
A11: A1-ET-A | B11: ET-A | C11: MS-ET | D11: MS-ET-M05 | E11: ET-S2 | F11: D | G11: LINEAGE 1 UNASSIGNED | H11: LINEAGE 2 UNASSIGNED | I11: 2 | J11: 2 | K11: 4 | L11: 4 | M11: 0 | N11: 0 | O11: 0 | P11: 0 | Q11: PLANNED; SOURCE EMPTY
A12: A1-ET-A | B12: ET-A | C12: MS-ET | D12: MS-ET-M06 | E12: ET-S2 | F12: R | G12: LINEAGE 1 UNASSIGNED | H12: LINEAGE 2 UNASSIGNED | I12: 2 | J12: 2 | K12: 4 | L12: 4 | M12: 0 | N12: 0 | O12: 0 | P12: 0 | Q12: PLANNED; SOURCE EMPTY
A13: A1-ET-A | B13: ET-A | C13: MS-ET | D13: MS-ET-M07 | E13: ET-S3 | F13: L | G13: LINEAGE 1 UNASSIGNED | H13: LINEAGE 2 UNASSIGNED | I13: 2 | J13: 2 | K13: 4 | L13: 4 | M13: 0 | N13: 0 | O13: 0 | P13: 0 | Q13: PLANNED; SOURCE EMPTY
A14: A1-ET-A | B14: ET-A | C14: MS-ET | D14: MS-ET-M08 | E14: ET-S3 | F14: D | G14: LINEAGE 1 UNASSIGNED | H14: LINEAGE 2 UNASSIGNED | I14: 2 | J14: 2 | K14: 4 | L14: 4 | M14: 0 | N14: 0 | O14: 0 | P14: 0 | Q14: PLANNED; SOURCE EMPTY
A15: A1-ET-A | B15: ET-A | C15: MS-ET | D15: MS-ET-M09 | E15: ET-S3 | F15: R | G15: LINEAGE 1 UNASSIGNED | H15: LINEAGE 2 UNASSIGNED | I15: 2 | J15: 2 | K15: 4 | L15: 4 | M15: 0 | N15: 0 | O15: 0 | P15: 0 | Q15: PLANNED; SOURCE EMPTY
A16: A1-ET-A | B16: ET-A | C16: MS-ET | D16: MS-ET-M10 | E16: ET-S4 | F16: L | G16: LINEAGE 1 UNASSIGNED | H16: LINEAGE 2 UNASSIGNED | I16: 2 | J16: 2 | K16: 4 | L16: 4 | M16: 0 | N16: 0 | O16: 0 | P16: 0 | Q16: PLANNED; SOURCE EMPTY
A17: A1-ET-A | B17: ET-A | C17: MS-ET | D17: MS-ET-M11 | E17: ET-S4 | F17: D | G17: LINEAGE 1 UNASSIGNED | H17: LINEAGE 2 UNASSIGNED | I17: 2 | J17: 2 | K17: 4 | L17: 4 | M17: 0 | N17: 0 | O17: 0 | P17: 0 | Q17: PLANNED; SOURCE EMPTY
A18: A1-ET-A | B18: ET-A | C18: MS-ET | D18: MS-ET-M12 | E18: ET-S4 | F18: R | G18: LINEAGE 1 UNASSIGNED | H18: LINEAGE 2 UNASSIGNED | I18: 2 | J18: 2 | K18: 4 | L18: 4 | M18: 0 | N18: 0 | O18: 0 | P18: 0 | Q18: PLANNED; SOURCE EMPTY
... A294: A1-RT-D | B294: RT-D | C294: MS-RT | D294: MS-RT-M12 | E294: RT-S4 | F294: R | G294: LINEAGE 1 UNASSIGNED | H294: LINEAGE 2 UNASSIGNED | I294: 2 | J294: 2 | K294: 4 | L294: 4 | M294: 0 | N294: 0 | O294: 0 | P294: 0 | Q294: PLANNED; SOURCE EMPTY

Sheet Public Seams
A2: Public Seams
A3: Commonality is limited to public meaning, interfaces and evidence portability. No public seam may become a shared candidate execution dependency.
A6: Seam | B6: Public object | C6: Allowed commonality | D6: May enter candidate runtime | E6: Boundary rule | F6: Version | G6: Status
A7: PS-01 | B7: service subject and denominator | C7: shared public meaning | D7: No | E7: a root cannot redefine who or what counts after seeing results | F7: PS-1 | G7: FROZEN
A8: PS-02 | B8: units, thresholds and coordinate schema | C8: shared public meaning | D8: No | E8: one coordinate cannot compensate for another | F8: PS-1 | G8: FROZEN
A9: PS-03 | B9: physical interface envelope | C9: interoperable boundary | D9: No | E9: geometry and media are public; actuation remains root-native | F9: PS-1 | G9: FROZEN
A10: PS-04 | B10: manifest and custody identifiers | C10: portable record semantics | D10: No | E10: identity does not authorize control | F10: PS-1 | G10: FROZEN
A11: PS-05 | B11: receiver-state and denial vocabulary | C11: comparable challenge description | D11: No | E11: the state generator implementation stays outside the candidate | F11: PS-1 | G11: FROZEN
A12: PS-06 | B12: calibration reference interface | C12: traceable public reference | D12: No | E12: a shared reference cannot become a shared sensor chain | F12: PS-1 | G12: FROZEN
A13: PS-07 | B13: evidence packet and replay schema | C13: public evidence portability | D13: No | E13: root estimators remain separate and executable from sealed originals | F13: PS-1 | G13: FROZEN
A14: PS-08 | B14: rights and accessibility receipt | C14: nonfungible civil record | D14: No | E14: absence of complaint is not consent or completion | F14: PS-1 | G14: FROZEN
A15: PS-09 | B15: stop-signal grammar | C15: publicly understood stop state | D15: No | E15: safeing implementation and actuation remain root-native | F15: PS-1 | G15: FROZEN
A16: PS-10 | B16: time, uncertainty and missingness encoding | C16: comparable epistemic state | D16: No | E16: missing decisive evidence remains unresolved rather than zero | F16: PS-1 | G16: FROZEN
A17: PS-11 | B17: residual, return and regeneration taxonomy | C17: complete lifecycle boundary | D17: No | E17: disposal or repair outside custody earns no service credit | F17: PS-1 | G17: FROZEN
A18: PS-12 | B18: recharter and export package | C18: receiver can reproduce the public boundary | D18: No | E18: transfer carries method and interface rights, not one vendor runtime | F18: PS-1 | G18: FROZEN

Sheet Governance
A2: Authority and nonconversion law
A3: No actor may define the requirement, realize receiver truth, build a root, classify validity, dispose the root and release money or production.
A6: Separated authorities
A7: Authority | B7: Owns | C7: Cannot infer | D7: Failure if combined | E7: Output | F7: Current identity
A8: Mission System Commands | B8: own service subject, vector and A0 package | C8: select mechanism or judge evidence | D8: requirement owner becomes favored designer | E8: frozen A0 package | F8: SOURCE EMPTY
A9: Public Method Council | B9: own method-card grammar and cross-system semantics | C9: supply root runtime or change field threshold | D9: method standard becomes technical monopoly | E9: versioned public method | F9: SOURCE EMPTY
A10: Receiver Emulator Authority | B10: realize physical states through unlike lineages | C10: score candidate or conceal emulator excursion | D10: range operator becomes result owner | E10: state realization record | F10: SOURCE EMPTY
A11: Blind Allocation Office | B11: assign challenge, control, lineage and reserve tokens | C11: view preferred outcome or change allocation | D11: sponsor optimizes the trial | E11: sealed allocation root | F11: SOURCE EMPTY
A12: Generating Services | B12: release professional construction and safety requirements | C12: accept public effect | D12: professional release becomes mission credit | E12: A1 construction warrant | F12: SOURCE EMPTY
A13: Root Houses | B13: design and build one complete root's mechanism | C13: define denominator, emulator truth or own adjudication | D13: builder writes its own test | E13: controlled A1 article | F13: SOURCE EMPTY
A14: Independent Metrology Service | B14: calibrate references and sign uncertainty | C14: operate root estimator or waive missing evidence | D14: measurement authority becomes analyst | E14: calibration chain | F14: SOURCE EMPTY
A15: Protection Inspectorate | B15: stop unsafe or rights-violating work | C15: convert a stop into technical failure automatically | D15: protection becomes a weighted score | E15: stop and consequence record | F15: SOURCE EMPTY
A16: Evidence Validity Board | B16: classify valid, invalid or unresolved event | C16: choose root disposition or payment | D16: validity judgment becomes sponsorship | E16: event validity warrant | F16: SOURCE EMPTY
A17: Root Disposition Board | B17: order continue, resize, reframe or kill | C17: release production | D17: A1 learning becomes scale authority | E17: reasoned root disposition | F17: SOURCE EMPTY
A18: Capital Board and Comptroller | B18: open options and pay accepted artifacts | C18: manufacture validity, field credit or production | D18: money becomes technical evidence | E18: option and payment ledger | F18: SOURCE EMPTY
A19: Continuity Receiver | B19: hold public foreground rights and clean recharter package | C19: claim readiness from custody | D19: possession becomes capability | E19: custody and reissue record | F19: SOURCE EMPTY
A21: Nonconversion laws
A22: Law | B22: Meaning | C22: Trigger | D22: Disposition
A23: NC-01 | B23: common interface is not common runtime | C23: Any public seam enters candidate execution | D23: SUSPEND affected releases
A24: NC-02 | B24: method freeze is not observed truth | C24: A frozen A0 is presented as proof | D24: REMOVE claim
A25: NC-03 | B25: issue authorization is not an award | C25: An A1 call identifies a winning firm or article | D25: VOID selection
A26: NC-04 | B26: award is not article acceptance | C26: Payment or contract signature creates evidence | D26: HOLD credit
A27: NC-05 | B27: safety stop is not event invalidity | C27: A valid dangerous response is erased as bad test | D27: RESTORE adverse record
A28: NC-06 | B28: emulator excursion is not candidate failure | C28: Reference state leaves tolerance | D28: INVALIDATE exact event only
A29: NC-07 | B29: missing evidence is not zero effect | C29: A decisive feature is imputed or omitted | D29: UNRESOLVED
A30: NC-08 | B30: simulation is not physical acceptance | C30: Model output substitutes for registered physical event | D30: DENY acceptance
A31: NC-09 | B31: one field is not a complete root | C31: A successful A1 earns A4 root credit | D31: HOLD root credit
A32: NC-10 | B32: root success is not production | C32: A4 evidence opens A6 without all-six mission | D32: HOLD production
A33: NC-11 | B33: valid adverse evidence is not nonperformance | C33: A failed proposition loses earned artifact payment | D33: PAY accepted work
A34: NC-12 | B34: post-result amendment is not correction | C34: Threshold, method or estimator changes for observed outcome | D34: NEW version and full affected replay

Sheet Finance
A2: A0 public-method and A1 release financial boundary
A3: USD billions. The A0 reservation is nested inside the inherited USD 80.0B public and enabling account; A1 exposure remains inside the USD 14.3B stageable option market.
A6: A0 cost element | B6: Quantity | C6: Unit cost (USD B) | D6: Calculated cost (USD B) | E6: Share | F6: Status | H6: A0 cost element | I6: USD billions
A7: Six public method packages | B7: 6 | C7: 0.25 | D7: =B7*C7 -> 1.5 | E7: =D7/$D$15 -> 0.125 | F7: PLANNING RESERVATION | H7: Six public method packages | I7: =D7 -> 1.5
A8: Twenty-four receiver-state lines | B8: 24 | C8: 0.175 | D8: =B8*C8 -> 4.2 | E8: =D8/$D$15 -> 0.35 | F8: PLANNING RESERVATION | H8: Twenty-four receiver-state lines | I8: =D8 -> 4.2
A9: One hundred forty-four method realizations | B9: 144 | C9: 0.0125 | D9: =B9*C9 -> 1.8 | E9: =D9/$D$15 -> 0.15 | F9: PLANNING RESERVATION | H9: One hundred forty-four method realizations | I9: =D9 -> 1.8
A10: One hundred forty-four calibration chains | B10: 144 | C10: 0.01 | D10: =B10*C10 -> 1.44 | E10: =D10/$D$15 -> 0.12 | F10: PLANNING RESERVATION | H10: One hundred forty-four calibration chains | I10: =D10 -> 1.44
A11: Twenty-four reset and forensic cells | B11: 24 | C11: 0.05 | D11: =B11*C11 -> 1.2 | E11: =D11/$D$15 -> 0.1 | F11: PLANNING RESERVATION | H11: Twenty-four reset and forensic cells | I11: =D11 -> 1.2
A12: Rights, safety and accessibility fixtures | B12: 6 | C12: 0.12 | D12: =B12*C12 -> 0.72 | E12: =D12/$D$15 -> 0.06 | F12: PLANNING RESERVATION | H12: Rights, safety and accessibility fixtures | I12: =D12 -> 0.72
A13: Evidence replay and cold-run capacity | B13: 6 | C13: 0.09 | D13: =B13*C13 -> 0.54 | E13: =D13/$D$15 -> 0.045 | F13: PLANNING RESERVATION | H13: Evidence replay and cold-run capacity | I13: =D13 -> 0.54
A14: Program uncertainty reserve | B14: 1 | C14: 0.6 | D14: =B14*C14 -> 0.6 | E14: =D14/$D$15 -> 0.05 | F14: PLANNING RESERVATION | H14: Program uncertainty reserve | I14: =D14 -> 0.6
A15: Total A0 public-method reservation | D15: =SUM(D7:D14) -> 12 | E15: =SUM(E7:E14) -> 1 | F15: UNOBLIGATED
A17: Private A1 exposure
A18: Private boundary | B18: Share | C18: Base (USD B) | D18: Exposure (USD B) | E18: Current obligation (USD B)
A19: Maximum payable through FRAME and MAKE | B19: 0.5 | C19: =$B$24 -> 14.347651 | D19: =B19*C19 -> 7.1738256 | E19: 0
A20: Stageable balance after MAKE | B20: 0.5 | C20: =$B$24 -> 14.347651 | D20: =B20*C20 -> 7.1738256 | E20: 0
A21: Private obligations now | E21: 0
A22: Public obligations now | E22: 0
A23: Selected-field T1 ceiling | B23: 27.5
A24: Private stageable options | B24: 14.347651
A25: Evidence-held mission authority | B25: 13.152349

Sheet Technology Agenda
A2: Technology Agenda
A3: The proving estate is itself a national technology program. These capabilities are program requirements, not claims that present systems already exist.
A6: Domain | B6: Technology thrust | C6: Required advance | D6: Strategic effect | E6: Current maturity | F6: Production credit
A7: Cross-system | B7: full-scale receiver-state synthesis | C7: Create safe, resettable physical states spanning motion, heat, fluids, structures, clinical workflow and damaged equipment. | D7: Enables repeatable service-denial science rather than demonstration theater. | E7: UNPROVED | F7: 0
A8: Cross-system | B8: unlike emulator realization | C8: Build two independently designed ways to create the same public state and quantify disagreement. | D8: Prevents one range implementation from defining national truth. | E8: UNPROVED | F8: 0
A9: Cross-system | B9: portable sovereign calibration | C9: Carry reference loads, flows, chemistry, physiology, time and geometry into disconnected field settings. | D9: Lets receivers reproduce claims without a central laboratory. | E9: UNPROVED | F9: 0
A10: Cross-system | B10: sealed multi-original evidence | C10: Retain independent raw originals, physical identity and causal order through total network loss. | D10: Makes missingness and tampering visible without one cloud. | E10: UNPROVED | F10: 0
A11: Cross-system | B11: estimator adjudication harness | C11: Execute unlike root-native estimators against sealed reference truth without standardizing the estimator. | D11: Creates comparability without a common analytic root. | E11: UNPROVED | F11: 0
A12: MS-ET | B12: dynamic heavy-load truth systems | C12: Generate coupled six-degree motion, transient contact, shore reaction and custody state at operational load. | D12: Makes no-pier heavy exchange a measurable discipline. | E12: UNPROVED | F12: 0
A13: MS-CT | B13: occupied-civil-terrain emulation | C13: Reproduce damaged-building geometry, heat, smoke, disability and consent constraints without endangering residents. | D13: Allows high-consequence human-machine access to fail safely in test. | E13: UNPROVED | F13: 0
A14: MS-HC | B14: closed fire and atmosphere ranges | C14: Create moving fire edges, ember fields, plume interaction and recoverable intervention residuals. | D14: Measures held effect and environmental consequence together. | E14: UNPROVED | F14: 0
A15: MS-LF | B15: coupled utility receiver grids | C15: Inject source, conversion, storage, corridor, demand and residual faults at water-energy scale. | D15: Tests complete utility service rather than independent nameplates. | E15: UNPROVED | F15: 0
A16: MS-HU | B16: clinical pathway state engines | C16: Represent acuity, workforce, utilities, transfer, consent and discharge as executable physical workflow. | D16: Tests completed episodes without exposing real patients to developmental risk. | E16: UNPROVED | F16: 0
A17: MS-RT | B17: regeneration truth factories | C17: Create known and blind damage, process variation, contamination and recertification loss across full articles. | D17: Makes configuration restoration measurable. | E17: UNPROVED | F17: 0
A18: Cross-system | B18: rights-native instrumentation | C18: Record consent, refusal, accessibility, separation, custody and receiver labor as first-class observations. | D18: Prevents technical rate from erasing civil completion. | E18: UNPROVED | F18: 0
... A20: Cross-system | B20: cold reconstruction compilers | C20: Allow an outside public team to rebuild method, emulator and article evidence from sealed artifacts. | D20: Turns knowledge transfer and export into physical capability rather than documentation possession. | E20: UNPROVED | F20: 0

Sheet Stress Tests
A2: Stress Tests
A3: Each case tests whether urgency, efficiency, favorable outcomes or common infrastructure can manufacture authority.
A6: # | B6: Stress world | C6: Required disposition | D6: Reason | E6: Prohibited conversions | F6: Result
A7: 1 | B7: Two emulator realizations disagree | C7: HOLD METHOD | D7: no decisive evidence until the state discrepancy is bounded | E7: 0 | F7: =IF(E7=0,"PASS","FAIL") -> PASS
A8: 2 | B8: Root House requests the public controller | C8: DENY DEPENDENCY | D8: public seams cannot implement candidate execution | E8: 0 | F8: =IF(E8=0,"PASS","FAIL") -> PASS
A9: 3 | B9: Favorable trial lacks one decisive raw original | C9: UNRESOLVED | D9: missing evidence cannot become a favorable zero | E9: 0 | F9: =IF(E9=0,"PASS","FAIL") -> PASS
A10: 4 | B10: Candidate triggers a valid safety stop | C10: PRESERVE ADVERSE | D10: stop protects people but does not erase the physical response | E10: 0 | F10: =IF(E10=0,"PASS","FAIL") -> PASS
A11: 5 | B11: Receiver state leaves registered tolerance | C11: INVALID EVENT | D11: only the exact event receives one bounded replay token | E11: 0 | F11: =IF(E11=0,"PASS","FAIL") -> PASS
A12: 6 | B12: Builder learns the blind challenge allocation | C12: VOID ALLOCATION | D12: issue a fresh sealed allocation before physical work | E12: 0 | F12: =IF(E12=0,"PASS","FAIL") -> PASS
A13: 7 | B13: Primary proving location is lost | C13: USE UNLIKE LINEAGE | D13: public method survives because implementation is plural and portable | E13: 0 | F13: =IF(E13=0,"PASS","FAIL") -> PASS
A14: 8 | B14: Method owner changes threshold after a result | C14: NEW VERSION | D14: prior method and result remain visible; replay the affected set | E14: 0 | F14: =IF(E14=0,"PASS","FAIL") -> PASS
A15: 9 | B15: One provider appears in two roots' decisive domain | C15: SUSPEND COLLISION | D15: restore exclusive ancestry before either release advances | E15: 0 | F15: =IF(E15=0,"PASS","FAIL") -> PASS
A16: 10 | B16: A striking prototype misses one service coordinate | C16: KILL OR RESIZE | D16: no weighted score or prestige exception exists | E16: 0 | F16: =IF(E16=0,"PASS","FAIL") -> PASS
A17: 11 | B17: Simulation passes but physical event fails | C17: BIND PHYSICAL RESULT | D17: simulation supports design and cannot overwrite observation | E17: 0 | F17: =IF(E17=0,"PASS","FAIL") -> PASS
A18: 12 | B18: Public evidence schema expands into a live broker | C18: REMOVE BROKER | D18: portable records do not authorize operational control | E18: 0 | F18: =IF(E18=0,"PASS","FAIL") -> PASS
... A22: 16 | B22: Partner receiver wants to reproduce a method | C22: TRANSFER PUBLIC PACKAGE | D22: receiver may rebuild public truth without receiving a vendor runtime | E22: 0 | F22: =IF(E22=0,"PASS","FAIL") -> PASS

Sheet Mutations
A2: Mutation restoration test
A3: Every deliberate defect must be detected, then the baseline must be restored without creating physical credit.
A6: # | B6: Control | C6: Required baseline | D6: Mutated value | E6: Mutation detected | F6: Restored value | G6: Restored | H6: Production credit
A7: 1 | B7: A0 package count | C7: 6 | D7: 5 | E7: =IF(D7<>C7,"YES","NO") -> YES | F7: =C7 -> 6 | G7: =IF(F7=C7,"YES","NO") -> YES | H7: 0
A8: 2 | B8: receiver-state count | C8: 24 | D8: 23 | E8: =IF(D8<>C8,"YES","NO") -> YES | F8: =C8 -> 24 | G8: =IF(F8=C8,"YES","NO") -> YES | H8: 0
A9: 3 | B9: public method count | C9: 72 | D9: 71 | E9: =IF(D9<>C9,"YES","NO") -> YES | F9: =C9 -> 72 | G9: =IF(F9=C9,"YES","NO") -> YES | H9: 0
A10: 4 | B10: method realization lineages | C10: 144 | D10: 72 | E10: =IF(D10<>C10,"YES","NO") -> YES | F10: =C10 -> 144 | G10: =IF(F10=C10,"YES","NO") -> YES | H10: 0
A11: 5 | B11: A1 warrant count | C11: 24 | D11: 23 | E11: =IF(D11<>C11,"YES","NO") -> YES | F11: =C11 -> 24 | G11: =IF(F11=C11,"YES","NO") -> YES | H11: 0
A12: 6 | B12: exclusive ancestry declarations | C12: 168 | D12: 167 | E12: =IF(D12<>C12,"YES","NO") -> YES | F12: =C12 -> 168 | G12: =IF(F12=C12,"YES","NO") -> YES | H12: 0
A13: 7 | B13: method-article cells | C13: 288 | D13: 287 | E13: =IF(D13<>C13,"YES","NO") -> YES | F13: =C13 -> 288 | G13: =IF(F13=C13,"YES","NO") -> YES | H13: 0
A14: 8 | B14: physical event slots | C14: 1152 | D14: 864 | E14: =IF(D14<>C14,"YES","NO") -> YES | F14: =C14 -> 1152 | G14: =IF(F14=C14,"YES","NO") -> YES | H14: 0
A15: 9 | B15: public seams | C15: 12 | D15: 13 | E15: =IF(D15<>C15,"YES","NO") -> YES | F15: =C15 -> 12 | G15: =IF(F15=C15,"YES","NO") -> YES | H15: 0
A16: 10 | B16: shared runtime count | C16: 0 | D16: 1 | E16: =IF(D16<>C16,"YES","NO") -> YES | F16: =C16 -> 0 | G16: =IF(F16=C16,"YES","NO") -> YES | H16: 0
A17: 11 | B17: current awards | C17: 0 | D17: 1 | E17: =IF(D17<>C17,"YES","NO") -> YES | F17: =C17 -> 0 | G17: =IF(F17=C17,"YES","NO") -> YES | H17: 0
A18: 12 | B18: production credit | C18: 0 | D18: 1 | E18: =IF(D18<>C18,"YES","NO") -> YES | F18: =C18 -> 0 | G18: =IF(F18=C18,"YES","NO") -> YES | H18: 0

Sheet Audit
A2: Terminal audit
A3: Checks are independent terminal diagnostics and do not feed any program decision or financial output.
A6: # | B6: Audit | C6: Actual | D6: Required | E6: Status | F6: Interpretation
A7: 1 | B7: Selected architecture gates | C7: ='Architecture Test'!N7 -> 12 | D7: 12 | E7: =IF(ABS(C7-D7)<0.000001,"PASS","FAIL") -> PASS | F7: All noncompensatory gates
A8: 2 | B8: Selected architecture count | C8: =COUNTIFS('Architecture Test'!O7:O11,"SELECT") -> 1 | D8: 1 | E8: =IF(ABS(C8-D8)<0.000001,"PASS","FAIL") -> PASS | F8: Exactly one architecture
A9: 3 | B9: A0 package count | C9: =COUNTA('A0 Packages'!A7:A12) -> 6 | D9: 6 | E9: =IF(ABS(C9-D9)<0.000001,"PASS","FAIL") -> PASS | F9: One per system
A10: 4 | B10: A0 frozen count | C10: =COUNTIFS('A0 Packages'!N7:N12,"FROZEN FOR ISSUE") -> 6 | D10: 6 | E10: =IF(ABS(C10-D10)<0.000001,"PASS","FAIL") -> PASS | F10: All public methods frozen
A11: 5 | B11: A0 observations | C11: =SUM('A0 Packages'!O7:O12) -> 0 | D11: 0 | E11: =IF(ABS(C11-D11)<0.000001,"PASS","FAIL") -> PASS | F11: No physical observation
A12: 6 | B12: A0 field credit | C12: =SUM('A0 Packages'!P7:P12) -> 0 | D12: 0 | E12: =IF(ABS(C12-D12)<0.000001,"PASS","FAIL") -> PASS | F12: Method is not effect
A13: 7 | B13: Vector coordinates | C13: =SUM('A0 Packages'!I7:I12) -> 48 | D13: 48 | E13: =IF(ABS(C13-D13)<0.000001,"PASS","FAIL") -> PASS | F13: Inherited without compensation
A14: 8 | B14: Receiver states | C14: =COUNTA('Receiver States'!A7:A30) -> 24 | D14: 24 | E14: =IF(ABS(C14-D14)<0.000001,"PASS","FAIL") -> PASS | F14: Four per system
A15: 9 | B15: Receiver implementation identities | C15: =COUNTIFS('Receiver States'!H7:H30,"<>SOURCE EMPTY") -> 0 | D15: 0 | E15: =IF(ABS(C15-D15)<0.000001,"PASS","FAIL") -> PASS | F15: Sites and providers held
A16: 10 | B16: Accepted receiver realizations | C16: =SUM('Receiver States'!I7:I30) -> 0 | D16: 0 | E16: =IF(ABS(C16-D16)<0.000001,"PASS","FAIL") -> PASS | F16: No facility acceptance
A17: 11 | B17: Public method cards | C17: =COUNTA('Public Methods'!A7:A78) -> 72 | D17: 72 | E17: =IF(ABS(C17-D17)<0.000001,"PASS","FAIL") -> PASS | F17: Twelve per system
A18: 12 | B18: Frozen public methods | C18: =COUNTIFS('Public Methods'!O7:O78,"FROZEN FOR ISSUE") -> 72 | D18: 72 | E18: =IF(ABS(C18-D18)<0.000001,"PASS","FAIL") -> PASS | F18: Pre-result version fixed
A19: 13 | B19: Required realization lineages | C19: =SUM('Public Methods'!M7:M78) -> 144 | D19: 144 | E19: =IF(ABS(C19-D19)<0.000001,"PASS","FAIL") -> PASS | F19: Two per method
A20: 14 | B20: Accepted realization lineages | C20: =SUM('Public Methods'!N7:N78) -> 0 | D20: 0 | E20: =IF(ABS(C20-D20)<0.000001,"PASS","FAIL") -> PASS | F20: Implementations source-empty
A21: 15 | B21: A1 development warrants | C21: =COUNTA('A1 Releases'!A7:A30) -> 24 | D21: 24 | E21: =IF(ABS(C21-D21)<0.000001,"PASS","FAIL") -> PASS | F21: Four per system
A22: 16 | B22: Issue-authorized warrants | C22: =COUNTIFS('A1 Releases'!L7:L30,"ISSUE AUTHORIZED") -> 24 | D22: 24 | E22: =IF(ABS(C22-D22)<0.000001,"PASS","FAIL") -> PASS | F22: Competition may be issued
A23: 17 | B23: Assigned Root Houses | C23: =COUNTIFS('A1 Releases'!M7:M30,"<>UNASSIGNED") -> 0 | D23: 0 | E23: =IF(ABS(C23-D23)<0.000001,"PASS","FAIL") -> PASS | F23: No firm selected
A24: 18 | B24: Article serial identities | C24: =COUNTIFS('A1 Releases'!N7:N30,"<>NONE") -> 0 | D24: 0 | E24: =IF(ABS(C24-D24)<0.000001,"PASS","FAIL") -> PASS | F24: No article exists
A25: 19 | B25: A1 accepted evidence | C25: =SUM('A1 Releases'!O7:O30) -> 0 | D25: 0 | E25: =IF(ABS(C25-D25)<0.000001,"PASS","FAIL") -> PASS | F25: No result
A26: 20 | B26: A1 field credit | C26: =SUM('A1 Releases'!P7:P30) -> 0 | D26: 0 | E26: =IF(ABS(C26-D26)<0.000001,"PASS","FAIL") -> PASS | F26: A1 is not A3
A27: 21 | B27: A1 production credit | C27: =SUM('A1 Releases'!Q7:Q30) -> 0 | D27: 0 | E27: =IF(ABS(C27-D27)<0.000001,"PASS","FAIL") -> PASS | F27: A1 is not A6
A28: 22 | B28: Ancestry declarations | C28: =COUNTA('Ancestry Firewall'!A7:A174) -> 168 | D28: 168 | E28: =IF(ABS(C28-D28)<0.000001,"PASS","FAIL") -> PASS | F28: Seven per root
A29: 23 | B29: Shared runtimes allowed | C29: =COUNTIFS('Ancestry Firewall'!G7:G174,"Yes") -> 0 | D29: 0 | E29: =IF(ABS(C29-D29)<0.000001,"PASS","FAIL") -> PASS | F29: No common technical root
A30: 24 | B30: Declared ancestry providers | C30: =COUNTIFS('Ancestry Firewall'!H7:H174,"<>SOURCE EMPTY") -> 0 | D30: 0 | E30: =IF(ABS(C30-D30)<0.000001,"PASS","FAIL") -> PASS | F30: Identities remain open
A31: 25 | B31: Accepted ancestry declarations | C31: =SUM('Ancestry Firewall'!I7:I174) -> 0 | D31: 0 | E31: =IF(ABS(C31-D31)<0.000001,"PASS","FAIL") -> PASS | F31: No paper ancestry credit
A32: 26 | B32: Method-article cells | C32: =COUNTA('Experiment Plan'!A7:A294) -> 288 | D32: 288 | E32: =IF(ABS(C32-D32)<0.000001,"PASS","FAIL") -> PASS | F32: Twelve per article
A33: 27 | B33: Experiment lineages | C33: =SUM('Experiment Plan'!I7:I294) -> 576 | D33: 576 | E33: =IF(ABS(C33-D33)<0.000001,"PASS","FAIL") -> PASS | F33: Two per cell
A34: 28 | B34: Physical event slots | C34: =SUM('Experiment Plan'!K7:K294) -> 1152 | D34: 1152 | E34: =IF(ABS(C34-D34)<0.000001,"PASS","FAIL") -> PASS | F34: Control and challenge on both lineages
A35: 29 | B35: Blind allocation tokens | C35: =SUM('Experiment Plan'!L7:L294) -> 1152 | D35: 1152 | E35: =IF(ABS(C35-D35)<0.000001,"PASS","FAIL") -> PASS | F35: One per physical event
A36: 30 | B36: Observed physical events | C36: =SUM('Experiment Plan'!M7:M294) -> 0 | D36: 0 | E36: =IF(ABS(C36-D36)<0.000001,"PASS","FAIL") -> PASS | F36: All source-empty
A37: 31 | B37: Valid events | C37: =SUM('Experiment Plan'!N7:N294) -> 0 | D37: 0 | E37: =IF(ABS(C37-D37)<0.000001,"PASS","FAIL") -> PASS | F37: No validity judgment
A38: 32 | B38: Invalid events | C38: =SUM('Experiment Plan'!O7:O294) -> 0 | D38: 0 | E38: =IF(ABS(C38-D38)<0.000001,"PASS","FAIL") -> PASS | F38: No event executed
A39: 33 | B39: Adverse events | C39: =SUM('Experiment Plan'!P7:P294) -> 0 | D39: 0 | E39: =IF(ABS(C39-D39)<0.000001,"PASS","FAIL") -> PASS | F39: No outcome
A40: 34 | B40: Public seams | C40: =COUNTA('Public Seams'!A7:A18) -> 12 | D40: 12 | E40: =IF(ABS(C40-D40)<0.000001,"PASS","FAIL") -> PASS | F40: Common semantics bounded
A41: 35 | B41: Seams entering candidate runtime | C41: =COUNTIFS('Public Seams'!D7:D18,"Yes") -> 0 | D41: 0 | E41: =IF(ABS(C41-D41)<0.000001,"PASS","FAIL") -> PASS | F41: No common operational stack
A42: 36 | B42: Separated authorities | C42: =COUNTA(Governance!A8:A19) -> 12 | D42: 12 | E42: =IF(ABS(C42-D42)<0.000001,"PASS","FAIL") -> PASS | F42: No unitary proof chain
A43: 37 | B43: Authority identities | C43: =COUNTIFS(Governance!F8:F19,"<>SOURCE EMPTY") -> 0 | D43: 0 | E43: =IF(ABS(C43-D43)<0.000001,"PASS","FAIL") -> PASS | F43: Appointments held
...

Sheet Sources & Limits
A2: Sources & Limits
A3: Internal evidence only. The workbook distinguishes inherited controls, prospective design requirements and still-empty physical records.
A6: Type | B6: Source or boundary | C6: Status | D6: Use
A7: Internal | B7: research/frontier.md | C7: Pass 208 frontier and Pass 209 parent question | D7: Current decision boundary and held identities
A8: Internal | B8: research/force/generation/department-of-resilience-first-six-system-requirement-cohort-and-public-service-vector-constitution.md | C8: Pass 208 | D8: Six fields, forty-eight vector coordinates and USD 27.5B boundary
A9: Internal | B9: models/programmatics/department-of-resilience-first-six-system-requirement-cohort.xlsx | C9: Pass 208 independently recalculated workbook | D9: System finances, root hypotheses and payment ladder
A10: Internal | B10: research/force/generation/department-of-resilience-first-physical-build-portfolio-and-release-sequence.md | C10: Pass 206 | D10: A0-A7 evidence ladder and USD 80.0B enabling account
A11: Internal | B11: research/force/generation/department-of-resilience-first-tranche-industrial-transaction-and-anti-convergence-constitution.md | C11: Pass 207 | D11: Root House options, artifact payment and anti-convergence law
A12: Internal | B12: research/force/generation/f36-cisa40-sa6-root-a-method-card-and-causal-estimator-constitution.md | C12: Method precedent | D12: Public method ownership, missingness and causal evidence
A13: Internal | B13: research/force/generation/f36-cisa40-sa6-root-b-method-card-and-causal-estimator-constitution.md | C13: Method precedent | D13: Independent method implementation and amendment law
A14: Limit | B14: No external sites used | C14: User constraint | D14: All quantities are internal design requirements or planning coefficients
A15: Limit | B15: No physical observations | C15: Pass 209 state | D15: Methods and event slots are prospective; all observation counts are zero
A16: Limit | B16: No supplier, site or serial identities | C16: Pass 209 state | D16: Release warrants are issuable public objects, not awards or accepted articles
A17: Limit | B17: USD 12.0B A0 reservation | C17: Planning construct | D17: Nested ceiling, not cost estimate, appropriation, obligation or market forecast
A18: Limit | B18: No rendering | C18: User constraint | D18: Exterior form remains held until physical requirements mature
