Workbook

Sheet Summary
A2: PFP-5 National First Physical Launch Compact
A4: Verdict: RETURN. The warranted launch lattice is executable as a competition constitution. It authorizes no firm, article, physical event, payment, capability or exterior form.
A6: Decision | B6: Result | C6: Unit | D6: State | E6: Meaning | F6: Current authority | G6: Next question
A7: selected launch architecture | B7: warranted launch lattice | C7: architecture | D7: RETURN | E7: four prior passes integrated | F7: issue bounded competitions | G7: A2 construction portfolio
A8: first-tranche ceiling | B8: 200 | C8: USD B | D8: CONSTITUTED | E8: five exclusive accounts | F8: ceiling only | G8: no additional money
A9: stageable private ceiling | B9: 57.4 | C9: USD B | D9: GATED | E9: artifact options | F9: no award | G9: control admission
A10: selected cohort | B10: 27.5 | C10: USD B | D10: FROZEN | E10: one field per system | F10: 24 A1 issues | G10: A2 endpoints
A11: cohort stageable | B11: 14.347651 | C11: USD B | D11: GATED | E11: twenty-four root experiments | F11: through MAKE capped at USD 7.17B | G11: artifact acceptance
A12: public-method reservation | B12: 12 | C12: USD B | D12: RESERVED | E12: nested in USD 80B enabling | F12: no obligation | G12: estate construction selection
A13: root houses | B13: 24 | C13: count | D13: ISSUE-READY | E13: one control group per root | F13: charter calls only | G13: identity admission
A14: root-field opportunities | B14: 96 | C14: count | D14: FROZEN | E14: 24 cohort and 72 held | F14: 24 may issue | G14: later field release
A15: A0.1 packages | B15: 6 | C15: count | D15: FROZEN FOR ISSUE | E15: public questions | F15: publication | G15: physical realization
A16: method realizations | B16: 144 | C16: count | D16: HELD | E16: two unlike per method card | F16: none | G16: independence acceptance
A17: A1 development warrants | B17: 24 | C17: count | D17: ISSUE AUTHORIZED | E17: one per root | F17: competition issue | G17: award
A18: A1 execution domains | B18: 168 | C18: count | D18: DECLARED | E18: subset of 288 parent cells | F18: provider identities remain empty | G18: ancestry admission
A19: prospective events | B19: 1152 | C19: count | D19: HELD | E19: event population only | F19: none | G19: sealed allocation
... A22: capability and production credit | B22: 0 | C22: count | D22: HELD | E22: no physical evidence | F22: none | G22: complete-root proof
A25: Terminal test | B25: Result | C25: State | E25: Returned parent question | F25: State | G25: Construction authority
A26: architecture eligible | B26: =COUNTIF(Architecture!R7:R11,"SELECT") -> 1 | C26: =IF(B26=1,"PASS","FAIL") -> PASS | E26: balance-first rigs | F26: TO TEST | G26: 0
A27: financial ledgers reconcile | B27: =Finance!B20 -> 200 | C27: =IF(B27=200,"PASS","FAIL") -> PASS | E27: causal-keystone rigs | F27: TO TEST | G27: 0
A28: contradictions resolved | B28: =COUNTIF(Contradictions!E7:E16,"RESOLVED") -> 10 | C28: =IF(B28=10,"PASS","FAIL") -> PASS | E28: receiver-state realizations | F28: TO TEST | G28: 0
A29: current obligation | B29: =Controls!B31 -> 0 | C29: =IF(B29=0,"PASS","FAIL") -> PASS | E29: compound six-system wave | F29: TO TEST | G29: 0
A30: A2 authority | B30: =SUM('A2 Return'!F7:F11) -> 0 | C30: =IF(B30=0,"PASS","FAIL") -> PASS | E30: full proving-estate formation | F30: TO TEST | G30: 0
A31: audit failures | B31: =COUNTIF(Audit!E7:E70,"FAIL") -> 0 | C31: =IF(B31=0,"PASS","FAIL") -> PASS

Sheet Controls
A2: Authoritative launch controls
A4: Blue cells are the only mutable design controls used by the audit and mutation harness. They are ceilings and counts, not awards or evidence.
A6: Control | B6: Value | C6: Unit | D6: Authority | E6: Meaning
A7: portfolio ceiling | B7: 200 | C7: USD B | D7: PFP-1 | E7: first tranche
A8: mission-system account | B8: 110 | C8: USD B | D8: PFP-1 | E8: six systems
A9: service technical bases | B9: 30 | C9: USD B | D9: PFP-1 | E9: public technical release
A10: common capacity | B10: 30 | C10: USD B | D10: PFP-1 | E10: shared noncandidate capacity
A11: sovereign technical estate | B11: 20 | C11: USD B | D11: PFP-1 | E11: public truth and continuity
A12: failure reserve | B12: 10 | C12: USD B | D12: PFP-1 | E12: protected
A13: stageable private options | B13: 57.4 | C13: USD B | D13: PFP-2 | E13: ceiling after gates
A14: evidence-held mission authority | B14: 52.6 | C14: USD B | D14: PFP-2 | E14: held by systems
A15: public and enabling authority | B15: 80 | C15: USD B | D15: PFP-2 | E15: service, common and estate
A16: cohort stageable options | B16: 14.347651 | C16: USD B | D16: PFP-3 | E16: twenty-four experiments
A17: cohort evidence-held authority | B17: 13.152349 | C17: USD B | D17: PFP-3 | E17: selected six fields
A18: public-method reservation | B18: 12 | C18: USD B | D18: PFP-4 | E18: nested in enabling
... A37: production credit | B37: 0 | C37: count | D37: PFP-5 | E37: not inferred

Sheet Architecture
A2: Launch architecture hard-gate test
A4: A candidate must pass all fourteen noncompensatory gates. A score cannot compensate for a failed gate.
A6: Architecture | B6: five accounts conserved | C6: all six systems live | D6: twenty-four roots separate | E6: complete-root liability | F6: compound cohort preserved | G6: public denominator | H6: plural physical truth | I6: independent proof | J6: receiver acceptance | K6: paid valid failure | L6: no production inference | M6: typed rollback | N6: zero-credit start | O6: executable issue path | P6: Passes | Q6: Eligible | R6: Decision
A7: Warranted launch lattice | B7: 1 | C7: 1 | D7: 1 | E7: 1 | F7: 1 | G7: 1 | H7: 1 | I7: 1 | J7: 1 | K7: 1 | L7: 1 | M7: 1 | N7: 1 | O7: 1 | P7: =SUM(B7:O7) -> 14 | Q7: =IF(P7=14,"YES","NO") -> YES | R7: =IF(Q7="YES","SELECT","REJECT") -> SELECT
A8: Consolidated launch office | B8: 1 | C8: 1 | D8: 0 | E8: 1 | F8: 1 | G8: 1 | H8: 0 | I8: 0 | J8: 0 | K8: 1 | L8: 0 | M8: 0 | N8: 0 | O8: 1 | P8: =SUM(B8:O8) -> 7 | Q8: =IF(P8=14,"YES","NO") -> NO | R8: =IF(Q8="YES","SELECT","REJECT") -> REJECT
A9: Six system program offices | B9: 1 | C9: 1 | D9: 1 | E9: 1 | F9: 0 | G9: 1 | H9: 1 | I9: 0 | J9: 0 | K9: 1 | L9: 1 | M9: 0 | N9: 0 | O9: 1 | P9: =SUM(B9:O9) -> 9 | Q9: =IF(P9=14,"YES","NO") -> NO | R9: =IF(Q9="YES","SELECT","REJECT") -> REJECT
A10: Twenty-four prime demonstrations | B10: 0 | C10: 1 | D10: 1 | E10: 1 | F10: 0 | G10: 0 | H10: 0 | I10: 0 | J10: 0 | K10: 0 | L10: 0 | M10: 0 | N10: 0 | O10: 1 | P10: =SUM(B10:O10) -> 4 | Q10: =IF(P10=14,"YES","NO") -> NO | R10: =IF(Q10="YES","SELECT","REJECT") -> REJECT
A11: Proving-estate-first launch | B11: 1 | C11: 0 | D11: 1 | E11: 0 | F11: 0 | G11: 1 | H11: 1 | I11: 1 | J11: 0 | K11: 1 | L11: 1 | M11: 1 | N11: 1 | O11: 0 | P11: =SUM(B11:O11) -> 9 | Q11: =IF(P11=14,"YES","NO") -> NO | R11: =IF(Q11="YES","SELECT","REJECT") -> REJECT

Sheet Integration
A2: Five-pass physical-portfolio integration
A4: Later passes supersede implementation ambiguity without erasing the quantities established earlier.
A6: Pass | B6: Research object | C6: Authoritative contribution | D6: Inherited quantity | E6: Launch interpretation | F6: Branch result
A7: 206 | B7: PFP-1 National First Article Portfolio | C7: all-six build-to-learn sequence | D7: USD 200B; 24 fields; 96 opportunities; eight article states | E7: constitute portfolio without production | F7: CLOSE
A8: 207 | B8: PFP-2 Separated option-and-proof market | C8: twenty-four one-root control groups and paid failure | D8: USD 57.4B stageable; 288 domains; 72 dependencies | E8: issue cancelable artifact options | F8: CLOSE
A9: 208 | B9: PFP-3 Compound First-Reach Cohort | C9: one synchronized field per system | D9: 24 experiments; 48 vector coordinates; 30 interfaces | E9: open one experiment per root | F9: CLOSE
A10: 209 | B10: PFP-4 Federated Physical-Truth Grid | C10: public questions with unlike realizations | D10: 6 methods; 72 cards; 144 realizations; 1,152 events | E10: freeze methods and authorize issue | F10: CLOSE
A11: 210 | B11: PFP-5 National First Physical Launch Compact | C11: warranted launch lattice and zero-credit boundary | D11: nine launch objects; ten reconciliations | E11: return first construction choice | F11: RETURN

Sheet Contradictions
A2: Resolved inherited contradictions
A4: Every reconciliation preserves the stricter interpretation. None creates money, evidence or capability.
A6: ID | B6: Apparent conflict | C6: Resolved interpretation | D6: Control test | E6: Status
A7: C01 | B7: 96 opportunities / 24 A1 warrants | C7: 24 are first cohort; 72 remain held | D7: 96 = 24 × 4 | E7: RESOLVED
A8: C02 | B8: 288 ancestry cells / 168 A1 domains | C8: 168 are seven-domain A1 subset; 120 parent cells remain held | D8: 288 = 168 + 120 | E8: RESOLVED
A9: C03 | B9: 72 dependencies / 12 public seams | C9: provider exposure and public grammar are different ledgers | D9: neither substitutes for the other | E9: RESOLVED
A10: C04 | B10: 30 directed interfaces / 12 public seams | C10: operational exchanges and portable semantics remain distinct | D10: no common controller | E10: RESOLVED
A11: C05 | B11: USD 80B enabling / USD 12B method reserve | C11: reservation is nested; USD 68B remains | D11: 80 = 12 + 68 | E11: RESOLVED
A12: C06 | B12: USD 57.4B stageable / USD 14.3B cohort | C12: cohort is a subset; USD 43.1B remains outside | D12: 57.4 = 14.3 + 43.1 | E12: RESOLVED
A13: C07 | B13: USD 200B tranche / USD 750B through year 15 | C13: present ceiling and contingent cumulative boundary | D13: later tranches need new warrants | E13: RESOLVED
A14: C08 | B14: frozen A0 / accepted method | C14: question frozen; implementation and calibration unaccepted | D14: accepted realizations = 0 | E14: RESOLVED
A15: C09 | B15: authorized A1 / awarded article | C15: solicitation may issue; identities, awards and serials remain zero | D15: current obligations = 0 | E15: RESOLVED
A16: C10 | B16: one cohort experiment / complete root | C16: one field proposition cannot prove four-field root | D16: root credit = 0 | E16: RESOLVED

Sheet Finance
A2: First-tranche financial reconciliation
A4: All values are authority ceilings in USD billions. Current obligations and payments remain zero.
A6: Fiscal account | B6: Authority | C6: Control | D6: Difference
A7: mission systems | B7: =Controls!B8 -> 110 | C7: 110 | D7: =B7-C7 -> 0
A8: service technical bases | B8: =Controls!B9 -> 30 | C8: 30 | D8: =B8-C8 -> 0
A9: common capacity | B9: =Controls!B10 -> 30 | C9: 30 | D9: =B9-C9 -> 0
A10: sovereign technical estate | B10: =Controls!B11 -> 20 | C10: 20 | D10: =B10-C10 -> 0
A11: failure reserve | B11: =Controls!B12 -> 10 | C11: 10 | D11: =B11-C11 -> 0
A12: TOTAL | B12: =SUM(B7:B11) -> 200 | C12: 200 | D12: =B12-C12 -> 0
A15: Economic state | B15: Authority | C15: Share | D15: Current obligation
A16: stageable private options | B16: =Controls!B13 -> 57.4 | C16: =B16/$B$20 -> 0.287 | D16: =Controls!B31 -> 0
A17: evidence-held mission authority | B17: =Controls!B14 -> 52.6 | C17: =B17/$B$20 -> 0.263 | D17: =Controls!B31 -> 0
A18: public and enabling authority | B18: =Controls!B15 -> 80 | C18: =B18/$B$20 -> 0.4 | D18: =Controls!B31 -> 0
A19: protected failure reserve | B19: =Controls!B12 -> 10 | C19: =B19/$B$20 -> 0.05 | D19: =Controls!B31 -> 0
A20: TOTAL | B20: =SUM(B16:B19) -> 200 | C20: =SUM(C16:C19) -> 1 | D20: =SUM(D16:D19) -> 0
A23: Cohort partition | B23: Authority | C23: Formula | D23: State
A24: cohort stageable | B24: =Controls!B16 -> 14.347651 | C24: selected share | D24: STAGEABLE
A25: cohort evidence-held | B25: =Controls!B17 -> 13.152349 | C25: selected share | D25: HELD
A26: outside-cohort stageable | B26: =Controls!B13-B24 -> 43.052349 | C26: remainder | D26: HELD
A27: outside-cohort evidence-held | B27: =Controls!B14-B25 -> 39.447651 | C27: remainder | D27: HELD
A28: public-method reservation | B28: =Controls!B18 -> 12 | C28: nested | D28: RESERVED
A29: enabling authority remaining | B29: =Controls!B15-B28 -> 68 | C29: remainder | D29: UNASSIGNED
A30: FRAME | B30: =B24*15% -> 2.1521477 | C30: 15% | D30: AVAILABLE AFTER GATE
A31: MAKE | B31: =B24*35% -> 5.0216779 | C31: 35% | D31: AVAILABLE AFTER GATE
A32: through MAKE | B32: =SUM(B30:B31) -> 7.1738256 | C32: 50% | D32: MAXIMUM EXPOSURE
A33: BREAK | B33: =B24*35% -> 5.0216779 | C33: 35% | D33: HELD
A34: TRANSFER | B34: =B24*15% -> 2.1521477 | C34: 15% | D34: HELD
A35: post-MAKE stageable | B35: =SUM(B33:B34) -> 7.1738256 | C35: 50% | D35: HELD
A39: System | B39: Selected field | C39: T1 field | D39: Stageable | E39: Held | F39: Roots | G39: Awarded | H39: Credit
A40: MS-ET | B40: No-pier heavy transfer | C40: 4.4511698 | D40: 2.0018985 | E40: 2.4492713 | F40: 4 | G40: =Controls!B31 -> 0 | H40: =Controls!B35 -> 0
A41: MS-CT | B41: Building and vertical access | C41: 4.5936399 | D41: 2.0659739 | E41: 2.527666 | F41: 4 | G41: =Controls!B31 -> 0 | H41: =Controls!B35 -> 0
A42: MS-HC | B42: Persistent fire control | C42: 2.7323978 | D42: 1.2288866 | E42: 1.5035112 | F42: 4 | G42: =Controls!B31 -> 0 | H42: =Controls!B35 -> 0
A43: MS-LF | B43: Strategic water-energy carriers | C43: 3.5976513 | D43: 3.5976513 | E43: 0 | F43: 4 | G43: =Controls!B31 -> 0 | H43: =Controls!B35 -> 0
A44: MS-HU | B44: Distributed definitive care | C44: 7.6550881 | D44: 3.4428498 | E44: 4.2122383 | F44: 4 | G44: =Controls!B31 -> 0 | H44: =Controls!B35 -> 0
A45: MS-RT | B45: Field regeneration | C45: 4.4700531 | D45: 2.0103912 | E45: 2.4596619 | F45: 4 | G45: =Controls!B31 -> 0 | H45: =Controls!B35 -> 0
A46: TOTAL | B46: six systems | C46: =SUM(C40:C45) -> 27.5 | D46: =SUM(D40:D45) -> 14.347651 | E46: =SUM(E40:E45) -> 13.152349 | F46: =SUM(F40:F45) -> 24 | G46: =SUM(G40:G45) -> 0 | H46: =SUM(H40:H45) -> 0

Sheet Launch Objects
A2: Exact launch objects and current states
A4: A launch state records what may happen next. It does not certify that the next act occurred.
A6: ID | B6: Launch object | C6: Quantity | D6: State now | E6: Authority granted | F6: Conversion prohibited | G6: Next warrant
A7: L01 | B7: first-tranche fiscal constitution | C7: USD 200B | D7: CONSTITUTED | E7: account structure | F7: ceiling to obligation or capability | G7: appropriation warrant
A8: L02 | B8: Root House charter calls | C8: 24 | D8: ISSUE-READY | E8: publish charter competition | F8: call to owner, firm or winner | G8: control admission
A9: L03 | B9: root-field registry | C9: 96 | D9: FROZEN | E9: preserve four fields per root | F9: held assignment to active award | G9: field issue
A10: L04 | B10: A0.1 method packages | C10: 6 | D10: FROZEN FOR ISSUE | E10: publish question and law | F10: method text to physical truth | G10: realization commission
A11: L05 | B11: first-cohort A1 warrants | C11: 24 | D11: ISSUE AUTHORIZED | E11: open development competition | F11: issue to award, article or evidence | G11: award warrant
A12: L06 | B12: unlike method realizations | C12: 144 | D12: HELD | E12: none | F12: plan to accepted implementation | G12: independence acceptance
A13: L07 | B13: prospective physical events | C13: 1152 | D13: HELD | E13: none | F13: slot to valid event | G13: event allocation
A14: L08 | B14: A2 endpoint rigs | C14: 0 | D14: RETURNED | E14: parent may select portfolio | F14: return to construction | G14: A2 construction warrant
A15: L09 | B15: obligation, payment and capability | C15: 0 | D15: HELD | E15: none | F15: schedule or spend to credit | G15: typed artifact acceptance

Sheet Warrant Ladder
A2: Typed launch succession
A4: Every row requires a new warrant. No row inherits the authority of the row above it.
A6: Step | B6: State object | C6: Issuing authority | D6: Required predicate | E6: Current state | F6: May create | G6: Cannot create
A7: 0 | B7: tranche constitution | C7: Congress and Comptroller | D7: five accounts reconcile | E7: CONSTITUTED | F7: bounded fiscal ceiling | G7: obligation
A8: 1 | B8: public denominator | C8: Mission System Command | D8: receiver and service subject fixed | E8: FROZEN | F8: competition question | G8: physical fact
A9: 2 | B9: charter call | C9: Capital Board | D9: one-root control law | E9: ISSUE-READY | F9: control applications | G9: Root House identity
A10: 3 | B10: control admission | C10: independent control registrar | D10: beneficial control and dependencies clear | E10: HELD | F10: eligible bidder | G10: fiscal option
A11: 4 | B11: fiscal option | C11: Capital Board | D11: admitted control plus assignment | E11: HELD | F11: artifact ceiling | G11: obligation or payment
A12: 5 | B12: method realization | C12: public-method custodian | D12: unlike implementation and calibration accepted | E12: HELD | F12: event-ready instrument | G12: valid event
A13: 6 | B13: A1 award | C13: Capital Board | D13: method, control and rights complete | E13: HELD | F13: controlled article work | G13: article acceptance
A14: 7 | B14: A2 construction | C14: technical-release authority | D14: selected endpoint portfolio and estate formation | E14: RETURNED | F14: rig build authority | G14: endpoint evidence
A15: 8 | B15: valid event | C15: Resilience Proving Service | D15: sealed event and custody complete | E15: HELD | F15: binding observation | G15: disposition
A16: 9 | B16: root disposition | C16: Root Disposition Board | D16: complete valid evidence packet | E16: HELD | F16: BUILD PROOF, RESIZE or KILL | G16: production
A17: 10 | B17: artifact payment | C17: Program Comptroller | D17: accepted payable artifact | E17: HELD | F17: payment | G17: favorable result
A18: 11 | B18: capability credit | C18: receiver and readiness authorities | D18: complete-root and formation warrants | E18: HELD | F18: bounded service credit | G18: production or readiness by inference

Sheet Root Register
A2: Twenty-four first-cohort root-field experiments
A6: Opportunity | B6: Root | C6: System | D6: Selected field | E6: Root thesis | F6: Mechanism hypothesis | G6: First artifact | H6: Stageable option | I6: Held option | J6: A1 state | K6: A2 state | L6: Awarded | M6: Spend | N6: Field credit | O6: Root credit
A7: C1-01 | B7: ET-A | C7: MS-ET | D7: No-pier heavy transfer | E7: Oceanic mass bridge | F7: Dynamically stabilized offshore exchange | G7: one no-pier transfer lane | H7: =INDEX(Finance!$D$40:$D$45,MATCH(C7,Finance!$A$40:$A$45,0))/4 -> 0.50047462 | I7: =INDEX(Finance!$E$40:$E$45,MATCH(C7,Finance!$A$40:$A$45,0))/4 -> 0.61231783 | J7: ISSUE AUTHORIZED | K7: RETURNED | L7: 0 | M7: 0 | N7: 0 | O7: 0
A8: C1-02 | B8: ET-B | C8: MS-ET | D8: No-pier heavy transfer | E8: Buoyant air bridge | F8: Buoyant heavy carriers | G8: one heavy air-to-ground chain | H8: =INDEX(Finance!$D$40:$D$45,MATCH(C8,Finance!$A$40:$A$45,0))/4 -> 0.50047462 | I8: =INDEX(Finance!$E$40:$E$45,MATCH(C8,Finance!$A$40:$A$45,0))/4 -> 0.61231783 | J8: ISSUE AUTHORIZED | K8: RETURNED | L8: 0 | M8: 0 | N8: 0 | O8: 0
A9: C1-03 | B9: ET-C | C9: MS-ET | D9: No-pier heavy transfer | E9: Austere surface bridge | F9: Machine-laid causeway and dry terminal | G9: one austere shore corridor | H9: =INDEX(Finance!$D$40:$D$45,MATCH(C9,Finance!$A$40:$A$45,0))/4 -> 0.50047462 | I9: =INDEX(Finance!$E$40:$E$45,MATCH(C9,Finance!$A$40:$A$45,0))/4 -> 0.61231783 | J9: ISSUE AUTHORIZED | K9: RETURNED | L9: 0 | M9: 0 | N9: 0 | O9: 0
A10: C1-04 | B10: ET-D | C10: MS-ET | D10: No-pier heavy transfer | E10: Amphibious autonomous mesh | F10: Distributed uncrewed amphibious lighters | G10: one multi-path transfer mesh | H10: =INDEX(Finance!$D$40:$D$45,MATCH(C10,Finance!$A$40:$A$45,0))/4 -> 0.50047462 | I10: =INDEX(Finance!$E$40:$E$45,MATCH(C10,Finance!$A$40:$A$45,0))/4 -> 0.61231783 | J10: ISSUE AUTHORIZED | K10: RETURNED | L10: 0 | M10: 0 | N10: 0 | O10: 0
A11: C1-05 | B11: CT-A | C11: MS-CT | D11: Building and vertical access | E11: Civic edge grid | F11: Prepared powered refuge interfaces | G11: one occupied-building sector | H11: =INDEX(Finance!$D$40:$D$45,MATCH(C11,Finance!$A$40:$A$45,0))/4 -> 0.51649348 | I11: =INDEX(Finance!$E$40:$E$45,MATCH(C11,Finance!$A$40:$A$45,0))/4 -> 0.6319165 | J11: ISSUE AUTHORIZED | K11: RETURNED | L11: 0 | M11: 0 | N11: 0 | O11: 0
A12: C1-06 | B12: CT-B | C12: MS-CT | D12: Building and vertical access | E12: Air-and-skin reach | F12: Exterior-climbing machines | G12: one high-rise skin-reach system | H12: =INDEX(Finance!$D$40:$D$45,MATCH(C12,Finance!$A$40:$A$45,0))/4 -> 0.51649348 | I12: =INDEX(Finance!$E$40:$E$45,MATCH(C12,Finance!$A$40:$A$45,0))/4 -> 0.6319165 | J12: ISSUE AUTHORIZED | K12: RETURNED | L12: 0 | M12: 0 | N12: 0 | O12: 0
A13: C1-07 | B13: CT-C | C13: MS-CT | D13: Building and vertical access | E13: Building utility spine | F13: Temporary external lift and utility spine | G13: one building utility spine | H13: =INDEX(Finance!$D$40:$D$45,MATCH(C13,Finance!$A$40:$A$45,0))/4 -> 0.51649348 | I13: =INDEX(Finance!$E$40:$E$45,MATCH(C13,Finance!$A$40:$A$45,0))/4 -> 0.6319165 | J13: ISSUE AUTHORIZED | K13: RETURNED | L13: 0 | M13: 0 | N13: 0 | O13: 0
A14: C1-08 | B14: CT-D | C14: MS-CT | D14: Building and vertical access | E14: Neighborhood machine swarm | F14: Human-assist mobility and distributed sensing | G14: one neighborhood access mesh | H14: =INDEX(Finance!$D$40:$D$45,MATCH(C14,Finance!$A$40:$A$45,0))/4 -> 0.51649348 | I14: =INDEX(Finance!$E$40:$E$45,MATCH(C14,Finance!$A$40:$A$45,0))/4 -> 0.6319165 | J14: ISSUE AUTHORIZED | K14: RETURNED | L14: 0 | M14: 0 | N14: 0 | O14: 0
A15: C1-09 | B15: HC-A | C15: MS-HC | D15: Persistent fire control | E15: Atmospheric control wing | F15: Endurance aircraft and multi-agent delivery | G15: one atmospheric fire-control element | H15: =INDEX(Finance!$D$40:$D$45,MATCH(C15,Finance!$A$40:$A$45,0))/4 -> 0.30722165 | I15: =INDEX(Finance!$E$40:$E$45,MATCH(C15,Finance!$A$40:$A$45,0))/4 -> 0.3758778 | J15: ISSUE AUTHORIZED | K15: RETURNED | L15: 0 | M15: 0 | N15: 0 | O15: 0
A16: C1-10 | B16: HC-B | C16: MS-HC | D16: Persistent fire control | E16: Fluid intervention lattice | F16: Closed-loop hydraulic intervention | G16: one fluid-intervention sector | H16: =INDEX(Finance!$D$40:$D$45,MATCH(C16,Finance!$A$40:$A$45,0))/4 -> 0.30722165 | I16: =INDEX(Finance!$E$40:$E$45,MATCH(C16,Finance!$A$40:$A$45,0))/4 -> 0.3758778 | J16: ISSUE AUTHORIZED | K16: RETURNED | L16: 0 | M16: 0 | N16: 0 | O16: 0
A17: C1-11 | B17: HC-C | C17: MS-HC | D17: Persistent fire control | E17: Autonomous terrain corps | F17: Optionally crewed line-production machines | G17: one robotic line train | H17: =INDEX(Finance!$D$40:$D$45,MATCH(C17,Finance!$A$40:$A$45,0))/4 -> 0.30722165 | I17: =INDEX(Finance!$E$40:$E$45,MATCH(C17,Finance!$A$40:$A$45,0))/4 -> 0.3758778 | J17: ISSUE AUTHORIZED | K17: RETURNED | L17: 0 | M17: 0 | N17: 0 | O17: 0
A18: C1-12 | B18: HC-D | C18: MS-HC | D18: Persistent fire control | E18: Distributed control field | F18: Distributed sensing and actuation | G18: one boundary-control field | H18: =INDEX(Finance!$D$40:$D$45,MATCH(C18,Finance!$A$40:$A$45,0))/4 -> 0.30722165 | I18: =INDEX(Finance!$E$40:$E$45,MATCH(C18,Finance!$A$40:$A$45,0))/4 -> 0.3758778 | J18: ISSUE AUTHORIZED | K18: RETURNED | L18: 0 | M18: 0 | N18: 0 | O18: 0
... A30: C1-24 | B30: RT-D | C30: MS-RT | D30: Field regeneration | E30: Closed-loop sustainment fleet | F30: Mobile decontamination and metrology | G30: one field-regeneration loop | H30: =INDEX(Finance!$D$40:$D$45,MATCH(C30,Finance!$A$40:$A$45,0))/4 -> 0.50259779 | I30: =INDEX(Finance!$E$40:$E$45,MATCH(C30,Finance!$A$40:$A$45,0))/4 -> 0.61491548 | J30: ISSUE AUTHORIZED | K30: RETURNED | L30: 0 | M30: 0 | N30: 0 | O30: 0
A33: TOTAL | B33: 24 roots | C33: 6 systems | D33: 6 fields | H33: =SUM(H7:H30) -> 14.347651 | I33: =SUM(I7:I30) -> 13.152349 | L33: =SUM(L7:L30) -> 0 | M33: =SUM(M7:M30) -> 0 | N33: =SUM(N7:N30) -> 0 | O33: =SUM(O7:O30) -> 0

Sheet Domain Register
A2: Complete-root and first-article ancestry register
A4: Every A1 declaration occupies one parent ancestry cell. The remaining five domains per root remain held for complete-root formation.
A6: Cell | B6: Root | C6: Parent domain | D6: Domain name | E6: In A1 subset | F6: A1 declaration | G6: Provider identity | H6: Collision | I6: State
A7: AD-001 | B7: ET-A | C7: P01 | D7: mission control and planning | E7: 1 | F7: ET-A-P01 | H7: 0 | I7: EXCLUSIVE DECLARATION
A8: AD-002 | B8: ET-A | C8: P02 | D8: state estimation and world model | E8: 1 | F8: ET-A-P02 | H8: 0 | I8: EXCLUSIVE DECLARATION
A9: AD-003 | B9: ET-A | C9: P03 | D9: sensing, time and calibration | E9: 1 | F9: ET-A-P03 | H9: 0 | I9: EXCLUSIVE DECLARATION
A10: AD-004 | B10: ET-A | C10: P04 | D10: actuation and low-level control | E10: 1 | F10: ET-A-P04 | H10: 0 | I10: EXCLUSIVE DECLARATION
A11: AD-005 | B11: ET-A | C11: P05 | D11: safeing and human override | E11: 1 | F11: ET-A-P05 | H11: 0 | I11: EXCLUSIVE DECLARATION
A12: AD-006 | B12: ET-A | C12: P06 | D12: energy and power management | E12: 1 | F12: ET-A-P06 | H12: 0 | I12: EXCLUSIVE DECLARATION
A13: AD-007 | B13: ET-A | C13: P07 | D13: build, repair and release | E13: 1 | F13: ET-A-P07 | H13: 0 | I13: EXCLUSIVE DECLARATION
A14: AD-008 | B14: ET-A | C14: P08 | D14: material supply | E14: 0 | H14: 0 | I14: HELD
A15: AD-009 | B15: ET-A | C15: P09 | D15: workforce and license | E15: 0 | H15: 0 | I15: HELD
A16: AD-010 | B16: ET-A | C16: P10 | D16: logistics and sustainment | E16: 0 | H16: 0 | I16: HELD
A17: AD-011 | B17: ET-A | C17: P11 | D17: receiver integration | E17: 0 | H17: 0 | I17: HELD
A18: AD-012 | B18: ET-A | C18: P12 | D18: regeneration | E18: 0 | H18: 0 | I18: HELD
A19: AD-013 | B19: ET-B | C19: P01 | D19: mission control and planning | E19: 1 | F19: ET-B-P01 | H19: 0 | I19: EXCLUSIVE DECLARATION
A20: AD-014 | B20: ET-B | C20: P02 | D20: state estimation and world model | E20: 1 | F20: ET-B-P02 | H20: 0 | I20: EXCLUSIVE DECLARATION
A21: AD-015 | B21: ET-B | C21: P03 | D21: sensing, time and calibration | E21: 1 | F21: ET-B-P03 | H21: 0 | I21: EXCLUSIVE DECLARATION
A22: AD-016 | B22: ET-B | C22: P04 | D22: actuation and low-level control | E22: 1 | F22: ET-B-P04 | H22: 0 | I22: EXCLUSIVE DECLARATION
A23: AD-017 | B23: ET-B | C23: P05 | D23: safeing and human override | E23: 1 | F23: ET-B-P05 | H23: 0 | I23: EXCLUSIVE DECLARATION
A24: AD-018 | B24: ET-B | C24: P06 | D24: energy and power management | E24: 1 | F24: ET-B-P06 | H24: 0 | I24: EXCLUSIVE DECLARATION
A25: AD-019 | B25: ET-B | C25: P07 | D25: build, repair and release | E25: 1 | F25: ET-B-P07 | H25: 0 | I25: EXCLUSIVE DECLARATION
A26: AD-020 | B26: ET-B | C26: P08 | D26: material supply | E26: 0 | H26: 0 | I26: HELD
A27: AD-021 | B27: ET-B | C27: P09 | D27: workforce and license | E27: 0 | H27: 0 | I27: HELD
A28: AD-022 | B28: ET-B | C28: P10 | D28: logistics and sustainment | E28: 0 | H28: 0 | I28: HELD
A29: AD-023 | B29: ET-B | C29: P11 | D29: receiver integration | E29: 0 | H29: 0 | I29: HELD
A30: AD-024 | B30: ET-B | C30: P12 | D30: regeneration | E30: 0 | H30: 0 | I30: HELD
A31: AD-025 | B31: ET-C | C31: P01 | D31: mission control and planning | E31: 1 | F31: ET-C-P01 | H31: 0 | I31: EXCLUSIVE DECLARATION
A32: AD-026 | B32: ET-C | C32: P02 | D32: state estimation and world model | E32: 1 | F32: ET-C-P02 | H32: 0 | I32: EXCLUSIVE DECLARATION
A33: AD-027 | B33: ET-C | C33: P03 | D33: sensing, time and calibration | E33: 1 | F33: ET-C-P03 | H33: 0 | I33: EXCLUSIVE DECLARATION
A34: AD-028 | B34: ET-C | C34: P04 | D34: actuation and low-level control | E34: 1 | F34: ET-C-P04 | H34: 0 | I34: EXCLUSIVE DECLARATION
A35: AD-029 | B35: ET-C | C35: P05 | D35: safeing and human override | E35: 1 | F35: ET-C-P05 | H35: 0 | I35: EXCLUSIVE DECLARATION
A36: AD-030 | B36: ET-C | C36: P06 | D36: energy and power management | E36: 1 | F36: ET-C-P06 | H36: 0 | I36: EXCLUSIVE DECLARATION
A37: AD-031 | B37: ET-C | C37: P07 | D37: build, repair and release | E37: 1 | F37: ET-C-P07 | H37: 0 | I37: EXCLUSIVE DECLARATION
A38: AD-032 | B38: ET-C | C38: P08 | D38: material supply | E38: 0 | H38: 0 | I38: HELD
A39: AD-033 | B39: ET-C | C39: P09 | D39: workforce and license | E39: 0 | H39: 0 | I39: HELD
A40: AD-034 | B40: ET-C | C40: P10 | D40: logistics and sustainment | E40: 0 | H40: 0 | I40: HELD
A41: AD-035 | B41: ET-C | C41: P11 | D41: receiver integration | E41: 0 | H41: 0 | I41: HELD
A42: AD-036 | B42: ET-C | C42: P12 | D42: regeneration | E42: 0 | H42: 0 | I42: HELD
A43: AD-037 | B43: ET-D | C43: P01 | D43: mission control and planning | E43: 1 | F43: ET-D-P01 | H43: 0 | I43: EXCLUSIVE DECLARATION
...

Sheet Interface Law
A2: Operational interfaces and public seams
A6: Interface | B6: From | C6: To | D6: Exchange record | E6: Shared controller | F6: Observation | G6: State
A7: 1 | B7: MS-ET | C7: MS-CT | D7: accepted entry, cargo custody and delivered formation state | E7: No | F7: SOURCE EMPTY | G7: OPEN
A8: 2 | B8: MS-ET | C8: MS-HC | D8: accepted entry, cargo custody and delivered formation state | E8: No | F8: SOURCE EMPTY | G8: OPEN
A9: 3 | B9: MS-ET | C9: MS-LF | D9: accepted entry, cargo custody and delivered formation state | E9: No | F9: SOURCE EMPTY | G9: OPEN
A10: 4 | B10: MS-ET | C10: MS-HU | D10: accepted entry, cargo custody and delivered formation state | E10: No | F10: SOURCE EMPTY | G10: OPEN
A11: 5 | B11: MS-ET | C11: MS-RT | D11: accepted entry, cargo custody and delivered formation state | E11: No | F11: SOURCE EMPTY | G11: OPEN
A12: 6 | B12: MS-CT | C12: MS-ET | D12: occupied-terrain access, receiver state and lawful handoff | E12: No | F12: SOURCE EMPTY | G12: OPEN
A13: 7 | B13: MS-CT | C13: MS-HC | D13: occupied-terrain access, receiver state and lawful handoff | E13: No | F13: SOURCE EMPTY | G13: OPEN
A14: 8 | B14: MS-CT | C14: MS-LF | D14: occupied-terrain access, receiver state and lawful handoff | E14: No | F14: SOURCE EMPTY | G14: OPEN
A15: 9 | B15: MS-CT | C15: MS-HU | D15: occupied-terrain access, receiver state and lawful handoff | E15: No | F15: SOURCE EMPTY | G15: OPEN
A16: 10 | B16: MS-CT | C16: MS-RT | D16: occupied-terrain access, receiver state and lawful handoff | E16: No | F16: SOURCE EMPTY | G16: OPEN
A17: 11 | B17: MS-HC | C17: MS-ET | D17: safe approach, controlled boundary and consequence state | E17: No | F17: SOURCE EMPTY | G17: OPEN
A18: 12 | B18: MS-HC | C18: MS-CT | D18: safe approach, controlled boundary and consequence state | E18: No | F18: SOURCE EMPTY | G18: OPEN
... A36: 30 | B36: MS-RT | C36: MS-HU | D36: sustainment, return acceptance, repair and renewed configuration | E36: No | F36: SOURCE EMPTY | G36: OPEN
A40: Seam | B40: Public grammar | C40: Candidate execution allowed | D40: State
A41: S01 | B41: service denominator | C41: No | D41: FROZEN
A42: S02 | B42: units and coordinate schema | C42: No | D42: FROZEN
A43: S03 | B43: physical interface envelope | C43: No | D43: FROZEN
A44: S04 | B44: manifest and custody identity | C44: No | D44: FROZEN
A45: S05 | B45: receiver-state vocabulary | C45: No | D45: FROZEN
A46: S06 | B46: calibration interface | C46: No | D46: FROZEN
A47: S07 | B47: evidence and replay schema | C47: No | D47: FROZEN
A48: S08 | B48: rights receipt | C48: No | D48: FROZEN
A49: S09 | B49: stop grammar | C49: No | D49: FROZEN
A50: S10 | B50: time, uncertainty and missingness encoding | C50: No | D50: FROZEN
A51: S11 | B51: residual and regeneration taxonomy | C51: No | D51: FROZEN
A52: S12 | B52: recharter and export package | C52: No | D52: FROZEN

Sheet Public Estate
A2: Public-method estate reservation
A4: The USD 12.0B reservation is nested inside the USD 80.0B enabling account and is not a cost estimate or obligation.
A6: Line | B6: Reservation | C6: Obligated | D6: Remaining | E6: Purpose | F6: State
A7: six method packages | B7: 1.5 | C7: 0 | D7: =B7-C7 -> 1.5 | E7: public question, denominator and amendment law | F7: RESERVED
A8: twenty-four receiver-state lines | B8: 4.2 | C8: 0 | D8: =B8-C8 -> 4.2 | E8: physical receiver and denial state lines | F8: RESERVED
A9: 144 method realizations | B9: 1.8 | C9: 0 | D9: =B9-C9 -> 1.8 | E9: two unlike implementations per method card | F9: RESERVED
A10: 144 calibration chains | B10: 1.44 | C10: 0 | D10: =B10-C10 -> 1.44 | E10: portable, independent calibration | F10: RESERVED
A11: reset and forensics | B11: 1.2 | C11: 0 | D11: =B11-C11 -> 1.2 | E11: invalidity recovery and causal examination | F11: RESERVED
A12: rights and safety fixtures | B12: 0.72 | C12: 0 | D12: =B12-C12 -> 0.72 | E12: nonwaivable stops and civil receipt | F12: RESERVED
A13: replay and cold-run capacity | B13: 0.54 | C13: 0 | D13: =B13-C13 -> 0.54 | E13: exact-event replay and outside reconstruction | F13: RESERVED
A14: uncertainty reserve | B14: 0.6 | C14: 0 | D14: =B14-C14 -> 0.6 | E14: bounded unknown implementation | F14: RESERVED
A16: METHOD TOTAL | B16: =SUM(B7:B14) -> 12 | C16: =SUM(C7:C14) -> 0 | D16: =SUM(D7:D14) -> 12 | E16: nested reservation
A17: ENABLING REMAINDER | B17: =Controls!B15-B16 -> 68 | C17: 0 | D17: =B17-C17 -> 68 | E17: authority outside the method reserve | F17: UNASSIGNED

Sheet Authority
A2: Separated launch authorities
A4: Authority is compositional only through typed artifacts. No actor inherits another actor's warrant.
A6: Authority class | B6: Exclusive power | C6: May issue now | D6: Cannot manufacture | E6: Failure response
A7: Congress and public budget law | B7: create five fiscal accounts and ceilings | C7: tranche constitution | D7: obligation, evidence or readiness | E7: repeal or revise prospectively
A8: Secretary | B8: priority, budget proposal, convening, disclosure and suspension | C8: direction inside warrants | D8: technical fact, acceptance or credit | E8: suspend unsafe work
A9: Mission System Commands | B9: complete-service denominators | C9: A0 questions | D9: technical release or receiver acceptance | E9: amend prospectively
A10: Generating Services | B10: system-native technical release | C10: bounded build standard | D10: mission success or evidence validity | E10: withdraw unsafe release
A11: control registrar | B11: beneficial-control and dependency admission | C11: eligibility record | D11: fiscal option or technical merit | E11: suspend collided control
A12: Capital Board | B12: open, stage, cancel and recharter options | C12: charter call | D12: evidence or capability | E12: cancel and return balance
A13: Root Houses | B13: design and configuration liability for one root | C13: propose artifacts | D13: public warrant or self-acceptance | E13: deliver transfer package
A14: public-method custodian | B14: freeze methods and accept unlike realization boundaries | C14: A0.1 publication | D14: candidate execution | E14: hold disagreeing method
A15: Resilience Proving Service | B15: challenge, control, reconstruction and custody | C15: event protocol | D15: candidate design or disposition | E15: invalidate exact event
A16: Root Disposition Board | B16: BUILD PROOF, RESIZE or KILL | C16: none before evidence | D16: production or readiness | E16: bind adverse evidence
A17: Program Comptroller | B17: pay accepted artifacts and conserve accounts | C17: none before acceptance | D17: favorable outcome | E17: recover or return funds
A18: receivers and readiness authorities | B18: accept service and certify formations | C18: none in this pass | D18: technical fact or production | E18: reject incomplete service

Sheet Failure Rollback
A2: Failure, rollback and retained truth
A4: Rollback removes authority, not history. Valid adverse evidence is never erased or averaged away.
A6: Trigger | B6: Immediate action | C6: State destroyed | D6: State retained | E6: Money rule | F6: Successor allowed
A7: beneficial-control collision | B7: suspend both affected roots | C7: control admission | D7: public denominator and prior valid evidence | E7: unearned option returns | F7: clean control group
A8: provider touches more than two roots | B8: suspend affected dependency | C8: dependency clearance | D8: root identities and public seams | E8: no payment for cure by incumbent | F8: unrelated alternate
A9: method realizations disagree | B9: hold method card | C9: event readiness | D9: frozen question and both results | E9: public reserve only | F9: third unlike realization after warrant
A10: calibration invalid | B10: invalidate exact event | C10: event validity | D10: article and all adverse history | E10: reserve may fund one exact replay | F10: same sealed event
A11: rights or safety stop | B11: halt and secure | C11: event and local release | D11: stop record and evidence | E11: accepted safety artifact payable | F11: fresh rights and safety warrant
A12: adverse balance endpoint | B12: RESIZE | C12: current configuration | D12: valid adverse evidence | E12: accepted BREAK artifact payable | F12: new configuration after re-entry
A13: adverse causal keystone | B13: KILL lineage | C13: root lineage | D13: valid adverse evidence and public rights | E13: accepted BREAK artifact payable | F13: clean replacement root
A14: Root House insolvency | B14: transfer to Continuity Receiver | C14: firm authority | D14: public foreground rights and evidence | E14: unearned option cancels | F14: clean recharter
A15: cost overrun | B15: cancel unearned option | C15: remaining private ceiling | D15: accepted artifacts | E15: failure reserve unavailable | F15: recompete bounded work
A16: operational emergency demand | B16: retain experimental status | C16: none | D16: all test restrictions | E16: no readiness payment | F16: separate operational procurement
A17: favorable demonstration | B17: record result only | C17: none | D17: all remaining gates | E17: payment only for accepted artifact | F17: continue evidence sequence
A18: site loss | B18: activate unlike proving path | C18: local schedule | D18: sealed protocol and custody | E18: estate reserve within ceiling | F18: different site and control chain

Sheet A2 Return
A2: Parent question returned for first physical construction
A4: This pass frames but does not select the A2 portfolio. Reversal of that next choice will alter the first physical estate.
A6: Candidate construction philosophy | B6: First object | C6: Potential advantage | D6: Fatal risk to test | E6: Required decision gates | F6: Authority now
A7: distributed balance-first wave | B7: one limiting-account rig per system | C7: broad early resizing power | D7: may miss causal keystones | E7: all-six coverage; receiver relevance; independent realization | F7: 0
A8: causal-keystone-first wave | B8: one kill experiment per system | C8: retires bad physics early | D8: keystone choice may be wrong | E8: causal specificity; safe failure; cold reconstruction | F8: 0
A9: receiver-state bootstrap | B9: unlike receiver-state realizations | C9: makes public truth physical | D9: estate may precede decisive claim | E9: method maturity; dual lineage; site-loss survival | F9: 0
A10: compound six-system falsification wave | B10: paired balance and keystone endpoints with receiver cells | C10: tests the mission chain and each root | D10: high integration and schedule burden | E10: non-substitution; cancellation; no common execution root | F10: 0
A11: full proving-estate formation | B11: complete multi-station public estate | C11: long-run capacity | D11: locks geography and apparatus too early | E11: portfolio selection; recovery topology; public custody | F11: 0

Sheet Stress Tests
A2: Launch-compact stress worlds
A4: A passing stress result preserves action while preventing one legal or accounting state from manufacturing another.
A6: ID | B6: World | C6: Required response | D6: Forbidden conversion | E6: Expected state | F6: Result
A7: S01 | B7: Congress appropriates full USD 200B | C7: partition five accounts | D7: appropriation to obligation | E7: CONSTITUTED | F7: PASS
A8: S02 | B8: one system requests priority | C8: retain all-six cohort | D8: priority to exclusive program | E8: ISSUE AUTHORIZED | F8: PASS
A9: S03 | B9: one prime offers six integrated roots | C9: reject cross-root control | D9: integration to independence | E9: REJECT | F9: PASS
A10: S04 | B10: public seam implementation offered to all roots | C10: limit seam to grammar | D10: common code to plural truth | E10: REJECT | F10: PASS
A11: S05 | B11: method text is complete | C11: retain realization acceptance at zero | D11: document to physical method | E11: HELD | F11: PASS
A12: S06 | B12: A1 competition publishes | C12: retain award and article at zero | D12: issue to award | E12: ISSUE AUTHORIZED | F12: PASS
A13: S07 | B13: all FRAME artifacts accepted | C13: pay only accepted FRAME work | D13: payment to favorable result | E13: BOUNDED | F13: PASS
A14: S08 | B14: valid adverse MAKE result | C14: retain and pay artifact | D14: failure to nonpayment | E14: BOUNDING EVIDENCE | F14: PASS
A15: S09 | B15: invalid event occurs | C15: one exact-event replay | D15: invalidity to adverse erasure | E15: REPLAY ONLY | F15: PASS
A16: S10 | B16: method lineages disagree | C16: hold method | D16: averaging to truth | E16: HELD | F16: PASS
A17: S11 | B17: provider touches third root | C17: suspend dependency | D17: shared supplier to independence | E17: SUSPEND | F17: PASS
... A24: S18 | B24: later USD 750B boundary cited | C24: require later tranche warrants | D24: cumulative ceiling to present authority | E24: HELD | F24: PASS

Sheet Mutations
A2: Live mutation and restoration log
A4: Each mutation changes one authoritative control, requires at least one terminal audit failure, and restores the baseline before export.
A6: ID | B6: Control cell | C6: Baseline | D6: Mutated | E6: Audit failures | F6: Mutation detected | G6: Baseline restored
A7: M01 | B7: Controls!B7 | C7: 200 | D7: 201 | E7: 1 | F7: YES | G7: YES
A8: M02 | B8: Controls!B8 | C8: 110 | D8: 111 | E8: 2 | F8: YES | G8: YES
A9: M03 | B9: Controls!B12 | C9: 10 | D9: 9 | E9: 2 | F9: YES | G9: YES
A10: M04 | B10: Controls!B13 | C10: 57.4 | D10: 58.4 | E10: 4 | F10: YES | G10: YES
A11: M05 | B11: Controls!B16 | C11: 14.347651 | D11: 15 | E11: 3 | F11: YES | G11: YES
A12: M06 | B12: Controls!B18 | C12: 12 | D12: 13 | E12: 2 | F12: YES | G12: YES
A13: M07 | B13: Controls!B19 | C13: 24 | D13: 23 | E13: 4 | F13: YES | G13: YES
A14: M08 | B14: Controls!B20 | C14: 4 | D14: 5 | E14: 2 | F14: YES | G14: YES
A15: M09 | B15: Controls!B22 | C15: 12 | D15: 11 | E15: 1 | F15: YES | G15: YES
A16: M10 | B16: Controls!B23 | C16: 7 | D16: 8 | E16: 1 | F16: YES | G16: YES
A17: M11 | B17: Controls!B24 | C17: 6 | D17: 5 | E17: 4 | F17: YES | G17: YES
A18: M12 | B18: Controls!B28 | C18: 48 | D18: 47 | E18: 1 | F18: YES | G18: YES
... A20: M14 | B20: Controls!B34 | C20: 0 | D20: 1 | E20: 1 | F20: YES | G20: YES

Sheet Audit
A2: Terminal structural and numerical audit
A4: The audit is terminal. It tests the model but grants no business, technical or physical authority.
A6: Audit | B6: Observed | C6: Expected | D6: Difference | E6: State
A7: portfolio ceiling | B7: =Controls!B7 -> 200 | C7: 200 | D7: =B7-C7 -> 0 | E7: =IF(ABS(D7)<0.000001,"PASS","FAIL") -> PASS
A8: five-account total | B8: =SUM(Controls!B8:B12) -> 200 | C8: 200 | D8: =B8-C8 -> 0 | E8: =IF(ABS(D8)<0.000001,"PASS","FAIL") -> PASS
A9: mission account | B9: =Controls!B8 -> 110 | C9: 110 | D9: =B9-C9 -> 0 | E9: =IF(ABS(D9)<0.000001,"PASS","FAIL") -> PASS
A10: public account subtotal | B10: =SUM(Controls!B9:B11) -> 80 | C10: 80 | D10: =B10-C10 -> 0 | E10: =IF(ABS(D10)<0.000001,"PASS","FAIL") -> PASS
A11: economic-state total | B11: =SUM(Controls!B13:B15)+Controls!B12 -> 200 | C11: 200 | D11: =B11-C11 -> 0 | E11: =IF(ABS(D11)<0.000001,"PASS","FAIL") -> PASS
A12: stageable plus held mission | B12: =SUM(Controls!B13:B14) -> 110 | C12: 110 | D12: =B12-C12 -> 0 | E12: =IF(ABS(D12)<0.000001,"PASS","FAIL") -> PASS
A13: cohort total | B13: =SUM(Controls!B16:B17) -> 27.5 | C13: 27.5 | D13: =B13-C13 -> 0 | E13: =IF(ABS(D13)<0.000001,"PASS","FAIL") -> PASS
A14: outside cohort total | B14: =Finance!B26+Finance!B27 -> 82.5 | C14: 82.5 | D14: =B14-C14 -> 0 | E14: =IF(ABS(D14)<0.000001,"PASS","FAIL") -> PASS
A15: cohort plus outside mission | B15: =SUM(Finance!B24:B27) -> 110 | C15: 110 | D15: =B15-C15 -> 0 | E15: =IF(ABS(D15)<0.000001,"PASS","FAIL") -> PASS
A16: method reserve | B16: =Controls!B18 -> 12 | C16: 12 | D16: =B16-C16 -> 0 | E16: =IF(ABS(D16)<0.000001,"PASS","FAIL") -> PASS
A17: enabling remainder | B17: =Finance!B29 -> 68 | C17: 68 | D17: =B17-C17 -> 0 | E17: =IF(ABS(D17)<0.000001,"PASS","FAIL") -> PASS
A18: public estate total | B18: ='Public Estate'!B16 -> 12 | C18: 12 | D18: =B18-C18 -> -1.7763568e-15 | E18: =IF(ABS(D18)<0.000001,"PASS","FAIL") -> PASS
A19: public estate obligation | B19: ='Public Estate'!C16 -> 0 | C19: 0 | D19: =B19-C19 -> 0 | E19: =IF(ABS(D19)<0.000001,"PASS","FAIL") -> PASS
A20: FRAME share | B20: =Finance!B30/Finance!B24 -> 0.15 | C20: 0.15 | D20: =B20-C20 -> 0 | E20: =IF(ABS(D20)<0.000001,"PASS","FAIL") -> PASS
A21: MAKE share | B21: =Finance!B31/Finance!B24 -> 0.35 | C21: 0.35 | D21: =B21-C21 -> 0 | E21: =IF(ABS(D21)<0.000001,"PASS","FAIL") -> PASS
A22: through MAKE share | B22: =Finance!B32/Finance!B24 -> 0.5 | C22: 0.5 | D22: =B22-C22 -> 0 | E22: =IF(ABS(D22)<0.000001,"PASS","FAIL") -> PASS
A23: post-MAKE share | B23: =Finance!B35/Finance!B24 -> 0.5 | C23: 0.5 | D23: =B23-C23 -> 0 | E23: =IF(ABS(D23)<0.000001,"PASS","FAIL") -> PASS
A24: stageable conserved | B24: =Finance!B32+Finance!B35 -> 14.347651 | C24: 14.347651 | D24: =B24-C24 -> 0 | E24: =IF(ABS(D24)<0.000001,"PASS","FAIL") -> PASS
A25: root count | B25: =COUNTA('Root Register'!B7:B30) -> 24 | C25: 24 | D25: =B25-C25 -> 0 | E25: =IF(ABS(D25)<0.000001,"PASS","FAIL") -> PASS
A26: unique opportunity count | B26: =COUNTA('Root Register'!A7:A30) -> 24 | C26: 24 | D26: =B26-C26 -> 0 | E26: =IF(ABS(D26)<0.000001,"PASS","FAIL") -> PASS
A27: system count | B27: =COUNTA(Finance!A40:A45) -> 6 | C27: 6 | D27: =B27-C27 -> 0 | E27: =IF(ABS(D27)<0.000001,"PASS","FAIL") -> PASS
A28: roots per system total | B28: =SUM(Finance!F40:F45) -> 24 | C28: 24 | D28: =B28-C28 -> 0 | E28: =IF(ABS(D28)<0.000001,"PASS","FAIL") -> PASS
A29: root stageable total | B29: ='Root Register'!H33 -> 14.347651 | C29: 14.347651 | D29: =B29-C29 -> -3.907985e-14 | E29: =IF(ABS(D29)<0.000001,"PASS","FAIL") -> PASS
A30: root held total | B30: ='Root Register'!I33 -> 13.152349 | C30: 13.152349 | D30: =B30-C30 -> 5.3290705e-14 | E30: =IF(ABS(D30)<0.000001,"PASS","FAIL") -> PASS
A31: root awards | B31: ='Root Register'!L33 -> 0 | C31: 0 | D31: =B31-C31 -> 0 | E31: =IF(ABS(D31)<0.000001,"PASS","FAIL") -> PASS
A32: root spend | B32: ='Root Register'!M33 -> 0 | C32: 0 | D32: =B32-C32 -> 0 | E32: =IF(ABS(D32)<0.000001,"PASS","FAIL") -> PASS
A33: field credit | B33: ='Root Register'!N33 -> 0 | C33: 0 | D33: =B33-C33 -> 0 | E33: =IF(ABS(D33)<0.000001,"PASS","FAIL") -> PASS
A34: root credit | B34: ='Root Register'!O33 -> 0 | C34: 0 | D34: =B34-C34 -> 0 | E34: =IF(ABS(D34)<0.000001,"PASS","FAIL") -> PASS
A35: root-field parent assignments | B35: =Controls!B19*Controls!B20 -> 96 | C35: 96 | D35: =B35-C35 -> 0 | E35: =IF(ABS(D35)<0.000001,"PASS","FAIL") -> PASS
A36: selected cohort assignments | B36: =Controls!B21 -> 24 | C36: 24 | D36: =B36-C36 -> 0 | E36: =IF(ABS(D36)<0.000001,"PASS","FAIL") -> PASS
A37: held assignments | B37: =Controls!B19*Controls!B20-Controls!B21 -> 72 | C37: 72 | D37: =B37-C37 -> 0 | E37: =IF(ABS(D37)<0.000001,"PASS","FAIL") -> PASS
A38: parent ancestry cells | B38: =Controls!B19*Controls!B22 -> 288 | C38: 288 | D38: =B38-C38 -> 0 | E38: =IF(ABS(D38)<0.000001,"PASS","FAIL") -> PASS
A39: domain-register rows | B39: =COUNTA('Domain Register'!A7:A294) -> 288 | C39: 288 | D39: =B39-C39 -> 0 | E39: =IF(ABS(D39)<0.000001,"PASS","FAIL") -> PASS
A40: A1 domain control product | B40: =Controls!B19*Controls!B23 -> 168 | C40: 168 | D40: =B40-C40 -> 0 | E40: =IF(ABS(D40)<0.000001,"PASS","FAIL") -> PASS
A41: A1 declarations | B41: =COUNTIF('Domain Register'!I7:I294,"EXCLUSIVE DECLARATION") -> 168 | C41: 168 | D41: =B41-C41 -> 0 | E41: =IF(ABS(D41)<0.000001,"PASS","FAIL") -> PASS
A42: held parent domains | B42: =COUNTIF('Domain Register'!I7:I294,"HELD") -> 120 | C42: 120 | D42: =B42-C42 -> 0 | E42: =IF(ABS(D42)<0.000001,"PASS","FAIL") -> PASS
A43: provider collisions | B43: =SUM('Domain Register'!H7:H294) -> 0 | C43: 0 | D43: =B43-C43 -> 0 | E43: =IF(ABS(D43)<0.000001,"PASS","FAIL") -> PASS
...

Sheet Sources & Limits
A2: Internal sources and model limits
A4: This workbook composes prior internal authorities. It does not claim empirical support for unbuilt systems.
A6: Source | B6: Repository artifact | C6: Role | D6: Access | E6: Limitation
A7: PFP-1 | B7: first physical build portfolio and release sequence | C7: portfolio, accounts and article ladder | D7: internal repository | E7: design authority; no observations
A8: PFP-2 | B8: first-tranche industrial transaction | C8: root market, payment and ancestry | D8: internal repository | E8: no firms, awards or providers
A9: PFP-3 | B9: first six-system requirement cohort | C9: selected fields, vectors and interfaces | D9: internal repository | E9: mechanism hypotheses only
A10: PFP-4 | B10: federated public-method grid and A1 release | C10: methods, realizations, events and seams | D10: internal repository | E10: no accepted physical implementations
A11: PFP-5 | B11: national first physical launch compact and return | C11: integration, reconciliation and return | D11: internal repository | E11: selects no A2 rig, site or formation
A12: Model boundary | B12: this workbook | C12: formula, structural and mutation tests | D12: internal repository | E12: no external sites used
A13: Evidence boundary | B13: all implementation records | C13: identities and observations remain source-empty | D13: not available | E13: zero is deliberate where authority requires zero
A14: Rendering boundary | B14: exterior form | C14: held until physical constitution | D14: not applicable | E14: no renderings in this pass
