Workbook

Sheet Decision
A2: First six-system requirement cohort
A3: Pass 208 | PFP-3 | compound first-reach cohort | Verdict: CLOSE
A6: Decision
A7: Open the first physical requirement wave around one compound service chain: no-pier heavy transfer, building and vertical access, persistent fire control, strategic water-energy carriers, distributed definitive care and field regeneration. Each field keeps eight noncompensatory service coordinates and four unlike root mechanisms. The cohort makes no platform, supplier, site, production or exterior-form selection.
A12: Cohort control | B12: Value | C12: Unit | E12: Physical obligation | F12: Value | G12: Unit
A13: Selected candidate | B13: =COUNTIFS('Cohort Test'!M7:M11,"SELECT") -> 1 | C13: candidate | E13: Entry flow by hour 72 | F13: ='Service Vectors'!F7 -> 5630 | G13: accepted tonnes/day
A14: Selected fields | B14: =COUNTA('Service Vectors'!A7:A12) -> 6 | C14: fields | E14: Civil-terrain population | F14: ='Service Vectors'!F8 -> 105000 | G14: people
A15: Vector coordinates | B15: =COUNTA('Vector Ledger'!A7:A54) -> 48 | C15: conjunctive coordinates | E15: Fire-control edge article | F15: ='Service Vectors'!F9 -> 1 | G15: kilometres
A16: Root-field experiments | B16: =COUNTA('Root Experiments'!A7:A30) -> 24 | C16: opportunities | E16: Lifeline population zone | F16: ='Service Vectors'!F10 -> 2000000 | G16: people
A17: Directed system interfaces | B17: =COUNTA(Interfaces!A7:A36) -> 30 | C17: records | E17: Clinical region | F17: ='Service Vectors'!F11 -> 100000 | G17: people
A18: First-tranche field ceiling | B18: =Finance!D13 -> 27.5 | C18: USD billions | E18: Regeneration stack | F18: ='Service Vectors'!F12 -> 99 | G18: controlled positions
A19: Stageable private option | B19: =Finance!E13 -> 14.347651 | C19: USD billions | E19: Payment phases | F19: =COUNTA(Payment!A7:A10) -> 4 | G19: states
A20: Evidence-held mission option | B20: =Finance!F13 -> 13.152349 | C20: USD billions | E20: Evidence states | F20: =COUNTA('Evidence Sequence'!A7:A14) -> 8 | G20: states
A21: Current awards | B21: =COUNTIFS('Root Experiments'!K7:K30,"<>UNAWARDED") -> 0 | C21: accepted identities | E21: Stress worlds | F21: =COUNTIFS('Stress Tests'!F7:F20,"PASS") -> 14 | G21: worlds
A22: Production credit | B22: =SUM('Root Experiments'!M7:M30) -> 0 | C22: USD billions | E22: Restored mutations | F22: =COUNTIFS(Mutations!G7:G16,"YES") -> 10 | G22: mutations
A24: Candidate comparison
A25: Candidate | B25: Passed gates | C25: Result | D25: Compound route | E25: Inherited vectors | F25: New physics | G25: Mechanism neutral | H25: Non-substitution | I25: Root diversity | J25: Stageable | K25: Adverse evidence | L25: Reason
A26: ='Cohort Test'!A7 -> Compound first reach | B26: ='Cohort Test'!L7 -> 10 | C26: ='Cohort Test'!M7 -> SELECT | D26: ='Cohort Test'!D7 -> 1 | E26: ='Cohort Test'!E7 -> 1 | F26: ='Cohort Test'!F7 -> 1 | G26: ='Cohort Test'!G7 -> 1 | H26: ='Cohort Test'!H7 -> 1 | I26: ='Cohort Test'!I7 -> 1 | J26: ='Cohort Test'!J7 -> 1 | K26: ='Cohort Test'!K7 -> 1 | L26: ='Cohort Test'!N7 -> A single damaged-region thread forces entry, last-building reach, hazard control, lifelines, definitive care and regeneration to close together.
A27: ='Cohort Test'!A8 -> Largest-demand first | B27: ='Cohort Test'!L8 -> 7 | C27: ='Cohort Test'!M8 -> REJECT | D27: ='Cohort Test'!D8 -> 0 | E27: ='Cohort Test'!E8 -> 1 | F27: ='Cohort Test'!F8 -> 0 | G27: ='Cohort Test'!G8 -> 1 | H27: ='Cohort Test'!H8 -> 0 | I27: ='Cohort Test'!I8 -> 1 | J27: ='Cohort Test'!J8 -> 1 | K27: ='Cohort Test'!K8 -> 1 | L27: ='Cohort Test'!N8 -> System-by-system demand ranking does not create one executable mission route and permits high-demand fields to dominate nonfungible failures.
A28: ='Cohort Test'!A9 -> Showcase machines | B28: ='Cohort Test'!L9 -> 8 | C28: ='Cohort Test'!M9 -> REJECT | D28: ='Cohort Test'!D9 -> 1 | E28: ='Cohort Test'!E9 -> 1 | F28: ='Cohort Test'!F9 -> 1 | G28: ='Cohort Test'!G9 -> 0 | H28: ='Cohort Test'!H9 -> 0 | I28: ='Cohort Test'!I9 -> 1 | J28: ='Cohort Test'!J9 -> 1 | K28: ='Cohort Test'!K9 -> 1 | L28: ='Cohort Test'!N9 -> Naming a heavy lifter, fire aircraft, utility ship and hospital ship chooses exteriors before service geometry and encourages platform substitution.
A29: ='Cohort Test'!A10 -> Infrastructure restoration | B29: ='Cohort Test'!L10 -> 9 | C29: ='Cohort Test'!M10 -> REJECT | D29: ='Cohort Test'!D10 -> 1 | E29: ='Cohort Test'!E10 -> 1 | F29: ='Cohort Test'!F10 -> 1 | G29: ='Cohort Test'!G10 -> 1 | H29: ='Cohort Test'!H10 -> 0 | I29: ='Cohort Test'!I10 -> 1 | J29: ='Cohort Test'!J10 -> 1 | K29: ='Cohort Test'!K10 -> 1 | L29: ='Cohort Test'!N10 -> Restored infrastructure can conceal failed clinical episodes, household reach and custody; it is not the complete public effect.
A30: ='Cohort Test'!A11 -> Autonomy and control substrate | B30: ='Cohort Test'!L11 -> 6 | C30: ='Cohort Test'!M11 -> REJECT | D30: ='Cohort Test'!D11 -> 0 | E30: ='Cohort Test'!E11 -> 0 | F30: ='Cohort Test'!F11 -> 1 | G30: ='Cohort Test'!G11 -> 1 | H30: ='Cohort Test'!H11 -> 0 | I30: ='Cohort Test'!I11 -> 0 | J30: ='Cohort Test'!J11 -> 1 | K30: ='Cohort Test'!K11 -> 1 | L30: ='Cohort Test'!N11 -> A common information and autonomy substrate risks becoming one decisive technical root and has no complete six-system public denominator.

Sheet Cohort Test
A2: Cohort selection test
A3: All ten gates must pass. Gate count cannot compensate for a failed public-service or physical-diversity condition.
A6: Candidate | B6: All six systems | C6: One field each | D6: Compound route | E6: Inherited vectors | F6: New physics | G6: Mechanism neutral | H6: Non-substitution | I6: Root diversity | J6: Stageable | K6: Adverse evidence | L6: Passed gates | M6: Result | N6: Governing reason
A7: Compound first reach | B7: 1 | C7: 1 | D7: 1 | E7: 1 | F7: 1 | G7: 1 | H7: 1 | I7: 1 | J7: 1 | K7: 1 | L7: =SUM(B7:K7) -> 10 | M7: =IF(L7=10,"SELECT","REJECT") -> SELECT | N7: A single damaged-region thread forces entry, last-building reach, hazard control, lifelines, definitive care and regeneration to close together.
A8: Largest-demand first | B8: 1 | C8: 1 | D8: 0 | E8: 1 | F8: 0 | G8: 1 | H8: 0 | I8: 1 | J8: 1 | K8: 1 | L8: =SUM(B8:K8) -> 7 | M8: =IF(L8=10,"SELECT","REJECT") -> REJECT | N8: System-by-system demand ranking does not create one executable mission route and permits high-demand fields to dominate nonfungible failures.
A9: Showcase machines | B9: 1 | C9: 1 | D9: 1 | E9: 1 | F9: 1 | G9: 0 | H9: 0 | I9: 1 | J9: 1 | K9: 1 | L9: =SUM(B9:K9) -> 8 | M9: =IF(L9=10,"SELECT","REJECT") -> REJECT | N9: Naming a heavy lifter, fire aircraft, utility ship and hospital ship chooses exteriors before service geometry and encourages platform substitution.
A10: Infrastructure restoration | B10: 1 | C10: 1 | D10: 1 | E10: 1 | F10: 1 | G10: 1 | H10: 0 | I10: 1 | J10: 1 | K10: 1 | L10: =SUM(B10:K10) -> 9 | M10: =IF(L10=10,"SELECT","REJECT") -> REJECT | N10: Restored infrastructure can conceal failed clinical episodes, household reach and custody; it is not the complete public effect.
A11: Autonomy and control substrate | B11: 1 | C11: 1 | D11: 0 | E11: 0 | F11: 1 | G11: 1 | H11: 0 | I11: 0 | J11: 1 | K11: 1 | L11: =SUM(B11:K11) -> 6 | M11: =IF(L11=10,"SELECT","REJECT") -> REJECT | N11: A common information and autonomy substrate risks becoming one decisive technical root and has no complete six-system public denominator.

Sheet Service Vectors
A2: Six public-service vectors
A3: Primary quantities summarize each field. All eight coordinates in the Vector Ledger remain conjunctive and system-native.
A6: Field ID | B6: System | C6: Mission system | D6: Selected problem field | E6: Public-service subject | F6: Primary floor | G6: Unit | H6: First required state | I6: Endurance | J6: Governing denial | K6: Noncompensable completion law | L6: Mechanism selected | M6: Evidence status
A7: ET-F1 | B7: MS-ET | C7: Enter a broken theater | D7: No-pier heavy transfer | E7: complete formation and cargo accepted through dry staging and onward custody | F7: 5630 | G7: accepted tonnes/day | H7: by hour 72 | I7: 30 days | J7: fixed pier absent; largest transfer path lost | K7: discharge, gross lift or cargo motion without accepted custody earns zero | L7: 0 | M7: UNOBSERVED
A8: CT-F2 | B8: MS-CT | C8: Reach occupied civil terrain | D8: Building and vertical access | E8: people and households lawfully reached through occupied, damaged structures | F8: 105000 | G8: people | H8: complete by hour 168 | I8: 7 days | J8: commercial network and one household company unavailable | K8: every household and vertical case closes or remains in an explicit exception queue | L8: 0 | M8: UNOBSERVED
A9: HC-F1 | B9: MS-HC | C9: Control an active hazard | D9: Persistent fire control | E9: protected fire edge held without host utilities and with intervention residual custody | F9: 1 | G9: protected kilometre | H9: first effect 6 h; full edge 18 h | I9: 72 h article; 30 day root | J9: grid, water, communications and drainage denied | K9: no registered crossing; line, water, agent, runoff and responder safety all pass | L9: 0 | M9: UNOBSERVED
A10: LF-F1 | B10: MS-LF | C10: Produce and distribute lifelines | D10: Strategic water-energy carriers | E10: two-million-person water, residual, firm-power and thermal service | F10: 2000000 | G10: people | H10: quarter output at 72 h; full at day 21 | I10: 30 days | J10: largest source, corridor or host utility unavailable | K10: water, power, thermal, storage, residual and point-of-use release all pass | L10: 0 | M10: UNOBSERVED
A11: HU-F1 | B11: MS-HU | C11: Preserve care and human continuity | D11: Distributed definitive care | E11: completed appropriate clinical episodes across ten unlike care lines | F11: 100000 | G11: people | H11: first complete pathway by 24 h; full service day 3 | I11: 30 days | J11: one clinical island and one governing utility family lost | K11: staff, acuity, utilities, transfer and supported discharge close for every episode | L11: 0 | M11: UNOBSERVED
A12: RT-F2 | B12: MS-RT | C12: Sustain, transfer and regenerate | D12: Field regeneration | E12: complete all-six quarter-load stack returned to known configuration | F12: 99 | G12: controlled positions | H12: every critical configuration by 168 h | I12: 30 day supported mission | J12: primary depot and one decisive recovery dependency unavailable | K12: no missing critical class; physical repair without signed recertification earns zero | L12: 0 | M12: UNOBSERVED

Sheet Vector Ledger
A2: Vector Ledger
A3: Forty-eight numeric coordinates govern invention. A field passes only when all eight of its coordinates pass; the workbook does not calculate a compensating score.
A6: Field ID | B6: System | C6: Problem field | D6: Coordinate | E6: Threshold | F6: Unit | G6: Direction | H6: Basis | I6: Observed | J6: Coordinate credit
A7: ET-F1 | B7: MS-ET | C7: No-pier heavy transfer | D7: Complete accepted flow | E7: 5630 | F7: tonnes/day | G7: >= | H7: Hour-72 theater-entry corridor floor | I7: SOURCE EMPTY | J7: 0
A8: ET-F1 | B8: MS-ET | C8: No-pier heavy transfer | D8: Rated no-pier node | E8: 600 | F8: tonnes/hour | G8: >= | H8: Specialized no-pier transfer reference | I8: SOURCE EMPTY | J8: 0
A9: ET-F1 | B9: MS-ET | C9: No-pier heavy transfer | D9: Available transfer fraction | E9: 0.82 | F9: share | G9: >= | H9: Rate is not assumed continuously available | I9: SOURCE EMPTY | J9: 0
A10: ET-F1 | B10: MS-ET | C10: No-pier heavy transfer | D10: Activation ceiling | E10: 48 | F10: hours | G10: <= | H10: No-pier node response reference | I10: SOURCE EMPTY | J10: 0
A11: ET-F1 | B11: MS-ET | C11: No-pier heavy transfer | D11: Sustained service | E11: 30 | F11: days | G11: >= | H11: Complete root endurance | I11: SOURCE EMPTY | J11: 0
A12: ET-F1 | B12: MS-ET | C12: No-pier heavy transfer | D12: Largest path losses survived | E12: 1 | F12: path | G12: >= | H12: Loss cannot end dry-stage flow | I12: SOURCE EMPTY | J12: 0
A13: ET-F1 | B13: MS-ET | C13: No-pier heavy transfer | D13: Manifested custody | E13: 1 | F13: share | G13: equal | H13: Every accepted load retains identity and onward owner | I13: SOURCE EMPTY | J13: 0
A14: ET-F1 | B14: MS-ET | C14: No-pier heavy transfer | D14: Borrowed host handling before release | E14: 0 | F14: systems | G14: equal | H14: Receiver burden cannot create apparent throughput | I14: SOURCE EMPTY | J14: 0
A15: CT-F2 | B15: MS-CT | C15: Building and vertical access | D15: Demand population | E15: 105000 | F15: people | G15: >= | H15: Three HCG-35B workloads | I15: SOURCE EMPTY | J15: 0
A16: CT-F2 | B16: MS-CT | C16: Building and vertical access | D16: Household workload | E16: 42800 | F16: households | G16: >= | H16: Every household disposition remains visible | I16: SOURCE EMPTY | J16: 0
A17: CT-F2 | B17: MS-CT | C17: Building and vertical access | D17: Released local route | E17: 180 | F17: kilometres | G17: >= | H17: Access must connect building to public service | I17: SOURCE EMPTY | J17: 0
A18: CT-F2 | B18: MS-CT | C18: Building and vertical access | D18: Completed household productivity | E18: 2.15 | F18: households/team-hour | G18: >= | H18: Isolation plus one-company-loss target | I18: SOURCE EMPTY | J18: 0
... A54: RT-F2 | B54: MS-RT | C54: Field regeneration | D54: Cold reconstruction paths | E54: 1 | F54: path | G54: >= | H54: Outside team and sovereign configuration release | I54: SOURCE EMPTY | J54: 0

Sheet Root Experiments
A2: Twenty-four selected root-field experiments
A3: Each complete root receives one field assignment in this cohort. The opportunity tests a physical proposition and cannot earn complete-root credit by itself.
A6: Opportunity | B6: Root | C6: System | D6: Problem field | E6: Root thesis | F6: Mechanism hypothesis | G6: Decisive physical proposition | H6: First artifact | I6: Stageable option (USD B) | J6: Held option (USD B) | K6: State | L6: Control identity | M6: Production credit | N6: Kill trigger
A7: C1-01 | B7: ET-A | C7: MS-ET | D7: No-pier heavy transfer | E7: Oceanic mass bridge | F7: Dynamically stabilized offshore exchange with modular high-rate shallow connectors | G7: coupled wave-load cancellation, cargo stabilization and dry handoff | H7: one no-pier transfer lane with serialized mixed cargo | I7: =Finance!E7/4 -> 0.50047462 | J7: =Finance!F7/4 -> 0.61231783 | K7: UNAWARDED | L7: SOURCE EMPTY | M7: 0 | N7: accepted rate or custody fails after loss of the largest connector
A8: C1-02 | B8: ET-B | C8: MS-ET | D8: No-pier heavy transfer | E8: Buoyant air bridge | F8: Buoyant heavy carriers that land or hover-transfer complete loads without a prepared runway | G8: distributed lift, low ground pressure and precision load exchange | H8: one heavy air-to-ground transfer chain | I8: =Finance!E7/4 -> 0.50047462 | J8: =Finance!F7/4 -> 0.61231783 | K8: UNAWARDED | L8: SOURCE EMPTY | M8: 0 | N8: weather, ground reaction or unload state defeats accepted cargo flow
A9: C1-03 | B9: ET-C | C9: MS-ET | D9: No-pier heavy transfer | E9: Austere surface bridge | F9: Machine-laid causeway, beachhead and rapid dry-terminal system | G9: deployable bearing surface, joint control and robotic cargo motion | H9: one austere shore-to-dry-stage corridor | I9: =Finance!E7/4 -> 0.50047462 | J9: =Finance!F7/4 -> 0.61231783 | K9: UNAWARDED | L9: SOURCE EMPTY | M9: 0 | N9: surface damage or route loss breaks the 72-hour service floor
A10: C1-04 | B10: ET-D | C10: MS-ET | D10: No-pier heavy transfer | E10: Amphibious autonomous mesh | F10: Distributed uncrewed amphibious lighters and autonomous cross-dock mesh | G10: swarm routing, shallow-water transition and independent custody | H10: one multi-path amphibious transfer mesh | I10: =Finance!E7/4 -> 0.50047462 | J10: =Finance!F7/4 -> 0.61231783 | K10: UNAWARDED | L10: SOURCE EMPTY | M10: 0 | N10: common control or one node loss removes the service path
A11: C1-05 | B11: CT-A | C11: MS-CT | D11: Building and vertical access | E11: Civic edge grid | F11: Prepared civic edge interfaces with powered refuge and accessible building adapters | G11: safe entry state, local power and standardized human-service connection | H11: one occupied-building access sector | I11: =Finance!E8/4 -> 0.51649348 | J11: =Finance!F8/4 -> 0.6319165 | K11: UNAWARDED | L11: SOURCE EMPTY | M11: 0 | N11: faster entry weakens evidence, consent or egress
A12: C1-06 | B12: CT-B | C12: MS-CT | D12: Building and vertical access | E12: Air-and-skin reach | F12: Exterior-climbing machines and envelope docking for access above failed cores | G12: adhesion, variable facade contact and protected human transfer | H12: one high-rise skin-reach system | I12: =Finance!E8/4 -> 0.51649348 | J12: =Finance!F8/4 -> 0.6319165 | K12: UNAWARDED | L12: SOURCE EMPTY | M12: 0 | N12: wind, facade damage or rescue load defeats safe vertical service
A13: C1-07 | B13: CT-C | C13: MS-CT | D13: Building and vertical access | E13: Building utility spine | F13: Temporary external lift, stair, power and water spine attached without relying on the building core | G13: reversible structural attachment and isolated utility transfer | H13: one building utility and vertical spine | I13: =Finance!E8/4 -> 0.51649348 | J13: =Finance!F8/4 -> 0.6319165 | K13: UNAWARDED | L13: SOURCE EMPTY | M13: 0 | N13: attachment, smoke or common shaft failure exports risk to occupants
A14: C1-08 | B14: CT-D | C14: MS-CT | D14: Building and vertical access | E14: Neighborhood machine swarm | F14: Neighborhood machine swarm with human-assist mobility and distributed sensing | G14: safe multi-robot work in occupied, hot, dark and cluttered interiors | H14: one disconnected neighborhood access mesh | I14: =Finance!E8/4 -> 0.51649348 | J14: =Finance!F8/4 -> 0.6319165 | K14: UNAWARDED | L14: SOURCE EMPTY | M14: 0 | N14: network loss, obstacle distribution or worker injury defeats completion
A15: C1-09 | B15: HC-A | C15: MS-HC | D15: Persistent fire control | E15: Atmospheric control wing | F15: Purpose-built endurance aircraft with precision multi-agent delivery and continuous edge sensing | G15: high-duty thermal structure, adaptive drop field and mixed-airspace control | H15: one persistent atmospheric fire-control element | I15: =Finance!E9/4 -> 0.30722165 | J15: =Finance!F9/4 -> 0.3758778 | K15: UNAWARDED | L15: SOURCE EMPTY | M15: 0 | N15: delivered fluid cannot be attributed to a held edge or safe cycle
A16: C1-10 | B16: HC-B | C16: MS-HC | D16: Persistent fire control | E16: Fluid intervention lattice | F16: Closed-loop high-rate water and agent lattice with deployable towers and recovery | G16: distributed hydraulic pulse shaping and contaminated return control | H16: one fluid-intervention edge sector | I16: =Finance!E9/4 -> 0.30722165 | J16: =Finance!F9/4 -> 0.3758778 | K16: UNAWARDED | L16: SOURCE EMPTY | M16: 0 | N16: host-water loss or runoff custody defeats persistent control
A17: C1-11 | B17: HC-C | C17: MS-HC | D17: Persistent fire control | E17: Autonomous terrain corps | F17: Optionally crewed terrain machines that cut, treat and hold line under plume exposure | G17: autonomous earthwork, tool exchange and thermal survivability | H17: one robotic line-production and hold train | I17: =Finance!E9/4 -> 0.30722165 | J17: =Finance!F9/4 -> 0.3758778 | K17: UNAWARDED | L17: SOURCE EMPTY | M17: 0 | N17: line production outruns hold, rescue or regeneration
A18: C1-12 | B18: HC-D | C18: MS-HC | D18: Persistent fire control | E18: Distributed control field | F18: Distributed sensing and actuator field that changes local heat, ember and fuel conditions | G18: edge prediction, cellular intervention and fault-contained autonomy | H18: one boundary-control field | I18: =Finance!E9/4 -> 0.30722165 | J18: =Finance!F9/4 -> 0.3758778 | K18: UNAWARDED | L18: SOURCE EMPTY | M18: 0 | N18: common sensing or actuation error creates an unobserved crossing
A19: C1-13 | B19: LF-A | C19: MS-LF | D19: Strategic water-energy carriers | E19: Oceanic nuclear utility | F19: Nuclear-thermal coastal utility carrier producing water, firm power and heat rejection | G19: passively safe mobile heat source, seawater conversion and reversible shore export | H19: one quarter-service coastal utility sector | I19: =Finance!E10/4 -> 0.89941282 | J19: =Finance!F10/4 -> 0 | K19: UNAWARDED | L19: SOURCE EMPTY | M19: 0 | N19: source safety, brine custody or shore export cannot close independently
A20: C1-14 | B20: LF-B | C20: MS-LF | D20: Strategic water-energy carriers | E20: Inland geothermal train | F20: Inland geothermal and brackish-water train with rapid wells and modular treatment | G20: rapid subsurface characterization, drilling and isolated heat-water conversion | H20: one quarter-service inland utility train | I20: =Finance!E10/4 -> 0.89941282 | J20: =Finance!F10/4 -> 0 | K20: UNAWARDED | L20: SOURCE EMPTY | M20: 0 | N20: aquifer, well, residual or deployment clock fails
A21: C1-15 | B21: LF-C | C21: MS-LF | D21: Strategic water-energy carriers | E21: Renewable electrochemical swarm | F21: Renewable electrochemical swarm with long-duration storage and selective separation | G21: distributed capture, storage, grid formation and variable-feed treatment | H21: one quarter-service electrochemical utility mesh | I21: =Finance!E10/4 -> 0.89941282 | J21: =Finance!F10/4 -> 0 | K21: UNAWARDED | L21: SOURCE EMPTY | M21: 0 | N21: correlated resource denial exceeds stored service or land boundary
A22: C1-16 | B22: LF-D | C22: MS-LF | D22: Strategic water-energy carriers | E22: Synthetic-fuel service fleet | F22: Synthetic-fuel cogeneration fleet with water treatment and captured residuals | G22: portable fuel synthesis, clean combustion and multi-product thermal integration | H22: one quarter-service fuel utility fleet | I22: =Finance!E10/4 -> 0.89941282 | J22: =Finance!F10/4 -> 0 | K22: UNAWARDED | L22: SOURCE EMPTY | M22: 0 | N22: fuel chain, emissions or residual dependence remains external
A23: C1-17 | B23: HU-A | C23: MS-HU | D23: Distributed definitive care | E23: Clinical continuity campus | F23: Federated configurable clinical islands with deep utilities and specialty support | G23: acuity-specific modular care, infection zoning and loss-tolerant clinical flow | H23: one distributed definitive-care lattice | I23: =Finance!E11/4 -> 0.86071245 | J23: =Finance!F11/4 -> 1.0530596 | K23: UNAWARDED | L23: SOURCE EMPTY | M23: 0 | N23: a care line, utility or discharge path disappears after island loss
A24: C1-18 | B24: HU-B | C24: MS-HU | D24: Distributed definitive care | E24: Neighborhood care fabric | F24: Neighborhood definitive-care fabric that moves staff and high-acuity functions to protected local nodes | G24: portable diagnostics, remote presence and supervised clinical robotics | H24: one neighborhood care network | I24: =Finance!E11/4 -> 0.86071245 | J24: =Finance!F11/4 -> 1.0530596 | K24: UNAWARDED | L24: SOURCE EMPTY | M24: 0 | N24: distributed care delays definitive treatment or fragments custody
A25: C1-19 | B25: HU-C | C25: MS-HU | D25: Distributed definitive care | E25: Mobile care network | F25: Mobile multimode care network that reconfigures while patients remain in the pathway | G25: vehicle-agnostic clinical blocks, continuous monitoring and accepted transfer | H25: one mobile care lattice | I25: =Finance!E11/4 -> 0.86071245 | J25: =Finance!F11/4 -> 1.0530596 | K25: UNAWARDED | L25: SOURCE EMPTY | M25: 0 | N25: motion or reconfiguration interrupts therapy or patient identity
A26: C1-20 | B26: HU-D | C26: MS-HU | D26: Distributed definitive care | E26: Host-building conversion system | F26: Rapid host-building conversion system with isolated clean, controlled and contaminated domains | G26: reversible clinical retrofit, independent utilities and commissioning evidence | H26: one converted definitive-care campus | I26: =Finance!E11/4 -> 0.86071245 | J26: =Finance!F11/4 -> 1.0530596 | K26: UNAWARDED | L26: SOURCE EMPTY | M26: 0 | N26: host structure or utilities remain a hidden single point of failure
A27: C1-21 | B27: RT-A | C27: MS-RT | D27: Field regeneration | E27: Heavy arsenal base | F27: Heavy automated arsenal with modular exchange and protected reference articles | G27: machine inspection, deep repair and configuration-controlled swap | H27: one field recovery and recertification line | I27: =Finance!E12/4 -> 0.50259779 | J27: =Finance!F12/4 -> 0.61491548 | K27: UNAWARDED | L27: SOURCE EMPTY | M27: 0 | N27: physical repair completes without independent configuration release
A28: C1-22 | B28: RT-B | C28: MS-RT | D28: Field regeneration | E28: Distributed microfactory mesh | F28: Distributed microfactory mesh for additive, subtractive and material-specific repair | G28: portable process qualification and serial-level genealogy | H28: one disconnected repair mesh | I28: =Finance!E12/4 -> 0.50259779 | J28: =Finance!F12/4 -> 0.61491548 | K28: UNAWARDED | L28: SOURCE EMPTY | M28: 0 | N28: common feedstock, software or metrology defeats independent return
A29: C1-23 | B29: RT-C | C29: MS-RT | D29: Field regeneration | E29: Exchange and remanufacture network | F29: Exchange and remanufacture network that routes failed modules to unlike recovery paths | G29: condition-based exchange, remanufacture and controlled substitution | H29: one multi-route return-and-replacement network | I29: =Finance!E12/4 -> 0.50259779 | J29: =Finance!F12/4 -> 0.61491548 | K29: UNAWARDED | L29: SOURCE EMPTY | M29: 0 | N29: a missing critical class is hidden by aggregate output
A30: C1-24 | B30: RT-D | C30: MS-RT | D30: Field regeneration | E30: Closed-loop sustainment fleet | F30: Closed-loop sustainment fleet that carries contamination control, repair and mobile metrology | G30: mobile decontamination, residual processing and sovereign recertification | H30: one closed field-regeneration loop | I30: =Finance!E12/4 -> 0.50259779 | J30: =Finance!F12/4 -> 0.61491548 | K30: UNAWARDED | L30: SOURCE EMPTY | M30: 0 | N30: return burdens the receiver or a vendor-only key blocks release

Sheet Interfaces
A2: Interfaces
A3: Thirty directed exchange records bind the six fields into one campaign. An interface may carry service or state; it may not turn one system's output into another system's credit.
A6: # | B6: Provider | C6: Receiver | D6: Exchange obligation | E6: Acceptance boundary | F6: May substitute | G6: Identity | H6: State
A7: 1 | B7: MS-ET | C7: MS-CT | D7: accepted entry, cargo custody and delivered formation state | E7: MS-ET output accepted by MS-CT at the public interface | F7: No | G7: SOURCE EMPTY | H7: OPEN
A8: 2 | B8: MS-ET | C8: MS-HC | D8: accepted entry, cargo custody and delivered formation state | E8: MS-ET output accepted by MS-HC at the public interface | F8: No | G8: SOURCE EMPTY | H8: OPEN
A9: 3 | B9: MS-ET | C9: MS-LF | D9: accepted entry, cargo custody and delivered formation state | E9: MS-ET output accepted by MS-LF at the public interface | F9: No | G9: SOURCE EMPTY | H9: OPEN
A10: 4 | B10: MS-ET | C10: MS-HU | D10: accepted entry, cargo custody and delivered formation state | E10: MS-ET output accepted by MS-HU at the public interface | F10: No | G10: SOURCE EMPTY | H10: OPEN
A11: 5 | B11: MS-ET | C11: MS-RT | D11: accepted entry, cargo custody and delivered formation state | E11: MS-ET output accepted by MS-RT at the public interface | F11: No | G11: SOURCE EMPTY | H11: OPEN
A12: 6 | B12: MS-CT | C12: MS-ET | D12: occupied-terrain access, receiver state and lawful person-service handoff | E12: MS-CT output accepted by MS-ET at the public interface | F12: No | G12: SOURCE EMPTY | H12: OPEN
A13: 7 | B13: MS-CT | C13: MS-HC | D13: occupied-terrain access, receiver state and lawful person-service handoff | E13: MS-CT output accepted by MS-HC at the public interface | F13: No | G13: SOURCE EMPTY | H13: OPEN
A14: 8 | B14: MS-CT | C14: MS-LF | D14: occupied-terrain access, receiver state and lawful person-service handoff | E14: MS-CT output accepted by MS-LF at the public interface | F14: No | G14: SOURCE EMPTY | H14: OPEN
A15: 9 | B15: MS-CT | C15: MS-HU | D15: occupied-terrain access, receiver state and lawful person-service handoff | E15: MS-CT output accepted by MS-HU at the public interface | F15: No | G15: SOURCE EMPTY | H15: OPEN
A16: 10 | B16: MS-CT | C16: MS-RT | D16: occupied-terrain access, receiver state and lawful person-service handoff | E16: MS-CT output accepted by MS-RT at the public interface | F16: No | G16: SOURCE EMPTY | H16: OPEN
A17: 11 | B17: MS-HC | C17: MS-ET | D17: safe approach, controlled boundary and consequence state | E17: MS-HC output accepted by MS-ET at the public interface | F17: No | G17: SOURCE EMPTY | H17: OPEN
A18: 12 | B18: MS-HC | C18: MS-CT | D18: safe approach, controlled boundary and consequence state | E18: MS-HC output accepted by MS-CT at the public interface | F18: No | G18: SOURCE EMPTY | H18: OPEN
... A36: 30 | B36: MS-RT | C36: MS-HU | D36: sustainment, return acceptance, repair and renewed configuration | E36: MS-RT output accepted by MS-HU at the public interface | F36: No | G36: SOURCE EMPTY | H36: OPEN

Sheet Finance
A2: Selected-cohort financial boundary
A3: One of four problem fields in every mission system enters the cohort. Authority is a ceiling, not an award, asset value or capability claim.
A6: System | B6: Mission system | C6: Full field program (USD B) | D6: T1 field ceiling (USD B) | E6: Stageable option (USD B) | F6: Evidence-held (USD B) | G6: Share of stageable cohort | H6: Root opportunities | I6: Awarded (USD B) | J6: Production credit | L6: Mission system | M6: Stageable option (USD B)
A7: MS-ET | B7: Enter a broken theater | C7: 22.255849 | D7: =C7*20% -> 4.4511698 | E7: =D7*(43/4)/($D$13-$D$10) -> 2.0018985 | F7: =D7-E7 -> 2.4492713 | G7: =E7/$E$13 -> 0.13952796 | H7: 4 | I7: 0 | J7: 0 | L7: =B7 -> Enter a broken theater | M7: =E7 -> 2.0018985
A8: MS-CT | B8: Reach occupied civil terrain | C8: 22.9682 | D8: =C8*20% -> 4.5936399 | E8: =D8*(43/4)/($D$13-$D$10) -> 2.0659739 | F8: =D8-E8 -> 2.527666 | G8: =E8/$E$13 -> 0.14399388 | H8: 4 | I8: 0 | J8: 0 | L8: =B8 -> Reach occupied civil terrain | M8: =E8 -> 2.0659739
A9: MS-HC | B9: Control an active hazard | C9: 13.661989 | D9: =C9*20% -> 2.7323978 | E9: =D9*(43/4)/($D$13-$D$10) -> 1.2288866 | F9: =D9-E9 -> 1.5035112 | G9: =E9/$E$13 -> 0.085650717 | H9: 4 | I9: 0 | J9: 0 | L9: =B9 -> Control an active hazard | M9: =E9 -> 1.2288866
A10: MS-LF | B10: Produce and distribute lifelines | C10: 17.988256 | D10: =C10*20% -> 3.5976513 | E10: =D10 -> 3.5976513 | F10: =D10-E10 -> 0 | G10: =E10/$E$13 -> 0.25074845 | H10: 4 | I10: 0 | J10: 0 | L10: =B10 -> Produce and distribute lifelines | M10: =E10 -> 3.5976513
A11: MS-HU | B11: Preserve care and human continuity | C11: 38.27544 | D11: =C11*20% -> 7.6550881 | E11: =D11*(43/4)/($D$13-$D$10) -> 3.4428498 | F11: =D11-E11 -> 4.2122383 | G11: =E11/$E$13 -> 0.23995912 | H11: 4 | I11: 0 | J11: 0 | L11: =B11 -> Preserve care and human continuity | M11: =E11 -> 3.4428498
A12: MS-RT | B12: Sustain, transfer and regenerate | C12: 22.350266 | D12: =C12*20% -> 4.4700531 | E12: =D12*(43/4)/($D$13-$D$10) -> 2.0103912 | F12: =D12-E12 -> 2.4596619 | G12: =E12/$E$13 -> 0.14011988 | H12: 4 | I12: 0 | J12: 0 | L12: =B12 -> Sustain, transfer and regenerate | M12: =E12 -> 2.0103912
A13: Total | B13: Six systems; one field each | C13: =SUM(C7:C12) -> 137.5 | D13: =SUM(D7:D12) -> 27.5 | E13: =SUM(E7:E12) -> 14.347651 | F13: =SUM(F7:F12) -> 13.152349 | G13: =SUM(G7:G12) -> 1 | H13: =SUM(H7:H12) -> 24 | I13: =SUM(I7:I12) -> 0 | J13: =SUM(J7:J12) -> 0

Sheet Payment
A2: Artifact payment for the selected cohort
A3: Payment follows accepted evidence-bearing work. Valid adverse evidence is payable; no payment state creates root or production credit.
A6: State | B6: Share | C6: Cohort ceiling (USD B) | D6: Cumulative paid (USD B) | E6: Unexercised balance (USD B) | F6: Earned artifact | G6: Adverse result paid | H6: Root credit | I6: Production credit | J6: Current acceptance
A7: FRAME | B7: 0.15 | C7: =B7*Finance!$E$13 -> 2.1521477 | D7: =C7 -> 2.1521477 | E7: =Finance!$E$13-D7 -> 12.195504 | F7: public vector, field charter and ancestry plan | G7: Yes | H7: 0 | I7: 0 | J7: NONE
A8: MAKE | B8: 0.35 | C8: =B8*Finance!$E$13 -> 5.0216779 | D8: =D7+C8 -> 7.1738256 | E8: =Finance!$E$13-D8 -> 7.1738256 | F8: measured mechanism article and controlled bill | G8: Yes | H8: 0 | I8: 0 | J8: NONE
A9: BREAK | B9: 0.35 | C9: =B9*Finance!$E$13 -> 5.0216779 | D9: =D8+C9 -> 12.195504 | E9: =Finance!$E$13-D9 -> 2.1521477 | F9: challenge, matched control and valid evidence packet | G9: Yes | H9: 0 | I9: 0 | J9: NONE
A10: TRANSFER | B10: 0.15 | C10: =B10*Finance!$E$13 -> 2.1521477 | D10: =D9+C10 -> 14.347651 | E10: =Finance!$E$13-D10 -> 0 | F10: cold-build package, public custody and disposition | G10: Yes | H10: 0 | I10: 0 | J10: NONE
A11: Total | B11: =SUM(B7:B10) -> 1 | C11: =SUM(C7:C10) -> 14.347651 | F11: Complete selected-field option ladder | G11: Yes | H11: 0 | I11: 0 | J11: NONE

Sheet Evidence Sequence
A2: Evidence Sequence
A3: The cohort advances through the inherited eight-state ladder. Only accepted artifacts change state; time, cost, urgency and visibility do not.
A6: State | B6: Physical meaning | C6: Required artifact | D6: Decision authority | E6: Field credit | F6: Root credit | G6: Production credit | H6: Current count
A7: A0 | B7: public method and interface | C7: frozen vector, test method, rights and receiver boundary | D7: Mission System Command + public standards | E7: 0 | F7: 0 | G7: 0 | H7: 0
A8: A1 | B8: mechanism article | C8: serialized physical proposition and controlled bill | D8: Generating Service | E8: 0 | F8: 0 | G8: 0 | H8: 0
A9: A2 | B9: endpoint rig | C9: matched challenge, control and independent packet | D9: Resilience Proving Service | E9: 0 | F9: 0 | G9: 0 | H9: 0
A10: A3 | B10: route-complete proof unit | C10: field mechanism inside every required route and stage | D10: Root Disposition Board | E10: 1 | F10: 0 | G10: 0 | H10: 0
A11: A4 | B11: reproduced complete root | C11: outside team cold-builds and repeats the complete root | D11: Independent release | E11: 1 | F11: 1 | G11: 0 | H11: 0
A12: A5 | B12: rotating all-six stack | C12: one accepted root per system closes the joint mission | D12: Joint mission acceptance | E12: 1 | F12: 1 | G12: 0 | H12: 0
A13: A6 | B13: production-representative increment | C13: cold lot survives production and configuration variation | D13: Production release authorities | E13: 1 | F13: 1 | G13: 0 | H13: 0
A14: A7 | B14: field formation or regenerated serial | C14: crew, receiver, sustainment and readiness all accepted | D14: Force generation and employment warrants | E14: 1 | F14: 1 | G14: 1 | H14: 0

Sheet Failure Logic
A2: Failure Logic
A3: The cohort is designed to learn from valid failure while refusing outcome-aware repetition and cross-field substitution.
A6: Trigger | B6: Disposition | C6: Paid work | D6: Held authority | E6: Required successor | F6: Evidence treatment | G6: May change vector | H6: Root credit | I6: Production credit
A7: Coordinate misses threshold | B7: RESIZE or KILL | C7: accepted valid work | D7: remains in owning system | E7: new physical proposition | F7: adverse result permanent | G7: No | H7: 0 | I7: 0
A8: Safety or rights failure | B8: STOP | C8: accepted safe work only | D8: remains held | E8: independent remedy and new event | F8: stop and consequence preserved | G8: No | H8: 0 | I8: 0
A9: Invalid event | B9: HOLD | C9: no evidentiary milestone | D9: one exact-event replay only | E9: same frozen event | F9: invalid record replaced, not erased | G9: No | H9: 0 | I9: 0
A10: Outcome-aware repeat | B10: DENY | C10: none | D10: no reserve draw | E10: none | F10: valid result remains binding | G10: No | H10: 0 | I10: 0
A11: One field succeeds inside incomplete root | B11: HOLD FIELD | C11: accepted artifact | D11: later root option held | E11: complete all-route root | F11: field result remains local | G11: No | H11: 0 | I11: 0
A12: Five systems close; one does not | B12: HOLD ALL-SIX | C12: accepted artifacts | D12: production stays zero | E12: sixth accepted root | F12: no weighted compensation | G12: No | H12: 0 | I12: 0
A13: Shared decisive dependency appears | B13: SUSPEND | C13: unrelated accepted work | D13: option frozen | E13: clean ancestry or new root | F13: collision disclosed | G13: No | H13: 0 | I13: 0
A14: Receiver burden creates result | B14: REJECT CREDIT | C14: valid observations retained | D14: option held | E14: candidate-owned missing function | F14: externalized service recorded | G14: No | H14: 0 | I14: 0
A15: Cold reconstruction fails | B15: REMOVE ROOT CLAIM | C15: accepted evidence | D15: later option held | E15: outside build path | F15: failure remains public | G15: No | H15: 0 | I15: 0
A16: All coordinates pass | B16: BUILD PROOF | C16: accepted work | D16: next option remains gated | E16: route-complete proof unit | F16: favorable evidence bounded | G16: No | H16: 0 | I16: 0

Sheet Authority
A2: Authority
A3: No one actor may define the vector, build the mechanism, create the denial, judge the result, pay itself and infer production.
A6: Authority | B6: Owns | C6: Cannot infer | D6: Failure if combined | E6: Output | F6: Current identity | G6: Credit
A7: Mission System Commands | B7: public service vectors and complete-root obligations | C7: mechanism or favorable result | D7: requirement owner becomes designer | E7: frozen vector | F7: SOURCE EMPTY | G7: 0
A8: Generating Services | B8: technical method, safety basis and lifecycle release | C8: public effect | D8: professional release becomes mission acceptance | E8: technical release | F8: SOURCE EMPTY | G8: 0
A9: Root Houses | B9: one root design and its four field mechanisms | C9: public warrant or evidence | D9: builder marks its own work | E9: controlled article | F9: SOURCE EMPTY | G9: 0
A10: Resilience Proving Service | B10: challenge, controls, custody and replay | C10: root disposition | D10: test owner becomes program sponsor | E10: valid packet | F10: SOURCE EMPTY | G10: 0
A11: Protection Inspectorate | B11: rights and safety stop | C11: technical success | D11: safety becomes score | E11: stop record | F11: SOURCE EMPTY | G11: 0
A12: Root Disposition Board | B12: BUILD PROOF, RESIZE or KILL | C12: production | D12: evidence judgment becomes scale authority | E12: reasoned disposition | F12: SOURCE EMPTY | G12: 0
A13: Capital Board | B13: open and cancel options | C13: technical validity | D13: money becomes evidence | E13: option warrant | F13: SOURCE EMPTY | G13: 0
A14: Program Comptroller | B14: pay accepted artifacts and return balances | C14: favorable outcome | D14: payment becomes program advocacy | E14: payment ledger | F14: SOURCE EMPTY | G14: 0
A15: Continuity Receiver | B15: public foreground and clean recharter | C15: readiness | D15: possession becomes capability | E15: custody record | F15: SOURCE EMPTY | G15: 0
A16: Joint mission acceptance | B16: all-six service release | C16: individual mechanism superiority | D16: integration hides system failure | E16: mission record | F16: SOURCE EMPTY | G16: 0

Sheet Technology Agenda
A2: Technology Agenda
A3: The cohort deliberately asks for capabilities that may require new science, manufacturing and professions. Each line remains a public research question, not a preferred vendor stack.
A6: Field | B6: Technology thrust | C6: Required advance | D6: Why present technology is insufficient | E6: Public seam | F6: Current maturity
A7: No-pier heavy transfer | B7: dynamic heavy-load exchange | C7: stabilize and transfer serialized heavy loads across wave, surf and damaged shore states | D7: commercial ports and military lighterage do not supply sustained civil custody through multiple shallow receivers | E7: load geometry, custody and receiver acceptance | F7: UNPROVED
A8: No-pier heavy transfer | B8: autonomous dry-stage logistics | C8: inspect, route and release mixed cargo without central networks or host handling | D8: nominal discharge rate hides customs, safety, cross-dock and onward-state bottlenecks | E8: manifest, hazard class and release state | F8: UNPROVED
A9: Building and vertical access | B9: reversible exterior reach | C9: attach safe lift, refuge, power and access paths to occupied damaged structures | D9: ordinary elevators and rescue equipment assume intact cores, short duration or sparse demand | E9: building state, safe load and rights receipt | F9: UNPROVED
A10: Building and vertical access | B10: occupied-space robotics | C10: work around people, heat, smoke, debris and accessibility needs under network loss | D10: industrial robots do not carry civil authority, safe human interaction or building-to-service closure | E10: task state, person custody and stop authority | F10: UNPROVED
A11: Persistent fire control | B11: high-duty precision delivery | C11: operate continuously with instrumented multi-agent fields and thermal/load-cycle resilience | D11: converted aircraft optimize transport heritage rather than persistent control geometry and rapid regeneration | E11: objective, placement and held-edge evidence | F11: UNPROVED
A12: Persistent fire control | B12: closed intervention metabolism | C12: produce water or agent, place it and recover contaminated runoff as one system | D12: suppression output often externalizes water, chemistry, smoke and environmental burden | E12: mass, heat, agent and residual ledgers | F12: UNPROVED
A13: Strategic water-energy carriers | B13: transportable firm heat source | C13: deliver passively safe, islandable heat and electricity for water and thermal service | D13: stationary grids and conventional generators do not close fuel, heat rejection, black start and residuals at disaster scale | E13: electrical, thermal and safety interface | F13: UNPROVED
A14: Strategic water-energy carriers | B14: robotic source-to-user corridors | C14: lay, join, test and repair high-flow pipe and conductors through damaged routes | D14: temporary utilities lack the industrial rate, sanitary proof and route autonomy demanded by the clock | E14: quality, pressure, voltage and route state | F14: UNPROVED
A15: Distributed definitive care | B15: reconfigurable acuity environments | C15: change clinical function while preserving air, infection, utilities, workflow and licensure evidence | D15: beds and modular rooms do not prove appropriate staffed episodes or safe reconfiguration | E15: patient state, care line and commissioning | F15: UNPROVED
A16: Distributed definitive care | B16: local clinical production | C16: make oxygen, sterile goods, diagnostics and selected therapies with protected quality | D16: health logistics can fail even when a care shell and clinicians arrive | E16: lot identity, quality release and waste custody | F16: UNPROVED
A17: Field regeneration | B17: autonomous damage-state reconstruction | C17: detect hidden damage and generate bounded repair decisions from distributed evidence | D17: maintenance speed without configuration truth can return an unsafe article | E17: serial state, limits and damage disposition | F17: UNPROVED
A18: Field regeneration | B18: portable sovereign recertification | C18: carry metrology, signing, process qualification and cold reconstruction into a denied field | D18: vendor-only keys, calibration and factories make physical repair operationally useless | E18: configuration, calibration and public signing | F18: UNPROVED

Sheet Stress Tests
A2: Stress Tests
A3: Each world tests whether the cohort preserves service meaning, root diversity and the production barrier when an attractive shortcut appears.
A6: # | B6: Stress world | C6: Required response | D6: Forbidden inference | E6: Held authority (USD B) | F6: Result | G6: Reason
A7: 1 | B7: No-pier system discharges fast but dry staging cannot accept cargo | C7: deny throughput credit | D7: gross discharge equals service | E7: 13.152349 | F7: PASS | G7: accepted onward custody is the numerator
A8: 2 | B8: Building machines raise speed but obstruct egress | C8: stop and preserve consequence | D8: productivity compensates safety | E8: 13.152349 | F8: PASS | G8: rights and safety are conjunctive
A9: 3 | B9: Fire aircraft deliver agent but edge crosses | C9: record adverse result | D9: gallons or sorties equal control | E9: 13.152349 | F9: PASS | G9: registered crossing defeats the field
A10: 4 | B10: Utility carrier supplies power but cannot retain brine | C10: deny service credit | D10: megawatts compensate residual failure | E10: 13.152349 | F10: PASS | G10: all lifeline coordinates must close
A11: 5 | B11: Clinical islands add beds without specialty staff | C11: deny episode credit | D11: nominal beds equal care | E11: 13.152349 | F11: PASS | G11: care line, staff and pathway remain specific
A12: 6 | B12: Repair completes but signer and calibration are unavailable | C12: deny return-to-service | D12: physical repair equals regenerated configuration | E12: 13.152349 | F12: PASS | G12: sovereign recertification remains required
A13: 7 | B13: One field article passes inside an incomplete root | C13: hold root credit | D13: field success equals complete root | E13: 13.152349 | F13: PASS | G13: four fields and every route remain required
A14: 8 | B14: Five systems close their vectors | C14: hold all production | D14: near-complete stack equals joint mission | E14: 150 | F14: PASS | G14: all-six barrier is conjunctive
A15: 9 | B15: One control stack operates mechanisms across several roots | C15: suspend affected claims | D15: open interface equals shared decisive root | E15: 13.152349 | F15: PASS | G15: public seams require unlike implementations
A16: 10 | B16: A prototype is requested during catastrophe | C16: keep it outside ready force | D16: urgency equals operational release | E16: 150 | F16: PASS | G16: article and readiness states remain separate
A17: 11 | B17: Candidate asks to change vector after failure | C17: deny change in the event | D17: observed result may redefine need | E17: 10 | F17: PASS | G17: denominator freezes before MAKE
A18: 12 | B18: Valid adverse event threatens schedule | C18: pay and retain it | D18: failure should be unpaid or repeated | E18: 10 | F18: PASS | G18: valid failure is a purchased output
... A20: 14 | B20: Exterior concept is proposed before route geometry closes | C20: hold rendering | D20: visual plausibility equals requirement maturity | E20: 0 | F20: PASS | G20: rendering remains outside the cohort

Sheet Mutations
A2: Mutations
A3: Deliberate invalid states must fail and restore without creating an award, root claim or production credit.
A6: # | B6: Mutation | C6: Broken law | D6: Expected | E6: Observed | F6: Restoration | G6: Restored | H6: Production credit
A7: 1 | B7: Replace six vectors with tonnes delivered | C7: nonfungible service | D7: FAIL | E7: FAIL | F7: restore six system-native vectors | G7: YES | H7: 0
A8: 2 | B8: Score vector coordinates with weighted average | C8: conjunctive completion | D8: FAIL | E8: FAIL | F8: require all eight coordinates | G8: YES | H8: 0
A9: 3 | B9: Call the selected field a complete root | C9: root completeness | D9: FAIL | E9: FAIL | F9: retain other three root fields | G9: YES | H9: 0
A10: 4 | B10: Choose nuclear ship, fire aircraft and hospital hull now | C10: mechanism neutrality | D10: FAIL | E10: FAIL | F10: restore physics-level rivals | G10: YES | H10: 0
A11: 5 | B11: Move held option to a visible winner | C11: account conservation | D11: FAIL | E11: FAIL | F11: return to owning system | G11: YES | H11: 0
A12: 6 | B12: Let receiver labor create candidate throughput | C12: receiver burden | D12: FAIL | E12: FAIL | F12: charge all required handling to candidate | G12: YES | H12: 0
A13: 7 | B13: Share one decisive autonomy stack across roots | C13: root independence | D13: FAIL | E13: FAIL | F13: require unrelated implementations | G13: YES | H13: 0
A14: 8 | B14: Repeat a valid adverse event with a new seed | C14: permanent evidence | D14: FAIL | E14: FAIL | F14: retain the frozen event result | G14: YES | H14: 0
A15: 9 | B15: Count A1 mechanism article as production | C15: state separation | D15: FAIL | E15: FAIL | F15: restore zero production credit | G15: YES | H15: 0
A16: 10 | B16: Render exterior before complete geometry | C16: rendering gate | D16: FAIL | E16: FAIL | F16: retain rendering hold | G16: YES | H16: 0

Sheet Audit
A2: Terminal audit
A3: Checks observe the cohort and do not feed requirements, options, evidence, dispositions or release.
A6: # | B6: Audit | C6: Actual | D6: Required | E6: Status | F6: Interpretation
A7: 1 | B7: Selected candidate gates | C7: ='Cohort Test'!L7 -> 10 | D7: 10 | E7: =IF(ABS(C7-D7)<0.001,"PASS","FAIL") -> PASS | F7: All hard gates
A8: 2 | B8: Selected candidate count | C8: =COUNTIFS('Cohort Test'!M7:M11,"SELECT") -> 1 | D8: 1 | E8: =IF(ABS(C8-D8)<0.001,"PASS","FAIL") -> PASS | F8: Exactly one selected
A9: 3 | B9: Mission systems | C9: =COUNTA('Service Vectors'!B7:B12) -> 6 | D9: 6 | E9: =IF(ABS(C9-D9)<0.001,"PASS","FAIL") -> PASS | F9: One field per system
A10: 4 | B10: Selected fields | C10: =COUNTA('Service Vectors'!A7:A12) -> 6 | D10: 6 | E10: =IF(ABS(C10-D10)<0.001,"PASS","FAIL") -> PASS | F10: Six fields
A11: 5 | B11: Mechanisms selected | C11: =SUM('Service Vectors'!L7:L12) -> 0 | D11: 0 | E11: =IF(ABS(C11-D11)<0.001,"PASS","FAIL") -> PASS | F11: No platform or mechanism selection
A12: 6 | B12: Vector coordinates | C12: =COUNTA('Vector Ledger'!A7:A54) -> 48 | D12: 48 | E12: =IF(ABS(C12-D12)<0.001,"PASS","FAIL") -> PASS | F12: Eight per field
A13: 7 | B13: Vector observed records | C13: =COUNTIFS('Vector Ledger'!I7:I54,"<>SOURCE EMPTY") -> 0 | D13: 0 | E13: =IF(ABS(C13-D13)<0.001,"PASS","FAIL") -> PASS | F13: No physical observation
A14: 8 | B14: Vector credit | C14: =SUM('Vector Ledger'!J7:J54) -> 0 | D14: 0 | E14: =IF(ABS(C14-D14)<0.001,"PASS","FAIL") -> PASS | F14: No paper performance
A15: 9 | B15: Root-field experiments | C15: =COUNTA('Root Experiments'!A7:A30) -> 24 | D15: 24 | E15: =IF(ABS(C15-D15)<0.001,"PASS","FAIL") -> PASS | F15: Four roots per selected field
A16: 10 | B16: Root identities | C16: =COUNTA('Root Experiments'!B7:B30) -> 24 | D16: 24 | E16: =IF(ABS(C16-D16)<0.001,"PASS","FAIL") -> PASS | F16: Twenty-four root opportunities
A17: 11 | B17: Current awards | C17: =COUNTIFS('Root Experiments'!K7:K30,"<>UNAWARDED") -> 0 | D17: 0 | E17: =IF(ABS(C17-D17)<0.001,"PASS","FAIL") -> PASS | F17: No award
A18: 12 | B18: Accepted control identities | C18: =COUNTIFS('Root Experiments'!L7:L30,"<>SOURCE EMPTY") -> 0 | D18: 0 | E18: =IF(ABS(C18-D18)<0.001,"PASS","FAIL") -> PASS | F18: Source empty
A19: 13 | B19: Root production credit | C19: =SUM('Root Experiments'!M7:M30) -> 0 | D19: 0 | E19: =IF(ABS(C19-D19)<0.001,"PASS","FAIL") -> PASS | F19: No production
A20: 14 | B20: Directed interfaces | C20: =COUNTA(Interfaces!A7:A36) -> 30 | D20: 30 | E20: =IF(ABS(C20-D20)<0.001,"PASS","FAIL") -> PASS | F20: Every ordered system pair
A21: 15 | B21: Accepted interfaces | C21: =COUNTIFS(Interfaces!G7:G36,"<>SOURCE EMPTY") -> 0 | D21: 0 | E21: =IF(ABS(C21-D21)<0.001,"PASS","FAIL") -> PASS | F21: No interface identity
A22: 16 | B22: Substitutive interfaces | C22: =COUNTIFS(Interfaces!F7:F36,"Yes") -> 0 | D22: 0 | E22: =IF(ABS(C22-D22)<0.001,"PASS","FAIL") -> PASS | F22: No cross-system credit
A23: 17 | B23: Full selected-field program | C23: =Finance!C13 -> 137.5 | D23: 137.5 | E23: =IF(ABS(C23-D23)<0.001,"PASS","FAIL") -> PASS | F23: One quarter of USD 550B
A24: 18 | B24: T1 selected-field ceiling | C24: =Finance!D13 -> 27.5 | D24: 27.5 | E24: =IF(ABS(C24-D24)<0.001,"PASS","FAIL") -> PASS | F24: One quarter of USD 110B
A25: 19 | B25: Stageable cohort options | C25: =Finance!E13 -> 14.347651 | D25: 14.347651 | E25: =IF(ABS(C25-D25)<0.001,"PASS","FAIL") -> PASS | F25: One quarter of active option market
A26: 20 | B26: Held cohort options | C26: =Finance!F13 -> 13.152349 | D26: 13.152349 | E26: =IF(ABS(C26-D26)<0.001,"PASS","FAIL") -> PASS | F26: Evidence-held mission authority
A27: 21 | B27: Finance shares | C27: =Finance!G13 -> 1 | D27: 1 | E27: =IF(ABS(C27-D27)<0.001,"PASS","FAIL") -> PASS | F27: Stageable allocation conserved
A28: 22 | B28: Root opportunities in finance | C28: =Finance!H13 -> 24 | D28: 24 | E28: =IF(ABS(C28-D28)<0.001,"PASS","FAIL") -> PASS | F28: Matches experiments
A29: 23 | B29: Awarded finance | C29: =Finance!I13 -> 0 | D29: 0 | E29: =IF(ABS(C29-D29)<0.001,"PASS","FAIL") -> PASS | F29: No award
A30: 24 | B30: Finance production credit | C30: =Finance!J13 -> 0 | D30: 0 | E30: =IF(ABS(C30-D30)<0.001,"PASS","FAIL") -> PASS | F30: No production
A31: 25 | B31: Decision T1 link | C31: =Decision!B18 -> 27.5 | D31: 27.5 | E31: =IF(ABS(C31-D31)<0.001,"PASS","FAIL") -> PASS | F31: Summary links to T1 field ceiling
A32: 26 | B32: Decision stageable link | C32: =Decision!B19 -> 14.347651 | D32: 14.347651 | E32: =IF(ABS(C32-D32)<0.001,"PASS","FAIL") -> PASS | F32: Summary links to stageable option
A33: 27 | B33: Decision held link | C33: =Decision!B20 -> 13.152349 | D33: 13.152349 | E33: =IF(ABS(C33-D33)<0.001,"PASS","FAIL") -> PASS | F33: Summary links to held option
A34: 28 | B34: Decision award link | C34: =Decision!B21 -> 0 | D34: 0 | E34: =IF(ABS(C34-D34)<0.001,"PASS","FAIL") -> PASS | F34: Summary reports zero awards
A35: 29 | B35: Root stageable trace | C35: =SUM('Root Experiments'!I7:I30) -> 14.347651 | D35: 14.347651 | E35: =IF(ABS(C35-D35)<0.001,"PASS","FAIL") -> PASS | F35: Matches finance
A36: 30 | B36: Root held trace | C36: =SUM('Root Experiments'!J7:J30) -> 13.152349 | D36: 13.152349 | E36: =IF(ABS(C36-D36)<0.001,"PASS","FAIL") -> PASS | F36: Matches finance
A37: 31 | B37: Payment phases | C37: =COUNTA(Payment!A7:A10) -> 4 | D37: 4 | E37: =IF(ABS(C37-D37)<0.001,"PASS","FAIL") -> PASS | F37: FRAME through TRANSFER
A38: 32 | B38: Payment shares | C38: =Payment!B11 -> 1 | D38: 1 | E38: =IF(ABS(C38-D38)<0.001,"PASS","FAIL") -> PASS | F38: Complete option ladder
A39: 33 | B39: Payment ceiling | C39: =Payment!C11 -> 14.347651 | D39: 14.347651 | E39: =IF(ABS(C39-D39)<0.001,"PASS","FAIL") -> PASS | F39: Matches stageable cohort
A40: 34 | B40: Paid through BREAK | C40: =Payment!D9 -> 12.195504 | D40: 12.195504 | E40: =IF(ABS(C40-D40)<0.001,"PASS","FAIL") -> PASS | F40: Eighty-five percent
A41: 35 | B41: Unexercised after BREAK | C41: =Payment!E9 -> 2.1521477 | D41: 2.1521477 | E41: =IF(ABS(C41-D41)<0.001,"PASS","FAIL") -> PASS | F41: Fifteen percent
A42: 36 | B42: Payment root credit | C42: =SUM(Payment!H7:H10) -> 0 | D42: 0 | E42: =IF(ABS(C42-D42)<0.001,"PASS","FAIL") -> PASS | F42: Payment is not service
A43: 37 | B43: Payment production credit | C43: =SUM(Payment!I7:I10) -> 0 | D43: 0 | E43: =IF(ABS(C43-D43)<0.001,"PASS","FAIL") -> PASS | F43: Payment is not production
...

Sheet Sources & Limits
A2: Sources & Limits
A3: Repository-internal sources only. Values are controlled acquisition hypotheses and inherited planning authorities, not observed performance, budget estimates or procurement decisions.
A6: Source or limit | B6: Title | C6: Claims used | D6: Status
A7: Pass 168 | B7: Six Mission-System Portfolio Topology | C7: six systems, twenty-four problem fields and USD 550B mission technology account | D7: Authoritative
A8: Pass 169 | B8: Human Continuity Service Contract | C8: five-route human-continuity contract and physical-care priority | D8: Authoritative
A9: Pass 175 | B9: Twenty-Four-Root Diversity Constitution | C9: four complete roots per system and root-exclusive decisive ancestry | D9: Authoritative
A10: Pass 176 | B10: Lifeline Root Physical Configuration | C10: two-million-person staged water, power, thermal and residual vector | D10: Authoritative
A11: Pass 180 | B11: Six-System G3 Proof Unit | C11: six system-native denominators, quarter-load units and route completeness | D11: Authoritative
A12: Civil-terrain studies | B12: NCAC-35 and HCG-35B | C12: 105,000-person district, household and vertical productivity targets | D12: Inherited hypothesis
A13: Fire studies | B13: Integrated Fire Control and denied-infrastructure edge | C13: persistent held-edge, 6/18/72-hour article and closed intervention residual | D13: Inherited hypothesis
A14: Clinical study | B14: HCSG-100 Clinical Continuity Service Contract | C14: 100,000-person, ten-care-line, thirty-day definitive-care vector | D14: Inherited hypothesis
A15: Pass 206 | B15: National First Article Portfolio | C15: USD 200B tranche, one-quarter field structure and A0-A7 ladder | D15: Authoritative
A16: Pass 207 | B16: Separated Option-and-Proof Market | C16: USD 57.4B stageable options, USD 52.6B held and four payment states | D16: Authoritative
A17: Source status | B17: All firms, sites, mechanisms, articles, events and observations | C17: no implementation identity or performance is accepted | D17: Source empty
... A22: Next decision | B22: Public denominator freeze and first mechanism articles | C22: constitute A0 methods and A1 article release without converging roots | D22: Frontier
