Workbook

Sheet Summary
A1: First A2 six-root sentinel construction wave
A2: The smallest all-six construction portfolio that can both resize a configuration and kill a causal lineage while leaving the full twenty-four-root estate unbuilt.
A4: Decision
A5: Selected architecture | B5: =INDEX(Alternatives!A5:A9,MATCH("PASS",Alternatives!L5:L9,0)) -> Compound falsification | F5: Selected roots
A6: Verdict | B6: CLOSE | F6: MS-ET | G6: ET-A | H6: Pelagic heavy bridge
A7: Branch | B7: A2C-1, first of at most five | F7: MS-CT | G7: CT-C | H7: Building utility spine
A8: Current state | B8: WARRANT-CONSTITUTED; obligations and observations remain zero | F8: MS-HC | G8: HC-A | H8: Atmospheric flux wing
F9: MS-LF | G9: LF-B | H9: Inland geothermal train
A10: Physical portfolio | F10: MS-HU | G10: HU-A | H10: Clinical continuity campus
A11: Measure | B11: Value | C11: Unit | D11: Interpretation | F11: MS-RT | G11: RT-B | H11: Microfactory mesh
A12: Selected sentinel roots | B12: =COUNTIF('Sentinel Selection'!H5:H28,"SELECTED") -> 6 | C12: count | D12: One per mission system
A13: Endpoint definitions | B13: =COUNTA('Root Endpoints'!A5:A16) -> 12 | C13: count | D13: Balance plus causal keystone
A14: Station nuclei | B14: =COUNTA('Station Nuclei'!A5:A22) -> 18 | C14: count | D14: Challenge, control, and reconstruction in all six systems | F14: Release rule
A15: Initial lanes | B15: =SUM('Station Nuclei'!H5:H22) -> 36 | C15: count | D15: One sentinel and one regeneration lane per station | F15: 1 | G15: Method fails | H15: Stop after S0; no candidate execution
A16: Held expansion lanes | B16: =SUM('Station Nuclei'!G5:G22) -> 54 | C16: count | D16: Three root lanes per station remain unbuilt | F16: 2 | G16: Balance upper bound < 1.00 | H16: RESIZE current configuration
A17: Receiver states | B17: =COUNTA('Receiver States'!A5:A28) -> 24 | C17: count | D17: Complete public handoff denominator | F17: 3 | G17: Keystone upper bound < 1.00 | H17: KILL causal lineage
A18: Unlike method realizations | B18: =COUNTA('Method Realizations'!A5:A148) -> 144 | C18: count | D18: Two physical lineages per method card | F18: 4 | G18: Interval crosses threshold | H18: HOLD; no imputation
A19: Decisive events | B19: =COUNTA('Event Register'!A5:A76) -> 72 | C19: count | D19: Twelve per selected root | F19: 5 | G19: Both endpoints support | H19: Cold reconstruction still required
A20: Evidence packages | B20: =COUNTA('Evidence Packages'!A5:A364) -> 360 | C20: count | D20: Five per event | F20: 6 | G20: Cold reproduction completes | H20: BUILD PROOF eligible, not capable
A21: Maximum attempts | B21: =COUNTA('Event Register'!A5:A76)+Controls!B16*Controls!B24 -> 84 | C21: count | D21: Invalidity-only reserve cannot replace adverse evidence
A24: Authority and loss boundaries | F24: Audit state
A25: Boundary | B25: Value | C25: Unit | D25: Meaning | F25: Terminal audits | G25: 64
A26: Selected private ceiling | B26: =Authority!D11 -> 3.5869128 | C26: USD B | D26: One quarter of each system's cohort option | F26: Restored mutations | G26: 14
A27: Reusable public-method ceiling | B27: =Authority!B24 -> 12 | C27: USD B | D27: Nested inside the USD 80.0B enabling account | F27: Formula errors | G27: 0
A28: Combined construction-wave ceiling | B28: ='Stage Schedule'!H8 -> 15.586913 | C28: USD B | D28: Authority only; not an obligation | F28: Master result | G28: =Audit!B4 -> PASS
A29: All-six valid KILL ceiling at BREAK | B29: ='Maximum Loss'!D7 -> 12.048876 | C29: USD B | D29: Public 75% plus private 85%; remaining stages cancelled
A30: Largest single-root KILL ceiling | B30: ='Maximum Loss'!D8 -> 0.7645009 | C30: USD B | D30: Maximum root-specific paid exposure
A31: Unreleased if all six die at BREAK | B31: ='Maximum Loss'!E7 -> 3.5380369 | C31: USD B | D31: Public cold/replay plus private TRANSFER remain held
A32: Protected failure reserve used | B32: ='Maximum Loss'!F7 -> 0 | C32: USD B | D32: Remains untouched without exact invalidity
A33: Current obligations | B33: =Controls!B37 -> 0 | C33: USD B | D33: No firm, site, or serial exists
A34: Current capability credit | B34: =Controls!B38 -> 0 | C34: count | D34: A2 construction cannot create force credit

Sheet Controls
A1: First A2 six-root sentinel construction wave
A2: Blue values are inherited planning controls. They are ceilings and test denominators, not obligations, observations, or capability.
A4: Control | B4: Value | C4: Unit | D4: Authority
A5: First tranche | B5: 200 | C5: USD B | D5: Pass 206/210
A6: Mission systems | B6: 110 | C6: USD B | D6: Pass 206/210
A7: Service technical bases | B7: 30 | C7: USD B | D7: Pass 206/210
A8: Common capacity | B8: 30 | C8: USD B | D8: Pass 206/210
A9: Sovereign technical estate | B9: 20 | C9: USD B | D9: Pass 206/210
A10: Protected failure reserve | B10: 10 | C10: USD B | D10: Pass 206/210
A11: Public and enabling account | B11: 80 | C11: USD B | D11: Pass 210, cross-classified
A12: Public-method reservation | B12: 12 | C12: USD B | D12: Pass 209/210, nested
A13: First-cohort stageable options | B13: 14.347651 | C13: USD B | D13: Pass 208/210
A14: Roots per system | B14: 4 | C14: count | D14: Pass 175/210
A15: Mission systems in sentinel wave | B15: 6 | C15: count | D15: Pass 208
A16: Selected sentinel roots | B16: 6 | C16: count | D16: Pass 211
... A43: Physical observations | B43: 0 | C43: count | D43: Source empty

Sheet Alternatives
A1: Construction architecture comparison
A2: A valid architecture must pass every gate. A larger portfolio does not compensate for a failed truth, independence, or loss-control gate.
A4: Alternative | B4: Core move | C4: All six systems enter | D4: Balance and keystone stay distinct | E4: Three rig roles remain independent | F4: Two unlike public realizations | G4: Candidate and public work co-gated | H4: Reusable public estate | I4: Maximum paid loss bounded | J4: Avoids unneeded root construction | K4: Pass count | L4: Disposition
A5: Balance-first | B5: Build only limiting-account rigs | C5: 1 | D5: 0 | E5: 1 | F5: 1 | G5: 1 | H5: 1 | I5: 1 | J5: 1 | K5: =SUM(C5:J5) -> 7 | L5: =IF(K5=8,"PASS","FAIL") -> FAIL
A6: Keystone-first | B6: Build only decisive-mechanism denial rigs | C6: 1 | D6: 0 | E6: 1 | F6: 1 | G6: 1 | H6: 1 | I6: 1 | J6: 1 | K6: =SUM(C6:J6) -> 7 | L6: =IF(K6=8,"PASS","FAIL") -> FAIL
A7: Receiver-bootstrap | B7: Build the public estate before candidate rigs | C7: 1 | D7: 0 | E7: 1 | F7: 1 | G7: 0 | H7: 1 | I7: 0 | J7: 0 | K7: =SUM(C7:J7) -> 4 | L7: =IF(K7=8,"PASS","FAIL") -> FAIL
A8: Compound falsification | B8: One root per system; both endpoints and all roles | C8: 1 | D8: 1 | E8: 1 | F8: 1 | G8: 1 | H8: 1 | I8: 1 | J8: 1 | K8: =SUM(C8:J8) -> 8 | L8: =IF(K8=8,"PASS","FAIL") -> PASS
A9: Full estate | B9: All twenty-four roots and all lanes at once | C9: 1 | D9: 1 | E9: 1 | F9: 1 | G9: 1 | H9: 1 | I9: 0 | J9: 0 | K9: =SUM(C9:J9) -> 6 | L9: =IF(K9=8,"PASS","FAIL") -> FAIL

Sheet Sentinel Selection
A1: Six sentinel roots
A2: Selection is lexicographic: lowest largest-cell-loss margin in each system, then a frozen tie-break based on cross-system causal leverage.
A4: Root | B4: System | C4: Mechanism | D4: Limiting account | E4: Loss margin | F4: Tie order | G4: Selection rank | H4: State | I4: System option (USD B) | J4: Root option (USD B) | K4: Tie-break basis | L4: Construction warrant
A5: ET-A | B5: MS-ET | C5: Pelagic heavy bridge | D5: Route flow | E5: 1.024 | F5: 1 | G5: =COUNTIFS($B$5:$B$28,B5,$E$5:$E$28,"<"&E5)+COUNTIFS($B$5:$B$28,B5,$E$5:$E$28,E5,$F$5:$F$28,"<"&F5)+1 -> 1 | H5: =IF(G5=1,"SELECTED","HELD") -> SELECTED | I5: 2.0018985 | J5: =I5/Controls!$B$14 -> 0.50047462 | K5: Lowest system margin | L5: =IF(H5="SELECTED","WARRANT-CONSTITUTED","HELD") -> WARRANT-CONSTITUTED
A6: ET-B | B6: MS-ET | C6: Aerostatic sky bridge | D6: Route flow | E6: 1.04 | F6: 2 | G6: =COUNTIFS($B$5:$B$28,B6,$E$5:$E$28,"<"&E6)+COUNTIFS($B$5:$B$28,B6,$E$5:$E$28,E6,$F$5:$F$28,"<"&F6)+1 -> 2 | H6: =IF(G6=1,"SELECTED","HELD") -> HELD | I6: 2.0018985 | J6: =I6/Controls!$B$14 -> 0.50047462 | K6: Later margin | L6: =IF(H6="SELECTED","WARRANT-CONSTITUTED","HELD") -> HELD
A7: ET-C | B7: MS-ET | C7: Terrain corridor train | D7: Mass | E7: 1.0465116 | F7: 3 | G7: =COUNTIFS($B$5:$B$28,B7,$E$5:$E$28,"<"&E7)+COUNTIFS($B$5:$B$28,B7,$E$5:$E$28,E7,$F$5:$F$28,"<"&F7)+1 -> 3 | H7: =IF(G7=1,"SELECTED","HELD") -> HELD | I7: 2.0018985 | J7: =I7/Controls!$B$14 -> 0.50047462 | K7: Later margin | L7: =IF(H7="SELECTED","WARRANT-CONSTITUTED","HELD") -> HELD
A8: ET-D | B8: MS-ET | C8: Amphibious mesh | D8: Safety | E8: 1.05 | F8: 4 | G8: =COUNTIFS($B$5:$B$28,B8,$E$5:$E$28,"<"&E8)+COUNTIFS($B$5:$B$28,B8,$E$5:$E$28,E8,$F$5:$F$28,"<"&F8)+1 -> 4 | H8: =IF(G8=1,"SELECTED","HELD") -> HELD | I8: 2.0018985 | J8: =I8/Controls!$B$14 -> 0.50047462 | K8: Later margin | L8: =IF(H8="SELECTED","WARRANT-CONSTITUTED","HELD") -> HELD
A9: CT-A | B9: MS-CT | C9: Civic edge grid | D9: Route flow | E9: 1.024 | F9: 3 | G9: =COUNTIFS($B$5:$B$28,B9,$E$5:$E$28,"<"&E9)+COUNTIFS($B$5:$B$28,B9,$E$5:$E$28,E9,$F$5:$F$28,"<"&F9)+1 -> 3 | H9: =IF(G9=1,"SELECTED","HELD") -> HELD | I9: 2.0659739 | J9: =I9/Controls!$B$14 -> 0.51649348 | K9: Above exact-boundary pair | L9: =IF(H9="SELECTED","WARRANT-CONSTITUTED","HELD") -> HELD
A10: CT-B | B10: MS-CT | C10: Air-and-skin reach | D10: Energy | E10: 1 | F10: 2 | G10: =COUNTIFS($B$5:$B$28,B10,$E$5:$E$28,"<"&E10)+COUNTIFS($B$5:$B$28,B10,$E$5:$E$28,E10,$F$5:$F$28,"<"&F10)+1 -> 2 | H10: =IF(G10=1,"SELECTED","HELD") -> HELD | I10: 2.0659739 | J10: =I10/Controls!$B$14 -> 0.51649348 | K10: Exact tie; lower compound leverage | L10: =IF(H10="SELECTED","WARRANT-CONSTITUTED","HELD") -> HELD
A11: CT-C | B11: MS-CT | C11: Building utility spine | D11: Energy | E11: 1 | F11: 1 | G11: =COUNTIFS($B$5:$B$28,B11,$E$5:$E$28,"<"&E11)+COUNTIFS($B$5:$B$28,B11,$E$5:$E$28,E11,$F$5:$F$28,"<"&F11)+1 -> 1 | H11: =IF(G11=1,"SELECTED","HELD") -> SELECTED | I11: 2.0659739 | J11: =I11/Controls!$B$14 -> 0.51649348 | K11: Exact tie; tests lifeline-to-building interface | L11: =IF(H11="SELECTED","WARRANT-CONSTITUTED","HELD") -> WARRANT-CONSTITUTED
A12: CT-D | B12: MS-CT | C12: Neighborhood machine swarm | D12: Energy | E12: 1.0263158 | F12: 4 | G12: =COUNTIFS($B$5:$B$28,B12,$E$5:$E$28,"<"&E12)+COUNTIFS($B$5:$B$28,B12,$E$5:$E$28,E12,$F$5:$F$28,"<"&F12)+1 -> 4 | H12: =IF(G12=1,"SELECTED","HELD") -> HELD | I12: 2.0659739 | J12: =I12/Controls!$B$14 -> 0.51649348 | K12: Later margin | L12: =IF(H12="SELECTED","WARRANT-CONSTITUTED","HELD") -> HELD
A13: HC-A | B13: MS-HC | C13: Atmospheric flux wing | D13: Route flow | E13: 1.024 | F13: 1 | G13: =COUNTIFS($B$5:$B$28,B13,$E$5:$E$28,"<"&E13)+COUNTIFS($B$5:$B$28,B13,$E$5:$E$28,E13,$F$5:$F$28,"<"&F13)+1 -> 1 | H13: =IF(G13=1,"SELECTED","HELD") -> SELECTED | I13: 1.2288866 | J13: =I13/Controls!$B$14 -> 0.30722165 | K13: Lowest system margin | L13: =IF(H13="SELECTED","WARRANT-CONSTITUTED","HELD") -> WARRANT-CONSTITUTED
A14: HC-B | B14: MS-HC | C14: Hydraulic intervention lattice | D14: Route flow | E14: 1.04 | F14: 3 | G14: =COUNTIFS($B$5:$B$28,B14,$E$5:$E$28,"<"&E14)+COUNTIFS($B$5:$B$28,B14,$E$5:$E$28,E14,$F$5:$F$28,"<"&F14)+1 -> 3 | H14: =IF(G14=1,"SELECTED","HELD") -> HELD | I14: 1.2288866 | J14: =I14/Controls!$B$14 -> 0.30722165 | K14: Later margin | L14: =IF(H14="SELECTED","WARRANT-CONSTITUTED","HELD") -> HELD
A15: HC-C | B15: MS-HC | C15: Autonomous terrain corps | D15: Mass | E15: 1.0375 | F15: 2 | G15: =COUNTIFS($B$5:$B$28,B15,$E$5:$E$28,"<"&E15)+COUNTIFS($B$5:$B$28,B15,$E$5:$E$28,E15,$F$5:$F$28,"<"&F15)+1 -> 2 | H15: =IF(G15=1,"SELECTED","HELD") -> HELD | I15: 1.2288866 | J15: =I15/Controls!$B$14 -> 0.30722165 | K15: Later margin | L15: =IF(H15="SELECTED","WARRANT-CONSTITUTED","HELD") -> HELD
A16: HC-D | B16: MS-HC | C16: Boundary-control field | D16: Mass | E16: 1.04 | F16: 4 | G16: =COUNTIFS($B$5:$B$28,B16,$E$5:$E$28,"<"&E16)+COUNTIFS($B$5:$B$28,B16,$E$5:$E$28,E16,$F$5:$F$28,"<"&F16)+1 -> 4 | H16: =IF(G16=1,"SELECTED","HELD") -> HELD | I16: 1.2288866 | J16: =I16/Controls!$B$14 -> 0.30722165 | K16: Later margin | L16: =IF(H16="SELECTED","WARRANT-CONSTITUTED","HELD") -> HELD
... A28: RT-D | B28: MS-RT | C28: Closed-loop sustainment fleet | D28: Energy | E28: 1.0131579 | F28: 2 | G28: =COUNTIFS($B$5:$B$28,B28,$E$5:$E$28,"<"&E28)+COUNTIFS($B$5:$B$28,B28,$E$5:$E$28,E28,$F$5:$F$28,"<"&F28)+1 -> 2 | H28: =IF(G28=1,"SELECTED","HELD") -> HELD | I28: 2.0103912 | J28: =I28/Controls!$B$14 -> 0.50259779 | K28: Later margin | L28: =IF(H28="SELECTED","WARRANT-CONSTITUTED","HELD") -> HELD

Sheet Root Endpoints
A1: Paired A2 endpoint constitution
A2: Each selected root receives one balance endpoint and one causal-keystone endpoint. A valid adverse balance result resizes; a valid adverse keystone result kills.
A4: Endpoint | B4: Root | C4: System | D4: Type | E4: Normalized threshold | F4: Limiting account | G4: Measured question | H4: Adverse action | I4: Rig roles | J4: Unlike lineages | K4: Observation | L4: Disposition
A5: A2-ET-A-BAL | B5: ET-A | C5: MS-ET | D5: BALANCE | E5: 1 | F5: Route flow | G5: Accepted complete tonnes per day through dry handoff after largest-connector loss | H5: RESIZE | I5: 3 | J5: 2 | L5: =IF(K5="","HOLD","UNADMITTED") -> HOLD
A6: A2-ET-A-KEY | B6: ET-A | C6: MS-ET | D6: KEYSTONE | E6: 1 | F6: Route flow | G6: Sectional hydrostatics, stabilized exchange, and custody remain one causal route after denial | H6: KILL | I6: 3 | J6: 2 | L6: =IF(K6="","HOLD","UNADMITTED") -> HOLD
A7: A2-CT-C-BAL | B7: CT-C | C7: MS-CT | D7: BALANCE | E7: 1 | F7: Energy | G7: Accepted occupied-building utility positions per delivered MWh after one trunk loss | H7: RESIZE | I7: 3 | J7: 2 | L7: =IF(K7="","HOLD","UNADMITTED") -> HOLD
A8: A2-CT-C-KEY | B8: CT-C | C8: MS-CT | D8: KEYSTONE | E8: 1 | F8: Energy | G8: Reversible robotic attachment and isolated transfer avoid structural, smoke, and contamination propagation | H8: KILL | I8: 3 | J8: 2 | L8: =IF(K8="","HOLD","UNADMITTED") -> HOLD
A9: A2-HC-A-BAL | B9: HC-A | C9: MS-HC | D9: BALANCE | E9: 1 | F9: Route flow | G9: Attributed protected-edge kilometres per delivery cycle after largest-cell loss | H9: RESIZE | I9: 3 | J9: 2 | L9: =IF(K9="","HOLD","UNADMITTED") -> HOLD
A10: A2-HC-A-KEY | B10: HC-A | C10: MS-HC | D10: KEYSTONE | E10: 1 | F10: Route flow | G10: High-duty flight, sensing, and precision deposition produce persistent held effect under plume denial | H10: KILL | I10: 3 | J10: 2 | L10: =IF(K10="","HOLD","UNADMITTED") -> HOLD
A11: A2-LF-B-BAL | B11: LF-B | C11: MS-LF | D11: BALANCE | E11: 1 | F11: Energy | G11: Delivered water, firm electricity, and thermal service divided by the common required bus | H11: RESIZE | I11: 3 | J11: 2 | L11: =IF(K11="","HOLD","UNADMITTED") -> HOLD
A12: A2-LF-B-KEY | B12: LF-B | C12: MS-LF | D12: KEYSTONE | E12: 1 | F12: Energy | G12: Rapid-bore subsurface characterization reaches day-21 service without unstable drawdown or induced hazard | H12: KILL | I12: 3 | J12: 2 | L12: =IF(K12="","HOLD","UNADMITTED") -> HOLD
A13: A2-HU-A-BAL | B13: HU-A | C13: MS-HU | D13: BALANCE | E13: 1 | F13: Mass | G13: Staffed, supplied, dischargeable care positions per deployed tonne after island loss | H13: RESIZE | I13: 3 | J13: 2 | L13: =IF(K13="","HOLD","UNADMITTED") -> HOLD
A14: A2-HU-A-KEY | B14: HU-A | C14: MS-HU | D14: KEYSTONE | E14: 1 | F14: Mass | G14: Clinical relationships survive utility-family, labor, and destination denial without deleting a care line | H14: KILL | I14: 3 | J14: 2 | L14: =IF(K14="","HOLD","UNADMITTED") -> HOLD
A15: A2-RT-B-BAL | B15: RT-B | C15: MS-RT | D15: BALANCE | E15: 1 | F15: Energy | G15: Independently qualified output per MWh during depot and vendor-key loss | H15: RESIZE | I15: 3 | J15: 2 | L15: =IF(K15="","HOLD","UNADMITTED") -> HOLD
A16: A2-RT-B-KEY | B16: RT-B | C16: MS-RT | D16: KEYSTONE | E16: 1 | F16: Energy | G16: Disconnected production reproduces material ancestry, calibration, and qualification | H16: KILL | I16: 3 | J16: 2 | L16: =IF(K16="","HOLD","UNADMITTED") -> HOLD

Sheet Station Nuclei
A1: Eighteen public proving-station nuclei
A2: Three station roles are formed in every mission system. Each begins with one sentinel lane and one regeneration lane, while three future root lanes stay physically and fiscally held.
A4: Station nucleus | B4: System | C4: Role | D4: Role duty | E4: Active root lane | F4: Regeneration lane | G4: Held expansion lanes | H4: Initial lanes | I4: Full lanes | J4: Site identity | K4: Operator identity | L4: State
A5: ST-ET-CHA | B5: MS-ET | C5: CHALLENGE | D5: Creates the decisive denial state without supplying candidate control | E5: ET-A | F5: 1 | G5: 3 | H5: =F5+Controls!$B$25 -> 2 | I5: =H5+G5 -> 5 | J5: SOURCE EMPTY | K5: SOURCE EMPTY | L5: WARRANT-CONSTITUTED
A6: ST-ET-CON | B6: MS-ET | C6: CONTROL | D6: Measures background burden in a matched, separately operated world | E6: ET-A | F6: 1 | G6: 3 | H6: =F6+Controls!$B$25 -> 2 | I6: =H6+G6 -> 5 | J6: SOURCE EMPTY | K6: SOURCE EMPTY | L6: WARRANT-CONSTITUTED
A7: ST-ET-REC | B7: MS-ET | C7: RECONSTRUCTION | D7: Cold-builds and replays from public technical data outside candidate craft lineage | E7: ET-A | F7: 1 | G7: 3 | H7: =F7+Controls!$B$25 -> 2 | I7: =H7+G7 -> 5 | J7: SOURCE EMPTY | K7: SOURCE EMPTY | L7: WARRANT-CONSTITUTED
A8: ST-CT-CHA | B8: MS-CT | C8: CHALLENGE | D8: Creates the decisive denial state without supplying candidate control | E8: CT-C | F8: 1 | G8: 3 | H8: =F8+Controls!$B$25 -> 2 | I8: =H8+G8 -> 5 | J8: SOURCE EMPTY | K8: SOURCE EMPTY | L8: WARRANT-CONSTITUTED
A9: ST-CT-CON | B9: MS-CT | C9: CONTROL | D9: Measures background burden in a matched, separately operated world | E9: CT-C | F9: 1 | G9: 3 | H9: =F9+Controls!$B$25 -> 2 | I9: =H9+G9 -> 5 | J9: SOURCE EMPTY | K9: SOURCE EMPTY | L9: WARRANT-CONSTITUTED
A10: ST-CT-REC | B10: MS-CT | C10: RECONSTRUCTION | D10: Cold-builds and replays from public technical data outside candidate craft lineage | E10: CT-C | F10: 1 | G10: 3 | H10: =F10+Controls!$B$25 -> 2 | I10: =H10+G10 -> 5 | J10: SOURCE EMPTY | K10: SOURCE EMPTY | L10: WARRANT-CONSTITUTED
A11: ST-HC-CHA | B11: MS-HC | C11: CHALLENGE | D11: Creates the decisive denial state without supplying candidate control | E11: HC-A | F11: 1 | G11: 3 | H11: =F11+Controls!$B$25 -> 2 | I11: =H11+G11 -> 5 | J11: SOURCE EMPTY | K11: SOURCE EMPTY | L11: WARRANT-CONSTITUTED
A12: ST-HC-CON | B12: MS-HC | C12: CONTROL | D12: Measures background burden in a matched, separately operated world | E12: HC-A | F12: 1 | G12: 3 | H12: =F12+Controls!$B$25 -> 2 | I12: =H12+G12 -> 5 | J12: SOURCE EMPTY | K12: SOURCE EMPTY | L12: WARRANT-CONSTITUTED
A13: ST-HC-REC | B13: MS-HC | C13: RECONSTRUCTION | D13: Cold-builds and replays from public technical data outside candidate craft lineage | E13: HC-A | F13: 1 | G13: 3 | H13: =F13+Controls!$B$25 -> 2 | I13: =H13+G13 -> 5 | J13: SOURCE EMPTY | K13: SOURCE EMPTY | L13: WARRANT-CONSTITUTED
A14: ST-LF-CHA | B14: MS-LF | C14: CHALLENGE | D14: Creates the decisive denial state without supplying candidate control | E14: LF-B | F14: 1 | G14: 3 | H14: =F14+Controls!$B$25 -> 2 | I14: =H14+G14 -> 5 | J14: SOURCE EMPTY | K14: SOURCE EMPTY | L14: WARRANT-CONSTITUTED
A15: ST-LF-CON | B15: MS-LF | C15: CONTROL | D15: Measures background burden in a matched, separately operated world | E15: LF-B | F15: 1 | G15: 3 | H15: =F15+Controls!$B$25 -> 2 | I15: =H15+G15 -> 5 | J15: SOURCE EMPTY | K15: SOURCE EMPTY | L15: WARRANT-CONSTITUTED
A16: ST-LF-REC | B16: MS-LF | C16: RECONSTRUCTION | D16: Cold-builds and replays from public technical data outside candidate craft lineage | E16: LF-B | F16: 1 | G16: 3 | H16: =F16+Controls!$B$25 -> 2 | I16: =H16+G16 -> 5 | J16: SOURCE EMPTY | K16: SOURCE EMPTY | L16: WARRANT-CONSTITUTED
... A22: ST-RT-REC | B22: MS-RT | C22: RECONSTRUCTION | D22: Cold-builds and replays from public technical data outside candidate craft lineage | E22: RT-B | F22: 1 | G22: 3 | H22: =F22+Controls!$B$25 -> 2 | I22: =H22+G22 -> 5 | J22: SOURCE EMPTY | K22: SOURCE EMPTY | L22: WARRANT-CONSTITUTED

Sheet Receiver States
A1: Twenty-four receiver states
A2: All four states in each system enter because a root may not pass at the machine boundary while failing the public handoff.
A4: State ID | B4: System | C4: State | D4: Selected root | E4: Load and quality card | F4: Denied-condition card | G4: Recovery and burden card | H4: State
A5: ET-RS1 | B5: MS-ET | C5: Moving interface | D5: ET-A | E5: ET-RS1-LQ | F5: ET-RS1-DEN | G5: ET-RS1-RCB | H5: WARRANT-CONSTITUTED
A6: ET-RS2 | B6: MS-ET | C6: Shore transition | D6: ET-A | E6: ET-RS2-LQ | F6: ET-RS2-DEN | G6: ET-RS2-RCB | H6: WARRANT-CONSTITUTED
A7: ET-RS3 | B7: MS-ET | C7: Dry staging | D7: ET-A | E7: ET-RS3-LQ | F7: ET-RS3-DEN | G7: ET-RS3-RCB | H7: WARRANT-CONSTITUTED
A8: ET-RS4 | B8: MS-ET | C8: Onward handoff | D8: ET-A | E8: ET-RS4-LQ | F8: ET-RS4-DEN | G8: ET-RS4-RCB | H8: WARRANT-CONSTITUTED
A9: CT-RS1 | B9: MS-CT | C9: District approach | D9: CT-C | E9: CT-RS1-LQ | F9: CT-RS1-DEN | G9: CT-RS1-RCB | H9: WARRANT-CONSTITUTED
A10: CT-RS2 | B10: MS-CT | C10: Occupied low-rise | D10: CT-C | E10: CT-RS2-LQ | F10: CT-RS2-DEN | G10: CT-RS2-RCB | H10: WARRANT-CONSTITUTED
A11: CT-RS3 | B11: MS-CT | C11: High-rise vertical | D11: CT-C | E11: CT-RS3-LQ | F11: CT-RS3-DEN | G11: CT-RS3-RCB | H11: WARRANT-CONSTITUTED
A12: CT-RS4 | B12: MS-CT | C12: Refuge and egress | D12: CT-C | E12: CT-RS4-LQ | F12: CT-RS4-DEN | G12: CT-RS4-RCB | H12: WARRANT-CONSTITUTED
A13: HC-RS1 | B13: MS-HC | C13: Advancing edge | D13: HC-A | E13: HC-RS1-LQ | F13: HC-RS1-DEN | G13: HC-RS1-RCB | H13: WARRANT-CONSTITUTED
A14: HC-RS2 | B14: MS-HC | C14: Ember and interface | D14: HC-A | E14: HC-RS2-LQ | F14: HC-RS2-DEN | G14: HC-RS2-RCB | H14: WARRANT-CONSTITUTED
A15: HC-RS3 | B15: MS-HC | C15: Plume and airspace | D15: HC-A | E15: HC-RS3-LQ | F15: HC-RS3-DEN | G15: HC-RS3-RCB | H15: WARRANT-CONSTITUTED
... A28: RT-RS4 | B28: MS-RT | C28: Calibration and release | D28: RT-B | E28: RT-RS4-LQ | F28: RT-RS4-DEN | G28: RT-RS4-RCB | H28: WARRANT-CONSTITUTED

Sheet Method Cards
A1: Seventy-two public method cards
A2: Each receiver state has load-and-quality, denied-condition, and recovery-and-burden cards. These define public questions, not candidate implementations.
A4: Method card | B4: State ID | C4: System | D4: Inquiry | E4: Public question | F4: Selected root | G4: Required lineages | H4: Accepted lineages | I4: Status | J4: Candidate code prohibited
A5: ET-RS1-LQ | B5: ET-RS1 | C5: MS-ET | D5: LOAD AND QUALITY | E5: What useful service reaches the receiver, at what rate and uncertainty? | F5: ET-A | G5: 2 | H5: 0 | I5: =IF(H5=G5,"ACCEPTED","HELD") -> HELD | J5: YES
A6: ET-RS1-DEN | B6: ET-RS1 | C6: MS-ET | D6: DENIED CONDITION | E6: Does the service survive its frozen largest-loss and rights boundary? | F6: ET-A | G6: 2 | H6: 0 | I6: =IF(H6=G6,"ACCEPTED","HELD") -> HELD | J6: YES
A7: ET-RS1-RCB | B7: ET-RS1 | C7: MS-ET | D7: RECOVERY AND BURDEN | E7: Can the root reset, account for residuals, and leave the receiver in an accepted state? | F7: ET-A | G7: 2 | H7: 0 | I7: =IF(H7=G7,"ACCEPTED","HELD") -> HELD | J7: YES
A8: ET-RS2-LQ | B8: ET-RS2 | C8: MS-ET | D8: LOAD AND QUALITY | E8: What useful service reaches the receiver, at what rate and uncertainty? | F8: ET-A | G8: 2 | H8: 0 | I8: =IF(H8=G8,"ACCEPTED","HELD") -> HELD | J8: YES
A9: ET-RS2-DEN | B9: ET-RS2 | C9: MS-ET | D9: DENIED CONDITION | E9: Does the service survive its frozen largest-loss and rights boundary? | F9: ET-A | G9: 2 | H9: 0 | I9: =IF(H9=G9,"ACCEPTED","HELD") -> HELD | J9: YES
A10: ET-RS2-RCB | B10: ET-RS2 | C10: MS-ET | D10: RECOVERY AND BURDEN | E10: Can the root reset, account for residuals, and leave the receiver in an accepted state? | F10: ET-A | G10: 2 | H10: 0 | I10: =IF(H10=G10,"ACCEPTED","HELD") -> HELD | J10: YES
A11: ET-RS3-LQ | B11: ET-RS3 | C11: MS-ET | D11: LOAD AND QUALITY | E11: What useful service reaches the receiver, at what rate and uncertainty? | F11: ET-A | G11: 2 | H11: 0 | I11: =IF(H11=G11,"ACCEPTED","HELD") -> HELD | J11: YES
A12: ET-RS3-DEN | B12: ET-RS3 | C12: MS-ET | D12: DENIED CONDITION | E12: Does the service survive its frozen largest-loss and rights boundary? | F12: ET-A | G12: 2 | H12: 0 | I12: =IF(H12=G12,"ACCEPTED","HELD") -> HELD | J12: YES
A13: ET-RS3-RCB | B13: ET-RS3 | C13: MS-ET | D13: RECOVERY AND BURDEN | E13: Can the root reset, account for residuals, and leave the receiver in an accepted state? | F13: ET-A | G13: 2 | H13: 0 | I13: =IF(H13=G13,"ACCEPTED","HELD") -> HELD | J13: YES
A14: ET-RS4-LQ | B14: ET-RS4 | C14: MS-ET | D14: LOAD AND QUALITY | E14: What useful service reaches the receiver, at what rate and uncertainty? | F14: ET-A | G14: 2 | H14: 0 | I14: =IF(H14=G14,"ACCEPTED","HELD") -> HELD | J14: YES
A15: ET-RS4-DEN | B15: ET-RS4 | C15: MS-ET | D15: DENIED CONDITION | E15: Does the service survive its frozen largest-loss and rights boundary? | F15: ET-A | G15: 2 | H15: 0 | I15: =IF(H15=G15,"ACCEPTED","HELD") -> HELD | J15: YES
A16: ET-RS4-RCB | B16: ET-RS4 | C16: MS-ET | D16: RECOVERY AND BURDEN | E16: Can the root reset, account for residuals, and leave the receiver in an accepted state? | F16: ET-A | G16: 2 | H16: 0 | I16: =IF(H16=G16,"ACCEPTED","HELD") -> HELD | J16: YES
... A76: RT-RS4-RCB | B76: RT-RS4 | C76: MS-RT | D76: RECOVERY AND BURDEN | E76: Can the root reset, account for residuals, and leave the receiver in an accepted state? | F76: RT-B | G76: 2 | H76: 0 | I76: =IF(H76=G76,"ACCEPTED","HELD") -> HELD | J76: YES

Sheet Method Realizations
A1: One hundred forty-four unlike physical realization lineages
A2: Every card receives two physically unlike public implementations. A lineage identity, site, instrument set, and acceptance record remain source empty.
A4: Realization | B4: Method card | C4: System | D4: Lineage | E4: Physical implementation family | F4: Independence requirement | G4: Direct realization reserve (USD B) | H4: Site | I4: Operator | J4: Accepted | K4: Status | L4: Candidate credit
A5: ET-RS1-LQ-L1 | B5: ET-RS1-LQ | C5: MS-ET | D5: L1 | E5: Moving-basin and flexible-shore field | F5: Different beneficial control, executive command, decisive tooling, and evidence custody | G5: =1.8/144 -> 0.0125 | H5: SOURCE EMPTY | I5: SOURCE EMPTY | J5: 0 | K5: =IF(J5=1,"ACCEPTED","WARRANT-CONSTITUTED") -> WARRANT-CONSTITUTED | L5: 0
A6: ET-RS1-LQ-L2 | B6: ET-RS1-LQ | C6: MS-ET | D6: L2 | E6: Independent articulated-motion and breakable-handoff complex | F6: Different beneficial control, executive command, decisive tooling, and evidence custody | G6: =1.8/144 -> 0.0125 | H6: SOURCE EMPTY | I6: SOURCE EMPTY | J6: 0 | K6: =IF(J6=1,"ACCEPTED","WARRANT-CONSTITUTED") -> WARRANT-CONSTITUTED | L6: 0
A7: ET-RS1-DEN-L1 | B7: ET-RS1-DEN | C7: MS-ET | D7: L1 | E7: Moving-basin and flexible-shore field | F7: Different beneficial control, executive command, decisive tooling, and evidence custody | G7: =1.8/144 -> 0.0125 | H7: SOURCE EMPTY | I7: SOURCE EMPTY | J7: 0 | K7: =IF(J7=1,"ACCEPTED","WARRANT-CONSTITUTED") -> WARRANT-CONSTITUTED | L7: 0
A8: ET-RS1-DEN-L2 | B8: ET-RS1-DEN | C8: MS-ET | D8: L2 | E8: Independent articulated-motion and breakable-handoff complex | F8: Different beneficial control, executive command, decisive tooling, and evidence custody | G8: =1.8/144 -> 0.0125 | H8: SOURCE EMPTY | I8: SOURCE EMPTY | J8: 0 | K8: =IF(J8=1,"ACCEPTED","WARRANT-CONSTITUTED") -> WARRANT-CONSTITUTED | L8: 0
A9: ET-RS1-RCB-L1 | B9: ET-RS1-RCB | C9: MS-ET | D9: L1 | E9: Moving-basin and flexible-shore field | F9: Different beneficial control, executive command, decisive tooling, and evidence custody | G9: =1.8/144 -> 0.0125 | H9: SOURCE EMPTY | I9: SOURCE EMPTY | J9: 0 | K9: =IF(J9=1,"ACCEPTED","WARRANT-CONSTITUTED") -> WARRANT-CONSTITUTED | L9: 0
A10: ET-RS1-RCB-L2 | B10: ET-RS1-RCB | C10: MS-ET | D10: L2 | E10: Independent articulated-motion and breakable-handoff complex | F10: Different beneficial control, executive command, decisive tooling, and evidence custody | G10: =1.8/144 -> 0.0125 | H10: SOURCE EMPTY | I10: SOURCE EMPTY | J10: 0 | K10: =IF(J10=1,"ACCEPTED","WARRANT-CONSTITUTED") -> WARRANT-CONSTITUTED | L10: 0
A11: ET-RS2-LQ-L1 | B11: ET-RS2-LQ | C11: MS-ET | D11: L1 | E11: Moving-basin and flexible-shore field | F11: Different beneficial control, executive command, decisive tooling, and evidence custody | G11: =1.8/144 -> 0.0125 | H11: SOURCE EMPTY | I11: SOURCE EMPTY | J11: 0 | K11: =IF(J11=1,"ACCEPTED","WARRANT-CONSTITUTED") -> WARRANT-CONSTITUTED | L11: 0
A12: ET-RS2-LQ-L2 | B12: ET-RS2-LQ | C12: MS-ET | D12: L2 | E12: Independent articulated-motion and breakable-handoff complex | F12: Different beneficial control, executive command, decisive tooling, and evidence custody | G12: =1.8/144 -> 0.0125 | H12: SOURCE EMPTY | I12: SOURCE EMPTY | J12: 0 | K12: =IF(J12=1,"ACCEPTED","WARRANT-CONSTITUTED") -> WARRANT-CONSTITUTED | L12: 0
A13: ET-RS2-DEN-L1 | B13: ET-RS2-DEN | C13: MS-ET | D13: L1 | E13: Moving-basin and flexible-shore field | F13: Different beneficial control, executive command, decisive tooling, and evidence custody | G13: =1.8/144 -> 0.0125 | H13: SOURCE EMPTY | I13: SOURCE EMPTY | J13: 0 | K13: =IF(J13=1,"ACCEPTED","WARRANT-CONSTITUTED") -> WARRANT-CONSTITUTED | L13: 0
A14: ET-RS2-DEN-L2 | B14: ET-RS2-DEN | C14: MS-ET | D14: L2 | E14: Independent articulated-motion and breakable-handoff complex | F14: Different beneficial control, executive command, decisive tooling, and evidence custody | G14: =1.8/144 -> 0.0125 | H14: SOURCE EMPTY | I14: SOURCE EMPTY | J14: 0 | K14: =IF(J14=1,"ACCEPTED","WARRANT-CONSTITUTED") -> WARRANT-CONSTITUTED | L14: 0
A15: ET-RS2-RCB-L1 | B15: ET-RS2-RCB | C15: MS-ET | D15: L1 | E15: Moving-basin and flexible-shore field | F15: Different beneficial control, executive command, decisive tooling, and evidence custody | G15: =1.8/144 -> 0.0125 | H15: SOURCE EMPTY | I15: SOURCE EMPTY | J15: 0 | K15: =IF(J15=1,"ACCEPTED","WARRANT-CONSTITUTED") -> WARRANT-CONSTITUTED | L15: 0
A16: ET-RS2-RCB-L2 | B16: ET-RS2-RCB | C16: MS-ET | D16: L2 | E16: Independent articulated-motion and breakable-handoff complex | F16: Different beneficial control, executive command, decisive tooling, and evidence custody | G16: =1.8/144 -> 0.0125 | H16: SOURCE EMPTY | I16: SOURCE EMPTY | J16: 0 | K16: =IF(J16=1,"ACCEPTED","WARRANT-CONSTITUTED") -> WARRANT-CONSTITUTED | L16: 0
... A148: RT-RS4-RCB-L2 | B148: RT-RS4-RCB | C148: MS-RT | D148: L2 | E148: Independent disconnected production and qualification cell | F148: Different beneficial control, executive command, decisive tooling, and evidence custody | G148: =1.8/144 -> 0.0125 | H148: SOURCE EMPTY | I148: SOURCE EMPTY | J148: 0 | K148: =IF(J148=1,"ACCEPTED","WARRANT-CONSTITUTED") -> WARRANT-CONSTITUTED | L148: 0

Sheet Event Register
A1: Seventy-two decisive A2 events
A2: The wave selects twelve events from each chosen A1's forty-eight prospective slots: two endpoint families, three rig roles, and two unlike realization lineages.
A4: Event | B4: Root | C4: System | D4: Endpoint | E4: Rig role | F4: Method lineage | G4: Receiver-state coverage | H4: Required valid credit | I4: Required packages | J4: Accepted packages | K4: Observation | L4: Event state
A5: EV-ET-A-BAL-CHA-L1 | B5: ET-A | C5: MS-ET | D5: BAL | E5: CHALLENGE | F5: L1 | G5: All four MS-ET receiver states; frozen card crosswalk | H5: 1 | I5: 5 | J5: 0 | L5: =IF(AND(H5=1,J5=I5,K5<>""),"ADJUDICABLE","HOLD") -> HOLD
A6: EV-ET-A-BAL-CHA-L2 | B6: ET-A | C6: MS-ET | D6: BAL | E6: CHALLENGE | F6: L2 | G6: All four MS-ET receiver states; frozen card crosswalk | H6: 1 | I6: 5 | J6: 0 | L6: =IF(AND(H6=1,J6=I6,K6<>""),"ADJUDICABLE","HOLD") -> HOLD
A7: EV-ET-A-BAL-CON-L1 | B7: ET-A | C7: MS-ET | D7: BAL | E7: CONTROL | F7: L1 | G7: All four MS-ET receiver states; frozen card crosswalk | H7: 1 | I7: 5 | J7: 0 | L7: =IF(AND(H7=1,J7=I7,K7<>""),"ADJUDICABLE","HOLD") -> HOLD
A8: EV-ET-A-BAL-CON-L2 | B8: ET-A | C8: MS-ET | D8: BAL | E8: CONTROL | F8: L2 | G8: All four MS-ET receiver states; frozen card crosswalk | H8: 1 | I8: 5 | J8: 0 | L8: =IF(AND(H8=1,J8=I8,K8<>""),"ADJUDICABLE","HOLD") -> HOLD
A9: EV-ET-A-BAL-REC-L1 | B9: ET-A | C9: MS-ET | D9: BAL | E9: RECONSTRUCTION | F9: L1 | G9: All four MS-ET receiver states; frozen card crosswalk | H9: 1 | I9: 5 | J9: 0 | L9: =IF(AND(H9=1,J9=I9,K9<>""),"ADJUDICABLE","HOLD") -> HOLD
A10: EV-ET-A-BAL-REC-L2 | B10: ET-A | C10: MS-ET | D10: BAL | E10: RECONSTRUCTION | F10: L2 | G10: All four MS-ET receiver states; frozen card crosswalk | H10: 1 | I10: 5 | J10: 0 | L10: =IF(AND(H10=1,J10=I10,K10<>""),"ADJUDICABLE","HOLD") -> HOLD
A11: EV-ET-A-KEY-CHA-L1 | B11: ET-A | C11: MS-ET | D11: KEY | E11: CHALLENGE | F11: L1 | G11: All four MS-ET receiver states; frozen card crosswalk | H11: 1 | I11: 5 | J11: 0 | L11: =IF(AND(H11=1,J11=I11,K11<>""),"ADJUDICABLE","HOLD") -> HOLD
A12: EV-ET-A-KEY-CHA-L2 | B12: ET-A | C12: MS-ET | D12: KEY | E12: CHALLENGE | F12: L2 | G12: All four MS-ET receiver states; frozen card crosswalk | H12: 1 | I12: 5 | J12: 0 | L12: =IF(AND(H12=1,J12=I12,K12<>""),"ADJUDICABLE","HOLD") -> HOLD
A13: EV-ET-A-KEY-CON-L1 | B13: ET-A | C13: MS-ET | D13: KEY | E13: CONTROL | F13: L1 | G13: All four MS-ET receiver states; frozen card crosswalk | H13: 1 | I13: 5 | J13: 0 | L13: =IF(AND(H13=1,J13=I13,K13<>""),"ADJUDICABLE","HOLD") -> HOLD
A14: EV-ET-A-KEY-CON-L2 | B14: ET-A | C14: MS-ET | D14: KEY | E14: CONTROL | F14: L2 | G14: All four MS-ET receiver states; frozen card crosswalk | H14: 1 | I14: 5 | J14: 0 | L14: =IF(AND(H14=1,J14=I14,K14<>""),"ADJUDICABLE","HOLD") -> HOLD
A15: EV-ET-A-KEY-REC-L1 | B15: ET-A | C15: MS-ET | D15: KEY | E15: RECONSTRUCTION | F15: L1 | G15: All four MS-ET receiver states; frozen card crosswalk | H15: 1 | I15: 5 | J15: 0 | L15: =IF(AND(H15=1,J15=I15,K15<>""),"ADJUDICABLE","HOLD") -> HOLD
A16: EV-ET-A-KEY-REC-L2 | B16: ET-A | C16: MS-ET | D16: KEY | E16: RECONSTRUCTION | F16: L2 | G16: All four MS-ET receiver states; frozen card crosswalk | H16: 1 | I16: 5 | J16: 0 | L16: =IF(AND(H16=1,J16=I16,K16<>""),"ADJUDICABLE","HOLD") -> HOLD
... A76: EV-RT-B-KEY-REC-L2 | B76: RT-B | C76: MS-RT | D76: KEY | E76: RECONSTRUCTION | F76: L2 | G76: All four MS-RT receiver states; frozen card crosswalk | H76: 1 | I76: 5 | J76: 0 | L76: =IF(AND(H76=1,J76=I76,K76<>""),"ADJUDICABLE","HOLD") -> HOLD

Sheet Evidence Packages
A1: Three hundred sixty evidence packages
A2: Five separately accepted packages are required for every valid event. Missing evidence produces HOLD, never a favorable zero.
A4: Package | B4: Event | C4: Root | D4: System | E4: Package type | F4: Custodian | G4: Record hash | H4: Accepted | I4: Status
A5: EV-ET-A-BAL-CHA-L1-CONFI | B5: EV-ET-A-BAL-CHA-L1 | C5: ET-A | D5: MS-ET | E5: CONFIGURATION | F5: SOURCE EMPTY | H5: 0 | I5: =IF(H5=1,"ACCEPTED","OPEN") -> OPEN
A6: EV-ET-A-BAL-CHA-L1-METRO | B6: EV-ET-A-BAL-CHA-L1 | C6: ET-A | D6: MS-ET | E6: METROLOGY | F6: SOURCE EMPTY | H6: 0 | I6: =IF(H6=1,"ACCEPTED","OPEN") -> OPEN
A7: EV-ET-A-BAL-CHA-L1-CUSTO | B7: EV-ET-A-BAL-CHA-L1 | C7: ET-A | D7: MS-ET | E7: CUSTODY | F7: SOURCE EMPTY | H7: 0 | I7: =IF(H7=1,"ACCEPTED","OPEN") -> OPEN
A8: EV-ET-A-BAL-CHA-L1-SAFET | B8: EV-ET-A-BAL-CHA-L1 | C8: ET-A | D8: MS-ET | E8: SAFETY AND RIGHTS | F8: SOURCE EMPTY | H8: 0 | I8: =IF(H8=1,"ACCEPTED","OPEN") -> OPEN
A9: EV-ET-A-BAL-CHA-L1-INDEP | B9: EV-ET-A-BAL-CHA-L1 | C9: ET-A | D9: MS-ET | E9: INDEPENDENT REPLAY | F9: SOURCE EMPTY | H9: 0 | I9: =IF(H9=1,"ACCEPTED","OPEN") -> OPEN
A10: EV-ET-A-BAL-CHA-L2-CONFI | B10: EV-ET-A-BAL-CHA-L2 | C10: ET-A | D10: MS-ET | E10: CONFIGURATION | F10: SOURCE EMPTY | H10: 0 | I10: =IF(H10=1,"ACCEPTED","OPEN") -> OPEN
A11: EV-ET-A-BAL-CHA-L2-METRO | B11: EV-ET-A-BAL-CHA-L2 | C11: ET-A | D11: MS-ET | E11: METROLOGY | F11: SOURCE EMPTY | H11: 0 | I11: =IF(H11=1,"ACCEPTED","OPEN") -> OPEN
A12: EV-ET-A-BAL-CHA-L2-CUSTO | B12: EV-ET-A-BAL-CHA-L2 | C12: ET-A | D12: MS-ET | E12: CUSTODY | F12: SOURCE EMPTY | H12: 0 | I12: =IF(H12=1,"ACCEPTED","OPEN") -> OPEN
A13: EV-ET-A-BAL-CHA-L2-SAFET | B13: EV-ET-A-BAL-CHA-L2 | C13: ET-A | D13: MS-ET | E13: SAFETY AND RIGHTS | F13: SOURCE EMPTY | H13: 0 | I13: =IF(H13=1,"ACCEPTED","OPEN") -> OPEN
A14: EV-ET-A-BAL-CHA-L2-INDEP | B14: EV-ET-A-BAL-CHA-L2 | C14: ET-A | D14: MS-ET | E14: INDEPENDENT REPLAY | F14: SOURCE EMPTY | H14: 0 | I14: =IF(H14=1,"ACCEPTED","OPEN") -> OPEN
A15: EV-ET-A-BAL-CON-L1-CONFI | B15: EV-ET-A-BAL-CON-L1 | C15: ET-A | D15: MS-ET | E15: CONFIGURATION | F15: SOURCE EMPTY | H15: 0 | I15: =IF(H15=1,"ACCEPTED","OPEN") -> OPEN
A16: EV-ET-A-BAL-CON-L1-METRO | B16: EV-ET-A-BAL-CON-L1 | C16: ET-A | D16: MS-ET | E16: METROLOGY | F16: SOURCE EMPTY | H16: 0 | I16: =IF(H16=1,"ACCEPTED","OPEN") -> OPEN
... A364: EV-RT-B-KEY-REC-L2-INDEP | B364: EV-RT-B-KEY-REC-L2 | C364: RT-B | D364: MS-RT | E364: INDEPENDENT REPLAY | F364: SOURCE EMPTY | H364: 0 | I364: =IF(H364=1,"ACCEPTED","OPEN") -> OPEN

Sheet Authority
A1: Conserved private and public authority
A2: The selected private ceiling is one quarter of each system's first-cohort option. The public USD 12.0B reservation remains nested inside enabling authority.
A4: System | B4: Sentinel root | C4: System option (USD B) | D4: Root option (USD B) | E4: FRAME 15% | F4: MAKE 35% | G4: BREAK 35% | H4: TRANSFER 15% | I4: Kill-paid ceiling 85% | J4: Current paid
A5: MS-ET | B5: ET-A | C5: 2.0018985 | D5: =C5/Controls!$B$14 -> 0.50047462 | E5: =D5*Controls!$B$28 -> 0.075071193 | F5: =D5*Controls!$B$29 -> 0.17516612 | G5: =D5*Controls!$B$30 -> 0.17516612 | H5: =D5*Controls!$B$31 -> 0.075071193 | I5: =SUM(E5:G5) -> 0.42540343 | J5: =0 -> 0
A6: MS-CT | B6: CT-C | C6: 2.0659739 | D6: =C6/Controls!$B$14 -> 0.51649348 | E6: =D6*Controls!$B$28 -> 0.077474022 | F6: =D6*Controls!$B$29 -> 0.18077272 | G6: =D6*Controls!$B$30 -> 0.18077272 | H6: =D6*Controls!$B$31 -> 0.077474022 | I6: =SUM(E6:G6) -> 0.43901946 | J6: =0 -> 0
A7: MS-HC | B7: HC-A | C7: 1.2288866 | D7: =C7/Controls!$B$14 -> 0.30722165 | E7: =D7*Controls!$B$28 -> 0.046083248 | F7: =D7*Controls!$B$29 -> 0.10752758 | G7: =D7*Controls!$B$30 -> 0.10752758 | H7: =D7*Controls!$B$31 -> 0.046083248 | I7: =SUM(E7:G7) -> 0.26113841 | J7: =0 -> 0
A8: MS-LF | B8: LF-B | C8: 3.5976513 | D8: =C8/Controls!$B$14 -> 0.89941282 | E8: =D8*Controls!$B$28 -> 0.13491192 | F8: =D8*Controls!$B$29 -> 0.31479449 | G8: =D8*Controls!$B$30 -> 0.31479449 | H8: =D8*Controls!$B$31 -> 0.13491192 | I8: =SUM(E8:G8) -> 0.7645009 | J8: =0 -> 0
A9: MS-HU | B9: HU-A | C9: 3.4428498 | D9: =C9/Controls!$B$14 -> 0.86071245 | E9: =D9*Controls!$B$28 -> 0.12910687 | F9: =D9*Controls!$B$29 -> 0.30124936 | G9: =D9*Controls!$B$30 -> 0.30124936 | H9: =D9*Controls!$B$31 -> 0.12910687 | I9: =SUM(E9:G9) -> 0.73160558 | J9: =0 -> 0
A10: MS-RT | B10: RT-B | C10: 2.0103912 | D10: =C10/Controls!$B$14 -> 0.50259779 | E10: =D10*Controls!$B$28 -> 0.075389669 | F10: =D10*Controls!$B$29 -> 0.17590923 | G10: =D10*Controls!$B$30 -> 0.17590923 | H10: =D10*Controls!$B$31 -> 0.075389669 | I10: =SUM(E10:G10) -> 0.42720812 | J10: =0 -> 0
A11: TOTAL | B11: Six-root wave | C11: =SUM(C5:C10) -> 14.347651 | D11: =SUM(D5:D10) -> 3.5869128 | E11: =SUM(E5:E10) -> 0.53803692 | F11: =SUM(F5:F10) -> 1.2554195 | G11: =SUM(G5:G10) -> 1.2554195 | H11: =SUM(H5:H10) -> 0.53803692 | I11: =SUM(I5:I10) -> 3.0488759 | J11: =SUM(J5:J10) -> 0
A14: Public-method reservation
A15: Public account | B15: Reserved (USD B) | C15: Share | D15: State
A16: Six A0 method packages | B16: 1.5 | C16: =B16/SUM($B$16:$B$23) -> 0.125 | D16: WARRANT-CONSTITUTED
A17: Twenty-four receiver-state lines | B17: 4.2 | C17: =B17/SUM($B$16:$B$23) -> 0.35 | D17: WARRANT-CONSTITUTED
A18: One hundred forty-four method realizations | B18: 1.8 | C18: =B18/SUM($B$16:$B$23) -> 0.15 | D18: WARRANT-CONSTITUTED
A19: One hundred forty-four calibration chains | B19: 1.44 | C19: =B19/SUM($B$16:$B$23) -> 0.12 | D19: WARRANT-CONSTITUTED
A20: Reset and forensics | B20: 1.2 | C20: =B20/SUM($B$16:$B$23) -> 0.1 | D20: WARRANT-CONSTITUTED
A21: Rights and safety fixtures | B21: 0.72 | C21: =B21/SUM($B$16:$B$23) -> 0.06 | D21: WARRANT-CONSTITUTED
A22: Replay and cold-run capacity | B22: 0.54 | C22: =B22/SUM($B$16:$B$23) -> 0.045 | D22: WARRANT-CONSTITUTED
A23: Uncertainty reserve | B23: 0.6 | C23: =B23/SUM($B$16:$B$23) -> 0.05 | D23: WARRANT-CONSTITUTED
A24: TOTAL | B24: =SUM(B16:B23) -> 12 | C24: =SUM(C16:C23) -> 1 | D24: NESTED IN USD 80.0B

Sheet Stage Schedule
A1: Four-stage release and cancellation schedule
A2: Public and private authority move on different ledgers. The valid all-kill case stops after BREAK and withholds both public cold/replay and private TRANSFER.
A4: Stage | B4: Physical gate | C4: Public share | D4: Public increment (USD B) | E4: Private stage | F4: Private share | G4: Private increment (USD B) | H4: Cumulative paid ceiling | I4: Cancellation boundary | K4: Stage | L4: Cumulative ceiling
A5: S0 | B5: Method and station qualification | C5: 0.25 | D5: =C5*Controls!$B$12 -> 3 | E5: FRAME | F5: 0.15 | G5: =F5*Authority!$D$11 -> 0.53803692 | H5: =SUM($D$5:D5)+SUM($G$5:G5) -> 3.5380369 | I5: Failure stops all dependent construction | K5: S0 | L5: =H5 -> 3.5380369
A6: S1 | B6: Paired challenge/control construction accepted | C6: 0.5 | D6: =C6*Controls!$B$12 -> 6 | E6: MAKE | F6: 0.35 | G6: =F6*Authority!$D$11 -> 1.2554195 | H6: =SUM($D$5:D6)+SUM($G$5:G6) -> 10.793456 | I6: Failure holds affected system and returns unreleased authority | K6: S1 | L6: =H6 -> 10.793456
A7: S2 | B7: Twelve valid endpoint events and sixty packages per root | C7: 0 | D7: =C7*Controls!$B$12 -> 0 | E7: BREAK | F7: 0.35 | G7: =F7*Authority!$D$11 -> 1.2554195 | H7: =SUM($D$5:D7)+SUM($G$5:G7) -> 12.048876 | I7: Valid keystone failure kills; valid balance failure resizes | K7: S2 | L7: =H7 -> 12.048876
A8: S3 | B8: Cold outside reconstruction and final disposition | C8: 0.25 | D8: =C8*Controls!$B$12 -> 3 | E8: TRANSFER | F8: 0.15 | G8: =F8*Authority!$D$11 -> 0.53803692 | H8: =SUM($D$5:D8)+SUM($G$5:G8) -> 15.586913 | I8: Missing or disagreeing replay holds; no proof release | K8: S3 | L8: =H8 -> 15.586913

Sheet Cancellation Law
A1: Maximum-loss and cancellation law
A2: Cancellation preserves valid adverse evidence, returns unearned authority to the owning system, and forbids transfer to a surviving winner.
A4: Trigger | B4: Scope | C4: Required state | D4: Immediate action | E4: Paid artifact boundary | F4: Returned authority | G4: Evidence treatment | H4: Successor permitted
A5: Public method lineages disagree | B5: Method card/system | C5: HOLD | D5: Stop dependent events and freeze both implementations | E5: Accepted public work only | F5: All unreleased public and private authority | G5: Preserve both results; no averaging | H5: Only after independent method correction
A6: Station independence collision | B6: Station role/system | C6: SUSPEND | D6: Remove conflicted control, tooling, or custody chain | E6: Accepted separable artifacts only | F6: Unreleased system authority | G6: Preserve collision record | H6: Yes, with clean public reconstitution
A7: Balance upper bound below 1.00 | B7: Root configuration | C7: RESIZE | D7: Cancel current CF1 scale and reopen denominator-preserving design | E7: Through BREAK if event valid | F7: TRANSFER and unearned root authority | G7: Permanent adverse evidence | H7: Yes, same mechanism with new controlled baseline
A8: Keystone upper bound below 1.00 | B8: Root lineage | C8: KILL | D8: Terminate lineage and prohibit favorable retest | E8: Through BREAK if event valid | F8: TRANSFER and unearned root authority | G8: Permanent adverse evidence | H8: Only genuinely unlike replacement lineage
A9: Interval crosses 1.00 | B9: Root endpoint | C9: HOLD | D9: No disposition and no next-stage release | E9: Accepted artifacts to current stage | F9: All later authority | G9: Preserve uncertainty and missingness | H9: Yes, only preregistered additional work
A10: Missing event or package | B10: Root endpoint | C10: HOLD | D10: No credit and no imputed zero | E10: Accepted complete artifacts only | F10: All later authority | G10: Missing remains missing | H10: Yes, within attempt cap
A11: More than two invalidity attempts | B11: Root lineage | C11: KILL | D11: Terminate lineage | E11: Accepted valid artifacts only | F11: All unreleased root authority | G11: Preserve invalid attempts | H11: No successor from killed branch
A12: Ancestry collision | B12: Affected roots | C12: KILL | D12: Terminate collided lineage or both if attribution cannot be separated | E12: Accepted uncontaminated artifacts only | F12: All unreleased affected authority | G12: Preserve collision graph | H12: Only clean unlike recharter
A13: Safety or rights terminal breach | B13: Event/root | C13: KILL OR HOLD | D13: Inspector stops work; validity authority classifies cause | E13: No credit from protective intervention | F13: All later affected authority | G13: Preserve intervention as evidence | H13: Only after independent remedy
A14: One realization or station lost | B14: Method/system | C14: HOLD | D14: Do not collapse to surviving lineage | E14: Accepted completed work only | F14: Dependent later authority | G14: Preserve pre-loss record | H14: Yes, replace unlike capacity
A15: Both endpoints support | B15: Root | C15: BUILD PROOF ELIGIBLE | D15: Release only after four-root system cohort is non-HOLD | E15: Through TRANSFER after cold replay | F15: None within root option | G15: Support does not equal capability | H15: Yes, proof construction only
A16: Premature identity, award, or serial claim | B16: Program | C16: VOID | D16: Withdraw defective warrant and reopen clean competition | E16: No defective artifact payment | F16: All associated authority | G16: Preserve administrative breach | H16: Yes, after clean reissue

Sheet Maximum Loss
A1: Maximum paid exposure boundaries
A2: These are contractual ceilings, not forecasts. Public facilities remain public assets even when a candidate root is validly killed.
A4: Boundary | B4: Public paid (USD B) | C4: Private paid (USD B) | D4: Total paid (USD B) | E4: Unreleased (USD B) | F4: Protected failure reserve used | G4: Interpretation
A5: Method fails at first gate | B5: ='Stage Schedule'!D5 -> 3 | C5: ='Stage Schedule'!G5 -> 0.53803692 | D5: =B5+C5 -> 3.5380369 | E5: ='Stage Schedule'!H8-D5 -> 12.048876 | F5: =0 -> 0 | G5: Maximum common-method exposure before qualification
A6: Private work before any valid endpoint outcome | B6: =0 -> 0 | C6: =SUM('Stage Schedule'!G5:G6) -> 1.7934564 | D6: =B6+C6 -> 1.7934564 | E6: =Authority!D11-C6 -> 1.7934564 | F6: =0 -> 0 | G6: FRAME and MAKE only; public estate shown separately
A7: All six roots validly killed at BREAK | B7: =SUM('Stage Schedule'!D5:D7) -> 9 | C7: =SUM(Authority!E11:G11) -> 3.0488759 | D7: =B7+C7 -> 12.048876 | E7: ='Stage Schedule'!H8-D7 -> 3.5380369 | F7: =0 -> 0 | G7: Public 75% remains reusable; TRANSFER and cold/replay stay held
A8: Largest single root killed at BREAK | B8: =0 -> 0 | C8: =MAX(Authority!I5:I10) -> 0.7645009 | D8: =B8+C8 -> 0.7645009 | E8: =MAX(Authority!D5:D10)-C8 -> 0.13491192 | F8: =0 -> 0 | G8: Root-specific exposure excludes shared public estate
A9: All six roots support and transfer | B9: =Controls!B12 -> 12 | C9: =Authority!D11 -> 3.5869128 | D9: =B9+C9 -> 15.586913 | E9: =0 -> 0 | F9: =0 -> 0 | G9: Upper construction-wave ceiling; still no capability credit

Sheet Technology Agenda
A1: Mission-driven proving technology agenda
A2: The first construction wave funds public truth machinery and root-native science that normal markets have little reason to develop.
A4: Program | B4: System | C4: Selected root | D4: Technology objective | E4: First physical truth object | F4: Kill or redesign signal | G4: State
A5: T-ET-1 | B5: MS-ET | C5: ET-A | D5: Programmable wave-load and hydrostatic exchange fields | E5: Full-scale moving-interface load frame | F5: Custody or stability breaks below service rate | G5: WARRANT-CONSTITUTED
A6: T-ET-2 | B6: MS-ET | C6: ET-A | D6: Self-forming wet-to-dry terminal mechanics | E6: Breakable shore transition and ground-bearing field | F6: Largest connector loss defeats dry handoff | G6: WARRANT-CONSTITUTED
A7: T-ET-3 | B7: MS-ET | C7: ET-A | D7: Machine-readable custody under motion and damage | E7: Physical manifest and transfer truth system | F7: Mass or ownership becomes untraceable | G7: WARRANT-CONSTITUTED
A8: T-CT-1 | B8: MS-CT | C8: CT-C | D8: Reversible load-safe attachment to unknown facades | E8: Full-scale reconfigurable building skin | F8: Anchor load propagates damage | G8: WARRANT-CONSTITUTED
A9: T-CT-2 | B9: MS-CT | C9: CT-C | D9: Robotic utility insertion through smoke and contamination | E9: Fault-insertable occupied utility block | F9: Isolation cannot prevent cross-domain casualty | G9: WARRANT-CONSTITUTED
A10: T-CT-3 | B10: MS-CT | C10: CT-C | D10: Human-safe temporary lift, stair, power, and water trunks | E10: Instrumented multi-utility spine | F10: Access rate or lawful egress falls below threshold | G10: WARRANT-CONSTITUTED
A11: T-HC-1 | B11: MS-HC | C11: HC-A | D11: High-duty thermal structures and rapid regenerative flight | E11: Thermal-cycle wing and propulsion article | F11: Duty cycle requires hidden fleet multiplication | G11: WARRANT-CONSTITUTED
A12: T-HC-2 | B12: MS-HC | C12: HC-A | D12: Sparse plume tomography without common autonomy | E12: Independent atmospheric state fields | F12: State disagreement prevents attributed effect | G12: WARRANT-CONSTITUTED
A13: T-HC-3 | B13: MS-HC | C13: HC-A | D13: Precision multi-agent fluid deposition reconstruction | E13: Full-scale drop-field metrology | F13: Delivered fluid cannot be tied to held edge | G13: WARRANT-CONSTITUTED
A14: T-LF-1 | B14: MS-LF | C14: LF-B | D14: Rapid-bore geothermal under uncertain geology | E14: Instrumented multi-geology bore and circulation field | F14: Day-21 firm output causes drawdown or induced hazard | G14: WARRANT-CONSTITUTED
A15: T-LF-2 | B15: MS-LF | C15: LF-B | D15: Coupled geochemistry, treatment, and residual closure | E15: Closed heat-water-brine loop | F15: Scaling or residual custody breaks complete service | G15: WARRANT-CONSTITUTED
... A22: T-RT-3 | B22: MS-RT | C22: RT-B | D22: Adaptive microfactory energy and process control | E22: Multi-process islanded production mesh | F22: Qualified output per MWh falls below threshold | G22: WARRANT-CONSTITUTED

Sheet Warrant State
A1: Construction-wave state ledger
A2: Selection and authority are real program decisions. They do not create a contract, site, serial, observation, payment, or capability state.
A4: Object | B4: Quantity | C4: State now | D4: Authorized transition | E4: Still prohibited | F4: Owning warrant
A5: Sentinel roots | B5: 6 | C5: WARRANT-CONSTITUTED | D5: Compete bounded A2 packages | E5: Winner, article, or proof inference | F5: Mission System Command
A6: Endpoint definitions | B6: 12 | C6: FROZEN | D6: Publish preregistered thresholds | E6: Outcome-aware amendment | F6: Root Disposition Board
A7: Station nuclei | B7: 18 | C7: WARRANT-CONSTITUTED | D7: Compete functional public stations | E7: Site or operator inference | F7: Resilience Proving Service
A8: Initial station lanes | B8: 36 | C8: WARRANT-CONSTITUTED | D8: One root plus one regeneration lane per station | E8: Three held root lanes per station | F8: Proving commands
A9: Receiver states | B9: 24 | C9: FROZEN | D9: Construct public state lines | E9: Candidate-defined receiver truth | F9: Mission System Commands
A10: Method cards | B10: 72 | C10: FROZEN | D10: Construct unlike realizations | E10: Shared candidate control code | F10: Standards and Custody Command
A11: Method realizations | B11: 144 | C11: WARRANT-CONSTITUTED | D11: Compete two unlike lineages per card | E11: Acceptance before evidence | F11: Worlds/Counterfactual Commands
A12: Decisive events | B12: 72 | C12: HELD | D12: Schedule only after all antecedent warrants | E12: Counting prospective slots as evidence | F12: Event validity authority
A13: Evidence packages | B13: 360 | C13: SOURCE EMPTY | D13: Populate only from valid physical events | E13: Imputation or favorable averaging | F13: Standards and Custody Command
A14: Private option ceiling | B14: =Authority!D11 -> 3.5869128 | C14: RESERVED | D14: Release four artifact payments | E14: Transfer between roots | F14: Program Comptroller
A15: Public reserve | B15: 12 | C15: RESERVED | D15: Release 25/50/0/25 by public gates | E15: Add to USD 80.0B account | F15: Program Comptroller
A16: Obligations and payments | B16: 0 | C16: HELD | D16: None until named warrant succession | E16: Schedule-to-payment conversion | F16: Program Comptroller
A17: Capability and production credit | B17: 0 | C17: HELD | D17: None in A2 | E17: Prototype-to-force conversion | F17: Capability authority
A18: Exterior rendering | B18: 0 | C18: HELD | D18: None before representative geometry | E18: Form choosing mechanism | F18: Design authority

Sheet Stress Tests
A1: Architecture stress tests
A2: Each case asks whether one attractive shortcut can preserve the selected construction constitution. PASS means the law rejects the shortcut or preserves the invariant.
A4: Test | B4: Perturbation | C4: Expected response | D4: Formula result | E4: Status | F4: Why it matters
A5: ST-01 | B5: Only five systems enter | C5: FAIL | D5: =IF(5=Controls!B15,"PASS","FAIL") -> FAIL | E5: =IF(D5=C5,"PASS","FAIL") -> PASS | F5: Reject partial portfolio
A6: ST-02 | B6: Balance endpoint omitted | C6: FAIL | D6: =IF(1=Controls!B20,"PASS","FAIL") -> FAIL | E6: =IF(D6=C6,"PASS","FAIL") -> PASS | F6: Reject mechanism-only testing
A7: ST-03 | B7: Keystone endpoint omitted | C7: FAIL | D7: =IF(1=Controls!B20,"PASS","FAIL") -> FAIL | E7: =IF(D7=C7,"PASS","FAIL") -> PASS | F7: Reject scale-only testing
A8: ST-04 | B8: Only two rig roles | C8: FAIL | D8: =IF(2=Controls!B21,"PASS","FAIL") -> FAIL | E8: =IF(D8=C8,"PASS","FAIL") -> PASS | F8: Preserve cold outside reconstruction
A9: ST-05 | B9: One method lineage | C9: FAIL | D9: =IF(1=Controls!B19,"PASS","FAIL") -> FAIL | E9: =IF(D9=C9,"PASS","FAIL") -> PASS | F9: Prevent self-confirming public truth
A10: ST-06 | B10: Twenty-four roots built | C10: FAIL | D10: =IF(24=Controls!B16,"PASS","FAIL") -> FAIL | E10: =IF(D10=C10,"PASS","FAIL") -> PASS | F10: Reject excess first-wave exposure
A11: ST-07 | B11: Public reserve raised to USD 13B | C11: FAIL | D11: =IF(13<=Controls!B12,"PASS","FAIL") -> FAIL | E11: =IF(D11=C11,"PASS","FAIL") -> PASS | F11: Conserve nested authority
A12: ST-08 | B12: Private wave exceeds selected six-root options | C12: FAIL | D12: =IF(4<=Authority!D11,"PASS","FAIL") -> FAIL | E12: =IF(D12=C12,"PASS","FAIL") -> PASS | F12: Preserve root-specific ceiling
A13: ST-09 | B13: TRANSFER paid after valid keystone kill | C13: FAIL | D13: =IF(Authority!H11=0,"PASS","FAIL") -> FAIL | E13: =IF(D13=C13,"PASS","FAIL") -> PASS | F13: Withhold unearned cold transfer
A14: ST-10 | B14: Failure reserve used for ordinary construction | C14: FAIL | D14: =IF(1=0,"PASS","FAIL") -> FAIL | E14: =IF(D14=C14,"PASS","FAIL") -> PASS | F14: Protect invalidity and reconstitution capacity
A15: ST-11 | B15: One active and one regeneration lane per station | C15: PASS | D15: =IF(AND(Controls!B25=1,Controls!B26=1),"PASS","FAIL") -> PASS | E15: =IF(D15=C15,"PASS","FAIL") -> PASS | F15: Minimum functional nucleus
A16: ST-12 | B16: Three future root lanes remain held | C16: PASS | D16: =IF(Controls!B27=3,"PASS","FAIL") -> PASS | E16: =IF(D16=C16,"PASS","FAIL") -> PASS | F16: Preserve four-root expansion without building it
A17: ST-13 | B17: Current obligations remain zero | C17: PASS | D17: =IF(Controls!B37=0,"PASS","FAIL") -> PASS | E17: =IF(D17=C17,"PASS","FAIL") -> PASS | F17: Authority is not a contract
A18: ST-14 | B18: Current capability credit remains zero | C18: PASS | D18: =IF(Controls!B38=0,"PASS","FAIL") -> PASS | E18: =IF(D18=C18,"PASS","FAIL") -> PASS | F18: Construction is not capability
A19: ST-15 | B19: Sites remain source empty | C19: PASS | D19: =IF(Controls!B40=0,"PASS","FAIL") -> PASS | E19: =IF(D19=C19,"PASS","FAIL") -> PASS | F19: No geography inferred
A20: ST-16 | B20: Exterior rendering remains held | C20: PASS | D20: =IF(Controls!B39=0,"PASS","FAIL") -> PASS | E20: =IF(D20=C20,"PASS","FAIL") -> PASS | F20: No premature form lock

Sheet Mutations
A1: Restored mutation register
A2: The builder changes fourteen controlling inputs one at a time, verifies that the master audit fails, and restores the authoritative value before export.
A4: Mutation | B4: Target | C4: Perturbation | D4: Expected master state | E4: Observed in build | F4: Restored | G4: Purpose
A5: M01 | B5: Controls!B5 | C5: First tranche +1 | D5: FAIL | E5: DETECTED | F5: YES | G5: Tranche conservation
A6: M02 | B6: Controls!B6 | C6: Mission systems +1 | D6: FAIL | E6: DETECTED | F6: YES | G6: Account conservation
A7: M03 | B7: Controls!B10 | C7: Failure reserve +1 | D7: FAIL | E7: DETECTED | F7: YES | G7: Reserve protection
A8: M04 | B8: Controls!B12 | C8: Public method +1 | D8: FAIL | E8: DETECTED | F8: YES | G8: Nested public ceiling
A9: M05 | B9: Controls!B13 | C9: Cohort options +1 | D9: FAIL | E9: DETECTED | F9: YES | G9: Inherited private ceiling
A10: M06 | B10: Controls!B15 | C10: Mission systems −1 | D10: FAIL | E10: DETECTED | F10: YES | G10: All-six requirement
A11: M07 | B11: Controls!B16 | C11: Selected roots +1 | D11: FAIL | E11: DETECTED | F11: YES | G11: One-root-per-system rule
A12: M08 | B12: Controls!B17 | C12: Receiver states +1 | D12: FAIL | E12: DETECTED | F12: YES | G12: Receiver denominator
A13: M09 | B13: Controls!B18 | C13: Method cards +1 | D13: FAIL | E13: DETECTED | F13: YES | G13: Method-card denominator
A14: M10 | B14: Controls!B19 | C14: Lineages −1 | D14: FAIL | E14: DETECTED | F14: YES | G14: Unlike realization rule
A15: M11 | B15: Controls!B20 | C15: Endpoints −1 | D15: FAIL | E15: DETECTED | F15: YES | G15: Paired endpoint rule
... A18: M14 | B18: Controls!B23 | C18: Packages per event −1 | D18: FAIL | E18: DETECTED | F18: YES | G18: Evidence completeness

Sheet Audit
A1: Terminal audit
A2: The master result fails if any invariant below fails. Checks use fixed authoritative boundaries rather than reading their expected answer from the same input.
A4: Master result | B4: =IF(COUNTIF(E7:E70,"PASS")=64,"PASS","FAIL") -> PASS
A6: Audit | B6: Requirement | C6: Expected | D6: Actual | E6: Status
A7: A01 | B7: First tranche conserved | C7: 200 | D7: =Controls!B5 -> 200 | E7: =IF(ISNUMBER(C7),IF(AND(ISNUMBER(D7),ABS(D7-C7)<0.000001),"PASS","FAIL"),IF(D7=C7,"PASS","FAIL")) -> PASS
A8: A02 | B8: Five accounts sum to tranche | C8: 200 | D8: =SUM(Controls!B6:B10) -> 200 | E8: =IF(ISNUMBER(C8),IF(AND(ISNUMBER(D8),ABS(D8-C8)<0.000001),"PASS","FAIL"),IF(D8=C8,"PASS","FAIL")) -> PASS
A9: A03 | B9: Public/enabling account unchanged | C9: 80 | D9: =Controls!B11 -> 80 | E9: =IF(ISNUMBER(C9),IF(AND(ISNUMBER(D9),ABS(D9-C9)<0.000001),"PASS","FAIL"),IF(D9=C9,"PASS","FAIL")) -> PASS
A10: A04 | B10: Public-method reserve unchanged | C10: 12 | D10: =Controls!B12 -> 12 | E10: =IF(ISNUMBER(C10),IF(AND(ISNUMBER(D10),ABS(D10-C10)<0.000001),"PASS","FAIL"),IF(D10=C10,"PASS","FAIL")) -> PASS
A11: A05 | B11: Public method remains nested | C11: PASS | D11: =IF(Controls!B12<=Controls!B11,"PASS","FAIL") -> PASS | E11: =IF(ISNUMBER(C11),IF(AND(ISNUMBER(D11),ABS(D11-C11)<0.000001),"PASS","FAIL"),IF(D11=C11,"PASS","FAIL")) -> PASS
A12: A06 | B12: Cohort stageable ceiling unchanged | C12: 14.347651 | D12: =Controls!B13 -> 14.347651 | E12: =IF(ISNUMBER(C12),IF(AND(ISNUMBER(D12),ABS(D12-C12)<0.000001),"PASS","FAIL"),IF(D12=C12,"PASS","FAIL")) -> PASS
A13: A07 | B13: Roots per system | C13: 4 | D13: =Controls!B14 -> 4 | E13: =IF(ISNUMBER(C13),IF(AND(ISNUMBER(D13),ABS(D13-C13)<0.000001),"PASS","FAIL"),IF(D13=C13,"PASS","FAIL")) -> PASS
A14: A08 | B14: Mission systems | C14: 6 | D14: =Controls!B15 -> 6 | E14: =IF(ISNUMBER(C14),IF(AND(ISNUMBER(D14),ABS(D14-C14)<0.000001),"PASS","FAIL"),IF(D14=C14,"PASS","FAIL")) -> PASS
