Workbook

Sheet Summary
A2: Cohort-one numerical interval solvency
A4: Pass 237 closes the numerical question negatively: all six forms require redesign and bounded physical coefficients.
A6: Decision | B6: Decision | C6: Decision | D6: Decision | E6: Decision | F6: Decision | M6: Form | N6: Current maximum interval | O6: Required interval
M7: ET-A-A | N7: ='Form Results'!E7 -> 0.013492203 | O7: =Inputs!$B$7 -> 0.025
A8: Method | B8: NIS-1 | C8: Lower capacity must meet upper requirement under source-specific intervals | M8: CT-C-B | N8: ='Form Results'!E8 -> 0.014084507 | O8: =Inputs!$B$7 -> 0.025
A9: Selected two-sided screen | B9: =Inputs!B7 -> 0.025 | C9: 2.5% capacity downside and 2.5% requirement upside | M9: HC-A-C | N9: ='Form Results'!E9 -> 0.014354067 | O9: =Inputs!$B$7 -> 0.025
A10: Required raw capacity ratio | B10: =Inputs!B10 -> 1.0512821 | C10: direct arithmetic | M10: LF-B-A | N10: ='Form Results'!E10 -> 0.013413763 | O10: =Inputs!$B$7 -> 0.025
A11: Forms closing all worlds | B11: =COUNTIF('Form Results'!$K$7:$K$12,"CLOSE") -> 0 | C11: none | M11: HU-A-B | N11: ='Form Results'!E11 -> 0.014292755 | O11: =Inputs!$B$7 -> 0.025
A12: Largest-loss accounts | B12: =COUNTIFS('Closure Cells'!$D$7:$D$126,"LARGEST_CELL_LOSS",'Closure Cells'!$O$7:$O$126,"CLOSE")&" close / "&COUNTIFS('Closure Cells'!$D$7:$D$126,"LARGEST_CELL_LOSS",'Closure Cells'!$O$7:$O$126,"FAIL")&" fail" -> 3 close / 21 fail | C12: twenty-one rating orders | M12: RT-B-C | N12: ='Form Results'!E12 -> 0.012738854 | O12: =Inputs!$B$7 -> 0.025
A13: Unbounded cells | B13: 72 | C13: fatal-keystone, cold-start and thermal states
A16: Portfolio consequence | B16: Portfolio consequence | C16: Portfolio consequence | D16: Portfolio consequence | E16: Portfolio consequence | F16: Portfolio consequence
A18: ET-A-A | B18: Service | C18: 247 t/h exchange path | D18: thermal duty and keystone retention still open
A19: CT-C-B | B19: Energy | C19: 7.36 MW isolated cell | D19: occupied-zone heat and anchor propagation still open
A20: HC-A-C | B20: Service | C20: 27.1 km/day held-line sector | D20: hot-zone duty and local-control loss still open
A21: LF-B-A | B21: Mass | C21: 4.08 kt access slot | D21: reservoir enthalpy and brine closure still open
A22: HU-A-B | B22: Mass | C22: 7.51 kt access cell | D22: clinical thermal continuity and bypass loss still open
A23: RT-B-C | B23: Energy | C23: 27.2 MW process cell | D23: process heat and trainlet isolation still open
A26: Authority boundary | B26: Authority boundary | C26: Authority boundary | D26: Authority boundary | E26: Authority boundary | F26: Authority boundary
A28: Measured coefficients | B28: 0 | C28: all thirty-six remain open
A29: Accepted baselines | B29: 0 | C29: design arithmetic is not evidence
A30: New obligation | B30: 0 | C30: USD179M obligation and USD359M reserve remain conserved
A31: Rendering authority | B31: 0 | C31: geometry, structure and safe-state closure remain next

Sheet Decision Tests
A2: Numerical closure method
A4: The selected method must expose both sides of the interval and preserve source-specific unknowns.
A6: Candidate | B6: Method | C6: Two-sided interval | D6: Root-specific | E6: No midpoint | F6: Missing holds | G6: Four worlds | H6: Five accounts | I6: Sensitivity | J6: No authority conversion | K6: Passed | L6: Disposition
A7: C1 | B7: Inherited one-sided 2.5% capacity screen | C7: 0 | D7: 1 | E7: 1 | F7: 1 | G7: 0 | H7: 0 | I7: 1 | J7: 1 | K7: =SUM(C7:J7) -> 5 | L7: =IF(K7=8,"SELECT","REJECT") -> REJECT
A8: C2 | B8: Common 5% gross reserve | C8: 1 | D8: 0 | E8: 1 | F8: 1 | G8: 0 | H8: 1 | I8: 1 | J8: 1 | K8: =SUM(C8:J8) -> 6 | L8: =IF(K8=8,"SELECT","REJECT") -> REJECT
A9: C3 | B9: Midpoint model with assigned priors | C9: 1 | D9: 1 | E9: 0 | F9: 0 | G9: 1 | H9: 1 | I9: 1 | J9: 1 | K9: =SUM(C9:J9) -> 6 | L9: =IF(K9=8,"SELECT","REJECT") -> REJECT
A10: C4 | B10: Unbounded worst case as automatic rejection | C10: 1 | D10: 1 | E10: 1 | F10: 0 | G10: 1 | H10: 1 | I10: 0 | J10: 1 | K10: =SUM(C10:J10) -> 6 | L10: =IF(K10=8,"SELECT","REJECT") -> REJECT
A11: C5 | B11: Source-specific interval budgets plus 2.5/2.5 design rule | C11: 1 | D11: 1 | E11: 1 | F11: 1 | G11: 1 | H11: 1 | I11: 1 | J11: 1 | K11: =SUM(C11:J11) -> 8 | L11: =IF(K11=8,"SELECT","REJECT") -> SELECT
A14: Authoritative decision | B14: Authoritative decision | C14: Authoritative decision | D14: Authoritative decision | E14: Authoritative decision | F14: Authoritative decision | G14: Authoritative decision | H14: Authoritative decision | I14: Authoritative decision | J14: Authoritative decision | K14: Authoritative decision | L14: Authoritative decision
A16: Decision | B16: NIS-1 | C16: Adopt two-sided interval solvency and issue twenty-one account uprates across all six forms
A17: Negative result | B17: 0 of 6 | C17: No form closes all five accounts in all four worlds
A18: Superseded claim | B18: Pass 219 | C18: One-sided 2.5% design close is no longer sufficient numerical closure
A19: Present authority | B19: DESIGN REDESIGN / TEST | C19: No evidence, selection, MAKE, REP-4, production or rendering authority

Sheet Form Results
A2: Cohort-one numerical disposition
A4: No form closes. All six need rating changes and bounded fatal, cold-start and thermal coefficients.
A6: Form | B6: Root | C6: Governing account | D6: Minimum loss ratio | E6: Maximum symmetric half-width | F6: Nominal accounts closed | G6: Loss accounts closed | H6: Loss accounts failed | I6: Unbounded cells | J6: Open coefficients | K6: Baseline disposition | L6: Governing redesign
A7: ET-A-A | B7: ET-A | C7: Service | D7: =MIN('Loss Rating Orders'!$G$7:$G$10) -> 1.0273535 | E7: =MIN('Loss Rating Orders'!$H$7:$H$10) -> 0.013492203 | F7: =COUNTIFS('Closure Cells'!$B$7:$B$126,A7,'Closure Cells'!$D$7:$D$126,"NOMINAL",'Closure Cells'!$O$7:$O$126,"CLOSE") -> 4 | G7: =COUNTIFS('Closure Cells'!$B$7:$B$126,A7,'Closure Cells'!$D$7:$D$126,"LARGEST_CELL_LOSS",'Closure Cells'!$O$7:$O$126,"CLOSE") -> 1 | H7: =COUNTIFS('Closure Cells'!$B$7:$B$126,A7,'Closure Cells'!$D$7:$D$126,"LARGEST_CELL_LOSS",'Closure Cells'!$O$7:$O$126,"FAIL") -> 3 | I7: =COUNTIFS('Closure Cells'!$B$7:$B$126,A7,'Closure Cells'!$O$7:$O$126,"HOLD") -> 12 | J7: =COUNTIFS('Coefficient Register'!$B$7:$B$42,A7,'Coefficient Register'!$K$7:$K$42,"OPEN") -> 6 | K7: =IF(AND(F7=4,G7=4,H7=0,I7=0,J7=0),"CLOSE","REDESIGN / HOLD") -> REDESIGN / HOLD | L7: Raise each complete exchange path from 241 to at least 247 t/h before thermal and keystone closure.
A8: CT-C-B | B8: CT-C | C8: Energy | D8: =MIN('Loss Rating Orders'!$G$11:$G$14) -> 1.0285714 | E8: =MIN('Loss Rating Orders'!$H$11:$H$14) -> 0.014084507 | F8: =COUNTIFS('Closure Cells'!$B$7:$B$126,A8,'Closure Cells'!$D$7:$D$126,"NOMINAL",'Closure Cells'!$O$7:$O$126,"CLOSE") -> 4 | G8: =COUNTIFS('Closure Cells'!$B$7:$B$126,A8,'Closure Cells'!$D$7:$D$126,"LARGEST_CELL_LOSS",'Closure Cells'!$O$7:$O$126,"CLOSE") -> 1 | H8: =COUNTIFS('Closure Cells'!$B$7:$B$126,A8,'Closure Cells'!$D$7:$D$126,"LARGEST_CELL_LOSS",'Closure Cells'!$O$7:$O$126,"FAIL") -> 3 | I8: =COUNTIFS('Closure Cells'!$B$7:$B$126,A8,'Closure Cells'!$O$7:$O$126,"HOLD") -> 12 | J8: =COUNTIFS('Coefficient Register'!$B$7:$B$42,A8,'Coefficient Register'!$K$7:$K$42,"OPEN") -> 6 | K8: =IF(AND(F8=4,G8=4,H8=0,I8=0,J8=0),"CLOSE","REDESIGN / HOLD") -> REDESIGN / HOLD | L8: Raise each isolated generation cell from 7.20 to at least 7.36 MW before thermal and attachment closure.
A9: HC-A-C | B9: HC-A | C9: Service | D9: =MIN('Loss Rating Orders'!$G$15:$G$18) -> 1.0291262 | E9: =MIN('Loss Rating Orders'!$H$15:$H$18) -> 0.014354067 | F9: =COUNTIFS('Closure Cells'!$B$7:$B$126,A9,'Closure Cells'!$D$7:$D$126,"NOMINAL",'Closure Cells'!$O$7:$O$126,"CLOSE") -> 4 | G9: =COUNTIFS('Closure Cells'!$B$7:$B$126,A9,'Closure Cells'!$D$7:$D$126,"LARGEST_CELL_LOSS",'Closure Cells'!$O$7:$O$126,"CLOSE") -> 0 | H9: =COUNTIFS('Closure Cells'!$B$7:$B$126,A9,'Closure Cells'!$D$7:$D$126,"LARGEST_CELL_LOSS",'Closure Cells'!$O$7:$O$126,"FAIL") -> 4 | I9: =COUNTIFS('Closure Cells'!$B$7:$B$126,A9,'Closure Cells'!$O$7:$O$126,"HOLD") -> 12 | J9: =COUNTIFS('Coefficient Register'!$B$7:$B$42,A9,'Coefficient Register'!$K$7:$K$42,"OPEN") -> 6 | K9: =IF(AND(F9=4,G9=4,H9=0,I9=0,J9=0),"CLOSE","REDESIGN / HOLD") -> REDESIGN / HOLD | L9: Raise each surviving held-line sector from 26.5 to at least 27.1 km/day before hot-zone closure.
A10: LF-B-A | B10: LF-B | C10: Mass | D10: =MIN('Loss Rating Orders'!$G$19:$G$22) -> 1.0271923 | E10: =MIN('Loss Rating Orders'!$H$19:$H$22) -> 0.013413763 | F10: =COUNTIFS('Closure Cells'!$B$7:$B$126,A10,'Closure Cells'!$D$7:$D$126,"NOMINAL",'Closure Cells'!$O$7:$O$126,"CLOSE") -> 4 | G10: =COUNTIFS('Closure Cells'!$B$7:$B$126,A10,'Closure Cells'!$D$7:$D$126,"LARGEST_CELL_LOSS",'Closure Cells'!$O$7:$O$126,"CLOSE") -> 0 | H10: =COUNTIFS('Closure Cells'!$B$7:$B$126,A10,'Closure Cells'!$D$7:$D$126,"LARGEST_CELL_LOSS",'Closure Cells'!$O$7:$O$126,"FAIL") -> 4 | I10: =COUNTIFS('Closure Cells'!$B$7:$B$126,A10,'Closure Cells'!$O$7:$O$126,"HOLD") -> 12 | J10: =COUNTIFS('Coefficient Register'!$B$7:$B$42,A10,'Coefficient Register'!$K$7:$K$42,"OPEN") -> 6 | K10: =IF(AND(F10=4,G10=4,H10=0,I10=0,J10=0),"CLOSE","REDESIGN / HOLD") -> REDESIGN / HOLD | L10: Raise each access-slot allowance from 3.99 to at least 4.08 kt before reservoir and brine closure.
A11: HU-A-B | B11: HU-A | C11: Mass | D11: =MIN('Loss Rating Orders'!$G$23:$G$26) -> 1.029 | E11: =MIN('Loss Rating Orders'!$H$23:$H$26) -> 0.014292755 | F11: =COUNTIFS('Closure Cells'!$B$7:$B$126,A11,'Closure Cells'!$D$7:$D$126,"NOMINAL",'Closure Cells'!$O$7:$O$126,"CLOSE") -> 4 | G11: =COUNTIFS('Closure Cells'!$B$7:$B$126,A11,'Closure Cells'!$D$7:$D$126,"LARGEST_CELL_LOSS",'Closure Cells'!$O$7:$O$126,"CLOSE") -> 1 | H11: =COUNTIFS('Closure Cells'!$B$7:$B$126,A11,'Closure Cells'!$D$7:$D$126,"LARGEST_CELL_LOSS",'Closure Cells'!$O$7:$O$126,"FAIL") -> 3 | I11: =COUNTIFS('Closure Cells'!$B$7:$B$126,A11,'Closure Cells'!$O$7:$O$126,"HOLD") -> 12 | J11: =COUNTIFS('Coefficient Register'!$B$7:$B$42,A11,'Coefficient Register'!$K$7:$K$42,"OPEN") -> 6 | K11: =IF(AND(F11=4,G11=4,H11=0,I11=0,J11=0),"CLOSE","REDESIGN / HOLD") -> REDESIGN / HOLD | L11: Raise each access-cell allowance from 7.35 to at least 7.51 kt without deleting a care line.
A12: RT-B-C | B12: RT-B | C12: Energy | D12: =MIN('Loss Rating Orders'!$G$27:$G$30) -> 1.0258065 | E12: =MIN('Loss Rating Orders'!$H$27:$H$30) -> 0.012738854 | F12: =COUNTIFS('Closure Cells'!$B$7:$B$126,A12,'Closure Cells'!$D$7:$D$126,"NOMINAL",'Closure Cells'!$O$7:$O$126,"CLOSE") -> 4 | G12: =COUNTIFS('Closure Cells'!$B$7:$B$126,A12,'Closure Cells'!$D$7:$D$126,"LARGEST_CELL_LOSS",'Closure Cells'!$O$7:$O$126,"CLOSE") -> 0 | H12: =COUNTIFS('Closure Cells'!$B$7:$B$126,A12,'Closure Cells'!$D$7:$D$126,"LARGEST_CELL_LOSS",'Closure Cells'!$O$7:$O$126,"FAIL") -> 4 | I12: =COUNTIFS('Closure Cells'!$B$7:$B$126,A12,'Closure Cells'!$O$7:$O$126,"HOLD") -> 12 | J12: =COUNTIFS('Coefficient Register'!$B$7:$B$42,A12,'Coefficient Register'!$K$7:$K$42,"OPEN") -> 6 | K12: =IF(AND(F12=4,G12=4,H12=0,I12=0,J12=0),"CLOSE","REDESIGN / HOLD") -> REDESIGN / HOLD | L12: Raise each isolated process-energy cell from 26.5 to at least 27.2 MW before process-heat closure.

Sheet Closure Cells
A2: Physical account interval closure
A4: A cell closes only when lower capacity meets upper requirement. Missing bounds order HOLD, never zero or midpoint substitution.
A6: Cell | B6: Form | C6: Account | D6: World | E6: Unit | F6: Raw capacity | G6: Capacity downside | H6: Raw requirement | I6: Requirement upside | J6: Lower capacity | K6: Upper requirement | L6: Interval ratio | M6: Maximum symmetric half-width | N6: Data state | O6: Disposition
A7: ET-A-A-SERVICE-NOMINAL | B7: ET-A-A | C7: Service | D7: NOMINAL | E7: t/h | F7: ='Source Inputs'!H7 -> 482 | G7: =Inputs!$B$7 -> 0.025 | H7: ='Source Inputs'!I7 -> 234.58333 | I7: =Inputs!$B$8 -> 0.025 | J7: =IF(ISNUMBER(F7),F7*(1-G7),"") -> 469.95 | K7: =IF(ISNUMBER(H7),H7*(1+I7),"") -> 240.44792 | L7: =IF(AND(ISNUMBER(J7),ISNUMBER(K7),K7>0),J7/K7,"") -> 1.9544773 | M7: =IF(AND(ISNUMBER(F7),ISNUMBER(H7),H7>0),(F7/H7-1)/(F7/H7+1),"") -> 0.34527271 | N7: =IF(AND(ISNUMBER(F7),ISNUMBER(H7)) ,"BOUNDED","UNBOUNDED") -> BOUNDED | O7: =IF(N7="UNBOUNDED","HOLD",IF(L7>=Inputs!$B$9,"CLOSE","FAIL")) -> CLOSE
A8: ET-A-A-SERVICE-LARGEST_CELL_LOSS | B8: ET-A-A | C8: Service | D8: LARGEST_CELL_LOSS | E8: t/h | F8: ='Source Inputs'!J7 -> 241 | G8: =Inputs!$B$7 -> 0.025 | H8: ='Source Inputs'!K7 -> 234.58333 | I8: =Inputs!$B$8 -> 0.025 | J8: =IF(ISNUMBER(F8),F8*(1-G8),"") -> 234.975 | K8: =IF(ISNUMBER(H8),H8*(1+I8),"") -> 240.44792 | L8: =IF(AND(ISNUMBER(J8),ISNUMBER(K8),K8>0),J8/K8,"") -> 0.97723866 | M8: =IF(AND(ISNUMBER(F8),ISNUMBER(H8),H8>0),(F8/H8-1)/(F8/H8+1),"") -> 0.013492203 | N8: =IF(AND(ISNUMBER(F8),ISNUMBER(H8)) ,"BOUNDED","UNBOUNDED") -> BOUNDED | O8: =IF(N8="UNBOUNDED","HOLD",IF(L8>=Inputs!$B$9,"CLOSE","FAIL")) -> FAIL
A9: ET-A-A-SERVICE-FATAL_KEYSTONE | B9: ET-A-A | C9: Service | D9: FATAL_KEYSTONE | E9: t/h | G9: =Inputs!$B$7 -> 0.025 | H9: ='Source Inputs'!I7 -> 234.58333 | I9: =Inputs!$B$8 -> 0.025 | J9: =IF(ISNUMBER(F9),F9*(1-G9),"") | K9: =IF(ISNUMBER(H9),H9*(1+I9),"") -> 240.44792 | L9: =IF(AND(ISNUMBER(J9),ISNUMBER(K9),K9>0),J9/K9,"") | M9: =IF(AND(ISNUMBER(F9),ISNUMBER(H9),H9>0),(F9/H9-1)/(F9/H9+1),"") | N9: =IF(AND(ISNUMBER(F9),ISNUMBER(H9)) ,"BOUNDED","UNBOUNDED") -> UNBOUNDED | O9: =IF(N9="UNBOUNDED","HOLD",IF(L9>=Inputs!$B$9,"CLOSE","FAIL")) -> HOLD
A10: ET-A-A-SERVICE-COLD_START | B10: ET-A-A | C10: Service | D10: COLD_START | E10: t/h | G10: =Inputs!$B$7 -> 0.025 | H10: ='Source Inputs'!I7 -> 234.58333 | I10: =Inputs!$B$8 -> 0.025 | J10: =IF(ISNUMBER(F10),F10*(1-G10),"") | K10: =IF(ISNUMBER(H10),H10*(1+I10),"") -> 240.44792 | L10: =IF(AND(ISNUMBER(J10),ISNUMBER(K10),K10>0),J10/K10,"") | M10: =IF(AND(ISNUMBER(F10),ISNUMBER(H10),H10>0),(F10/H10-1)/(F10/H10+1),"") | N10: =IF(AND(ISNUMBER(F10),ISNUMBER(H10)) ,"BOUNDED","UNBOUNDED") -> UNBOUNDED | O10: =IF(N10="UNBOUNDED","HOLD",IF(L10>=Inputs!$B$9,"CLOSE","FAIL")) -> HOLD
A11: ET-A-A-MASS-NOMINAL | B11: ET-A-A | C11: Mass | D11: NOMINAL | E11: t | F11: ='Source Inputs'!H8 -> 128000 | G11: =Inputs!$B$7 -> 0.025 | H11: ='Source Inputs'!I8 -> 102000 | I11: =Inputs!$B$8 -> 0.025 | J11: =IF(ISNUMBER(F11),F11*(1-G11),"") -> 124800 | K11: =IF(ISNUMBER(H11),H11*(1+I11),"") -> 104550 | L11: =IF(AND(ISNUMBER(J11),ISNUMBER(K11),K11>0),J11/K11,"") -> 1.1936872 | M11: =IF(AND(ISNUMBER(F11),ISNUMBER(H11),H11>0),(F11/H11-1)/(F11/H11+1),"") -> 0.11304348 | N11: =IF(AND(ISNUMBER(F11),ISNUMBER(H11)) ,"BOUNDED","UNBOUNDED") -> BOUNDED | O11: =IF(N11="UNBOUNDED","HOLD",IF(L11>=Inputs!$B$9,"CLOSE","FAIL")) -> CLOSE
A12: ET-A-A-MASS-LARGEST_CELL_LOSS | B12: ET-A-A | C12: Mass | D12: LARGEST_CELL_LOSS | E12: t | F12: ='Source Inputs'!J8 -> 112000 | G12: =Inputs!$B$7 -> 0.025 | H12: ='Source Inputs'!K8 -> 102000 | I12: =Inputs!$B$8 -> 0.025 | J12: =IF(ISNUMBER(F12),F12*(1-G12),"") -> 109200 | K12: =IF(ISNUMBER(H12),H12*(1+I12),"") -> 104550 | L12: =IF(AND(ISNUMBER(J12),ISNUMBER(K12),K12>0),J12/K12,"") -> 1.0444763 | M12: =IF(AND(ISNUMBER(F12),ISNUMBER(H12),H12>0),(F12/H12-1)/(F12/H12+1),"") -> 0.046728972 | N12: =IF(AND(ISNUMBER(F12),ISNUMBER(H12)) ,"BOUNDED","UNBOUNDED") -> BOUNDED | O12: =IF(N12="UNBOUNDED","HOLD",IF(L12>=Inputs!$B$9,"CLOSE","FAIL")) -> CLOSE
A13: ET-A-A-MASS-FATAL_KEYSTONE | B13: ET-A-A | C13: Mass | D13: FATAL_KEYSTONE | E13: t | G13: =Inputs!$B$7 -> 0.025 | H13: ='Source Inputs'!I8 -> 102000 | I13: =Inputs!$B$8 -> 0.025 | J13: =IF(ISNUMBER(F13),F13*(1-G13),"") | K13: =IF(ISNUMBER(H13),H13*(1+I13),"") -> 104550 | L13: =IF(AND(ISNUMBER(J13),ISNUMBER(K13),K13>0),J13/K13,"") | M13: =IF(AND(ISNUMBER(F13),ISNUMBER(H13),H13>0),(F13/H13-1)/(F13/H13+1),"") | N13: =IF(AND(ISNUMBER(F13),ISNUMBER(H13)) ,"BOUNDED","UNBOUNDED") -> UNBOUNDED | O13: =IF(N13="UNBOUNDED","HOLD",IF(L13>=Inputs!$B$9,"CLOSE","FAIL")) -> HOLD
A14: ET-A-A-MASS-COLD_START | B14: ET-A-A | C14: Mass | D14: COLD_START | E14: t | G14: =Inputs!$B$7 -> 0.025 | H14: ='Source Inputs'!I8 -> 102000 | I14: =Inputs!$B$8 -> 0.025 | J14: =IF(ISNUMBER(F14),F14*(1-G14),"") | K14: =IF(ISNUMBER(H14),H14*(1+I14),"") -> 104550 | L14: =IF(AND(ISNUMBER(J14),ISNUMBER(K14),K14>0),J14/K14,"") | M14: =IF(AND(ISNUMBER(F14),ISNUMBER(H14),H14>0),(F14/H14-1)/(F14/H14+1),"") | N14: =IF(AND(ISNUMBER(F14),ISNUMBER(H14)) ,"BOUNDED","UNBOUNDED") -> UNBOUNDED | O14: =IF(N14="UNBOUNDED","HOLD",IF(L14>=Inputs!$B$9,"CLOSE","FAIL")) -> HOLD
A15: ET-A-A-ENERGY-NOMINAL | B15: ET-A-A | C15: Energy | D15: NOMINAL | E15: MW | F15: ='Source Inputs'!H9 -> 120 | G15: =Inputs!$B$7 -> 0.025 | H15: ='Source Inputs'!I9 -> 96 | I15: =Inputs!$B$8 -> 0.025 | J15: =IF(ISNUMBER(F15),F15*(1-G15),"") -> 117 | K15: =IF(ISNUMBER(H15),H15*(1+I15),"") -> 98.4 | L15: =IF(AND(ISNUMBER(J15),ISNUMBER(K15),K15>0),J15/K15,"") -> 1.1890244 | M15: =IF(AND(ISNUMBER(F15),ISNUMBER(H15),H15>0),(F15/H15-1)/(F15/H15+1),"") -> 0.11111111 | N15: =IF(AND(ISNUMBER(F15),ISNUMBER(H15)) ,"BOUNDED","UNBOUNDED") -> BOUNDED | O15: =IF(N15="UNBOUNDED","HOLD",IF(L15>=Inputs!$B$9,"CLOSE","FAIL")) -> CLOSE
A16: ET-A-A-ENERGY-LARGEST_CELL_LOSS | B16: ET-A-A | C16: Energy | D16: LARGEST_CELL_LOSS | E16: MW | F16: ='Source Inputs'!J9 -> 100 | G16: =Inputs!$B$7 -> 0.025 | H16: ='Source Inputs'!K9 -> 96 | I16: =Inputs!$B$8 -> 0.025 | J16: =IF(ISNUMBER(F16),F16*(1-G16),"") -> 97.5 | K16: =IF(ISNUMBER(H16),H16*(1+I16),"") -> 98.4 | L16: =IF(AND(ISNUMBER(J16),ISNUMBER(K16),K16>0),J16/K16,"") -> 0.99085366 | M16: =IF(AND(ISNUMBER(F16),ISNUMBER(H16),H16>0),(F16/H16-1)/(F16/H16+1),"") -> 0.020408163 | N16: =IF(AND(ISNUMBER(F16),ISNUMBER(H16)) ,"BOUNDED","UNBOUNDED") -> BOUNDED | O16: =IF(N16="UNBOUNDED","HOLD",IF(L16>=Inputs!$B$9,"CLOSE","FAIL")) -> FAIL
A17: ET-A-A-ENERGY-FATAL_KEYSTONE | B17: ET-A-A | C17: Energy | D17: FATAL_KEYSTONE | E17: MW | G17: =Inputs!$B$7 -> 0.025 | H17: ='Source Inputs'!I9 -> 96 | I17: =Inputs!$B$8 -> 0.025 | J17: =IF(ISNUMBER(F17),F17*(1-G17),"") | K17: =IF(ISNUMBER(H17),H17*(1+I17),"") -> 98.4 | L17: =IF(AND(ISNUMBER(J17),ISNUMBER(K17),K17>0),J17/K17,"") | M17: =IF(AND(ISNUMBER(F17),ISNUMBER(H17),H17>0),(F17/H17-1)/(F17/H17+1),"") | N17: =IF(AND(ISNUMBER(F17),ISNUMBER(H17)) ,"BOUNDED","UNBOUNDED") -> UNBOUNDED | O17: =IF(N17="UNBOUNDED","HOLD",IF(L17>=Inputs!$B$9,"CLOSE","FAIL")) -> HOLD
A18: ET-A-A-ENERGY-COLD_START | B18: ET-A-A | C18: Energy | D18: COLD_START | E18: MW | G18: =Inputs!$B$7 -> 0.025 | H18: ='Source Inputs'!I9 -> 96 | I18: =Inputs!$B$8 -> 0.025 | J18: =IF(ISNUMBER(F18),F18*(1-G18),"") | K18: =IF(ISNUMBER(H18),H18*(1+I18),"") -> 98.4 | L18: =IF(AND(ISNUMBER(J18),ISNUMBER(K18),K18>0),J18/K18,"") | M18: =IF(AND(ISNUMBER(F18),ISNUMBER(H18),H18>0),(F18/H18-1)/(F18/H18+1),"") | N18: =IF(AND(ISNUMBER(F18),ISNUMBER(H18)) ,"BOUNDED","UNBOUNDED") -> UNBOUNDED | O18: =IF(N18="UNBOUNDED","HOLD",IF(L18>=Inputs!$B$9,"CLOSE","FAIL")) -> HOLD
A19: ET-A-A-FLOW-NOMINAL | B19: ET-A-A | C19: Flow | D19: NOMINAL | E19: t/day | F19: ='Source Inputs'!H10 -> 1512 | G19: =Inputs!$B$7 -> 0.025 | H19: ='Source Inputs'!I10 -> 1200 | I19: =Inputs!$B$8 -> 0.025 | J19: =IF(ISNUMBER(F19),F19*(1-G19),"") -> 1474.2 | K19: =IF(ISNUMBER(H19),H19*(1+I19),"") -> 1230 | L19: =IF(AND(ISNUMBER(J19),ISNUMBER(K19),K19>0),J19/K19,"") -> 1.1985366 | M19: =IF(AND(ISNUMBER(F19),ISNUMBER(H19),H19>0),(F19/H19-1)/(F19/H19+1),"") -> 0.11504425 | N19: =IF(AND(ISNUMBER(F19),ISNUMBER(H19)) ,"BOUNDED","UNBOUNDED") -> BOUNDED | O19: =IF(N19="UNBOUNDED","HOLD",IF(L19>=Inputs!$B$9,"CLOSE","FAIL")) -> CLOSE
A20: ET-A-A-FLOW-LARGEST_CELL_LOSS | B20: ET-A-A | C20: Flow | D20: LARGEST_CELL_LOSS | E20: t/day | F20: ='Source Inputs'!J10 -> 1260 | G20: =Inputs!$B$7 -> 0.025 | H20: ='Source Inputs'!K10 -> 1200 | I20: =Inputs!$B$8 -> 0.025 | J20: =IF(ISNUMBER(F20),F20*(1-G20),"") -> 1228.5 | K20: =IF(ISNUMBER(H20),H20*(1+I20),"") -> 1230 | L20: =IF(AND(ISNUMBER(J20),ISNUMBER(K20),K20>0),J20/K20,"") -> 0.99878049 | M20: =IF(AND(ISNUMBER(F20),ISNUMBER(H20),H20>0),(F20/H20-1)/(F20/H20+1),"") -> 0.024390244 | N20: =IF(AND(ISNUMBER(F20),ISNUMBER(H20)) ,"BOUNDED","UNBOUNDED") -> BOUNDED | O20: =IF(N20="UNBOUNDED","HOLD",IF(L20>=Inputs!$B$9,"CLOSE","FAIL")) -> FAIL
A21: ET-A-A-FLOW-FATAL_KEYSTONE | B21: ET-A-A | C21: Flow | D21: FATAL_KEYSTONE | E21: t/day | G21: =Inputs!$B$7 -> 0.025 | H21: ='Source Inputs'!I10 -> 1200 | I21: =Inputs!$B$8 -> 0.025 | J21: =IF(ISNUMBER(F21),F21*(1-G21),"") | K21: =IF(ISNUMBER(H21),H21*(1+I21),"") -> 1230 | L21: =IF(AND(ISNUMBER(J21),ISNUMBER(K21),K21>0),J21/K21,"") | M21: =IF(AND(ISNUMBER(F21),ISNUMBER(H21),H21>0),(F21/H21-1)/(F21/H21+1),"") | N21: =IF(AND(ISNUMBER(F21),ISNUMBER(H21)) ,"BOUNDED","UNBOUNDED") -> UNBOUNDED | O21: =IF(N21="UNBOUNDED","HOLD",IF(L21>=Inputs!$B$9,"CLOSE","FAIL")) -> HOLD
A22: ET-A-A-FLOW-COLD_START | B22: ET-A-A | C22: Flow | D22: COLD_START | E22: t/day | G22: =Inputs!$B$7 -> 0.025 | H22: ='Source Inputs'!I10 -> 1200 | I22: =Inputs!$B$8 -> 0.025 | J22: =IF(ISNUMBER(F22),F22*(1-G22),"") | K22: =IF(ISNUMBER(H22),H22*(1+I22),"") -> 1230 | L22: =IF(AND(ISNUMBER(J22),ISNUMBER(K22),K22>0),J22/K22,"") | M22: =IF(AND(ISNUMBER(F22),ISNUMBER(H22),H22>0),(F22/H22-1)/(F22/H22+1),"") | N22: =IF(AND(ISNUMBER(F22),ISNUMBER(H22)) ,"BOUNDED","UNBOUNDED") -> UNBOUNDED | O22: =IF(N22="UNBOUNDED","HOLD",IF(L22>=Inputs!$B$9,"CLOSE","FAIL")) -> HOLD
A23: ET-A-A-THERMAL-NOMINAL | B23: ET-A-A | C23: Thermal | D23: NOMINAL | E23: form-native | G23: =Inputs!$B$7 -> 0.025 | I23: =Inputs!$B$8 -> 0.025 | J23: =IF(ISNUMBER(F23),F23*(1-G23),"") | K23: =IF(ISNUMBER(H23),H23*(1+I23),"") | L23: =IF(AND(ISNUMBER(J23),ISNUMBER(K23),K23>0),J23/K23,"") | M23: =IF(AND(ISNUMBER(F23),ISNUMBER(H23),H23>0),(F23/H23-1)/(F23/H23+1),"") | N23: =IF(AND(ISNUMBER(F23),ISNUMBER(H23)) ,"BOUNDED","UNBOUNDED") -> UNBOUNDED | O23: =IF(N23="UNBOUNDED","HOLD",IF(L23>=Inputs!$B$9,"CLOSE","FAIL")) -> HOLD
A24: ET-A-A-THERMAL-LARGEST_CELL_LOSS | B24: ET-A-A | C24: Thermal | D24: LARGEST_CELL_LOSS | E24: form-native | G24: =Inputs!$B$7 -> 0.025 | I24: =Inputs!$B$8 -> 0.025 | J24: =IF(ISNUMBER(F24),F24*(1-G24),"") | K24: =IF(ISNUMBER(H24),H24*(1+I24),"") | L24: =IF(AND(ISNUMBER(J24),ISNUMBER(K24),K24>0),J24/K24,"") | M24: =IF(AND(ISNUMBER(F24),ISNUMBER(H24),H24>0),(F24/H24-1)/(F24/H24+1),"") | N24: =IF(AND(ISNUMBER(F24),ISNUMBER(H24)) ,"BOUNDED","UNBOUNDED") -> UNBOUNDED | O24: =IF(N24="UNBOUNDED","HOLD",IF(L24>=Inputs!$B$9,"CLOSE","FAIL")) -> HOLD
A25: ET-A-A-THERMAL-FATAL_KEYSTONE | B25: ET-A-A | C25: Thermal | D25: FATAL_KEYSTONE | E25: form-native | G25: =Inputs!$B$7 -> 0.025 | I25: =Inputs!$B$8 -> 0.025 | J25: =IF(ISNUMBER(F25),F25*(1-G25),"") | K25: =IF(ISNUMBER(H25),H25*(1+I25),"") | L25: =IF(AND(ISNUMBER(J25),ISNUMBER(K25),K25>0),J25/K25,"") | M25: =IF(AND(ISNUMBER(F25),ISNUMBER(H25),H25>0),(F25/H25-1)/(F25/H25+1),"") | N25: =IF(AND(ISNUMBER(F25),ISNUMBER(H25)) ,"BOUNDED","UNBOUNDED") -> UNBOUNDED | O25: =IF(N25="UNBOUNDED","HOLD",IF(L25>=Inputs!$B$9,"CLOSE","FAIL")) -> HOLD
A26: ET-A-A-THERMAL-COLD_START | B26: ET-A-A | C26: Thermal | D26: COLD_START | E26: form-native | G26: =Inputs!$B$7 -> 0.025 | I26: =Inputs!$B$8 -> 0.025 | J26: =IF(ISNUMBER(F26),F26*(1-G26),"") | K26: =IF(ISNUMBER(H26),H26*(1+I26),"") | L26: =IF(AND(ISNUMBER(J26),ISNUMBER(K26),K26>0),J26/K26,"") | M26: =IF(AND(ISNUMBER(F26),ISNUMBER(H26),H26>0),(F26/H26-1)/(F26/H26+1),"") | N26: =IF(AND(ISNUMBER(F26),ISNUMBER(H26)) ,"BOUNDED","UNBOUNDED") -> UNBOUNDED | O26: =IF(N26="UNBOUNDED","HOLD",IF(L26>=Inputs!$B$9,"CLOSE","FAIL")) -> HOLD
A27: CT-C-B-SERVICE-NOMINAL | B27: CT-C-B | C27: Service | D27: NOMINAL | E27: ratio | F27: ='Source Inputs'!H11 -> 1.32 | G27: =Inputs!$B$7 -> 0.025 | H27: ='Source Inputs'!I11 -> 1 | I27: =Inputs!$B$8 -> 0.025 | J27: =IF(ISNUMBER(F27),F27*(1-G27),"") -> 1.287 | K27: =IF(ISNUMBER(H27),H27*(1+I27),"") -> 1.025 | L27: =IF(AND(ISNUMBER(J27),ISNUMBER(K27),K27>0),J27/K27,"") -> 1.2556098 | M27: =IF(AND(ISNUMBER(F27),ISNUMBER(H27),H27>0),(F27/H27-1)/(F27/H27+1),"") -> 0.13793103 | N27: =IF(AND(ISNUMBER(F27),ISNUMBER(H27)) ,"BOUNDED","UNBOUNDED") -> BOUNDED | O27: =IF(N27="UNBOUNDED","HOLD",IF(L27>=Inputs!$B$9,"CLOSE","FAIL")) -> CLOSE
A28: CT-C-B-SERVICE-LARGEST_CELL_LOSS | B28: CT-C-B | C28: Service | D28: LARGEST_CELL_LOSS | E28: ratio | F28: ='Source Inputs'!J11 -> 1.056 | G28: =Inputs!$B$7 -> 0.025 | H28: ='Source Inputs'!K11 -> 1 | I28: =Inputs!$B$8 -> 0.025 | J28: =IF(ISNUMBER(F28),F28*(1-G28),"") -> 1.0296 | K28: =IF(ISNUMBER(H28),H28*(1+I28),"") -> 1.025 | L28: =IF(AND(ISNUMBER(J28),ISNUMBER(K28),K28>0),J28/K28,"") -> 1.0044878 | M28: =IF(AND(ISNUMBER(F28),ISNUMBER(H28),H28>0),(F28/H28-1)/(F28/H28+1),"") -> 0.027237354 | N28: =IF(AND(ISNUMBER(F28),ISNUMBER(H28)) ,"BOUNDED","UNBOUNDED") -> BOUNDED | O28: =IF(N28="UNBOUNDED","HOLD",IF(L28>=Inputs!$B$9,"CLOSE","FAIL")) -> CLOSE
A29: CT-C-B-SERVICE-FATAL_KEYSTONE | B29: CT-C-B | C29: Service | D29: FATAL_KEYSTONE | E29: ratio | G29: =Inputs!$B$7 -> 0.025 | H29: ='Source Inputs'!I11 -> 1 | I29: =Inputs!$B$8 -> 0.025 | J29: =IF(ISNUMBER(F29),F29*(1-G29),"") | K29: =IF(ISNUMBER(H29),H29*(1+I29),"") -> 1.025 | L29: =IF(AND(ISNUMBER(J29),ISNUMBER(K29),K29>0),J29/K29,"") | M29: =IF(AND(ISNUMBER(F29),ISNUMBER(H29),H29>0),(F29/H29-1)/(F29/H29+1),"") | N29: =IF(AND(ISNUMBER(F29),ISNUMBER(H29)) ,"BOUNDED","UNBOUNDED") -> UNBOUNDED | O29: =IF(N29="UNBOUNDED","HOLD",IF(L29>=Inputs!$B$9,"CLOSE","FAIL")) -> HOLD
A30: CT-C-B-SERVICE-COLD_START | B30: CT-C-B | C30: Service | D30: COLD_START | E30: ratio | G30: =Inputs!$B$7 -> 0.025 | H30: ='Source Inputs'!I11 -> 1 | I30: =Inputs!$B$8 -> 0.025 | J30: =IF(ISNUMBER(F30),F30*(1-G30),"") | K30: =IF(ISNUMBER(H30),H30*(1+I30),"") -> 1.025 | L30: =IF(AND(ISNUMBER(J30),ISNUMBER(K30),K30>0),J30/K30,"") | M30: =IF(AND(ISNUMBER(F30),ISNUMBER(H30),H30>0),(F30/H30-1)/(F30/H30+1),"") | N30: =IF(AND(ISNUMBER(F30),ISNUMBER(H30)) ,"BOUNDED","UNBOUNDED") -> UNBOUNDED | O30: =IF(N30="UNBOUNDED","HOLD",IF(L30>=Inputs!$B$9,"CLOSE","FAIL")) -> HOLD
A31: CT-C-B-MASS-NOMINAL | B31: CT-C-B | C31: Mass | D31: NOMINAL | E31: t | F31: ='Source Inputs'!H12 -> 36000 | G31: =Inputs!$B$7 -> 0.025 | H31: ='Source Inputs'!I12 -> 31000 | I31: =Inputs!$B$8 -> 0.025 | J31: =IF(ISNUMBER(F31),F31*(1-G31),"") -> 35100 | K31: =IF(ISNUMBER(H31),H31*(1+I31),"") -> 31775 | L31: =IF(AND(ISNUMBER(J31),ISNUMBER(K31),K31>0),J31/K31,"") -> 1.104642 | M31: =IF(AND(ISNUMBER(F31),ISNUMBER(H31),H31>0),(F31/H31-1)/(F31/H31+1),"") -> 0.074626866 | N31: =IF(AND(ISNUMBER(F31),ISNUMBER(H31)) ,"BOUNDED","UNBOUNDED") -> BOUNDED | O31: =IF(N31="UNBOUNDED","HOLD",IF(L31>=Inputs!$B$9,"CLOSE","FAIL")) -> CLOSE
A32: CT-C-B-MASS-LARGEST_CELL_LOSS | B32: CT-C-B | C32: Mass | D32: LARGEST_CELL_LOSS | E32: t | F32: ='Source Inputs'!J12 -> 32400 | G32: =Inputs!$B$7 -> 0.025 | H32: ='Source Inputs'!K12 -> 31000 | I32: =Inputs!$B$8 -> 0.025 | J32: =IF(ISNUMBER(F32),F32*(1-G32),"") -> 31590 | K32: =IF(ISNUMBER(H32),H32*(1+I32),"") -> 31775 | L32: =IF(AND(ISNUMBER(J32),ISNUMBER(K32),K32>0),J32/K32,"") -> 0.99417781 | M32: =IF(AND(ISNUMBER(F32),ISNUMBER(H32),H32>0),(F32/H32-1)/(F32/H32+1),"") -> 0.022082019 | N32: =IF(AND(ISNUMBER(F32),ISNUMBER(H32)) ,"BOUNDED","UNBOUNDED") -> BOUNDED | O32: =IF(N32="UNBOUNDED","HOLD",IF(L32>=Inputs!$B$9,"CLOSE","FAIL")) -> FAIL
A33: CT-C-B-MASS-FATAL_KEYSTONE | B33: CT-C-B | C33: Mass | D33: FATAL_KEYSTONE | E33: t | G33: =Inputs!$B$7 -> 0.025 | H33: ='Source Inputs'!I12 -> 31000 | I33: =Inputs!$B$8 -> 0.025 | J33: =IF(ISNUMBER(F33),F33*(1-G33),"") | K33: =IF(ISNUMBER(H33),H33*(1+I33),"") -> 31775 | L33: =IF(AND(ISNUMBER(J33),ISNUMBER(K33),K33>0),J33/K33,"") | M33: =IF(AND(ISNUMBER(F33),ISNUMBER(H33),H33>0),(F33/H33-1)/(F33/H33+1),"") | N33: =IF(AND(ISNUMBER(F33),ISNUMBER(H33)) ,"BOUNDED","UNBOUNDED") -> UNBOUNDED | O33: =IF(N33="UNBOUNDED","HOLD",IF(L33>=Inputs!$B$9,"CLOSE","FAIL")) -> HOLD
A34: CT-C-B-MASS-COLD_START | B34: CT-C-B | C34: Mass | D34: COLD_START | E34: t | G34: =Inputs!$B$7 -> 0.025 | H34: ='Source Inputs'!I12 -> 31000 | I34: =Inputs!$B$8 -> 0.025 | J34: =IF(ISNUMBER(F34),F34*(1-G34),"") | K34: =IF(ISNUMBER(H34),H34*(1+I34),"") -> 31775 | L34: =IF(AND(ISNUMBER(J34),ISNUMBER(K34),K34>0),J34/K34,"") | M34: =IF(AND(ISNUMBER(F34),ISNUMBER(H34),H34>0),(F34/H34-1)/(F34/H34+1),"") | N34: =IF(AND(ISNUMBER(F34),ISNUMBER(H34)) ,"BOUNDED","UNBOUNDED") -> UNBOUNDED | O34: =IF(N34="UNBOUNDED","HOLD",IF(L34>=Inputs!$B$9,"CLOSE","FAIL")) -> HOLD
A35: CT-C-B-ENERGY-NOMINAL | B35: CT-C-B | C35: Energy | D35: NOMINAL | E35: MW | F35: ='Source Inputs'!H13 -> 50.4 | G35: =Inputs!$B$7 -> 0.025 | H35: ='Source Inputs'!I13 -> 42 | I35: =Inputs!$B$8 -> 0.025 | J35: =IF(ISNUMBER(F35),F35*(1-G35),"") -> 49.14 | K35: =IF(ISNUMBER(H35),H35*(1+I35),"") -> 43.05 | L35: =IF(AND(ISNUMBER(J35),ISNUMBER(K35),K35>0),J35/K35,"") -> 1.1414634 | M35: =IF(AND(ISNUMBER(F35),ISNUMBER(H35),H35>0),(F35/H35-1)/(F35/H35+1),"") -> 0.090909091 | N35: =IF(AND(ISNUMBER(F35),ISNUMBER(H35)) ,"BOUNDED","UNBOUNDED") -> BOUNDED | O35: =IF(N35="UNBOUNDED","HOLD",IF(L35>=Inputs!$B$9,"CLOSE","FAIL")) -> CLOSE
A36: CT-C-B-ENERGY-LARGEST_CELL_LOSS | B36: CT-C-B | C36: Energy | D36: LARGEST_CELL_LOSS | E36: MW | F36: ='Source Inputs'!J13 -> 43.2 | G36: =Inputs!$B$7 -> 0.025 | H36: ='Source Inputs'!K13 -> 42 | I36: =Inputs!$B$8 -> 0.025 | J36: =IF(ISNUMBER(F36),F36*(1-G36),"") -> 42.12 | K36: =IF(ISNUMBER(H36),H36*(1+I36),"") -> 43.05 | L36: =IF(AND(ISNUMBER(J36),ISNUMBER(K36),K36>0),J36/K36,"") -> 0.97839721 | M36: =IF(AND(ISNUMBER(F36),ISNUMBER(H36),H36>0),(F36/H36-1)/(F36/H36+1),"") -> 0.014084507 | N36: =IF(AND(ISNUMBER(F36),ISNUMBER(H36)) ,"BOUNDED","UNBOUNDED") -> BOUNDED | O36: =IF(N36="UNBOUNDED","HOLD",IF(L36>=Inputs!$B$9,"CLOSE","FAIL")) -> FAIL
A37: CT-C-B-ENERGY-FATAL_KEYSTONE | B37: CT-C-B | C37: Energy | D37: FATAL_KEYSTONE | E37: MW | G37: =Inputs!$B$7 -> 0.025 | H37: ='Source Inputs'!I13 -> 42 | I37: =Inputs!$B$8 -> 0.025 | J37: =IF(ISNUMBER(F37),F37*(1-G37),"") | K37: =IF(ISNUMBER(H37),H37*(1+I37),"") -> 43.05 | L37: =IF(AND(ISNUMBER(J37),ISNUMBER(K37),K37>0),J37/K37,"") | M37: =IF(AND(ISNUMBER(F37),ISNUMBER(H37),H37>0),(F37/H37-1)/(F37/H37+1),"") | N37: =IF(AND(ISNUMBER(F37),ISNUMBER(H37)) ,"BOUNDED","UNBOUNDED") -> UNBOUNDED | O37: =IF(N37="UNBOUNDED","HOLD",IF(L37>=Inputs!$B$9,"CLOSE","FAIL")) -> HOLD
A38: CT-C-B-ENERGY-COLD_START | B38: CT-C-B | C38: Energy | D38: COLD_START | E38: MW | G38: =Inputs!$B$7 -> 0.025 | H38: ='Source Inputs'!I13 -> 42 | I38: =Inputs!$B$8 -> 0.025 | J38: =IF(ISNUMBER(F38),F38*(1-G38),"") | K38: =IF(ISNUMBER(H38),H38*(1+I38),"") -> 43.05 | L38: =IF(AND(ISNUMBER(J38),ISNUMBER(K38),K38>0),J38/K38,"") | M38: =IF(AND(ISNUMBER(F38),ISNUMBER(H38),H38>0),(F38/H38-1)/(F38/H38+1),"") | N38: =IF(AND(ISNUMBER(F38),ISNUMBER(H38)) ,"BOUNDED","UNBOUNDED") -> UNBOUNDED | O38: =IF(N38="UNBOUNDED","HOLD",IF(L38>=Inputs!$B$9,"CLOSE","FAIL")) -> HOLD
A39: CT-C-B-FLOW-NOMINAL | B39: CT-C-B | C39: Flow | D39: NOMINAL | E39: t/day | F39: ='Source Inputs'!H14 -> 277.2 | G39: =Inputs!$B$7 -> 0.025 | H39: ='Source Inputs'!I14 -> 220 | I39: =Inputs!$B$8 -> 0.025 | J39: =IF(ISNUMBER(F39),F39*(1-G39),"") -> 270.27 | K39: =IF(ISNUMBER(H39),H39*(1+I39),"") -> 225.5 | L39: =IF(AND(ISNUMBER(J39),ISNUMBER(K39),K39>0),J39/K39,"") -> 1.1985366 | M39: =IF(AND(ISNUMBER(F39),ISNUMBER(H39),H39>0),(F39/H39-1)/(F39/H39+1),"") -> 0.11504425 | N39: =IF(AND(ISNUMBER(F39),ISNUMBER(H39)) ,"BOUNDED","UNBOUNDED") -> BOUNDED | O39: =IF(N39="UNBOUNDED","HOLD",IF(L39>=Inputs!$B$9,"CLOSE","FAIL")) -> CLOSE
A40: CT-C-B-FLOW-LARGEST_CELL_LOSS | B40: CT-C-B | C40: Flow | D40: LARGEST_CELL_LOSS | E40: t/day | F40: ='Source Inputs'!J14 -> 231 | G40: =Inputs!$B$7 -> 0.025 | H40: ='Source Inputs'!K14 -> 220 | I40: =Inputs!$B$8 -> 0.025 | J40: =IF(ISNUMBER(F40),F40*(1-G40),"") -> 225.225 | K40: =IF(ISNUMBER(H40),H40*(1+I40),"") -> 225.5 | L40: =IF(AND(ISNUMBER(J40),ISNUMBER(K40),K40>0),J40/K40,"") -> 0.99878049 | M40: =IF(AND(ISNUMBER(F40),ISNUMBER(H40),H40>0),(F40/H40-1)/(F40/H40+1),"") -> 0.024390244 | N40: =IF(AND(ISNUMBER(F40),ISNUMBER(H40)) ,"BOUNDED","UNBOUNDED") -> BOUNDED | O40: =IF(N40="UNBOUNDED","HOLD",IF(L40>=Inputs!$B$9,"CLOSE","FAIL")) -> FAIL
A41: CT-C-B-FLOW-FATAL_KEYSTONE | B41: CT-C-B | C41: Flow | D41: FATAL_KEYSTONE | E41: t/day | G41: =Inputs!$B$7 -> 0.025 | H41: ='Source Inputs'!I14 -> 220 | I41: =Inputs!$B$8 -> 0.025 | J41: =IF(ISNUMBER(F41),F41*(1-G41),"") | K41: =IF(ISNUMBER(H41),H41*(1+I41),"") -> 225.5 | L41: =IF(AND(ISNUMBER(J41),ISNUMBER(K41),K41>0),J41/K41,"") | M41: =IF(AND(ISNUMBER(F41),ISNUMBER(H41),H41>0),(F41/H41-1)/(F41/H41+1),"") | N41: =IF(AND(ISNUMBER(F41),ISNUMBER(H41)) ,"BOUNDED","UNBOUNDED") -> UNBOUNDED | O41: =IF(N41="UNBOUNDED","HOLD",IF(L41>=Inputs!$B$9,"CLOSE","FAIL")) -> HOLD
A42: CT-C-B-FLOW-COLD_START | B42: CT-C-B | C42: Flow | D42: COLD_START | E42: t/day | G42: =Inputs!$B$7 -> 0.025 | H42: ='Source Inputs'!I14 -> 220 | I42: =Inputs!$B$8 -> 0.025 | J42: =IF(ISNUMBER(F42),F42*(1-G42),"") | K42: =IF(ISNUMBER(H42),H42*(1+I42),"") -> 225.5 | L42: =IF(AND(ISNUMBER(J42),ISNUMBER(K42),K42>0),J42/K42,"") | M42: =IF(AND(ISNUMBER(F42),ISNUMBER(H42),H42>0),(F42/H42-1)/(F42/H42+1),"") | N42: =IF(AND(ISNUMBER(F42),ISNUMBER(H42)) ,"BOUNDED","UNBOUNDED") -> UNBOUNDED | O42: =IF(N42="UNBOUNDED","HOLD",IF(L42>=Inputs!$B$9,"CLOSE","FAIL")) -> HOLD
A43: CT-C-B-THERMAL-NOMINAL | B43: CT-C-B | C43: Thermal | D43: NOMINAL | E43: form-native | G43: =Inputs!$B$7 -> 0.025 | I43: =Inputs!$B$8 -> 0.025 | J43: =IF(ISNUMBER(F43),F43*(1-G43),"") | K43: =IF(ISNUMBER(H43),H43*(1+I43),"") | L43: =IF(AND(ISNUMBER(J43),ISNUMBER(K43),K43>0),J43/K43,"") | M43: =IF(AND(ISNUMBER(F43),ISNUMBER(H43),H43>0),(F43/H43-1)/(F43/H43+1),"") | N43: =IF(AND(ISNUMBER(F43),ISNUMBER(H43)) ,"BOUNDED","UNBOUNDED") -> UNBOUNDED | O43: =IF(N43="UNBOUNDED","HOLD",IF(L43>=Inputs!$B$9,"CLOSE","FAIL")) -> HOLD
...

Sheet Loss Rating Orders
A2: Largest-cell-loss rating orders
A4: The target is the minimum raw surviving capacity required for independent 2.5% downside and 2.5% requirement upside.
A6: Order | B6: Form | C6: Account | D6: Unit | E6: Current survivor capacity | F6: Loss requirement | G6: Current raw ratio | H6: Maximum symmetric half-width | I6: Required raw ratio | J6: Required survivor capacity | K6: Capacity gap | L6: Required uplift | M6: State | N6: Engineering instruction
A7: ET-A-A-SERVICE-RATING | B7: ET-A-A | C7: Service | D7: t/h | E7: ='Source Inputs'!J7 -> 241 | F7: ='Source Inputs'!K7 -> 234.58333 | G7: =E7/F7 -> 1.0273535 | H7: =(G7-1)/(G7+1) -> 0.013492203 | I7: =Inputs!$B$10 -> 1.0512821 | J7: =F7*I7 -> 246.61325 | K7: =MAX(0,J7-E7) -> 5.6132479 | L7: =MAX(0,J7/E7-1) -> 0.023291485 | M7: =IF(E7>=J7,"RETAIN","UPRATE") -> UPRATE | N7: Raise each complete exchange path from 241 to at least 247 t/h before thermal and keystone closure.
A8: ET-A-A-MASS-RATING | B8: ET-A-A | C8: Mass | D8: t | E8: ='Source Inputs'!J8 -> 112000 | F8: ='Source Inputs'!K8 -> 102000 | G8: =E8/F8 -> 1.0980392 | H8: =(G8-1)/(G8+1) -> 0.046728972 | I8: =Inputs!$B$10 -> 1.0512821 | J8: =F8*I8 -> 107230.77 | K8: =MAX(0,J8-E8) -> 0 | L8: =MAX(0,J8/E8-1) -> 0 | M8: =IF(E8>=J8,"RETAIN","UPRATE") -> RETAIN | N8: Meet the form-native mass target without borrowing a sibling coefficient or deleting a cell boundary.
A9: ET-A-A-ENERGY-RATING | B9: ET-A-A | C9: Energy | D9: MW | E9: ='Source Inputs'!J9 -> 100 | F9: ='Source Inputs'!K9 -> 96 | G9: =E9/F9 -> 1.0416667 | H9: =(G9-1)/(G9+1) -> 0.020408163 | I9: =Inputs!$B$10 -> 1.0512821 | J9: =F9*I9 -> 100.92308 | K9: =MAX(0,J9-E9) -> 0.92307692 | L9: =MAX(0,J9/E9-1) -> 0.0092307692 | M9: =IF(E9>=J9,"RETAIN","UPRATE") -> UPRATE | N9: Meet the form-native energy target without borrowing a sibling coefficient or deleting a cell boundary.
A10: ET-A-A-FLOW-RATING | B10: ET-A-A | C10: Flow | D10: t/day | E10: ='Source Inputs'!J10 -> 1260 | F10: ='Source Inputs'!K10 -> 1200 | G10: =E10/F10 -> 1.05 | H10: =(G10-1)/(G10+1) -> 0.024390244 | I10: =Inputs!$B$10 -> 1.0512821 | J10: =F10*I10 -> 1261.5385 | K10: =MAX(0,J10-E10) -> 1.5384615 | L10: =MAX(0,J10/E10-1) -> 0.0012210012 | M10: =IF(E10>=J10,"RETAIN","UPRATE") -> UPRATE | N10: Meet the form-native flow target without borrowing a sibling coefficient or deleting a cell boundary.
A11: CT-C-B-SERVICE-RATING | B11: CT-C-B | C11: Service | D11: ratio | E11: ='Source Inputs'!J11 -> 1.056 | F11: ='Source Inputs'!K11 -> 1 | G11: =E11/F11 -> 1.056 | H11: =(G11-1)/(G11+1) -> 0.027237354 | I11: =Inputs!$B$10 -> 1.0512821 | J11: =F11*I11 -> 1.0512821 | K11: =MAX(0,J11-E11) -> 0 | L11: =MAX(0,J11/E11-1) -> 0 | M11: =IF(E11>=J11,"RETAIN","UPRATE") -> RETAIN | N11: Meet the form-native service target without borrowing a sibling coefficient or deleting a cell boundary.
A12: CT-C-B-MASS-RATING | B12: CT-C-B | C12: Mass | D12: t | E12: ='Source Inputs'!J12 -> 32400 | F12: ='Source Inputs'!K12 -> 31000 | G12: =E12/F12 -> 1.0451613 | H12: =(G12-1)/(G12+1) -> 0.022082019 | I12: =Inputs!$B$10 -> 1.0512821 | J12: =F12*I12 -> 32589.744 | K12: =MAX(0,J12-E12) -> 189.74359 | L12: =MAX(0,J12/E12-1) -> 0.0058562836 | M12: =IF(E12>=J12,"RETAIN","UPRATE") -> UPRATE | N12: Meet the form-native mass target without borrowing a sibling coefficient or deleting a cell boundary.
A13: CT-C-B-ENERGY-RATING | B13: CT-C-B | C13: Energy | D13: MW | E13: ='Source Inputs'!J13 -> 43.2 | F13: ='Source Inputs'!K13 -> 42 | G13: =E13/F13 -> 1.0285714 | H13: =(G13-1)/(G13+1) -> 0.014084507 | I13: =Inputs!$B$10 -> 1.0512821 | J13: =F13*I13 -> 44.153846 | K13: =MAX(0,J13-E13) -> 0.95384615 | L13: =MAX(0,J13/E13-1) -> 0.022079772 | M13: =IF(E13>=J13,"RETAIN","UPRATE") -> UPRATE | N13: Raise each isolated generation cell from 7.20 to at least 7.36 MW before thermal and attachment closure.
A14: CT-C-B-FLOW-RATING | B14: CT-C-B | C14: Flow | D14: t/day | E14: ='Source Inputs'!J14 -> 231 | F14: ='Source Inputs'!K14 -> 220 | G14: =E14/F14 -> 1.05 | H14: =(G14-1)/(G14+1) -> 0.024390244 | I14: =Inputs!$B$10 -> 1.0512821 | J14: =F14*I14 -> 231.28205 | K14: =MAX(0,J14-E14) -> 0.28205128 | L14: =MAX(0,J14/E14-1) -> 0.0012210012 | M14: =IF(E14>=J14,"RETAIN","UPRATE") -> UPRATE | N14: Meet the form-native flow target without borrowing a sibling coefficient or deleting a cell boundary.
A15: HC-A-C-SERVICE-RATING | B15: HC-A-C | C15: Service | D15: km/day | E15: ='Source Inputs'!J15 -> 106 | F15: ='Source Inputs'!K15 -> 103 | G15: =E15/F15 -> 1.0291262 | H15: =(G15-1)/(G15+1) -> 0.014354067 | I15: =Inputs!$B$10 -> 1.0512821 | J15: =F15*I15 -> 108.28205 | K15: =MAX(0,J15-E15) -> 2.2820513 | L15: =MAX(0,J15/E15-1) -> 0.021528786 | M15: =IF(E15>=J15,"RETAIN","UPRATE") -> UPRATE | N15: Raise each surviving held-line sector from 26.5 to at least 27.1 km/day before hot-zone closure.
A16: HC-A-C-MASS-RATING | B16: HC-A-C | C16: Mass | D16: t | E16: ='Source Inputs'!J16 -> 56700 | F16: ='Source Inputs'!K16 -> 54000 | G16: =E16/F16 -> 1.05 | H16: =(G16-1)/(G16+1) -> 0.024390244 | I16: =Inputs!$B$10 -> 1.0512821 | J16: =F16*I16 -> 56769.231 | K16: =MAX(0,J16-E16) -> 69.230769 | L16: =MAX(0,J16/E16-1) -> 0.0012210012 | M16: =IF(E16>=J16,"RETAIN","UPRATE") -> UPRATE | N16: Meet the form-native mass target without borrowing a sibling coefficient or deleting a cell boundary.
A17: HC-A-C-ENERGY-RATING | B17: HC-A-C | C17: Energy | D17: MW | E17: ='Source Inputs'!J17 -> 144.2 | F17: ='Source Inputs'!K17 -> 140 | G17: =E17/F17 -> 1.03 | H17: =(G17-1)/(G17+1) -> 0.014778325 | I17: =Inputs!$B$10 -> 1.0512821 | J17: =F17*I17 -> 147.17949 | K17: =MAX(0,J17-E17) -> 2.9794872 | L17: =MAX(0,J17/E17-1) -> 0.020662186 | M17: =IF(E17>=J17,"RETAIN","UPRATE") -> UPRATE | N17: Meet the form-native energy target without borrowing a sibling coefficient or deleting a cell boundary.
A18: HC-A-C-FLOW-RATING | B18: HC-A-C | C18: Flow | D18: t/day | E18: ='Source Inputs'!J18 -> 945 | F18: ='Source Inputs'!K18 -> 900 | G18: =E18/F18 -> 1.05 | H18: =(G18-1)/(G18+1) -> 0.024390244 | I18: =Inputs!$B$10 -> 1.0512821 | J18: =F18*I18 -> 946.15385 | K18: =MAX(0,J18-E18) -> 1.1538462 | L18: =MAX(0,J18/E18-1) -> 0.0012210012 | M18: =IF(E18>=J18,"RETAIN","UPRATE") -> UPRATE | N18: Meet the form-native flow target without borrowing a sibling coefficient or deleting a cell boundary.
... A30: RT-B-C-FLOW-RATING | B30: RT-B-C | C30: Flow | D30: t/day | E30: ='Source Inputs'!J30 -> 1260 | F30: ='Source Inputs'!K30 -> 1200 | G30: =E30/F30 -> 1.05 | H30: =(G30-1)/(G30+1) -> 0.024390244 | I30: =Inputs!$B$10 -> 1.0512821 | J30: =F30*I30 -> 1261.5385 | K30: =MAX(0,J30-E30) -> 1.5384615 | L30: =MAX(0,J30/E30-1) -> 0.0012210012 | M30: =IF(E30>=J30,"RETAIN","UPRATE") -> UPRATE | N30: Meet the form-native flow target without borrowing a sibling coefficient or deleting a cell boundary.

Sheet Sensitivity
A2: Loss-world interval sensitivity
A4: This view varies the public symmetric screen. It does not invent probability distributions or close missing worlds.
A6: Scenario | B6: Symmetric half-width | C6: Form | D6: Governing raw ratio | E6: Lower interval ratio | F6: Loss-world result | G6: Full-baseline result
A7: No interval | B7: 0 | C7: ET-A-A | D7: =MIN('Loss Rating Orders'!$G$7:$G$10) -> 1.0273535 | E7: =D7*(1-B7)/(1+B7) -> 1.0273535 | F7: =IF(E7>=1,"CLOSE","FAIL") -> CLOSE | G7: ="HOLD: unbounded fatal, cold and thermal cells" -> HOLD: unbounded fatal, cold and thermal cells
A8: No interval | B8: 0 | C8: CT-C-B | D8: =MIN('Loss Rating Orders'!$G$11:$G$14) -> 1.0285714 | E8: =D8*(1-B8)/(1+B8) -> 1.0285714 | F8: =IF(E8>=1,"CLOSE","FAIL") -> CLOSE | G8: ="HOLD: unbounded fatal, cold and thermal cells" -> HOLD: unbounded fatal, cold and thermal cells
A9: No interval | B9: 0 | C9: HC-A-C | D9: =MIN('Loss Rating Orders'!$G$15:$G$18) -> 1.0291262 | E9: =D9*(1-B9)/(1+B9) -> 1.0291262 | F9: =IF(E9>=1,"CLOSE","FAIL") -> CLOSE | G9: ="HOLD: unbounded fatal, cold and thermal cells" -> HOLD: unbounded fatal, cold and thermal cells
A10: No interval | B10: 0 | C10: LF-B-A | D10: =MIN('Loss Rating Orders'!$G$19:$G$22) -> 1.0271923 | E10: =D10*(1-B10)/(1+B10) -> 1.0271923 | F10: =IF(E10>=1,"CLOSE","FAIL") -> CLOSE | G10: ="HOLD: unbounded fatal, cold and thermal cells" -> HOLD: unbounded fatal, cold and thermal cells
A11: No interval | B11: 0 | C11: HU-A-B | D11: =MIN('Loss Rating Orders'!$G$23:$G$26) -> 1.029 | E11: =D11*(1-B11)/(1+B11) -> 1.029 | F11: =IF(E11>=1,"CLOSE","FAIL") -> CLOSE | G11: ="HOLD: unbounded fatal, cold and thermal cells" -> HOLD: unbounded fatal, cold and thermal cells
A12: No interval | B12: 0 | C12: RT-B-C | D12: =MIN('Loss Rating Orders'!$G$27:$G$30) -> 1.0258065 | E12: =D12*(1-B12)/(1+B12) -> 1.0258065 | F12: =IF(E12>=1,"CLOSE","FAIL") -> CLOSE | G12: ="HOLD: unbounded fatal, cold and thermal cells" -> HOLD: unbounded fatal, cold and thermal cells
A13: 1.00% | B13: 0.01 | C13: ET-A-A | D13: =MIN('Loss Rating Orders'!$G$7:$G$10) -> 1.0273535 | E13: =D13*(1-B13)/(1+B13) -> 1.0070098 | F13: =IF(E13>=1,"CLOSE","FAIL") -> CLOSE | G13: ="HOLD: unbounded fatal, cold and thermal cells" -> HOLD: unbounded fatal, cold and thermal cells
A14: 1.00% | B14: 0.01 | C14: CT-C-B | D14: =MIN('Loss Rating Orders'!$G$11:$G$14) -> 1.0285714 | E14: =D14*(1-B14)/(1+B14) -> 1.0082037 | F14: =IF(E14>=1,"CLOSE","FAIL") -> CLOSE | G14: ="HOLD: unbounded fatal, cold and thermal cells" -> HOLD: unbounded fatal, cold and thermal cells
A15: 1.00% | B15: 0.01 | C15: HC-A-C | D15: =MIN('Loss Rating Orders'!$G$15:$G$18) -> 1.0291262 | E15: =D15*(1-B15)/(1+B15) -> 1.0087475 | F15: =IF(E15>=1,"CLOSE","FAIL") -> CLOSE | G15: ="HOLD: unbounded fatal, cold and thermal cells" -> HOLD: unbounded fatal, cold and thermal cells
A16: 1.00% | B16: 0.01 | C16: LF-B-A | D16: =MIN('Loss Rating Orders'!$G$19:$G$22) -> 1.0271923 | E16: =D16*(1-B16)/(1+B16) -> 1.0068518 | F16: =IF(E16>=1,"CLOSE","FAIL") -> CLOSE | G16: ="HOLD: unbounded fatal, cold and thermal cells" -> HOLD: unbounded fatal, cold and thermal cells
A17: 1.00% | B17: 0.01 | C17: HU-A-B | D17: =MIN('Loss Rating Orders'!$G$23:$G$26) -> 1.029 | E17: =D17*(1-B17)/(1+B17) -> 1.0086238 | F17: =IF(E17>=1,"CLOSE","FAIL") -> CLOSE | G17: ="HOLD: unbounded fatal, cold and thermal cells" -> HOLD: unbounded fatal, cold and thermal cells
A18: 1.00% | B18: 0.01 | C18: RT-B-C | D18: =MIN('Loss Rating Orders'!$G$27:$G$30) -> 1.0258065 | E18: =D18*(1-B18)/(1+B18) -> 1.0054935 | F18: =IF(E18>=1,"CLOSE","FAIL") -> CLOSE | G18: ="HOLD: unbounded fatal, cold and thermal cells" -> HOLD: unbounded fatal, cold and thermal cells
A19: 1.25% | B19: 0.0125 | C19: ET-A-A | D19: =MIN('Loss Rating Orders'!$G$7:$G$10) -> 1.0273535 | E19: =D19*(1-B19)/(1+B19) -> 1.0019867 | F19: =IF(E19>=1,"CLOSE","FAIL") -> CLOSE | G19: ="HOLD: unbounded fatal, cold and thermal cells" -> HOLD: unbounded fatal, cold and thermal cells
A20: 1.25% | B20: 0.0125 | C20: CT-C-B | D20: =MIN('Loss Rating Orders'!$G$11:$G$14) -> 1.0285714 | E20: =D20*(1-B20)/(1+B20) -> 1.0031746 | F20: =IF(E20>=1,"CLOSE","FAIL") -> CLOSE | G20: ="HOLD: unbounded fatal, cold and thermal cells" -> HOLD: unbounded fatal, cold and thermal cells
A21: 1.25% | B21: 0.0125 | C21: HC-A-C | D21: =MIN('Loss Rating Orders'!$G$15:$G$18) -> 1.0291262 | E21: =D21*(1-B21)/(1+B21) -> 1.0037157 | F21: =IF(E21>=1,"CLOSE","FAIL") -> CLOSE | G21: ="HOLD: unbounded fatal, cold and thermal cells" -> HOLD: unbounded fatal, cold and thermal cells
A22: 1.25% | B22: 0.0125 | C22: LF-B-A | D22: =MIN('Loss Rating Orders'!$G$19:$G$22) -> 1.0271923 | E22: =D22*(1-B22)/(1+B22) -> 1.0018295 | F22: =IF(E22>=1,"CLOSE","FAIL") -> CLOSE | G22: ="HOLD: unbounded fatal, cold and thermal cells" -> HOLD: unbounded fatal, cold and thermal cells
A23: 1.25% | B23: 0.0125 | C23: HU-A-B | D23: =MIN('Loss Rating Orders'!$G$23:$G$26) -> 1.029 | E23: =D23*(1-B23)/(1+B23) -> 1.0035926 | F23: =IF(E23>=1,"CLOSE","FAIL") -> CLOSE | G23: ="HOLD: unbounded fatal, cold and thermal cells" -> HOLD: unbounded fatal, cold and thermal cells
A24: 1.25% | B24: 0.0125 | C24: RT-B-C | D24: =MIN('Loss Rating Orders'!$G$27:$G$30) -> 1.0258065 | E24: =D24*(1-B24)/(1+B24) -> 1.0004779 | F24: =IF(E24>=1,"CLOSE","FAIL") -> CLOSE | G24: ="HOLD: unbounded fatal, cold and thermal cells" -> HOLD: unbounded fatal, cold and thermal cells
A25: 1.50% | B25: 0.015 | C25: ET-A-A | D25: =MIN('Loss Rating Orders'!$G$7:$G$10) -> 1.0273535 | E25: =D25*(1-B25)/(1+B25) -> 0.99698834 | F25: =IF(E25>=1,"CLOSE","FAIL") -> FAIL | G25: ="HOLD: unbounded fatal, cold and thermal cells" -> HOLD: unbounded fatal, cold and thermal cells
A26: 1.50% | B26: 0.015 | C26: CT-C-B | D26: =MIN('Loss Rating Orders'!$G$11:$G$14) -> 1.0285714 | E26: =D26*(1-B26)/(1+B26) -> 0.9981703 | F26: =IF(E26>=1,"CLOSE","FAIL") -> FAIL | G26: ="HOLD: unbounded fatal, cold and thermal cells" -> HOLD: unbounded fatal, cold and thermal cells
A27: 1.50% | B27: 0.015 | C27: HC-A-C | D27: =MIN('Loss Rating Orders'!$G$15:$G$18) -> 1.0291262 | E27: =D27*(1-B27)/(1+B27) -> 0.99870869 | F27: =IF(E27>=1,"CLOSE","FAIL") -> FAIL | G27: ="HOLD: unbounded fatal, cold and thermal cells" -> HOLD: unbounded fatal, cold and thermal cells
A28: 1.50% | B28: 0.015 | C28: LF-B-A | D28: =MIN('Loss Rating Orders'!$G$19:$G$22) -> 1.0271923 | E28: =D28*(1-B28)/(1+B28) -> 0.99683191 | F28: =IF(E28>=1,"CLOSE","FAIL") -> FAIL | G28: ="HOLD: unbounded fatal, cold and thermal cells" -> HOLD: unbounded fatal, cold and thermal cells
A29: 1.50% | B29: 0.015 | C29: HU-A-B | D29: =MIN('Loss Rating Orders'!$G$23:$G$26) -> 1.029 | E29: =D29*(1-B29)/(1+B29) -> 0.99858621 | F29: =IF(E29>=1,"CLOSE","FAIL") -> FAIL | G29: ="HOLD: unbounded fatal, cold and thermal cells" -> HOLD: unbounded fatal, cold and thermal cells
A30: 1.50% | B30: 0.015 | C30: RT-B-C | D30: =MIN('Loss Rating Orders'!$G$27:$G$30) -> 1.0258065 | E30: =D30*(1-B30)/(1+B30) -> 0.99548705 | F30: =IF(E30>=1,"CLOSE","FAIL") -> FAIL | G30: ="HOLD: unbounded fatal, cold and thermal cells" -> HOLD: unbounded fatal, cold and thermal cells
A31: Selected 2.50% | B31: 0.025 | C31: ET-A-A | D31: =MIN('Loss Rating Orders'!$G$7:$G$10) -> 1.0273535 | E31: =D31*(1-B31)/(1+B31) -> 0.97723866 | F31: =IF(E31>=1,"CLOSE","FAIL") -> FAIL | G31: ="HOLD: unbounded fatal, cold and thermal cells" -> HOLD: unbounded fatal, cold and thermal cells
A32: Selected 2.50% | B32: 0.025 | C32: CT-C-B | D32: =MIN('Loss Rating Orders'!$G$11:$G$14) -> 1.0285714 | E32: =D32*(1-B32)/(1+B32) -> 0.97839721 | F32: =IF(E32>=1,"CLOSE","FAIL") -> FAIL | G32: ="HOLD: unbounded fatal, cold and thermal cells" -> HOLD: unbounded fatal, cold and thermal cells
A33: Selected 2.50% | B33: 0.025 | C33: HC-A-C | D33: =MIN('Loss Rating Orders'!$G$15:$G$18) -> 1.0291262 | E33: =D33*(1-B33)/(1+B33) -> 0.97892493 | F33: =IF(E33>=1,"CLOSE","FAIL") -> FAIL | G33: ="HOLD: unbounded fatal, cold and thermal cells" -> HOLD: unbounded fatal, cold and thermal cells
A34: Selected 2.50% | B34: 0.025 | C34: LF-B-A | D34: =MIN('Loss Rating Orders'!$G$19:$G$22) -> 1.0271923 | E34: =D34*(1-B34)/(1+B34) -> 0.97708534 | F34: =IF(E34>=1,"CLOSE","FAIL") -> FAIL | G34: ="HOLD: unbounded fatal, cold and thermal cells" -> HOLD: unbounded fatal, cold and thermal cells
A35: Selected 2.50% | B35: 0.025 | C35: HU-A-B | D35: =MIN('Loss Rating Orders'!$G$23:$G$26) -> 1.029 | E35: =D35*(1-B35)/(1+B35) -> 0.97880488 | F35: =IF(E35>=1,"CLOSE","FAIL") -> FAIL | G35: ="HOLD: unbounded fatal, cold and thermal cells" -> HOLD: unbounded fatal, cold and thermal cells
A36: Selected 2.50% | B36: 0.025 | C36: RT-B-C | D36: =MIN('Loss Rating Orders'!$G$27:$G$30) -> 1.0258065 | E36: =D36*(1-B36)/(1+B36) -> 0.97576711 | F36: =IF(E36>=1,"CLOSE","FAIL") -> FAIL | G36: ="HOLD: unbounded fatal, cold and thermal cells" -> HOLD: unbounded fatal, cold and thermal cells
A37: 5.00% | B37: 0.05 | C37: ET-A-A | D37: =MIN('Loss Rating Orders'!$G$7:$G$10) -> 1.0273535 | E37: =D37*(1-B37)/(1+B37) -> 0.92951028 | F37: =IF(E37>=1,"CLOSE","FAIL") -> FAIL | G37: ="HOLD: unbounded fatal, cold and thermal cells" -> HOLD: unbounded fatal, cold and thermal cells
A38: 5.00% | B38: 0.05 | C38: CT-C-B | D38: =MIN('Loss Rating Orders'!$G$11:$G$14) -> 1.0285714 | E38: =D38*(1-B38)/(1+B38) -> 0.93061224 | F38: =IF(E38>=1,"CLOSE","FAIL") -> FAIL | G38: ="HOLD: unbounded fatal, cold and thermal cells" -> HOLD: unbounded fatal, cold and thermal cells
A39: 5.00% | B39: 0.05 | C39: HC-A-C | D39: =MIN('Loss Rating Orders'!$G$15:$G$18) -> 1.0291262 | E39: =D39*(1-B39)/(1+B39) -> 0.93111419 | F39: =IF(E39>=1,"CLOSE","FAIL") -> FAIL | G39: ="HOLD: unbounded fatal, cold and thermal cells" -> HOLD: unbounded fatal, cold and thermal cells
A40: 5.00% | B40: 0.05 | C40: LF-B-A | D40: =MIN('Loss Rating Orders'!$G$19:$G$22) -> 1.0271923 | E40: =D40*(1-B40)/(1+B40) -> 0.92936444 | F40: =IF(E40>=1,"CLOSE","FAIL") -> FAIL | G40: ="HOLD: unbounded fatal, cold and thermal cells" -> HOLD: unbounded fatal, cold and thermal cells
A41: 5.00% | B41: 0.05 | C41: HU-A-B | D41: =MIN('Loss Rating Orders'!$G$23:$G$26) -> 1.029 | E41: =D41*(1-B41)/(1+B41) -> 0.931 | F41: =IF(E41>=1,"CLOSE","FAIL") -> FAIL | G41: ="HOLD: unbounded fatal, cold and thermal cells" -> HOLD: unbounded fatal, cold and thermal cells
A42: 5.00% | B42: 0.05 | C42: RT-B-C | D42: =MIN('Loss Rating Orders'!$G$27:$G$30) -> 1.0258065 | E42: =D42*(1-B42)/(1+B42) -> 0.9281106 | F42: =IF(E42>=1,"CLOSE","FAIL") -> FAIL | G42: ="HOLD: unbounded fatal, cold and thermal cells" -> HOLD: unbounded fatal, cold and thermal cells
A43: 10.0% | B43: 0.1 | C43: ET-A-A | D43: =MIN('Loss Rating Orders'!$G$7:$G$10) -> 1.0273535 | E43: =D43*(1-B43)/(1+B43) -> 0.84056192 | F43: =IF(E43>=1,"CLOSE","FAIL") -> FAIL | G43: ="HOLD: unbounded fatal, cold and thermal cells" -> HOLD: unbounded fatal, cold and thermal cells
...

Sheet Coefficient Register
A2: Source-specific coefficient register
A4: Every form must bound its own six coefficients. No sibling value, midpoint or favorable zero may be imported.
A6: Coefficient | B6: Form | C6: Symbol | D6: Quantity | E6: Unit | F6: Lower bound | G6: Upper bound | H6: Measured | I6: Required experiment | J6: Prohibited substitution | K6: State | L6: Closure use
A7: ET-A-A-CAP | B7: ET-A-A | C7: βC | D7: capacity calibration factor | E7: ratio | H7: 0 | I7: full-range metered capacity sweep | J7: nominal rating or sibling derate | K7: =IF(AND(ISNUMBER(F7),ISNUMBER(G7),H7=1),"BOUNDED","OPEN") -> OPEN | L7: capacity lower bound
A8: ET-A-A-REQ | B8: ET-A-A | C8: βR | D8: service requirement scale factor | E8: ratio | H8: 0 | I8: receiver-denominator replay | J8: interval midpoint or average receiver | K8: =IF(AND(ISNUMBER(F8),ISNUMBER(G8),H8=1),"BOUNDED","OPEN") -> OPEN | L8: requirement upper bound
A9: ET-A-A-LOSS | B9: ET-A-A | C9: λ | D9: largest-cell propagation fraction | E9: share | H9: 0 | I9: instrumented cell-loss trial | J9: independence declaration | K9: =IF(AND(ISNUMBER(F9),ISNUMBER(G9),H9=1),"BOUNDED","OPEN") -> OPEN | L9: loss-world capacity
A10: ET-A-A-KEY | B10: ET-A-A | C10: κ | D10: fatal-keystone retained fraction | E10: share | H10: 0 | I10: frozen keystone intervention | J10: modeled safeing or operator judgment | K10: =IF(AND(ISNUMBER(F10),ISNUMBER(G10),H10=1),"BOUNDED","OPEN") -> OPEN | L10: fatal-world capacity
A11: ET-A-A-COLD | B11: ET-A-A | C11: χ | D11: cold-start retained fraction | E11: share | H11: 0 | I11: clean-team reconstruction and black start | J11: builder demonstration or vendor runtime | K11: =IF(AND(ISNUMBER(F11),ISNUMBER(G11),H11=1),"BOUNDED","OPEN") -> OPEN | L11: cold-start capacity
A12: ET-A-A-THERM | B12: ET-A-A | C12: θ | D12: peak thermal duty coefficient | E12: form-native | H12: 0 | I12: worst-ambient calorimetry and heat rejection | J12: electrical surplus or sibling coefficient | K12: =IF(AND(ISNUMBER(F12),ISNUMBER(G12),H12=1),"BOUNDED","OPEN") -> OPEN | L12: thermal capacity and requirement
A13: CT-C-B-CAP | B13: CT-C-B | C13: βC | D13: capacity calibration factor | E13: ratio | H13: 0 | I13: full-range metered capacity sweep | J13: nominal rating or sibling derate | K13: =IF(AND(ISNUMBER(F13),ISNUMBER(G13),H13=1),"BOUNDED","OPEN") -> OPEN | L13: capacity lower bound
A14: CT-C-B-REQ | B14: CT-C-B | C14: βR | D14: service requirement scale factor | E14: ratio | H14: 0 | I14: receiver-denominator replay | J14: interval midpoint or average receiver | K14: =IF(AND(ISNUMBER(F14),ISNUMBER(G14),H14=1),"BOUNDED","OPEN") -> OPEN | L14: requirement upper bound
A15: CT-C-B-LOSS | B15: CT-C-B | C15: λ | D15: largest-cell propagation fraction | E15: share | H15: 0 | I15: instrumented cell-loss trial | J15: independence declaration | K15: =IF(AND(ISNUMBER(F15),ISNUMBER(G15),H15=1),"BOUNDED","OPEN") -> OPEN | L15: loss-world capacity
A16: CT-C-B-KEY | B16: CT-C-B | C16: κ | D16: fatal-keystone retained fraction | E16: share | H16: 0 | I16: frozen keystone intervention | J16: modeled safeing or operator judgment | K16: =IF(AND(ISNUMBER(F16),ISNUMBER(G16),H16=1),"BOUNDED","OPEN") -> OPEN | L16: fatal-world capacity
A17: CT-C-B-COLD | B17: CT-C-B | C17: χ | D17: cold-start retained fraction | E17: share | H17: 0 | I17: clean-team reconstruction and black start | J17: builder demonstration or vendor runtime | K17: =IF(AND(ISNUMBER(F17),ISNUMBER(G17),H17=1),"BOUNDED","OPEN") -> OPEN | L17: cold-start capacity
A18: CT-C-B-THERM | B18: CT-C-B | C18: θ | D18: peak thermal duty coefficient | E18: form-native | H18: 0 | I18: worst-ambient calorimetry and heat rejection | J18: electrical surplus or sibling coefficient | K18: =IF(AND(ISNUMBER(F18),ISNUMBER(G18),H18=1),"BOUNDED","OPEN") -> OPEN | L18: thermal capacity and requirement
... A42: RT-B-C-THERM | B42: RT-B-C | C42: θ | D42: peak thermal duty coefficient | E42: form-native | H42: 0 | I42: worst-ambient calorimetry and heat rejection | J42: electrical surplus or sibling coefficient | K42: =IF(AND(ISNUMBER(F42),ISNUMBER(G42),H42=1),"BOUNDED","OPEN") -> OPEN | L42: thermal capacity and requirement

Sheet Thermal Experiments
A2: Thermal closure experiments
A4: Electrical reserve cannot establish heat rejection, occupied-zone temperature, reservoir balance or process thermal safety.
A6: Form | B6: Thermal coefficient | C6: Control envelope | D6: Measured boundary | E6: Instrumentation | F6: Required intervention | G6: Closure condition | H6: Current bound | I6: State | J6: Technology consequence
A7: ET-A-A | B7: MWth per dry-custody t/h | C7: peak relative motion; warm seawater; saturated air | D7: connector drive, drying, refrigeration and refuge rejection | E7: shaft torque, calorimetry, wet/dry enthalpy and zone temperature | F7: disable one body and one rejection loop | G7: upper duty remains below surviving exchanger capacity with no wet-dry propagation | I7: OPEN | J7: two-body heat rejection must remain independent across the transfer saddle
A8: CT-C-B | B8: MWth per delivered utility MW | C8: occupied envelope; smoke-control limit; severed mixed trunk | D8: conversion loss, cable heat, smoke transport and indoor rejection | E8: distributed temperature, smoke, current, flow and pressure tomography | F8: fault and guillotine one mixed-utility segment | G8: occupied-zone limits hold after isolation without exporting heat or smoke | I8: OPEN | J8: utility guillotines need thermal as well as hydraulic and electrical selectivity
A9: HC-A-C | B9: MJth per held-line km | C9: hot-day plume; hover; 72 h duty; denied coordination | D9: rotor drive, battery or fluid exchange, payload and refuge thermal state | E9: cell calorimetry, winding and pack temperature, plume and refill enthalpy | F9: safe one cell inside plume and continue locally | G9: four cells hold the line without thermal runaway or shared cooling | I9: OPEN | J9: hot-zone exchange must be cell-local and operable without the mesh
A10: LF-B-A | B10: MWth per thousand m3/day | C10: reservoir decline; full salinity; ambient maximum | D10: wellhead enthalpy, conversion rejection, product cooling and reinjection | E10: mass-flow and enthalpy metering from bore through injection | F10: isolate one header, conversion cell and bore at full state | G10: three conversion cells and two injection paths close enthalpy and chemistry | I10: OPEN | J10: brine-to-mineral metabolism becomes part of heat rejection, not a byproduct
A11: HU-A-B | B11: MWth per complete care line | C11: full census; hot-humid ambient; sterile and cold-chain duty | D11: clinical sensible and latent load, sterilization, refrigeration and refuge | E11: zone calorimetry, humidity, cold-chain and utility metering | F11: block one spine section and one cooling path | G11: all ten care lines remain within clinical temperature and humidity limits | I11: OPEN | J11: bypass architecture must carry thermal continuity with clinical continuity
A12: RT-B-C | B12: MJth per released product-equivalent | C12: worst product mix; pulsed loads; islanded trainlets | D12: process heat, machine losses, quarantine and rejected-material cooling | E12: machine-level energy, calorimetry and material-ancestry ledger | F12: isolate one trainlet and its largest energy cell | G12: four trainlets preserve qualified release without shared heat sink | I12: OPEN | J12: self-describing process chains must include heat and cooling ancestry

Sheet World Rules
A2: World-specific numerical law
A4: The same content-addressed baseline enters every world. Reconfiguration, receiver substitution and cross-form borrowing are prohibited.
A6: World | B6: Capacity basis | C6: Requirement basis | D6: Uncertainty treatment | E6: Missing-value treatment | F6: Allowed closure | G6: Current bounded cells | H6: Current disposition | I6: Reason
A7: NOMINAL | B7: nominal | C7: nominal | D7: capacity lower bound versus requirement upper bound | E7: HOLD; never zero or midpoint | F7: all five accounts conjunctive | G7: =COUNTIFS('Closure Cells'!$D$7:$D$126,A7,'Closure Cells'!$N$7:$N$126,"BOUNDED") -> 24 | H7: =IF(COUNTIFS('Closure Cells'!$D$7:$D$126,A7,'Closure Cells'!$O$7:$O$126,"HOLD")>0,"HOLD",IF(COUNTIFS('Closure Cells'!$D$7:$D$126,A7,'Closure Cells'!$O$7:$O$126,"FAIL")>0,"FAIL","CLOSE")) -> HOLD | I7: No denial; configured service denominator applies.
