Workbook

Sheet Summary
A2: Six-root quantitative causal-section triage
A4: Result: the six roots do not close. Forty-five cells close numerically, fourteen are negative and eighty-five remain unquantified; all six roots require resize and remain held.
A6: Measure | B6: Result | D6: Root | E6: Article | F6: Negative | G6: Unquantified | H6: Worst margin | I6: G06 | J6: Disposition | L6: Root | M6: Worst margin
A7: Roots fully closed | B7: =SUM('Root Triage'!I7:I12) -> 0 | D7: ='Root Triage'!B7 -> ET-A | E7: ='Root Triage'!C7 -> Pelagic exchange cell | F7: ='Root Triage'!F7 -> 1 | G7: ='Root Triage'!G7 -> 14 | H7: ='Root Triage'!H7 -> -0.0016 | I7: ='Root Triage'!J7 -> 0 | J7: ='Root Triage'!K7 -> RESIZE / HOLD | L7: ET-A | M7: ='Root Triage'!H7 -> -0.0016
A8: Numeric cells closed | B8: =COUNTIFS('Closure Cells'!Q7:Q150,"CLOSE") -> 45 | D8: ='Root Triage'!B8 -> CT-C | E8: ='Root Triage'!C8 -> Occupied-building utility-spine sector | F8: ='Root Triage'!F8 -> 1 | G8: ='Root Triage'!G8 -> 14 | H8: ='Root Triage'!H8 -> -0.025 | I8: ='Root Triage'!J8 -> 0 | J8: ='Root Triage'!K8 -> RESIZE / HOLD | L8: CT-C | M8: ='Root Triage'!H8 -> -0.025
A9: Negative cells | B9: =COUNTIFS('Closure Cells'!Q7:Q150,"NEGATIVE") -> 14 | D9: ='Root Triage'!B9 -> HC-A | E9: ='Root Triage'!C9 -> Atmospheric intervention cell | F9: ='Root Triage'!F9 -> 2 | G9: ='Root Triage'!G9 -> 14 | H9: ='Root Triage'!H9 -> -0.0016 | I9: ='Root Triage'!J9 -> 0 | J9: ='Root Triage'!K9 -> RESIZE / HOLD | L9: HC-A | M9: ='Root Triage'!H9 -> -0.0016
A10: Unquantified cells | B10: =COUNTIFS('Closure Cells'!Q7:Q150,"UNQUANTIFIED") -> 85 | D10: ='Root Triage'!B10 -> LF-B | E10: ='Root Triage'!C10 -> Geothermal source position | F10: ='Root Triage'!F10 -> 8 | G10: ='Root Triage'!G10 -> 15 | H10: ='Root Triage'!H10 -> -1 | I10: ='Root Triage'!J10 -> 0 | J10: ='Root Triage'!K10 -> RESIZE / HOLD | L10: HU-A | M10: ='Root Triage'!H11 -> -0.0172
A11: Total closure cells | B11: =COUNTA('Closure Cells'!A7:A150) -> 144 | D11: ='Root Triage'!B11 -> HU-A | E11: ='Root Triage'!C11 -> Complete clinical island | F11: ='Root Triage'!F11 -> 1 | G11: ='Root Triage'!G11 -> 14 | H11: ='Root Triage'!H11 -> -0.0172 | I11: ='Root Triage'!J11 -> 0 | J11: ='Root Triage'!K11 -> RESIZE / HOLD | L11: RT-B | M11: ='Root Triage'!H12 -> -0.018709677
A12: Resize orders | B12: =COUNTA('Resize Orders'!A7:A17) -> 11 | D12: ='Root Triage'!B12 -> RT-B | E12: ='Root Triage'!C12 -> Disconnected microfactory mesh | F12: ='Root Triage'!F12 -> 1 | G12: ='Root Triage'!G12 -> 14 | H12: ='Root Triage'!H12 -> -0.018709677 | I12: ='Root Triage'!J12 -> 0 | J12: ='Root Triage'!K12 -> RESIZE / HOLD
A13: Maximum FRAME ceiling USD B | B13: =Finance!F13 -> 0.53803692
A14: Accepted authority USD B | B14: =Finance!G13 -> 0
A15: Physical observations | B15: =Controls!B18 -> 0
A16: Rendering authority | B16: =Controls!B21 -> 0

Sheet Controls
A2: Authoritative quantitative-triage controls
A4: Blue cells are controlled planning inputs. Missing physical coefficients remain blank and do not become zero.
A6: Control | B6: Value | C6: Unit | D6: Authority
A7: adverse coefficient screen | B7: 0.025 | C7: share | D7: Pass 182 sensitivity boundary
A8: closure threshold | B8: 1 | C8: ratio | D8: Pass 216 endpoint rule
A9: roots | B9: 6 | C9: count | D9: Pass 211 / 216
A10: accounts | B10: 6 | C10: count | D10: Pass 217
A11: worlds | B11: 4 | C11: count | D11: Pass 217
A12: closure cells | B12: 144 | C12: count | D12: Pass 217
A13: option ceiling | B13: 3.5869128 | C13: USD B | D13: Pass 215
A14: FRAME share | B14: 0.15 | C14: share | D14: Pass 215
A15: FRAME ceiling | B15: 0.53803692 | C15: USD B | D15: direct arithmetic
A16: accepted authority | B16: 0 | C16: USD B | D16: held
A17: paid authority | B17: 0 | C17: USD B | D17: held
A18: physical observations | B18: 0 | C18: count | D18: source empty
... A21: rendering authority | B21: 0 | C21: count | D21: held

Sheet Root Baselines
A2: Thirty-six root-native account bases
A4: These are inherited controlled hypotheses and direct arithmetic, not observations. Blanks identify quantities the repository has not yet established.
A6: System | B6: Root | C6: Account | D6: Closure account | E6: Native metric | F6: Unit | G6: W01 capacity / limit | H6: W01 requirement / burden | I6: W03 capacity / limit | J6: W03 requirement / burden | K6: Adverse screen | L6: Internal authority | M6: Interpretation
A7: MS-ET | B7: ET-A | C7: A01 | D7: Mass and material custody | E7: deployment access envelope | F7: t | G7: 128000 | H7: 102000 | I7: 112000 | J7: 102000 | K7: =Controls!$B$7 -> 0.025 | L7: Pass 182 Mass Access | M7: 8 cells × 16,000 t; seven survive
A8: MS-ET | B8: ET-A | C8: A02 | D8: Energy and heat | E8: firm generation and black start minimum | F8: MW-equivalent | G8: 120 | H8: 96 | I8: 100 | J8: 96 | K8: =Controls!$B$7 -> 0.025 | L8: Pass 182 Energy | M8: six 20 MW cells; five survive
A9: MS-ET | B9: ET-A | C9: A03 | D9: Geometry and load path | E9: minimum complete-route flow | F9: ratio | G9: 1.28 | H9: 1 | I9: 1.024 | J9: 1 | K9: =Controls!$B$7 -> 0.025 | L9: Pass 182 Route Flow | M9: governing 5,630 t/day route
A10: MS-ET | B10: ET-A | C10: A04 | D10: Safe state and human boundary | E10: minimum refuge and receiver ratio | F10: ratio | G10: 1.26 | H10: 1 | I10: 1.05 | J10: 1 | K10: =Controls!$B$7 -> 0.025 | L10: Pass 182 Safety / Receivers | M10: conjunctive minimum
A11: MS-ET | B11: ET-A | C11: A05 | D11: Residual and environmental custody | E11: owned treatment and buffer | F11: t/day | G11: 1512 | H11: 1200 | I11: 1260 | J11: 1200 | K11: =Controls!$B$7 -> 0.025 | L11: Pass 182 Residual | M11: six cells; five survive
A12: MS-ET | B12: ET-A | C12: A06 | D12: Removal and cold reconstruction | E12: cold-rebuild completion | F12: h | H12: 168 | J12: 168 | K12: =Controls!$B$7 -> 0.025 | L12: Pass 216 Form Loads | M12: upper completion time absent
A13: MS-CT | B13: CT-C | C13: A01 | D13: Mass and material custody | E13: deployment access envelope | F13: t | G13: 36000 | H13: 31000 | I13: 32400 | J13: 31000 | K13: =Controls!$B$7 -> 0.025 | L13: Pass 182 Mass Access | M13: ten 3,600 t cells; nine survive
A14: MS-CT | B14: CT-C | C14: A02 | D14: Energy and heat | E14: firm generation and black start minimum | F14: MW-equivalent | G14: 49 | H14: 42 | I14: 42 | J14: 42 | K14: =Controls!$B$7 -> 0.025 | L14: Pass 182 Energy | M14: seven 7 MW cells; six survive
A15: MS-CT | B15: CT-C | C15: A03 | D15: Geometry and load path | E15: minimum governed route ratio | F15: ratio | G15: 1.32 | H15: 1 | I15: 1.056 | J15: 1 | K15: =Controls!$B$7 -> 0.025 | L15: Pass 182 Route Flow | M15: people, household and route minima
A16: MS-CT | B16: CT-C | C16: A04 | D16: Safe state and human boundary | E16: minimum refuge and receiver ratio | F16: ratio | G16: 1.2 | H16: 1 | I16: 1.05 | J16: 1 | K16: =Controls!$B$7 -> 0.025 | L16: Pass 182 Safety / Receivers | M16: conjunctive minimum
A17: MS-CT | B17: CT-C | C17: A05 | D17: Residual and environmental custody | E17: owned dirty-return treatment | F17: t/day | G17: 277.2 | H17: 220 | I17: 231 | J17: 220 | K17: =Controls!$B$7 -> 0.025 | L17: Pass 182 Residual | M17: six cells; five survive
A18: MS-CT | B18: CT-C | C18: A06 | D18: Removal and cold reconstruction | E18: cold-rebuild completion | F18: h | H18: 168 | J18: 168 | K18: =Controls!$B$7 -> 0.025 | L18: Pass 217 section grammar | M18: upper completion time absent
A19: MS-HC | B19: HC-A | C19: A01 | D19: Mass and material custody | E19: deployment access envelope | F19: t | G19: 63000 | H19: 54000 | I19: 56700 | J19: 54000 | K19: =Controls!$B$7 -> 0.025 | L19: Pass 182 Mass Access | M19: ten 6,300 t cells; nine survive
A20: MS-HC | B20: HC-A | C20: A02 | D20: Energy and heat | E20: firm generation and black start minimum | F20: MW-equivalent | G20: 164 | H20: 140 | I20: 143.5 | J20: 140 | K20: =Controls!$B$7 -> 0.025 | L20: Pass 182 Energy | M20: eight 20.5 MW cells; seven survive
A21: MS-HC | B21: HC-A | C21: A03 | D21: Geometry and load path | E21: minimum held-line route ratio | F21: ratio | G21: 1.28 | H21: 1 | I21: 1.024 | J21: 1 | K21: =Controls!$B$7 -> 0.025 | L21: Pass 182 Route Flow | M21: 103 km/day controlling route
A22: MS-HC | B22: HC-A | C22: A04 | D22: Safe state and human boundary | E22: minimum refuge and receiver ratio | F22: ratio | G22: 1.2 | H22: 1 | I22: 1.05 | J22: 1 | K22: =Controls!$B$7 -> 0.025 | L22: Pass 182 Safety / Receivers | M22: conjunctive minimum
A23: MS-HC | B23: HC-A | C23: A05 | D23: Residual and environmental custody | E23: owned runoff/material treatment | F23: t/day | G23: 1134 | H23: 900 | I23: 945 | J23: 900 | K23: =Controls!$B$7 -> 0.025 | L23: Pass 182 Residual | M23: six? controlling distributed cells
A24: MS-HC | B24: HC-A | C24: A06 | D24: Removal and cold reconstruction | E24: cold-rebuild completion | F24: h | H24: 168 | J24: 168 | K24: =Controls!$B$7 -> 0.025 | L24: Pass 217 section grammar | M24: upper completion time absent
A25: MS-LF | B25: LF-B | C25: A01 | D25: Mass and material custody | E25: one-position access allowance | F25: t | G25: 31075 | H25: 31075 | J25: 31075 | K25: =Controls!$B$7 -> 0.025 | L25: Pass 183 Article Bill / direct quarter arithmetic | M25: 31,075 t identity; no independent access cell
A26: MS-LF | B26: LF-B | C26: A02 | D26: Energy and heat | E26: source-position firm bus | F26: MW | G26: 40 | H26: 37.351042 | I26: 0 | J26: 37.351042 | K26: =Controls!$B$7 -> 0.025 | L26: Pass 183 Source Balance | M26: single bus has no declared N−1 partition
A27: MS-LF | B27: LF-B | C27: A03 | D27: Geometry and load path | E27: two 15 km water paths | F27: pipe-km | G27: 30 | H27: 30 | I27: 15 | J27: 15 | K27: =Controls!$B$7 -> 0.025 | L27: Pass 216 Form Loads | M27: one full path survives, but no usable-route reserve
A28: MS-LF | B28: LF-B | C28: A04 | D28: Safe state and human boundary | E28: one-day buffer and black start | F28: ratio | G28: 1 | H28: 1 | I28: 0 | J28: 1 | K28: =Controls!$B$7 -> 0.025 | L28: Pass 216 Form Loads | M28: no independent buffer partition declared
A29: MS-LF | B29: LF-B | C29: A05 | D29: Residual and environmental custody | E29: wastewater/brine intake | F29: m3/day | G29: 20000 | H29: 20000 | I29: 0 | J29: 20000 | K29: =Controls!$B$7 -> 0.025 | L29: Pass 216 Form Loads | M29: single injection route is decisive
A30: MS-LF | B30: LF-B | C30: A06 | D30: Removal and cold reconstruction | E30: cold-rebuild completion | F30: h | H30: 168 | J30: 168 | K30: =Controls!$B$7 -> 0.025 | L30: Pass 217 section grammar | M30: upper completion time absent
A31: MS-HU | B31: HU-A | C31: A01 | D31: Mass and material custody | E31: deployment access envelope | F31: t | G31: 57600 | H31: 50000 | I31: 50400 | J31: 50000 | K31: =Controls!$B$7 -> 0.025 | L31: Pass 182 Mass Access | M31: eight 7,200 t cells; seven survive
A32: MS-HU | B32: HU-A | C32: A02 | D32: Energy and heat | E32: firm generation and black start minimum | F32: MW-equivalent | G32: 66 | H32: 52 | I32: 55 | J32: 52 | K32: =Controls!$B$7 -> 0.025 | L32: Pass 182 Energy | M32: six 11 MW cells; five survive
A33: MS-HU | B33: HU-A | C33: A03 | D33: Geometry and load path | E33: minimum care/transfer route ratio | F33: ratio | G33: 1.28 | H33: 1 | I33: 1.032 | J33: 1 | K33: =Controls!$B$7 -> 0.025 | L33: Pass 182 Route Flow | M33: definitive-care loss case governs
A34: MS-HU | B34: HU-A | C34: A04 | D34: Safe state and human boundary | E34: minimum refuge and receiver ratio | F34: ratio | G34: 1.2 | H34: 1 | I34: 1.05 | J34: 1 | K34: =Controls!$B$7 -> 0.025 | L34: Pass 182 Safety / Receivers | M34: conjunctive minimum
A35: MS-HU | B35: HU-A | C35: A05 | D35: Residual and environmental custody | E35: owned clinical residual treatment | F35: t/day | G35: 441 | H35: 350 | I35: 367.5 | J35: 350 | K35: =Controls!$B$7 -> 0.025 | L35: Pass 182 Residual | M35: six cells; five survive
A36: MS-HU | B36: HU-A | C36: A06 | D36: Removal and cold reconstruction | E36: cold-rebuild completion | F36: h | H36: 168 | J36: 168 | K36: =Controls!$B$7 -> 0.025 | L36: Pass 217 section grammar | M36: upper completion time absent
A37: MS-RT | B37: RT-B | C37: A01 | D37: Mass and material custody | E37: deployment access envelope | F37: t | G37: 84000 | H37: 72000 | I37: 75600 | J37: 72000 | K37: =Controls!$B$7 -> 0.025 | L37: Pass 182 Mass Access | M37: ten 8,400 t cells; nine survive
A38: MS-RT | B38: RT-B | C38: A02 | D38: Energy and heat | E38: firm process energy and black start | F38: MW-equivalent | G38: 182 | H38: 155 | I38: 156 | J38: 155 | K38: =Controls!$B$7 -> 0.025 | L38: Pass 182 Energy | M38: seven 26 MW cells; six survive
A39: MS-RT | B39: RT-B | C39: A03 | D39: Geometry and load path | E39: minimum complete-process route ratio | F39: ratio | G39: 1.3 | H39: 1 | I39: 1.04 | J39: 1 | K39: =Controls!$B$7 -> 0.025 | L39: Pass 182 Route Flow | M39: 99-position replacement route
A40: MS-RT | B40: RT-B | C40: A04 | D40: Safe state and human boundary | E40: minimum refuge and receiver ratio | F40: ratio | G40: 1.18125 | H40: 1 | I40: 1.05 | J40: 1 | K40: =Controls!$B$7 -> 0.025 | L40: Pass 182 Safety / Receivers | M40: receiver interface governs nominal
A41: MS-RT | B41: RT-B | C41: A05 | D41: Residual and environmental custody | E41: owned dirty-return treatment | F41: t/day | G41: 1512 | H41: 1200 | I41: 1260 | J41: 1200 | K41: =Controls!$B$7 -> 0.025 | L41: Pass 182 Residual | M41: six cells; five survive
A42: MS-RT | B42: RT-B | C42: A06 | D42: Removal and cold reconstruction | E42: cold-rebuild completion | F42: h | H42: 168 | J42: 168 | K42: =Controls!$B$7 -> 0.025 | L42: Pass 216 Form Loads | M42: upper completion time absent

Sheet Account Rules
A2: Six noncompensatory closure accounts
A4: All numeric worlds use the lower owned bound after the controlled adverse screen. A missing input remains unquantified.
A6: Account | B6: Closure account | C6: Decision expression | D6: Form
A7: A01 | B7: Mass and material custody | C7: lower owned capacity / upper burden | D7: capacity ratio
A8: A02 | B8: Energy and heat | C8: lower owned capacity / upper demand | D8: capacity ratio
A9: A03 | B9: Geometry and load path | C9: lower usable geometry / upper required geometry | D9: capacity ratio
A10: A04 | B10: Safe state and human boundary | C10: minimum conjunctive safe-state ratio | D10: conjunctive ratio
A11: A05 | B11: Residual and environmental custody | C11: lower owned treatment / upper generated residual | D11: capacity ratio
A12: A06 | B12: Removal and cold reconstruction | C12: time ceiling / upper observed reconstruction time | D12: time ratio

Sheet Worlds
A2: Four required quantitative worlds
A4: W02 and W04 cannot inherit a paper ratio: both require new physical coefficients and executable records.
A6: World | B6: State | C6: Closure rule
A7: W01 | B7: Nominal mission | C7: Declared article mission; lower-bound ratio must be at least 1.00
A8: W02 | B8: Fatal-keystone challenge | C8: No numeric survival credit before a valid full-scale causal challenge
A9: W03 | B9: Largest-independent-cell loss | C9: Largest declared independent cell or path removed; lower-bound ratio must be at least 1.00
A10: W04 | B10: Cold reconstruction | C10: Outside team, frozen records, no originating runtime; no credit before executable record and timed replay

Sheet Closure Cells
A2: One hundred forty-four root-account-world cells
A4: A blank quantitative input remains blank. It cannot be treated as zero, passed through an average or borrowed from a host.
A6: Cell | B6: System | C6: Root | D6: Account | E6: Closure account | F6: World | G6: World state | H6: Native metric | I6: Unit | J6: Capacity / limit | K6: Requirement / burden | L6: Base ratio | M6: Adverse screen | N6: Lower-bound ratio | O6: Margin | P6: Quantified | Q6: Disposition | R6: Basis or missing input | S6: Host contribution | T6: Evidence accepted
A7: ET-A-A01-W01 | B7: MS-ET | C7: ET-A | D7: A01 | E7: Mass and material custody | F7: W01 | G7: Nominal mission | H7: deployment access envelope | I7: t | J7: 128000 | K7: 102000 | L7: =IF(AND(ISNUMBER(J7),ISNUMBER(K7),K7>0),J7/K7,"") -> 1.254902 | M7: =Controls!$B$7 -> 0.025 | N7: =IF(P7=1,L7*(1-M7),"") -> 1.2235294 | O7: =IF(P7=1,N7-Controls!$B$8,"") -> 0.22352941 | P7: =IF(AND(ISNUMBER(J7),ISNUMBER(K7),K7>0),1,0) -> 1 | Q7: =IF(P7=0,"UNQUANTIFIED",IF(O7>=0,"CLOSE","NEGATIVE")) -> CLOSE | R7: Pass 182 Mass Access | S7: 0 | T7: 0
A8: ET-A-A01-W02 | B8: MS-ET | C8: ET-A | D8: A01 | E8: Mass and material custody | F8: W02 | G8: Fatal-keystone challenge | H8: deployment access envelope | I8: t | L8: =IF(AND(ISNUMBER(J8),ISNUMBER(K8),K8>0),J8/K8,"") | M8: =Controls!$B$7 -> 0.025 | N8: =IF(P8=1,L8*(1-M8),"") | O8: =IF(P8=1,N8-Controls!$B$8,"") | P8: =IF(AND(ISNUMBER(J8),ISNUMBER(K8),K8>0),1,0) -> 0 | Q8: =IF(P8=0,"UNQUANTIFIED",IF(O8>=0,"CLOSE","NEGATIVE")) -> UNQUANTIFIED | R8: fatal-keystone coefficient and valid full-scale outcome absent | S8: 0 | T8: 0
A9: ET-A-A01-W03 | B9: MS-ET | C9: ET-A | D9: A01 | E9: Mass and material custody | F9: W03 | G9: Largest-independent-cell loss | H9: deployment access envelope | I9: t | J9: 112000 | K9: 102000 | L9: =IF(AND(ISNUMBER(J9),ISNUMBER(K9),K9>0),J9/K9,"") -> 1.0980392 | M9: =Controls!$B$7 -> 0.025 | N9: =IF(P9=1,L9*(1-M9),"") -> 1.0705882 | O9: =IF(P9=1,N9-Controls!$B$8,"") -> 0.070588235 | P9: =IF(AND(ISNUMBER(J9),ISNUMBER(K9),K9>0),1,0) -> 1 | Q9: =IF(P9=0,"UNQUANTIFIED",IF(O9>=0,"CLOSE","NEGATIVE")) -> CLOSE | R9: Pass 182 Mass Access | S9: 0 | T9: 0
A10: ET-A-A01-W04 | B10: MS-ET | C10: ET-A | D10: A01 | E10: Mass and material custody | F10: W04 | G10: Cold reconstruction | H10: deployment access envelope | I10: t | L10: =IF(AND(ISNUMBER(J10),ISNUMBER(K10),K10>0),J10/K10,"") | M10: =Controls!$B$7 -> 0.025 | N10: =IF(P10=1,L10*(1-M10),"") | O10: =IF(P10=1,N10-Controls!$B$8,"") | P10: =IF(AND(ISNUMBER(J10),ISNUMBER(K10),K10>0),1,0) -> 0 | Q10: =IF(P10=0,"UNQUANTIFIED",IF(O10>=0,"CLOSE","NEGATIVE")) -> UNQUANTIFIED | R10: outside-team build record and upper reconstruction time absent | S10: 0 | T10: 0
A11: ET-A-A02-W01 | B11: MS-ET | C11: ET-A | D11: A02 | E11: Energy and heat | F11: W01 | G11: Nominal mission | H11: firm generation and black start minimum | I11: MW-equivalent | J11: 120 | K11: 96 | L11: =IF(AND(ISNUMBER(J11),ISNUMBER(K11),K11>0),J11/K11,"") -> 1.25 | M11: =Controls!$B$7 -> 0.025 | N11: =IF(P11=1,L11*(1-M11),"") -> 1.21875 | O11: =IF(P11=1,N11-Controls!$B$8,"") -> 0.21875 | P11: =IF(AND(ISNUMBER(J11),ISNUMBER(K11),K11>0),1,0) -> 1 | Q11: =IF(P11=0,"UNQUANTIFIED",IF(O11>=0,"CLOSE","NEGATIVE")) -> CLOSE | R11: Pass 182 Energy | S11: 0 | T11: 0
A12: ET-A-A02-W02 | B12: MS-ET | C12: ET-A | D12: A02 | E12: Energy and heat | F12: W02 | G12: Fatal-keystone challenge | H12: firm generation and black start minimum | I12: MW-equivalent | L12: =IF(AND(ISNUMBER(J12),ISNUMBER(K12),K12>0),J12/K12,"") | M12: =Controls!$B$7 -> 0.025 | N12: =IF(P12=1,L12*(1-M12),"") | O12: =IF(P12=1,N12-Controls!$B$8,"") | P12: =IF(AND(ISNUMBER(J12),ISNUMBER(K12),K12>0),1,0) -> 0 | Q12: =IF(P12=0,"UNQUANTIFIED",IF(O12>=0,"CLOSE","NEGATIVE")) -> UNQUANTIFIED | R12: fatal-keystone coefficient and valid full-scale outcome absent | S12: 0 | T12: 0
A13: ET-A-A02-W03 | B13: MS-ET | C13: ET-A | D13: A02 | E13: Energy and heat | F13: W03 | G13: Largest-independent-cell loss | H13: firm generation and black start minimum | I13: MW-equivalent | J13: 100 | K13: 96 | L13: =IF(AND(ISNUMBER(J13),ISNUMBER(K13),K13>0),J13/K13,"") -> 1.0416667 | M13: =Controls!$B$7 -> 0.025 | N13: =IF(P13=1,L13*(1-M13),"") -> 1.015625 | O13: =IF(P13=1,N13-Controls!$B$8,"") -> 0.015625 | P13: =IF(AND(ISNUMBER(J13),ISNUMBER(K13),K13>0),1,0) -> 1 | Q13: =IF(P13=0,"UNQUANTIFIED",IF(O13>=0,"CLOSE","NEGATIVE")) -> CLOSE | R13: Pass 182 Energy | S13: 0 | T13: 0
A14: ET-A-A02-W04 | B14: MS-ET | C14: ET-A | D14: A02 | E14: Energy and heat | F14: W04 | G14: Cold reconstruction | H14: firm generation and black start minimum | I14: MW-equivalent | L14: =IF(AND(ISNUMBER(J14),ISNUMBER(K14),K14>0),J14/K14,"") | M14: =Controls!$B$7 -> 0.025 | N14: =IF(P14=1,L14*(1-M14),"") | O14: =IF(P14=1,N14-Controls!$B$8,"") | P14: =IF(AND(ISNUMBER(J14),ISNUMBER(K14),K14>0),1,0) -> 0 | Q14: =IF(P14=0,"UNQUANTIFIED",IF(O14>=0,"CLOSE","NEGATIVE")) -> UNQUANTIFIED | R14: outside-team build record and upper reconstruction time absent | S14: 0 | T14: 0
A15: ET-A-A03-W01 | B15: MS-ET | C15: ET-A | D15: A03 | E15: Geometry and load path | F15: W01 | G15: Nominal mission | H15: minimum complete-route flow | I15: ratio | J15: 1.28 | K15: 1 | L15: =IF(AND(ISNUMBER(J15),ISNUMBER(K15),K15>0),J15/K15,"") -> 1.28 | M15: =Controls!$B$7 -> 0.025 | N15: =IF(P15=1,L15*(1-M15),"") -> 1.248 | O15: =IF(P15=1,N15-Controls!$B$8,"") -> 0.248 | P15: =IF(AND(ISNUMBER(J15),ISNUMBER(K15),K15>0),1,0) -> 1 | Q15: =IF(P15=0,"UNQUANTIFIED",IF(O15>=0,"CLOSE","NEGATIVE")) -> CLOSE | R15: Pass 182 Route Flow | S15: 0 | T15: 0
A16: ET-A-A03-W02 | B16: MS-ET | C16: ET-A | D16: A03 | E16: Geometry and load path | F16: W02 | G16: Fatal-keystone challenge | H16: minimum complete-route flow | I16: ratio | L16: =IF(AND(ISNUMBER(J16),ISNUMBER(K16),K16>0),J16/K16,"") | M16: =Controls!$B$7 -> 0.025 | N16: =IF(P16=1,L16*(1-M16),"") | O16: =IF(P16=1,N16-Controls!$B$8,"") | P16: =IF(AND(ISNUMBER(J16),ISNUMBER(K16),K16>0),1,0) -> 0 | Q16: =IF(P16=0,"UNQUANTIFIED",IF(O16>=0,"CLOSE","NEGATIVE")) -> UNQUANTIFIED | R16: fatal-keystone coefficient and valid full-scale outcome absent | S16: 0 | T16: 0
A17: ET-A-A03-W03 | B17: MS-ET | C17: ET-A | D17: A03 | E17: Geometry and load path | F17: W03 | G17: Largest-independent-cell loss | H17: minimum complete-route flow | I17: ratio | J17: 1.024 | K17: 1 | L17: =IF(AND(ISNUMBER(J17),ISNUMBER(K17),K17>0),J17/K17,"") -> 1.024 | M17: =Controls!$B$7 -> 0.025 | N17: =IF(P17=1,L17*(1-M17),"") -> 0.9984 | O17: =IF(P17=1,N17-Controls!$B$8,"") -> -0.0016 | P17: =IF(AND(ISNUMBER(J17),ISNUMBER(K17),K17>0),1,0) -> 1 | Q17: =IF(P17=0,"UNQUANTIFIED",IF(O17>=0,"CLOSE","NEGATIVE")) -> NEGATIVE | R17: Pass 182 Route Flow | S17: 0 | T17: 0
A18: ET-A-A03-W04 | B18: MS-ET | C18: ET-A | D18: A03 | E18: Geometry and load path | F18: W04 | G18: Cold reconstruction | H18: minimum complete-route flow | I18: ratio | L18: =IF(AND(ISNUMBER(J18),ISNUMBER(K18),K18>0),J18/K18,"") | M18: =Controls!$B$7 -> 0.025 | N18: =IF(P18=1,L18*(1-M18),"") | O18: =IF(P18=1,N18-Controls!$B$8,"") | P18: =IF(AND(ISNUMBER(J18),ISNUMBER(K18),K18>0),1,0) -> 0 | Q18: =IF(P18=0,"UNQUANTIFIED",IF(O18>=0,"CLOSE","NEGATIVE")) -> UNQUANTIFIED | R18: outside-team build record and upper reconstruction time absent | S18: 0 | T18: 0
A19: ET-A-A04-W01 | B19: MS-ET | C19: ET-A | D19: A04 | E19: Safe state and human boundary | F19: W01 | G19: Nominal mission | H19: minimum refuge and receiver ratio | I19: ratio | J19: 1.26 | K19: 1 | L19: =IF(AND(ISNUMBER(J19),ISNUMBER(K19),K19>0),J19/K19,"") -> 1.26 | M19: =Controls!$B$7 -> 0.025 | N19: =IF(P19=1,L19*(1-M19),"") -> 1.2285 | O19: =IF(P19=1,N19-Controls!$B$8,"") -> 0.2285 | P19: =IF(AND(ISNUMBER(J19),ISNUMBER(K19),K19>0),1,0) -> 1 | Q19: =IF(P19=0,"UNQUANTIFIED",IF(O19>=0,"CLOSE","NEGATIVE")) -> CLOSE | R19: Pass 182 Safety / Receivers | S19: 0 | T19: 0
A20: ET-A-A04-W02 | B20: MS-ET | C20: ET-A | D20: A04 | E20: Safe state and human boundary | F20: W02 | G20: Fatal-keystone challenge | H20: minimum refuge and receiver ratio | I20: ratio | L20: =IF(AND(ISNUMBER(J20),ISNUMBER(K20),K20>0),J20/K20,"") | M20: =Controls!$B$7 -> 0.025 | N20: =IF(P20=1,L20*(1-M20),"") | O20: =IF(P20=1,N20-Controls!$B$8,"") | P20: =IF(AND(ISNUMBER(J20),ISNUMBER(K20),K20>0),1,0) -> 0 | Q20: =IF(P20=0,"UNQUANTIFIED",IF(O20>=0,"CLOSE","NEGATIVE")) -> UNQUANTIFIED | R20: fatal-keystone coefficient and valid full-scale outcome absent | S20: 0 | T20: 0
A21: ET-A-A04-W03 | B21: MS-ET | C21: ET-A | D21: A04 | E21: Safe state and human boundary | F21: W03 | G21: Largest-independent-cell loss | H21: minimum refuge and receiver ratio | I21: ratio | J21: 1.05 | K21: 1 | L21: =IF(AND(ISNUMBER(J21),ISNUMBER(K21),K21>0),J21/K21,"") -> 1.05 | M21: =Controls!$B$7 -> 0.025 | N21: =IF(P21=1,L21*(1-M21),"") -> 1.02375 | O21: =IF(P21=1,N21-Controls!$B$8,"") -> 0.02375 | P21: =IF(AND(ISNUMBER(J21),ISNUMBER(K21),K21>0),1,0) -> 1 | Q21: =IF(P21=0,"UNQUANTIFIED",IF(O21>=0,"CLOSE","NEGATIVE")) -> CLOSE | R21: Pass 182 Safety / Receivers | S21: 0 | T21: 0
A22: ET-A-A04-W04 | B22: MS-ET | C22: ET-A | D22: A04 | E22: Safe state and human boundary | F22: W04 | G22: Cold reconstruction | H22: minimum refuge and receiver ratio | I22: ratio | L22: =IF(AND(ISNUMBER(J22),ISNUMBER(K22),K22>0),J22/K22,"") | M22: =Controls!$B$7 -> 0.025 | N22: =IF(P22=1,L22*(1-M22),"") | O22: =IF(P22=1,N22-Controls!$B$8,"") | P22: =IF(AND(ISNUMBER(J22),ISNUMBER(K22),K22>0),1,0) -> 0 | Q22: =IF(P22=0,"UNQUANTIFIED",IF(O22>=0,"CLOSE","NEGATIVE")) -> UNQUANTIFIED | R22: outside-team build record and upper reconstruction time absent | S22: 0 | T22: 0
A23: ET-A-A05-W01 | B23: MS-ET | C23: ET-A | D23: A05 | E23: Residual and environmental custody | F23: W01 | G23: Nominal mission | H23: owned treatment and buffer | I23: t/day | J23: 1512 | K23: 1200 | L23: =IF(AND(ISNUMBER(J23),ISNUMBER(K23),K23>0),J23/K23,"") -> 1.26 | M23: =Controls!$B$7 -> 0.025 | N23: =IF(P23=1,L23*(1-M23),"") -> 1.2285 | O23: =IF(P23=1,N23-Controls!$B$8,"") -> 0.2285 | P23: =IF(AND(ISNUMBER(J23),ISNUMBER(K23),K23>0),1,0) -> 1 | Q23: =IF(P23=0,"UNQUANTIFIED",IF(O23>=0,"CLOSE","NEGATIVE")) -> CLOSE | R23: Pass 182 Residual | S23: 0 | T23: 0
A24: ET-A-A05-W02 | B24: MS-ET | C24: ET-A | D24: A05 | E24: Residual and environmental custody | F24: W02 | G24: Fatal-keystone challenge | H24: owned treatment and buffer | I24: t/day | L24: =IF(AND(ISNUMBER(J24),ISNUMBER(K24),K24>0),J24/K24,"") | M24: =Controls!$B$7 -> 0.025 | N24: =IF(P24=1,L24*(1-M24),"") | O24: =IF(P24=1,N24-Controls!$B$8,"") | P24: =IF(AND(ISNUMBER(J24),ISNUMBER(K24),K24>0),1,0) -> 0 | Q24: =IF(P24=0,"UNQUANTIFIED",IF(O24>=0,"CLOSE","NEGATIVE")) -> UNQUANTIFIED | R24: fatal-keystone coefficient and valid full-scale outcome absent | S24: 0 | T24: 0
A25: ET-A-A05-W03 | B25: MS-ET | C25: ET-A | D25: A05 | E25: Residual and environmental custody | F25: W03 | G25: Largest-independent-cell loss | H25: owned treatment and buffer | I25: t/day | J25: 1260 | K25: 1200 | L25: =IF(AND(ISNUMBER(J25),ISNUMBER(K25),K25>0),J25/K25,"") -> 1.05 | M25: =Controls!$B$7 -> 0.025 | N25: =IF(P25=1,L25*(1-M25),"") -> 1.02375 | O25: =IF(P25=1,N25-Controls!$B$8,"") -> 0.02375 | P25: =IF(AND(ISNUMBER(J25),ISNUMBER(K25),K25>0),1,0) -> 1 | Q25: =IF(P25=0,"UNQUANTIFIED",IF(O25>=0,"CLOSE","NEGATIVE")) -> CLOSE | R25: Pass 182 Residual | S25: 0 | T25: 0
A26: ET-A-A05-W04 | B26: MS-ET | C26: ET-A | D26: A05 | E26: Residual and environmental custody | F26: W04 | G26: Cold reconstruction | H26: owned treatment and buffer | I26: t/day | L26: =IF(AND(ISNUMBER(J26),ISNUMBER(K26),K26>0),J26/K26,"") | M26: =Controls!$B$7 -> 0.025 | N26: =IF(P26=1,L26*(1-M26),"") | O26: =IF(P26=1,N26-Controls!$B$8,"") | P26: =IF(AND(ISNUMBER(J26),ISNUMBER(K26),K26>0),1,0) -> 0 | Q26: =IF(P26=0,"UNQUANTIFIED",IF(O26>=0,"CLOSE","NEGATIVE")) -> UNQUANTIFIED | R26: outside-team build record and upper reconstruction time absent | S26: 0 | T26: 0
A27: ET-A-A06-W01 | B27: MS-ET | C27: ET-A | D27: A06 | E27: Removal and cold reconstruction | F27: W01 | G27: Nominal mission | H27: cold-rebuild completion | I27: h | K27: 168 | L27: =IF(AND(ISNUMBER(J27),ISNUMBER(K27),K27>0),J27/K27,"") | M27: =Controls!$B$7 -> 0.025 | N27: =IF(P27=1,L27*(1-M27),"") | O27: =IF(P27=1,N27-Controls!$B$8,"") | P27: =IF(AND(ISNUMBER(J27),ISNUMBER(K27),K27>0),1,0) -> 0 | Q27: =IF(P27=0,"UNQUANTIFIED",IF(O27>=0,"CLOSE","NEGATIVE")) -> UNQUANTIFIED | R27: executable build record, frozen ancestry and upper reconstruction time absent | S27: 0 | T27: 0
A28: ET-A-A06-W02 | B28: MS-ET | C28: ET-A | D28: A06 | E28: Removal and cold reconstruction | F28: W02 | G28: Fatal-keystone challenge | H28: cold-rebuild completion | I28: h | L28: =IF(AND(ISNUMBER(J28),ISNUMBER(K28),K28>0),J28/K28,"") | M28: =Controls!$B$7 -> 0.025 | N28: =IF(P28=1,L28*(1-M28),"") | O28: =IF(P28=1,N28-Controls!$B$8,"") | P28: =IF(AND(ISNUMBER(J28),ISNUMBER(K28),K28>0),1,0) -> 0 | Q28: =IF(P28=0,"UNQUANTIFIED",IF(O28>=0,"CLOSE","NEGATIVE")) -> UNQUANTIFIED | R28: executable build record, frozen ancestry and upper reconstruction time absent | S28: 0 | T28: 0
A29: ET-A-A06-W03 | B29: MS-ET | C29: ET-A | D29: A06 | E29: Removal and cold reconstruction | F29: W03 | G29: Largest-independent-cell loss | H29: cold-rebuild completion | I29: h | K29: 168 | L29: =IF(AND(ISNUMBER(J29),ISNUMBER(K29),K29>0),J29/K29,"") | M29: =Controls!$B$7 -> 0.025 | N29: =IF(P29=1,L29*(1-M29),"") | O29: =IF(P29=1,N29-Controls!$B$8,"") | P29: =IF(AND(ISNUMBER(J29),ISNUMBER(K29),K29>0),1,0) -> 0 | Q29: =IF(P29=0,"UNQUANTIFIED",IF(O29>=0,"CLOSE","NEGATIVE")) -> UNQUANTIFIED | R29: executable build record, frozen ancestry and upper reconstruction time absent | S29: 0 | T29: 0
A30: ET-A-A06-W04 | B30: MS-ET | C30: ET-A | D30: A06 | E30: Removal and cold reconstruction | F30: W04 | G30: Cold reconstruction | H30: cold-rebuild completion | I30: h | L30: =IF(AND(ISNUMBER(J30),ISNUMBER(K30),K30>0),J30/K30,"") | M30: =Controls!$B$7 -> 0.025 | N30: =IF(P30=1,L30*(1-M30),"") | O30: =IF(P30=1,N30-Controls!$B$8,"") | P30: =IF(AND(ISNUMBER(J30),ISNUMBER(K30),K30>0),1,0) -> 0 | Q30: =IF(P30=0,"UNQUANTIFIED",IF(O30>=0,"CLOSE","NEGATIVE")) -> UNQUANTIFIED | R30: executable build record, frozen ancestry and upper reconstruction time absent | S30: 0 | T30: 0
A31: CT-C-A01-W01 | B31: MS-CT | C31: CT-C | D31: A01 | E31: Mass and material custody | F31: W01 | G31: Nominal mission | H31: deployment access envelope | I31: t | J31: 36000 | K31: 31000 | L31: =IF(AND(ISNUMBER(J31),ISNUMBER(K31),K31>0),J31/K31,"") -> 1.1612903 | M31: =Controls!$B$7 -> 0.025 | N31: =IF(P31=1,L31*(1-M31),"") -> 1.1322581 | O31: =IF(P31=1,N31-Controls!$B$8,"") -> 0.13225806 | P31: =IF(AND(ISNUMBER(J31),ISNUMBER(K31),K31>0),1,0) -> 1 | Q31: =IF(P31=0,"UNQUANTIFIED",IF(O31>=0,"CLOSE","NEGATIVE")) -> CLOSE | R31: Pass 182 Mass Access | S31: 0 | T31: 0
A32: CT-C-A01-W02 | B32: MS-CT | C32: CT-C | D32: A01 | E32: Mass and material custody | F32: W02 | G32: Fatal-keystone challenge | H32: deployment access envelope | I32: t | L32: =IF(AND(ISNUMBER(J32),ISNUMBER(K32),K32>0),J32/K32,"") | M32: =Controls!$B$7 -> 0.025 | N32: =IF(P32=1,L32*(1-M32),"") | O32: =IF(P32=1,N32-Controls!$B$8,"") | P32: =IF(AND(ISNUMBER(J32),ISNUMBER(K32),K32>0),1,0) -> 0 | Q32: =IF(P32=0,"UNQUANTIFIED",IF(O32>=0,"CLOSE","NEGATIVE")) -> UNQUANTIFIED | R32: fatal-keystone coefficient and valid full-scale outcome absent | S32: 0 | T32: 0
A33: CT-C-A01-W03 | B33: MS-CT | C33: CT-C | D33: A01 | E33: Mass and material custody | F33: W03 | G33: Largest-independent-cell loss | H33: deployment access envelope | I33: t | J33: 32400 | K33: 31000 | L33: =IF(AND(ISNUMBER(J33),ISNUMBER(K33),K33>0),J33/K33,"") -> 1.0451613 | M33: =Controls!$B$7 -> 0.025 | N33: =IF(P33=1,L33*(1-M33),"") -> 1.0190323 | O33: =IF(P33=1,N33-Controls!$B$8,"") -> 0.019032258 | P33: =IF(AND(ISNUMBER(J33),ISNUMBER(K33),K33>0),1,0) -> 1 | Q33: =IF(P33=0,"UNQUANTIFIED",IF(O33>=0,"CLOSE","NEGATIVE")) -> CLOSE | R33: Pass 182 Mass Access | S33: 0 | T33: 0
A34: CT-C-A01-W04 | B34: MS-CT | C34: CT-C | D34: A01 | E34: Mass and material custody | F34: W04 | G34: Cold reconstruction | H34: deployment access envelope | I34: t | L34: =IF(AND(ISNUMBER(J34),ISNUMBER(K34),K34>0),J34/K34,"") | M34: =Controls!$B$7 -> 0.025 | N34: =IF(P34=1,L34*(1-M34),"") | O34: =IF(P34=1,N34-Controls!$B$8,"") | P34: =IF(AND(ISNUMBER(J34),ISNUMBER(K34),K34>0),1,0) -> 0 | Q34: =IF(P34=0,"UNQUANTIFIED",IF(O34>=0,"CLOSE","NEGATIVE")) -> UNQUANTIFIED | R34: outside-team build record and upper reconstruction time absent | S34: 0 | T34: 0
A35: CT-C-A02-W01 | B35: MS-CT | C35: CT-C | D35: A02 | E35: Energy and heat | F35: W01 | G35: Nominal mission | H35: firm generation and black start minimum | I35: MW-equivalent | J35: 49 | K35: 42 | L35: =IF(AND(ISNUMBER(J35),ISNUMBER(K35),K35>0),J35/K35,"") -> 1.1666667 | M35: =Controls!$B$7 -> 0.025 | N35: =IF(P35=1,L35*(1-M35),"") -> 1.1375 | O35: =IF(P35=1,N35-Controls!$B$8,"") -> 0.1375 | P35: =IF(AND(ISNUMBER(J35),ISNUMBER(K35),K35>0),1,0) -> 1 | Q35: =IF(P35=0,"UNQUANTIFIED",IF(O35>=0,"CLOSE","NEGATIVE")) -> CLOSE | R35: Pass 182 Energy | S35: 0 | T35: 0
A36: CT-C-A02-W02 | B36: MS-CT | C36: CT-C | D36: A02 | E36: Energy and heat | F36: W02 | G36: Fatal-keystone challenge | H36: firm generation and black start minimum | I36: MW-equivalent | L36: =IF(AND(ISNUMBER(J36),ISNUMBER(K36),K36>0),J36/K36,"") | M36: =Controls!$B$7 -> 0.025 | N36: =IF(P36=1,L36*(1-M36),"") | O36: =IF(P36=1,N36-Controls!$B$8,"") | P36: =IF(AND(ISNUMBER(J36),ISNUMBER(K36),K36>0),1,0) -> 0 | Q36: =IF(P36=0,"UNQUANTIFIED",IF(O36>=0,"CLOSE","NEGATIVE")) -> UNQUANTIFIED | R36: fatal-keystone coefficient and valid full-scale outcome absent | S36: 0 | T36: 0
A37: CT-C-A02-W03 | B37: MS-CT | C37: CT-C | D37: A02 | E37: Energy and heat | F37: W03 | G37: Largest-independent-cell loss | H37: firm generation and black start minimum | I37: MW-equivalent | J37: 42 | K37: 42 | L37: =IF(AND(ISNUMBER(J37),ISNUMBER(K37),K37>0),J37/K37,"") -> 1 | M37: =Controls!$B$7 -> 0.025 | N37: =IF(P37=1,L37*(1-M37),"") -> 0.975 | O37: =IF(P37=1,N37-Controls!$B$8,"") -> -0.025 | P37: =IF(AND(ISNUMBER(J37),ISNUMBER(K37),K37>0),1,0) -> 1 | Q37: =IF(P37=0,"UNQUANTIFIED",IF(O37>=0,"CLOSE","NEGATIVE")) -> NEGATIVE | R37: Pass 182 Energy | S37: 0 | T37: 0
A38: CT-C-A02-W04 | B38: MS-CT | C38: CT-C | D38: A02 | E38: Energy and heat | F38: W04 | G38: Cold reconstruction | H38: firm generation and black start minimum | I38: MW-equivalent | L38: =IF(AND(ISNUMBER(J38),ISNUMBER(K38),K38>0),J38/K38,"") | M38: =Controls!$B$7 -> 0.025 | N38: =IF(P38=1,L38*(1-M38),"") | O38: =IF(P38=1,N38-Controls!$B$8,"") | P38: =IF(AND(ISNUMBER(J38),ISNUMBER(K38),K38>0),1,0) -> 0 | Q38: =IF(P38=0,"UNQUANTIFIED",IF(O38>=0,"CLOSE","NEGATIVE")) -> UNQUANTIFIED | R38: outside-team build record and upper reconstruction time absent | S38: 0 | T38: 0
A39: CT-C-A03-W01 | B39: MS-CT | C39: CT-C | D39: A03 | E39: Geometry and load path | F39: W01 | G39: Nominal mission | H39: minimum governed route ratio | I39: ratio | J39: 1.32 | K39: 1 | L39: =IF(AND(ISNUMBER(J39),ISNUMBER(K39),K39>0),J39/K39,"") -> 1.32 | M39: =Controls!$B$7 -> 0.025 | N39: =IF(P39=1,L39*(1-M39),"") -> 1.287 | O39: =IF(P39=1,N39-Controls!$B$8,"") -> 0.287 | P39: =IF(AND(ISNUMBER(J39),ISNUMBER(K39),K39>0),1,0) -> 1 | Q39: =IF(P39=0,"UNQUANTIFIED",IF(O39>=0,"CLOSE","NEGATIVE")) -> CLOSE | R39: Pass 182 Route Flow | S39: 0 | T39: 0
A40: CT-C-A03-W02 | B40: MS-CT | C40: CT-C | D40: A03 | E40: Geometry and load path | F40: W02 | G40: Fatal-keystone challenge | H40: minimum governed route ratio | I40: ratio | L40: =IF(AND(ISNUMBER(J40),ISNUMBER(K40),K40>0),J40/K40,"") | M40: =Controls!$B$7 -> 0.025 | N40: =IF(P40=1,L40*(1-M40),"") | O40: =IF(P40=1,N40-Controls!$B$8,"") | P40: =IF(AND(ISNUMBER(J40),ISNUMBER(K40),K40>0),1,0) -> 0 | Q40: =IF(P40=0,"UNQUANTIFIED",IF(O40>=0,"CLOSE","NEGATIVE")) -> UNQUANTIFIED | R40: fatal-keystone coefficient and valid full-scale outcome absent | S40: 0 | T40: 0
A41: CT-C-A03-W03 | B41: MS-CT | C41: CT-C | D41: A03 | E41: Geometry and load path | F41: W03 | G41: Largest-independent-cell loss | H41: minimum governed route ratio | I41: ratio | J41: 1.056 | K41: 1 | L41: =IF(AND(ISNUMBER(J41),ISNUMBER(K41),K41>0),J41/K41,"") -> 1.056 | M41: =Controls!$B$7 -> 0.025 | N41: =IF(P41=1,L41*(1-M41),"") -> 1.0296 | O41: =IF(P41=1,N41-Controls!$B$8,"") -> 0.0296 | P41: =IF(AND(ISNUMBER(J41),ISNUMBER(K41),K41>0),1,0) -> 1 | Q41: =IF(P41=0,"UNQUANTIFIED",IF(O41>=0,"CLOSE","NEGATIVE")) -> CLOSE | R41: Pass 182 Route Flow | S41: 0 | T41: 0
A42: CT-C-A03-W04 | B42: MS-CT | C42: CT-C | D42: A03 | E42: Geometry and load path | F42: W04 | G42: Cold reconstruction | H42: minimum governed route ratio | I42: ratio | L42: =IF(AND(ISNUMBER(J42),ISNUMBER(K42),K42>0),J42/K42,"") | M42: =Controls!$B$7 -> 0.025 | N42: =IF(P42=1,L42*(1-M42),"") | O42: =IF(P42=1,N42-Controls!$B$8,"") | P42: =IF(AND(ISNUMBER(J42),ISNUMBER(K42),K42>0),1,0) -> 0 | Q42: =IF(P42=0,"UNQUANTIFIED",IF(O42>=0,"CLOSE","NEGATIVE")) -> UNQUANTIFIED | R42: outside-team build record and upper reconstruction time absent | S42: 0 | T42: 0
A43: CT-C-A04-W01 | B43: MS-CT | C43: CT-C | D43: A04 | E43: Safe state and human boundary | F43: W01 | G43: Nominal mission | H43: minimum refuge and receiver ratio | I43: ratio | J43: 1.2 | K43: 1 | L43: =IF(AND(ISNUMBER(J43),ISNUMBER(K43),K43>0),J43/K43,"") -> 1.2 | M43: =Controls!$B$7 -> 0.025 | N43: =IF(P43=1,L43*(1-M43),"") -> 1.17 | O43: =IF(P43=1,N43-Controls!$B$8,"") -> 0.17 | P43: =IF(AND(ISNUMBER(J43),ISNUMBER(K43),K43>0),1,0) -> 1 | Q43: =IF(P43=0,"UNQUANTIFIED",IF(O43>=0,"CLOSE","NEGATIVE")) -> CLOSE | R43: Pass 182 Safety / Receivers | S43: 0 | T43: 0
...

Sheet Root Triage
A2: Six-root quantitative disposition
A4: No root earns G06. Negative arithmetic orders resize; missing keystone or reconstruction coefficients preserve HOLD rather than becoming zero.
A6: System | B6: Root | C6: Article | D6: Governing issue | E6: Closed numeric cells | F6: Negative cells | G6: Unquantified cells | H6: Worst numeric margin | I6: All 24 close | J6: G06 credit | K6: Disposition
A7: MS-ET | B7: ET-A | C7: Pelagic exchange cell | D7: Geometry / route flow | E7: =COUNTIFS('Closure Cells'!$C$7:$C$150,B7,'Closure Cells'!$Q$7:$Q$150,"CLOSE") -> 9 | F7: =COUNTIFS('Closure Cells'!$C$7:$C$150,B7,'Closure Cells'!$Q$7:$Q$150,"NEGATIVE") -> 1 | G7: =COUNTIFS('Closure Cells'!$C$7:$C$150,B7,'Closure Cells'!$Q$7:$Q$150,"UNQUANTIFIED") -> 14 | H7: =MIN('Closure Cells'!O7:O30) -> -0.0016 | I7: =IF(E7=24,1,0) -> 0 | J7: =I7 -> 0 | K7: =IF(F7>0,"RESIZE / HOLD",IF(G7>0,"HOLD","CLOSE")) -> RESIZE / HOLD
A8: MS-CT | B8: CT-C | C8: Occupied-building utility-spine sector | D8: Energy | E8: =COUNTIFS('Closure Cells'!$C$7:$C$150,B8,'Closure Cells'!$Q$7:$Q$150,"CLOSE") -> 9 | F8: =COUNTIFS('Closure Cells'!$C$7:$C$150,B8,'Closure Cells'!$Q$7:$Q$150,"NEGATIVE") -> 1 | G8: =COUNTIFS('Closure Cells'!$C$7:$C$150,B8,'Closure Cells'!$Q$7:$Q$150,"UNQUANTIFIED") -> 14 | H8: =MIN('Closure Cells'!O31:O54) -> -0.025 | I8: =IF(E8=24,1,0) -> 0 | J8: =I8 -> 0 | K8: =IF(F8>0,"RESIZE / HOLD",IF(G8>0,"HOLD","CLOSE")) -> RESIZE / HOLD
A9: MS-HC | B9: HC-A | C9: Atmospheric intervention cell | D9: Energy and geometry | E9: =COUNTIFS('Closure Cells'!$C$7:$C$150,B9,'Closure Cells'!$Q$7:$Q$150,"CLOSE") -> 8 | F9: =COUNTIFS('Closure Cells'!$C$7:$C$150,B9,'Closure Cells'!$Q$7:$Q$150,"NEGATIVE") -> 2 | G9: =COUNTIFS('Closure Cells'!$C$7:$C$150,B9,'Closure Cells'!$Q$7:$Q$150,"UNQUANTIFIED") -> 14 | H9: =MIN('Closure Cells'!O55:O78) -> -0.0016 | I9: =IF(E9=24,1,0) -> 0 | J9: =I9 -> 0 | K9: =IF(F9>0,"RESIZE / HOLD",IF(G9>0,"HOLD","CLOSE")) -> RESIZE / HOLD
A10: MS-LF | B10: LF-B | C10: Geothermal source position | D10: Internal partitioning | E10: =COUNTIFS('Closure Cells'!$C$7:$C$150,B10,'Closure Cells'!$Q$7:$Q$150,"CLOSE") -> 1 | F10: =COUNTIFS('Closure Cells'!$C$7:$C$150,B10,'Closure Cells'!$Q$7:$Q$150,"NEGATIVE") -> 8 | G10: =COUNTIFS('Closure Cells'!$C$7:$C$150,B10,'Closure Cells'!$Q$7:$Q$150,"UNQUANTIFIED") -> 15 | H10: =MIN('Closure Cells'!O79:O102) -> -1 | I10: =IF(E10=24,1,0) -> 0 | J10: =I10 -> 0 | K10: =IF(F10>0,"RESIZE / HOLD",IF(G10>0,"HOLD","CLOSE")) -> RESIZE / HOLD
A11: MS-HU | B11: HU-A | C11: Complete clinical island | D11: Mass / access envelope | E11: =COUNTIFS('Closure Cells'!$C$7:$C$150,B11,'Closure Cells'!$Q$7:$Q$150,"CLOSE") -> 9 | F11: =COUNTIFS('Closure Cells'!$C$7:$C$150,B11,'Closure Cells'!$Q$7:$Q$150,"NEGATIVE") -> 1 | G11: =COUNTIFS('Closure Cells'!$C$7:$C$150,B11,'Closure Cells'!$Q$7:$Q$150,"UNQUANTIFIED") -> 14 | H11: =MIN('Closure Cells'!O103:O126) -> -0.0172 | I11: =IF(E11=24,1,0) -> 0 | J11: =I11 -> 0 | K11: =IF(F11>0,"RESIZE / HOLD",IF(G11>0,"HOLD","CLOSE")) -> RESIZE / HOLD
A12: MS-RT | B12: RT-B | C12: Disconnected microfactory mesh | D12: Energy | E12: =COUNTIFS('Closure Cells'!$C$7:$C$150,B12,'Closure Cells'!$Q$7:$Q$150,"CLOSE") -> 9 | F12: =COUNTIFS('Closure Cells'!$C$7:$C$150,B12,'Closure Cells'!$Q$7:$Q$150,"NEGATIVE") -> 1 | G12: =COUNTIFS('Closure Cells'!$C$7:$C$150,B12,'Closure Cells'!$Q$7:$Q$150,"UNQUANTIFIED") -> 14 | H12: =MIN('Closure Cells'!O127:O150) -> -0.018709677 | I12: =IF(E12=24,1,0) -> 0 | J12: =I12 -> 0 | K12: =IF(F12>0,"RESIZE / HOLD",IF(G12>0,"HOLD","CLOSE")) -> RESIZE / HOLD

Sheet Resize Orders
A2: Eleven minimum robust-section corrections
A4: The selected values are discrete design hypotheses under a 2.5% adverse screen. They authorize neither form nor construction.
A6: Order | B6: Root | C6: Account / world | D6: Controlled quantity | E6: Current | F6: Minimum robust | G6: Selected planning value | H6: Unit | I6: Selected change | J6: Selected lower-bound ratio | K6: Selected margin | L6: Required physical implication | M6: State
A7: RZ-01 | B7: ET-A | C7: A03 / W03 | D7: surviving complete-flow path | E7: 234.58333 | F7: 240.59829 | G7: 241 | H7: t/h | I7: =G7-E7 -> 6.4166667 | J7: =G7*(1-Controls!$B$7)/E7 -> 1.0016696 | K7: =J7-1 -> 0.001669627 | L7: two separable paths each retain the robust complete-flow floor | M7: PLANNING HYPOTHESIS
A8: RZ-02 | B8: CT-C | C8: A02 / W03 | D8: rating per generation cell | E8: 7 | F8: 7.1794872 | G8: 7.2 | H8: MW | I8: =G8-E8 -> 0.2 | J8: =6*G8*(1-Controls!$B$7)/42 -> 1.0028571 | K8: =J8-1 -> 0.0028571429 | L8: seven cells; six survivors provide 43.2 MW | M8: PLANNING HYPOTHESIS
A9: RZ-03 | B9: HC-A | C9: A03 / W03 | D9: held-line capacity per surviving cell | E9: 26.368 | F9: 26.410256 | G9: 26.5 | H9: km/day | I9: =G9-E9 -> 0.132 | J9: =4*G9*(1-Controls!$B$7)/103 -> 1.0033981 | K9: =J9-1 -> 0.0033980583 | L9: five cells; four survivors provide 106 km/day | M9: PLANNING HYPOTHESIS
A10: RZ-04 | B10: HC-A | C10: A02 / W03 | D10: rating per generation cell | E10: 20.5 | F10: 20.512821 | G10: 20.6 | H10: MW | I10: =G10-E10 -> 0.1 | J10: =7*G10*(1-Controls!$B$7)/140 -> 1.00425 | K10: =J10-1 -> 0.00425 | L10: eight cells; seven survivors provide 144.2 MW | M10: PLANNING HYPOTHESIS
A11: RZ-05 | B11: LF-B | C11: A01 / W01 | D11: one-position access envelope | E11: 31.075 | F11: 31.871795 | G11: 31.9 | H11: kt | I11: =G11-E11 -> 0.825 | J11: =G11*(1-Controls!$B$7)/31.075 -> 1.000885 | K11: =J11-1 -> 0.00088495575 | L11: separate mass allowance from credited hardware | M11: PLANNING HYPOTHESIS
A12: RZ-06 | B12: LF-B | C12: A02 / W03 | D12: four-cell installed source bus | E12: 40 | F12: 51.078006 | G12: 52 | H12: MW | I12: =G12-E12 -> 12 | J12: =3*(G12/4)*(1-Controls!$B$7)/37.3510416667 -> 1.0180439 | K12: =J12-1 -> 0.018043897 | L12: four 13 MW cells; three survivors provide 39 MW | M12: PLANNING HYPOTHESIS
A13: RZ-07 | B13: LF-B | C13: A03 / W01,W03 | D13: two-path surveyed route envelope | E13: 30 | F13: 30.769231 | G13: 31 | H13: pipe-km | I13: =G13-E13 -> 1 | J13: =G13*(1-Controls!$B$7)/30 -> 1.0075 | K13: =J13-1 -> 0.0075 | L13: two 15.5 km usable paths | M13: PLANNING HYPOTHESIS
A14: RZ-08 | B14: LF-B | C14: A04 / W03 | D14: three-cell product-water buffer | E14: 25 | F14: 38.461538 | G14: 39 | H14: thousand m3 | I14: =G14-E14 -> 14 | J14: =(2/3)*G14*(1-Controls!$B$7)/25 -> 1.014 | K14: =J14-1 -> 0.014 | L14: three 13,000 m3 cells; two survive | M14: PLANNING HYPOTHESIS
A15: RZ-09 | B15: LF-B | C15: A05 / W03 | D15: three-cell residual intake | E15: 20 | F15: 30.769231 | G15: 30.9 | H15: thousand m3/day | I15: =G15-E15 -> 10.9 | J15: =(2/3)*G15*(1-Controls!$B$7)/20 -> 1.00425 | K15: =J15-1 -> 0.00425 | L15: three 10,300 m3/day paths; two survive | M15: PLANNING HYPOTHESIS
A16: RZ-10 | B16: HU-A | C16: A01 / W03 | D16: eight-cell access envelope | E16: 57.6 | F16: 58.608059 | G16: 58.8 | H16: kt | I16: =G16-E16 -> 1.2 | J16: =(7/8)*G16*(1-Controls!$B$7)/50 -> 1.003275 | K16: =J16-1 -> 0.003275 | L16: eight 7.35 kt cells; seven survivors retain 50.2 kt lower bound | M16: PLANNING HYPOTHESIS
A17: RZ-11 | B17: RT-B | C17: A02 / W03 | D17: seven-cell installed process bus | E17: 182 | F17: 185.47009 | G17: 185.5 | H17: MW | I17: =G17-E17 -> 3.5 | J17: =(6/7)*G17*(1-Controls!$B$7)/155 -> 1.0001613 | K17: =J17-1 -> 0.00016129032 | L17: seven 26.5 MW cells; six survivors retain 155 MW lower bound | M17: PLANNING HYPOTHESIS

Sheet Keystone Gaps
A2: Thirty-six fatal-keystone coefficient gaps
A4: A fatal challenge is not a modeled derating. It can kill a root after valid evidence, so every coefficient remains source empty today.
A6: Gap | B6: System | C6: Root | D6: Account | E6: Closure account | F6: Causal claim | G6: Required quantitative object | H6: Observation | I6: Accepted | J6: State
A7: KX-ET-A-A01 | B7: MS-ET | C7: ET-A | D7: A01 | E7: Mass and material custody | F7: motion compensation, wet-to-dry transition and custody remain causally attributable | G7: valid full-scale causal coefficient and safe terminal state | H7: SOURCE EMPTY | I7: 0 | J7: HOLD
A8: KX-ET-A-A02 | B8: MS-ET | C8: ET-A | D8: A02 | E8: Energy and heat | F8: motion compensation, wet-to-dry transition and custody remain causally attributable | G8: valid full-scale causal coefficient and safe terminal state | H8: SOURCE EMPTY | I8: 0 | J8: HOLD
A9: KX-ET-A-A03 | B9: MS-ET | C9: ET-A | D9: A03 | E9: Geometry and load path | F9: motion compensation, wet-to-dry transition and custody remain causally attributable | G9: valid full-scale causal coefficient and safe terminal state | H9: SOURCE EMPTY | I9: 0 | J9: HOLD
A10: KX-ET-A-A04 | B10: MS-ET | C10: ET-A | D10: A04 | E10: Safe state and human boundary | F10: motion compensation, wet-to-dry transition and custody remain causally attributable | G10: valid full-scale causal coefficient and safe terminal state | H10: SOURCE EMPTY | I10: 0 | J10: HOLD
A11: KX-ET-A-A05 | B11: MS-ET | C11: ET-A | D11: A05 | E11: Residual and environmental custody | F11: motion compensation, wet-to-dry transition and custody remain causally attributable | G11: valid full-scale causal coefficient and safe terminal state | H11: SOURCE EMPTY | I11: 0 | J11: HOLD
A12: KX-ET-A-A06 | B12: MS-ET | C12: ET-A | D12: A06 | E12: Removal and cold reconstruction | F12: motion compensation, wet-to-dry transition and custody remain causally attributable | G12: valid full-scale causal coefficient and safe terminal state | H12: SOURCE EMPTY | I12: 0 | J12: HOLD
A13: KX-CT-C-A01 | B13: MS-CT | C13: CT-C | D13: A01 | E13: Mass and material custody | F13: reversible attachment and utility isolation prevent structural, smoke or contamination propagation | G13: valid full-scale causal coefficient and safe terminal state | H13: SOURCE EMPTY | I13: 0 | J13: HOLD
A14: KX-CT-C-A02 | B14: MS-CT | C14: CT-C | D14: A02 | E14: Energy and heat | F14: reversible attachment and utility isolation prevent structural, smoke or contamination propagation | G14: valid full-scale causal coefficient and safe terminal state | H14: SOURCE EMPTY | I14: 0 | J14: HOLD
A15: KX-CT-C-A03 | B15: MS-CT | C15: CT-C | D15: A03 | E15: Geometry and load path | F15: reversible attachment and utility isolation prevent structural, smoke or contamination propagation | G15: valid full-scale causal coefficient and safe terminal state | H15: SOURCE EMPTY | I15: 0 | J15: HOLD
A16: KX-CT-C-A04 | B16: MS-CT | C16: CT-C | D16: A04 | E16: Safe state and human boundary | F16: reversible attachment and utility isolation prevent structural, smoke or contamination propagation | G16: valid full-scale causal coefficient and safe terminal state | H16: SOURCE EMPTY | I16: 0 | J16: HOLD
A17: KX-CT-C-A05 | B17: MS-CT | C17: CT-C | D17: A05 | E17: Residual and environmental custody | F17: reversible attachment and utility isolation prevent structural, smoke or contamination propagation | G17: valid full-scale causal coefficient and safe terminal state | H17: SOURCE EMPTY | I17: 0 | J17: HOLD
A18: KX-CT-C-A06 | B18: MS-CT | C18: CT-C | D18: A06 | E18: Removal and cold reconstruction | F18: reversible attachment and utility isolation prevent structural, smoke or contamination propagation | G18: valid full-scale causal coefficient and safe terminal state | H18: SOURCE EMPTY | I18: 0 | J18: HOLD
... A42: KX-RT-B-A06 | B42: MS-RT | C42: RT-B | D42: A06 | E42: Removal and cold reconstruction | F42: material state, calibration, ancestry and independent release survive disconnection | G42: valid full-scale causal coefficient and safe terminal state | H42: SOURCE EMPTY | I42: 0 | J42: HOLD

Sheet Reconstruction Gaps
A2: Thirty-six outside-team reconstruction gaps
A4: Paper replaceability is not reconstruction. Every account requires a timed outside-team replay from frozen records without the originating runtime.
A6: Gap | B6: System | C6: Root | D6: Account | E6: Closure account | F6: Reconstruction claim | G6: Required quantitative object | H6: Observation | I6: Accepted | J6: State
A7: RC-ET-A-A01 | B7: MS-ET | C7: ET-A | D7: A01 | E7: Mass and material custody | F7: rebuild dynamic connector, transition and custody chain from frozen records | G7: outside-team upper completion time, toolchain and accepted ancestry | H7: SOURCE EMPTY | I7: 0 | J7: HOLD
A8: RC-ET-A-A02 | B8: MS-ET | C8: ET-A | D8: A02 | E8: Energy and heat | F8: rebuild dynamic connector, transition and custody chain from frozen records | G8: outside-team upper completion time, toolchain and accepted ancestry | H8: SOURCE EMPTY | I8: 0 | J8: HOLD
A9: RC-ET-A-A03 | B9: MS-ET | C9: ET-A | D9: A03 | E9: Geometry and load path | F9: rebuild dynamic connector, transition and custody chain from frozen records | G9: outside-team upper completion time, toolchain and accepted ancestry | H9: SOURCE EMPTY | I9: 0 | J9: HOLD
A10: RC-ET-A-A04 | B10: MS-ET | C10: ET-A | D10: A04 | E10: Safe state and human boundary | F10: rebuild dynamic connector, transition and custody chain from frozen records | G10: outside-team upper completion time, toolchain and accepted ancestry | H10: SOURCE EMPTY | I10: 0 | J10: HOLD
A11: RC-ET-A-A05 | B11: MS-ET | C11: ET-A | D11: A05 | E11: Residual and environmental custody | F11: rebuild dynamic connector, transition and custody chain from frozen records | G11: outside-team upper completion time, toolchain and accepted ancestry | H11: SOURCE EMPTY | I11: 0 | J11: HOLD
A12: RC-ET-A-A06 | B12: MS-ET | C12: ET-A | D12: A06 | E12: Removal and cold reconstruction | F12: rebuild dynamic connector, transition and custody chain from frozen records | G12: outside-team upper completion time, toolchain and accepted ancestry | H12: SOURCE EMPTY | I12: 0 | J12: HOLD
A13: RC-CT-C-A01 | B13: MS-CT | C13: CT-C | D13: A01 | E13: Mass and material custody | F13: remove and rebuild attachment plus five isolated trunks in an occupied receiver | G13: outside-team upper completion time, toolchain and accepted ancestry | H13: SOURCE EMPTY | I13: 0 | J13: HOLD
A14: RC-CT-C-A02 | B14: MS-CT | C14: CT-C | D14: A02 | E14: Energy and heat | F14: remove and rebuild attachment plus five isolated trunks in an occupied receiver | G14: outside-team upper completion time, toolchain and accepted ancestry | H14: SOURCE EMPTY | I14: 0 | J14: HOLD
A15: RC-CT-C-A03 | B15: MS-CT | C15: CT-C | D15: A03 | E15: Geometry and load path | F15: remove and rebuild attachment plus five isolated trunks in an occupied receiver | G15: outside-team upper completion time, toolchain and accepted ancestry | H15: SOURCE EMPTY | I15: 0 | J15: HOLD
A16: RC-CT-C-A04 | B16: MS-CT | C16: CT-C | D16: A04 | E16: Safe state and human boundary | F16: remove and rebuild attachment plus five isolated trunks in an occupied receiver | G16: outside-team upper completion time, toolchain and accepted ancestry | H16: SOURCE EMPTY | I16: 0 | J16: HOLD
A17: RC-CT-C-A05 | B17: MS-CT | C17: CT-C | D17: A05 | E17: Residual and environmental custody | F17: remove and rebuild attachment plus five isolated trunks in an occupied receiver | G17: outside-team upper completion time, toolchain and accepted ancestry | H17: SOURCE EMPTY | I17: 0 | J17: HOLD
A18: RC-CT-C-A06 | B18: MS-CT | C18: CT-C | D18: A06 | E18: Removal and cold reconstruction | F18: remove and rebuild attachment plus five isolated trunks in an occupied receiver | G18: outside-team upper completion time, toolchain and accepted ancestry | H18: SOURCE EMPTY | I18: 0 | J18: HOLD
... A42: RC-RT-B-A06 | B42: MS-RT | C42: RT-B | D42: A06 | E42: Removal and cold reconstruction | F42: recreate dirty-return-to-signed-release process mesh and calibration ancestry | G42: outside-team upper completion time, toolchain and accepted ancestry | H42: SOURCE EMPTY | I42: 0 | J42: HOLD

Sheet Sensitivity
A2: Governing loss margin under adverse movement
A4: This screen varies only the inherited coefficient. It does not fill keystone or reconstruction gaps.
A6: Scenario | B6: Adverse movement | C6: Root | D6: Current minimum W03 ratio | E6: Lower-bound ratio | F6: Margin | G6: Decision
A7: No adverse screen | B7: 0 | C7: ET-A | D7: 1.024 | E7: =D7*(1-B7) -> 1.024 | F7: =E7-Controls!$B$8 -> 0.024 | G7: =IF(F7>=0,"CLOSE","NEGATIVE") -> CLOSE
A8: No adverse screen | B8: 0 | C8: CT-C | D8: 1 | E8: =D8*(1-B8) -> 1 | F8: =E8-Controls!$B$8 -> 0 | G8: =IF(F8>=0,"CLOSE","NEGATIVE") -> CLOSE
A9: No adverse screen | B9: 0 | C9: HC-A | D9: 1.024 | E9: =D9*(1-B9) -> 1.024 | F9: =E9-Controls!$B$8 -> 0.024 | G9: =IF(F9>=0,"CLOSE","NEGATIVE") -> CLOSE
A10: No adverse screen | B10: 0 | C10: LF-B | D10: 0 | E10: =D10*(1-B10) -> 0 | F10: =E10-Controls!$B$8 -> -1 | G10: =IF(F10>=0,"CLOSE","NEGATIVE") -> NEGATIVE
A11: No adverse screen | B11: 0 | C11: HU-A | D11: 1.008 | E11: =D11*(1-B11) -> 1.008 | F11: =E11-Controls!$B$8 -> 0.008 | G11: =IF(F11>=0,"CLOSE","NEGATIVE") -> CLOSE
A12: No adverse screen | B12: 0 | C12: RT-B | D12: 1.0064516 | E12: =D12*(1-B12) -> 1.0064516 | F12: =E12-Controls!$B$8 -> 0.0064516129 | G12: =IF(F12>=0,"CLOSE","NEGATIVE") -> CLOSE
A13: 1% adverse | B13: 0.01 | C13: ET-A | D13: 1.024 | E13: =D13*(1-B13) -> 1.01376 | F13: =E13-Controls!$B$8 -> 0.01376 | G13: =IF(F13>=0,"CLOSE","NEGATIVE") -> CLOSE
A14: 1% adverse | B14: 0.01 | C14: CT-C | D14: 1 | E14: =D14*(1-B14) -> 0.99 | F14: =E14-Controls!$B$8 -> -0.01 | G14: =IF(F14>=0,"CLOSE","NEGATIVE") -> NEGATIVE
A15: 1% adverse | B15: 0.01 | C15: HC-A | D15: 1.024 | E15: =D15*(1-B15) -> 1.01376 | F15: =E15-Controls!$B$8 -> 0.01376 | G15: =IF(F15>=0,"CLOSE","NEGATIVE") -> CLOSE
A16: 1% adverse | B16: 0.01 | C16: LF-B | D16: 0 | E16: =D16*(1-B16) -> 0 | F16: =E16-Controls!$B$8 -> -1 | G16: =IF(F16>=0,"CLOSE","NEGATIVE") -> NEGATIVE
A17: 1% adverse | B17: 0.01 | C17: HU-A | D17: 1.008 | E17: =D17*(1-B17) -> 0.99792 | F17: =E17-Controls!$B$8 -> -0.00208 | G17: =IF(F17>=0,"CLOSE","NEGATIVE") -> NEGATIVE
A18: 1% adverse | B18: 0.01 | C18: RT-B | D18: 1.0064516 | E18: =D18*(1-B18) -> 0.9963871 | F18: =E18-Controls!$B$8 -> -0.0036129032 | G18: =IF(F18>=0,"CLOSE","NEGATIVE") -> NEGATIVE
... A36: 10% adverse | B36: 0.1 | C36: RT-B | D36: 1.0064516 | E36: =D36*(1-B36) -> 0.90580645 | F36: =E36-Controls!$B$8 -> -0.094193548 | G36: =IF(F36>=0,"CLOSE","NEGATIVE") -> NEGATIVE

Sheet Finance
A2: Authority remains held after quantitative triage
A4: Negative and unquantified cells release no money. The inherited USD 0.538B FRAME ceiling is conserved, not spent.
A6: System | B6: Root | C6: Article | D6: Option ceiling USD B | E6: FRAME share | F6: Maximum FRAME USD B | G6: Accepted USD B | H6: Paid USD B | I6: State
A7: MS-ET | B7: ET-A | C7: Pelagic exchange cell | D7: 0.50047462 | E7: =Controls!$B$14 -> 0.15 | F7: =D7*E7 -> 0.075071193 | G7: 0 | H7: 0 | I7: HELD
A8: MS-CT | B8: CT-C | C8: Occupied-building utility-spine sector | D8: 0.51649348 | E8: =Controls!$B$14 -> 0.15 | F8: =D8*E8 -> 0.077474022 | G8: 0 | H8: 0 | I8: HELD
A9: MS-HC | B9: HC-A | C9: Atmospheric intervention cell | D9: 0.30722165 | E9: =Controls!$B$14 -> 0.15 | F9: =D9*E9 -> 0.046083248 | G9: 0 | H9: 0 | I9: HELD
A10: MS-LF | B10: LF-B | C10: Geothermal source position | D10: 0.89941282 | E10: =Controls!$B$14 -> 0.15 | F10: =D10*E10 -> 0.13491192 | G10: 0 | H10: 0 | I10: HELD
A11: MS-HU | B11: HU-A | C11: Complete clinical island | D11: 0.86071245 | E11: =Controls!$B$14 -> 0.15 | F11: =D11*E11 -> 0.12910687 | G11: 0 | H11: 0 | I11: HELD
A12: MS-RT | B12: RT-B | C12: Disconnected microfactory mesh | D12: 0.50259779 | E12: =Controls!$B$14 -> 0.15 | F12: =D12*E12 -> 0.075389669 | G12: 0 | H12: 0 | I12: HELD
A13: TOTAL | B13: six roots | C13: candidate section work | D13: =SUM(D7:D12) -> 3.5869128 | F13: =SUM(F7:F12) -> 0.53803692 | G13: =SUM(G7:G12) -> 0 | H13: =SUM(H7:H12) -> 0 | I13: HELD

Sheet Release Gates
A2: Seventy-two requirement-to-architecture gates
A4: G06 remains open for every root. Triage is a decision result, not quantitative closure of a candidate section.
A6: Gate | B6: System | C6: Root | D6: Order | E6: Gate claim | F6: State | G6: Authority basis | H6: Requirement closed | I6: Evidence accepted | J6: Pass 218 effect | K6: Exterior authority
A7: ET-A-G01 | B7: MS-ET | C7: ET-A | D7: 1 | E7: denominator | F7: CONSTITUTED | G7: Pass 216 requirement record | H7: 1 | I7: 0 | J7: NO CHANGE | K7: n.a.
A8: ET-A-G02 | B8: MS-ET | C8: ET-A | D8: 2 | E8: article boundary | F8: CONSTITUTED | G8: Pass 216 requirement record | H8: 1 | I8: 0 | J8: NO CHANGE | K8: n.a.
A9: ET-A-G03 | B9: MS-ET | C9: ET-A | D9: 3 | E9: form loads | F9: CONSTITUTED | G9: Pass 216 requirement record | H9: 1 | I9: 0 | J9: NO CHANGE | K9: n.a.
A10: ET-A-G04 | B10: MS-ET | C10: ET-A | D10: 4 | E10: interfaces | F10: CONSTITUTED | G10: Pass 216 requirement record | H10: 1 | I10: 0 | J10: NO CHANGE | K10: n.a.
A11: ET-A-G05 | B11: MS-ET | C11: ET-A | D11: 5 | E11: denial set | F11: CONSTITUTED | G11: Pass 216 requirement record | H11: 1 | I11: 0 | J11: NO CHANGE | K11: n.a.
A12: ET-A-G06 | B12: MS-ET | C12: ET-A | D12: 6 | E12: paper closure | F12: OPEN | G12: Pass 218 triage finds negative or unquantified cells | H12: 0 | I12: 0 | J12: TRIAGED / NOT CLOSED | K12: n.a.
A13: ET-A-G07 | B13: MS-ET | C13: ET-A | D13: 7 | E13: safety and rights | F13: OPEN | G13: future accepted record | H13: 0 | I13: 0 | J13: NO CHANGE | K13: n.a.
A14: ET-A-G08 | B14: MS-ET | C14: ET-A | D14: 8 | E14: ancestry | F14: OPEN | G14: future accepted record | H14: 0 | I14: 0 | J14: NO CHANGE | K14: n.a.
A15: ET-A-G09 | B15: MS-ET | C15: ET-A | D15: 9 | E15: executable build record | F15: OPEN | G15: future accepted record | H15: 0 | I15: 0 | J15: NO CHANGE | K15: n.a.
A16: ET-A-G10 | B16: MS-ET | C16: ET-A | D16: 10 | E16: representative event | F16: OPEN | G16: future accepted record | H16: 0 | I16: 0 | J16: NO CHANGE | K16: n.a.
A17: ET-A-G11 | B17: MS-ET | C17: ET-A | D17: 11 | E17: cold reconstruction | F17: OPEN | G17: future accepted record | H17: 0 | I17: 0 | J17: NO CHANGE | K17: n.a.
A18: ET-A-G12 | B18: MS-ET | C18: ET-A | D18: 12 | E18: architecture warrant | F18: OPEN | G18: future accepted record | H18: 0 | I18: 0 | J18: NO CHANGE | K18: HELD
... A78: RT-B-G12 | B78: MS-RT | C78: RT-B | D78: 12 | E78: architecture warrant | F78: OPEN | G78: future accepted record | H78: 0 | I78: 0 | J78: NO CHANGE | K78: HELD

Sheet Mutations
A2: Restored control-mutation register
A4: The verification run applies each edit to a disposable workbook, recalculates, confirms the named boundary changes, and restores the baseline.
A6: Mutation | B6: Counterfactual edit | C6: Expected propagation | D6: Observed boundary | E6: Result
A7: M01 | B7: adverse screen set to zero | C7: negative-cell count changes | D7: Audit negative-cell count | E7: DETECTED
A8: M02 | B8: ET-A W03 flow raised to robust minimum | C8: ET-A negative count changes | D8: Root Triage | E8: DETECTED
A9: M03 | B9: CT-C W03 energy capacity reduced | C9: worst margin decreases | D9: Root Triage | E9: DETECTED
