Workbook

Sheet Summary
A2: Six-root dimension envelope and interface atlas
A4: Decision measure | B4: Value | C4: State | M4: Form | N4: Primary range ratio | O4: Cell-volume range ratio
A5: root-native frames | B5: =COUNTA('Coordinate Frames'!A5:A10) -> 6 | C5: COMPLETE | E5: Decision All eighteen corrected forms receive interval-bounded system and largest-cell envelopes plus six decisive-interface coordinate boxes. Six root-native frames make the coordinates noninterchangeable. Every form carries its inherited section bill, but all observations and technology campaigns remain open. The atlas prevents a common chassis and prevents apparent plate dimensions from becoming metrology. | M5: ET-A-A | N5: ='Envelope Register'!K5/'Envelope Register'!J5 -> 1.3125 | O5: =('Envelope Register'!S5*'Envelope Register'!U5*'Envelope Register'!W5)/('Envelope Register'!R5*'Envelope Register'!T5*'Envelope Register'!V5) -> 3.1015385
A6: dimension envelopes | B6: =COUNTA('Envelope Register'!A5:A22) -> 18 | C6: COMPLETE | M6: ET-A-B | N6: ='Envelope Register'!K6/'Envelope Register'!J6 -> 1.3846154 | O6: =('Envelope Register'!S6*'Envelope Register'!U6*'Envelope Register'!W6)/('Envelope Register'!R6*'Envelope Register'!T6*'Envelope Register'!V6) -> 4.2666667
A7: valid envelopes | B7: =COUNTIF('Envelope Register'!AE5:AE22,"DIMENSIONED / UNSELECTED") -> 18 | C7: PASS | M7: ET-A-C | N7: ='Envelope Register'!K7/'Envelope Register'!J7 -> 1.3684211 | O7: =('Envelope Register'!S7*'Envelope Register'!U7*'Envelope Register'!W7)/('Envelope Register'!R7*'Envelope Register'!T7*'Envelope Register'!V7) -> 4.345679
A8: decisive-interface zones | B8: =COUNTA('Interface Zones'!A5:A112) -> 108 | C8: COMPLETE | M8: CT-C-A | N8: ='Envelope Register'!K8/'Envelope Register'!J8 -> 2 | O8: =('Envelope Register'!S8*'Envelope Register'!U8*'Envelope Register'!W8)/('Envelope Register'!R8*'Envelope Register'!T8*'Envelope Register'!V8) -> 5.5555556
A9: zones within bounds | B9: =COUNTIF('Interface Zones'!S5:S112,"PASS") -> 108 | C9: PASS | M9: CT-C-B | N9: ='Envelope Register'!K9/'Envelope Register'!J9 -> 2.5 | O9: =('Envelope Register'!S9*'Envelope Register'!U9*'Envelope Register'!W9)/('Envelope Register'!R9*'Envelope Register'!T9*'Envelope Register'!V9) -> 8.3333333
A10: section carryover decisions | B10: =COUNTA('Section Carryover'!A5:A112) -> 108 | C10: COMPLETE | M10: CT-C-C | N10: ='Envelope Register'!K10/'Envelope Register'!J10 -> 2.5 | O10: =('Envelope Register'!S10*'Envelope Register'!U10*'Envelope Register'!W10)/('Envelope Register'!R10*'Envelope Register'!T10*'Envelope Register'!V10) -> 8.3314286
A11: design-close carryovers | B11: =COUNTIF('Section Carryover'!K5:K112,"DESIGN-CLOSE / TEST OPEN") -> 108 | C11: DESIGN ONLY | M11: HC-A-A | N11: ='Envelope Register'!K11/'Envelope Register'!J11 -> 5 | O11: =('Envelope Register'!S11*'Envelope Register'!U11*'Envelope Register'!W11)/('Envelope Register'!R11*'Envelope Register'!T11*'Envelope Register'!V11) -> 4.0228571
A12: technology campaigns | B12: =COUNTA('Technology Demands'!A5:A58) -> 54 | C12: OPEN / UNPROVEN | M12: HC-A-B | N12: ='Envelope Register'!K12/'Envelope Register'!J12 -> 5 | O12: =('Envelope Register'!S12*'Envelope Register'!U12*'Envelope Register'!W12)/('Envelope Register'!R12*'Envelope Register'!T12*'Envelope Register'!V12) -> 7.2
A13: common chassis entries | B13: =COUNTA('Envelope Register'!Z5:Z22) -> 0 | C13: ZERO | M13: HC-A-C | N13: ='Envelope Register'!K13/'Envelope Register'!J13 -> 3 | O13: =('Envelope Register'!S13*'Envelope Register'!U13*'Envelope Register'!W13)/('Envelope Register'!R13*'Envelope Register'!T13*'Envelope Register'!V13) -> 10.5
A14: selected forms | B14: =SUM('Envelope Register'!AA5:AA22) -> 0 | C14: ZERO | M14: LF-B-A | N14: ='Envelope Register'!K14/'Envelope Register'!J14 -> 3 | O14: =('Envelope Register'!S14*'Envelope Register'!U14*'Envelope Register'!W14)/('Envelope Register'!R14*'Envelope Register'!T14*'Envelope Register'!V14) -> 9.765625
A15: accepted observations | B15: =SUM('Envelope Register'!AB5:AB22) -> 0 | C15: ZERO | M15: LF-B-B | N15: ='Envelope Register'!K15/'Envelope Register'!J15 -> 4 | O15: =('Envelope Register'!S15*'Envelope Register'!U15*'Envelope Register'!W15)/('Envelope Register'!R15*'Envelope Register'!T15*'Envelope Register'!V15) -> 14
A16: incremental ceiling USD B | B16: =Finance!G11 -> 0 | C16: ZERO | M16: LF-B-C | N16: ='Envelope Register'!K16/'Envelope Register'!J16 -> 3 | O16: =('Envelope Register'!S16*'Envelope Register'!U16*'Envelope Register'!W16)/('Envelope Register'!R16*'Envelope Register'!T16*'Envelope Register'!V16) -> 6.0267857
M17: HU-A-A | N17: ='Envelope Register'!K17/'Envelope Register'!J17 -> 2 | O17: =('Envelope Register'!S17*'Envelope Register'!U17*'Envelope Register'!W17)/('Envelope Register'!R17*'Envelope Register'!T17*'Envelope Register'!V17) -> 10
M18: HU-A-B | N18: ='Envelope Register'!K18/'Envelope Register'!J18 -> 2.2857143 | O18: =('Envelope Register'!S18*'Envelope Register'!U18*'Envelope Register'!W18)/('Envelope Register'!R18*'Envelope Register'!T18*'Envelope Register'!V18) -> 8
M19: HU-A-C | N19: ='Envelope Register'!K19/'Envelope Register'!J19 -> 1.6666667 | O19: =('Envelope Register'!S19*'Envelope Register'!U19*'Envelope Register'!W19)/('Envelope Register'!R19*'Envelope Register'!T19*'Envelope Register'!V19) -> 5.5555556
M20: RT-B-A | N20: ='Envelope Register'!K20/'Envelope Register'!J20 -> 3.3333333 | O20: =('Envelope Register'!S20*'Envelope Register'!U20*'Envelope Register'!W20)/('Envelope Register'!R20*'Envelope Register'!T20*'Envelope Register'!V20) -> 8
M21: RT-B-B | N21: ='Envelope Register'!K21/'Envelope Register'!J21 -> 2.4 | O21: =('Envelope Register'!S21*'Envelope Register'!U21*'Envelope Register'!W21)/('Envelope Register'!R21*'Envelope Register'!T21*'Envelope Register'!V21) -> 10
M22: RT-B-C | N22: ='Envelope Register'!K22/'Envelope Register'!J22 -> 4 | O22: =('Envelope Register'!S22*'Envelope Register'!U22*'Envelope Register'!W22)/('Envelope Register'!R22*'Envelope Register'!T22*'Envelope Register'!V22) -> 12

Sheet Controls
A2: Root-native dimension authority controls
A5: Control | B5: Value | C5: Unit | D5: Authority
A6: roots | B6: 6 | C6: count | D6: Pass 211
A7: hypotheses | B7: 18 | C7: count | D7: Pass 223
A8: interfaces per form | B8: 6 | C8: count | D8: Pass 224
A9: coordinate half-zone x | B9: 0.035 | C9: share of minimum primary extent | D9: Pass 224 hypothesis
A10: coordinate half-zone y | B10: 0.055 | C10: share of minimum cross extent | D10: Pass 224 hypothesis
A11: default height half-zone | B11: 0.045 | C11: share of minimum vertical extent | D11: Pass 224 hypothesis; RT-B uses 0.070
A12: depth half-zone | B12: 0.1 | C12: share of minimum depth | D12: Pass 224 hypothesis
A13: FRAME share | B13: 0.15 | C13: share | D13: Pass 215
A14: selected forms | B14: 0 | C14: count | D14: held
A15: accepted observations | B15: 0 | C15: count | D15: source empty
A16: branch kills | B16: 0 | C16: count | D16: Pass 224 decision
A17: incremental dimensioning ceiling | B17: 0 | C17: USD B | D17: no new authority

Sheet Envelope Register
A2: Eighteen root-native minimum dimension envelopes
A4: Hypothesis | B4: Root | C4: Variant | D4: Corrected form | E4: Topology token | F4: Bounded object | G4: Isolation basis | H4: Independent assemblies | I4: Required minimum | J4: Primary min m | K4: Primary max m | L4: Cross min m | M4: Cross max m | N4: Vertical min m | O4: Vertical max m | P4: Depth min m | Q4: Depth max m | R4: Cell length min m | S4: Cell length max m | T4: Cell width min m | U4: Cell width max m | V4: Cell height min m | W4: Cell height max m | X4: Reach min m | Y4: Reach max m | Z4: Common chassis ID | AA4: Selected | AB4: Accepted evidence | AC4: Topology occurrences | AD4: Range state | AE4: Authority state | AF4: Hypothesis occurrences
A5: ET-A-A | B5: ET-A | C5: A | D5: Distributed twin-body exchange | E5: twin-body / path-separated | F5: two-body exchange cluster | G5: two complete end-to-end paths | H5: 2 | I5: 2 | J5: 160 | K5: 210 | L5: 90 | M5: 130 | N5: 26 | O5: 36 | P5: 8 | Q5: 12 | R5: 130 | S5: 180 | T5: 25 | U5: 40 | V5: 25 | W5: 35 | X5: 1000 | Y5: 3000 | AA5: 0 | AB5: 0 | AC5: =COUNTIF($E$5:$E$22,E5) -> 1 | AD5: =IF(AND(H5>=I5,J5>0,K5>=J5,L5>0,M5>=L5,N5>0,O5>=N5,P5>=0,Q5>=P5,R5>0,S5>=R5,T5>0,U5>=T5,V5>0,W5>=V5,X5>0,Y5>=X5),"PASS","FAIL") -> PASS | AE5: =IF(AND(AC5=1,AF5=1,AD5="PASS",Z5="",AA5=0,AB5=0),"DIMENSIONED / UNSELECTED","FAIL") -> DIMENSIONED / UNSELECTED | AF5: =COUNTIF($A$5:$A$22,A5) -> 1
A6: ET-A-B | B6: ET-A | C6: B | D6: Dual-chain articulated offshore spine | E6: dual-chain / articulated | F6: two-chain articulated cluster | G6: two separately safeable chains | H6: 2 | I6: 2 | J6: 260 | K6: 360 | L6: 45 | M6: 70 | N6: 22 | O6: 32 | P6: 6 | Q6: 10 | R6: 35 | S6: 60 | T6: 25 | U6: 40 | V6: 18 | W6: 28 | X6: 1500 | Y6: 5000 | AA6: 0 | AB6: 0 | AC6: =COUNTIF($E$5:$E$22,E6) -> 1 | AD6: =IF(AND(H6>=I6,J6>0,K6>=J6,L6>0,M6>=L6,N6>0,O6>=N6,P6>=0,Q6>=P6,R6>0,S6>=R6,T6>0,U6>=T6,V6>0,W6>=V6,X6>0,Y6>=X6),"PASS","FAIL") -> PASS | AE6: =IF(AND(AC6=1,AF6=1,AD6="PASS",Z6="",AA6=0,AB6=0),"DIMENSIONED / UNSELECTED","FAIL") -> DIMENSIONED / UNSELECTED | AF6: =COUNTIF($A$5:$A$22,A6) -> 1
A7: ET-A-C | B7: ET-A | C7: C | D7: Split-frame semi-submersible exchange lattice | E7: split-frame / semi-submersible | F7: two-frame lattice cluster | G7: two independent wet-to-dry frames | H7: 2 | I7: 2 | J7: 190 | K7: 260 | L7: 100 | M7: 150 | N7: 20 | O7: 30 | P7: 12 | Q7: 18 | R7: 45 | S7: 80 | T7: 35 | U7: 55 | V7: 18 | W7: 28 | X7: 1000 | Y7: 3000 | AA7: 0 | AB7: 0 | AC7: =COUNTIF($E$5:$E$22,E7) -> 1 | AD7: =IF(AND(H7>=I7,J7>0,K7>=J7,L7>0,M7>=L7,N7>0,O7>=N7,P7>=0,Q7>=P7,R7>0,S7>=R7,T7>0,U7>=T7,V7>0,W7>=V7,X7>0,Y7>=X7),"PASS","FAIL") -> PASS | AE7: =IF(AND(AC7=1,AF7=1,AD7="PASS",Z7="",AA7=0,AB7=0),"DIMENSIONED / UNSELECTED","FAIL") -> DIMENSIONED / UNSELECTED | AF7: =COUNTIF($A$5:$A$22,A7) -> 1
A8: CT-C-A | B8: CT-C | C8: A | D8: Segmented telescoping utility spine | E8: segmented / telescoping | F8: five-trunk deployed sector | G8: five separately founded trunk groups | H8: 5 | I8: 5 | J8: 450 | K8: 900 | L8: 18 | M8: 30 | N8: 30 | O8: 55 | P8: 0 | Q8: 0 | R8: 60 | S8: 120 | T8: 12 | U8: 20 | V8: 12 | W8: 20 | X8: 1000 | Y8: 3000 | AA8: 0 | AB8: 0 | AC8: =COUNTIF($E$5:$E$22,E8) -> 1 | AD8: =IF(AND(H8>=I8,J8>0,K8>=J8,L8>0,M8>=L8,N8>0,O8>=N8,P8>=0,Q8>=P8,R8>0,S8>=R8,T8>0,U8>=T8,V8>0,W8>=V8,X8>0,Y8>=X8),"PASS","FAIL") -> PASS | AE8: =IF(AND(AC8=1,AF8=1,AD8="PASS",Z8="",AA8=0,AB8=0),"DIMENSIONED / UNSELECTED","FAIL") -> DIMENSIONED / UNSELECTED | AF8: =COUNTIF($A$5:$A$22,A8) -> 1
A9: CT-C-B | B9: CT-C | C9: B | D9: Sectional suspended utility belt | E9: sectional / suspended | F9: five-trunk façade sector | G9: five independent anchor zones | H9: 5 | I9: 5 | J9: 800 | K9: 2000 | L9: 12 | M9: 22 | N9: 45 | O9: 120 | P9: 0 | Q9: 0 | R9: 100 | S9: 250 | T9: 6 | U9: 10 | V9: 6 | W9: 12 | X9: 2000 | Y9: 6000 | AA9: 0 | AB9: 0 | AC9: =COUNTIF($E$5:$E$22,E9) -> 1 | AD9: =IF(AND(H9>=I9,J9>0,K9>=J9,L9>0,M9>=L9,N9>0,O9>=N9,P9>=0,Q9>=P9,R9>0,S9>=R9,T9>0,U9>=T9,V9>0,W9>=V9,X9>0,Y9>=X9),"PASS","FAIL") -> PASS | AE9: =IF(AND(AC9=1,AF9=1,AD9="PASS",Z9="",AA9=0,AB9=0),"DIMENSIONED / UNSELECTED","FAIL") -> DIMENSIONED / UNSELECTED | AF9: =COUNTIF($A$5:$A$22,A9) -> 1
A10: CT-C-C | B10: CT-C | C10: C | D10: Mast-and-bridge insertion grid | E10: mast-grid / bridged | F10: five-trunk occupied-boundary grid | G10: five separate bridge drops | H10: 5 | I10: 5 | J10: 600 | K10: 1500 | L10: 600 | M10: 1500 | N10: 35 | O10: 90 | P10: 0 | Q10: 0 | R10: 10 | S10: 18 | T10: 10 | U10: 18 | V10: 35 | W10: 90 | X10: 3000 | Y10: 10000 | AA10: 0 | AB10: 0 | AC10: =COUNTIF($E$5:$E$22,E10) -> 1 | AD10: =IF(AND(H10>=I10,J10>0,K10>=J10,L10>0,M10>=L10,N10>0,O10>=N10,P10>=0,Q10>=P10,R10>0,S10>=R10,T10>0,U10>=T10,V10>0,W10>=V10,X10>0,Y10>=X10),"PASS","FAIL") -> PASS | AE10: =IF(AND(AC10=1,AF10=1,AD10="PASS",Z10="",AA10=0,AB10=0),"DIMENSIONED / UNSELECTED","FAIL") -> DIMENSIONED / UNSELECTED | AF10: =COUNTIF($A$5:$A$22,A10) -> 1
A11: HC-A-A | B11: HC-A | C11: A | D11: Independent winged sector cells | E11: five-wing / distributed | F11: five-sector intervention field | G11: five independent airframes | H11: 5 | I11: 5 | J11: 1000 | K11: 5000 | L11: 5000 | M11: 15000 | N11: 1000 | O11: 5000 | P11: 0 | Q11: 0 | R11: 35 | S11: 55 | T11: 50 | U11: 80 | V11: 10 | W11: 16 | X11: 5000 | Y11: 30000 | AA11: 0 | AB11: 0 | AC11: =COUNTIF($E$5:$E$22,E11) -> 1 | AD11: =IF(AND(H11>=I11,J11>0,K11>=J11,L11>0,M11>=L11,N11>0,O11>=N11,P11>=0,Q11>=P11,R11>0,S11>=R11,T11>0,U11>=T11,V11>0,W11>=V11,X11>0,Y11>=X11),"PASS","FAIL") -> PASS | AE11: =IF(AND(AC11=1,AF11=1,AD11="PASS",Z11="",AA11=0,AB11=0),"DIMENSIONED / UNSELECTED","FAIL") -> DIMENSIONED / UNSELECTED | AF11: =COUNTIF($A$5:$A$22,A11) -> 1
A12: HC-A-B | B12: HC-A | C12: B | D12: Independent aerostat sector cells | E12: five-aerostat / tethered | F12: five-sector intervention field | G12: five independent tether stations | H12: 5 | I12: 5 | J12: 1000 | K12: 5000 | L12: 5000 | M12: 15000 | N12: 300 | O12: 1500 | P12: 0 | Q12: 0 | R12: 50 | S12: 90 | T12: 25 | U12: 50 | V12: 30 | W12: 60 | X12: 5000 | Y12: 30000 | AA12: 0 | AB12: 0 | AC12: =COUNTIF($E$5:$E$22,E12) -> 1 | AD12: =IF(AND(H12>=I12,J12>0,K12>=J12,L12>0,M12>=L12,N12>0,O12>=N12,P12>=0,Q12>=P12,R12>0,S12>=R12,T12>0,U12>=T12,V12>0,W12>=V12,X12>0,Y12>=X12),"PASS","FAIL") -> PASS | AE12: =IF(AND(AC12=1,AF12=1,AD12="PASS",Z12="",AA12=0,AB12=0),"DIMENSIONED / UNSELECTED","FAIL") -> DIMENSIONED / UNSELECTED | AF12: =COUNTIF($A$5:$A$22,A12) -> 1
A13: HC-A-C | B13: HC-A | C13: C | D13: Distributed rotorborne cells | E13: five-rotor / distributed | F13: five-sector intervention field | G13: five independent rotor cells | H13: 5 | I13: 5 | J13: 1000 | K13: 3000 | L13: 5000 | M13: 12000 | N13: 50 | O13: 500 | P13: 0 | Q13: 0 | R13: 12 | S13: 24 | T13: 12 | U13: 28 | V13: 4 | W13: 9 | X13: 3000 | Y13: 20000 | AA13: 0 | AB13: 0 | AC13: =COUNTIF($E$5:$E$22,E13) -> 1 | AD13: =IF(AND(H13>=I13,J13>0,K13>=J13,L13>0,M13>=L13,N13>0,O13>=N13,P13>=0,Q13>=P13,R13>0,S13>=R13,T13>0,U13>=T13,V13>0,W13>=V13,X13>0,Y13>=X13),"PASS","FAIL") -> PASS | AE13: =IF(AND(AC13=1,AF13=1,AD13="PASS",Z13="",AA13=0,AB13=0),"DIMENSIONED / UNSELECTED","FAIL") -> DIMENSIONED / UNSELECTED | AF13: =COUNTIF($A$5:$A$22,A13) -> 1
A14: LF-B-A | B14: LF-B | C14: A | D14: Cellular radial multi-bore field | E14: radial / loss-celled | F14: complete source position | G14: nine access slots around isolated conversion cells | H14: 9 | I14: 9 | J14: 500 | K14: 1500 | L14: 500 | M14: 1500 | N14: 20 | O14: 45 | P14: 2500 | Q14: 6000 | R14: 120 | S14: 250 | T14: 120 | U14: 250 | V14: 20 | W14: 45 | X14: 15500 | Y14: 30000 | AA14: 0 | AB14: 0 | AC14: =COUNTIF($E$5:$E$22,E14) -> 1 | AD14: =IF(AND(H14>=I14,J14>0,K14>=J14,L14>0,M14>=L14,N14>0,O14>=N14,P14>=0,Q14>=P14,R14>0,S14>=R14,T14>0,U14>=T14,V14>0,W14>=V14,X14>0,Y14>=X14),"PASS","FAIL") -> PASS | AE14: =IF(AND(AC14=1,AF14=1,AD14="PASS",Z14="",AA14=0,AB14=0),"DIMENSIONED / UNSELECTED","FAIL") -> DIMENSIONED / UNSELECTED | AF14: =COUNTIF($A$5:$A$22,A14) -> 1
A15: LF-B-B | B15: LF-B | C15: B | D15: Dual-basin roadless source train | E15: dual-basin / linear | F15: two-basin source position | G15: two independently accessible route basins | H15: 2 | I15: 2 | J15: 2000 | K15: 8000 | L15: 500 | M15: 2000 | N15: 20 | O15: 45 | P15: 2500 | Q15: 6000 | R15: 300 | S15: 800 | T15: 60 | U15: 140 | V15: 20 | W15: 45 | X15: 15500 | Y15: 40000 | AA15: 0 | AB15: 0 | AC15: =COUNTIF($E$5:$E$22,E15) -> 1 | AD15: =IF(AND(H15>=I15,J15>0,K15>=J15,L15>0,M15>=L15,N15>0,O15>=N15,P15>=0,Q15>=P15,R15>0,S15>=R15,T15>0,U15>=T15,V15>0,W15>=V15,X15>0,Y15>=X15),"PASS","FAIL") -> PASS | AE15: =IF(AND(AC15=1,AF15=1,AD15="PASS",Z15="",AA15=0,AB15=0),"DIMENSIONED / UNSELECTED","FAIL") -> DIMENSIONED / UNSELECTED | AF15: =COUNTIF($A$5:$A$22,A15) -> 1
A16: LF-B-C | B16: LF-B | C16: C | D16: Nearshore caisson source archipelago | E16: three-caisson / nearshore | F16: three-caisson source position | G16: three separately founded caissons | H16: 3 | I16: 3 | J16: 600 | K16: 1800 | L16: 600 | M16: 1800 | N16: 35 | O16: 70 | P16: 2500 | Q16: 6000 | R16: 80 | S16: 150 | T16: 80 | U16: 150 | V16: 35 | W16: 60 | X16: 15500 | Y16: 30000 | AA16: 0 | AB16: 0 | AC16: =COUNTIF($E$5:$E$22,E16) -> 1 | AD16: =IF(AND(H16>=I16,J16>0,K16>=J16,L16>0,M16>=L16,N16>0,O16>=N16,P16>=0,Q16>=P16,R16>0,S16>=R16,T16>0,U16>=T16,V16>0,W16>=V16,X16>0,Y16>=X16),"PASS","FAIL") -> PASS | AE16: =IF(AND(AC16=1,AF16=1,AD16="PASS",Z16="",AA16=0,AB16=0),"DIMENSIONED / UNSELECTED","FAIL") -> DIMENSIONED / UNSELECTED | AF16: =COUNTIF($A$5:$A$22,A16) -> 1
... A22: RT-B-C | B22: RT-B | C22: C | D22: Parallel mobile microfactory trainlets | E22: parallel-trainlet / mobile | F22: complete 99-position regeneration field | G22: five complete mobile trainlets | H22: 5 | I22: 5 | J22: 500 | K22: 2000 | L22: 100 | M22: 400 | N22: 8 | O22: 16 | P22: 0 | Q22: 0 | R22: 100 | S22: 250 | T22: 25 | U22: 60 | V22: 8 | W22: 16 | X22: 5000 | Y22: 20000 | AA22: 0 | AB22: 0 | AC22: =COUNTIF($E$5:$E$22,E22) -> 1 | AD22: =IF(AND(H22>=I22,J22>0,K22>=J22,L22>0,M22>=L22,N22>0,O22>=N22,P22>=0,Q22>=P22,R22>0,S22>=R22,T22>0,U22>=T22,V22>0,W22>=V22,X22>0,Y22>=X22),"PASS","FAIL") -> PASS | AE22: =IF(AND(AC22=1,AF22=1,AD22="PASS",Z22="",AA22=0,AB22=0),"DIMENSIONED / UNSELECTED","FAIL") -> DIMENSIONED / UNSELECTED | AF22: =COUNTIF($A$5:$A$22,A22) -> 1

Sheet Coordinate Frames
A2: Six noninterchangeable coordinate frames
A4: Root | B4: Origin | C4: Positive x | D4: Positive y | E4: Positive z | F4: Depth convention | G4: Permitted transform | H4: Prohibited transform | I4: Frame complete | J4: Authority
A5: ET-A | B5: wet-source contact at calm-waterline projection | C5: wet source toward dry handoff | D5: path A toward path B | E5: waterline upward | F5: draft below z=0 | G5: rigid translation and yaw only | H5: no scale transform; paths retain separate frames | I5: =IF(COUNTA(A5:H5)=8,"PASS","FAIL") -> PASS | J5: PLANNING DATUM
A6: CT-C | B6: first reversible ground attachment | C6: along occupied-boundary insertion | D6: façade outward | E6: grade upward | F6: none | G6: translate along surveyed building datum | H6: no rotation that exchanges inside and outside | I6: =IF(COUNTA(A6:H6)=8,"PASS","FAIL") -> PASS | J6: PLANNING DATUM
A7: HC-A | B7: upwind protected-edge datum | C7: upwind toward downwind causal corridor | D7: along held line | E7: terrain upward | F7: none | G7: each sector georeferences independently | H7: no common moving origin across sectors | I7: =IF(COUNTA(A7:H7)=8,"PASS","FAIL") -> PASS | J7: PLANNING DATUM
A8: LF-B | B8: surface projection of first production contact | C8: production toward conversion and handoff | D8: production toward injection separation | E8: surface upward | F8: bore depth below z=0 | G8: translate within one geodetic source datum | H8: no depth rescaling or basin-frame merger | I8: =IF(COUNTA(A8:H8)=8,"PASS","FAIL") -> PASS | J8: PLANNING DATUM
A9: HU-A | B9: public reception threshold | C9: reception toward supported discharge | D9: clean circulation toward dirty service | E9: grade upward | F9: none | G9: translate within one clinical island | H9: no transform that exchanges sterile and dirty sides | I9: =IF(COUNTA(A9:H9)=8,"PASS","FAIL") -> PASS | J9: PLANNING DATUM
A10: RT-B | B10: dirty-return custody threshold | C10: dirty return toward signed release | D10: failure island 1 toward failure island 5 | E10: grade upward | F10: none | G10: translate a complete process island | H10: no transform that hides process ancestry | I10: =IF(COUNTA(A10:H10)=8,"PASS","FAIL") -> PASS | J10: PLANNING DATUM

Sheet Interface Zones
A2: One hundred eight decisive-interface coordinate boxes
A4: Zone | B4: Root | C4: Hypothesis | D4: Decisive interface | E4: x center share | F4: x half-zone | G4: y center share | H4: y half-zone | I4: z basis | J4: z center share | K4: z half-zone | L4: x low m | M4: x high m | N4: y low m | O4: y high m | P4: z low m | Q4: z high m | R4: Role occurrences | S4: Bound state | T4: Authority | U4: Zone occurrences
A5: ET-A-A-I1 | B5: ET-A | C5: ET-A-A | D5: wet-source receiver | E5: 0.08 | F5: 0.035 | G5: 0.18 | H5: 0.055 | I5: HEIGHT | J5: 0.1 | K5: 0.045 | L5: =ROUND(INDEX('Envelope Register'!$J$5:$J$22,MATCH(C5,'Envelope Register'!$A$5:$A$22,0))*(E5-F5),0) -> 7 | M5: =ROUND(INDEX('Envelope Register'!$J$5:$J$22,MATCH(C5,'Envelope Register'!$A$5:$A$22,0))*(E5+F5),0) -> 18 | N5: =ROUND(INDEX('Envelope Register'!$L$5:$L$22,MATCH(C5,'Envelope Register'!$A$5:$A$22,0))*(G5-H5),0) -> 11 | O5: =ROUND(INDEX('Envelope Register'!$L$5:$L$22,MATCH(C5,'Envelope Register'!$A$5:$A$22,0))*(G5+H5),0) -> 21 | P5: =IF(I5="DEPTH",ROUND(-INDEX('Envelope Register'!$P$5:$P$22,MATCH(C5,'Envelope Register'!$A$5:$A$22,0))*(J5+K5),0),ROUND(INDEX('Envelope Register'!$N$5:$N$22,MATCH(C5,'Envelope Register'!$A$5:$A$22,0))*(J5-K5),0)) -> 1 | Q5: =IF(I5="DEPTH",ROUND(-INDEX('Envelope Register'!$P$5:$P$22,MATCH(C5,'Envelope Register'!$A$5:$A$22,0))*(J5-K5),0),ROUND(INDEX('Envelope Register'!$N$5:$N$22,MATCH(C5,'Envelope Register'!$A$5:$A$22,0))*(J5+K5),0)) -> 4 | R5: =COUNTIFS($C$5:$C$112,C5,$D$5:$D$112,D5) -> 1 | S5: =IF(AND(L5>=0,M5<=INDEX('Envelope Register'!$J$5:$J$22,MATCH(C5,'Envelope Register'!$A$5:$A$22,0)),N5>=0,O5<=INDEX('Envelope Register'!$L$5:$L$22,MATCH(C5,'Envelope Register'!$A$5:$A$22,0)),P5>=-INDEX('Envelope Register'!$P$5:$P$22,MATCH(C5,'Envelope Register'!$A$5:$A$22,0)),Q5<=INDEX('Envelope Register'!$N$5:$N$22,MATCH(C5,'Envelope Register'!$A$5:$A$22,0)),L5<M5,N5<O5,P5<Q5,R5=1,U5=1),"PASS","FAIL") -> PASS | T5: PLANNING BOX | U5: =COUNTIF($A$5:$A$112,A5) -> 1
A6: ET-A-A-I2 | B6: ET-A | C6: ET-A-A | D6: transfer path A | E6: 0.25 | F6: 0.035 | G6: 0.18 | H6: 0.055 | I6: HEIGHT | J6: 0.4 | K6: 0.045 | L6: =ROUND(INDEX('Envelope Register'!$J$5:$J$22,MATCH(C6,'Envelope Register'!$A$5:$A$22,0))*(E6-F6),0) -> 34 | M6: =ROUND(INDEX('Envelope Register'!$J$5:$J$22,MATCH(C6,'Envelope Register'!$A$5:$A$22,0))*(E6+F6),0) -> 46 | N6: =ROUND(INDEX('Envelope Register'!$L$5:$L$22,MATCH(C6,'Envelope Register'!$A$5:$A$22,0))*(G6-H6),0) -> 11 | O6: =ROUND(INDEX('Envelope Register'!$L$5:$L$22,MATCH(C6,'Envelope Register'!$A$5:$A$22,0))*(G6+H6),0) -> 21 | P6: =IF(I6="DEPTH",ROUND(-INDEX('Envelope Register'!$P$5:$P$22,MATCH(C6,'Envelope Register'!$A$5:$A$22,0))*(J6+K6),0),ROUND(INDEX('Envelope Register'!$N$5:$N$22,MATCH(C6,'Envelope Register'!$A$5:$A$22,0))*(J6-K6),0)) -> 9 | Q6: =IF(I6="DEPTH",ROUND(-INDEX('Envelope Register'!$P$5:$P$22,MATCH(C6,'Envelope Register'!$A$5:$A$22,0))*(J6-K6),0),ROUND(INDEX('Envelope Register'!$N$5:$N$22,MATCH(C6,'Envelope Register'!$A$5:$A$22,0))*(J6+K6),0)) -> 12 | R6: =COUNTIFS($C$5:$C$112,C6,$D$5:$D$112,D6) -> 1 | S6: =IF(AND(L6>=0,M6<=INDEX('Envelope Register'!$J$5:$J$22,MATCH(C6,'Envelope Register'!$A$5:$A$22,0)),N6>=0,O6<=INDEX('Envelope Register'!$L$5:$L$22,MATCH(C6,'Envelope Register'!$A$5:$A$22,0)),P6>=-INDEX('Envelope Register'!$P$5:$P$22,MATCH(C6,'Envelope Register'!$A$5:$A$22,0)),Q6<=INDEX('Envelope Register'!$N$5:$N$22,MATCH(C6,'Envelope Register'!$A$5:$A$22,0)),L6<M6,N6<O6,P6<Q6,R6=1,U6=1),"PASS","FAIL") -> PASS | T6: PLANNING BOX | U6: =COUNTIF($A$5:$A$112,A6) -> 1
A7: ET-A-A-I3 | B7: ET-A | C7: ET-A-A | D7: transfer path B | E7: 0.42 | F7: 0.035 | G7: 0.82 | H7: 0.055 | I7: HEIGHT | J7: 0.4 | K7: 0.045 | L7: =ROUND(INDEX('Envelope Register'!$J$5:$J$22,MATCH(C7,'Envelope Register'!$A$5:$A$22,0))*(E7-F7),0) -> 62 | M7: =ROUND(INDEX('Envelope Register'!$J$5:$J$22,MATCH(C7,'Envelope Register'!$A$5:$A$22,0))*(E7+F7),0) -> 73 | N7: =ROUND(INDEX('Envelope Register'!$L$5:$L$22,MATCH(C7,'Envelope Register'!$A$5:$A$22,0))*(G7-H7),0) -> 69 | O7: =ROUND(INDEX('Envelope Register'!$L$5:$L$22,MATCH(C7,'Envelope Register'!$A$5:$A$22,0))*(G7+H7),0) -> 79 | P7: =IF(I7="DEPTH",ROUND(-INDEX('Envelope Register'!$P$5:$P$22,MATCH(C7,'Envelope Register'!$A$5:$A$22,0))*(J7+K7),0),ROUND(INDEX('Envelope Register'!$N$5:$N$22,MATCH(C7,'Envelope Register'!$A$5:$A$22,0))*(J7-K7),0)) -> 9 | Q7: =IF(I7="DEPTH",ROUND(-INDEX('Envelope Register'!$P$5:$P$22,MATCH(C7,'Envelope Register'!$A$5:$A$22,0))*(J7-K7),0),ROUND(INDEX('Envelope Register'!$N$5:$N$22,MATCH(C7,'Envelope Register'!$A$5:$A$22,0))*(J7+K7),0)) -> 12 | R7: =COUNTIFS($C$5:$C$112,C7,$D$5:$D$112,D7) -> 1 | S7: =IF(AND(L7>=0,M7<=INDEX('Envelope Register'!$J$5:$J$22,MATCH(C7,'Envelope Register'!$A$5:$A$22,0)),N7>=0,O7<=INDEX('Envelope Register'!$L$5:$L$22,MATCH(C7,'Envelope Register'!$A$5:$A$22,0)),P7>=-INDEX('Envelope Register'!$P$5:$P$22,MATCH(C7,'Envelope Register'!$A$5:$A$22,0)),Q7<=INDEX('Envelope Register'!$N$5:$N$22,MATCH(C7,'Envelope Register'!$A$5:$A$22,0)),L7<M7,N7<O7,P7<Q7,R7=1,U7=1),"PASS","FAIL") -> PASS | T7: PLANNING BOX | U7: =COUNTIF($A$5:$A$112,A7) -> 1
A8: ET-A-A-I4 | B8: ET-A | C8: ET-A-A | D8: wet-dry break | E8: 0.58 | F8: 0.035 | G8: 0.82 | H8: 0.055 | I8: HEIGHT | J8: 0.52 | K8: 0.045 | L8: =ROUND(INDEX('Envelope Register'!$J$5:$J$22,MATCH(C8,'Envelope Register'!$A$5:$A$22,0))*(E8-F8),0) -> 87 | M8: =ROUND(INDEX('Envelope Register'!$J$5:$J$22,MATCH(C8,'Envelope Register'!$A$5:$A$22,0))*(E8+F8),0) -> 98 | N8: =ROUND(INDEX('Envelope Register'!$L$5:$L$22,MATCH(C8,'Envelope Register'!$A$5:$A$22,0))*(G8-H8),0) -> 69 | O8: =ROUND(INDEX('Envelope Register'!$L$5:$L$22,MATCH(C8,'Envelope Register'!$A$5:$A$22,0))*(G8+H8),0) -> 79 | P8: =IF(I8="DEPTH",ROUND(-INDEX('Envelope Register'!$P$5:$P$22,MATCH(C8,'Envelope Register'!$A$5:$A$22,0))*(J8+K8),0),ROUND(INDEX('Envelope Register'!$N$5:$N$22,MATCH(C8,'Envelope Register'!$A$5:$A$22,0))*(J8-K8),0)) -> 12 | Q8: =IF(I8="DEPTH",ROUND(-INDEX('Envelope Register'!$P$5:$P$22,MATCH(C8,'Envelope Register'!$A$5:$A$22,0))*(J8-K8),0),ROUND(INDEX('Envelope Register'!$N$5:$N$22,MATCH(C8,'Envelope Register'!$A$5:$A$22,0))*(J8+K8),0)) -> 15 | R8: =COUNTIFS($C$5:$C$112,C8,$D$5:$D$112,D8) -> 1 | S8: =IF(AND(L8>=0,M8<=INDEX('Envelope Register'!$J$5:$J$22,MATCH(C8,'Envelope Register'!$A$5:$A$22,0)),N8>=0,O8<=INDEX('Envelope Register'!$L$5:$L$22,MATCH(C8,'Envelope Register'!$A$5:$A$22,0)),P8>=-INDEX('Envelope Register'!$P$5:$P$22,MATCH(C8,'Envelope Register'!$A$5:$A$22,0)),Q8<=INDEX('Envelope Register'!$N$5:$N$22,MATCH(C8,'Envelope Register'!$A$5:$A$22,0)),L8<M8,N8<O8,P8<Q8,R8=1,U8=1),"PASS","FAIL") -> PASS | T8: PLANNING BOX | U8: =COUNTIF($A$5:$A$112,A8) -> 1
A9: ET-A-A-I5 | B9: ET-A | C9: ET-A-A | D9: dry custody and handoff | E9: 0.76 | F9: 0.035 | G9: 0.25 | H9: 0.055 | I9: HEIGHT | J9: 0.65 | K9: 0.045 | L9: =ROUND(INDEX('Envelope Register'!$J$5:$J$22,MATCH(C9,'Envelope Register'!$A$5:$A$22,0))*(E9-F9),0) -> 116 | M9: =ROUND(INDEX('Envelope Register'!$J$5:$J$22,MATCH(C9,'Envelope Register'!$A$5:$A$22,0))*(E9+F9),0) -> 127 | N9: =ROUND(INDEX('Envelope Register'!$L$5:$L$22,MATCH(C9,'Envelope Register'!$A$5:$A$22,0))*(G9-H9),0) -> 18 | O9: =ROUND(INDEX('Envelope Register'!$L$5:$L$22,MATCH(C9,'Envelope Register'!$A$5:$A$22,0))*(G9+H9),0) -> 27 | P9: =IF(I9="DEPTH",ROUND(-INDEX('Envelope Register'!$P$5:$P$22,MATCH(C9,'Envelope Register'!$A$5:$A$22,0))*(J9+K9),0),ROUND(INDEX('Envelope Register'!$N$5:$N$22,MATCH(C9,'Envelope Register'!$A$5:$A$22,0))*(J9-K9),0)) -> 16 | Q9: =IF(I9="DEPTH",ROUND(-INDEX('Envelope Register'!$P$5:$P$22,MATCH(C9,'Envelope Register'!$A$5:$A$22,0))*(J9-K9),0),ROUND(INDEX('Envelope Register'!$N$5:$N$22,MATCH(C9,'Envelope Register'!$A$5:$A$22,0))*(J9+K9),0)) -> 18 | R9: =COUNTIFS($C$5:$C$112,C9,$D$5:$D$112,D9) -> 1 | S9: =IF(AND(L9>=0,M9<=INDEX('Envelope Register'!$J$5:$J$22,MATCH(C9,'Envelope Register'!$A$5:$A$22,0)),N9>=0,O9<=INDEX('Envelope Register'!$L$5:$L$22,MATCH(C9,'Envelope Register'!$A$5:$A$22,0)),P9>=-INDEX('Envelope Register'!$P$5:$P$22,MATCH(C9,'Envelope Register'!$A$5:$A$22,0)),Q9<=INDEX('Envelope Register'!$N$5:$N$22,MATCH(C9,'Envelope Register'!$A$5:$A$22,0)),L9<M9,N9<O9,P9<Q9,R9=1,U9=1),"PASS","FAIL") -> PASS | T9: PLANNING BOX | U9: =COUNTIF($A$5:$A$112,A9) -> 1
A10: ET-A-A-I6 | B10: ET-A | C10: ET-A-A | D10: residual and cold access | E10: 0.92 | F10: 0.035 | G10: 0.75 | H10: 0.055 | I10: HEIGHT | J10: 0.22 | K10: 0.045 | L10: =ROUND(INDEX('Envelope Register'!$J$5:$J$22,MATCH(C10,'Envelope Register'!$A$5:$A$22,0))*(E10-F10),0) -> 142 | M10: =ROUND(INDEX('Envelope Register'!$J$5:$J$22,MATCH(C10,'Envelope Register'!$A$5:$A$22,0))*(E10+F10),0) -> 153 | N10: =ROUND(INDEX('Envelope Register'!$L$5:$L$22,MATCH(C10,'Envelope Register'!$A$5:$A$22,0))*(G10-H10),0) -> 63 | O10: =ROUND(INDEX('Envelope Register'!$L$5:$L$22,MATCH(C10,'Envelope Register'!$A$5:$A$22,0))*(G10+H10),0) -> 72 | P10: =IF(I10="DEPTH",ROUND(-INDEX('Envelope Register'!$P$5:$P$22,MATCH(C10,'Envelope Register'!$A$5:$A$22,0))*(J10+K10),0),ROUND(INDEX('Envelope Register'!$N$5:$N$22,MATCH(C10,'Envelope Register'!$A$5:$A$22,0))*(J10-K10),0)) -> 5 | Q10: =IF(I10="DEPTH",ROUND(-INDEX('Envelope Register'!$P$5:$P$22,MATCH(C10,'Envelope Register'!$A$5:$A$22,0))*(J10-K10),0),ROUND(INDEX('Envelope Register'!$N$5:$N$22,MATCH(C10,'Envelope Register'!$A$5:$A$22,0))*(J10+K10),0)) -> 7 | R10: =COUNTIFS($C$5:$C$112,C10,$D$5:$D$112,D10) -> 1 | S10: =IF(AND(L10>=0,M10<=INDEX('Envelope Register'!$J$5:$J$22,MATCH(C10,'Envelope Register'!$A$5:$A$22,0)),N10>=0,O10<=INDEX('Envelope Register'!$L$5:$L$22,MATCH(C10,'Envelope Register'!$A$5:$A$22,0)),P10>=-INDEX('Envelope Register'!$P$5:$P$22,MATCH(C10,'Envelope Register'!$A$5:$A$22,0)),Q10<=INDEX('Envelope Register'!$N$5:$N$22,MATCH(C10,'Envelope Register'!$A$5:$A$22,0)),L10<M10,N10<O10,P10<Q10,R10=1,U10=1),"PASS","FAIL") -> PASS | T10: PLANNING BOX | U10: =COUNTIF($A$5:$A$112,A10) -> 1
A11: ET-A-B-I1 | B11: ET-A | C11: ET-A-B | D11: wet-source receiver | E11: 0.06 | F11: 0.035 | G11: 0.5 | H11: 0.055 | I11: HEIGHT | J11: 0.1 | K11: 0.045 | L11: =ROUND(INDEX('Envelope Register'!$J$5:$J$22,MATCH(C11,'Envelope Register'!$A$5:$A$22,0))*(E11-F11),0) -> 6 | M11: =ROUND(INDEX('Envelope Register'!$J$5:$J$22,MATCH(C11,'Envelope Register'!$A$5:$A$22,0))*(E11+F11),0) -> 25 | N11: =ROUND(INDEX('Envelope Register'!$L$5:$L$22,MATCH(C11,'Envelope Register'!$A$5:$A$22,0))*(G11-H11),0) -> 20 | O11: =ROUND(INDEX('Envelope Register'!$L$5:$L$22,MATCH(C11,'Envelope Register'!$A$5:$A$22,0))*(G11+H11),0) -> 25 | P11: =IF(I11="DEPTH",ROUND(-INDEX('Envelope Register'!$P$5:$P$22,MATCH(C11,'Envelope Register'!$A$5:$A$22,0))*(J11+K11),0),ROUND(INDEX('Envelope Register'!$N$5:$N$22,MATCH(C11,'Envelope Register'!$A$5:$A$22,0))*(J11-K11),0)) -> 1 | Q11: =IF(I11="DEPTH",ROUND(-INDEX('Envelope Register'!$P$5:$P$22,MATCH(C11,'Envelope Register'!$A$5:$A$22,0))*(J11-K11),0),ROUND(INDEX('Envelope Register'!$N$5:$N$22,MATCH(C11,'Envelope Register'!$A$5:$A$22,0))*(J11+K11),0)) -> 3 | R11: =COUNTIFS($C$5:$C$112,C11,$D$5:$D$112,D11) -> 1 | S11: =IF(AND(L11>=0,M11<=INDEX('Envelope Register'!$J$5:$J$22,MATCH(C11,'Envelope Register'!$A$5:$A$22,0)),N11>=0,O11<=INDEX('Envelope Register'!$L$5:$L$22,MATCH(C11,'Envelope Register'!$A$5:$A$22,0)),P11>=-INDEX('Envelope Register'!$P$5:$P$22,MATCH(C11,'Envelope Register'!$A$5:$A$22,0)),Q11<=INDEX('Envelope Register'!$N$5:$N$22,MATCH(C11,'Envelope Register'!$A$5:$A$22,0)),L11<M11,N11<O11,P11<Q11,R11=1,U11=1),"PASS","FAIL") -> PASS | T11: PLANNING BOX | U11: =COUNTIF($A$5:$A$112,A11) -> 1
A12: ET-A-B-I2 | B12: ET-A | C12: ET-A-B | D12: transfer path A | E12: 0.22 | F12: 0.035 | G12: 0.28 | H12: 0.055 | I12: HEIGHT | J12: 0.4 | K12: 0.045 | L12: =ROUND(INDEX('Envelope Register'!$J$5:$J$22,MATCH(C12,'Envelope Register'!$A$5:$A$22,0))*(E12-F12),0) -> 48 | M12: =ROUND(INDEX('Envelope Register'!$J$5:$J$22,MATCH(C12,'Envelope Register'!$A$5:$A$22,0))*(E12+F12),0) -> 66 | N12: =ROUND(INDEX('Envelope Register'!$L$5:$L$22,MATCH(C12,'Envelope Register'!$A$5:$A$22,0))*(G12-H12),0) -> 10 | O12: =ROUND(INDEX('Envelope Register'!$L$5:$L$22,MATCH(C12,'Envelope Register'!$A$5:$A$22,0))*(G12+H12),0) -> 15 | P12: =IF(I12="DEPTH",ROUND(-INDEX('Envelope Register'!$P$5:$P$22,MATCH(C12,'Envelope Register'!$A$5:$A$22,0))*(J12+K12),0),ROUND(INDEX('Envelope Register'!$N$5:$N$22,MATCH(C12,'Envelope Register'!$A$5:$A$22,0))*(J12-K12),0)) -> 8 | Q12: =IF(I12="DEPTH",ROUND(-INDEX('Envelope Register'!$P$5:$P$22,MATCH(C12,'Envelope Register'!$A$5:$A$22,0))*(J12-K12),0),ROUND(INDEX('Envelope Register'!$N$5:$N$22,MATCH(C12,'Envelope Register'!$A$5:$A$22,0))*(J12+K12),0)) -> 10 | R12: =COUNTIFS($C$5:$C$112,C12,$D$5:$D$112,D12) -> 1 | S12: =IF(AND(L12>=0,M12<=INDEX('Envelope Register'!$J$5:$J$22,MATCH(C12,'Envelope Register'!$A$5:$A$22,0)),N12>=0,O12<=INDEX('Envelope Register'!$L$5:$L$22,MATCH(C12,'Envelope Register'!$A$5:$A$22,0)),P12>=-INDEX('Envelope Register'!$P$5:$P$22,MATCH(C12,'Envelope Register'!$A$5:$A$22,0)),Q12<=INDEX('Envelope Register'!$N$5:$N$22,MATCH(C12,'Envelope Register'!$A$5:$A$22,0)),L12<M12,N12<O12,P12<Q12,R12=1,U12=1),"PASS","FAIL") -> PASS | T12: PLANNING BOX | U12: =COUNTIF($A$5:$A$112,A12) -> 1
A13: ET-A-B-I3 | B13: ET-A | C13: ET-A-B | D13: transfer path B | E13: 0.4 | F13: 0.035 | G13: 0.72 | H13: 0.055 | I13: HEIGHT | J13: 0.4 | K13: 0.045 | L13: =ROUND(INDEX('Envelope Register'!$J$5:$J$22,MATCH(C13,'Envelope Register'!$A$5:$A$22,0))*(E13-F13),0) -> 95 | M13: =ROUND(INDEX('Envelope Register'!$J$5:$J$22,MATCH(C13,'Envelope Register'!$A$5:$A$22,0))*(E13+F13),0) -> 113 | N13: =ROUND(INDEX('Envelope Register'!$L$5:$L$22,MATCH(C13,'Envelope Register'!$A$5:$A$22,0))*(G13-H13),0) -> 30 | O13: =ROUND(INDEX('Envelope Register'!$L$5:$L$22,MATCH(C13,'Envelope Register'!$A$5:$A$22,0))*(G13+H13),0) -> 35 | P13: =IF(I13="DEPTH",ROUND(-INDEX('Envelope Register'!$P$5:$P$22,MATCH(C13,'Envelope Register'!$A$5:$A$22,0))*(J13+K13),0),ROUND(INDEX('Envelope Register'!$N$5:$N$22,MATCH(C13,'Envelope Register'!$A$5:$A$22,0))*(J13-K13),0)) -> 8 | Q13: =IF(I13="DEPTH",ROUND(-INDEX('Envelope Register'!$P$5:$P$22,MATCH(C13,'Envelope Register'!$A$5:$A$22,0))*(J13-K13),0),ROUND(INDEX('Envelope Register'!$N$5:$N$22,MATCH(C13,'Envelope Register'!$A$5:$A$22,0))*(J13+K13),0)) -> 10 | R13: =COUNTIFS($C$5:$C$112,C13,$D$5:$D$112,D13) -> 1 | S13: =IF(AND(L13>=0,M13<=INDEX('Envelope Register'!$J$5:$J$22,MATCH(C13,'Envelope Register'!$A$5:$A$22,0)),N13>=0,O13<=INDEX('Envelope Register'!$L$5:$L$22,MATCH(C13,'Envelope Register'!$A$5:$A$22,0)),P13>=-INDEX('Envelope Register'!$P$5:$P$22,MATCH(C13,'Envelope Register'!$A$5:$A$22,0)),Q13<=INDEX('Envelope Register'!$N$5:$N$22,MATCH(C13,'Envelope Register'!$A$5:$A$22,0)),L13<M13,N13<O13,P13<Q13,R13=1,U13=1),"PASS","FAIL") -> PASS | T13: PLANNING BOX | U13: =COUNTIF($A$5:$A$112,A13) -> 1
A14: ET-A-B-I4 | B14: ET-A | C14: ET-A-B | D14: wet-dry break | E14: 0.6 | F14: 0.035 | G14: 0.28 | H14: 0.055 | I14: HEIGHT | J14: 0.52 | K14: 0.045 | L14: =ROUND(INDEX('Envelope Register'!$J$5:$J$22,MATCH(C14,'Envelope Register'!$A$5:$A$22,0))*(E14-F14),0) -> 147 | M14: =ROUND(INDEX('Envelope Register'!$J$5:$J$22,MATCH(C14,'Envelope Register'!$A$5:$A$22,0))*(E14+F14),0) -> 165 | N14: =ROUND(INDEX('Envelope Register'!$L$5:$L$22,MATCH(C14,'Envelope Register'!$A$5:$A$22,0))*(G14-H14),0) -> 10 | O14: =ROUND(INDEX('Envelope Register'!$L$5:$L$22,MATCH(C14,'Envelope Register'!$A$5:$A$22,0))*(G14+H14),0) -> 15 | P14: =IF(I14="DEPTH",ROUND(-INDEX('Envelope Register'!$P$5:$P$22,MATCH(C14,'Envelope Register'!$A$5:$A$22,0))*(J14+K14),0),ROUND(INDEX('Envelope Register'!$N$5:$N$22,MATCH(C14,'Envelope Register'!$A$5:$A$22,0))*(J14-K14),0)) -> 10 | Q14: =IF(I14="DEPTH",ROUND(-INDEX('Envelope Register'!$P$5:$P$22,MATCH(C14,'Envelope Register'!$A$5:$A$22,0))*(J14-K14),0),ROUND(INDEX('Envelope Register'!$N$5:$N$22,MATCH(C14,'Envelope Register'!$A$5:$A$22,0))*(J14+K14),0)) -> 12 | R14: =COUNTIFS($C$5:$C$112,C14,$D$5:$D$112,D14) -> 1 | S14: =IF(AND(L14>=0,M14<=INDEX('Envelope Register'!$J$5:$J$22,MATCH(C14,'Envelope Register'!$A$5:$A$22,0)),N14>=0,O14<=INDEX('Envelope Register'!$L$5:$L$22,MATCH(C14,'Envelope Register'!$A$5:$A$22,0)),P14>=-INDEX('Envelope Register'!$P$5:$P$22,MATCH(C14,'Envelope Register'!$A$5:$A$22,0)),Q14<=INDEX('Envelope Register'!$N$5:$N$22,MATCH(C14,'Envelope Register'!$A$5:$A$22,0)),L14<M14,N14<O14,P14<Q14,R14=1,U14=1),"PASS","FAIL") -> PASS | T14: PLANNING BOX | U14: =COUNTIF($A$5:$A$112,A14) -> 1
A15: ET-A-B-I5 | B15: ET-A | C15: ET-A-B | D15: dry custody and handoff | E15: 0.78 | F15: 0.035 | G15: 0.72 | H15: 0.055 | I15: HEIGHT | J15: 0.65 | K15: 0.045 | L15: =ROUND(INDEX('Envelope Register'!$J$5:$J$22,MATCH(C15,'Envelope Register'!$A$5:$A$22,0))*(E15-F15),0) -> 194 | M15: =ROUND(INDEX('Envelope Register'!$J$5:$J$22,MATCH(C15,'Envelope Register'!$A$5:$A$22,0))*(E15+F15),0) -> 212 | N15: =ROUND(INDEX('Envelope Register'!$L$5:$L$22,MATCH(C15,'Envelope Register'!$A$5:$A$22,0))*(G15-H15),0) -> 30 | O15: =ROUND(INDEX('Envelope Register'!$L$5:$L$22,MATCH(C15,'Envelope Register'!$A$5:$A$22,0))*(G15+H15),0) -> 35 | P15: =IF(I15="DEPTH",ROUND(-INDEX('Envelope Register'!$P$5:$P$22,MATCH(C15,'Envelope Register'!$A$5:$A$22,0))*(J15+K15),0),ROUND(INDEX('Envelope Register'!$N$5:$N$22,MATCH(C15,'Envelope Register'!$A$5:$A$22,0))*(J15-K15),0)) -> 13 | Q15: =IF(I15="DEPTH",ROUND(-INDEX('Envelope Register'!$P$5:$P$22,MATCH(C15,'Envelope Register'!$A$5:$A$22,0))*(J15-K15),0),ROUND(INDEX('Envelope Register'!$N$5:$N$22,MATCH(C15,'Envelope Register'!$A$5:$A$22,0))*(J15+K15),0)) -> 15 | R15: =COUNTIFS($C$5:$C$112,C15,$D$5:$D$112,D15) -> 1 | S15: =IF(AND(L15>=0,M15<=INDEX('Envelope Register'!$J$5:$J$22,MATCH(C15,'Envelope Register'!$A$5:$A$22,0)),N15>=0,O15<=INDEX('Envelope Register'!$L$5:$L$22,MATCH(C15,'Envelope Register'!$A$5:$A$22,0)),P15>=-INDEX('Envelope Register'!$P$5:$P$22,MATCH(C15,'Envelope Register'!$A$5:$A$22,0)),Q15<=INDEX('Envelope Register'!$N$5:$N$22,MATCH(C15,'Envelope Register'!$A$5:$A$22,0)),L15<M15,N15<O15,P15<Q15,R15=1,U15=1),"PASS","FAIL") -> PASS | T15: PLANNING BOX | U15: =COUNTIF($A$5:$A$112,A15) -> 1
A16: ET-A-B-I6 | B16: ET-A | C16: ET-A-B | D16: residual and cold access | E16: 0.94 | F16: 0.035 | G16: 0.5 | H16: 0.055 | I16: HEIGHT | J16: 0.22 | K16: 0.045 | L16: =ROUND(INDEX('Envelope Register'!$J$5:$J$22,MATCH(C16,'Envelope Register'!$A$5:$A$22,0))*(E16-F16),0) -> 235 | M16: =ROUND(INDEX('Envelope Register'!$J$5:$J$22,MATCH(C16,'Envelope Register'!$A$5:$A$22,0))*(E16+F16),0) -> 254 | N16: =ROUND(INDEX('Envelope Register'!$L$5:$L$22,MATCH(C16,'Envelope Register'!$A$5:$A$22,0))*(G16-H16),0) -> 20 | O16: =ROUND(INDEX('Envelope Register'!$L$5:$L$22,MATCH(C16,'Envelope Register'!$A$5:$A$22,0))*(G16+H16),0) -> 25 | P16: =IF(I16="DEPTH",ROUND(-INDEX('Envelope Register'!$P$5:$P$22,MATCH(C16,'Envelope Register'!$A$5:$A$22,0))*(J16+K16),0),ROUND(INDEX('Envelope Register'!$N$5:$N$22,MATCH(C16,'Envelope Register'!$A$5:$A$22,0))*(J16-K16),0)) -> 4 | Q16: =IF(I16="DEPTH",ROUND(-INDEX('Envelope Register'!$P$5:$P$22,MATCH(C16,'Envelope Register'!$A$5:$A$22,0))*(J16-K16),0),ROUND(INDEX('Envelope Register'!$N$5:$N$22,MATCH(C16,'Envelope Register'!$A$5:$A$22,0))*(J16+K16),0)) -> 6 | R16: =COUNTIFS($C$5:$C$112,C16,$D$5:$D$112,D16) -> 1 | S16: =IF(AND(L16>=0,M16<=INDEX('Envelope Register'!$J$5:$J$22,MATCH(C16,'Envelope Register'!$A$5:$A$22,0)),N16>=0,O16<=INDEX('Envelope Register'!$L$5:$L$22,MATCH(C16,'Envelope Register'!$A$5:$A$22,0)),P16>=-INDEX('Envelope Register'!$P$5:$P$22,MATCH(C16,'Envelope Register'!$A$5:$A$22,0)),Q16<=INDEX('Envelope Register'!$N$5:$N$22,MATCH(C16,'Envelope Register'!$A$5:$A$22,0)),L16<M16,N16<O16,P16<Q16,R16=1,U16=1),"PASS","FAIL") -> PASS | T16: PLANNING BOX | U16: =COUNTIF($A$5:$A$112,A16) -> 1
... A112: RT-B-C-I6 | B112: RT-B | C112: RT-B-C | D112: signed release | E112: 0.85 | F112: 0.035 | G112: 0.8 | H112: 0.055 | I112: HEIGHT | J112: 0.75 | K112: 0.07 | L112: =ROUND(INDEX('Envelope Register'!$J$5:$J$22,MATCH(C112,'Envelope Register'!$A$5:$A$22,0))*(E112-F112),0) -> 408 | M112: =ROUND(INDEX('Envelope Register'!$J$5:$J$22,MATCH(C112,'Envelope Register'!$A$5:$A$22,0))*(E112+F112),0) -> 443 | N112: =ROUND(INDEX('Envelope Register'!$L$5:$L$22,MATCH(C112,'Envelope Register'!$A$5:$A$22,0))*(G112-H112),0) -> 75 | O112: =ROUND(INDEX('Envelope Register'!$L$5:$L$22,MATCH(C112,'Envelope Register'!$A$5:$A$22,0))*(G112+H112),0) -> 86 | P112: =IF(I112="DEPTH",ROUND(-INDEX('Envelope Register'!$P$5:$P$22,MATCH(C112,'Envelope Register'!$A$5:$A$22,0))*(J112+K112),0),ROUND(INDEX('Envelope Register'!$N$5:$N$22,MATCH(C112,'Envelope Register'!$A$5:$A$22,0))*(J112-K112),0)) -> 5 | Q112: =IF(I112="DEPTH",ROUND(-INDEX('Envelope Register'!$P$5:$P$22,MATCH(C112,'Envelope Register'!$A$5:$A$22,0))*(J112-K112),0),ROUND(INDEX('Envelope Register'!$N$5:$N$22,MATCH(C112,'Envelope Register'!$A$5:$A$22,0))*(J112+K112),0)) -> 7 | R112: =COUNTIFS($C$5:$C$112,C112,$D$5:$D$112,D112) -> 1 | S112: =IF(AND(L112>=0,M112<=INDEX('Envelope Register'!$J$5:$J$22,MATCH(C112,'Envelope Register'!$A$5:$A$22,0)),N112>=0,O112<=INDEX('Envelope Register'!$L$5:$L$22,MATCH(C112,'Envelope Register'!$A$5:$A$22,0)),P112>=-INDEX('Envelope Register'!$P$5:$P$22,MATCH(C112,'Envelope Register'!$A$5:$A$22,0)),Q112<=INDEX('Envelope Register'!$N$5:$N$22,MATCH(C112,'Envelope Register'!$A$5:$A$22,0)),L112<M112,N112<O112,P112<Q112,R112=1,U112=1),"PASS","FAIL") -> PASS | T112: PLANNING BOX | U112: =COUNTIF($A$5:$A$112,A112) -> 1

Sheet Section Carryover
A2: One hundred eight section-to-form carryover decisions
A4: Record | B4: Hypothesis | C4: Root | D4: Account | E4: Inherited minimum section | F4: Required units | G4: Provided units | H4: Observed values | I4: Count state | J4: Evidence state | K4: Carryover state | L4: Source
A5: C001 | B5: ET-A-A | C5: ET-A | D5: mass | E5: complete 241 t/h exchange paths | F5: 2 | G5: 2 | H5: 0 | I5: =IF(G5>=F5,"PASS","FAIL") -> PASS | J5: =IF(H5=0,"UNOBSERVED","INVALID") -> UNOBSERVED | K5: =IF(AND(I5="PASS",J5="UNOBSERVED"),"DESIGN-CLOSE / TEST OPEN","FAIL") -> DESIGN-CLOSE / TEST OPEN | L5: Pass 219
A6: C002 | B6: ET-A-A | C6: ET-A | D6: energy | E6: black-start energy cells | F6: 6 | G6: 6 | H6: 0 | I6: =IF(G6>=F6,"PASS","FAIL") -> PASS | J6: =IF(H6=0,"UNOBSERVED","INVALID") -> UNOBSERVED | K6: =IF(AND(I6="PASS",J6="UNOBSERVED"),"DESIGN-CLOSE / TEST OPEN","FAIL") -> DESIGN-CLOSE / TEST OPEN | L6: Pass 219
A7: C003 | B7: ET-A-A | C7: ET-A | D7: geometry | E7: wet-to-dry transition paths | F7: 2 | G7: 2 | H7: 0 | I7: =IF(G7>=F7,"PASS","FAIL") -> PASS | J7: =IF(H7=0,"UNOBSERVED","INVALID") -> UNOBSERVED | K7: =IF(AND(I7="PASS",J7="UNOBSERVED"),"DESIGN-CLOSE / TEST OPEN","FAIL") -> DESIGN-CLOSE / TEST OPEN | L7: Pass 219
A8: C004 | B8: ET-A-A | C8: ET-A | D8: safe state | E8: separately safeable exchange paths | F8: 2 | G8: 2 | H8: 0 | I8: =IF(G8>=F8,"PASS","FAIL") -> PASS | J8: =IF(H8=0,"UNOBSERVED","INVALID") -> UNOBSERVED | K8: =IF(AND(I8="PASS",J8="UNOBSERVED"),"DESIGN-CLOSE / TEST OPEN","FAIL") -> DESIGN-CLOSE / TEST OPEN | L8: Pass 219
A9: C005 | B9: ET-A-A | C9: ET-A | D9: residual | E9: residual custody paths | F9: 2 | G9: 2 | H9: 0 | I9: =IF(G9>=F9,"PASS","FAIL") -> PASS | J9: =IF(H9=0,"UNOBSERVED","INVALID") -> UNOBSERVED | K9: =IF(AND(I9="PASS",J9="UNOBSERVED"),"DESIGN-CLOSE / TEST OPEN","FAIL") -> DESIGN-CLOSE / TEST OPEN | L9: Pass 219
A10: C006 | B10: ET-A-A | C10: ET-A | D10: reconstruction | E10: cold-build path objects | F10: 2 | G10: 2 | H10: 0 | I10: =IF(G10>=F10,"PASS","FAIL") -> PASS | J10: =IF(H10=0,"UNOBSERVED","INVALID") -> UNOBSERVED | K10: =IF(AND(I10="PASS",J10="UNOBSERVED"),"DESIGN-CLOSE / TEST OPEN","FAIL") -> DESIGN-CLOSE / TEST OPEN | L10: Pass 219
A11: C007 | B11: ET-A-B | C11: ET-A | D11: mass | E11: complete 241 t/h exchange paths | F11: 2 | G11: 2 | H11: 0 | I11: =IF(G11>=F11,"PASS","FAIL") -> PASS | J11: =IF(H11=0,"UNOBSERVED","INVALID") -> UNOBSERVED | K11: =IF(AND(I11="PASS",J11="UNOBSERVED"),"DESIGN-CLOSE / TEST OPEN","FAIL") -> DESIGN-CLOSE / TEST OPEN | L11: Pass 219
A12: C008 | B12: ET-A-B | C12: ET-A | D12: energy | E12: black-start energy cells | F12: 6 | G12: 6 | H12: 0 | I12: =IF(G12>=F12,"PASS","FAIL") -> PASS | J12: =IF(H12=0,"UNOBSERVED","INVALID") -> UNOBSERVED | K12: =IF(AND(I12="PASS",J12="UNOBSERVED"),"DESIGN-CLOSE / TEST OPEN","FAIL") -> DESIGN-CLOSE / TEST OPEN | L12: Pass 219
A13: C009 | B13: ET-A-B | C13: ET-A | D13: geometry | E13: wet-to-dry transition paths | F13: 2 | G13: 2 | H13: 0 | I13: =IF(G13>=F13,"PASS","FAIL") -> PASS | J13: =IF(H13=0,"UNOBSERVED","INVALID") -> UNOBSERVED | K13: =IF(AND(I13="PASS",J13="UNOBSERVED"),"DESIGN-CLOSE / TEST OPEN","FAIL") -> DESIGN-CLOSE / TEST OPEN | L13: Pass 219
A14: C010 | B14: ET-A-B | C14: ET-A | D14: safe state | E14: separately safeable exchange paths | F14: 2 | G14: 2 | H14: 0 | I14: =IF(G14>=F14,"PASS","FAIL") -> PASS | J14: =IF(H14=0,"UNOBSERVED","INVALID") -> UNOBSERVED | K14: =IF(AND(I14="PASS",J14="UNOBSERVED"),"DESIGN-CLOSE / TEST OPEN","FAIL") -> DESIGN-CLOSE / TEST OPEN | L14: Pass 219
A15: C011 | B15: ET-A-B | C15: ET-A | D15: residual | E15: residual custody paths | F15: 2 | G15: 2 | H15: 0 | I15: =IF(G15>=F15,"PASS","FAIL") -> PASS | J15: =IF(H15=0,"UNOBSERVED","INVALID") -> UNOBSERVED | K15: =IF(AND(I15="PASS",J15="UNOBSERVED"),"DESIGN-CLOSE / TEST OPEN","FAIL") -> DESIGN-CLOSE / TEST OPEN | L15: Pass 219
A16: C012 | B16: ET-A-B | C16: ET-A | D16: reconstruction | E16: cold-build path objects | F16: 2 | G16: 2 | H16: 0 | I16: =IF(G16>=F16,"PASS","FAIL") -> PASS | J16: =IF(H16=0,"UNOBSERVED","INVALID") -> UNOBSERVED | K16: =IF(AND(I16="PASS",J16="UNOBSERVED"),"DESIGN-CLOSE / TEST OPEN","FAIL") -> DESIGN-CLOSE / TEST OPEN | L16: Pass 219
... A112: C108 | B112: RT-B-C | C112: RT-B | D112: reconstruction | E112: cold-build process meshes | F112: 5 | G112: 5 | H112: 0 | I112: =IF(G112>=F112,"PASS","FAIL") -> PASS | J112: =IF(H112=0,"UNOBSERVED","INVALID") -> UNOBSERVED | K112: =IF(AND(I112="PASS",J112="UNOBSERVED"),"DESIGN-CLOSE / TEST OPEN","FAIL") -> DESIGN-CLOSE / TEST OPEN | L112: Pass 219

Sheet Technology Demands
A2: Fifty-four form-induced invention campaigns
A4: Campaign | B4: Hypothesis | C4: Root | D4: Decisive interface | E4: Required advance | F4: Why current class is insufficient | G4: Fatal prototype event | H4: Accepted evidence | I4: Campaigns per form | J4: State | K4: Authority
A5: T001 | B5: ET-A-A | C5: ET-A | D5: moving-source receiver | E5: active six-axis transfer saddle | F5: ordinary offshore cranes do not preserve two custody-complete paths under relative motion | G5: remove one saddle during rated transfer; surviving path must retain metered custody | H5: 0 | I5: =COUNTIF($B$5:$B$58,B5) -> 3 | J5: =IF(AND(E5<>"",G5<>"",H5=0,I5=3),"OPEN / UNPROVEN","FAIL") -> OPEN / UNPROVEN | K5: EXPERIMENT SPECIFICATION
A6: T002 | B6: ET-A-A | C6: ET-A | D6: wet-dry break | E6: self-forming amphibious shore bridge | F6: fixed ramps cannot create a reconstructable break across changing beach and flood profiles | G6: erase one shore segment and cold-build a replacement without stopping the other path | H6: 0 | I6: =COUNTIF($B$5:$B$58,B6) -> 3 | J6: =IF(AND(E6<>"",G6<>"",H6=0,I6=3),"OPEN / UNPROVEN","FAIL") -> OPEN / UNPROVEN | K6: EXPERIMENT SPECIFICATION
A7: T003 | B7: ET-A-A | C7: ET-A | D7: dry custody | E7: distributed tamper-evident flow metrology | F7: single custody stations remain common failure and cannot survive salt, motion and disconnection | G7: deny network and one meter chain; reconcile wet receipt to dry handoff locally | H7: 0 | I7: =COUNTIF($B$5:$B$58,B7) -> 3 | J7: =IF(AND(E7<>"",G7<>"",H7=0,I7=3),"OPEN / UNPROVEN","FAIL") -> OPEN / UNPROVEN | K7: EXPERIMENT SPECIFICATION
A8: T004 | B8: ET-A-B | C8: ET-A | D8: articulation chain | E8: load-sharing joints with physical safeing | F8: ship hinges are not designed as separately reconstructable cargo-custody boundaries | G8: lock one articulation at worst phase and retain one complete chain | H8: 0 | I8: =COUNTIF($B$5:$B$58,B8) -> 3 | J8: =IF(AND(E8<>"",G8<>"",H8=0,I8=3),"OPEN / UNPROVEN","FAIL") -> OPEN / UNPROVEN | K8: EXPERIMENT SPECIFICATION
A9: T005 | B9: ET-A-B | C9: ET-A | D9: surge buffer | E9: cell-local kinetic and material buffering | F9: central surge storage recouples both chains | G9: remove the largest buffer and sustain the lower-bound path rate | H9: 0 | I9: =COUNTIF($B$5:$B$58,B9) -> 3 | J9: =IF(AND(E9<>"",G9<>"",H9=0,I9=3),"OPEN / UNPROVEN","FAIL") -> OPEN / UNPROVEN | K9: EXPERIMENT SPECIFICATION
A10: T006 | B10: ET-A-B | C10: ET-A | D10: shore handoff | E10: autonomous chain reconfiguration | F10: preplanned moorings cannot cover unprepared shore geometry | G10: cold-plan and deploy a new chain geometry from sealed public records | H10: 0 | I10: =COUNTIF($B$5:$B$58,B10) -> 3 | J10: =IF(AND(E10<>"",G10<>"",H10=0,I10=3),"OPEN / UNPROVEN","FAIL") -> OPEN / UNPROVEN | K10: EXPERIMENT SPECIFICATION
A11: T007 | B11: ET-A-C | C11: ET-A | D11: split frame | E11: reconfigurable semi-submersible exchange cells | F11: offshore frames share ballast and stationkeeping ancestry | G11: flood or disable one frame while the other retains independent trim and flow | H11: 0 | I11: =COUNTIF($B$5:$B$58,B11) -> 3 | J11: =IF(AND(E11<>"",G11<>"",H11=0,I11=3),"OPEN / UNPROVEN","FAIL") -> OPEN / UNPROVEN | K11: EXPERIMENT SPECIFICATION
A12: T008 | B12: ET-A-C | C12: ET-A | D12: wet-to-dry sorting | E12: distributed custody-aware routing | F12: port sorting assumes fixed decks and common controls | G12: corrupt one routing controller and preserve signed flow on the second frame | H12: 0 | I12: =COUNTIF($B$5:$B$58,B12) -> 3 | J12: =IF(AND(E12<>"",G12<>"",H12=0,I12=3),"OPEN / UNPROVEN","FAIL") -> OPEN / UNPROVEN | K12: EXPERIMENT SPECIFICATION
A13: T009 | B13: ET-A-C | C13: ET-A | D13: stationkeeping | E13: separately safeable low-energy stationkeeping | F13: dynamic positioning commonly shares power and estimation | G13: deny one power and navigation lineage without merging frame control | H13: 0 | I13: =COUNTIF($B$5:$B$58,B13) -> 3 | J13: =IF(AND(E13<>"",G13<>"",H13=0,I13=3),"OPEN / UNPROVEN","FAIL") -> OPEN / UNPROVEN | K13: EXPERIMENT SPECIFICATION
A14: T010 | B14: CT-C-A | C14: CT-C | D14: reversible attachment | E14: robotic proof-loaded building anchors | F14: temporary works rarely certify occupied, damaged substrates in real time | G14: misclassify one anchor zone; local structure must isolate before propagation | H14: 0 | I14: =COUNTIF($B$5:$B$58,B14) -> 3 | J14: =IF(AND(E14<>"",G14<>"",H14=0,I14=3),"OPEN / UNPROVEN","FAIL") -> OPEN / UNPROVEN | K14: EXPERIMENT SPECIFICATION
A15: T011 | B15: CT-C-A | C15: CT-C | D15: telescoping spine | E15: fault-contained multi-utility telescoping joints | F15: utility couplers do not combine motion, smoke and contamination isolation | G15: remove one joint under full mixed-utility load and preserve adjacent trunks | H15: 0 | I15: =COUNTIF($B$5:$B$58,B15) -> 3 | J15: =IF(AND(E15<>"",G15<>"",H15=0,I15=3),"OPEN / UNPROVEN","FAIL") -> OPEN / UNPROVEN | K15: EXPERIMENT SPECIFICATION
A16: T012 | B16: CT-C-A | C16: CT-C | D16: cold reconstruction | E16: machine-readable attachment grammar | F16: site craft knowledge is not reconstructable from public records | G16: clean team rebuilds one section with original runtime and staff denied | H16: 0 | I16: =COUNTIF($B$5:$B$58,B16) -> 3 | J16: =IF(AND(E16<>"",G16<>"",H16=0,I16=3),"OPEN / UNPROVEN","FAIL") -> OPEN / UNPROVEN | K16: EXPERIMENT SPECIFICATION
... A58: T054 | B58: RT-B-C | C58: RT-B | D58: cold rebuild | E58: self-describing machines and fixtures | F58: machine tools depend on vendor software, keys and tacit setup | G58: clean team rebuilds one trainlet with vendors and private keys denied | H58: 0 | I58: =COUNTIF($B$5:$B$58,B58) -> 3 | J58: =IF(AND(E58<>"",G58<>"",H58=0,I58=3),"OPEN / UNPROVEN","FAIL") -> OPEN / UNPROVEN | K58: EXPERIMENT SPECIFICATION

Sheet Finance
A2: Dimensioning adds no financial authority
A4: System | B4: Root | C4: Article | D4: Option ceiling USD B | E4: FRAME share | F4: Maximum FRAME USD B | G4: Incremental dimensioning USD B | H4: Accepted USD B | I4: Paid USD B | J4: State
A5: MS-ET | B5: ET-A | C5: Pelagic exchange cell | D5: 0.50047462 | E5: =Controls!$B$13 -> 0.15 | F5: =D5*E5 -> 0.075071193 | G5: =Controls!$B$17 -> 0 | H5: 0 | I5: 0 | J5: =IF(OR(G5>0,H5>0,I5>0),"INVALID","HELD") -> HELD
A6: MS-CT | B6: CT-C | C6: Occupied-building utility-spine sector | D6: 0.51649348 | E6: =Controls!$B$13 -> 0.15 | F6: =D6*E6 -> 0.077474022 | G6: =Controls!$B$17 -> 0 | H6: 0 | I6: 0 | J6: =IF(OR(G6>0,H6>0,I6>0),"INVALID","HELD") -> HELD
A7: MS-HC | B7: HC-A | C7: Atmospheric intervention cell | D7: 0.30722165 | E7: =Controls!$B$13 -> 0.15 | F7: =D7*E7 -> 0.046083248 | G7: =Controls!$B$17 -> 0 | H7: 0 | I7: 0 | J7: =IF(OR(G7>0,H7>0,I7>0),"INVALID","HELD") -> HELD
A8: MS-LF | B8: LF-B | C8: Geothermal source position | D8: 0.89941282 | E8: =Controls!$B$13 -> 0.15 | F8: =D8*E8 -> 0.13491192 | G8: =Controls!$B$17 -> 0 | H8: 0 | I8: 0 | J8: =IF(OR(G8>0,H8>0,I8>0),"INVALID","HELD") -> HELD
A9: MS-HU | B9: HU-A | C9: Complete clinical island | D9: 0.86071245 | E9: =Controls!$B$13 -> 0.15 | F9: =D9*E9 -> 0.12910687 | G9: =Controls!$B$17 -> 0 | H9: 0 | I9: 0 | J9: =IF(OR(G9>0,H9>0,I9>0),"INVALID","HELD") -> HELD
A10: MS-RT | B10: RT-B | C10: Disconnected microfactory mesh | D10: 0.50259779 | E10: =Controls!$B$13 -> 0.15 | F10: =D10*E10 -> 0.075389669 | G10: =Controls!$B$17 -> 0 | H10: 0 | I10: 0 | J10: =IF(OR(G10>0,H10>0,I10>0),"INVALID","HELD") -> HELD
A11: TOTAL | B11: six roots | C11: dimension-envelope issuance | D11: =SUM(D5:D10) -> 3.5869128 | F11: =SUM(F5:F10) -> 0.53803692 | G11: =SUM(G5:G10) -> 0 | H11: =SUM(H5:H10) -> 0 | I11: =SUM(I5:I10) -> 0 | J11: =IF(COUNTIF(J5:J10,"INVALID")>0,"INVALID","HELD") -> HELD

Sheet Mutations
A2: Mutation test register
A4: Mutation | B4: Controlled change | C4: Expected detection | D4: Detected | E4: Restored
A5: M01 | B5: set one primary minimum to zero | C5: envelope range fails | D5: 1 | E5: 1
A6: M02 | B6: set one primary maximum below minimum | C6: envelope range fails | D6: 1 | E6: 1
A7: M03 | B7: duplicate one topology token | C7: topology uniqueness fails | D7: 1 | E7: 1
A8: M04 | B8: enter a common chassis ID | C8: authority state fails | D8: 1 | E8: 1
A9: M05 | B9: select one form | C9: zero-selection audit fails | D9: 1 | E9: 1
A10: M06 | B10: enter accepted evidence | C10: zero-evidence audit fails | D10: 1 | E10: 1
A11: M07 | B11: move one x zone outside minimum envelope | C11: zone bound fails | D11: 1 | E11: 1
A12: M08 | B12: duplicate one interface role | C12: role uniqueness fails | D12: 1 | E12: 1
A13: M09 | B13: blank one coordinate origin | C13: frame completeness fails | D13: 1 | E13: 1
A14: M10 | B14: reduce one carried section below minimum | C14: section carryover fails | D14: 1 | E14: 1
A15: M11 | B15: blank one required technology advance | C15: campaign state fails | D15: 1 | E15: 1
A16: M12 | B16: raise FRAME share | C16: finance conservation fails | D16: 1 | E16: 1
... A18: M14 | B18: enter a branch kill | C18: branch-kill audit fails | D18: 1 | E18: 1

Sheet Audit
A2: Independent workbook checks
A4: Audit | B4: Check | C4: Actual | D4: Expected | E4: Result
A5: A01 | B5: root count | C5: =COUNTA('Coordinate Frames'!A5:A10) -> 6 | D5: 6 | E5: =IF(ABS(C5-D5)<0.0000001,"PASS","FAIL") -> PASS
A6: A02 | B6: complete coordinate frames | C6: =COUNTIF('Coordinate Frames'!I5:I10,"PASS") -> 6 | D6: 6 | E6: =IF(ABS(C6-D6)<0.0000001,"PASS","FAIL") -> PASS
A7: A03 | B7: hypothesis count | C7: =COUNTA('Envelope Register'!A5:A22) -> 18 | D7: 18 | E7: =IF(ABS(C7-D7)<0.0000001,"PASS","FAIL") -> PASS
A8: A04 | B8: unique hypothesis IDs | C8: =COUNTIF('Envelope Register'!AF5:AF22,1) -> 18 | D8: 18 | E8: =IF(ABS(C8-D8)<0.0000001,"PASS","FAIL") -> PASS
A9: A05 | B9: unique topology tokens | C9: =COUNTIF('Envelope Register'!AC5:AC22,1) -> 18 | D9: 18 | E9: =IF(ABS(C9-D9)<0.0000001,"PASS","FAIL") -> PASS
A10: A06 | B10: valid dimension states | C10: =COUNTIF('Envelope Register'!AD5:AD22,"PASS") -> 18 | D10: 18 | E10: =IF(ABS(C10-D10)<0.0000001,"PASS","FAIL") -> PASS
A11: A07 | B11: authorized dimension states | C11: =COUNTIF('Envelope Register'!AE5:AE22,"DIMENSIONED / UNSELECTED") -> 18 | D11: 18 | E11: =IF(ABS(C11-D11)<0.0000001,"PASS","FAIL") -> PASS
A12: A08 | B12: common chassis entries | C12: =COUNTA('Envelope Register'!Z5:Z22) -> 0 | D12: 0 | E12: =IF(ABS(C12-D12)<0.0000001,"PASS","FAIL") -> PASS
A13: A09 | B13: selected forms | C13: =SUM('Envelope Register'!AA5:AA22) -> 0 | D13: 0 | E13: =IF(ABS(C13-D13)<0.0000001,"PASS","FAIL") -> PASS
A14: A10 | B14: accepted evidence | C14: =SUM('Envelope Register'!AB5:AB22) -> 0 | D14: 0 | E14: =IF(ABS(C14-D14)<0.0000001,"PASS","FAIL") -> PASS
A15: A11 | B15: interface zones | C15: =COUNTA('Interface Zones'!A5:A112) -> 108 | D15: 108 | E15: =IF(ABS(C15-D15)<0.0000001,"PASS","FAIL") -> PASS
A16: A12 | B16: unique zone IDs | C16: =COUNTIF('Interface Zones'!U5:U112,1) -> 108 | D16: 108 | E16: =IF(ABS(C16-D16)<0.0000001,"PASS","FAIL") -> PASS
A17: A13 | B17: bounded interface zones | C17: =COUNTIF('Interface Zones'!S5:S112,"PASS") -> 108 | D17: 108 | E17: =IF(ABS(C17-D17)<0.0000001,"PASS","FAIL") -> PASS
A18: A14 | B18: six roles per form | C18: =COUNTIF('Interface Zones'!R5:R112,1)/6 -> 18 | D18: 18 | E18: =IF(ABS(C18-D18)<0.0000001,"PASS","FAIL") -> PASS
A19: A15 | B19: section carryover decisions | C19: =COUNTA('Section Carryover'!A5:A112) -> 108 | D19: 108 | E19: =IF(ABS(C19-D19)<0.0000001,"PASS","FAIL") -> PASS
A20: A16 | B20: section count passes | C20: =COUNTIF('Section Carryover'!I5:I112,"PASS") -> 108 | D20: 108 | E20: =IF(ABS(C20-D20)<0.0000001,"PASS","FAIL") -> PASS
A21: A17 | B21: unobserved section records | C21: =COUNTIF('Section Carryover'!J5:J112,"UNOBSERVED") -> 108 | D21: 108 | E21: =IF(ABS(C21-D21)<0.0000001,"PASS","FAIL") -> PASS
A22: A18 | B22: design-close carryovers | C22: =COUNTIF('Section Carryover'!K5:K112,"DESIGN-CLOSE / TEST OPEN") -> 108 | D22: 108 | E22: =IF(ABS(C22-D22)<0.0000001,"PASS","FAIL") -> PASS
A23: A19 | B23: technology campaigns | C23: =COUNTA('Technology Demands'!A5:A58) -> 54 | D23: 54 | E23: =IF(ABS(C23-D23)<0.0000001,"PASS","FAIL") -> PASS
A24: A20 | B24: three campaigns per form | C24: =COUNTIF('Technology Demands'!I5:I58,3)/3 -> 18 | D24: 18 | E24: =IF(ABS(C24-D24)<0.0000001,"PASS","FAIL") -> PASS
A25: A21 | B25: technology remains unproven | C25: =COUNTIF('Technology Demands'!J5:J58,"OPEN / UNPROVEN") -> 54 | D25: 54 | E25: =IF(ABS(C25-D25)<0.0000001,"PASS","FAIL") -> PASS
A26: A22 | B26: option ceiling conservation | C26: =Finance!D11 -> 3.5869128 | D26: 3.5869128 | E26: =IF(ABS(C26-D26)<0.0000001,"PASS","FAIL") -> PASS
A27: A23 | B27: FRAME ceiling conservation | C27: =Finance!F11 -> 0.53803692 | D27: 0.53803692 | E27: =IF(ABS(C27-D27)<0.0000001,"PASS","FAIL") -> PASS
A28: A24 | B28: incremental ceiling | C28: =Finance!G11 -> 0 | D28: 0 | E28: =IF(ABS(C28-D28)<0.0000001,"PASS","FAIL") -> PASS
A29: A25 | B29: accepted amount | C29: =Finance!H11 -> 0 | D29: 0 | E29: =IF(ABS(C29-D29)<0.0000001,"PASS","FAIL") -> PASS
A30: A26 | B30: paid amount | C30: =Finance!I11 -> 0 | D30: 0 | E30: =IF(ABS(C30-D30)<0.0000001,"PASS","FAIL") -> PASS
A31: A27 | B31: finance states held | C31: =COUNTIF(Finance!J5:J10,"HELD") -> 6 | D31: 6 | E31: =IF(ABS(C31-D31)<0.0000001,"PASS","FAIL") -> PASS
A32: A28 | B32: mutations detected | C32: =SUM(Mutations!D5:D18) -> 14 | D32: 14 | E32: =IF(ABS(C32-D32)<0.0000001,"PASS","FAIL") -> PASS
A33: A29 | B33: mutations restored | C33: =SUM(Mutations!E5:E18) -> 14 | D33: 14 | E33: =IF(ABS(C33-D33)<0.0000001,"PASS","FAIL") -> PASS
A34: A30 | B34: branch kills | C34: =Controls!B16 -> 0 | D34: 0 | E34: =IF(ABS(C34-D34)<0.0000001,"PASS","FAIL") -> PASS

Sheet Sources & Limits
A2: Internal sources and claim limits
A4: Source | B4: Role | C4: Controlled use | D4: Limit
A5: Pass 215 construction compact | B5: finance source | C5: root option ceilings and 15 percent FRAME share | D5: ceilings are not awards or payments
A6: Pass 216 candidate article requirements | B6: mission boundary | C6: six root-native causal articles and full-scale burdens | D6: requirements are not observed performance
