Workbook

Sheet Summary
A2: Concurrent six-root causal-section closure
A4: Six root-native architecture lanes start together and close on their own clocks. This constitution fixes the closure grammar and preserves unlike mechanisms; it does not claim a closed physical margin.
A6: Decision object | B6: Value | C6: Unit | D6: State | E6: Meaning | F6: Authority | G6: Prohibited conversion | H6: Next burden
A7: selected sequence | B7: bounded asynchronous all-six | C7: text | D7: SELECTED | E7: six roots begin together and finish locally | F7: FGR-2 | G7: parallel work to common control | H7: quantitative root closure
A8: root-native lanes | B8: 6 | C8: count | D8: CONSTITUTED | E8: one isolated lane per sentinel root | F8: FGR-2 | G8: one finish to portfolio completion | H8: six complete dossiers
A9: section packets | B9: 48 | C9: count | D9: CONSTITUTED | E9: eight packets per root | F9: FGR-2 | G9: packet to evidence | H9: accepted paper artifacts
A10: closure cells | B10: 144 | C10: count | D10: OPEN | E10: six accounts across four worlds per root | F10: FGR-2 | G10: nominal surplus to denial pass | H10: owned and required bounds
A11: public seam records | B11: 72 | C11: count | D11: FROZEN | E11: twelve semantic seams per root | F11: PFP-4 | G11: shared meaning to common runtime | H11: root-native mappings
A12: author-challenge cells | B12: 12 | C12: count | D12: CONSTITUTED | E12: one author and one challenger per root | F12: FGR-2 | G12: review to design authority | H12: source-empty identities
A13: serial comparison | B13: 182 | C13: weeks | D13: PLANNING | E13: sum of six controlled durations | F13: FGR-2 | G13: paper duration to schedule fact | H13: observed work duration
A14: parallel wall-clock | B14: 36 | C14: weeks | D14: PLANNING | E14: longest controlled root duration | F14: FGR-2 | G14: slowest lane to command | H14: local review completion
A15: calendar reduction | B15: 0.8021978 | C15: share | D15: PLANNING | E15: parallel comparison against serial queue | F15: FGR-2 | G15: comparison to delivery promise | H15: observed schedule
A16: maximum FRAME envelope | B16: 0.53803692 | C16: USD B | D16: HELD | E16: fifteen percent of inherited six-root options | F16: A2C-5 | G16: ceiling to award or payment | H16: accepted packets
A17: accepted value | B17: 0 | C17: USD B | D17: HELD | E17: no artifact has been accepted | F17: SOURCE EMPTY | G17: constitution to fiscal transaction | H17: independent acceptance
A18: capability credit | B18: 0 | C18: count | D18: HELD | E18: paper closure is not readiness | F18: none | G18: model to observed effect | H18: representative events
A19: production authority | B19: 0 | C19: count | D19: HELD | E19: sentinels do not select production winners | F19: none | G19: one root to force winner | H19: complete-root proof
A20: rendering authority | B20: 0 | C20: count | D20: HELD | E20: exterior follows earned internal form | F20: none | G20: section grammar to image | H20: later form warrant
A23: Terminal test | B23: Observed | C23: State
A24: selected sequence | B24: =COUNTIFS(Alternatives!P7:P12,"SELECT") -> 1 | C24: =IF(ABS(B24-1)<0.000001,"PASS","FAIL") -> PASS
A25: root lanes | B25: =COUNTA('Root Lanes'!A7:A12) -> 6 | C25: =IF(ABS(B25-6)<0.000001,"PASS","FAIL") -> PASS
A26: closure cells | B26: =COUNTA('Closure Matrix'!A7:A150) -> 144 | C26: =IF(ABS(B26-144)<0.000001,"PASS","FAIL") -> PASS
A27: section packets | B27: =COUNTA('Section Packets'!A7:A54) -> 48 | C27: =IF(ABS(B27-48)<0.000001,"PASS","FAIL") -> PASS
A28: public seam records | B28: =COUNTA('Public Seams'!A7:A78) -> 72 | C28: =IF(ABS(B28-72)<0.000001,"PASS","FAIL") -> PASS
A29: serial weeks | B29: ='Concurrency Schedule'!M7 -> 182 | C29: =IF(ABS(B29-182)<0.000001,"PASS","FAIL") -> PASS
A30: parallel weeks | B30: ='Concurrency Schedule'!M8 -> 36 | C30: =IF(ABS(B30-36)<0.000001,"PASS","FAIL") -> PASS
A31: audit failures | B31: =COUNTIFS(Audit!E7:E105,"FAIL") -> 0 | C31: =IF(ABS(B31-0)<0.000001,"PASS","FAIL") -> PASS
A32: observations | B32: =Controls!B34 -> 0 | C32: =IF(ABS(B32-0)<0.000001,"PASS","FAIL") -> PASS
A33: capability | B33: =Controls!B35 -> 0 | C33: =IF(ABS(B33-0)<0.000001,"PASS","FAIL") -> PASS
A34: production | B34: =Controls!B36 -> 0 | C34: =IF(ABS(B34-0)<0.000001,"PASS","FAIL") -> PASS
A35: rendering | B35: =Controls!B37 -> 0 | C35: =IF(ABS(B35-0)<0.000001,"PASS","FAIL") -> PASS

Sheet Controls
A2: Authoritative FGR-2 controls
A4: Blue cells are controlled planning inputs. They create no article, evidence, payment, capability, production or rendering authority.
A6: Control | B6: Value | C6: Unit | D6: Authority | E6: Meaning
A7: mission systems | B7: 6 | C7: count | D7: FGR-2 | E7: constituted planning boundary
A8: closure accounts | B8: 6 | C8: count | D8: FGR-2 | E8: constituted planning boundary
A9: closure worlds | B9: 4 | C9: count | D9: FGR-2 | E9: constituted planning boundary
A10: closure cells | B10: 144 | C10: count | D10: FGR-2 | E10: constituted planning boundary
A11: packets per root | B11: 8 | C11: count | D11: FGR-2 | E11: constituted planning boundary
A12: packet rows | B12: 48 | C12: count | D12: FGR-2 | E12: constituted planning boundary
A13: public seams | B13: 12 | C13: count | D13: PFP-4 | E13: constituted planning boundary
A14: seam rows | B14: 72 | C14: count | D14: FGR-2 | E14: constituted planning boundary
A15: root authors | B15: 6 | C15: count | D15: FGR-2 | E15: constituted planning boundary
A16: independent challengers | B16: 6 | C16: count | D16: FGR-2 | E16: constituted planning boundary
A17: author-challenge cells | B17: 12 | C17: count | D17: FGR-2 | E17: constituted planning boundary
A18: private option ceiling | B18: 3.5869128 | C18: USD B | D18: A2C-5 | E18: constituted planning boundary
... A37: rendering | B37: 0 | C37: count | D37: HELD | E37: implementation state held

Sheet Alternatives
A2: Internal-architecture sequence hard-gate test
A4: Bounded asynchronous concurrency is selected only if all six roots remain independent, comparable and able to finish inside the branch stop condition.
A6: Sequence | B6: six roots active | C6: separate authors | D6: separate challengers | E6: no common solver | F6: existing seams only | G6: conflict visible | H6: no shared queue | I6: branch budget fit | J6: no root precedent | K6: failure local | L6: money conserved | M6: exterior held | N6: Passes | O6: Eligible | P6: Decision
A7: bounded asynchronous all-six | B7: 1 | C7: 1 | D7: 1 | E7: 1 | F7: 1 | G7: 1 | H7: 1 | I7: 1 | J7: 1 | K7: 1 | L7: 1 | M7: 1 | N7: =SUM(B7:M7) -> 12 | O7: =IF(N7=12,"YES","NO") -> YES | P7: =IF(O7="YES","SELECT","REJECT") -> SELECT
A8: lifeline-first serial | B8: 0 | C8: 1 | D8: 1 | E8: 1 | F8: 1 | G8: 0 | H8: 0 | I8: 0 | J8: 0 | K8: 1 | L8: 1 | M8: 1 | N8: =SUM(B8:M8) -> 7 | O8: =IF(N8=12,"YES","NO") -> NO | P8: =IF(O8="YES","SELECT","REJECT") -> REJECT
A9: lowest-margin-first serial | B9: 0 | C9: 1 | D9: 1 | E9: 1 | F9: 1 | G9: 0 | H9: 0 | I9: 0 | J9: 0 | K9: 1 | L9: 1 | M9: 1 | N9: =SUM(B9:M9) -> 7 | O9: =IF(N9=12,"YES","NO") -> NO | P9: =IF(O9="YES","SELECT","REJECT") -> REJECT
A10: limiting-account waves | B10: 0 | C10: 1 | D10: 1 | E10: 0 | F10: 1 | G10: 1 | H10: 0 | I10: 1 | J10: 0 | K10: 1 | L10: 1 | M10: 1 | N10: =SUM(B10:M10) -> 8 | O10: =IF(N10=12,"YES","NO") -> NO | P10: =IF(O10="YES","SELECT","REJECT") -> REJECT
A11: synchronized all-six lockstep | B11: 1 | C11: 1 | D11: 1 | E11: 1 | F11: 1 | G11: 1 | H11: 0 | I11: 1 | J11: 1 | K11: 0 | L11: 1 | M11: 1 | N11: =SUM(B11:M11) -> 10 | O11: =IF(N11=12,"YES","NO") -> NO | P11: =IF(O11="YES","SELECT","REJECT") -> REJECT
A12: unbounded parallel drafting | B12: 1 | C12: 0 | D12: 0 | E12: 0 | F12: 0 | G12: 0 | H12: 1 | I12: 1 | J12: 1 | K12: 0 | L12: 1 | M12: 1 | N12: =SUM(B12:M12) -> 6 | O12: =IF(N12=12,"YES","NO") -> NO | P12: =IF(O12="YES","SELECT","REJECT") -> REJECT

Sheet Root Lanes
A2: Six isolated root-native architecture lanes
A4: All lanes start together but close on their own clocks. One root cannot lend a model, margin or completion state to another.
A6: System | B6: Root | C6: Article | D6: Limiting account | E6: Causal section | F6: Duration weeks | G6: Start week | H6: Finish week | I6: Option USD B | J6: Maximum FRAME USD B | K6: State
A7: MS-ET | B7: ET-A | C7: Pelagic exchange cell | D7: Route flow | E7: moving-source mass and custody section | F7: 26 | G7: 0 | H7: =F7+G7 -> 26 | I7: 0.50047462 | J7: =I7*Controls!$B$19 -> 0.075071193 | K7: CONCURRENT / HELD
A8: MS-CT | B8: CT-C | C8: Occupied-building utility-spine sector | D8: Energy | E8: occupied-structure reaction and utility section | F8: 28 | G8: 0 | H8: =F8+G8 -> 28 | I8: 0.51649348 | J8: =I8*Controls!$B$19 -> 0.077474022 | K8: CONCURRENT / HELD
A9: MS-HC | B9: HC-A | C9: Atmospheric intervention cell | D9: Route flow | E9: energy-fluid-effect kilometre section | F9: 30 | G9: 0 | H9: =F9+G9 -> 30 | I9: 0.30722165 | J9: =I9*Controls!$B$19 -> 0.046083248 | K9: CONCURRENT / HELD
A10: MS-LF | B10: LF-B | C10: IGT-50 geothermal source position | D10: Energy | E10: reservoir-bore-bus-treatment-injection section | F10: 36 | G10: 0 | H10: =F10+G10 -> 36 | I10: 0.89941282 | J10: =I10*Controls!$B$19 -> 0.13491192 | K10: CONCURRENT / HELD
A11: MS-HU | B11: HU-A | C11: Complete clinical island | D11: Mass | E11: person-care-sterility-relationship section | F11: 32 | G11: 0 | H11: =F11+G11 -> 32 | I11: 0.86071245 | J11: =I11*Controls!$B$19 -> 0.12910687 | K11: CONCURRENT / HELD
A12: MS-RT | B12: RT-B | C12: Disconnected microfactory mesh | D12: Energy | E12: dirty-return-to-qualified-release topology | F12: 30 | G12: 0 | H12: =F12+G12 -> 30 | I12: 0.50259779 | J12: =I12*Controls!$B$19 -> 0.075389669 | K12: CONCURRENT / HELD

Sheet Section Grammar
A2: Six noncompensatory causal-section accounts
A4: The grammar standardizes meaning, not geometry, method, solver, material, controller or drawing template.
A6: Account | B6: Closure account | C6: Required content | D6: Decision form
A7: A01 | B7: Mass and material custody | C7: source, product, consumable, payload and retained hazard | D7: capacity or burden
A8: A02 | B8: Energy and heat | C8: generation, distribution, black start, conversion loss and heat rejection | D8: capacity or burden
A9: A03 | B9: Geometry and load path | C9: working volume, structure, stability, clearances, interfaces and removal direction | D9: capacity or burden
A10: A04 | B10: Safe state and human boundary | C10: detection, isolation, refuge, egress, manual control and civil rights | D10: conjunctive
A11: A05 | B11: Residual and environmental custody | C11: dirty return, brine, runoff, smoke, clinical waste and rejected material | D11: capacity or burden
A12: A06 | B12: Removal and cold reconstruction | C12: disassembly, inspection, replacement, rebuild and ancestry recovery | D12: conjunctive

Sheet Worlds
A2: Four required section worlds
A4: Every account must close separately in every world. Nominal surplus cannot compensate for a denial or reconstruction failure.
A6: World | B6: State | C6: Required condition
A7: W01 | B7: Nominal mission | C7: declared article mission without inserted loss
A8: W02 | B8: Fatal-keystone challenge | C8: principal causal mechanism challenged at full physical scale
A9: W03 | B9: Largest-independent-cell loss | C9: largest independent contributing cell or path removed
A10: W04 | B10: Cold reconstruction | C10: outside team rebuilds from frozen records without origin runtime

Sheet Closure Matrix
A2: One hundred forty-four root-account-world closure cells
A4: Inputs remain source empty. A quantitative closure pass must populate owned bounds and demands without adding decisive host capacity.
A6: Cell | B6: System | C6: Root | D6: Account | E6: Closure account | F6: World | G6: World state | H6: Decision form | I6: Owned quantity | J6: Requirement or limit | K6: Host contribution | L6: Modeled margin | M6: Disposition | N6: Observation | O6: G06 credit
A7: ET-A-A01-W01 | B7: MS-ET | C7: ET-A | D7: A01 | E7: Mass and material custody | F7: W01 | G7: Nominal mission | H7: capacity or burden | I7: SOURCE EMPTY | J7: SOURCE EMPTY | K7: 0 | L7: n.a. | M7: OPEN | N7: SOURCE EMPTY | O7: 0
A8: ET-A-A01-W02 | B8: MS-ET | C8: ET-A | D8: A01 | E8: Mass and material custody | F8: W02 | G8: Fatal-keystone challenge | H8: capacity or burden | I8: SOURCE EMPTY | J8: SOURCE EMPTY | K8: 0 | L8: n.a. | M8: OPEN | N8: SOURCE EMPTY | O8: 0
A9: ET-A-A01-W03 | B9: MS-ET | C9: ET-A | D9: A01 | E9: Mass and material custody | F9: W03 | G9: Largest-independent-cell loss | H9: capacity or burden | I9: SOURCE EMPTY | J9: SOURCE EMPTY | K9: 0 | L9: n.a. | M9: OPEN | N9: SOURCE EMPTY | O9: 0
A10: ET-A-A01-W04 | B10: MS-ET | C10: ET-A | D10: A01 | E10: Mass and material custody | F10: W04 | G10: Cold reconstruction | H10: capacity or burden | I10: SOURCE EMPTY | J10: SOURCE EMPTY | K10: 0 | L10: n.a. | M10: OPEN | N10: SOURCE EMPTY | O10: 0
A11: ET-A-A02-W01 | B11: MS-ET | C11: ET-A | D11: A02 | E11: Energy and heat | F11: W01 | G11: Nominal mission | H11: capacity or burden | I11: SOURCE EMPTY | J11: SOURCE EMPTY | K11: 0 | L11: n.a. | M11: OPEN | N11: SOURCE EMPTY | O11: 0
A12: ET-A-A02-W02 | B12: MS-ET | C12: ET-A | D12: A02 | E12: Energy and heat | F12: W02 | G12: Fatal-keystone challenge | H12: capacity or burden | I12: SOURCE EMPTY | J12: SOURCE EMPTY | K12: 0 | L12: n.a. | M12: OPEN | N12: SOURCE EMPTY | O12: 0
A13: ET-A-A02-W03 | B13: MS-ET | C13: ET-A | D13: A02 | E13: Energy and heat | F13: W03 | G13: Largest-independent-cell loss | H13: capacity or burden | I13: SOURCE EMPTY | J13: SOURCE EMPTY | K13: 0 | L13: n.a. | M13: OPEN | N13: SOURCE EMPTY | O13: 0
A14: ET-A-A02-W04 | B14: MS-ET | C14: ET-A | D14: A02 | E14: Energy and heat | F14: W04 | G14: Cold reconstruction | H14: capacity or burden | I14: SOURCE EMPTY | J14: SOURCE EMPTY | K14: 0 | L14: n.a. | M14: OPEN | N14: SOURCE EMPTY | O14: 0
A15: ET-A-A03-W01 | B15: MS-ET | C15: ET-A | D15: A03 | E15: Geometry and load path | F15: W01 | G15: Nominal mission | H15: capacity or burden | I15: SOURCE EMPTY | J15: SOURCE EMPTY | K15: 0 | L15: n.a. | M15: OPEN | N15: SOURCE EMPTY | O15: 0
A16: ET-A-A03-W02 | B16: MS-ET | C16: ET-A | D16: A03 | E16: Geometry and load path | F16: W02 | G16: Fatal-keystone challenge | H16: capacity or burden | I16: SOURCE EMPTY | J16: SOURCE EMPTY | K16: 0 | L16: n.a. | M16: OPEN | N16: SOURCE EMPTY | O16: 0
A17: ET-A-A03-W03 | B17: MS-ET | C17: ET-A | D17: A03 | E17: Geometry and load path | F17: W03 | G17: Largest-independent-cell loss | H17: capacity or burden | I17: SOURCE EMPTY | J17: SOURCE EMPTY | K17: 0 | L17: n.a. | M17: OPEN | N17: SOURCE EMPTY | O17: 0
A18: ET-A-A03-W04 | B18: MS-ET | C18: ET-A | D18: A03 | E18: Geometry and load path | F18: W04 | G18: Cold reconstruction | H18: capacity or burden | I18: SOURCE EMPTY | J18: SOURCE EMPTY | K18: 0 | L18: n.a. | M18: OPEN | N18: SOURCE EMPTY | O18: 0
... A150: RT-B-A06-W04 | B150: MS-RT | C150: RT-B | D150: A06 | E150: Removal and cold reconstruction | F150: W04 | G150: Cold reconstruction | H150: conjunctive | I150: SOURCE EMPTY | J150: SOURCE EMPTY | K150: 0 | L150: n.a. | M150: OPEN | N150: SOURCE EMPTY | O150: 0

Sheet Section Packets
A2: Forty-eight causal-section dossier packets
A4: Packets may share public field names. They may not share a technical drawing template or candidate runtime.
A6: Packet | B6: System | C6: Root | D6: Type | E6: Required packet | F6: Root-native section | G6: Packet state | H6: Accepted | I6: Result | J6: Common implementation?
A7: ET-A-P01 | B7: MS-ET | C7: ET-A | D7: P01 | E7: Coordinate, boundary and ancestry | F7: moving-source mass and custody section | G7: CONSTITUTED | H7: 0 | I7: OPEN | J7: no common drawing template
A8: ET-A-P02 | B8: MS-ET | C8: ET-A | D8: P02 | E8: Causal path and public denominator | F8: moving-source mass and custody section | G8: CONSTITUTED | H8: 0 | I8: OPEN | J8: no common drawing template
A9: ET-A-P03 | B9: MS-ET | C9: ET-A | D9: P03 | E9: Conserved state and mass packets | F9: moving-source mass and custody section | G9: CONSTITUTED | H9: 0 | I9: OPEN | J9: no common drawing template
A10: ET-A-P04 | B10: MS-ET | C10: ET-A | D10: P04 | E10: Geometry, volume, clearance and load path | F10: moving-source mass and custody section | G10: CONSTITUTED | H10: 0 | I10: OPEN | J10: no common drawing template
A11: ET-A-P05 | B11: MS-ET | C11: ET-A | D11: P05 | E11: Energy, heat and working medium | F11: moving-source mass and custody section | G11: CONSTITUTED | H11: 0 | I11: OPEN | J11: no common drawing template
A12: ET-A-P06 | B12: MS-ET | C12: ET-A | D12: P06 | E12: Human access, safe state and residual custody | F12: moving-source mass and custody section | G12: CONSTITUTED | H12: 0 | I12: OPEN | J12: no common drawing template
A13: ET-A-P07 | B13: MS-ET | C13: ET-A | D13: P07 | E13: Removal, replacement and cold reconstruction | F13: moving-source mass and custody section | G13: CONSTITUTED | H13: 0 | I13: OPEN | J13: no common drawing template
A14: ET-A-P08 | B14: MS-ET | C14: ET-A | D14: P08 | E14: Uncertainty, change and independent challenge | F14: moving-source mass and custody section | G14: CONSTITUTED | H14: 0 | I14: OPEN | J14: no common drawing template
A15: CT-C-P01 | B15: MS-CT | C15: CT-C | D15: P01 | E15: Coordinate, boundary and ancestry | F15: occupied-structure reaction and utility section | G15: CONSTITUTED | H15: 0 | I15: OPEN | J15: no common drawing template
A16: CT-C-P02 | B16: MS-CT | C16: CT-C | D16: P02 | E16: Causal path and public denominator | F16: occupied-structure reaction and utility section | G16: CONSTITUTED | H16: 0 | I16: OPEN | J16: no common drawing template
A17: CT-C-P03 | B17: MS-CT | C17: CT-C | D17: P03 | E17: Conserved state and mass packets | F17: occupied-structure reaction and utility section | G17: CONSTITUTED | H17: 0 | I17: OPEN | J17: no common drawing template
A18: CT-C-P04 | B18: MS-CT | C18: CT-C | D18: P04 | E18: Geometry, volume, clearance and load path | F18: occupied-structure reaction and utility section | G18: CONSTITUTED | H18: 0 | I18: OPEN | J18: no common drawing template
... A54: RT-B-P08 | B54: MS-RT | C54: RT-B | D54: P08 | E54: Uncertainty, change and independent challenge | F54: dirty-return-to-qualified-release topology | G54: CONSTITUTED | H54: 0 | I54: OPEN | J54: no common drawing template

Sheet Public Seams
A2: Seventy-two root-to-public seam declarations
A4: The twelve inherited seams carry comparable meaning only. A seam registrar cannot choose geometry, control, safeing or reconstruction.
A6: Record | B6: System | C6: Root | D6: Public seam | E6: Shared content | F6: Implementation | G6: Common runtime | H6: State | I6: Accepted | J6: Boundary
A7: ET-A-S01 | B7: MS-ET | C7: ET-A | D7: public denominator | E7: public meaning only | F7: root-native | G7: PROHIBITED | H7: FROZEN | I7: 0 | J7: no technical solution transferred
A8: ET-A-S02 | B8: MS-ET | C8: ET-A | D8: service clock | E8: public meaning only | F8: root-native | G8: PROHIBITED | H8: FROZEN | I8: 0 | J8: no technical solution transferred
A9: ET-A-S03 | B9: MS-ET | C9: ET-A | D9: mass identity | E9: public meaning only | F9: root-native | G9: PROHIBITED | H9: FROZEN | I9: 0 | J9: no technical solution transferred
A10: ET-A-S04 | B10: MS-ET | C10: ET-A | D10: energy identity | E10: public meaning only | F10: root-native | G10: PROHIBITED | H10: FROZEN | I10: 0 | J10: no technical solution transferred
A11: ET-A-S05 | B11: MS-ET | C11: ET-A | D11: working-medium identity | E11: public meaning only | F11: root-native | G11: PROHIBITED | H11: FROZEN | I11: 0 | J11: no technical solution transferred
A12: ET-A-S06 | B12: MS-ET | C12: ET-A | D12: receiver state | E12: public meaning only | F12: root-native | G12: PROHIBITED | H12: FROZEN | I12: 0 | J12: no technical solution transferred
A13: ET-A-S07 | B13: MS-ET | C13: ET-A | D13: rights status | E13: public meaning only | F13: root-native | G13: PROHIBITED | H13: FROZEN | I13: 0 | J13: no technical solution transferred
A14: ET-A-S08 | B14: MS-ET | C14: ET-A | D14: safe-state status | E14: public meaning only | F14: root-native | G14: PROHIBITED | H14: FROZEN | I14: 0 | J14: no technical solution transferred
A15: ET-A-S09 | B15: MS-ET | C15: ET-A | D15: residual custody | E15: public meaning only | F15: root-native | G15: PROHIBITED | H15: FROZEN | I15: 0 | J15: no technical solution transferred
A16: ET-A-S10 | B16: MS-ET | C16: ET-A | D16: evidence clock | E16: public meaning only | F16: root-native | G16: PROHIBITED | H16: FROZEN | I16: 0 | J16: no technical solution transferred
A17: ET-A-S11 | B17: MS-ET | C17: ET-A | D17: configuration ancestry | E17: public meaning only | F17: root-native | G17: PROHIBITED | H17: FROZEN | I17: 0 | J17: no technical solution transferred
A18: ET-A-S12 | B18: MS-ET | C18: ET-A | D18: reconstruction result | E18: public meaning only | F18: root-native | G18: PROHIBITED | H18: FROZEN | I18: 0 | J18: no technical solution transferred
... A78: RT-B-S12 | B78: MS-RT | C78: RT-B | D78: reconstruction result | E78: public meaning only | F78: root-native | G78: PROHIBITED | H78: FROZEN | I78: 0 | J78: no technical solution transferred

Sheet Concurrency Schedule
A2: Twenty-four asynchronous planning phases
A4: Durations are controlled planning assumptions. Each root advances locally; there is no portfolio lockstep gate.
A6: Record | B6: System | C6: Root | D6: Order | E6: Phase | F6: Start week | G6: Duration weeks | H6: Finish week | I6: Execution | J6: State | L6: Calendar comparison | M6: Weeks
A7: ET-A-Q1 | B7: MS-ET | C7: ET-A | D7: 1 | E7: boundary freeze | F7: 0 | G7: 4 | H7: =F7+G7 -> 4 | I7: root-native | J7: PLANNING | L7: serial queue | M7: =SUM('Root Lanes'!F7:F12) -> 182
A8: ET-A-Q2 | B8: MS-ET | C8: ET-A | D8: 2 | E8: internal tensor build | F8: =H7 -> 4 | G8: 12 | H8: =F8+G8 -> 16 | I8: root-native | J8: PLANNING | L8: bounded asynchronous | M8: =MAX('Root Lanes'!H7:H12) -> 36
A9: ET-A-Q3 | B9: MS-ET | C9: ET-A | D9: 3 | E9: independent challenge | F9: =H8 -> 16 | G9: 6 | H9: =F9+G9 -> 22 | I9: root-native | J9: PLANNING | L9: calendar reduction | M9: =1-M8/M7 -> 0.8021978
A10: ET-A-Q4 | B10: MS-ET | C10: ET-A | D10: 4 | E10: public seam return | F10: =H9 -> 22 | G10: 4 | H10: =F10+G10 -> 26 | I10: root-native | J10: PLANNING
A11: CT-C-Q1 | B11: MS-CT | C11: CT-C | D11: 1 | E11: boundary freeze | F11: 0 | G11: 4 | H11: =F11+G11 -> 4 | I11: root-native | J11: PLANNING
A12: CT-C-Q2 | B12: MS-CT | C12: CT-C | D12: 2 | E12: internal tensor build | F12: =H11 -> 4 | G12: 13 | H12: =F12+G12 -> 17 | I12: root-native | J12: PLANNING
A13: CT-C-Q3 | B13: MS-CT | C13: CT-C | D13: 3 | E13: independent challenge | F13: =H12 -> 17 | G13: 7 | H13: =F13+G13 -> 24 | I13: root-native | J13: PLANNING
A14: CT-C-Q4 | B14: MS-CT | C14: CT-C | D14: 4 | E14: public seam return | F14: =H13 -> 24 | G14: 4 | H14: =F14+G14 -> 28 | I14: root-native | J14: PLANNING
A15: HC-A-Q1 | B15: MS-HC | C15: HC-A | D15: 1 | E15: boundary freeze | F15: 0 | G15: 4 | H15: =F15+G15 -> 4 | I15: root-native | J15: PLANNING
A16: HC-A-Q2 | B16: MS-HC | C16: HC-A | D16: 2 | E16: internal tensor build | F16: =H15 -> 4 | G16: 14 | H16: =F16+G16 -> 18 | I16: root-native | J16: PLANNING
A17: HC-A-Q3 | B17: MS-HC | C17: HC-A | D17: 3 | E17: independent challenge | F17: =H16 -> 18 | G17: 8 | H17: =F17+G17 -> 26 | I17: root-native | J17: PLANNING
A18: HC-A-Q4 | B18: MS-HC | C18: HC-A | D18: 4 | E18: public seam return | F18: =H17 -> 26 | G18: 4 | H18: =F18+G18 -> 30 | I18: root-native | J18: PLANNING
A19: LF-B-Q1 | B19: MS-LF | C19: LF-B | D19: 1 | E19: boundary freeze | F19: 0 | G19: 5 | H19: =F19+G19 -> 5 | I19: root-native | J19: PLANNING
A20: LF-B-Q2 | B20: MS-LF | C20: LF-B | D20: 2 | E20: internal tensor build | F20: =H19 -> 5 | G20: 17 | H20: =F20+G20 -> 22 | I20: root-native | J20: PLANNING
A21: LF-B-Q3 | B21: MS-LF | C21: LF-B | D21: 3 | E21: independent challenge | F21: =H20 -> 22 | G21: 9 | H21: =F21+G21 -> 31 | I21: root-native | J21: PLANNING
A22: LF-B-Q4 | B22: MS-LF | C22: LF-B | D22: 4 | E22: public seam return | F22: =H21 -> 31 | G22: 5 | H22: =F22+G22 -> 36 | I22: root-native | J22: PLANNING
A23: HU-A-Q1 | B23: MS-HU | C23: HU-A | D23: 1 | E23: boundary freeze | F23: 0 | G23: 5 | H23: =F23+G23 -> 5 | I23: root-native | J23: PLANNING
A24: HU-A-Q2 | B24: MS-HU | C24: HU-A | D24: 2 | E24: internal tensor build | F24: =H23 -> 5 | G24: 15 | H24: =F24+G24 -> 20 | I24: root-native | J24: PLANNING
A25: HU-A-Q3 | B25: MS-HU | C25: HU-A | D25: 3 | E25: independent challenge | F25: =H24 -> 20 | G25: 8 | H25: =F25+G25 -> 28 | I25: root-native | J25: PLANNING
A26: HU-A-Q4 | B26: MS-HU | C26: HU-A | D26: 4 | E26: public seam return | F26: =H25 -> 28 | G26: 4 | H26: =F26+G26 -> 32 | I26: root-native | J26: PLANNING
A27: RT-B-Q1 | B27: MS-RT | C27: RT-B | D27: 1 | E27: boundary freeze | F27: 0 | G27: 4 | H27: =F27+G27 -> 4 | I27: root-native | J27: PLANNING
A28: RT-B-Q2 | B28: MS-RT | C28: RT-B | D28: 2 | E28: internal tensor build | F28: =H27 -> 4 | G28: 14 | H28: =F28+G28 -> 18 | I28: root-native | J28: PLANNING
A29: RT-B-Q3 | B29: MS-RT | C29: RT-B | D29: 3 | E29: independent challenge | F29: =H28 -> 18 | G29: 8 | H29: =F29+G29 -> 26 | I29: root-native | J29: PLANNING
A30: RT-B-Q4 | B30: MS-RT | C30: RT-B | D30: 4 | E30: public seam return | F30: =H29 -> 26 | G30: 4 | H30: =F30+G30 -> 30 | I30: root-native | J30: PLANNING

Sheet Workforce Separation
A2: Twelve public author and challenge cells
A4: A person or beneficial-control group may not author and independently challenge the same root. Identities remain source empty.
A6: Cell | B6: System | C6: Root | D6: Role | E6: Author credit | F6: Challenge credit | G6: Cross-root decisive control | H6: Identity | I6: Restriction
A7: ET-A-AUTHOR | B7: MS-ET | C7: ET-A | D7: root-native author | E7: 1 | F7: 0 | G7: 0 | H7: SOURCE EMPTY | I7: may not challenge own root
A8: ET-A-CHALLENGE | B8: MS-ET | C8: ET-A | D8: independent challenger | E8: 0 | F8: 1 | G8: 0 | H8: SOURCE EMPTY | I8: may not author root model
A9: CT-C-AUTHOR | B9: MS-CT | C9: CT-C | D9: root-native author | E9: 1 | F9: 0 | G9: 0 | H9: SOURCE EMPTY | I9: may not challenge own root
A10: CT-C-CHALLENGE | B10: MS-CT | C10: CT-C | D10: independent challenger | E10: 0 | F10: 1 | G10: 0 | H10: SOURCE EMPTY | I10: may not author root model
A11: HC-A-AUTHOR | B11: MS-HC | C11: HC-A | D11: root-native author | E11: 1 | F11: 0 | G11: 0 | H11: SOURCE EMPTY | I11: may not challenge own root
A12: HC-A-CHALLENGE | B12: MS-HC | C12: HC-A | D12: independent challenger | E12: 0 | F12: 1 | G12: 0 | H12: SOURCE EMPTY | I12: may not author root model
A13: LF-B-AUTHOR | B13: MS-LF | C13: LF-B | D13: root-native author | E13: 1 | F13: 0 | G13: 0 | H13: SOURCE EMPTY | I13: may not challenge own root
A14: LF-B-CHALLENGE | B14: MS-LF | C14: LF-B | D14: independent challenger | E14: 0 | F14: 1 | G14: 0 | H14: SOURCE EMPTY | I14: may not author root model
A15: HU-A-AUTHOR | B15: MS-HU | C15: HU-A | D15: root-native author | E15: 1 | F15: 0 | G15: 0 | H15: SOURCE EMPTY | I15: may not challenge own root
A16: HU-A-CHALLENGE | B16: MS-HU | C16: HU-A | D16: independent challenger | E16: 0 | F16: 1 | G16: 0 | H16: SOURCE EMPTY | I16: may not author root model
A17: RT-B-AUTHOR | B17: MS-RT | C17: RT-B | D17: root-native author | E17: 1 | F17: 0 | G17: 0 | H17: SOURCE EMPTY | I17: may not challenge own root
A18: RT-B-CHALLENGE | B18: MS-RT | C18: RT-B | D18: independent challenger | E18: 0 | F18: 1 | G18: 0 | H18: SOURCE EMPTY | I18: may not author root model

Sheet Finance
A2: Candidate authority under concurrent section closure
A4: Concurrency changes peak eligible FRAME exposure and calendar, not the USD 3.59B option ceiling. No amount is awarded, obligated or paid.
A6: System | B6: Root | C6: Article | D6: Option USD B | E6: FRAME share | F6: Maximum FRAME USD B | G6: Held share | H6: Held authority USD B | I6: Accepted USD B | J6: Paid USD B | K6: State
A7: MS-ET | B7: ET-A | C7: Pelagic exchange cell | D7: 0.50047462 | E7: =Controls!$B$19 -> 0.15 | F7: =D7*E7 -> 0.075071193 | G7: =Controls!$B$21 -> 0.85 | H7: =D7*G7 -> 0.42540343 | I7: 0 | J7: 0 | K7: HELD
A8: MS-CT | B8: CT-C | C8: Occupied-building utility-spine sector | D8: 0.51649348 | E8: =Controls!$B$19 -> 0.15 | F8: =D8*E8 -> 0.077474022 | G8: =Controls!$B$21 -> 0.85 | H8: =D8*G8 -> 0.43901946 | I8: 0 | J8: 0 | K8: HELD
A9: MS-HC | B9: HC-A | C9: Atmospheric intervention cell | D9: 0.30722165 | E9: =Controls!$B$19 -> 0.15 | F9: =D9*E9 -> 0.046083248 | G9: =Controls!$B$21 -> 0.85 | H9: =D9*G9 -> 0.26113841 | I9: 0 | J9: 0 | K9: HELD
A10: MS-LF | B10: LF-B | C10: IGT-50 geothermal source position | D10: 0.89941282 | E10: =Controls!$B$19 -> 0.15 | F10: =D10*E10 -> 0.13491192 | G10: =Controls!$B$21 -> 0.85 | H10: =D10*G10 -> 0.7645009 | I10: 0 | J10: 0 | K10: HELD
A11: MS-HU | B11: HU-A | C11: Complete clinical island | D11: 0.86071245 | E11: =Controls!$B$19 -> 0.15 | F11: =D11*E11 -> 0.12910687 | G11: =Controls!$B$21 -> 0.85 | H11: =D11*G11 -> 0.73160558 | I11: 0 | J11: 0 | K11: HELD
A12: MS-RT | B12: RT-B | C12: Disconnected microfactory mesh | D12: 0.50259779 | E12: =Controls!$B$19 -> 0.15 | F12: =D12*E12 -> 0.075389669 | G12: =Controls!$B$21 -> 0.85 | H12: =D12*G12 -> 0.42720812 | I12: 0 | J12: 0 | K12: HELD
A13: TOTAL | B13: six roots | C13: all causal-section lanes | D13: =SUM(D7:D12) -> 3.5869128 | F13: =SUM(F7:F12) -> 0.53803692 | H13: =SUM(H7:H12) -> 3.0488759 | I13: =SUM(I7:I12) -> 0 | J13: =SUM(J7:J12) -> 0 | K13: HELD

Sheet FRAME Allocation
A2: Thirty cross-classified FRAME work views
A4: Work views divide the inherited FRAME ceiling once. They do not create a second budget or authorize payment.
A6: System | B6: Root | C6: Work view | D6: Share | E6: Root FRAME ceiling USD B | F6: Work-view ceiling USD B | G6: Accepted USD B | H6: State
A7: MS-ET | B7: ET-A | C7: mass and geometry | D7: 0.3 | E7: =Finance!F7 -> 0.075071193 | F7: =D7*E7 -> 0.022521358 | G7: 0 | H7: HELD
A8: MS-ET | B8: ET-A | C8: energy and working medium | D8: 0.25 | E8: =Finance!F7 -> 0.075071193 | F8: =D8*E8 -> 0.018767798 | G8: 0 | H8: HELD
A9: MS-ET | B9: ET-A | C9: safe state and residual | D9: 0.2 | E9: =Finance!F7 -> 0.075071193 | F9: =D9*E9 -> 0.015014239 | G9: 0 | H9: HELD
A10: MS-ET | B10: ET-A | C10: reconstruction and ancestry | D10: 0.15 | E10: =Finance!F7 -> 0.075071193 | F10: =D10*E10 -> 0.011260679 | G10: 0 | H10: HELD
A11: MS-ET | B11: ET-A | C11: public-seam challenge | D11: 0.1 | E11: =Finance!F7 -> 0.075071193 | F11: =D11*E11 -> 0.0075071193 | G11: 0 | H11: HELD
A12: MS-CT | B12: CT-C | C12: mass and geometry | D12: 0.3 | E12: =Finance!F8 -> 0.077474022 | F12: =D12*E12 -> 0.023242207 | G12: 0 | H12: HELD
A13: MS-CT | B13: CT-C | C13: energy and working medium | D13: 0.25 | E13: =Finance!F8 -> 0.077474022 | F13: =D13*E13 -> 0.019368506 | G13: 0 | H13: HELD
A14: MS-CT | B14: CT-C | C14: safe state and residual | D14: 0.2 | E14: =Finance!F8 -> 0.077474022 | F14: =D14*E14 -> 0.015494804 | G14: 0 | H14: HELD
A15: MS-CT | B15: CT-C | C15: reconstruction and ancestry | D15: 0.15 | E15: =Finance!F8 -> 0.077474022 | F15: =D15*E15 -> 0.011621103 | G15: 0 | H15: HELD
A16: MS-CT | B16: CT-C | C16: public-seam challenge | D16: 0.1 | E16: =Finance!F8 -> 0.077474022 | F16: =D16*E16 -> 0.0077474022 | G16: 0 | H16: HELD
A17: MS-HC | B17: HC-A | C17: mass and geometry | D17: 0.3 | E17: =Finance!F9 -> 0.046083248 | F17: =D17*E17 -> 0.013824974 | G17: 0 | H17: HELD
A18: MS-HC | B18: HC-A | C18: energy and working medium | D18: 0.25 | E18: =Finance!F9 -> 0.046083248 | F18: =D18*E18 -> 0.011520812 | G18: 0 | H18: HELD
A19: MS-HC | B19: HC-A | C19: safe state and residual | D19: 0.2 | E19: =Finance!F9 -> 0.046083248 | F19: =D19*E19 -> 0.0092166496 | G19: 0 | H19: HELD
A20: MS-HC | B20: HC-A | C20: reconstruction and ancestry | D20: 0.15 | E20: =Finance!F9 -> 0.046083248 | F20: =D20*E20 -> 0.0069124872 | G20: 0 | H20: HELD
A21: MS-HC | B21: HC-A | C21: public-seam challenge | D21: 0.1 | E21: =Finance!F9 -> 0.046083248 | F21: =D21*E21 -> 0.0046083248 | G21: 0 | H21: HELD
A22: MS-LF | B22: LF-B | C22: mass and geometry | D22: 0.3 | E22: =Finance!F10 -> 0.13491192 | F22: =D22*E22 -> 0.040473577 | G22: 0 | H22: HELD
A23: MS-LF | B23: LF-B | C23: energy and working medium | D23: 0.25 | E23: =Finance!F10 -> 0.13491192 | F23: =D23*E23 -> 0.033727981 | G23: 0 | H23: HELD
A24: MS-LF | B24: LF-B | C24: safe state and residual | D24: 0.2 | E24: =Finance!F10 -> 0.13491192 | F24: =D24*E24 -> 0.026982385 | G24: 0 | H24: HELD
A25: MS-LF | B25: LF-B | C25: reconstruction and ancestry | D25: 0.15 | E25: =Finance!F10 -> 0.13491192 | F25: =D25*E25 -> 0.020236788 | G25: 0 | H25: HELD
A26: MS-LF | B26: LF-B | C26: public-seam challenge | D26: 0.1 | E26: =Finance!F10 -> 0.13491192 | F26: =D26*E26 -> 0.013491192 | G26: 0 | H26: HELD
A27: MS-HU | B27: HU-A | C27: mass and geometry | D27: 0.3 | E27: =Finance!F11 -> 0.12910687 | F27: =D27*E27 -> 0.03873206 | G27: 0 | H27: HELD
A28: MS-HU | B28: HU-A | C28: energy and working medium | D28: 0.25 | E28: =Finance!F11 -> 0.12910687 | F28: =D28*E28 -> 0.032276717 | G28: 0 | H28: HELD
A29: MS-HU | B29: HU-A | C29: safe state and residual | D29: 0.2 | E29: =Finance!F11 -> 0.12910687 | F29: =D29*E29 -> 0.025821374 | G29: 0 | H29: HELD
A30: MS-HU | B30: HU-A | C30: reconstruction and ancestry | D30: 0.15 | E30: =Finance!F11 -> 0.12910687 | F30: =D30*E30 -> 0.01936603 | G30: 0 | H30: HELD
A31: MS-HU | B31: HU-A | C31: public-seam challenge | D31: 0.1 | E31: =Finance!F11 -> 0.12910687 | F31: =D31*E31 -> 0.012910687 | G31: 0 | H31: HELD
A32: MS-RT | B32: RT-B | C32: mass and geometry | D32: 0.3 | E32: =Finance!F12 -> 0.075389669 | F32: =D32*E32 -> 0.022616901 | G32: 0 | H32: HELD
A33: MS-RT | B33: RT-B | C33: energy and working medium | D33: 0.25 | E33: =Finance!F12 -> 0.075389669 | F33: =D33*E33 -> 0.018847417 | G33: 0 | H33: HELD
A34: MS-RT | B34: RT-B | C34: safe state and residual | D34: 0.2 | E34: =Finance!F12 -> 0.075389669 | F34: =D34*E34 -> 0.015077934 | G34: 0 | H34: HELD
A35: MS-RT | B35: RT-B | C35: reconstruction and ancestry | D35: 0.15 | E35: =Finance!F12 -> 0.075389669 | F35: =D35*E35 -> 0.01130845 | G35: 0 | H35: HELD
A36: MS-RT | B36: RT-B | C36: public-seam challenge | D36: 0.1 | E36: =Finance!F12 -> 0.075389669 | F36: =D36*E36 -> 0.0075389669 | G36: 0 | H36: HELD

Sheet Release Gates
A2: Seventy-two inherited requirement-to-architecture gates
A4: The causal-section grammar does not close G06. Quantitative margins, safety, ancestry, build, event and reconstruction evidence remain absent.
A6: Gate | B6: System | C6: Root | D6: Order | E6: Gate claim | F6: State | G6: Authority basis | H6: Requirement closed | I6: Evidence accepted | J6: This pass effect | K6: Exterior authority
A7: ET-A-G01 | B7: MS-ET | C7: ET-A | D7: 1 | E7: denominator | F7: CONSTITUTED | G7: FGR-1 | H7: 1 | I7: 0 | J7: NEXT GATE | K7: n.a.
A8: ET-A-G02 | B8: MS-ET | C8: ET-A | D8: 2 | E8: article boundary | F8: CONSTITUTED | G8: FGR-1 | H8: 1 | I8: 0 | J8: NEXT GATE | K8: n.a.
A9: ET-A-G03 | B9: MS-ET | C9: ET-A | D9: 3 | E9: form loads | F9: CONSTITUTED | G9: FGR-1 | H9: 1 | I9: 0 | J9: NEXT GATE | K9: n.a.
A10: ET-A-G04 | B10: MS-ET | C10: ET-A | D10: 4 | E10: interfaces | F10: CONSTITUTED | G10: FGR-1 | H10: 1 | I10: 0 | J10: NEXT GATE | K10: n.a.
A11: ET-A-G05 | B11: MS-ET | C11: ET-A | D11: 5 | E11: denial set | F11: CONSTITUTED | G11: FGR-1 | H11: 1 | I11: 0 | J11: NEXT GATE | K11: n.a.
A12: ET-A-G06 | B12: MS-ET | C12: ET-A | D12: 6 | E12: paper closure | F12: OPEN | G12: grammar constituted; quantitative margin absent | H12: 0 | I12: 0 | J12: GRAMMAR ONLY | K12: n.a.
A13: ET-A-G07 | B13: MS-ET | C13: ET-A | D13: 7 | E13: safety and rights | F13: OPEN | G13: future source record | H13: 0 | I13: 0 | J13: NEXT GATE | K13: n.a.
A14: ET-A-G08 | B14: MS-ET | C14: ET-A | D14: 8 | E14: ancestry | F14: OPEN | G14: future source record | H14: 0 | I14: 0 | J14: NEXT GATE | K14: n.a.
A15: ET-A-G09 | B15: MS-ET | C15: ET-A | D15: 9 | E15: executable build record | F15: OPEN | G15: future source record | H15: 0 | I15: 0 | J15: NEXT GATE | K15: n.a.
A16: ET-A-G10 | B16: MS-ET | C16: ET-A | D16: 10 | E16: representative event | F16: OPEN | G16: future source record | H16: 0 | I16: 0 | J16: NEXT GATE | K16: n.a.
A17: ET-A-G11 | B17: MS-ET | C17: ET-A | D17: 11 | E17: cold reconstruction | F17: OPEN | G17: future source record | H17: 0 | I17: 0 | J17: NEXT GATE | K17: n.a.
A18: ET-A-G12 | B18: MS-ET | C18: ET-A | D18: 12 | E18: architecture warrant | F18: OPEN | G18: future source record | H18: 0 | I18: 0 | J18: INTERNAL ARCHITECTURE ONLY | K18: HELD
... A78: RT-B-G12 | B78: MS-RT | C78: RT-B | D78: 12 | E78: architecture warrant | F78: OPEN | G78: future source record | H78: 0 | I78: 0 | J78: INTERNAL ARCHITECTURE ONLY | K78: HELD

Sheet Nonconversions
A2: Twenty prohibited causal-section conversions
A4: These are hard type boundaries. Crossing one invalidates the claimed downstream state.
A6: Rule | B6: From | C6: Must not become | D6: Reason
A7: N01 | B7: causal-section grammar | C7: common geometric drawing | D7: shared meaning cannot select common form
A8: N02 | B8: public seam | C8: technical interface implementation | D8: a registrar cannot design a root
A9: N03 | B9: parallel start | C9: common program control | D9: simultaneous work does not create one owner
A10: N04 | B10: root finish | C10: portfolio completion | D10: one dossier cannot release five others
A11: N05 | B11: longest duration | C11: portfolio authority | D11: the slowest lane cannot command the rest
A12: N06 | B12: paper duration | C12: schedule fact | D12: planning weeks are not observed performance
A13: N07 | B13: FRAME ceiling | C13: award or obligation | D13: eligible exposure is not a fiscal transaction
A14: N08 | B14: accepted packet | C14: physical evidence | D14: paper acceptance cannot prove hardware
A15: N09 | B15: owned quantity blank | C15: zero burden | D15: missing input cannot become favorable closure
A16: N10 | B16: host contribution zero | C16: proved independence | D16: a declared zero still requires evidence
A17: N11 | B17: modeled margin | C17: observed performance | D17: calculation is not a representative event
... A26: N20 | B26: all-six paper closure | C26: force readiness | D26: complete-root proof still governs capability

Sheet Stress Tests
A2: Sixteen concurrency and closure stress cases
A4: The constitution must keep parallel learning from becoming shared technical control or premature evidence.
A6: ID | B6: Disturbance | C6: Required response | D6: Forbidden conversion | E6: Disposition | F6: State
A7: S01 | B7: LF-B asks to define the energy template | C7: retain six root-native energy maps | D7: root precedent | E7: RETURN | F7: PASS
A8: S02 | B8: one author serves two decisive roots | C8: split authorship before work | D8: shared ancestry | E8: INVALID | F8: PASS
A9: S03 | B9: challenger helped author same root | C9: replace challenger and replay review | D9: self-certification | E9: INVALID | F9: PASS
A10: S04 | B10: root finishes before siblings | C10: hold portfolio claim; retain local packet | D10: finish to portfolio completion | E10: HOLD | F10: PASS
A11: S05 | B11: root exceeds planned duration | C11: continue local review without lockstep | D11: slowest root to command | E11: HOLD | F11: PASS
A12: S06 | B12: public seam exposes incompatible units | C12: return both mappings without selecting method | D12: registrar to designer | E12: RETURN | F12: PASS
A13: S07 | B13: host capacity closes negative margin | C13: remove host contribution or enlarge article | D13: borrowed support to closure | E13: RESIZE | F13: PASS
A14: S08 | B14: interval crosses zero | C14: retain indeterminate state | D14: uncertainty to pass | E14: HOLD | F14: PASS
A15: S09 | B15: fatal keystone fails validly | C15: kill root claim | D15: adverse result to schedule delay | E15: KILL | F15: PASS
A16: S10 | B16: nominal case offsets denial failure | C16: reject compensation | D16: average to closure | E16: RESIZE | F16: PASS
A17: S11 | B17: one packet accepted | C17: release only that packet state | D17: paper to evidence | E17: HOLD | F17: PASS
... A22: S16 | B22: exterior depiction requested | C22: require later form warrant | D22: internal section to rendering | E22: HELD | F22: PASS

Sheet Mutations
A2: Live mutation and restoration log
A4: Each mutation changes one authoritative control, trips at least one terminal audit and restores the passing baseline before export.
A6: ID | B6: Control cell | C6: Baseline | D6: Mutated | E6: Audit failures | F6: Mutation detected | G6: Baseline restored
A7: M01 | B7: Controls!B7 | C7: 6 | D7: 5 | E7: 1 | F7: YES | G7: YES
A8: M02 | B8: Controls!B8 | C8: 6 | D8: 5 | E8: 1 | F8: YES | G8: YES
A9: M03 | B9: Controls!B9 | C9: 4 | D9: 3 | E9: 1 | F9: YES | G9: YES
A10: M04 | B10: Controls!B10 | C10: 144 | D10: 143 | E10: 1 | F10: YES | G10: YES
A11: M05 | B11: Controls!B11 | C11: 8 | D11: 7 | E11: 1 | F11: YES | G11: YES
A12: M06 | B12: Controls!B12 | C12: 48 | D12: 47 | E12: 1 | F12: YES | G12: YES
A13: M07 | B13: Controls!B13 | C13: 12 | D13: 11 | E13: 1 | F13: YES | G13: YES
A14: M08 | B14: Controls!B14 | C14: 72 | D14: 71 | E14: 1 | F14: YES | G14: YES
A15: M09 | B15: Controls!B15 | C15: 6 | D15: 5 | E15: 1 | F15: YES | G15: YES
A16: M10 | B16: Controls!B16 | C16: 6 | D16: 5 | E16: 1 | F16: YES | G16: YES
A17: M11 | B17: Controls!B17 | C17: 12 | D17: 11 | E17: 1 | F17: YES | G17: YES
A18: M12 | B18: Controls!B18 | C18: 3.5869128 | D18: 4 | E18: 1 | F18: YES | G18: YES
... A26: M20 | B26: Controls!B37 | C26: 0 | D26: 1 | E26: 1 | F26: YES | G26: YES

Sheet Audit
A2: Terminal concurrent-section audit
A4: Passing checks prove internal conservation and source-empty boundaries only. They create no physical closure, payment, capability, production or rendering authority.
A6: Audit | B6: Observed | C6: Expected | D6: Difference | E6: State
A7: control: mission systems | B7: =Controls!B7 -> 6 | C7: 6 | D7: =B7-C7 -> 0 | E7: =IF(ABS(D7)<0.000001,"PASS","FAIL") -> PASS
A8: control: closure accounts | B8: =Controls!B8 -> 6 | C8: 6 | D8: =B8-C8 -> 0 | E8: =IF(ABS(D8)<0.000001,"PASS","FAIL") -> PASS
A9: control: closure worlds | B9: =Controls!B9 -> 4 | C9: 4 | D9: =B9-C9 -> 0 | E9: =IF(ABS(D9)<0.000001,"PASS","FAIL") -> PASS
A10: control: closure cells | B10: =Controls!B10 -> 144 | C10: 144 | D10: =B10-C10 -> 0 | E10: =IF(ABS(D10)<0.000001,"PASS","FAIL") -> PASS
A11: control: packets per root | B11: =Controls!B11 -> 8 | C11: 8 | D11: =B11-C11 -> 0 | E11: =IF(ABS(D11)<0.000001,"PASS","FAIL") -> PASS
A12: control: packet rows | B12: =Controls!B12 -> 48 | C12: 48 | D12: =B12-C12 -> 0 | E12: =IF(ABS(D12)<0.000001,"PASS","FAIL") -> PASS
A13: control: public seams | B13: =Controls!B13 -> 12 | C13: 12 | D13: =B13-C13 -> 0 | E13: =IF(ABS(D13)<0.000001,"PASS","FAIL") -> PASS
A14: control: seam rows | B14: =Controls!B14 -> 72 | C14: 72 | D14: =B14-C14 -> 0 | E14: =IF(ABS(D14)<0.000001,"PASS","FAIL") -> PASS
A15: control: root authors | B15: =Controls!B15 -> 6 | C15: 6 | D15: =B15-C15 -> 0 | E15: =IF(ABS(D15)<0.000001,"PASS","FAIL") -> PASS
A16: control: independent challengers | B16: =Controls!B16 -> 6 | C16: 6 | D16: =B16-C16 -> 0 | E16: =IF(ABS(D16)<0.000001,"PASS","FAIL") -> PASS
A17: control: author-challenge cells | B17: =Controls!B17 -> 12 | C17: 12 | D17: =B17-C17 -> 0 | E17: =IF(ABS(D17)<0.000001,"PASS","FAIL") -> PASS
A18: control: private option ceiling | B18: =Controls!B18 -> 3.5869128 | C18: 3.5869128 | D18: =B18-C18 -> 0 | E18: =IF(ABS(D18)<0.000001,"PASS","FAIL") -> PASS
... A37: control: rendering | B37: =Controls!B37 -> 0 | C37: 0 | D37: =B37-C37 -> 0 | E37: =IF(ABS(D37)<0.000001,"PASS","FAIL") -> PASS
A38: selected sequence | B38: =COUNTIFS(Alternatives!P7:P12,"SELECT") -> 1 | C38: 1 | D38: =B38-C38 -> 0 | E38: =IF(ABS(D38)<0.000001,"PASS","FAIL") -> PASS
A39: rejected sequences | B39: =COUNTIFS(Alternatives!P7:P12,"REJECT") -> 5 | C39: 5 | D39: =B39-C39 -> 0 | E39: =IF(ABS(D39)<0.000001,"PASS","FAIL") -> PASS
A40: root lanes | B40: =COUNTA('Root Lanes'!A7:A12) -> 6 | C40: 6 | D40: =B40-C40 -> 0 | E40: =IF(ABS(D40)<0.000001,"PASS","FAIL") -> PASS
A41: section accounts | B41: =COUNTA('Section Grammar'!A7:A12) -> 6 | C41: 6 | D41: =B41-C41 -> 0 | E41: =IF(ABS(D41)<0.000001,"PASS","FAIL") -> PASS
A42: section worlds | B42: =COUNTA(Worlds!A7:A10) -> 4 | C42: 4 | D42: =B42-C42 -> 0 | E42: =IF(ABS(D42)<0.000001,"PASS","FAIL") -> PASS
A43: closure rows | B43: =COUNTA('Closure Matrix'!A7:A150) -> 144 | C43: 144 | D43: =B43-C43 -> 0 | E43: =IF(ABS(D43)<0.000001,"PASS","FAIL") -> PASS
A44: closure rows open | B44: =COUNTIFS('Closure Matrix'!M7:M150,"OPEN") -> 144 | C44: 144 | D44: =B44-C44 -> 0 | E44: =IF(ABS(D44)<0.000001,"PASS","FAIL") -> PASS
A45: closure owned source empty | B45: =COUNTIFS('Closure Matrix'!I7:I150,"SOURCE EMPTY") -> 144 | C45: 144 | D45: =B45-C45 -> 0 | E45: =IF(ABS(D45)<0.000001,"PASS","FAIL") -> PASS
A46: closure requirements source empty | B46: =COUNTIFS('Closure Matrix'!J7:J150,"SOURCE EMPTY") -> 144 | C46: 144 | D46: =B46-C46 -> 0 | E46: =IF(ABS(D46)<0.000001,"PASS","FAIL") -> PASS
A47: closure host contribution zero | B47: =SUM('Closure Matrix'!K7:K150) -> 0 | C47: 0 | D47: =B47-C47 -> 0 | E47: =IF(ABS(D47)<0.000001,"PASS","FAIL") -> PASS
A48: closure G06 credit zero | B48: =SUM('Closure Matrix'!O7:O150) -> 0 | C48: 0 | D48: =B48-C48 -> 0 | E48: =IF(ABS(D48)<0.000001,"PASS","FAIL") -> PASS
A49: packet rows | B49: =COUNTA('Section Packets'!A7:A54) -> 48 | C49: 48 | D49: =B49-C49 -> 0 | E49: =IF(ABS(D49)<0.000001,"PASS","FAIL") -> PASS
A50: packet rows constituted | B50: =COUNTIFS('Section Packets'!G7:G54,"CONSTITUTED") -> 48 | C50: 48 | D50: =B50-C50 -> 0 | E50: =IF(ABS(D50)<0.000001,"PASS","FAIL") -> PASS
A51: packet acceptance zero | B51: =SUM('Section Packets'!H7:H54) -> 0 | C51: 0 | D51: =B51-C51 -> 0 | E51: =IF(ABS(D51)<0.000001,"PASS","FAIL") -> PASS
A52: seam rows | B52: =COUNTA('Public Seams'!A7:A78) -> 72 | C52: 72 | D52: =B52-C52 -> 0 | E52: =IF(ABS(D52)<0.000001,"PASS","FAIL") -> PASS
A53: common runtime prohibited | B53: =COUNTIFS('Public Seams'!G7:G78,"PROHIBITED") -> 72 | C53: 72 | D53: =B53-C53 -> 0 | E53: =IF(ABS(D53)<0.000001,"PASS","FAIL") -> PASS
A54: seam acceptance zero | B54: =SUM('Public Seams'!I7:I78) -> 0 | C54: 0 | D54: =B54-C54 -> 0 | E54: =IF(ABS(D54)<0.000001,"PASS","FAIL") -> PASS
A55: schedule rows | B55: =COUNTA('Concurrency Schedule'!A7:A30) -> 24 | C55: 24 | D55: =B55-C55 -> 0 | E55: =IF(ABS(D55)<0.000001,"PASS","FAIL") -> PASS
A56: six concurrent starts | B56: =COUNTIFS('Concurrency Schedule'!D7:D30,1,'Concurrency Schedule'!F7:F30,0) -> 6 | C56: 6 | D56: =B56-C56 -> 0 | E56: =IF(ABS(D56)<0.000001,"PASS","FAIL") -> PASS
A57: serial weeks | B57: ='Concurrency Schedule'!M7 -> 182 | C57: 182 | D57: =B57-C57 -> 0 | E57: =IF(ABS(D57)<0.000001,"PASS","FAIL") -> PASS
A58: parallel weeks | B58: ='Concurrency Schedule'!M8 -> 36 | C58: 36 | D58: =B58-C58 -> 0 | E58: =IF(ABS(D58)<0.000001,"PASS","FAIL") -> PASS
A59: calendar reduction | B59: ='Concurrency Schedule'!M9 -> 0.8021978 | C59: 0.8021978 | D59: =B59-C59 -> 0 | E59: =IF(ABS(D59)<0.000001,"PASS","FAIL") -> PASS
A60: workforce cells | B60: =COUNTA('Workforce Separation'!A7:A18) -> 12 | C60: 12 | D60: =B60-C60 -> 0 | E60: =IF(ABS(D60)<0.000001,"PASS","FAIL") -> PASS
A61: author cells | B61: =SUM('Workforce Separation'!E7:E18) -> 6 | C61: 6 | D61: =B61-C61 -> 0 | E61: =IF(ABS(D61)<0.000001,"PASS","FAIL") -> PASS
...

Sheet Sources & Limits
A2: Internal authorities and model limits
A4: Only internal repository authorities are used. Durations and every physical coefficient remain controlled planning hypotheses until evidence closes them.
A6: Source | B6: Repository artifact | C6: Use | D6: Status | E6: Limitation
A7: FGR-1 | B7: Six-Root Form-Giving Candidate Requirements | C7: six articles, loads, interfaces and gates | D7: authoritative | E7: no internal closure margin
A8: A2C-5 | B8: National First Sentinel Construction Compact | C8: option ceilings, payment states and nonconversions | D8: authoritative | E8: no implementation identities
A9: C3-SPW-3 | B9: Twenty Non-Lifeline Physical Balances | C9: seven-account paper balance context | D9: controlled hypothesis | E9: coefficients unobserved
A10: C3-LFG3-1 | B10: Lifeline Four-Root Configuration | C10: LF-B source-position balance | D10: controlled hypothesis | E10: geology and rates unobserved
A11: A2C-2 | B11: Sovereign Truth Trains | C11: root-native proof and public substrate boundary | D11: authoritative | E11: rig is not article form
A12: SAT-170R | B12: Internal Architecture and Coupled Closure | C12: precedent for coupled mass, energy, geometry and removal | D12: historical method | E12: not a common template
A13: Model boundary | B13: this workbook | C13: sequence, grammar, finance and release checks | D13: planning only | E13: no modeled physical margin
A14: Evidence boundary | B14: all observation fields | C14: deliberate source-empty state | D14: not available | E14: no physical event has run
