Workbook

Sheet Summary
A2: A2C-3 Severable Construction Lattice
A4: Verdict: CLOSE. Buy eighteen station nuclei and six truth trains as 102 severable lots behind a forty-eight-control-group floor. No site, firm, award, payment, acceptance, capability or exterior form exists.
A6: Decision | B6: Result | C6: Unit | D6: State | E6: Why it matters | F6: Current authority | G6: Held conversion | H6: Next object
A7: selected architecture | B7: severable construction lattice | C7: architecture | D7: CLOSE | E7: keeps complete liability without common causal control | F7: lot constitution | G7: lot to winner | H7: bid admission
A8: construction lots | B8: 102 | C8: count | D8: CONSTITUTED | E8: six complete object classes | F8: records only | G8: record to award | H8: collision-free slate
A9: public decisive lots | B9: 72 | C9: count | D9: CONSTITUTED | E9: rigs, methods and regeneration remain separate | F9: records only | G9: lot to as-built | H9: construction packets
A10: public boundary lots | B10: 24 | C10: count | D10: CONSTITUTED | E10: substrate and integration cannot become technical roots | F10: records only | G10: boundary to control | H10: site classes
A11: candidate lots | B11: 6 | C11: count | D11: GATED | E11: one option per selected Root House | F11: option ceilings | G11: option to award | H11: bid admission
A12: minimum control groups | B12: 48 | C12: count | D12: FROZEN | E12: control follows ownership, debt, tools, keys and people | F12: firewall | G12: slot to firm | H12: ownership proof
A13: acceptance packets | B13: 510 | C13: count | D13: OPEN | E13: five complete construction records per lot | F13: grammar only | G13: packet to acceptance | H13: physical records
A14: acceptance decisions | B14: 714 | C14: count | D14: OPEN | E14: seven noncompensatory gates per lot | F14: grammar only | G14: gate to pass | H14: physical decisions
A15: public reserve | B15: 12 | C15: USD B | D15: RESERVED | E15: existing authority only | F15: ceiling | G15: reserve to obligation | H15: award warrant
A16: private options | B16: 3.5869128 | C16: USD B | D16: GATED | E16: root-specific option ceilings | F16: ceiling | G16: option to payment | H16: accepted artifact
A17: combined wave | B17: 15.586913 | C17: USD B | D17: CONSTITUTED | E17: no added authority | F17: ceiling | G17: authority to spend | H17: release sequence
A18: through MAKE exposure | B18: 10.793456 | C18: USD B | D18: CEILING | E18: limits pre-destruction loss | F18: schedule | G18: ceiling to payment | H18: accepted stages
A19: all-six kill unreleased | B19: 3.5380369 | C19: USD B | D19: PROTECTED | E19: valid failure returns transfer money | F19: schedule | G19: failure to production | H19: root disposition
... A22: rendering authority | B22: 0 | C22: count | D22: HELD | E22: form follows stabilized requirements | F22: none | G22: envelope to exterior | H22: later design
A25: Terminal test | B25: Observed | C25: State
A26: eligible architecture | B26: =COUNTIF(Alternatives!P7:P11,"SELECT") -> 1 | C26: =IF(ABS(B26-1)<0.000001,"PASS","FAIL") -> PASS
A27: lot count | B27: ='Lot Classes'!D13 -> 102 | C27: =IF(ABS(B27-102)<0.000001,"PASS","FAIL") -> PASS
A28: control groups | B28: =COUNTA('Control Groups'!A7:A54) -> 48 | C28: =IF(ABS(B28-48)<0.000001,"PASS","FAIL") -> PASS
A29: packet records | B29: =COUNTA('Acceptance Packets'!A7:A516) -> 510 | C29: =IF(ABS(B29-510)<0.000001,"PASS","FAIL") -> PASS
A30: gate decisions | B30: =COUNTA('Acceptance Gates'!A7:A720) -> 714 | C30: =IF(ABS(B30-714)<0.000001,"PASS","FAIL") -> PASS
A31: public authority | B31: =SUM('Lot Classes'!E7:E11) -> 12 | C31: =IF(ABS(B31-12)<0.000001,"PASS","FAIL") -> PASS
A32: combined ceiling | B32: ='Lot Classes'!E13 -> 15.586913 | C32: =IF(ABS(B32-15.5869128193206)<0.000001,"PASS","FAIL") -> PASS
A33: audit failures | B33: =COUNTIF(Audit!E7:E86,"FAIL") -> 0 | C33: =IF(ABS(B33-0)<0.000001,"PASS","FAIL") -> PASS
A34: awards | B34: =Controls!B22 -> 0 | C34: =IF(ABS(B34-0)<0.000001,"PASS","FAIL") -> PASS
A35: rendering authority | B35: =Controls!B28 -> 0 | C35: =IF(ABS(B35-0)<0.000001,"PASS","FAIL") -> PASS

Sheet Controls
A2: Authoritative A2C-3 controls
A4: Blue cells are the only mutable controls used by the audit. A zero is a held state, not missing work silently treated as complete.
A6: Control | B6: Value | C6: Unit | D6: Authority | E6: Meaning
A7: public construction reserve | B7: 12 | C7: USD B | D7: A2C-2 | E7: nested in enabling authority
A8: selected candidate options | B8: 3.5869128 | C8: USD B | D8: A2C-1 | E8: six root-specific ceilings
A9: mission systems | B9: 6 | C9: count | D9: A2C-2 | E9: all six remain live
A10: roles per system | B10: 3 | C10: count | D10: A2C-2 | E10: challenge, control, reconstruction
A11: civil substrate lots | B11: 6 | C11: count | D11: A2C-3 | E11: one balanced three-station package each
A12: root-native rig lots | B12: 18 | C12: count | D12: A2C-3 | E12: one per station
A13: method-lineage lots | B13: 36 | C13: count | D13: A2C-3 | E13: two unlike lineages per station
A14: regeneration-tool lots | B14: 18 | C14: count | D14: A2C-3 | E14: one per station
A15: station-integration lots | B15: 18 | C15: count | D15: A2C-3 | E15: one nondecisive interface lot per station
A16: candidate-mechanism lots | B16: 6 | C16: count | D16: A2C-3 | E16: one per selected Root House
A17: minimum control groups | B17: 48 | C17: count | D17: A2C-3 | E17: six candidate, thirty-six decisive, six boundary
A18: packet families per lot | B18: 5 | C18: count | D18: A2C-3 | E18: all required
... A28: rendering authority | B28: 0 | C28: count | D28: A2C-3 | E28: exterior form held

Sheet Alternatives
A2: Construction architecture hard-gate test
A4: All twelve gates are conjunctive. A large contractor roster cannot compensate for unified causal control or orphaned system responsibility.
A6: Architecture | B6: complete liability | C6: candidate separation | D6: role separation | E6: method plurality | F6: regen separation | G6: control transparency | H6: tooling separation | I6: acceptance separation | J6: failure severability | K6: public interfaces | L6: bounded integration | M6: cold return | N6: Passes | O6: Eligible | P6: Decision
A7: 102-lot severable lattice | B7: 1 | C7: 1 | D7: 1 | E7: 1 | F7: 1 | G7: 1 | H7: 1 | I7: 1 | J7: 1 | K7: 1 | L7: 1 | M7: 1 | N7: =SUM(B7:M7) -> 12 | O7: =IF(N7=12,"YES","NO") -> YES | P7: =IF(O7="YES","SELECT","REJECT") -> SELECT
A8: one national EPC prime | B8: 1 | C8: 0 | D8: 0 | E8: 0 | F8: 0 | G8: 0 | H8: 0 | I8: 0 | J8: 0 | K8: 1 | L8: 0 | M8: 0 | N8: =SUM(B8:M8) -> 2 | O8: =IF(N8=12,"YES","NO") -> NO | P8: =IF(O8="YES","SELECT","REJECT") -> REJECT
A9: six system primes | B9: 1 | C9: 0 | D9: 0 | E9: 0 | F9: 0 | G9: 1 | H9: 0 | I9: 0 | J9: 0 | K9: 1 | L9: 0 | M9: 0 | N9: =SUM(B9:M9) -> 3 | O9: =IF(N9=12,"YES","NO") -> NO | P9: =IF(O9="YES","SELECT","REJECT") -> REJECT
A10: eighteen station primes | B10: 1 | C10: 1 | D10: 1 | E10: 0 | F10: 0 | G10: 1 | H10: 0 | I10: 0 | J10: 1 | K10: 1 | L10: 0 | M10: 0 | N10: =SUM(B10:M10) -> 6 | O10: =IF(N10=12,"YES","NO") -> NO | P10: =IF(O10="YES","SELECT","REJECT") -> REJECT
A11: component atomization | B11: 0 | C11: 1 | D11: 1 | E11: 1 | F11: 1 | G11: 1 | H11: 1 | I11: 1 | J11: 1 | K11: 1 | L11: 1 | M11: 1 | N11: =SUM(B11:M11) -> 11 | O11: =IF(N11=12,"YES","NO") -> NO | P11: =IF(O11="YES","SELECT","REJECT") -> REJECT

Sheet Lot Classes
A2: Six severable construction-lot classes
A4: Public classes exhaust the USD 12.0B reservation. Candidate options remain private and root-specific.
A6: Code | B6: Class | C6: Funding | D6: Lots | E6: Authority USD B | F6: Nature | G6: Release | H6: Complete liability | I6: Per-lot USD B | J6: Share of wave
A7: SUB | B7: Civil substrate | C7: Public | D7: 6 | E7: 0.72 | F7: nondecisive | G7: R2 | H7: public boundary control | I7: =E7/D7 -> 0.12 | J7: =E7/$E$13 -> 0.046192598
A8: RIG | B8: Root-native rig | C8: Public | D8: 18 | E8: 5.7 | F8: decisive | G8: R3 | H8: native physical control | I8: =E8/D8 -> 0.31666667 | J8: =E8/$E$13 -> 0.3656914
A9: MTH | B9: Method lineage | C9: Public | D9: 36 | E9: 3.24 | F9: decisive | G9: R3 | H9: unlike realization | I9: =E9/D9 -> 0.09 | J9: =E9/$E$13 -> 0.20786669
A10: REG | B10: Regeneration tool | C10: Public | D10: 18 | E10: 1.2 | F10: decisive | G10: R3 | H10: outside recovery | I10: =E10/D10 -> 0.066666667 | J10: =E10/$E$13 -> 0.076987664
A11: INT | B11: Station integration | C11: Public | D11: 18 | E11: 1.14 | F11: nondecisive | G11: R4 | H11: public-interface assembly only | I11: =E11/D11 -> 0.063333333 | J11: =E11/$E$13 -> 0.07313828
A12: CAN | B12: Candidate mechanism | C12: Private option | D12: 6 | E12: 3.5869128 | F12: decisive | G12: R3 | H12: selected Root House mechanism | I12: =E12/D12 -> 0.5978188 | J12: =E12/$E$13 -> 0.23012336
A13: TOTAL | B13: six classes | C13: mixed | D13: =SUM(D7:D12) -> 102 | E13: =SUM(E7:E12) -> 15.586913 | F13: — | G13: — | H13: 102 separately severable objects | I13: =E13/D13 -> 0.15281287 | J13: =SUM(J7:J12) -> 1

Sheet Lot Register
A2: One hundred two separately severable construction lots
A4: Identity, supplier, award, obligation, payment, acceptance and capability remain source-empty or zero. A constituted lot is not a contract.
A6: Lot ID | B6: Class | C6: Funding | D6: System | E6: Root | F6: Role | G6: Station/package | H6: Lineage | I6: Release | J6: Control group | K6: Authority USD B | L6: Controller ID | M6: Supplier ID | N6: Award | O6: Obligation USD B | P6: Payment USD B | Q6: Packets passed | R6: Gates passed | S6: Capability credit | T6: State
A7: SUB-01 | B7: Civil substrate | C7: Public | D7: MULTI | E7: — | F7: ROTATED | G7: ST-ET-CHA · ST-HC-REC · ST-HU-CON | H7: BOUNDARY | I7: R2 | J7: CG-BND-01 | K7: 0.12 | L7: SOURCE EMPTY | M7: SOURCE EMPTY | N7: 0 | O7: =N7*K7 -> 0 | P7: =Controls!B24 -> 0 | Q7: =Controls!B25 -> 0 | R7: =Controls!B26 -> 0 | S7: =Controls!B27 -> 0 | T7: =IF(N7=0,"CONSTITUTED","AWARDED") -> CONSTITUTED
A8: SUB-02 | B8: Civil substrate | C8: Public | D8: MULTI | E8: — | F8: ROTATED | G8: ST-CT-CHA · ST-LF-REC · ST-RT-CON | H8: BOUNDARY | I8: R2 | J8: CG-BND-02 | K8: 0.12 | L8: SOURCE EMPTY | M8: SOURCE EMPTY | N8: 0 | O8: =N8*K8 -> 0 | P8: =Controls!B24 -> 0 | Q8: =Controls!B25 -> 0 | R8: =Controls!B26 -> 0 | S8: =Controls!B27 -> 0 | T8: =IF(N8=0,"CONSTITUTED","AWARDED") -> CONSTITUTED
A9: SUB-03 | B9: Civil substrate | C9: Public | D9: MULTI | E9: — | F9: ROTATED | G9: ST-ET-CON · ST-HC-CHA · ST-HU-REC | H9: BOUNDARY | I9: R2 | J9: CG-BND-03 | K9: 0.12 | L9: SOURCE EMPTY | M9: SOURCE EMPTY | N9: 0 | O9: =N9*K9 -> 0 | P9: =Controls!B24 -> 0 | Q9: =Controls!B25 -> 0 | R9: =Controls!B26 -> 0 | S9: =Controls!B27 -> 0 | T9: =IF(N9=0,"CONSTITUTED","AWARDED") -> CONSTITUTED
A10: SUB-04 | B10: Civil substrate | C10: Public | D10: MULTI | E10: — | F10: ROTATED | G10: ST-CT-CON · ST-LF-CHA · ST-RT-REC | H10: BOUNDARY | I10: R2 | J10: CG-BND-04 | K10: 0.12 | L10: SOURCE EMPTY | M10: SOURCE EMPTY | N10: 0 | O10: =N10*K10 -> 0 | P10: =Controls!B24 -> 0 | Q10: =Controls!B25 -> 0 | R10: =Controls!B26 -> 0 | S10: =Controls!B27 -> 0 | T10: =IF(N10=0,"CONSTITUTED","AWARDED") -> CONSTITUTED
A11: SUB-05 | B11: Civil substrate | C11: Public | D11: MULTI | E11: — | F11: ROTATED | G11: ST-ET-REC · ST-HC-CON · ST-HU-CHA | H11: BOUNDARY | I11: R2 | J11: CG-BND-05 | K11: 0.12 | L11: SOURCE EMPTY | M11: SOURCE EMPTY | N11: 0 | O11: =N11*K11 -> 0 | P11: =Controls!B24 -> 0 | Q11: =Controls!B25 -> 0 | R11: =Controls!B26 -> 0 | S11: =Controls!B27 -> 0 | T11: =IF(N11=0,"CONSTITUTED","AWARDED") -> CONSTITUTED
A12: SUB-06 | B12: Civil substrate | C12: Public | D12: MULTI | E12: — | F12: ROTATED | G12: ST-CT-REC · ST-LF-CON · ST-RT-CHA | H12: BOUNDARY | I12: R2 | J12: CG-BND-06 | K12: 0.12 | L12: SOURCE EMPTY | M12: SOURCE EMPTY | N12: 0 | O12: =N12*K12 -> 0 | P12: =Controls!B24 -> 0 | Q12: =Controls!B25 -> 0 | R12: =Controls!B26 -> 0 | S12: =Controls!B27 -> 0 | T12: =IF(N12=0,"CONSTITUTED","AWARDED") -> CONSTITUTED
A13: RIG-ET-CHA | B13: Root-native rig | C13: Public | D13: MS-ET | E13: ET-A | F13: CHALLENGE | G13: ST-ET-CHA | H13: RIG | I13: R3 | J13: CG-DEC-RIG-CHA-01 | K13: 0.31666667 | L13: SOURCE EMPTY | M13: SOURCE EMPTY | N13: 0 | O13: =N13*K13 -> 0 | P13: =Controls!B24 -> 0 | Q13: =Controls!B25 -> 0 | R13: =Controls!B26 -> 0 | S13: =Controls!B27 -> 0 | T13: =IF(N13=0,"CONSTITUTED","AWARDED") -> CONSTITUTED
A14: MTH-ET-CHA-L1 | B14: Method lineage | C14: Public | D14: MS-ET | E14: ET-A | F14: CHALLENGE | G14: ST-ET-CHA | H14: L1 | I14: R3 | J14: CG-DEC-M1-CHA-01 | K14: 0.09 | L14: SOURCE EMPTY | M14: SOURCE EMPTY | N14: 0 | O14: =N14*K14 -> 0 | P14: =Controls!B24 -> 0 | Q14: =Controls!B25 -> 0 | R14: =Controls!B26 -> 0 | S14: =Controls!B27 -> 0 | T14: =IF(N14=0,"CONSTITUTED","AWARDED") -> CONSTITUTED
A15: MTH-ET-CHA-L2 | B15: Method lineage | C15: Public | D15: MS-ET | E15: ET-A | F15: CHALLENGE | G15: ST-ET-CHA | H15: L2 | I15: R3 | J15: CG-DEC-M2-CHA-01 | K15: 0.09 | L15: SOURCE EMPTY | M15: SOURCE EMPTY | N15: 0 | O15: =N15*K15 -> 0 | P15: =Controls!B24 -> 0 | Q15: =Controls!B25 -> 0 | R15: =Controls!B26 -> 0 | S15: =Controls!B27 -> 0 | T15: =IF(N15=0,"CONSTITUTED","AWARDED") -> CONSTITUTED
A16: REG-ET-CHA | B16: Regeneration tool | C16: Public | D16: MS-ET | E16: ET-A | F16: CHALLENGE | G16: ST-ET-CHA | H16: REGEN | I16: R3 | J16: CG-DEC-REG-CHA-01 | K16: 0.066666667 | L16: SOURCE EMPTY | M16: SOURCE EMPTY | N16: 0 | O16: =N16*K16 -> 0 | P16: =Controls!B24 -> 0 | Q16: =Controls!B25 -> 0 | R16: =Controls!B26 -> 0 | S16: =Controls!B27 -> 0 | T16: =IF(N16=0,"CONSTITUTED","AWARDED") -> CONSTITUTED
A17: INT-ET-CHA | B17: Station integration | C17: Public | D17: MS-ET | E17: ET-A | F17: CHALLENGE | G17: ST-ET-CHA | H17: BOUNDARY | I17: R4 | J17: CG-BND-02 | K17: 0.063333333 | L17: SOURCE EMPTY | M17: SOURCE EMPTY | N17: 0 | O17: =N17*K17 -> 0 | P17: =Controls!B24 -> 0 | Q17: =Controls!B25 -> 0 | R17: =Controls!B26 -> 0 | S17: =Controls!B27 -> 0 | T17: =IF(N17=0,"CONSTITUTED","AWARDED") -> CONSTITUTED
A18: RIG-ET-CON | B18: Root-native rig | C18: Public | D18: MS-ET | E18: ET-A | F18: CONTROL | G18: ST-ET-CON | H18: RIG | I18: R3 | J18: CG-DEC-RIG-CON-01 | K18: 0.31666667 | L18: SOURCE EMPTY | M18: SOURCE EMPTY | N18: 0 | O18: =N18*K18 -> 0 | P18: =Controls!B24 -> 0 | Q18: =Controls!B25 -> 0 | R18: =Controls!B26 -> 0 | S18: =Controls!B27 -> 0 | T18: =IF(N18=0,"CONSTITUTED","AWARDED") -> CONSTITUTED
A19: MTH-ET-CON-L1 | B19: Method lineage | C19: Public | D19: MS-ET | E19: ET-A | F19: CONTROL | G19: ST-ET-CON | H19: L1 | I19: R3 | J19: CG-DEC-M1-CON-01 | K19: 0.09 | L19: SOURCE EMPTY | M19: SOURCE EMPTY | N19: 0 | O19: =N19*K19 -> 0 | P19: =Controls!B24 -> 0 | Q19: =Controls!B25 -> 0 | R19: =Controls!B26 -> 0 | S19: =Controls!B27 -> 0 | T19: =IF(N19=0,"CONSTITUTED","AWARDED") -> CONSTITUTED
A20: MTH-ET-CON-L2 | B20: Method lineage | C20: Public | D20: MS-ET | E20: ET-A | F20: CONTROL | G20: ST-ET-CON | H20: L2 | I20: R3 | J20: CG-DEC-M2-CON-01 | K20: 0.09 | L20: SOURCE EMPTY | M20: SOURCE EMPTY | N20: 0 | O20: =N20*K20 -> 0 | P20: =Controls!B24 -> 0 | Q20: =Controls!B25 -> 0 | R20: =Controls!B26 -> 0 | S20: =Controls!B27 -> 0 | T20: =IF(N20=0,"CONSTITUTED","AWARDED") -> CONSTITUTED
A21: REG-ET-CON | B21: Regeneration tool | C21: Public | D21: MS-ET | E21: ET-A | F21: CONTROL | G21: ST-ET-CON | H21: REGEN | I21: R3 | J21: CG-DEC-REG-CON-01 | K21: 0.066666667 | L21: SOURCE EMPTY | M21: SOURCE EMPTY | N21: 0 | O21: =N21*K21 -> 0 | P21: =Controls!B24 -> 0 | Q21: =Controls!B25 -> 0 | R21: =Controls!B26 -> 0 | S21: =Controls!B27 -> 0 | T21: =IF(N21=0,"CONSTITUTED","AWARDED") -> CONSTITUTED
A22: INT-ET-CON | B22: Station integration | C22: Public | D22: MS-ET | E22: ET-A | F22: CONTROL | G22: ST-ET-CON | H22: BOUNDARY | I22: R4 | J22: CG-BND-04 | K22: 0.063333333 | L22: SOURCE EMPTY | M22: SOURCE EMPTY | N22: 0 | O22: =N22*K22 -> 0 | P22: =Controls!B24 -> 0 | Q22: =Controls!B25 -> 0 | R22: =Controls!B26 -> 0 | S22: =Controls!B27 -> 0 | T22: =IF(N22=0,"CONSTITUTED","AWARDED") -> CONSTITUTED
A23: RIG-ET-REC | B23: Root-native rig | C23: Public | D23: MS-ET | E23: ET-A | F23: RECONSTRUCTION | G23: ST-ET-REC | H23: RIG | I23: R3 | J23: CG-DEC-RIG-REC-01 | K23: 0.31666667 | L23: SOURCE EMPTY | M23: SOURCE EMPTY | N23: 0 | O23: =N23*K23 -> 0 | P23: =Controls!B24 -> 0 | Q23: =Controls!B25 -> 0 | R23: =Controls!B26 -> 0 | S23: =Controls!B27 -> 0 | T23: =IF(N23=0,"CONSTITUTED","AWARDED") -> CONSTITUTED
A24: MTH-ET-REC-L1 | B24: Method lineage | C24: Public | D24: MS-ET | E24: ET-A | F24: RECONSTRUCTION | G24: ST-ET-REC | H24: L1 | I24: R3 | J24: CG-DEC-M1-REC-01 | K24: 0.09 | L24: SOURCE EMPTY | M24: SOURCE EMPTY | N24: 0 | O24: =N24*K24 -> 0 | P24: =Controls!B24 -> 0 | Q24: =Controls!B25 -> 0 | R24: =Controls!B26 -> 0 | S24: =Controls!B27 -> 0 | T24: =IF(N24=0,"CONSTITUTED","AWARDED") -> CONSTITUTED
A25: MTH-ET-REC-L2 | B25: Method lineage | C25: Public | D25: MS-ET | E25: ET-A | F25: RECONSTRUCTION | G25: ST-ET-REC | H25: L2 | I25: R3 | J25: CG-DEC-M2-REC-01 | K25: 0.09 | L25: SOURCE EMPTY | M25: SOURCE EMPTY | N25: 0 | O25: =N25*K25 -> 0 | P25: =Controls!B24 -> 0 | Q25: =Controls!B25 -> 0 | R25: =Controls!B26 -> 0 | S25: =Controls!B27 -> 0 | T25: =IF(N25=0,"CONSTITUTED","AWARDED") -> CONSTITUTED
A26: REG-ET-REC | B26: Regeneration tool | C26: Public | D26: MS-ET | E26: ET-A | F26: RECONSTRUCTION | G26: ST-ET-REC | H26: REGEN | I26: R3 | J26: CG-DEC-REG-REC-01 | K26: 0.066666667 | L26: SOURCE EMPTY | M26: SOURCE EMPTY | N26: 0 | O26: =N26*K26 -> 0 | P26: =Controls!B24 -> 0 | Q26: =Controls!B25 -> 0 | R26: =Controls!B26 -> 0 | S26: =Controls!B27 -> 0 | T26: =IF(N26=0,"CONSTITUTED","AWARDED") -> CONSTITUTED
A27: INT-ET-REC | B27: Station integration | C27: Public | D27: MS-ET | E27: ET-A | F27: RECONSTRUCTION | G27: ST-ET-REC | H27: BOUNDARY | I27: R4 | J27: CG-BND-06 | K27: 0.063333333 | L27: SOURCE EMPTY | M27: SOURCE EMPTY | N27: 0 | O27: =N27*K27 -> 0 | P27: =Controls!B24 -> 0 | Q27: =Controls!B25 -> 0 | R27: =Controls!B26 -> 0 | S27: =Controls!B27 -> 0 | T27: =IF(N27=0,"CONSTITUTED","AWARDED") -> CONSTITUTED
A28: RIG-CT-CHA | B28: Root-native rig | C28: Public | D28: MS-CT | E28: CT-C | F28: CHALLENGE | G28: ST-CT-CHA | H28: RIG | I28: R3 | J28: CG-DEC-RIG-CHA-02 | K28: 0.31666667 | L28: SOURCE EMPTY | M28: SOURCE EMPTY | N28: 0 | O28: =N28*K28 -> 0 | P28: =Controls!B24 -> 0 | Q28: =Controls!B25 -> 0 | R28: =Controls!B26 -> 0 | S28: =Controls!B27 -> 0 | T28: =IF(N28=0,"CONSTITUTED","AWARDED") -> CONSTITUTED
A29: MTH-CT-CHA-L1 | B29: Method lineage | C29: Public | D29: MS-CT | E29: CT-C | F29: CHALLENGE | G29: ST-CT-CHA | H29: L1 | I29: R3 | J29: CG-DEC-M1-CHA-02 | K29: 0.09 | L29: SOURCE EMPTY | M29: SOURCE EMPTY | N29: 0 | O29: =N29*K29 -> 0 | P29: =Controls!B24 -> 0 | Q29: =Controls!B25 -> 0 | R29: =Controls!B26 -> 0 | S29: =Controls!B27 -> 0 | T29: =IF(N29=0,"CONSTITUTED","AWARDED") -> CONSTITUTED
A30: MTH-CT-CHA-L2 | B30: Method lineage | C30: Public | D30: MS-CT | E30: CT-C | F30: CHALLENGE | G30: ST-CT-CHA | H30: L2 | I30: R3 | J30: CG-DEC-M2-CHA-02 | K30: 0.09 | L30: SOURCE EMPTY | M30: SOURCE EMPTY | N30: 0 | O30: =N30*K30 -> 0 | P30: =Controls!B24 -> 0 | Q30: =Controls!B25 -> 0 | R30: =Controls!B26 -> 0 | S30: =Controls!B27 -> 0 | T30: =IF(N30=0,"CONSTITUTED","AWARDED") -> CONSTITUTED
A31: REG-CT-CHA | B31: Regeneration tool | C31: Public | D31: MS-CT | E31: CT-C | F31: CHALLENGE | G31: ST-CT-CHA | H31: REGEN | I31: R3 | J31: CG-DEC-REG-CHA-02 | K31: 0.066666667 | L31: SOURCE EMPTY | M31: SOURCE EMPTY | N31: 0 | O31: =N31*K31 -> 0 | P31: =Controls!B24 -> 0 | Q31: =Controls!B25 -> 0 | R31: =Controls!B26 -> 0 | S31: =Controls!B27 -> 0 | T31: =IF(N31=0,"CONSTITUTED","AWARDED") -> CONSTITUTED
A32: INT-CT-CHA | B32: Station integration | C32: Public | D32: MS-CT | E32: CT-C | F32: CHALLENGE | G32: ST-CT-CHA | H32: BOUNDARY | I32: R4 | J32: CG-BND-03 | K32: 0.063333333 | L32: SOURCE EMPTY | M32: SOURCE EMPTY | N32: 0 | O32: =N32*K32 -> 0 | P32: =Controls!B24 -> 0 | Q32: =Controls!B25 -> 0 | R32: =Controls!B26 -> 0 | S32: =Controls!B27 -> 0 | T32: =IF(N32=0,"CONSTITUTED","AWARDED") -> CONSTITUTED
A33: RIG-CT-CON | B33: Root-native rig | C33: Public | D33: MS-CT | E33: CT-C | F33: CONTROL | G33: ST-CT-CON | H33: RIG | I33: R3 | J33: CG-DEC-RIG-CON-02 | K33: 0.31666667 | L33: SOURCE EMPTY | M33: SOURCE EMPTY | N33: 0 | O33: =N33*K33 -> 0 | P33: =Controls!B24 -> 0 | Q33: =Controls!B25 -> 0 | R33: =Controls!B26 -> 0 | S33: =Controls!B27 -> 0 | T33: =IF(N33=0,"CONSTITUTED","AWARDED") -> CONSTITUTED
A34: MTH-CT-CON-L1 | B34: Method lineage | C34: Public | D34: MS-CT | E34: CT-C | F34: CONTROL | G34: ST-CT-CON | H34: L1 | I34: R3 | J34: CG-DEC-M1-CON-02 | K34: 0.09 | L34: SOURCE EMPTY | M34: SOURCE EMPTY | N34: 0 | O34: =N34*K34 -> 0 | P34: =Controls!B24 -> 0 | Q34: =Controls!B25 -> 0 | R34: =Controls!B26 -> 0 | S34: =Controls!B27 -> 0 | T34: =IF(N34=0,"CONSTITUTED","AWARDED") -> CONSTITUTED
A35: MTH-CT-CON-L2 | B35: Method lineage | C35: Public | D35: MS-CT | E35: CT-C | F35: CONTROL | G35: ST-CT-CON | H35: L2 | I35: R3 | J35: CG-DEC-M2-CON-02 | K35: 0.09 | L35: SOURCE EMPTY | M35: SOURCE EMPTY | N35: 0 | O35: =N35*K35 -> 0 | P35: =Controls!B24 -> 0 | Q35: =Controls!B25 -> 0 | R35: =Controls!B26 -> 0 | S35: =Controls!B27 -> 0 | T35: =IF(N35=0,"CONSTITUTED","AWARDED") -> CONSTITUTED
A36: REG-CT-CON | B36: Regeneration tool | C36: Public | D36: MS-CT | E36: CT-C | F36: CONTROL | G36: ST-CT-CON | H36: REGEN | I36: R3 | J36: CG-DEC-REG-CON-02 | K36: 0.066666667 | L36: SOURCE EMPTY | M36: SOURCE EMPTY | N36: 0 | O36: =N36*K36 -> 0 | P36: =Controls!B24 -> 0 | Q36: =Controls!B25 -> 0 | R36: =Controls!B26 -> 0 | S36: =Controls!B27 -> 0 | T36: =IF(N36=0,"CONSTITUTED","AWARDED") -> CONSTITUTED
A37: INT-CT-CON | B37: Station integration | C37: Public | D37: MS-CT | E37: CT-C | F37: CONTROL | G37: ST-CT-CON | H37: BOUNDARY | I37: R4 | J37: CG-BND-05 | K37: 0.063333333 | L37: SOURCE EMPTY | M37: SOURCE EMPTY | N37: 0 | O37: =N37*K37 -> 0 | P37: =Controls!B24 -> 0 | Q37: =Controls!B25 -> 0 | R37: =Controls!B26 -> 0 | S37: =Controls!B27 -> 0 | T37: =IF(N37=0,"CONSTITUTED","AWARDED") -> CONSTITUTED
A38: RIG-CT-REC | B38: Root-native rig | C38: Public | D38: MS-CT | E38: CT-C | F38: RECONSTRUCTION | G38: ST-CT-REC | H38: RIG | I38: R3 | J38: CG-DEC-RIG-REC-02 | K38: 0.31666667 | L38: SOURCE EMPTY | M38: SOURCE EMPTY | N38: 0 | O38: =N38*K38 -> 0 | P38: =Controls!B24 -> 0 | Q38: =Controls!B25 -> 0 | R38: =Controls!B26 -> 0 | S38: =Controls!B27 -> 0 | T38: =IF(N38=0,"CONSTITUTED","AWARDED") -> CONSTITUTED
A39: MTH-CT-REC-L1 | B39: Method lineage | C39: Public | D39: MS-CT | E39: CT-C | F39: RECONSTRUCTION | G39: ST-CT-REC | H39: L1 | I39: R3 | J39: CG-DEC-M1-REC-02 | K39: 0.09 | L39: SOURCE EMPTY | M39: SOURCE EMPTY | N39: 0 | O39: =N39*K39 -> 0 | P39: =Controls!B24 -> 0 | Q39: =Controls!B25 -> 0 | R39: =Controls!B26 -> 0 | S39: =Controls!B27 -> 0 | T39: =IF(N39=0,"CONSTITUTED","AWARDED") -> CONSTITUTED
A40: MTH-CT-REC-L2 | B40: Method lineage | C40: Public | D40: MS-CT | E40: CT-C | F40: RECONSTRUCTION | G40: ST-CT-REC | H40: L2 | I40: R3 | J40: CG-DEC-M2-REC-02 | K40: 0.09 | L40: SOURCE EMPTY | M40: SOURCE EMPTY | N40: 0 | O40: =N40*K40 -> 0 | P40: =Controls!B24 -> 0 | Q40: =Controls!B25 -> 0 | R40: =Controls!B26 -> 0 | S40: =Controls!B27 -> 0 | T40: =IF(N40=0,"CONSTITUTED","AWARDED") -> CONSTITUTED
A41: REG-CT-REC | B41: Regeneration tool | C41: Public | D41: MS-CT | E41: CT-C | F41: RECONSTRUCTION | G41: ST-CT-REC | H41: REGEN | I41: R3 | J41: CG-DEC-REG-REC-02 | K41: 0.066666667 | L41: SOURCE EMPTY | M41: SOURCE EMPTY | N41: 0 | O41: =N41*K41 -> 0 | P41: =Controls!B24 -> 0 | Q41: =Controls!B25 -> 0 | R41: =Controls!B26 -> 0 | S41: =Controls!B27 -> 0 | T41: =IF(N41=0,"CONSTITUTED","AWARDED") -> CONSTITUTED
A42: INT-CT-REC | B42: Station integration | C42: Public | D42: MS-CT | E42: CT-C | F42: RECONSTRUCTION | G42: ST-CT-REC | H42: BOUNDARY | I42: R4 | J42: CG-BND-01 | K42: 0.063333333 | L42: SOURCE EMPTY | M42: SOURCE EMPTY | N42: 0 | O42: =N42*K42 -> 0 | P42: =Controls!B24 -> 0 | Q42: =Controls!B25 -> 0 | R42: =Controls!B26 -> 0 | S42: =Controls!B27 -> 0 | T42: =IF(N42=0,"CONSTITUTED","AWARDED") -> CONSTITUTED
A43: RIG-HC-CHA | B43: Root-native rig | C43: Public | D43: MS-HC | E43: HC-A | F43: CHALLENGE | G43: ST-HC-CHA | H43: RIG | I43: R3 | J43: CG-DEC-RIG-CHA-03 | K43: 0.31666667 | L43: SOURCE EMPTY | M43: SOURCE EMPTY | N43: 0 | O43: =N43*K43 -> 0 | P43: =Controls!B24 -> 0 | Q43: =Controls!B25 -> 0 | R43: =Controls!B26 -> 0 | S43: =Controls!B27 -> 0 | T43: =IF(N43=0,"CONSTITUTED","AWARDED") -> CONSTITUTED
...

Sheet Substrate Rotation
A2: Six balanced civil-substrate packages
A4: Each substrate lineage touches three distinct systems and one station in each role; no system-role cell repeats.
A6: Lot | B6: Control group | C6: Stations | D6: Systems | E6: Roles | F6: Station count | G6: Distinct systems | H6: Distinct roles | I6: Authority USD B | J6: State
A7: SUB-01 | B7: CG-BND-01 | C7: ST-ET-CHA · ST-HC-REC · ST-HU-CON | D7: MS-ET · MS-HC · MS-HU | E7: CHALLENGE · RECONSTRUCTION · CONTROL | F7: 3 | G7: 3 | H7: 3 | I7: 0.12 | J7: CONSTITUTED
A8: SUB-02 | B8: CG-BND-02 | C8: ST-CT-CHA · ST-LF-REC · ST-RT-CON | D8: MS-CT · MS-LF · MS-RT | E8: CHALLENGE · RECONSTRUCTION · CONTROL | F8: 3 | G8: 3 | H8: 3 | I8: 0.12 | J8: CONSTITUTED
A9: SUB-03 | B9: CG-BND-03 | C9: ST-ET-CON · ST-HC-CHA · ST-HU-REC | D9: MS-ET · MS-HC · MS-HU | E9: CONTROL · CHALLENGE · RECONSTRUCTION | F9: 3 | G9: 3 | H9: 3 | I9: 0.12 | J9: CONSTITUTED
A10: SUB-04 | B10: CG-BND-04 | C10: ST-CT-CON · ST-LF-CHA · ST-RT-REC | D10: MS-CT · MS-LF · MS-RT | E10: CONTROL · CHALLENGE · RECONSTRUCTION | F10: 3 | G10: 3 | H10: 3 | I10: 0.12 | J10: CONSTITUTED
A11: SUB-05 | B11: CG-BND-05 | C11: ST-ET-REC · ST-HC-CON · ST-HU-CHA | D11: MS-ET · MS-HC · MS-HU | E11: RECONSTRUCTION · CONTROL · CHALLENGE | F11: 3 | G11: 3 | H11: 3 | I11: 0.12 | J11: CONSTITUTED
A12: SUB-06 | B12: CG-BND-06 | C12: ST-CT-REC · ST-LF-CON · ST-RT-CHA | D12: MS-CT · MS-LF · MS-RT | E12: RECONSTRUCTION · CONTROL · CHALLENGE | F12: 3 | G12: 3 | H12: 3 | I12: 0.12 | J12: CONSTITUTED

Sheet Station Crosswalk
A2: Eighteen station nuclei and their five local lots
A4: The candidate option is system-level; each station receives five public construction objects and one rotated substrate package.
A6: Station | B6: System | C6: Root | D6: Role | E6: Substrate | F6: Rig | G6: Method L1 | H6: Method L2 | I6: Regeneration | J6: Integration | K6: Boundary group | L6: Site | M6: State
A7: ST-ET-CHA | B7: MS-ET | C7: ET-A | D7: CHALLENGE | E7: SUB-01 | F7: RIG-ET-CHA | G7: MTH-ET-CHA-L1 | H7: MTH-ET-CHA-L2 | I7: REG-ET-CHA | J7: INT-ET-CHA | K7: CG-BND-02 | L7: SOURCE EMPTY | M7: CONSTITUTED
A8: ST-ET-CON | B8: MS-ET | C8: ET-A | D8: CONTROL | E8: SUB-03 | F8: RIG-ET-CON | G8: MTH-ET-CON-L1 | H8: MTH-ET-CON-L2 | I8: REG-ET-CON | J8: INT-ET-CON | K8: CG-BND-04 | L8: SOURCE EMPTY | M8: CONSTITUTED
A9: ST-ET-REC | B9: MS-ET | C9: ET-A | D9: RECONSTRUCTION | E9: SUB-05 | F9: RIG-ET-REC | G9: MTH-ET-REC-L1 | H9: MTH-ET-REC-L2 | I9: REG-ET-REC | J9: INT-ET-REC | K9: CG-BND-06 | L9: SOURCE EMPTY | M9: CONSTITUTED
A10: ST-CT-CHA | B10: MS-CT | C10: CT-C | D10: CHALLENGE | E10: SUB-02 | F10: RIG-CT-CHA | G10: MTH-CT-CHA-L1 | H10: MTH-CT-CHA-L2 | I10: REG-CT-CHA | J10: INT-CT-CHA | K10: CG-BND-03 | L10: SOURCE EMPTY | M10: CONSTITUTED
A11: ST-CT-CON | B11: MS-CT | C11: CT-C | D11: CONTROL | E11: SUB-04 | F11: RIG-CT-CON | G11: MTH-CT-CON-L1 | H11: MTH-CT-CON-L2 | I11: REG-CT-CON | J11: INT-CT-CON | K11: CG-BND-05 | L11: SOURCE EMPTY | M11: CONSTITUTED
A12: ST-CT-REC | B12: MS-CT | C12: CT-C | D12: RECONSTRUCTION | E12: SUB-06 | F12: RIG-CT-REC | G12: MTH-CT-REC-L1 | H12: MTH-CT-REC-L2 | I12: REG-CT-REC | J12: INT-CT-REC | K12: CG-BND-01 | L12: SOURCE EMPTY | M12: CONSTITUTED
A13: ST-HC-CHA | B13: MS-HC | C13: HC-A | D13: CHALLENGE | E13: SUB-03 | F13: RIG-HC-CHA | G13: MTH-HC-CHA-L1 | H13: MTH-HC-CHA-L2 | I13: REG-HC-CHA | J13: INT-HC-CHA | K13: CG-BND-04 | L13: SOURCE EMPTY | M13: CONSTITUTED
A14: ST-HC-CON | B14: MS-HC | C14: HC-A | D14: CONTROL | E14: SUB-05 | F14: RIG-HC-CON | G14: MTH-HC-CON-L1 | H14: MTH-HC-CON-L2 | I14: REG-HC-CON | J14: INT-HC-CON | K14: CG-BND-06 | L14: SOURCE EMPTY | M14: CONSTITUTED
A15: ST-HC-REC | B15: MS-HC | C15: HC-A | D15: RECONSTRUCTION | E15: SUB-01 | F15: RIG-HC-REC | G15: MTH-HC-REC-L1 | H15: MTH-HC-REC-L2 | I15: REG-HC-REC | J15: INT-HC-REC | K15: CG-BND-02 | L15: SOURCE EMPTY | M15: CONSTITUTED
A16: ST-LF-CHA | B16: MS-LF | C16: LF-B | D16: CHALLENGE | E16: SUB-04 | F16: RIG-LF-CHA | G16: MTH-LF-CHA-L1 | H16: MTH-LF-CHA-L2 | I16: REG-LF-CHA | J16: INT-LF-CHA | K16: CG-BND-05 | L16: SOURCE EMPTY | M16: CONSTITUTED
A17: ST-LF-CON | B17: MS-LF | C17: LF-B | D17: CONTROL | E17: SUB-06 | F17: RIG-LF-CON | G17: MTH-LF-CON-L1 | H17: MTH-LF-CON-L2 | I17: REG-LF-CON | J17: INT-LF-CON | K17: CG-BND-01 | L17: SOURCE EMPTY | M17: CONSTITUTED
... A24: ST-RT-REC | B24: MS-RT | C24: RT-B | D24: RECONSTRUCTION | E24: SUB-04 | F24: RIG-RT-REC | G24: MTH-RT-REC-L1 | H24: MTH-RT-REC-L2 | I24: REG-RT-REC | J24: INT-RT-REC | K24: CG-BND-05 | L24: SOURCE EMPTY | M24: CONSTITUTED

Sheet Control Groups
A2: Forty-eight beneficial-control groups
A4: Control is tested through beneficial ownership, debt, decisive subcontractors, tooling, keys, calibration and accepting personnel—not prime names.
A6: Group | B6: Control class | C6: Permitted work | D6: Lot cap | E6: Assigned lots | F6: Headroom | G6: Cap state | H6: Controller identity | I6: Cross-class control | J6: Rule
A7: CG-CAN-ET | B7: Candidate | C7: private mechanism | D7: 1 | E7: 1 | F7: =D7-E7 -> 0 | G7: =IF(F7>=0,"PASS","FAIL") -> PASS | H7: SOURCE EMPTY | I7: NO | J7: one Root House; no public lot in system
A8: CG-CAN-CT | B8: Candidate | C8: private mechanism | D8: 1 | E8: 1 | F8: =D8-E8 -> 0 | G8: =IF(F8>=0,"PASS","FAIL") -> PASS | H8: SOURCE EMPTY | I8: NO | J8: one Root House; no public lot in system
A9: CG-CAN-HC | B9: Candidate | C9: private mechanism | D9: 1 | E9: 1 | F9: =D9-E9 -> 0 | G9: =IF(F9>=0,"PASS","FAIL") -> PASS | H9: SOURCE EMPTY | I9: NO | J9: one Root House; no public lot in system
A10: CG-CAN-LF | B10: Candidate | C10: private mechanism | D10: 1 | E10: 1 | F10: =D10-E10 -> 0 | G10: =IF(F10>=0,"PASS","FAIL") -> PASS | H10: SOURCE EMPTY | I10: NO | J10: one Root House; no public lot in system
A11: CG-CAN-HU | B11: Candidate | C11: private mechanism | D11: 1 | E11: 1 | F11: =D11-E11 -> 0 | G11: =IF(F11>=0,"PASS","FAIL") -> PASS | H11: SOURCE EMPTY | I11: NO | J11: one Root House; no public lot in system
A12: CG-CAN-RT | B12: Candidate | C12: private mechanism | D12: 1 | E12: 1 | F12: =D12-E12 -> 0 | G12: =IF(F12>=0,"PASS","FAIL") -> PASS | H12: SOURCE EMPTY | I12: NO | J12: one Root House; no public lot in system
A13: CG-DEC-RIG-CHA-01 | B13: Public decisive | C13: RIG | D13: 2 | E13: 2 | F13: =D13-E13 -> 0 | G13: =IF(F13>=0,"PASS","FAIL") -> PASS | H13: SOURCE EMPTY | I13: NO | J13: different systems; one class and role
A14: CG-DEC-RIG-CHA-02 | B14: Public decisive | C14: RIG | D14: 2 | E14: 2 | F14: =D14-E14 -> 0 | G14: =IF(F14>=0,"PASS","FAIL") -> PASS | H14: SOURCE EMPTY | I14: NO | J14: different systems; one class and role
A15: CG-DEC-RIG-CHA-03 | B15: Public decisive | C15: RIG | D15: 2 | E15: 2 | F15: =D15-E15 -> 0 | G15: =IF(F15>=0,"PASS","FAIL") -> PASS | H15: SOURCE EMPTY | I15: NO | J15: different systems; one class and role
A16: CG-DEC-RIG-CON-01 | B16: Public decisive | C16: RIG | D16: 2 | E16: 2 | F16: =D16-E16 -> 0 | G16: =IF(F16>=0,"PASS","FAIL") -> PASS | H16: SOURCE EMPTY | I16: NO | J16: different systems; one class and role
A17: CG-DEC-RIG-CON-02 | B17: Public decisive | C17: RIG | D17: 2 | E17: 2 | F17: =D17-E17 -> 0 | G17: =IF(F17>=0,"PASS","FAIL") -> PASS | H17: SOURCE EMPTY | I17: NO | J17: different systems; one class and role
A18: CG-DEC-RIG-CON-03 | B18: Public decisive | C18: RIG | D18: 2 | E18: 2 | F18: =D18-E18 -> 0 | G18: =IF(F18>=0,"PASS","FAIL") -> PASS | H18: SOURCE EMPTY | I18: NO | J18: different systems; one class and role
... A54: CG-BND-06 | B54: Public boundary | C54: substrate + integration | D54: 4 | E54: 4 | F54: =D54-E54 -> 0 | G54: =IF(F54>=0,"PASS","FAIL") -> PASS | H54: SOURCE EMPTY | I54: NO | J54: no same-station substrate and integration

Sheet Collision Rules
A2: Industrial firewalls that survive nominal subcontracting
A4: The national slate must pass every rule before any partial award; later corporate transactions reopen the complete slate.
A6: ID | B6: Scope | C6: Rule | D6: Test object | E6: Violation action | F6: May waiver fix it? | G6: State
A7: C01 | B7: candidate | C7: one beneficial-control group per selected Root House | D7: owner, debt, keys, tooling | E7: reject slate | F7: NO | G7: FROZEN
A8: C02 | B8: candidate/public | C8: candidate controller holds no public lot in its system | D8: all controlled affiliates | E8: reject slate | F8: NO | G8: FROZEN
A9: C03 | B9: decisive public | C9: maximum two lots nationally | D9: beneficial-control group | E9: reject excess lots | F9: NO | G9: FROZEN
A10: C04 | B10: decisive public | C10: no two controlled lots in one system | D10: system ancestry | E10: reject slate | F10: NO | G10: FROZEN
A11: C05 | B11: method | C11: one controller may not hold both L1 and L2 | D11: method lineage | E11: reject slate | F11: NO | G11: FROZEN
A12: C06 | B12: station | C12: rig and regeneration may not share control | D12: station ancestry | E12: reject slate | F12: NO | G12: FROZEN
A13: C07 | B13: boundary | C13: substrate and integration at one station may not share control | D13: station boundary | E13: reject slate | F13: NO | G13: FROZEN
A14: C08 | B14: cross-class | C14: candidate, public decisive and public boundary classes do not cross-control | D14: complete group map | E14: reject slate | F14: NO | G14: FROZEN
A15: C09 | B15: subtier | C15: decisive subcontractor obeys the prime cap | D15: subtier control graph | E15: replace dependency | F15: NO | G15: FROZEN
A16: C10 | B16: toolchain | C16: executable compiler, calibration or key that changes outcome is decisive | D16: artifact ancestry | E16: split implementation | F16: NO | G16: FROZEN
A17: C11 | B17: commodity | C17: common item is allowed only when incapable of changing outcome | D17: failure and tuning envelope | E17: reclassify or split | F17: NO | G17: FROZEN
A18: C12 | B18: acceptance | C18: builder and integrator sign no acceptance decision on their own lot | D18: signer graph | E18: invalidate acceptance | F18: NO | G18: FROZEN

Sheet Method Lots
A2: Thirty-six unlike physical method-lineage lots
A4: Each lineage realizes all four receiver-state bays at one station. L1 and L2 never share beneficial control, decisive tooling or accepting personnel.
A6: Lot | B6: Station | C6: System | D6: Root | E6: Role | F6: Lineage | G6: Receiver-state bays | H6: Control group | I6: Authority USD B | J6: Realization identity | K6: Accepted bays | L6: State
A7: MTH-ET-CHA-L1 | B7: ST-ET-CHA | C7: MS-ET | D7: ET-A | E7: CHALLENGE | F7: L1 | G7: 4 | H7: CG-DEC-M1-CHA-01 | I7: 0.09 | J7: SOURCE EMPTY | K7: 0 | L7: HELD
A8: MTH-ET-CHA-L2 | B8: ST-ET-CHA | C8: MS-ET | D8: ET-A | E8: CHALLENGE | F8: L2 | G8: 4 | H8: CG-DEC-M2-CHA-01 | I8: 0.09 | J8: SOURCE EMPTY | K8: 0 | L8: HELD
A9: MTH-ET-CON-L1 | B9: ST-ET-CON | C9: MS-ET | D9: ET-A | E9: CONTROL | F9: L1 | G9: 4 | H9: CG-DEC-M1-CON-01 | I9: 0.09 | J9: SOURCE EMPTY | K9: 0 | L9: HELD
A10: MTH-ET-CON-L2 | B10: ST-ET-CON | C10: MS-ET | D10: ET-A | E10: CONTROL | F10: L2 | G10: 4 | H10: CG-DEC-M2-CON-01 | I10: 0.09 | J10: SOURCE EMPTY | K10: 0 | L10: HELD
A11: MTH-ET-REC-L1 | B11: ST-ET-REC | C11: MS-ET | D11: ET-A | E11: RECONSTRUCTION | F11: L1 | G11: 4 | H11: CG-DEC-M1-REC-01 | I11: 0.09 | J11: SOURCE EMPTY | K11: 0 | L11: HELD
A12: MTH-ET-REC-L2 | B12: ST-ET-REC | C12: MS-ET | D12: ET-A | E12: RECONSTRUCTION | F12: L2 | G12: 4 | H12: CG-DEC-M2-REC-01 | I12: 0.09 | J12: SOURCE EMPTY | K12: 0 | L12: HELD
A13: MTH-CT-CHA-L1 | B13: ST-CT-CHA | C13: MS-CT | D13: CT-C | E13: CHALLENGE | F13: L1 | G13: 4 | H13: CG-DEC-M1-CHA-02 | I13: 0.09 | J13: SOURCE EMPTY | K13: 0 | L13: HELD
A14: MTH-CT-CHA-L2 | B14: ST-CT-CHA | C14: MS-CT | D14: CT-C | E14: CHALLENGE | F14: L2 | G14: 4 | H14: CG-DEC-M2-CHA-02 | I14: 0.09 | J14: SOURCE EMPTY | K14: 0 | L14: HELD
A15: MTH-CT-CON-L1 | B15: ST-CT-CON | C15: MS-CT | D15: CT-C | E15: CONTROL | F15: L1 | G15: 4 | H15: CG-DEC-M1-CON-02 | I15: 0.09 | J15: SOURCE EMPTY | K15: 0 | L15: HELD
A16: MTH-CT-CON-L2 | B16: ST-CT-CON | C16: MS-CT | D16: CT-C | E16: CONTROL | F16: L2 | G16: 4 | H16: CG-DEC-M2-CON-02 | I16: 0.09 | J16: SOURCE EMPTY | K16: 0 | L16: HELD
A17: MTH-CT-REC-L1 | B17: ST-CT-REC | C17: MS-CT | D17: CT-C | E17: RECONSTRUCTION | F17: L1 | G17: 4 | H17: CG-DEC-M1-REC-02 | I17: 0.09 | J17: SOURCE EMPTY | K17: 0 | L17: HELD
A18: MTH-CT-REC-L2 | B18: ST-CT-REC | C18: MS-CT | D18: CT-C | E18: RECONSTRUCTION | F18: L2 | G18: 4 | H18: CG-DEC-M2-REC-02 | I18: 0.09 | J18: SOURCE EMPTY | K18: 0 | L18: HELD
... A42: MTH-RT-REC-L2 | B42: ST-RT-REC | C42: MS-RT | D42: RT-B | E42: RECONSTRUCTION | F42: L2 | G42: 4 | H42: CG-DEC-M2-REC-03 | I42: 0.09 | J42: SOURCE EMPTY | K42: 0 | L42: HELD

Sheet Acceptance Packets
A2: Five hundred ten construction-acceptance packet records
A4: Every lot owes all five packet families. Source identity and acceptance remain empty or zero until a separately warranted physical record exists.
A6: Packet ID | B6: Lot ID | C6: Lot class | D6: System | E6: Station/package | F6: Packet family | G6: Required evidence | H6: Accepting authority | I6: Source identity | J6: Accepted | K6: State
A7: ="PKT-"&B7&"-CONFIGURATION" -> PKT-SUB-01-CONFIGURATION | B7: ='Lot Register'!A7 -> SUB-01 | C7: ='Lot Register'!B7 -> Civil substrate | D7: ='Lot Register'!D7 -> MULTI | E7: ='Lot Register'!G7 -> ST-ET-CHA · ST-HC-REC · ST-HU-CON | F7: CONFIGURATION | G7: frozen requirement, materials, interfaces and as-built record | H7: Requirement issuer | I7: SOURCE EMPTY | J7: =Controls!B25 -> 0 | K7: =IF(J7=1,"ACCEPTED","OPEN") -> OPEN
A8: ="PKT-"&B8&"-CONTROL" -> PKT-SUB-01-CONTROL | B8: ='Lot Register'!A7 -> SUB-01 | C8: ='Lot Register'!B7 -> Civil substrate | D8: ='Lot Register'!D7 -> MULTI | E8: ='Lot Register'!G7 -> ST-ET-CHA · ST-HC-REC · ST-HU-CON | F8: CONTROL | G8: beneficial ownership, decisive ancestry, debt, tooling and key custody | H8: Control registrar | I8: SOURCE EMPTY | J8: =Controls!B25 -> 0 | K8: =IF(J8=1,"ACCEPTED","OPEN") -> OPEN
A9: ="PKT-"&B9&"-METROLOGY" -> PKT-SUB-01-METROLOGY | B9: ='Lot Register'!A7 -> SUB-01 | C9: ='Lot Register'!B7 -> Civil substrate | D9: ='Lot Register'!D7 -> MULTI | E9: ='Lot Register'!G7 -> ST-ET-CHA · ST-HC-REC · ST-HU-CON | F9: METROLOGY | G9: native commissioning, calibration chain and measurement uncertainty | H9: Commissioning authority | I9: SOURCE EMPTY | J9: =Controls!B25 -> 0 | K9: =IF(J9=1,"ACCEPTED","OPEN") -> OPEN
A10: ="PKT-"&B10&"-SAFETY" -> PKT-SUB-01-SAFETY | B10: ='Lot Register'!A7 -> SUB-01 | C10: ='Lot Register'!B7 -> Civil substrate | D10: ='Lot Register'!D7 -> MULTI | E10: ='Lot Register'!G7 -> ST-ET-CHA · ST-HC-REC · ST-HU-CON | F10: SAFETY | G10: worker, civil-rights, environmental, residual and safe-stop record | H10: Safety and rights authority | I10: SOURCE EMPTY | J10: =Controls!B25 -> 0 | K10: =IF(J10=1,"ACCEPTED","OPEN") -> OPEN
A11: ="PKT-"&B11&"-RECONSTRUCTION" -> PKT-SUB-01-RECONSTRUCTION | B11: ='Lot Register'!A7 -> SUB-01 | C11: ='Lot Register'!B7 -> Civil substrate | D11: ='Lot Register'!D7 -> MULTI | E11: ='Lot Register'!G7 -> ST-ET-CHA · ST-HC-REC · ST-HU-CON | F11: RECONSTRUCTION | G11: sealed custody, cold build description and outside-team replay | H11: Evidence Court | I11: SOURCE EMPTY | J11: =Controls!B25 -> 0 | K11: =IF(J11=1,"ACCEPTED","OPEN") -> OPEN
A12: ="PKT-"&B12&"-CONFIGURATION" -> PKT-SUB-02-CONFIGURATION | B12: ='Lot Register'!A8 -> SUB-02 | C12: ='Lot Register'!B8 -> Civil substrate | D12: ='Lot Register'!D8 -> MULTI | E12: ='Lot Register'!G8 -> ST-CT-CHA · ST-LF-REC · ST-RT-CON | F12: CONFIGURATION | G12: frozen requirement, materials, interfaces and as-built record | H12: Requirement issuer | I12: SOURCE EMPTY | J12: =Controls!B25 -> 0 | K12: =IF(J12=1,"ACCEPTED","OPEN") -> OPEN
A13: ="PKT-"&B13&"-CONTROL" -> PKT-SUB-02-CONTROL | B13: ='Lot Register'!A8 -> SUB-02 | C13: ='Lot Register'!B8 -> Civil substrate | D13: ='Lot Register'!D8 -> MULTI | E13: ='Lot Register'!G8 -> ST-CT-CHA · ST-LF-REC · ST-RT-CON | F13: CONTROL | G13: beneficial ownership, decisive ancestry, debt, tooling and key custody | H13: Control registrar | I13: SOURCE EMPTY | J13: =Controls!B25 -> 0 | K13: =IF(J13=1,"ACCEPTED","OPEN") -> OPEN
A14: ="PKT-"&B14&"-METROLOGY" -> PKT-SUB-02-METROLOGY | B14: ='Lot Register'!A8 -> SUB-02 | C14: ='Lot Register'!B8 -> Civil substrate | D14: ='Lot Register'!D8 -> MULTI | E14: ='Lot Register'!G8 -> ST-CT-CHA · ST-LF-REC · ST-RT-CON | F14: METROLOGY | G14: native commissioning, calibration chain and measurement uncertainty | H14: Commissioning authority | I14: SOURCE EMPTY | J14: =Controls!B25 -> 0 | K14: =IF(J14=1,"ACCEPTED","OPEN") -> OPEN
A15: ="PKT-"&B15&"-SAFETY" -> PKT-SUB-02-SAFETY | B15: ='Lot Register'!A8 -> SUB-02 | C15: ='Lot Register'!B8 -> Civil substrate | D15: ='Lot Register'!D8 -> MULTI | E15: ='Lot Register'!G8 -> ST-CT-CHA · ST-LF-REC · ST-RT-CON | F15: SAFETY | G15: worker, civil-rights, environmental, residual and safe-stop record | H15: Safety and rights authority | I15: SOURCE EMPTY | J15: =Controls!B25 -> 0 | K15: =IF(J15=1,"ACCEPTED","OPEN") -> OPEN
A16: ="PKT-"&B16&"-RECONSTRUCTION" -> PKT-SUB-02-RECONSTRUCTION | B16: ='Lot Register'!A8 -> SUB-02 | C16: ='Lot Register'!B8 -> Civil substrate | D16: ='Lot Register'!D8 -> MULTI | E16: ='Lot Register'!G8 -> ST-CT-CHA · ST-LF-REC · ST-RT-CON | F16: RECONSTRUCTION | G16: sealed custody, cold build description and outside-team replay | H16: Evidence Court | I16: SOURCE EMPTY | J16: =Controls!B25 -> 0 | K16: =IF(J16=1,"ACCEPTED","OPEN") -> OPEN
A17: ="PKT-"&B17&"-CONFIGURATION" -> PKT-SUB-03-CONFIGURATION | B17: ='Lot Register'!A9 -> SUB-03 | C17: ='Lot Register'!B9 -> Civil substrate | D17: ='Lot Register'!D9 -> MULTI | E17: ='Lot Register'!G9 -> ST-ET-CON · ST-HC-CHA · ST-HU-REC | F17: CONFIGURATION | G17: frozen requirement, materials, interfaces and as-built record | H17: Requirement issuer | I17: SOURCE EMPTY | J17: =Controls!B25 -> 0 | K17: =IF(J17=1,"ACCEPTED","OPEN") -> OPEN
A18: ="PKT-"&B18&"-CONTROL" -> PKT-SUB-03-CONTROL | B18: ='Lot Register'!A9 -> SUB-03 | C18: ='Lot Register'!B9 -> Civil substrate | D18: ='Lot Register'!D9 -> MULTI | E18: ='Lot Register'!G9 -> ST-ET-CON · ST-HC-CHA · ST-HU-REC | F18: CONTROL | G18: beneficial ownership, decisive ancestry, debt, tooling and key custody | H18: Control registrar | I18: SOURCE EMPTY | J18: =Controls!B25 -> 0 | K18: =IF(J18=1,"ACCEPTED","OPEN") -> OPEN
A19: ="PKT-"&B19&"-METROLOGY" -> PKT-SUB-03-METROLOGY | B19: ='Lot Register'!A9 -> SUB-03 | C19: ='Lot Register'!B9 -> Civil substrate | D19: ='Lot Register'!D9 -> MULTI | E19: ='Lot Register'!G9 -> ST-ET-CON · ST-HC-CHA · ST-HU-REC | F19: METROLOGY | G19: native commissioning, calibration chain and measurement uncertainty | H19: Commissioning authority | I19: SOURCE EMPTY | J19: =Controls!B25 -> 0 | K19: =IF(J19=1,"ACCEPTED","OPEN") -> OPEN
A20: ="PKT-"&B20&"-SAFETY" -> PKT-SUB-03-SAFETY | B20: ='Lot Register'!A9 -> SUB-03 | C20: ='Lot Register'!B9 -> Civil substrate | D20: ='Lot Register'!D9 -> MULTI | E20: ='Lot Register'!G9 -> ST-ET-CON · ST-HC-CHA · ST-HU-REC | F20: SAFETY | G20: worker, civil-rights, environmental, residual and safe-stop record | H20: Safety and rights authority | I20: SOURCE EMPTY | J20: =Controls!B25 -> 0 | K20: =IF(J20=1,"ACCEPTED","OPEN") -> OPEN
A21: ="PKT-"&B21&"-RECONSTRUCTION" -> PKT-SUB-03-RECONSTRUCTION | B21: ='Lot Register'!A9 -> SUB-03 | C21: ='Lot Register'!B9 -> Civil substrate | D21: ='Lot Register'!D9 -> MULTI | E21: ='Lot Register'!G9 -> ST-ET-CON · ST-HC-CHA · ST-HU-REC | F21: RECONSTRUCTION | G21: sealed custody, cold build description and outside-team replay | H21: Evidence Court | I21: SOURCE EMPTY | J21: =Controls!B25 -> 0 | K21: =IF(J21=1,"ACCEPTED","OPEN") -> OPEN
A22: ="PKT-"&B22&"-CONFIGURATION" -> PKT-SUB-04-CONFIGURATION | B22: ='Lot Register'!A10 -> SUB-04 | C22: ='Lot Register'!B10 -> Civil substrate | D22: ='Lot Register'!D10 -> MULTI | E22: ='Lot Register'!G10 -> ST-CT-CON · ST-LF-CHA · ST-RT-REC | F22: CONFIGURATION | G22: frozen requirement, materials, interfaces and as-built record | H22: Requirement issuer | I22: SOURCE EMPTY | J22: =Controls!B25 -> 0 | K22: =IF(J22=1,"ACCEPTED","OPEN") -> OPEN
A23: ="PKT-"&B23&"-CONTROL" -> PKT-SUB-04-CONTROL | B23: ='Lot Register'!A10 -> SUB-04 | C23: ='Lot Register'!B10 -> Civil substrate | D23: ='Lot Register'!D10 -> MULTI | E23: ='Lot Register'!G10 -> ST-CT-CON · ST-LF-CHA · ST-RT-REC | F23: CONTROL | G23: beneficial ownership, decisive ancestry, debt, tooling and key custody | H23: Control registrar | I23: SOURCE EMPTY | J23: =Controls!B25 -> 0 | K23: =IF(J23=1,"ACCEPTED","OPEN") -> OPEN
A24: ="PKT-"&B24&"-METROLOGY" -> PKT-SUB-04-METROLOGY | B24: ='Lot Register'!A10 -> SUB-04 | C24: ='Lot Register'!B10 -> Civil substrate | D24: ='Lot Register'!D10 -> MULTI | E24: ='Lot Register'!G10 -> ST-CT-CON · ST-LF-CHA · ST-RT-REC | F24: METROLOGY | G24: native commissioning, calibration chain and measurement uncertainty | H24: Commissioning authority | I24: SOURCE EMPTY | J24: =Controls!B25 -> 0 | K24: =IF(J24=1,"ACCEPTED","OPEN") -> OPEN
A25: ="PKT-"&B25&"-SAFETY" -> PKT-SUB-04-SAFETY | B25: ='Lot Register'!A10 -> SUB-04 | C25: ='Lot Register'!B10 -> Civil substrate | D25: ='Lot Register'!D10 -> MULTI | E25: ='Lot Register'!G10 -> ST-CT-CON · ST-LF-CHA · ST-RT-REC | F25: SAFETY | G25: worker, civil-rights, environmental, residual and safe-stop record | H25: Safety and rights authority | I25: SOURCE EMPTY | J25: =Controls!B25 -> 0 | K25: =IF(J25=1,"ACCEPTED","OPEN") -> OPEN
A26: ="PKT-"&B26&"-RECONSTRUCTION" -> PKT-SUB-04-RECONSTRUCTION | B26: ='Lot Register'!A10 -> SUB-04 | C26: ='Lot Register'!B10 -> Civil substrate | D26: ='Lot Register'!D10 -> MULTI | E26: ='Lot Register'!G10 -> ST-CT-CON · ST-LF-CHA · ST-RT-REC | F26: RECONSTRUCTION | G26: sealed custody, cold build description and outside-team replay | H26: Evidence Court | I26: SOURCE EMPTY | J26: =Controls!B25 -> 0 | K26: =IF(J26=1,"ACCEPTED","OPEN") -> OPEN
A27: ="PKT-"&B27&"-CONFIGURATION" -> PKT-SUB-05-CONFIGURATION | B27: ='Lot Register'!A11 -> SUB-05 | C27: ='Lot Register'!B11 -> Civil substrate | D27: ='Lot Register'!D11 -> MULTI | E27: ='Lot Register'!G11 -> ST-ET-REC · ST-HC-CON · ST-HU-CHA | F27: CONFIGURATION | G27: frozen requirement, materials, interfaces and as-built record | H27: Requirement issuer | I27: SOURCE EMPTY | J27: =Controls!B25 -> 0 | K27: =IF(J27=1,"ACCEPTED","OPEN") -> OPEN
A28: ="PKT-"&B28&"-CONTROL" -> PKT-SUB-05-CONTROL | B28: ='Lot Register'!A11 -> SUB-05 | C28: ='Lot Register'!B11 -> Civil substrate | D28: ='Lot Register'!D11 -> MULTI | E28: ='Lot Register'!G11 -> ST-ET-REC · ST-HC-CON · ST-HU-CHA | F28: CONTROL | G28: beneficial ownership, decisive ancestry, debt, tooling and key custody | H28: Control registrar | I28: SOURCE EMPTY | J28: =Controls!B25 -> 0 | K28: =IF(J28=1,"ACCEPTED","OPEN") -> OPEN
A29: ="PKT-"&B29&"-METROLOGY" -> PKT-SUB-05-METROLOGY | B29: ='Lot Register'!A11 -> SUB-05 | C29: ='Lot Register'!B11 -> Civil substrate | D29: ='Lot Register'!D11 -> MULTI | E29: ='Lot Register'!G11 -> ST-ET-REC · ST-HC-CON · ST-HU-CHA | F29: METROLOGY | G29: native commissioning, calibration chain and measurement uncertainty | H29: Commissioning authority | I29: SOURCE EMPTY | J29: =Controls!B25 -> 0 | K29: =IF(J29=1,"ACCEPTED","OPEN") -> OPEN
A30: ="PKT-"&B30&"-SAFETY" -> PKT-SUB-05-SAFETY | B30: ='Lot Register'!A11 -> SUB-05 | C30: ='Lot Register'!B11 -> Civil substrate | D30: ='Lot Register'!D11 -> MULTI | E30: ='Lot Register'!G11 -> ST-ET-REC · ST-HC-CON · ST-HU-CHA | F30: SAFETY | G30: worker, civil-rights, environmental, residual and safe-stop record | H30: Safety and rights authority | I30: SOURCE EMPTY | J30: =Controls!B25 -> 0 | K30: =IF(J30=1,"ACCEPTED","OPEN") -> OPEN
A31: ="PKT-"&B31&"-RECONSTRUCTION" -> PKT-SUB-05-RECONSTRUCTION | B31: ='Lot Register'!A11 -> SUB-05 | C31: ='Lot Register'!B11 -> Civil substrate | D31: ='Lot Register'!D11 -> MULTI | E31: ='Lot Register'!G11 -> ST-ET-REC · ST-HC-CON · ST-HU-CHA | F31: RECONSTRUCTION | G31: sealed custody, cold build description and outside-team replay | H31: Evidence Court | I31: SOURCE EMPTY | J31: =Controls!B25 -> 0 | K31: =IF(J31=1,"ACCEPTED","OPEN") -> OPEN
A32: ="PKT-"&B32&"-CONFIGURATION" -> PKT-SUB-06-CONFIGURATION | B32: ='Lot Register'!A12 -> SUB-06 | C32: ='Lot Register'!B12 -> Civil substrate | D32: ='Lot Register'!D12 -> MULTI | E32: ='Lot Register'!G12 -> ST-CT-REC · ST-LF-CON · ST-RT-CHA | F32: CONFIGURATION | G32: frozen requirement, materials, interfaces and as-built record | H32: Requirement issuer | I32: SOURCE EMPTY | J32: =Controls!B25 -> 0 | K32: =IF(J32=1,"ACCEPTED","OPEN") -> OPEN
A33: ="PKT-"&B33&"-CONTROL" -> PKT-SUB-06-CONTROL | B33: ='Lot Register'!A12 -> SUB-06 | C33: ='Lot Register'!B12 -> Civil substrate | D33: ='Lot Register'!D12 -> MULTI | E33: ='Lot Register'!G12 -> ST-CT-REC · ST-LF-CON · ST-RT-CHA | F33: CONTROL | G33: beneficial ownership, decisive ancestry, debt, tooling and key custody | H33: Control registrar | I33: SOURCE EMPTY | J33: =Controls!B25 -> 0 | K33: =IF(J33=1,"ACCEPTED","OPEN") -> OPEN
A34: ="PKT-"&B34&"-METROLOGY" -> PKT-SUB-06-METROLOGY | B34: ='Lot Register'!A12 -> SUB-06 | C34: ='Lot Register'!B12 -> Civil substrate | D34: ='Lot Register'!D12 -> MULTI | E34: ='Lot Register'!G12 -> ST-CT-REC · ST-LF-CON · ST-RT-CHA | F34: METROLOGY | G34: native commissioning, calibration chain and measurement uncertainty | H34: Commissioning authority | I34: SOURCE EMPTY | J34: =Controls!B25 -> 0 | K34: =IF(J34=1,"ACCEPTED","OPEN") -> OPEN
A35: ="PKT-"&B35&"-SAFETY" -> PKT-SUB-06-SAFETY | B35: ='Lot Register'!A12 -> SUB-06 | C35: ='Lot Register'!B12 -> Civil substrate | D35: ='Lot Register'!D12 -> MULTI | E35: ='Lot Register'!G12 -> ST-CT-REC · ST-LF-CON · ST-RT-CHA | F35: SAFETY | G35: worker, civil-rights, environmental, residual and safe-stop record | H35: Safety and rights authority | I35: SOURCE EMPTY | J35: =Controls!B25 -> 0 | K35: =IF(J35=1,"ACCEPTED","OPEN") -> OPEN
A36: ="PKT-"&B36&"-RECONSTRUCTION" -> PKT-SUB-06-RECONSTRUCTION | B36: ='Lot Register'!A12 -> SUB-06 | C36: ='Lot Register'!B12 -> Civil substrate | D36: ='Lot Register'!D12 -> MULTI | E36: ='Lot Register'!G12 -> ST-CT-REC · ST-LF-CON · ST-RT-CHA | F36: RECONSTRUCTION | G36: sealed custody, cold build description and outside-team replay | H36: Evidence Court | I36: SOURCE EMPTY | J36: =Controls!B25 -> 0 | K36: =IF(J36=1,"ACCEPTED","OPEN") -> OPEN
A37: ="PKT-"&B37&"-CONFIGURATION" -> PKT-RIG-ET-CHA-CONFIGURATION | B37: ='Lot Register'!A13 -> RIG-ET-CHA | C37: ='Lot Register'!B13 -> Root-native rig | D37: ='Lot Register'!D13 -> MS-ET | E37: ='Lot Register'!G13 -> ST-ET-CHA | F37: CONFIGURATION | G37: frozen requirement, materials, interfaces and as-built record | H37: Requirement issuer | I37: SOURCE EMPTY | J37: =Controls!B25 -> 0 | K37: =IF(J37=1,"ACCEPTED","OPEN") -> OPEN
A38: ="PKT-"&B38&"-CONTROL" -> PKT-RIG-ET-CHA-CONTROL | B38: ='Lot Register'!A13 -> RIG-ET-CHA | C38: ='Lot Register'!B13 -> Root-native rig | D38: ='Lot Register'!D13 -> MS-ET | E38: ='Lot Register'!G13 -> ST-ET-CHA | F38: CONTROL | G38: beneficial ownership, decisive ancestry, debt, tooling and key custody | H38: Control registrar | I38: SOURCE EMPTY | J38: =Controls!B25 -> 0 | K38: =IF(J38=1,"ACCEPTED","OPEN") -> OPEN
A39: ="PKT-"&B39&"-METROLOGY" -> PKT-RIG-ET-CHA-METROLOGY | B39: ='Lot Register'!A13 -> RIG-ET-CHA | C39: ='Lot Register'!B13 -> Root-native rig | D39: ='Lot Register'!D13 -> MS-ET | E39: ='Lot Register'!G13 -> ST-ET-CHA | F39: METROLOGY | G39: native commissioning, calibration chain and measurement uncertainty | H39: Commissioning authority | I39: SOURCE EMPTY | J39: =Controls!B25 -> 0 | K39: =IF(J39=1,"ACCEPTED","OPEN") -> OPEN
A40: ="PKT-"&B40&"-SAFETY" -> PKT-RIG-ET-CHA-SAFETY | B40: ='Lot Register'!A13 -> RIG-ET-CHA | C40: ='Lot Register'!B13 -> Root-native rig | D40: ='Lot Register'!D13 -> MS-ET | E40: ='Lot Register'!G13 -> ST-ET-CHA | F40: SAFETY | G40: worker, civil-rights, environmental, residual and safe-stop record | H40: Safety and rights authority | I40: SOURCE EMPTY | J40: =Controls!B25 -> 0 | K40: =IF(J40=1,"ACCEPTED","OPEN") -> OPEN
A41: ="PKT-"&B41&"-RECONSTRUCTION" -> PKT-RIG-ET-CHA-RECONSTRUCTION | B41: ='Lot Register'!A13 -> RIG-ET-CHA | C41: ='Lot Register'!B13 -> Root-native rig | D41: ='Lot Register'!D13 -> MS-ET | E41: ='Lot Register'!G13 -> ST-ET-CHA | F41: RECONSTRUCTION | G41: sealed custody, cold build description and outside-team replay | H41: Evidence Court | I41: SOURCE EMPTY | J41: =Controls!B25 -> 0 | K41: =IF(J41=1,"ACCEPTED","OPEN") -> OPEN
A42: ="PKT-"&B42&"-CONFIGURATION" -> PKT-MTH-ET-CHA-L1-CONFIGURATION | B42: ='Lot Register'!A14 -> MTH-ET-CHA-L1 | C42: ='Lot Register'!B14 -> Method lineage | D42: ='Lot Register'!D14 -> MS-ET | E42: ='Lot Register'!G14 -> ST-ET-CHA | F42: CONFIGURATION | G42: frozen requirement, materials, interfaces and as-built record | H42: Requirement issuer | I42: SOURCE EMPTY | J42: =Controls!B25 -> 0 | K42: =IF(J42=1,"ACCEPTED","OPEN") -> OPEN
A43: ="PKT-"&B43&"-CONTROL" -> PKT-MTH-ET-CHA-L1-CONTROL | B43: ='Lot Register'!A14 -> MTH-ET-CHA-L1 | C43: ='Lot Register'!B14 -> Method lineage | D43: ='Lot Register'!D14 -> MS-ET | E43: ='Lot Register'!G14 -> ST-ET-CHA | F43: CONTROL | G43: beneficial ownership, decisive ancestry, debt, tooling and key custody | H43: Control registrar | I43: SOURCE EMPTY | J43: =Controls!B25 -> 0 | K43: =IF(J43=1,"ACCEPTED","OPEN") -> OPEN
...

Sheet Acceptance Gates
A2: Seven hundred fourteen noncompensatory construction decisions
A4: One failed gate holds the lot. A valid adverse candidate result may be payable, but it cannot convert a failed construction gate into completion.
A6: Decision ID | B6: Lot ID | C6: Lot class | D6: System | E6: Station/package | F6: Gate | G6: Name | H6: Criterion | I6: Accepting authority | J6: Evidence identity | K6: Accepted | L6: State
A7: ="DEC-"&B7&"-G1" -> DEC-SUB-01-G1 | B7: ='Lot Register'!A7 -> SUB-01 | C7: ='Lot Register'!B7 -> Civil substrate | D7: ='Lot Register'!D7 -> MULTI | E7: ='Lot Register'!G7 -> ST-ET-CHA · ST-HC-REC · ST-HU-CON | F7: G1 | G7: IDENTITY | H7: identity and beneficial control admissible | I7: Control registrar | J7: SOURCE EMPTY | K7: =Controls!B26 -> 0 | L7: =IF(K7=1,"PASS","OPEN") -> OPEN
A8: ="DEC-"&B8&"-G2" -> DEC-SUB-01-G2 | B8: ='Lot Register'!A7 -> SUB-01 | C8: ='Lot Register'!B7 -> Civil substrate | D8: ='Lot Register'!D7 -> MULTI | E8: ='Lot Register'!G7 -> ST-ET-CHA · ST-HC-REC · ST-HU-CON | F8: G2 | G8: BASELINE | H8: issue baseline frozen without builder conversion | I8: Requirement issuer | J8: SOURCE EMPTY | K8: =Controls!B26 -> 0 | L8: =IF(K8=1,"PASS","OPEN") -> OPEN
A9: ="DEC-"&B9&"-G3" -> DEC-SUB-01-G3 | B9: ='Lot Register'!A7 -> SUB-01 | C9: ='Lot Register'!B7 -> Civil substrate | D9: ='Lot Register'!D7 -> MULTI | E9: ='Lot Register'!G7 -> ST-ET-CHA · ST-HC-REC · ST-HU-CON | F9: G3 | G9: AS-BUILT | H9: materials, interfaces and as-built state reconcile | I9: Commissioning authority | J9: SOURCE EMPTY | K9: =Controls!B26 -> 0 | L9: =IF(K9=1,"PASS","OPEN") -> OPEN
A10: ="DEC-"&B10&"-G4" -> DEC-SUB-01-G4 | B10: ='Lot Register'!A7 -> SUB-01 | C10: ='Lot Register'!B7 -> Civil substrate | D10: ='Lot Register'!D7 -> MULTI | E10: ='Lot Register'!G7 -> ST-ET-CHA · ST-HC-REC · ST-HU-CON | F10: G4 | G10: ISOLATION | H10: no forbidden common decisive path | I10: Control registrar | J10: SOURCE EMPTY | K10: =Controls!B26 -> 0 | L10: =IF(K10=1,"PASS","OPEN") -> OPEN
A11: ="DEC-"&B11&"-G5" -> DEC-SUB-01-G5 | B11: ='Lot Register'!A7 -> SUB-01 | C11: ='Lot Register'!B7 -> Civil substrate | D11: ='Lot Register'!D7 -> MULTI | E11: ='Lot Register'!G7 -> ST-ET-CHA · ST-HC-REC · ST-HU-CON | F11: G5 | G11: COMMISSION | H11: root-native commissioning closes | I11: Commissioning authority | J11: SOURCE EMPTY | K11: =Controls!B26 -> 0 | L11: =IF(K11=1,"PASS","OPEN") -> OPEN
A12: ="DEC-"&B12&"-G6" -> DEC-SUB-01-G6 | B12: ='Lot Register'!A7 -> SUB-01 | C12: ='Lot Register'!B7 -> Civil substrate | D12: ='Lot Register'!D7 -> MULTI | E12: ='Lot Register'!G7 -> ST-ET-CHA · ST-HC-REC · ST-HU-CON | F12: G6 | G12: DENIAL | H12: controlled denial or destructive witness is valid | I12: Evidence Court | J12: SOURCE EMPTY | K12: =Controls!B26 -> 0 | L12: =IF(K12=1,"PASS","OPEN") -> OPEN
A13: ="DEC-"&B13&"-G7" -> DEC-SUB-01-G7 | B13: ='Lot Register'!A7 -> SUB-01 | C13: ='Lot Register'!B7 -> Civil substrate | D13: ='Lot Register'!D7 -> MULTI | E13: ='Lot Register'!G7 -> ST-ET-CHA · ST-HC-REC · ST-HU-CON | F13: G7 | G13: COLD RETURN | H13: outside team reconstructs accepted state | I13: Evidence Court | J13: SOURCE EMPTY | K13: =Controls!B26 -> 0 | L13: =IF(K13=1,"PASS","OPEN") -> OPEN
A14: ="DEC-"&B14&"-G1" -> DEC-SUB-02-G1 | B14: ='Lot Register'!A8 -> SUB-02 | C14: ='Lot Register'!B8 -> Civil substrate | D14: ='Lot Register'!D8 -> MULTI | E14: ='Lot Register'!G8 -> ST-CT-CHA · ST-LF-REC · ST-RT-CON | F14: G1 | G14: IDENTITY | H14: identity and beneficial control admissible | I14: Control registrar | J14: SOURCE EMPTY | K14: =Controls!B26 -> 0 | L14: =IF(K14=1,"PASS","OPEN") -> OPEN
A15: ="DEC-"&B15&"-G2" -> DEC-SUB-02-G2 | B15: ='Lot Register'!A8 -> SUB-02 | C15: ='Lot Register'!B8 -> Civil substrate | D15: ='Lot Register'!D8 -> MULTI | E15: ='Lot Register'!G8 -> ST-CT-CHA · ST-LF-REC · ST-RT-CON | F15: G2 | G15: BASELINE | H15: issue baseline frozen without builder conversion | I15: Requirement issuer | J15: SOURCE EMPTY | K15: =Controls!B26 -> 0 | L15: =IF(K15=1,"PASS","OPEN") -> OPEN
A16: ="DEC-"&B16&"-G3" -> DEC-SUB-02-G3 | B16: ='Lot Register'!A8 -> SUB-02 | C16: ='Lot Register'!B8 -> Civil substrate | D16: ='Lot Register'!D8 -> MULTI | E16: ='Lot Register'!G8 -> ST-CT-CHA · ST-LF-REC · ST-RT-CON | F16: G3 | G16: AS-BUILT | H16: materials, interfaces and as-built state reconcile | I16: Commissioning authority | J16: SOURCE EMPTY | K16: =Controls!B26 -> 0 | L16: =IF(K16=1,"PASS","OPEN") -> OPEN
A17: ="DEC-"&B17&"-G4" -> DEC-SUB-02-G4 | B17: ='Lot Register'!A8 -> SUB-02 | C17: ='Lot Register'!B8 -> Civil substrate | D17: ='Lot Register'!D8 -> MULTI | E17: ='Lot Register'!G8 -> ST-CT-CHA · ST-LF-REC · ST-RT-CON | F17: G4 | G17: ISOLATION | H17: no forbidden common decisive path | I17: Control registrar | J17: SOURCE EMPTY | K17: =Controls!B26 -> 0 | L17: =IF(K17=1,"PASS","OPEN") -> OPEN
A18: ="DEC-"&B18&"-G5" -> DEC-SUB-02-G5 | B18: ='Lot Register'!A8 -> SUB-02 | C18: ='Lot Register'!B8 -> Civil substrate | D18: ='Lot Register'!D8 -> MULTI | E18: ='Lot Register'!G8 -> ST-CT-CHA · ST-LF-REC · ST-RT-CON | F18: G5 | G18: COMMISSION | H18: root-native commissioning closes | I18: Commissioning authority | J18: SOURCE EMPTY | K18: =Controls!B26 -> 0 | L18: =IF(K18=1,"PASS","OPEN") -> OPEN
A19: ="DEC-"&B19&"-G6" -> DEC-SUB-02-G6 | B19: ='Lot Register'!A8 -> SUB-02 | C19: ='Lot Register'!B8 -> Civil substrate | D19: ='Lot Register'!D8 -> MULTI | E19: ='Lot Register'!G8 -> ST-CT-CHA · ST-LF-REC · ST-RT-CON | F19: G6 | G19: DENIAL | H19: controlled denial or destructive witness is valid | I19: Evidence Court | J19: SOURCE EMPTY | K19: =Controls!B26 -> 0 | L19: =IF(K19=1,"PASS","OPEN") -> OPEN
