Workbook

Sheet Summary
A2: Artifact Validity Authority Terminal Compact
A4: AVA-TC reconciles funded design, reconstructability, estate availability, commissioning, validity and payment without creating evidence or production authority.
A6: Terminal decision | L6: Authority record | M6: Current count
L7: Issued learning warrants | M7: 18
A8: Selected compact | B8: AVA-TC | L8: Active form cells | M8: 6
A9: Verdict | B9: RETURN | L9: Active packages | M9: 30
A10: AVA branch | B10: 5 of 5 | L10: Artifact Validity Warrants | M10: 0
A11: Active packages | B11: 30 | L11: Finance Disbursement Warrants | M11: 0
A12: Validity gate records | B12: 360 | L12: Accepted observations | M12: 0
A13: Current gates passed | B13: 60 | L13: Selected forms | M13: 0
A14: Current AVWs | B14: 0 | L14: MAKE warrants | M14: 0
A15: Current FDWs | B15: 0 | L15: REP-4 records | M15: 0
A16: Current payments | B16: 0
A17: Running open items | B17: 0
A20: Controlling boundary
A22: Unit of validity | B22: one package; never a whole form
A23: Validity condition | B23: twelve gates plus dual reconstruction plus available estate and NDW
A24: Payment condition | B24: package AVW plus accepted milestone plus separate FDW
A25: Fatal condition | B25: common control, leakage, truth displacement or prohibited conversion
A26: Finance | B26: USD179M obligation; USD359M sibling reserve; USD540M nested capital ceiling
A27: Present fact | B27: thirty packages are funded work; no artifact, payment, evidence, MAKE or REP-4 exists
A30: Model status
A32: Candidate compacts | B32: 5
A33: Selected candidates | B33: =COUNTIFS('Decision Tests'!N7:N11,"SELECT") -> 1
A34: Separation rules | B34: 36
A35: Nonconversions | B35: 32
A36: Expiry routes | B36: 18
A37: Rollback routes | B37: 18
A38: Termination routes | B38: 16
A39: Stress worlds | B39: 40
A40: Stress results passing | B40: =COUNTIFS('Stress Worlds'!AC7:AC46,"PASS") -> 40

Sheet Decision Tests
A2: Terminal compact decision
A4: A candidate must pass every hard gate. Scores do not compensate for a failed constitutional boundary.
A6: Candidate | B6: Architecture | C6: Package-level validity | D6: Dual reconstruction | E6: Root-native courts | F6: Commissioned estate | G6: Separated payment | H6: Zero evidence conversion | I6: Common-control termination | J6: Explicit expiry | K6: Sibling reserve | L6: Terminal return | M6: Passed | N6: Disposition
A7: C1 | B7: Unified artifact office | C7: 1 | D7: 1 | E7: 0 | F7: 1 | G7: 0 | H7: 0 | I7: 0 | J7: 1 | K7: 1 | L7: 1 | M7: =SUM(C7:L7) -> 6 | N7: =IF(M7=10,"SELECT","REJECT") -> REJECT
A8: C2 | B8: Contract acceptance chain | C8: 1 | D8: 0 | E8: 0 | F8: 0 | G8: 0 | H8: 1 | I8: 0 | J8: 0 | K8: 1 | L8: 1 | M8: =SUM(C8:L8) -> 4 | N8: =IF(M8=10,"SELECT","REJECT") -> REJECT
A9: C3 | B9: Automated hash gate | C9: 1 | D9: 0 | E9: 0 | F9: 1 | G9: 1 | H9: 1 | I9: 1 | J9: 0 | K9: 1 | L9: 1 | M9: =SUM(C9:L9) -> 7 | N9: =IF(M9=10,"SELECT","REJECT") -> REJECT
A10: C4 | B10: Validity-to-evidence bridge | C10: 1 | D10: 1 | E10: 1 | F10: 1 | G10: 1 | H10: 0 | I10: 1 | J10: 1 | K10: 1 | L10: 1 | M10: =SUM(C10:L10) -> 9 | N10: =IF(M10=10,"SELECT","REJECT") -> REJECT
A11: C5 | B11: Federated typed-warrant compact | C11: 1 | D11: 1 | E11: 1 | F11: 1 | G11: 1 | H11: 1 | I11: 1 | J11: 1 | K11: 1 | L11: 1 | M11: =SUM(C11:L11) -> 10 | N11: =IF(M11=10,"SELECT","REJECT") -> SELECT
A14: Controlling interpretation
A16: Selected object | B16: AVA-TC | C16: Artifact Validity Authority Terminal Compact
A17: Integration rule | B17: Typed precedence | C17: A predecessor may be a prerequisite but never transfers its authority
A18: Terminal boundary | B18: RETURN | C18: The branch closes its only item, opens none and returns to the registered cohort-one parent
A19: Current effect | B19: ZERO | C19: No artifact, payment, observation, selection, MAKE or REP-4 authority advances

Sheet Precedence
A2: Typed precedence and warrant stack
A4: An instrument may consume a predecessor as a prerequisite. It cannot inherit any authority the predecessor did not possess.
A6: Order | B6: Instrument | C6: Source | D6: Unit | E6: Prerequisite | F6: Authority created | G6: Cannot create | H6: Expiry basis | I6: Current count | J6: Current state
A7: 1 | B7: Selection covenant | C7: Pass 225 | D7: 18 forms | E7: registered form | F7: future evidence disposition | G7: artifact validity or payment | H7: supersession | I7: 1 | J7: CONSTITUTED
A8: 2 | B8: Parallel FRAME authority | C8: Pass 226 | D8: 18 forms | E8: selection covenant | F8: bounded design eligibility | G8: obligation or selection | H8: warrant expiry | I8: 18 | J8: ISSUED
A9: 3 | B9: Balanced cohort schedule | C9: Pass 227 | D9: 3 cohorts | E9: issued warrants | F9: activation order | G9: performance priority | H9: schedule supersession | I9: 3 | J9: ACTIVE
A10: 4 | B10: Root safety-change route | C10: Pass 228 | D10: 6 roots | E10: source-blind burden | F10: root epoch translation | G10: relative performance | H10: epoch supersession | I10: 6 | J10: CONSTITUTED
A11: 5 | B11: CEW-1 | C11: Pass 229 | D11: 30 packages | E11: twelve form gates | F11: work and obligation | G11: artifact validity or payment | H11: cohort termination | I11: 1 | J11: ACTIVE
A12: 6 | B12: FSA-TC | C12: Pass 230 | D12: 1 compact | E12: five FSA decisions | F12: pre-evidence precedence | G12: evidence or selection | H12: parent supersession | I12: 1 | J12: AUTHORITATIVE
A13: 7 | B13: AVC-1 | C13: Pass 231 | D13: 30 packages | E13: active package | F13: validity and finance grammar | G13: physical correctness | H13: compact supersession | I13: 1 | J13: AUTHORITATIVE
A14: 8 | B14: DRG-1 | C14: Pass 232 | D14: 30 packages | E14: source capsule | F14: dual reconstruction | G14: physical evidence | H14: capsule supersession | I14: 1 | J14: AUTHORITATIVE
A15: 9 | B15: FAE-1 | C15: Pass 233 | D15: 6 roots | E15: estate topology | F15: failure-tolerant venue | G15: commissioning | H15: topology supersession | I15: 1 | J15: AUTHORITATIVE
A16: 10 | B16: CNW-1 | C16: Pass 234 | D16: 18 sites | E16: site docket | F16: commissioning route | G16: artifact validity | H16: NDW expiry | I16: 1 | J16: AUTHORITATIVE
A17: 11 | B17: Site admission | C17: AVA-TC | D17: 18 sites | E17: admitted place | F17: site identity | G17: independence | H17: site change | I17: 0 | J17: OPEN
A18: 12 | B18: Role appointment | C18: AVA-TC | D18: 96 posts | E18: control clearance | F18: bounded office | G18: key validity | H18: appointment expiry | I18: 0 | J18: OPEN
... A33: 27 | B33: REP-4 record | C33: Parent authority | D33: 18 forms | E33: as-built metrology authority | F33: bounded representation | G33: readiness | H33: record supersession | I33: 0 | J33: HELD

Sheet Package Register
A2: Cohort-one package register
A4: Thirty funded packages are active work. None is currently a valid artifact or payable claim.
A6: Package | B6: Form | C6: Root | D6: Family | E6: Work package | F6: Ceiling (USD M) | G6: Obligated | H6: Gates passed | I6: Capsule fields | J6: Native stages | K6: Clean stages | L6: Invariants | M6: AVW | N6: Package state
A7: P01 | B7: ET-A-A | C7: ET-A | D7: METHOD | E7: Event method and denominator | F7: 5.0047462 | G7: 1 | H7: =COUNTIFS('Validity Gates'!$B$7:$B$366,A7,'Validity Gates'!$H$7:$H$366,"PASS") -> 2 | I7: 0 | J7: 0 | K7: 0 | L7: 0 | M7: 0 | N7: =IF(M7=1,"VALID",IF(AND(G7=1,H7<12),"WORKING / VALIDITY OPEN","HELD")) -> WORKING / VALIDITY OPEN
A8: P02 | B8: ET-A-A | C8: ET-A | D8: MEASURE | E8: Instrumentation, custody and validity | F8: 6.2559327 | G8: 1 | H8: =COUNTIFS('Validity Gates'!$B$7:$B$366,A8,'Validity Gates'!$H$7:$H$366,"PASS") -> 2 | I8: 0 | J8: 0 | K8: 0 | L8: 0 | M8: 0 | N8: =IF(M8=1,"VALID",IF(AND(G8=1,H8<12),"WORKING / VALIDITY OPEN","HELD")) -> WORKING / VALIDITY OPEN
A9: P03 | B9: ET-A-A | C9: ET-A | D9: CIVIL | E9: Rights, receiver and residual closure | F9: 3.7535596 | G9: 1 | H9: =COUNTIFS('Validity Gates'!$B$7:$B$366,A9,'Validity Gates'!$H$7:$H$366,"PASS") -> 2 | I9: 0 | J9: 0 | K9: 0 | L9: 0 | M9: 0 | N9: =IF(M9=1,"VALID",IF(AND(G9=1,H9<12),"WORKING / VALIDITY OPEN","HELD")) -> WORKING / VALIDITY OPEN
A10: P04 | B10: ET-A-A | C10: ET-A | D10: ARTICLE | E10: Destructive-article engineering | F10: 6.2559327 | G10: 1 | H10: =COUNTIFS('Validity Gates'!$B$7:$B$366,A10,'Validity Gates'!$H$7:$H$366,"PASS") -> 2 | I10: 0 | J10: 0 | K10: 0 | L10: 0 | M10: 0 | N10: =IF(M10=1,"VALID",IF(AND(G10=1,H10<12),"WORKING / VALIDITY OPEN","HELD")) -> WORKING / VALIDITY OPEN
A11: P05 | B11: ET-A-A | C11: ET-A | D11: REBUILD | E11: Cold reconstruction and challenge | F11: 3.7535596 | G11: 1 | H11: =COUNTIFS('Validity Gates'!$B$7:$B$366,A11,'Validity Gates'!$H$7:$H$366,"PASS") -> 2 | I11: 0 | J11: 0 | K11: 0 | L11: 0 | M11: 0 | N11: =IF(M11=1,"VALID",IF(AND(G11=1,H11<12),"WORKING / VALIDITY OPEN","HELD")) -> WORKING / VALIDITY OPEN
A12: P06 | B12: CT-C-B | C12: CT-C | D12: METHOD | E12: Event method and denominator | F12: 5.1649348 | G12: 1 | H12: =COUNTIFS('Validity Gates'!$B$7:$B$366,A12,'Validity Gates'!$H$7:$H$366,"PASS") -> 2 | I12: 0 | J12: 0 | K12: 0 | L12: 0 | M12: 0 | N12: =IF(M12=1,"VALID",IF(AND(G12=1,H12<12),"WORKING / VALIDITY OPEN","HELD")) -> WORKING / VALIDITY OPEN
A13: P07 | B13: CT-C-B | C13: CT-C | D13: MEASURE | E13: Instrumentation, custody and validity | F13: 6.4561685 | G13: 1 | H13: =COUNTIFS('Validity Gates'!$B$7:$B$366,A13,'Validity Gates'!$H$7:$H$366,"PASS") -> 2 | I13: 0 | J13: 0 | K13: 0 | L13: 0 | M13: 0 | N13: =IF(M13=1,"VALID",IF(AND(G13=1,H13<12),"WORKING / VALIDITY OPEN","HELD")) -> WORKING / VALIDITY OPEN
A14: P08 | B14: CT-C-B | C14: CT-C | D14: CIVIL | E14: Rights, receiver and residual closure | F14: 3.8737011 | G14: 1 | H14: =COUNTIFS('Validity Gates'!$B$7:$B$366,A14,'Validity Gates'!$H$7:$H$366,"PASS") -> 2 | I14: 0 | J14: 0 | K14: 0 | L14: 0 | M14: 0 | N14: =IF(M14=1,"VALID",IF(AND(G14=1,H14<12),"WORKING / VALIDITY OPEN","HELD")) -> WORKING / VALIDITY OPEN
A15: P09 | B15: CT-C-B | C15: CT-C | D15: ARTICLE | E15: Destructive-article engineering | F15: 6.4561685 | G15: 1 | H15: =COUNTIFS('Validity Gates'!$B$7:$B$366,A15,'Validity Gates'!$H$7:$H$366,"PASS") -> 2 | I15: 0 | J15: 0 | K15: 0 | L15: 0 | M15: 0 | N15: =IF(M15=1,"VALID",IF(AND(G15=1,H15<12),"WORKING / VALIDITY OPEN","HELD")) -> WORKING / VALIDITY OPEN
A16: P10 | B16: CT-C-B | C16: CT-C | D16: REBUILD | E16: Cold reconstruction and challenge | F16: 3.8737011 | G16: 1 | H16: =COUNTIFS('Validity Gates'!$B$7:$B$366,A16,'Validity Gates'!$H$7:$H$366,"PASS") -> 2 | I16: 0 | J16: 0 | K16: 0 | L16: 0 | M16: 0 | N16: =IF(M16=1,"VALID",IF(AND(G16=1,H16<12),"WORKING / VALIDITY OPEN","HELD")) -> WORKING / VALIDITY OPEN
A17: P11 | B17: HC-A-C | C17: HC-A | D17: METHOD | E17: Event method and denominator | F17: 3.0722165 | G17: 1 | H17: =COUNTIFS('Validity Gates'!$B$7:$B$366,A17,'Validity Gates'!$H$7:$H$366,"PASS") -> 2 | I17: 0 | J17: 0 | K17: 0 | L17: 0 | M17: 0 | N17: =IF(M17=1,"VALID",IF(AND(G17=1,H17<12),"WORKING / VALIDITY OPEN","HELD")) -> WORKING / VALIDITY OPEN
A18: P12 | B18: HC-A-C | C18: HC-A | D18: MEASURE | E18: Instrumentation, custody and validity | F18: 3.8402707 | G18: 1 | H18: =COUNTIFS('Validity Gates'!$B$7:$B$366,A18,'Validity Gates'!$H$7:$H$366,"PASS") -> 2 | I18: 0 | J18: 0 | K18: 0 | L18: 0 | M18: 0 | N18: =IF(M18=1,"VALID",IF(AND(G18=1,H18<12),"WORKING / VALIDITY OPEN","HELD")) -> WORKING / VALIDITY OPEN
... A36: P30 | B36: RT-B-C | C36: RT-B | D36: REBUILD | E36: Cold reconstruction and challenge | F36: 3.7694834 | G36: 1 | H36: =COUNTIFS('Validity Gates'!$B$7:$B$366,A36,'Validity Gates'!$H$7:$H$366,"PASS") -> 2 | I36: 0 | J36: 0 | K36: 0 | L36: 0 | M36: 0 | N36: =IF(M36=1,"VALID",IF(AND(G36=1,H36<12),"WORKING / VALIDITY OPEN","HELD")) -> WORKING / VALIDITY OPEN

Sheet Validity Gates
A2: Package validity gates
A4: Twelve gates are noncompensatory. Only the sixty inherited constitutional gates pass; all package-content gates remain open.
A6: Record | B6: Package | C6: Gate | D6: Requirement | E6: Source | F6: Required | G6: Current | H6: Status
A7: VG001 | B7: P01 | C7: G01 | D7: Source manifest | E7: AVC-1 | F7: 1 | G7: 0 | H7: =IF(G7=F7,"PASS","OPEN") -> OPEN
A8: VG002 | B8: P01 | C8: G02 | D8: Frozen configuration hash | E8: AVC-1 | F8: 1 | G8: 0 | H8: =IF(G8=F8,"PASS","OPEN") -> OPEN
A9: VG003 | B9: P01 | C9: G03 | D9: Executable native artifact | E9: AVC-1 | F9: 1 | G9: 0 | H9: =IF(G9=F9,"PASS","OPEN") -> OPEN
A10: VG004 | B10: P01 | C10: G04 | D10: Dependency, tool and material ledger | E10: AVC-1 | F10: 1 | G10: 0 | H10: =IF(G10=F10,"PASS","OPEN") -> OPEN
A11: VG005 | B11: P01 | C11: G05 | D11: Assumptions and unknowns | E11: AVC-1 | F11: 1 | G11: 0 | H11: =IF(G11=F11,"PASS","OPEN") -> OPEN
A12: VG006 | B12: P01 | C12: G06 | D12: Independent clean-room replay | E12: AVC-1 / DRG-1 | F12: 1 | G12: 0 | H12: =IF(G12=F12,"PASS","OPEN") -> OPEN
A13: VG007 | B13: P01 | C13: G07 | D13: Interface and destructive-test trace | E13: AVC-1 | F13: 1 | G13: 0 | H13: =IF(G13=F13,"PASS","OPEN") -> OPEN
A14: VG008 | B14: P01 | C14: G08 | D14: Rights and safe-state closure | E14: AVC-1 | F14: 1 | G14: 0 | H14: =IF(G14=F14,"PASS","OPEN") -> OPEN
A15: VG009 | B15: P01 | C15: G09 | D15: Receiver and residual closure | E15: AVC-1 | F15: 1 | G15: 0 | H15: =IF(G15=F15,"PASS","OPEN") -> OPEN
A16: VG010 | B16: P01 | C16: G10 | D16: Challenge response and terminal archive | E16: AVC-1 | F16: 1 | G16: 0 | H16: =IF(G16=F16,"PASS","OPEN") -> OPEN
A17: VG011 | B17: P01 | C17: G11 | D17: No sibling performance exposure | E17: AVC-1 / FSA-TC | F17: 1 | G17: 1 | H17: =IF(G17=F17,"PASS","OPEN") -> PASS
A18: VG012 | B18: P01 | C18: G12 | D18: Separated builder-validity control | E18: AVC-1 / FSA-TC | F18: 1 | G18: 1 | H18: =IF(G18=F18,"PASS","OPEN") -> PASS
... A366: VG360 | B366: P30 | C366: G12 | D366: Separated builder-validity control | E366: AVC-1 / FSA-TC | F366: 1 | G366: 1 | H366: =IF(G366=F366,"PASS","OPEN") -> PASS

Sheet Claim Register
A2: Artifact payment claims
A4: A claim is payable only when submission, AVW, milestone acceptance and FDW are all present. Payment creates cash finality only.
A6: Claim | B6: Package | C6: Milestone | D6: Description | E6: Share | F6: Package ceiling | G6: Claim amount | H6: Submitted | I6: AVW | J6: Accepted | K6: FDW | L6: Paid | M6: State
A7: C001 | B7: P01 | C7: M1 | D7: Source capsule | E7: 0.1 | F7: 5.0047462 | G7: =E7*F7 -> 0.50047462 | H7: 0 | I7: 0 | J7: 0 | K7: 0 | L7: 0 | M7: =IF(AND(H7=1,I7=1,J7=1,K7=1),IF(L7=1,"PAID","PAYABLE"),"HELD") -> HELD
A8: C002 | B8: P01 | C8: M2 | D8: Executable causal ledger | E8: 0.2 | F8: 5.0047462 | G8: =E8*F8 -> 1.0009492 | H8: 0 | I8: 0 | J8: 0 | K8: 0 | L8: 0 | M8: =IF(AND(H8=1,I8=1,J8=1,K8=1),IF(L8=1,"PAID","PAYABLE"),"HELD") -> HELD
A9: C003 | B9: P01 | C9: M3 | D9: Dependency and unknown register | E9: 0.15 | F9: 5.0047462 | G9: =E9*F9 -> 0.75071193 | H9: 0 | I9: 0 | J9: 0 | K9: 0 | L9: 0 | M9: =IF(AND(H9=1,I9=1,J9=1,K9=1),IF(L9=1,"PAID","PAYABLE"),"HELD") -> HELD
A10: C004 | B10: P01 | C10: M4 | D10: Independent clean-room replay | E10: 0.25 | F10: 5.0047462 | G10: =E10*F10 -> 1.2511865 | H10: 0 | I10: 0 | J10: 0 | K10: 0 | L10: 0 | M10: =IF(AND(H10=1,I10=1,J10=1,K10=1),IF(L10=1,"PAID","PAYABLE"),"HELD") -> HELD
A11: C005 | B11: P01 | C11: M5 | D11: Rights, receiver and residual closure | E11: 0.2 | F11: 5.0047462 | G11: =E11*F11 -> 1.0009492 | H11: 0 | I11: 0 | J11: 0 | K11: 0 | L11: 0 | M11: =IF(AND(H11=1,I11=1,J11=1,K11=1),IF(L11=1,"PAID","PAYABLE"),"HELD") -> HELD
A12: C006 | B12: P01 | C12: M6 | D12: Challenge closure and terminal archive | E12: 0.1 | F12: 5.0047462 | G12: =E12*F12 -> 0.50047462 | H12: 0 | I12: 0 | J12: 0 | K12: 0 | L12: 0 | M12: =IF(AND(H12=1,I12=1,J12=1,K12=1),IF(L12=1,"PAID","PAYABLE"),"HELD") -> HELD
A13: C007 | B13: P02 | C13: M1 | D13: Source capsule | E13: 0.1 | F13: 6.2559327 | G13: =E13*F13 -> 0.62559327 | H13: 0 | I13: 0 | J13: 0 | K13: 0 | L13: 0 | M13: =IF(AND(H13=1,I13=1,J13=1,K13=1),IF(L13=1,"PAID","PAYABLE"),"HELD") -> HELD
A14: C008 | B14: P02 | C14: M2 | D14: Executable causal ledger | E14: 0.2 | F14: 6.2559327 | G14: =E14*F14 -> 1.2511865 | H14: 0 | I14: 0 | J14: 0 | K14: 0 | L14: 0 | M14: =IF(AND(H14=1,I14=1,J14=1,K14=1),IF(L14=1,"PAID","PAYABLE"),"HELD") -> HELD
A15: C009 | B15: P02 | C15: M3 | D15: Dependency and unknown register | E15: 0.15 | F15: 6.2559327 | G15: =E15*F15 -> 0.93838991 | H15: 0 | I15: 0 | J15: 0 | K15: 0 | L15: 0 | M15: =IF(AND(H15=1,I15=1,J15=1,K15=1),IF(L15=1,"PAID","PAYABLE"),"HELD") -> HELD
A16: C010 | B16: P02 | C16: M4 | D16: Independent clean-room replay | E16: 0.25 | F16: 6.2559327 | G16: =E16*F16 -> 1.5639832 | H16: 0 | I16: 0 | J16: 0 | K16: 0 | L16: 0 | M16: =IF(AND(H16=1,I16=1,J16=1,K16=1),IF(L16=1,"PAID","PAYABLE"),"HELD") -> HELD
A17: C011 | B17: P02 | C17: M5 | D17: Rights, receiver and residual closure | E17: 0.2 | F17: 6.2559327 | G17: =E17*F17 -> 1.2511865 | H17: 0 | I17: 0 | J17: 0 | K17: 0 | L17: 0 | M17: =IF(AND(H17=1,I17=1,J17=1,K17=1),IF(L17=1,"PAID","PAYABLE"),"HELD") -> HELD
A18: C012 | B18: P02 | C18: M6 | D18: Challenge closure and terminal archive | E18: 0.1 | F18: 6.2559327 | G18: =E18*F18 -> 0.62559327 | H18: 0 | I18: 0 | J18: 0 | K18: 0 | L18: 0 | M18: =IF(AND(H18=1,I18=1,J18=1,K18=1),IF(L18=1,"PAID","PAYABLE"),"HELD") -> HELD
... A186: C180 | B186: P30 | C186: M6 | D186: Challenge closure and terminal archive | E186: 0.1 | F186: 3.7694834 | G186: =E186*F186 -> 0.37694834 | H186: 0 | I186: 0 | J186: 0 | K186: 0 | L186: 0 | M186: =IF(AND(H186=1,I186=1,J186=1,K186=1),IF(L186=1,"PAID","PAYABLE"),"HELD") -> HELD

Sheet Authority Separation
A2: Authority separation register
A4: A conflict is judged through beneficial control, people, keys, tools, debt, custody and accepting authority, not organization names.
A6: Rule | B6: First authority | C6: Second authority | D6: Forbidden combination | E6: Consequence | F6: Current conflict | G6: Status | H6: Compact source
A7: S01 | B7: Form-cell builder | C7: Native replay operator | D7: perform and replay | E7: terminate package | F7: 0 | G7: =IF(F7=0,"PASS","FAIL") -> PASS | H7: AVA-TC
A8: S02 | B8: Form-cell builder | C8: Clean reconstruction lead | D8: perform and reconstruct | E8: terminate form cell | F8: 0 | G8: =IF(F8=0,"PASS","FAIL") -> PASS | H8: AVA-TC
A9: S03 | B9: Form-cell builder | C9: Divergence officer | D9: author and adjudicate | E9: terminate form cell | F9: 0 | G9: =IF(F9=0,"PASS","FAIL") -> PASS | H9: AVA-TC
A10: S04 | B10: Form-cell builder | C10: Root Artifact Court | D10: author and validate | E10: terminate form cell | F10: 0 | G10: =IF(F10=0,"PASS","FAIL") -> PASS | H10: AVA-TC
A11: S05 | B11: Form-cell builder | C11: Milestone acceptance officer | D11: perform and accept | E11: terminate claim | F11: 0 | G11: =IF(F11=0,"PASS","FAIL") -> PASS | H11: AVA-TC
A12: S06 | B12: Form-cell builder | C12: FDW officer | D12: perform and release money | E12: terminate claim | F12: 0 | G12: =IF(F12=0,"PASS","FAIL") -> PASS | H12: AVA-TC
A13: S07 | B13: Form-cell builder | C13: Disbursing officer | D13: perform and pay | E13: terminate claim | F13: 0 | G13: =IF(F13=0,"PASS","FAIL") -> PASS | H13: AVA-TC
A14: S08 | B14: Form-cell builder | C14: Evidence Court | D14: design and admit evidence | E14: terminate compact | F14: 0 | G14: =IF(F14=0,"PASS","FAIL") -> PASS | H14: AVA-TC
A15: S09 | B15: Form-cell builder | C15: Selection Court | D15: design and select | E15: terminate compact | F15: 0 | G15: =IF(F15=0,"PASS","FAIL") -> PASS | H15: AVA-TC
A16: S10 | B16: Native replay operator | C16: Clean reconstruction lead | D16: common technical path | E16: terminate package | F16: 0 | G16: =IF(F16=0,"PASS","FAIL") -> PASS | H16: AVA-TC
A17: S11 | B17: Native replay operator | C17: Divergence officer | D17: produce and adjudicate | E17: terminate package | F17: 0 | G17: =IF(F17=0,"PASS","FAIL") -> PASS | H17: AVA-TC
A18: S12 | B18: Clean reconstruction lead | C18: Divergence officer | D18: produce and adjudicate | E18: terminate package | F18: 0 | G18: =IF(F18=0,"PASS","FAIL") -> PASS | H18: AVA-TC
... A42: S36 | B42: Representation authority | C42: Selection Court | D42: image issue and preference | E42: terminate compact | F42: 0 | G42: =IF(F42=0,"PASS","FAIL") -> PASS | H42: AVA-TC

Sheet Nonconversions
A2: Thirty-two nonconversion laws
A4: Each source state remains narrow. A later act requires its own authority even when every prior record is complete.
A6: Rule | B6: Source state | C6: Forbidden result | D6: Permitted next act | E6: Required independent instrument | F6: Violation route | G6: Source
A7: N01 | B7: learning-warrant issue | C7: obligation | D7: reserve cohort | E7: CEW-1 | F7: hold | G7: FSA-TC
A8: N02 | B8: cohort schedule | C8: execution | D8: activate gates | E8: CEW-1 | F8: hold | G8: FSA-TC
A9: N03 | B9: obligation | C9: payment | D9: perform bounded work | E9: AVW plus FDW | F9: rollback | G9: CEW-1
A10: N04 | B10: notice to proceed | C10: artifact validity | D10: produce package | E10: AVW | F10: rework | G10: CEW-1
A11: N05 | B11: active work | C11: observation | D11: submit artifact | E11: Evidence Court warrant | F11: terminate | G11: AVC-1
A12: N06 | B12: source-capsule receipt | C12: native replay | D12: instantiate environment | E12: Native replay record | F12: rework | G12: DRG-1
A13: N07 | B13: native replay | C13: clean reconstruction | D13: open public contract | E13: Clean reconstruction record | F13: hold | G13: DRG-1
A14: N08 | B14: clean reconstruction | C14: semantic agreement | D14: commit comparison | E14: Divergence disposition | F14: hold | G14: DRG-1
A15: N09 | B15: semantic agreement | C15: physical correctness | D15: seek artifact validity | E15: AVW | F15: zero evidence credit | G15: DRG-1
A16: N10 | B16: common kernel | C16: common solver | D16: transport public meaning | E16: none | F16: terminate | G16: DRG-1
A17: N11 | B17: archive presence | C17: reproducibility | D17: initiate reconstruction | E17: dual reconstruction | F17: hold | G17: DRG-1
... A38: N32 | B38: failover activation | C38: renewed validity | D38: operate lawful survivor | E38: new recovery warrant | F38: hold | G38: AVA-TC

Sheet Expiry Routes
A2: Expiry constitution
A4: Validity is leased to one configuration, ancestry, civic obligation and available estate. It is never permanent.
A6: Route | B6: Object | C6: Trigger | D6: Expiry clock | E6: Immediate action | F6: Re-entry requirement | G6: Money effect | H6: Current events
A7: E01 | B7: AVW | C7: configuration hash changes | D7: immediate | E7: revoke AVW | F7: new dual reconstruction | G7: freeze unpaid claims | H7: 0
A8: E02 | B8: AVW | C8: causal event or denominator changes | D8: immediate | E8: revoke AVW | F8: new trace and reconstruction | G8: freeze unpaid claims | H8: 0
A9: E03 | B9: AVW | C9: dependency or license bill changes | D9: before next use | E9: hold package | F9: native and clean replay | G9: freeze unpaid claims | H9: 0
A10: E04 | B10: AVW | C10: material or process assumption changes | D10: before next use | E10: hold package | F10: physical ledger revision | G10: freeze unpaid claims | H10: 0
A11: E05 | B11: AVW | C11: root epoch advances | D11: epoch boundary | E11: hold package | F11: source-blind translation plus replay | G11: competitive ceiling unchanged | H11: 0
A12: E06 | B12: AVW | C12: rights or access obligation changes | D12: immediate | E12: hold package | F12: civil closure review | G12: freeze unpaid claims | H12: 0
A13: E07 | B13: Source capsule | C13: superseding capsule issues | D13: immediate | E13: seal predecessor | F13: new content-addressed record | G13: none | H13: 0
A14: E08 | B14: Native replay | C14: sealed toolchain changes | D14: immediate | E14: invalidate replay | F14: rerun frozen case | G14: none | H14: 0
A15: E09 | B15: Clean reconstruction | C15: decisive tool ancestry changes | D15: immediate | E15: invalidate clean path | F15: new disjoint commitment | G15: none | H15: 0
A16: E10 | B16: Divergence disposition | C16: semantic delta reopens | D16: immediate | E16: hold package | F16: new court disposition | G16: none | H16: 0
A17: E11 | B17: Court quorum | C17: seat conflict or loss | D17: immediate | E17: suspend issue | F17: reconstitute two-of-three quorum | G17: none | H17: 0
A18: E12 | B18: NDW | C18: truth schedule or capacity changes | D18: before co-use | E18: revoke capacity claim | F18: repeat concurrent cold run | G18: capital remains nested | H18: 0
... A24: E18 | B24: Payment instruction | C24: execution window closes | D24: claim expiry | E24: cancel instruction | F24: new AVW and FDW check | G24: no cash finality | H24: 0

Sheet Rollback Routes
A2: Rollback routes
A4: Rollback removes only the authority created by the invalid act and preserves prior adverse records, sibling reserves and public lineage.
A6: Route | B6: Trigger | C6: Scope | D6: Return state | E6: Required action | F6: Fiscal disposition | G6: Forbidden shortcut | H6: Current events
A7: R01 | B7: open validity gate after issue | C7: package | D7: WORK / REWORK | E7: revoke AVW and return gate | F7: freeze unpaid claim | G7: administrative waiver | H7: 0
A8: R02 | B8: native replay failure | C8: package | D8: CAPSULE REWORK | E8: repair sealed environment | F8: preserve budget | G8: clean-only validity | H8: 0
A9: R03 | B9: clean reconstruction failure | C9: package | D9: DIVERGENT / HOLD | E9: rebuild with disjoint tools | F9: preserve budget | G9: native-only validity | H9: 0
A10: R04 | B10: semantic mismatch | C10: package | D10: DIVERGENT / HOLD | E10: court disposition | F10: preserve budget | G10: average results | H10: 0
A11: R05 | B11: performance leakage | C11: root | D11: HELD | E11: isolate recipients and restore epoch | F11: no sibling transfer | G11: redesign later sibling | H11: 0
A12: R06 | B12: common control | C12: form cell | D12: TERMINATED | E12: seal artifacts and appoint clean successor | F12: unearned funds protected | G12: efficiency waiver | H12: 0
A13: R07 | B13: site loss | C13: site | D13: DEGRADED | E13: activate lawful standby and restore | F13: none | G13: central takeover | H13: 0
A14: R08 | B14: region loss | C14: three roots | D14: DEGRADED | E14: activate cross-region paths | F14: none | G14: cross-root borrowing | H14: 0
A15: R09 | B15: truth-capacity displacement | C15: site | D15: PLANNED | E15: revoke NDW and release artifact load | F15: capital remains nested | G15: capacity inferred from spend | H15: 0
A16: R10 | B16: vendor exit | C16: docket | D16: HELD | E16: public step-in and clean reconstruction | F16: unearned vendor amount held | G16: vendor operation | H16: 0
A17: R11 | B17: key compromise | C17: key set | D17: KEYED | E17: destroy shares and rekey | F17: none | G17: single master key | H17: 0
A18: R12 | B18: court conflict | C18: root court | D18: RE-QUORUM | E18: recuse and reconstruct quorum | F18: none | G18: national substitute judge | H18: 0
... A24: R18 | B24: expired fifth-pass branch | C24: branch | D24: RETURNED | E24: close item and return to parent | F24: none | G24: sixth AVA pass | H24: 0

Sheet Termination Routes
A2: Nonwaivable termination routes
A4: A fatal finding ends the affected authority. It cannot be converted into rework, a variance or centralized rescue.
A6: Route | B6: Fatal finding | C6: Scope | D6: Authority terminated | E6: Evidence preserved | F6: Fiscal destination | G6: Successor rule | H6: Current events
A7: T01 | B7: builder controls clean reconstruction | C7: form cell | D7: artifact-validity path | E7: all source and divergence records | F7: protected custody | G7: clean successor only | H7: 0
A8: T02 | B8: native and clean paths share decisive tools | C8: package | D8: AVW eligibility | E8: both committed results | F8: package ceiling held | G8: new disjoint path | H8: 0
A9: T03 | B9: court quorum under common control | C9: root court | D9: root AVW issue | E9: prior warrants and recusals | F9: none | G9: reconstitute court | H9: 0
A10: T04 | B10: custody threshold captured | C10: Exchange | D10: escrow release | E10: all mirror histories | F10: none | G10: rekey from public mirrors | H10: 0
A11: T05 | B11: intentional sibling performance leakage | C11: root | D11: affected root epoch | E11: disclosed payload and recipients | F11: all sibling money protected | G11: independent contamination inquiry | H11: 0
A12: T06 | B12: source or lineage falsification | C12: package | D12: package lineage | E12: false and corrected records | F12: unearned amount protected | G12: new authorship chain | H12: 0
A13: T07 | B13: append-only archive overwritten | C13: estate | D13: estate availability | E13: recovered histories | F13: capital held | G13: reconstitute public archive | H13: 0
A14: T08 | B14: vendor becomes operating dependency | C14: docket | D14: site commissioning | E14: dependency record | F14: vendor amount held | G14: public step-in | H14: 0
A15: T09 | B15: truth reservation displaced | C15: site | D15: NDW and root availability | E15: capacity transcript | F15: capital remains nested | G15: repeat after physical separation | H15: 0
A16: T10 | B16: rights or residual obligation falsified | C16: package | D16: AVW eligibility | E16: civil record | F16: unearned amount protected | G16: new civil closure | H16: 0
A17: T11 | B17: payment issued without AVW and FDW | C17: claim | D17: claim authority | E17: claim and payment record | F17: recover if lawful | G17: new separated review | H17: 0
A18: T12 | B18: artifact accepted as observation | C18: compact | D18: AVA-TC | E18: invalid observation preserved | F18: none | G18: Evidence Court only | H18: 0
... A22: T16 | B22: protected sibling reserve encumbered | C22: compact | D22: cohort-one finance | E22: encumbrance record | F22: restore USD359M boundary | G22: new finance compact | H22: 0

Sheet Stress Worlds
A2: Integrated constitutional stress worlds
A4: The model tests lawful progress, incomplete prerequisites, control failure, premature finance and prohibited downstream conversion.
A6: World | B6: Class | C6: Condition | D6: Gates | E6: Native | F6: Clean | G6: Invariants | H6: Estate | I6: NDW | J6: Independent | K6: Leakage | L6: Milestone | M6: Ceiling | N6: AVW claimed | O6: FDW claimed | P6: Payment claimed | Q6: Evidence claimed | R6: Selection claimed | S6: MAKE claimed | T6: REP-4 claimed | U6: Reserve intact | V6: Expected package state | W6: Expected compact state | X6: AVW eligible | Y6: FDW eligible | Z6: Payment eligible | AA6: Computed package state | AB6: Computed compact state | AC6: Result
A7: W01 | B7: LAWFUL | C7: obligation only | D7: 0 | E7: 0 | F7: 0 | G7: 0 | H7: 0 | I7: 0 | J7: 1 | K7: 0 | L7: 0 | M7: 0 | N7: 0 | O7: 0 | P7: 0 | Q7: 0 | R7: 0 | S7: 0 | T7: 0 | U7: 1 | V7: OBLIGATED / OPEN | W7: CONTROLLED | X7: =IF(AND(D7=Inputs!$B$10,E7=1,F7=1,G7=Inputs!$B$15,H7=1,I7=1,J7=1,K7=0),1,0) -> 0 | Y7: =IF(AND(X7=1,L7=1,M7=1,N7=1),1,0) -> 0 | Z7: =IF(AND(Y7=1,O7=1,P7=1),1,0) -> 0 | AA7: =IF(OR(J7=0,K7=1),"TERMINATED",IF(AND(X7=1,N7=1),"VALID",IF(X7=1,"ELIGIBLE / UNISSUED",IF(D7=Inputs!$B$10,"RECONSTRUCTION / HOLD",IF(D7>0,"WORK / REWORK","OBLIGATED / OPEN"))))) -> OBLIGATED / OPEN | AB7: =IF(OR(Q7=1,R7=1,S7=1,T7=1,U7=0,J7=0,K7=1),"TERMINATED",IF(OR(AND(N7=1,X7=0),AND(O7=1,Y7=0),AND(P7=1,Z7=0)),"ROLLBACK","CONTROLLED")) -> CONTROLLED | AC7: =IF(AND(AA7=V7,AB7=W7),"PASS","FAIL") -> PASS
A8: W02 | B8: LAWFUL | C8: partial package gates | D8: 6 | E8: 0 | F8: 0 | G8: 0 | H8: 1 | I8: 1 | J8: 1 | K8: 0 | L8: 1 | M8: 1 | N8: 0 | O8: 0 | P8: 0 | Q8: 0 | R8: 0 | S8: 0 | T8: 0 | U8: 1 | V8: WORK / REWORK | W8: CONTROLLED | X8: =IF(AND(D8=Inputs!$B$10,E8=1,F8=1,G8=Inputs!$B$15,H8=1,I8=1,J8=1,K8=0),1,0) -> 0 | Y8: =IF(AND(X8=1,L8=1,M8=1,N8=1),1,0) -> 0 | Z8: =IF(AND(Y8=1,O8=1,P8=1),1,0) -> 0 | AA8: =IF(OR(J8=0,K8=1),"TERMINATED",IF(AND(X8=1,N8=1),"VALID",IF(X8=1,"ELIGIBLE / UNISSUED",IF(D8=Inputs!$B$10,"RECONSTRUCTION / HOLD",IF(D8>0,"WORK / REWORK","OBLIGATED / OPEN"))))) -> WORK / REWORK | AB8: =IF(OR(Q8=1,R8=1,S8=1,T8=1,U8=0,J8=0,K8=1),"TERMINATED",IF(OR(AND(N8=1,X8=0),AND(O8=1,Y8=0),AND(P8=1,Z8=0)),"ROLLBACK","CONTROLLED")) -> CONTROLLED | AC8: =IF(AND(AA8=V8,AB8=W8),"PASS","FAIL") -> PASS
A9: W03 | B9: LAWFUL | C9: gates complete, reconstruction absent | D9: 12 | E9: 0 | F9: 0 | G9: 0 | H9: 1 | I9: 1 | J9: 1 | K9: 0 | L9: 1 | M9: 1 | N9: 0 | O9: 0 | P9: 0 | Q9: 0 | R9: 0 | S9: 0 | T9: 0 | U9: 1 | V9: RECONSTRUCTION / HOLD | W9: CONTROLLED | X9: =IF(AND(D9=Inputs!$B$10,E9=1,F9=1,G9=Inputs!$B$15,H9=1,I9=1,J9=1,K9=0),1,0) -> 0 | Y9: =IF(AND(X9=1,L9=1,M9=1,N9=1),1,0) -> 0 | Z9: =IF(AND(Y9=1,O9=1,P9=1),1,0) -> 0 | AA9: =IF(OR(J9=0,K9=1),"TERMINATED",IF(AND(X9=1,N9=1),"VALID",IF(X9=1,"ELIGIBLE / UNISSUED",IF(D9=Inputs!$B$10,"RECONSTRUCTION / HOLD",IF(D9>0,"WORK / REWORK","OBLIGATED / OPEN"))))) -> RECONSTRUCTION / HOLD | AB9: =IF(OR(Q9=1,R9=1,S9=1,T9=1,U9=0,J9=0,K9=1),"TERMINATED",IF(OR(AND(N9=1,X9=0),AND(O9=1,Y9=0),AND(P9=1,Z9=0)),"ROLLBACK","CONTROLLED")) -> CONTROLLED | AC9: =IF(AND(AA9=V9,AB9=W9),"PASS","FAIL") -> PASS
A10: W04 | B10: LAWFUL | C10: native replay only | D10: 12 | E10: 1 | F10: 0 | G10: 0 | H10: 1 | I10: 1 | J10: 1 | K10: 0 | L10: 1 | M10: 1 | N10: 0 | O10: 0 | P10: 0 | Q10: 0 | R10: 0 | S10: 0 | T10: 0 | U10: 1 | V10: RECONSTRUCTION / HOLD | W10: CONTROLLED | X10: =IF(AND(D10=Inputs!$B$10,E10=1,F10=1,G10=Inputs!$B$15,H10=1,I10=1,J10=1,K10=0),1,0) -> 0 | Y10: =IF(AND(X10=1,L10=1,M10=1,N10=1),1,0) -> 0 | Z10: =IF(AND(Y10=1,O10=1,P10=1),1,0) -> 0 | AA10: =IF(OR(J10=0,K10=1),"TERMINATED",IF(AND(X10=1,N10=1),"VALID",IF(X10=1,"ELIGIBLE / UNISSUED",IF(D10=Inputs!$B$10,"RECONSTRUCTION / HOLD",IF(D10>0,"WORK / REWORK","OBLIGATED / OPEN"))))) -> RECONSTRUCTION / HOLD | AB10: =IF(OR(Q10=1,R10=1,S10=1,T10=1,U10=0,J10=0,K10=1),"TERMINATED",IF(OR(AND(N10=1,X10=0),AND(O10=1,Y10=0),AND(P10=1,Z10=0)),"ROLLBACK","CONTROLLED")) -> CONTROLLED | AC10: =IF(AND(AA10=V10,AB10=W10),"PASS","FAIL") -> PASS
A11: W05 | B11: LAWFUL | C11: semantic set incomplete | D11: 12 | E11: 1 | F11: 1 | G11: 5 | H11: 1 | I11: 1 | J11: 1 | K11: 0 | L11: 1 | M11: 1 | N11: 0 | O11: 0 | P11: 0 | Q11: 0 | R11: 0 | S11: 0 | T11: 0 | U11: 1 | V11: RECONSTRUCTION / HOLD | W11: CONTROLLED | X11: =IF(AND(D11=Inputs!$B$10,E11=1,F11=1,G11=Inputs!$B$15,H11=1,I11=1,J11=1,K11=0),1,0) -> 0 | Y11: =IF(AND(X11=1,L11=1,M11=1,N11=1),1,0) -> 0 | Z11: =IF(AND(Y11=1,O11=1,P11=1),1,0) -> 0 | AA11: =IF(OR(J11=0,K11=1),"TERMINATED",IF(AND(X11=1,N11=1),"VALID",IF(X11=1,"ELIGIBLE / UNISSUED",IF(D11=Inputs!$B$10,"RECONSTRUCTION / HOLD",IF(D11>0,"WORK / REWORK","OBLIGATED / OPEN"))))) -> RECONSTRUCTION / HOLD | AB11: =IF(OR(Q11=1,R11=1,S11=1,T11=1,U11=0,J11=0,K11=1),"TERMINATED",IF(OR(AND(N11=1,X11=0),AND(O11=1,Y11=0),AND(P11=1,Z11=0)),"ROLLBACK","CONTROLLED")) -> CONTROLLED | AC11: =IF(AND(AA11=V11,AB11=W11),"PASS","FAIL") -> PASS
A12: W06 | B12: LAWFUL | C12: eligible, AVW unissued | D12: 12 | E12: 1 | F12: 1 | G12: 6 | H12: 1 | I12: 1 | J12: 1 | K12: 0 | L12: 1 | M12: 1 | N12: 0 | O12: 0 | P12: 0 | Q12: 0 | R12: 0 | S12: 0 | T12: 0 | U12: 1 | V12: ELIGIBLE / UNISSUED | W12: CONTROLLED | X12: =IF(AND(D12=Inputs!$B$10,E12=1,F12=1,G12=Inputs!$B$15,H12=1,I12=1,J12=1,K12=0),1,0) -> 1 | Y12: =IF(AND(X12=1,L12=1,M12=1,N12=1),1,0) -> 0 | Z12: =IF(AND(Y12=1,O12=1,P12=1),1,0) -> 0 | AA12: =IF(OR(J12=0,K12=1),"TERMINATED",IF(AND(X12=1,N12=1),"VALID",IF(X12=1,"ELIGIBLE / UNISSUED",IF(D12=Inputs!$B$10,"RECONSTRUCTION / HOLD",IF(D12>0,"WORK / REWORK","OBLIGATED / OPEN"))))) -> ELIGIBLE / UNISSUED | AB12: =IF(OR(Q12=1,R12=1,S12=1,T12=1,U12=0,J12=0,K12=1),"TERMINATED",IF(OR(AND(N12=1,X12=0),AND(O12=1,Y12=0),AND(P12=1,Z12=0)),"ROLLBACK","CONTROLLED")) -> CONTROLLED | AC12: =IF(AND(AA12=V12,AB12=W12),"PASS","FAIL") -> PASS
A13: W07 | B13: LAWFUL | C13: valid artifact, finance unissued | D13: 12 | E13: 1 | F13: 1 | G13: 6 | H13: 1 | I13: 1 | J13: 1 | K13: 0 | L13: 1 | M13: 1 | N13: 1 | O13: 0 | P13: 0 | Q13: 0 | R13: 0 | S13: 0 | T13: 0 | U13: 1 | V13: VALID | W13: CONTROLLED | X13: =IF(AND(D13=Inputs!$B$10,E13=1,F13=1,G13=Inputs!$B$15,H13=1,I13=1,J13=1,K13=0),1,0) -> 1 | Y13: =IF(AND(X13=1,L13=1,M13=1,N13=1),1,0) -> 1 | Z13: =IF(AND(Y13=1,O13=1,P13=1),1,0) -> 0 | AA13: =IF(OR(J13=0,K13=1),"TERMINATED",IF(AND(X13=1,N13=1),"VALID",IF(X13=1,"ELIGIBLE / UNISSUED",IF(D13=Inputs!$B$10,"RECONSTRUCTION / HOLD",IF(D13>0,"WORK / REWORK","OBLIGATED / OPEN"))))) -> VALID | AB13: =IF(OR(Q13=1,R13=1,S13=1,T13=1,U13=0,J13=0,K13=1),"TERMINATED",IF(OR(AND(N13=1,X13=0),AND(O13=1,Y13=0),AND(P13=1,Z13=0)),"ROLLBACK","CONTROLLED")) -> CONTROLLED | AC13: =IF(AND(AA13=V13,AB13=W13),"PASS","FAIL") -> PASS
A14: W08 | B14: LAWFUL | C14: valid and payable claim | D14: 12 | E14: 1 | F14: 1 | G14: 6 | H14: 1 | I14: 1 | J14: 1 | K14: 0 | L14: 1 | M14: 1 | N14: 1 | O14: 1 | P14: 1 | Q14: 0 | R14: 0 | S14: 0 | T14: 0 | U14: 1 | V14: VALID | W14: CONTROLLED | X14: =IF(AND(D14=Inputs!$B$10,E14=1,F14=1,G14=Inputs!$B$15,H14=1,I14=1,J14=1,K14=0),1,0) -> 1 | Y14: =IF(AND(X14=1,L14=1,M14=1,N14=1),1,0) -> 1 | Z14: =IF(AND(Y14=1,O14=1,P14=1),1,0) -> 1 | AA14: =IF(OR(J14=0,K14=1),"TERMINATED",IF(AND(X14=1,N14=1),"VALID",IF(X14=1,"ELIGIBLE / UNISSUED",IF(D14=Inputs!$B$10,"RECONSTRUCTION / HOLD",IF(D14>0,"WORK / REWORK","OBLIGATED / OPEN"))))) -> VALID | AB14: =IF(OR(Q14=1,R14=1,S14=1,T14=1,U14=0,J14=0,K14=1),"TERMINATED",IF(OR(AND(N14=1,X14=0),AND(O14=1,Y14=0),AND(P14=1,Z14=0)),"ROLLBACK","CONTROLLED")) -> CONTROLLED | AC14: =IF(AND(AA14=V14,AB14=W14),"PASS","FAIL") -> PASS
A15: W09 | B15: VALIDITY | C15: source gate open | D15: 11 | E15: 1 | F15: 1 | G15: 6 | H15: 1 | I15: 1 | J15: 1 | K15: 0 | L15: 1 | M15: 1 | N15: 1 | O15: 0 | P15: 0 | Q15: 0 | R15: 0 | S15: 0 | T15: 0 | U15: 1 | V15: WORK / REWORK | W15: ROLLBACK | X15: =IF(AND(D15=Inputs!$B$10,E15=1,F15=1,G15=Inputs!$B$15,H15=1,I15=1,J15=1,K15=0),1,0) -> 0 | Y15: =IF(AND(X15=1,L15=1,M15=1,N15=1),1,0) -> 0 | Z15: =IF(AND(Y15=1,O15=1,P15=1),1,0) -> 0 | AA15: =IF(OR(J15=0,K15=1),"TERMINATED",IF(AND(X15=1,N15=1),"VALID",IF(X15=1,"ELIGIBLE / UNISSUED",IF(D15=Inputs!$B$10,"RECONSTRUCTION / HOLD",IF(D15>0,"WORK / REWORK","OBLIGATED / OPEN"))))) -> WORK / REWORK | AB15: =IF(OR(Q15=1,R15=1,S15=1,T15=1,U15=0,J15=0,K15=1),"TERMINATED",IF(OR(AND(N15=1,X15=0),AND(O15=1,Y15=0),AND(P15=1,Z15=0)),"ROLLBACK","CONTROLLED")) -> ROLLBACK | AC15: =IF(AND(AA15=V15,AB15=W15),"PASS","FAIL") -> PASS
A16: W10 | B16: VALIDITY | C16: native replay fails | D16: 12 | E16: 0 | F16: 1 | G16: 6 | H16: 1 | I16: 1 | J16: 1 | K16: 0 | L16: 1 | M16: 1 | N16: 1 | O16: 0 | P16: 0 | Q16: 0 | R16: 0 | S16: 0 | T16: 0 | U16: 1 | V16: RECONSTRUCTION / HOLD | W16: ROLLBACK | X16: =IF(AND(D16=Inputs!$B$10,E16=1,F16=1,G16=Inputs!$B$15,H16=1,I16=1,J16=1,K16=0),1,0) -> 0 | Y16: =IF(AND(X16=1,L16=1,M16=1,N16=1),1,0) -> 0 | Z16: =IF(AND(Y16=1,O16=1,P16=1),1,0) -> 0 | AA16: =IF(OR(J16=0,K16=1),"TERMINATED",IF(AND(X16=1,N16=1),"VALID",IF(X16=1,"ELIGIBLE / UNISSUED",IF(D16=Inputs!$B$10,"RECONSTRUCTION / HOLD",IF(D16>0,"WORK / REWORK","OBLIGATED / OPEN"))))) -> RECONSTRUCTION / HOLD | AB16: =IF(OR(Q16=1,R16=1,S16=1,T16=1,U16=0,J16=0,K16=1),"TERMINATED",IF(OR(AND(N16=1,X16=0),AND(O16=1,Y16=0),AND(P16=1,Z16=0)),"ROLLBACK","CONTROLLED")) -> ROLLBACK | AC16: =IF(AND(AA16=V16,AB16=W16),"PASS","FAIL") -> PASS
A17: W11 | B17: VALIDITY | C17: clean reconstruction fails | D17: 12 | E17: 1 | F17: 0 | G17: 6 | H17: 1 | I17: 1 | J17: 1 | K17: 0 | L17: 1 | M17: 1 | N17: 1 | O17: 0 | P17: 0 | Q17: 0 | R17: 0 | S17: 0 | T17: 0 | U17: 1 | V17: RECONSTRUCTION / HOLD | W17: ROLLBACK | X17: =IF(AND(D17=Inputs!$B$10,E17=1,F17=1,G17=Inputs!$B$15,H17=1,I17=1,J17=1,K17=0),1,0) -> 0 | Y17: =IF(AND(X17=1,L17=1,M17=1,N17=1),1,0) -> 0 | Z17: =IF(AND(Y17=1,O17=1,P17=1),1,0) -> 0 | AA17: =IF(OR(J17=0,K17=1),"TERMINATED",IF(AND(X17=1,N17=1),"VALID",IF(X17=1,"ELIGIBLE / UNISSUED",IF(D17=Inputs!$B$10,"RECONSTRUCTION / HOLD",IF(D17>0,"WORK / REWORK","OBLIGATED / OPEN"))))) -> RECONSTRUCTION / HOLD | AB17: =IF(OR(Q17=1,R17=1,S17=1,T17=1,U17=0,J17=0,K17=1),"TERMINATED",IF(OR(AND(N17=1,X17=0),AND(O17=1,Y17=0),AND(P17=1,Z17=0)),"ROLLBACK","CONTROLLED")) -> ROLLBACK | AC17: =IF(AND(AA17=V17,AB17=W17),"PASS","FAIL") -> PASS
A18: W12 | B18: VALIDITY | C18: one invariant fails | D18: 12 | E18: 1 | F18: 1 | G18: 5 | H18: 1 | I18: 1 | J18: 1 | K18: 0 | L18: 1 | M18: 1 | N18: 1 | O18: 0 | P18: 0 | Q18: 0 | R18: 0 | S18: 0 | T18: 0 | U18: 1 | V18: RECONSTRUCTION / HOLD | W18: ROLLBACK | X18: =IF(AND(D18=Inputs!$B$10,E18=1,F18=1,G18=Inputs!$B$15,H18=1,I18=1,J18=1,K18=0),1,0) -> 0 | Y18: =IF(AND(X18=1,L18=1,M18=1,N18=1),1,0) -> 0 | Z18: =IF(AND(Y18=1,O18=1,P18=1),1,0) -> 0 | AA18: =IF(OR(J18=0,K18=1),"TERMINATED",IF(AND(X18=1,N18=1),"VALID",IF(X18=1,"ELIGIBLE / UNISSUED",IF(D18=Inputs!$B$10,"RECONSTRUCTION / HOLD",IF(D18>0,"WORK / REWORK","OBLIGATED / OPEN"))))) -> RECONSTRUCTION / HOLD | AB18: =IF(OR(Q18=1,R18=1,S18=1,T18=1,U18=0,J18=0,K18=1),"TERMINATED",IF(OR(AND(N18=1,X18=0),AND(O18=1,Y18=0),AND(P18=1,Z18=0)),"ROLLBACK","CONTROLLED")) -> ROLLBACK | AC18: =IF(AND(AA18=V18,AB18=W18),"PASS","FAIL") -> PASS
... A46: W40 | B46: RETURN | C46: fifth pass closes without successor | D46: 12 | E46: 1 | F46: 1 | G46: 6 | H46: 1 | I46: 1 | J46: 1 | K46: 0 | L46: 1 | M46: 1 | N46: 0 | O46: 0 | P46: 0 | Q46: 0 | R46: 0 | S46: 0 | T46: 0 | U46: 1 | V46: ELIGIBLE / UNISSUED | W46: CONTROLLED | X46: =IF(AND(D46=Inputs!$B$10,E46=1,F46=1,G46=Inputs!$B$15,H46=1,I46=1,J46=1,K46=0),1,0) -> 1 | Y46: =IF(AND(X46=1,L46=1,M46=1,N46=1),1,0) -> 0 | Z46: =IF(AND(Y46=1,O46=1,P46=1),1,0) -> 0 | AA46: =IF(OR(J46=0,K46=1),"TERMINATED",IF(AND(X46=1,N46=1),"VALID",IF(X46=1,"ELIGIBLE / UNISSUED",IF(D46=Inputs!$B$10,"RECONSTRUCTION / HOLD",IF(D46>0,"WORK / REWORK","OBLIGATED / OPEN"))))) -> ELIGIBLE / UNISSUED | AB46: =IF(OR(Q46=1,R46=1,S46=1,T46=1,U46=0,J46=0,K46=1),"TERMINATED",IF(OR(AND(N46=1,X46=0),AND(O46=1,Y46=0),AND(P46=1,Z46=0)),"ROLLBACK","CONTROLLED")) -> CONTROLLED | AC46: =IF(AND(AA46=V46,AB46=W46),"PASS","FAIL") -> PASS

Sheet Finance
A2: Conserved artifact-validity finance
A4: The compact adds no money. It preserves the cohort obligation, later-sibling reserve, estate co-use ceiling and zero payment state.
A6: Cohort-one account allocation (USD millions)
A8: Account | B8: Share | C8: Cohort ceiling | D8: Current paid | E8: Authority created
A9: Design production | B9: 0.72 | C9: =B9*Inputs!$B$28 -> 129.12886 | D9: 0 | E9: =IF(D9=0,"ZERO","UNAUTHORIZED") -> ZERO
A10: Independent reconstruction | B10: 0.15 | C10: =B10*Inputs!$B$28 -> 26.901846 | D10: 0 | E10: =IF(D10=0,"ZERO","UNAUTHORIZED") -> ZERO
A11: Public source escrow | B11: 0.08 | C11: =B11*Inputs!$B$28 -> 14.347651 | D11: 0 | E11: =IF(D11=0,"ZERO","UNAUTHORIZED") -> ZERO
A12: Terminal holdback | B12: 0.05 | C12: =B12*Inputs!$B$28 -> 8.967282 | D12: 0 | E12: =IF(D12=0,"ZERO","UNAUTHORIZED") -> ZERO
A13: ="Total" -> Total | B13: =SUM(B9:B12) -> 1 | C13: =SUM(C9:C12) -> 179.34564 | D13: =SUM(D9:D12) -> 0 | E13: ="ZERO" -> ZERO
A16: Conservation controls (USD millions)
A18: Control | B18: Amount | C18: Interpretation
A19: Cohort-one obligation | B19: =Inputs!B28 -> 179.34564 | C19: active design liability
A20: Protected sibling reserve | B20: =Inputs!B29 -> 358.69128 | C20: cannot cover cohort-one overruns
A21: FRAME ceiling | B21: =Inputs!B30 -> 538.03692 | C21: conserved across all three cohorts
A22: Artifact-estate capital co-use ceiling | B22: =Inputs!B26 -> 540 | C22: nested inside public-method reserve
A23: Artifact-estate operating ceiling | B23: =Inputs!B27 -> 41.254333 | C23: inside reconstruction and escrow accounts
A24: Current payments | B24: 0 | C24: cash finality remains zero
A27: Claim reconciliation
A29: Claim records | B29: 180
A30: Claim ceiling | B30: =SUM('Claim Register'!G7:G186) -> 179.34564
A31: Payable claims | B31: =COUNTIFS('Claim Register'!M7:M186,"PAYABLE") -> 0
A32: Paid claims | B32: =SUM('Claim Register'!L7:L186) -> 0
A33: Protected reserve used | B33: 0

Sheet Return Ledger
A2: AVA terminal reconciliation and return
A4: The fifth pass closes the branch's only item, opens none and returns the integrated answer to the pre-registered cohort-one parent.
A6: Four controlling predecessor decisions
A8: Decision | B8: Pass | C8: Controlling object | D8: Contribution | E8: Cannot contribute | F8: Terminal status
A9: AVC-1 | B9: 231 | C9: package validity and payment firewall | D9: AVW, FDW and twelve gates | E9: evidence or selection | F9: RETAIN
A10: DRG-1 | B10: 232 | C10: source capsule and dual reconstruction | D10: reproducibility and semantic divergence | E10: physical truth | F10: RETAIN
A11: FAE-1 | B11: 233 | C11: eighteen-site federated estate | D11: courts, custody and failure topology | E11: commissioning | F11: RETAIN
A12: CNW-1 | B12: 234 | C12: commissioning and non-displacement | D12: dockets, capacity and recovery clocks | E12: package validity | F12: RETAIN
A15: Branch ledger
A17: Items opened | B17: 0
A18: Items closed | B18: 1
A19: Net change | B19: -1
A20: Running open total | B20: 0
A21: Branch passes consumed | B21: 5
A22: Branch budget | B22: 5
A23: No-KILL count since HR-02 | B23: 5
A26: Verdict and parent
A28: Verdict | B28: RETURN
A29: Branch | B29: AVA 5 of 5; no successor authorized
A30: Parent question | B30: Can the six active cohort-one form cells convert thirty funded FRAME packages into source-sealed, independently reproducible and payable design artifacts without converting acceptance into evidence, exposing comparative performance, weakening sibling reserves or authorizing MAKE or REP-4; and what invalidity or common-control finding would terminate that authority?
A31: Returned answer | B31: Yes, but only through AVA-TC. The path is constituted and all implementation, validity, payment, evidence and production claims remain zero.

Sheet Inputs
A2: Terminal compact controls
A4: Editable controls are blue. Current implementation and downstream authority remain zero unless an external warranted act occurs.
A6: Inherited constitutional controls | D6: Compact candidates
A7: Root count | B7: 6 | D7: C1 | E7: Unified artifact office | F7: 6 | G7: 4 | H7: REJECT
A8: Active form cells | B8: 6 | D8: C2 | E8: Contract acceptance chain | F8: 4 | G8: 6 | H8: REJECT
A9: Active packages | B9: 30 | D9: C3 | E9: Automated hash gate | F9: 7 | G9: 3 | H9: REJECT
A10: Validity gates per package | B10: 12 | D10: C4 | E10: Validity-to-evidence bridge | F10: 9 | G10: 1 | H10: REJECT
A11: Claims per package | B11: 6 | D11: C5 | E11: Federated typed-warrant compact | F11: 10 | G11: 0 | H11: SELECT
A12: Capsule fields per package | B12: 18
A13: Native replay stages | B13: 8
A14: Clean reconstruction stages | B14: 10
A15: Semantic invariants | B15: 6
A16: Artifact-estate sites | B16: 18
A17: Role appointments | B17: 96
A18: Key and share records | B18: 78
A19: Vendor lots | B19: 72
A20: Failure worlds | B20: 30
A21: Resource classes | B21: 6
A22: Normalized host capacity | B22: 100
A23: Truth reservation | B23: 75
... A31: Tolerance | B31: 1e-06
A34: Current implementation and authority
A35: Issued learning warrants | B35: 18
A36: Active form cells | B36: 6
A37: Active packages | B37: 30
A38: Site admissions | B38: 0
A39: Role appointments | B39: 0
A40: Issued keys and shares | B40: 0
A41: Vendor awards | B41: 0
A42: Commissioned builds | B42: 0
A43: Completed recovery trials | B43: 0
A44: Non-displacement warrants | B44: 0
A45: Root availability warrants | B45: 0
A46: Completed source capsules | B46: 0
... A59: Performance-leakage findings | B59: 0

Sheet Mutations
A2: Controlled mutation register
A4: Each corruption is applied to the live model, detected by a named terminal audit and restored before export.
A6: Mutation | B6: Target | C6: Baseline | D6: Mutated | E6: Expected audit | F6: Detected | G6: Restored
A7: M01 | B7: Inputs!B7 | C7: 6 | D7: 5 | E7: A01 | F7: YES | G7: YES
A8: M02 | B8: Inputs!B9 | C8: 30 | D8: 29 | E8: A03 | F8: YES | G8: YES
A9: M03 | B9: Inputs!B10 | C9: 12 | D9: 11 | E9: A04 | F9: YES | G9: YES
A10: M04 | B10: Inputs!B11 | C10: 6 | D10: 5 | E10: A05 | F10: YES | G10: YES
A11: M05 | B11: Inputs!B12 | C11: 18 | D11: 17 | E11: A06 | F11: YES | G11: YES
A12: M06 | B12: Inputs!B13 | C12: 8 | D12: 7 | E12: A07 | F12: YES | G12: YES
A13: M07 | B13: Inputs!B14 | C13: 10 | D13: 9 | E13: A08 | F13: YES | G13: YES
A14: M08 | B14: Inputs!B15 | C14: 6 | D14: 5 | E14: A09 | F14: YES | G14: YES
A15: M09 | B15: Inputs!B16 | C15: 18 | D15: 17 | E15: A10 | F15: YES | G15: YES
A16: M10 | B16: Inputs!B20 | C16: 30 | D16: 29 | E16: A14 | F16: YES | G16: YES
A17: M11 | B17: Inputs!B23 | C17: 75 | D17: 80 | E17: A16 | F17: YES | G17: YES
A18: M12 | B18: Inputs!B24 | C18: 20 | D18: 25 | E18: A16 | F18: YES | G18: YES
... A30: M24 | B30: Inputs!B58 | C30: 0 | D30: 1 | E30: A67 | F30: YES | G30: YES

Sheet Audit
A2: Terminal audit
A4: Audit is one-way. No business result, warrant, payment or authority depends on this sheet.
A6: Audit | B6: Test | C6: Observed | D6: Expected | E6: Status
A7: A01 | B7: Root count | C7: =Inputs!B7 -> 6 | D7: 6 | E7: =IF(ABS(C7-D7)<=Inputs!$B$31,"PASS","FAIL") -> PASS
A8: A02 | B8: Active form count | C8: =Inputs!B8 -> 6 | D8: 6 | E8: =IF(ABS(C8-D8)<=Inputs!$B$31,"PASS","FAIL") -> PASS
A9: A03 | B9: Active package control | C9: =Inputs!B9 -> 30 | D9: 30 | E9: =IF(ABS(C9-D9)<=Inputs!$B$31,"PASS","FAIL") -> PASS
A10: A04 | B10: Validity-gate control | C10: =Inputs!B10 -> 12 | D10: 12 | E10: =IF(ABS(C10-D10)<=Inputs!$B$31,"PASS","FAIL") -> PASS
A11: A05 | B11: Claim-count control | C11: =Inputs!B11 -> 6 | D11: 6 | E11: =IF(ABS(C11-D11)<=Inputs!$B$31,"PASS","FAIL") -> PASS
A12: A06 | B12: Capsule-field control | C12: =Inputs!B12 -> 18 | D12: 18 | E12: =IF(ABS(C12-D12)<=Inputs!$B$31,"PASS","FAIL") -> PASS
A13: A07 | B13: Native-stage control | C13: =Inputs!B13 -> 8 | D13: 8 | E13: =IF(ABS(C13-D13)<=Inputs!$B$31,"PASS","FAIL") -> PASS
A14: A08 | B14: Clean-stage control | C14: =Inputs!B14 -> 10 | D14: 10 | E14: =IF(ABS(C14-D14)<=Inputs!$B$31,"PASS","FAIL") -> PASS
A15: A09 | B15: Invariant control | C15: =Inputs!B15 -> 6 | D15: 6 | E15: =IF(ABS(C15-D15)<=Inputs!$B$31,"PASS","FAIL") -> PASS
A16: A10 | B16: Site-count control | C16: =Inputs!B16 -> 18 | D16: 18 | E16: =IF(ABS(C16-D16)<=Inputs!$B$31,"PASS","FAIL") -> PASS
A17: A11 | B17: Appointment control | C17: =Inputs!B17 -> 96 | D17: 96 | E17: =IF(ABS(C17-D17)<=Inputs!$B$31,"PASS","FAIL") -> PASS
A18: A12 | B18: Key-record control | C18: =Inputs!B18 -> 78 | D18: 78 | E18: =IF(ABS(C18-D18)<=Inputs!$B$31,"PASS","FAIL") -> PASS
... A21: A15 | B21: Resource-class control | C21: =Inputs!B21 -> 6 | D21: 6 | E21: =IF(ABS(C21-D21)<=Inputs!$B$31,"PASS","FAIL") -> PASS
A22: A16 | B22: Capacity partition conserved | C22: =Inputs!B23+Inputs!B24+Inputs!B25 -> 100 | D22: 100 | E22: =IF(ABS(C22-D22)<=Inputs!$B$31,"PASS","FAIL") -> PASS
A23: A17 | B23: Capital ceiling conserved | C23: =Inputs!B26 -> 540 | D23: 540 | E23: =IF(ABS(C23-D23)<=Inputs!$B$31,"PASS","FAIL") -> PASS
A24: A18 | B24: Operating ceiling conserved | C24: =Inputs!B27 -> 41.254333 | D24: 41.254333 | E24: =IF(ABS(C24-D24)<=Inputs!$B$31,"PASS","FAIL") -> PASS
A25: A19 | B25: Cohort obligation conserved | C25: =Inputs!B28 -> 179.34564 | D25: 179.34564 | E25: =IF(ABS(C25-D25)<=Inputs!$B$31,"PASS","FAIL") -> PASS
A26: A20 | B26: Sibling reserve conserved | C26: =Inputs!B29 -> 358.69128 | D26: 358.69128 | E26: =IF(ABS(C26-D26)<=Inputs!$B$31,"PASS","FAIL") -> PASS
A27: A21 | B27: FRAME ceiling conserved | C27: =Inputs!B28+Inputs!B29 -> 538.03692 | D27: 538.03692 | E27: =IF(ABS(C27-D27)<=Inputs!$B$31,"PASS","FAIL") -> PASS
A28: A22 | B28: Five candidate compacts | C28: =COUNTA('Decision Tests'!A7:A11) -> 5 | D28: 5 | E28: =IF(ABS(C28-D28)<=Inputs!$B$31,"PASS","FAIL") -> PASS
A29: A23 | B29: One selected compact | C29: =COUNTIFS('Decision Tests'!N7:N11,"SELECT") -> 1 | D29: 1 | E29: =IF(ABS(C29-D29)<=Inputs!$B$31,"PASS","FAIL") -> PASS
A30: A24 | B30: Selected compact passes all gates | C30: =SUMIFS('Decision Tests'!M7:M11,'Decision Tests'!N7:N11,"SELECT") -> 10 | D30: 10 | E30: =IF(ABS(C30-D30)<=Inputs!$B$31,"PASS","FAIL") -> PASS
A31: A25 | B31: Twenty-seven precedence records | C31: =COUNTA(Precedence!A7:A33) -> 27 | D31: 27 | E31: =IF(ABS(C31-D31)<=Inputs!$B$31,"PASS","FAIL") -> PASS
A32: A26 | B32: Thirty package records | C32: =COUNTA('Package Register'!A7:A36) -> 30 | D32: 30 | E32: =IF(ABS(C32-D32)<=Inputs!$B$31,"PASS","FAIL") -> PASS
A33: A27 | B33: Package ceilings reconcile | C33: =SUM('Package Register'!F7:F36) -> 179.34564 | D33: 179.34564 | E33: =IF(ABS(C33-D33)<=Inputs!$B$31,"PASS","FAIL") -> PASS
A34: A28 | B34: Thirty obligated packages | C34: =SUM('Package Register'!G7:G36) -> 30 | D34: 30 | E34: =IF(ABS(C34-D34)<=Inputs!$B$31,"PASS","FAIL") -> PASS
A35: A29 | B35: Three hundred sixty validity gates | C35: =COUNTA('Validity Gates'!A7:A366) -> 360 | D35: 360 | E35: =IF(ABS(C35-D35)<=Inputs!$B$31,"PASS","FAIL") -> PASS
A36: A30 | B36: Sixty passing constitutional gates | C36: =COUNTIFS('Validity Gates'!H7:H366,"PASS") -> 60 | D36: 60 | E36: =IF(ABS(C36-D36)<=Inputs!$B$31,"PASS","FAIL") -> PASS
A37: A31 | B37: Three hundred open artifact gates | C37: =COUNTIFS('Validity Gates'!H7:H366,"OPEN") -> 300 | D37: 300 | E37: =IF(ABS(C37-D37)<=Inputs!$B$31,"PASS","FAIL") -> PASS
A38: A32 | B38: One hundred eighty claims | C38: =COUNTA('Claim Register'!A7:A186) -> 180 | D38: 180 | E38: =IF(ABS(C38-D38)<=Inputs!$B$31,"PASS","FAIL") -> PASS
A39: A33 | B39: Claim shares reconcile by package | C39: =SUMIFS('Claim Register'!E7:E186,'Claim Register'!B7:B186,"P01") -> 1 | D39: 1 | E39: =IF(ABS(C39-D39)<=Inputs!$B$31,"PASS","FAIL") -> PASS
A40: A34 | B40: Claim amount reconciles | C40: =SUM('Claim Register'!G7:G186) -> 179.34564 | D40: 179.34564 | E40: =IF(ABS(C40-D40)<=Inputs!$B$31,"PASS","FAIL") -> PASS
A41: A35 | B41: Payable claims remain zero | C41: =COUNTIFS('Claim Register'!M7:M186,"PAYABLE") -> 0 | D41: 0 | E41: =IF(ABS(C41-D41)<=Inputs!$B$31,"PASS","FAIL") -> PASS
A42: A36 | B42: Paid claims remain zero | C42: =SUM('Claim Register'!L7:L186) -> 0 | D42: 0 | E42: =IF(ABS(C42-D42)<=Inputs!$B$31,"PASS","FAIL") -> PASS
A43: A37 | B43: Thirty-six separation rules | C43: =COUNTA('Authority Separation'!A7:A42) -> 36 | D43: 36 | E43: =IF(ABS(C43-D43)<=Inputs!$B$31,"PASS","FAIL") -> PASS
A44: A38 | B44: All separation controls pass | C44: =COUNTIFS('Authority Separation'!G7:G42,"PASS") -> 36 | D44: 36 | E44: =IF(ABS(C44-D44)<=Inputs!$B$31,"PASS","FAIL") -> PASS
A45: A39 | B45: Thirty-two nonconversions | C45: =COUNTA(Nonconversions!A7:A38) -> 32 | D45: 32 | E45: =IF(ABS(C45-D45)<=Inputs!$B$31,"PASS","FAIL") -> PASS
...

Sheet ReadMe
A2: Model notes and limits
A4: This workbook specifies a terminal authority compact. It does not complete a package, commission an estate, pay a claim or create physical evidence.
A6: Purpose
A8: AVA-TC integrates AVC-1, DRG-1, FAE-1 and CNW-1 as typed prerequisites rather than one approval hierarchy.
A9: The validity unit is one funded package. Whole-form validity, physical correctness and production readiness are excluded.
A10: An AVW requires all twelve validity gates, dual reconstruction, semantic closure, an available root estate and a live non-displacement warrant.
A11: Payment requires a package AVW, accepted milestone, separate FDW and payment instruction. Cash finality creates no technical credit.
A12: Thirty-two nonconversions, eighteen expiry routes, eighteen rollback routes and sixteen termination routes make authority reversible.
A13: The fifth AVA pass closes its only item, opens none and returns to the pre-registered cohort-one parent question.
A16: Current boundary
A18: Thirty packages are obligated and active work. Sixty constitutional gates pass; 300 package-content gates remain open.
A19: All sites, appointments, keys, vendors, builds, recovery trials, NDWs and root-availability warrants remain zero.
... A32: Vehicle and facility renderings remain deferred.
