Workbook

Sheet Summary
A2: Cohort-one Engineering Definition Baselines
A4: EDB-1 defines six unlike source-specific baselines, their physical worlds, provenance and closure law. Numerical closure remains open.
A6: Decision | B6: Decision | C6: Decision | D6: Decision | E6: Decision | F6: Decision | L6: Form | M6: Minimum W03 margin
L7: ET-A-A | M7: 0.001669627
A8: Selected architecture | B8: Six sovereign baselines with a public semantic kernel | L8: CT-C-B | M8: 0.0028571429
A9: Configuration objects | B9: 6 | C9: one for each active cohort-one form | L9: HC-A-C | M9: 0.0033980583
A10: Physical worlds | B10: 24 | C10: four per form | L10: LF-B-A | M10: 0.0015124698
A11: Noncompensatory accounts | B11: 54 | C11: nine per form | L11: HU-A-B | M11: 0.003275
A12: Source records | B12: 72 | C12: twelve per form | L12: RT-B-C | M12: 0.00016129032
A13: Present claim | B13: grammar constituted; all physical measurements and acceptances remain zero
A16: Engineering boundary | B16: Engineering boundary | C16: Engineering boundary | D16: Engineering boundary | E16: Engineering boundary | F16: Engineering boundary
A18: Configuration rule | B18: one content-addressed baseline binds all five packages for one form
A19: Load-case rule | B19: nominal, largest-cell loss, fatal keystone and cold rebuild use the same baseline
A20: Account rule | B20: service, mass, energy, flow, thermal, geometry, rights, residual and rebuild are conjunctive
A21: Source rule | B21: every inherited value carries class, allowed use, expiry and an explicit measured flag
A22: Missingness rule | B22: blank or open coefficient orders HOLD; midpoint and zero substitution are prohibited
A23: Technology rule | B23: eighteen form-induced advances end in fatal prototype events
A24: Authority rule | B24: design closure cannot create evidence, selection, MAKE, REP-4, capability or production credit
A27: Pass ledger | B27: Pass ledger | C27: Pass ledger | D27: Pass ledger | E27: Pass ledger | F27: Pass ledger
A29: Items opened | B29: 1
A30: Items closed | B30: 1
A31: Net change | B31: 0
A32: Running open total | B32: 1
A33: EDB passes consumed | B33: 1
A34: Branch budget | B34: 5
A35: No-KILL count since HR-02 | B35: 6

Sheet Decision Tests
A2: Engineering baseline architecture
A4: A candidate must pass every hard gate. A high score cannot compensate for one failed boundary.
A6: Candidate | B6: Architecture | C6: Root-native | D6: Four worlds | E6: Nine accounts | F6: Public provenance | G6: Unknowns visible | H6: Noncompensatory | I6: Cold rebuild | J6: Thirty packages | K6: Zero conversion | L6: Five-pass return | M6: Passed | N6: Disposition
A7: C1 | B7: Common platform master model | C7: 0 | D7: 1 | E7: 1 | F7: 1 | G7: 0 | H7: 0 | I7: 1 | J7: 1 | K7: 1 | L7: 1 | M7: =SUM(C7:L7) -> 7 | N7: =IF(M7=10,"SELECT","REJECT") -> REJECT
A8: C2 | B8: Six contractor digital twins | C8: 1 | D8: 1 | E8: 1 | F8: 0 | G8: 0 | H8: 1 | I8: 0 | J8: 1 | K8: 1 | L8: 1 | M8: =SUM(C8:L8) -> 7 | N8: =IF(M8=10,"SELECT","REJECT") -> REJECT
A9: C3 | B9: Interface-only baseline | C9: 1 | D9: 1 | E9: 0 | F9: 1 | G9: 1 | H9: 0 | I9: 1 | J9: 1 | K9: 1 | L9: 1 | M9: =SUM(C9:L9) -> 8 | N9: =IF(M9=10,"SELECT","REJECT") -> REJECT
A10: C4 | B10: Root-native baselines with common solver | C10: 1 | D10: 1 | E10: 1 | F10: 1 | G10: 1 | H10: 1 | I10: 1 | J10: 1 | K10: 0 | L10: 1 | M10: =SUM(C10:L10) -> 9 | N10: =IF(M10=10,"SELECT","REJECT") -> REJECT
A11: C5 | B11: Six sovereign baselines with public semantic kernel | C11: 1 | D11: 1 | E11: 1 | F11: 1 | G11: 1 | H11: 1 | I11: 1 | J11: 1 | K11: 1 | L11: 1 | M11: =SUM(C11:L11) -> 10 | N11: =IF(M11=10,"SELECT","REJECT") -> SELECT
A14: Selected interpretation | B14: Selected interpretation | C14: Selected interpretation | D14: Selected interpretation | E14: Selected interpretation | F14: Selected interpretation | G14: Selected interpretation | H14: Selected interpretation | I14: Selected interpretation | J14: Selected interpretation | K14: Selected interpretation | L14: Selected interpretation | M14: Selected interpretation | N14: Selected interpretation
A16: Decision | B16: EDB-1 | C16: Six source-specific configuration baselines under one narrow semantic grammar
A17: Shared layer | B17: Meaning only | C17: IDs, units, boundaries, provenance, uncertainty, causal trace, civil obligation
A18: Prohibited common layer | B18: Implementation | C18: No common solver, controller, geometry, safeing path, runtime or predicted performance
A19: Present authority | B19: SPECIFICATION | C19: No measurement, evidence, selection, MAKE, REP-4, capability or production credit

Sheet Baseline Register
A2: Cohort-one configuration baselines
A4: Each row is a controlled source-specific design object. It remains unmeasured and unaccepted.
A6: Form | B6: Root | C6: Service system | D6: Physical topology | E6: System envelope | F6: Largest isolated cell | G6: Reach | H6: Independence | I6: Minimum W03 margin | J6: Load cases | K6: Account rules | L6: Source records | M6: Form ceiling (USD M) | N6: Measured inputs | O6: State
A7: ET-A-A | B7: ET-A | C7: Pelagic exchange | D7: Twin-body pelagic exchange | E7: 160–210 × 90–130 × 26–36 m; 8–12 m draft | F7: 130–180 × 25–40 × 25–35 m | G7: 1–3 km | H7: two complete custody paths | I7: 0.001669627 | J7: =COUNTIFS('Load Cases'!$B$7:$B$30,A7) -> 4 | K7: =COUNTIFS('Account Grammar'!$B$7:$B$60,A7) -> 9 | L7: =COUNTIFS('Provenance Ledger'!$B$7:$B$78,A7) -> 12 | M7: 25.023731 | N7: 0 | O7: =IF(AND(J7=Inputs!$B$10,K7=Inputs!$B$9,L7=Inputs!$B$12,N7=0),"CONSTITUTED / UNMEASURED","INCOMPLETE") -> CONSTITUTED / UNMEASURED
A8: CT-C-B | B8: CT-C | C8: Occupied-boundary infrastructure | D8: Sectional suspended utility belt | E8: 800–2,000 × 12–22 × 45–120 m | F8: 100–250 × 6–10 × 6–12 m | G8: 2–6 km | H8: five anchor zones and five trunks | I8: 0.0028571429 | J8: =COUNTIFS('Load Cases'!$B$7:$B$30,A8) -> 4 | K8: =COUNTIFS('Account Grammar'!$B$7:$B$60,A8) -> 9 | L8: =COUNTIFS('Provenance Ledger'!$B$7:$B$78,A8) -> 12 | M8: 25.824674 | N8: 0 | O8: =IF(AND(J8=Inputs!$B$10,K8=Inputs!$B$9,L8=Inputs!$B$12,N8=0),"CONSTITUTED / UNMEASURED","INCOMPLETE") -> CONSTITUTED / UNMEASURED
A9: HC-A-C | B9: HC-A | C9: Atmospheric intervention | D9: Distributed rotorborne cells | E9: 1–3 × 5–12 × 0.05–0.5 km intervention field | F9: 12–24 × 12–28 × 4–9 m | G9: 3–20 km | H9: five rotor cells with local control | I9: 0.0033980583 | J9: =COUNTIFS('Load Cases'!$B$7:$B$30,A9) -> 4 | K9: =COUNTIFS('Account Grammar'!$B$7:$B$60,A9) -> 9 | L9: =COUNTIFS('Provenance Ledger'!$B$7:$B$78,A9) -> 12 | M9: 15.361083 | N9: 0 | O9: =IF(AND(J9=Inputs!$B$10,K9=Inputs!$B$9,L9=Inputs!$B$12,N9=0),"CONSTITUTED / UNMEASURED","INCOMPLETE") -> CONSTITUTED / UNMEASURED
A10: LF-B-A | B10: LF-B | C10: Geothermal water and power | D10: Cellular radial multi-bore field | E10: 500–1,500 × 500–1,500 × 20–45 m; 2.5–6 km depth | F10: 120–250 × 120–250 × 20–45 m | G10: 15.5–30 km | H10: nine access slots around four conversion cells | I10: 0.0015124698 | J10: =COUNTIFS('Load Cases'!$B$7:$B$30,A10) -> 4 | K10: =COUNTIFS('Account Grammar'!$B$7:$B$60,A10) -> 9 | L10: =COUNTIFS('Provenance Ledger'!$B$7:$B$78,A10) -> 12 | M10: 44.970641 | N10: 0 | O10: =IF(AND(J10=Inputs!$B$10,K10=Inputs!$B$9,L10=Inputs!$B$12,N10=0),"CONSTITUTED / UNMEASURED","INCOMPLETE") -> CONSTITUTED / UNMEASURED
A11: HU-A-B | B11: HU-A | C11: Clinical continuity | D11: Sectional bypassed care spine | E11: 350–800 × 80–180 × 12–30 m | F11: 50–100 × 50–80 × 12–30 m | G11: 1–5 km | H11: eight spine sections with independent bypass | I11: 0.003275 | J11: =COUNTIFS('Load Cases'!$B$7:$B$30,A11) -> 4 | K11: =COUNTIFS('Account Grammar'!$B$7:$B$60,A11) -> 9 | L11: =COUNTIFS('Provenance Ledger'!$B$7:$B$78,A11) -> 12 | M11: 43.035623 | N11: 0 | O11: =IF(AND(J11=Inputs!$B$10,K11=Inputs!$B$9,L11=Inputs!$B$12,N11=0),"CONSTITUTED / UNMEASURED","INCOMPLETE") -> CONSTITUTED / UNMEASURED
A12: RT-B-C | B12: RT-B | C12: Disconnected regeneration | D12: Parallel mobile microfactory trainlets | E12: 500–2,000 × 100–400 × 8–16 m | F12: 100–250 × 25–60 × 8–16 m | G12: 5–20 km | H12: five complete mobile trainlets | I12: 0.00016129032 | J12: =COUNTIFS('Load Cases'!$B$7:$B$30,A12) -> 4 | K12: =COUNTIFS('Account Grammar'!$B$7:$B$60,A12) -> 9 | L12: =COUNTIFS('Provenance Ledger'!$B$7:$B$78,A12) -> 12 | M12: 25.12989 | N12: 0 | O12: =IF(AND(J12=Inputs!$B$10,K12=Inputs!$B$9,L12=Inputs!$B$12,N12=0),"CONSTITUTED / UNMEASURED","INCOMPLETE") -> CONSTITUTED / UNMEASURED

Sheet Load Cases
A2: Registered load cases
A4: Four worlds apply to every form. Their conditions differ by mechanism and remain unobserved.
A6: Case | B6: Form | C6: World | D6: Configuration | E6: Denial or intervention | F6: Required controlled outcome | G6: Observation | H6: Evidence credit | I6: Source | J6: State
A7: ET-A-A-W01 | B7: ET-A-A | C7: NOMINAL | D7: lower-bound configured article | E7: none | F7: close all nine account rules at the registered service denominator | H7: 0 | I7: Passes 216/219 | J7: SPECIFIED / UNOBSERVED
A8: ET-A-A-W02 | B8: ET-A-A | C8: LARGEST_CELL_LOSS | D8: same baseline and receiver | E8: two complete custody paths | F8: preserve complete service without cross-boundary propagation | H8: 0 | I8: Pass 219 | J8: SPECIFIED / UNOBSERVED
A9: ET-A-A-W03 | B9: ET-A-A | C9: FATAL_KEYSTONE | D9: full causal interface | E9: disable one body and its energy, control and custody chain at peak relative motion | F9: produce the disqualifying observation or pass every conjunctive boundary | H9: 0 | I9: Pass 225 | J9: SPECIFIED / UNOBSERVED
A10: ET-A-A-W04 | B10: ET-A-A | C10: COLD_REBUILD | D10: sealed public record and physical inventory | E10: deny builder team, runtime, vendor key and tacit setup | F10: reconstruct and requalify the complete causal section within 168 h | H10: 0 | I10: Passes 219/232 | J10: SPECIFIED / UNOBSERVED
A11: CT-C-B-W01 | B11: CT-C-B | C11: NOMINAL | D11: lower-bound configured article | E11: none | F11: close all nine account rules at the registered service denominator | H11: 0 | I11: Passes 216/219 | J11: SPECIFIED / UNOBSERVED
A12: CT-C-B-W02 | B12: CT-C-B | C12: LARGEST_CELL_LOSS | D12: same baseline and receiver | E12: five anchor zones and five trunks | F12: preserve complete service without cross-boundary propagation | H12: 0 | I12: Pass 219 | J12: SPECIFIED / UNOBSERVED
A13: CT-C-B-W03 | B13: CT-C-B | C13: FATAL_KEYSTONE | D13: full causal interface | E13: release one anchor zone and fault one mixed-utility belt section under occupied load | F13: produce the disqualifying observation or pass every conjunctive boundary | H13: 0 | I13: Pass 225 | J13: SPECIFIED / UNOBSERVED
A14: CT-C-B-W04 | B14: CT-C-B | C14: COLD_REBUILD | D14: sealed public record and physical inventory | E14: deny builder team, runtime, vendor key and tacit setup | F14: reconstruct and requalify the complete causal section within 168 h | H14: 0 | I14: Passes 219/232 | J14: SPECIFIED / UNOBSERVED
A15: HC-A-C-W01 | B15: HC-A-C | C15: NOMINAL | D15: lower-bound configured article | E15: none | F15: close all nine account rules at the registered service denominator | H15: 0 | I15: Passes 216/219 | J15: SPECIFIED / UNOBSERVED
A16: HC-A-C-W02 | B16: HC-A-C | C16: LARGEST_CELL_LOSS | D16: same baseline and receiver | E16: five rotor cells with local control | F16: preserve complete service without cross-boundary propagation | H16: 0 | I16: Pass 219 | J16: SPECIFIED / UNOBSERVED
A17: HC-A-C-W03 | B17: HC-A-C | C17: FATAL_KEYSTONE | D17: full causal interface | E17: deny the coordination network and safe one rotor cell inside a plume corridor | F17: produce the disqualifying observation or pass every conjunctive boundary | H17: 0 | I17: Pass 225 | J17: SPECIFIED / UNOBSERVED
A18: HC-A-C-W04 | B18: HC-A-C | C18: COLD_REBUILD | D18: sealed public record and physical inventory | E18: deny builder team, runtime, vendor key and tacit setup | F18: reconstruct and requalify the complete causal section within 168 h | H18: 0 | I18: Passes 219/232 | J18: SPECIFIED / UNOBSERVED
... A30: RT-B-C-W04 | B30: RT-B-C | C30: COLD_REBUILD | D30: sealed public record and physical inventory | E30: deny builder team, runtime, vendor key and tacit setup | F30: reconstruct and requalify the complete causal section within 168 h | H30: 0 | I30: Passes 219/232 | J30: SPECIFIED / UNOBSERVED

Sheet Account Grammar
A2: Noncompensatory account grammar
A4: Every form must close all nine accounts in all four worlds. Missing inputs order HOLD and never become zero.
A6: Record | B6: Form | C6: Account | D6: Definition | E6: Unit | F6: Inherited design input | G6: Input class | H6: Closure rule | I6: Missing treatment | J6: Measured input | K6: Current state | L6: Next physical object
A7: ET-A-A-SVC | B7: ET-A-A | C7: SVC | D7: Service denominator | E7: root-native service | F7: 600 t/h rated; at least 241 t/h surviving path; start by h72; sustain 30 d | G7: INHERITED REQUIREMENT | H7: registered service and duration are conjunctive | I7: HOLD | K7: DEFINED / UNMEASURED | L7: receiver-complete service trace
A8: ET-A-A-MASS | B8: ET-A-A | C8: MASS | D8: Mass and custody | E8: root-native mass | F8: 102,000 t requirement; 112,000 t survivor capacity | G8: INHERITED DESIGN HYPOTHESIS | H8: owned mass and custody close nominal and loss worlds | I8: HOLD | K8: DEFINED / UNMEASURED | L8: weighed article and custody ledger
A9: ET-A-A-ENERGY | B9: ET-A-A | C9: ENERGY | D9: Energy balance | E9: MW | F9: 96 MW requirement; 100 MW survivor capacity | G9: INHERITED DESIGN HYPOTHESIS | H9: generation, storage, start and rejection close by cell | I9: HOLD | K9: DEFINED / UNMEASURED | L9: instrumented bus and black-start test
A10: ET-A-A-FLOW | B10: ET-A-A | C10: FLOW | D10: Flow or productive rate | E10: root-native rate | F10: 235 t/h lower-bound requirement; 241 t/h survivor capacity | G10: INHERITED DESIGN HYPOTHESIS | H10: delivered rate closes at the lawful receiver after loss | I10: HOLD | K10: DEFINED / UNMEASURED | L10: metered causal flow section
A11: ET-A-A-THERMAL | B11: ET-A-A | C11: THERMAL | D11: Thermal state | E11: root-native heat | F11: OPEN: connector-drive and wet-dry transient rejection | G11: MISSING DESIGN COEFFICIENT | H11: source, conversion, storage and rejection close transient and sustained states | I11: HOLD | K11: DEFINED / COEFFICIENT OPEN | L11: calorimetric transient section
A12: ET-A-A-GEOMETRY | B12: ET-A-A | C12: GEOMETRY | D12: Geometry and load path | E12: interval | F12: 160–210 × 90–130 × 26–36 m; 8–12 m draft | G12: INHERITED INTERVAL | H12: every decisive interface fits inside the baseline without midpoint substitution | I12: HOLD | K12: DEFINED / UNMEASURED | L12: surveyed coordinate and load article
A13: ET-A-A-RIGHTS | B13: ET-A-A | C13: RIGHTS | D13: Safe state and civil rights | E13: conjunctive | F13: six refuge/receiver zones; five survive largest loss | G13: INHERITED DESIGN HYPOTHESIS | H13: detection, isolation, refuge, egress, consent and disposition all close | I13: HOLD | K13: DEFINED / UNMEASURED | L13: receiver and protected-state drill
A14: ET-A-A-RESIDUAL | B14: ET-A-A | C14: RESIDUAL | D14: Residual custody | E14: root-native residual | F14: 1,200 t/day requirement; 1,260 t/day survivor capacity | G14: INHERITED DESIGN HYPOTHESIS | H14: generated, retained, treated and released material reconciles | I14: HOLD | K14: DEFINED / UNMEASURED | L14: sealed residual balance trial
A15: ET-A-A-REBUILD | B15: ET-A-A | C15: REBUILD | D15: Cold reconstruction | E15: h | F15: complete exchange section within 168 h | G15: INHERITED TEST CEILING | H15: outside team rebuilds and requalifies without prohibited dependencies | I15: HOLD | K15: DEFINED / UNMEASURED | L15: clean-team reconstruction event
A16: CT-C-B-SVC | B16: CT-C-B | C16: SVC | D16: Service denominator | E16: root-native service | F16: 105,000 people; 42,800 households; 180 route-km by h168 | G16: INHERITED REQUIREMENT | H16: registered service and duration are conjunctive | I16: HOLD | K16: DEFINED / UNMEASURED | L16: receiver-complete service trace
A17: CT-C-B-MASS | B17: CT-C-B | C17: MASS | D17: Mass and custody | E17: root-native mass | F17: 31,000 t requirement; 32,400 t survivor capacity | G17: INHERITED DESIGN HYPOTHESIS | H17: owned mass and custody close nominal and loss worlds | I17: HOLD | K17: DEFINED / UNMEASURED | L17: weighed article and custody ledger
A18: CT-C-B-ENERGY | B18: CT-C-B | C18: ENERGY | D18: Energy balance | E18: MW | F18: 42 MW requirement; 43.2 MW survivor capacity | G18: INHERITED DESIGN HYPOTHESIS | H18: generation, storage, start and rejection close by cell | I18: HOLD | K18: DEFINED / UNMEASURED | L18: instrumented bus and black-start test
... A60: RT-B-C-REBUILD | B60: RT-B-C | C60: REBUILD | D60: Cold reconstruction | E60: h | F60: dirty-return-to-release trainlet within 168 h | G60: INHERITED TEST CEILING | H60: outside team rebuilds and requalifies without prohibited dependencies | I60: HOLD | K60: DEFINED / UNMEASURED | L60: clean-team reconstruction event

Sheet Provenance Ledger
A2: Repository source and provenance ledger
A4: Every inherited value is a design input with an allowed use and expiry. No repository estimate is relabeled as measurement.
A6: Source record | B6: Form | C6: Parameter family | D6: Source artifact | E6: Pass | F6: Source class | G6: Inherited value | H6: Unit | I6: Allowed use | J6: Measured | K6: Expiry trigger | L6: State
A7: S001 | B7: ET-A-A | C7: Service denominator | D7: department-of-resilience-six-root-form-giving-candidate-article-requirement-constitution.md | E7: 216 | F7: DESIGN REQUIREMENT | G7: 600 t/h rated; at least 241 t/h surviving path; start by h72; sustain 30 d | H7: root-native | I7: size test article and receiver burden | J7: 0 | K7: denominator supersession | L7: ADMITTED / UNMEASURED
A8: S002 | B8: ET-A-A | C8: Article boundary | D8: department-of-resilience-six-root-form-giving-candidate-article-requirement-constitution.md | E8: 216 | F8: DESIGN REQUIREMENT | G8: motion-decoupled flow and dry custody | H8: text | I8: bound causal interface | J8: 0 | K8: boundary supersession | L8: ADMITTED / UNMEASURED
A9: S003 | B9: ET-A-A | C9: Internal partitions | D9: department-of-resilience-six-root-internal-section-architecture-and-measurement-constitution.md | E9: 219 | F9: DESIGN HYPOTHESIS | G9: two complete custody paths | H9: text | I9: define loss-isolated cells | J9: 0 | K9: section supersession | L9: ADMITTED / UNMEASURED
A10: S004 | B10: ET-A-A | C10: Mass account | D10: department-of-resilience-six-root-internal-section-architecture-and-measurement-constitution.md | E10: 219 | F10: DESIGN HYPOTHESIS | G10: 102,000 t requirement; 112,000 t survivor capacity | H10: root-native | I10: prepare mass ledger | J10: 0 | K10: measured mass available | L10: ADMITTED / UNMEASURED
A11: S005 | B11: ET-A-A | C11: Energy account | D11: department-of-resilience-six-root-internal-section-architecture-and-measurement-constitution.md | E11: 219 | F11: DESIGN HYPOTHESIS | G11: 96 MW requirement; 100 MW survivor capacity | H11: MW | I11: prepare energy ledger | J11: 0 | K11: measured power available | L11: ADMITTED / UNMEASURED
A12: S006 | B12: ET-A-A | C12: Flow account | D12: department-of-resilience-six-root-internal-section-architecture-and-measurement-constitution.md | E12: 219 | F12: DESIGN HYPOTHESIS | G12: 235 t/h lower-bound requirement; 241 t/h survivor capacity | H12: root-native | I12: prepare rate ledger | J12: 0 | K12: measured flow available | L12: ADMITTED / UNMEASURED
A13: S007 | B13: ET-A-A | C13: Civil and safe state | D13: department-of-resilience-six-root-internal-section-architecture-and-measurement-constitution.md | E13: 219 | F13: DESIGN HYPOTHESIS | G13: six refuge/receiver zones; five survive largest loss | H13: conjunctive | I13: prepare protected-state protocol | J13: 0 | K13: rights covenant supersession | L13: ADMITTED / UNMEASURED
A14: S008 | B14: ET-A-A | C14: Residual account | D14: department-of-resilience-six-root-internal-section-architecture-and-measurement-constitution.md | E14: 219 | F14: DESIGN HYPOTHESIS | G14: 1,200 t/day requirement; 1,260 t/day survivor capacity | H14: root-native | I14: prepare residual ledger | J14: 0 | K14: measured residual available | L14: ADMITTED / UNMEASURED
A15: S009 | B15: ET-A-A | C15: Cold rebuild ceiling | D15: department-of-resilience-six-root-internal-section-architecture-and-measurement-constitution.md | E15: 219 | F15: TEST CEILING | G15: complete exchange section within 168 h | H15: h | I15: prepare reconstruction event | J15: 0 | K15: clock supersession | L15: ADMITTED / UNMEASURED
A16: S010 | B16: ET-A-A | C16: Dimension envelope | D16: department-of-resilience-six-root-native-dimension-envelope-and-decisive-interface-atlas.md | E16: 224 | F16: PLANNING INTERVAL | G16: 160–210 × 90–130 × 26–36 m; 8–12 m draft | H16: interval | I16: bound exploration without midpoint | J16: 0 | K16: surveyed geometry available | L16: ADMITTED / UNMEASURED
A17: S011 | B17: ET-A-A | C17: Fatal event | D17: department-of-resilience-six-root-pre-evidence-form-selection-covenant-and-return.md | E17: 225 | F17: EXPERIMENT SPECIFICATION | G17: disable one body and its energy, control and custody chain at peak relative motion | H17: text | I17: freeze disqualifying test | J17: 0 | K17: event invalidation | L17: ADMITTED / UNMEASURED
A18: S012 | B18: ET-A-A | C18: Form ceiling | D18: department-of-resilience-cohort-one-execution-warrant-and-protected-sibling-reserve.md | E18: 229 | F18: FISCAL CEILING | G18: 25.023731 | H18: USD M | I18: cap five design packages | J18: 0 | K18: fiscal supersession | L18: ADMITTED / UNMEASURED
A19: S013 | B19: CT-C-B | C19: Service denominator | D19: department-of-resilience-six-root-form-giving-candidate-article-requirement-constitution.md | E19: 216 | F19: DESIGN REQUIREMENT | G19: 105,000 people; 42,800 households; 180 route-km by h168 | H19: root-native | I19: size test article and receiver burden | J19: 0 | K19: denominator supersession | L19: ADMITTED / UNMEASURED
A20: S014 | B20: CT-C-B | C20: Article boundary | D20: department-of-resilience-six-root-form-giving-candidate-article-requirement-constitution.md | E20: 216 | F20: DESIGN REQUIREMENT | G20: fault-contained attachment and five-utility insertion | H20: text | I20: bound causal interface | J20: 0 | K20: boundary supersession | L20: ADMITTED / UNMEASURED
A21: S015 | B21: CT-C-B | C21: Internal partitions | D21: department-of-resilience-six-root-internal-section-architecture-and-measurement-constitution.md | E21: 219 | F21: DESIGN HYPOTHESIS | G21: five anchor zones and five trunks | H21: text | I21: define loss-isolated cells | J21: 0 | K21: section supersession | L21: ADMITTED / UNMEASURED
A22: S016 | B22: CT-C-B | C22: Mass account | D22: department-of-resilience-six-root-internal-section-architecture-and-measurement-constitution.md | E22: 219 | F22: DESIGN HYPOTHESIS | G22: 31,000 t requirement; 32,400 t survivor capacity | H22: root-native | I22: prepare mass ledger | J22: 0 | K22: measured mass available | L22: ADMITTED / UNMEASURED
A23: S017 | B23: CT-C-B | C23: Energy account | D23: department-of-resilience-six-root-internal-section-architecture-and-measurement-constitution.md | E23: 219 | F23: DESIGN HYPOTHESIS | G23: 42 MW requirement; 43.2 MW survivor capacity | H23: MW | I23: prepare energy ledger | J23: 0 | K23: measured power available | L23: ADMITTED / UNMEASURED
A24: S018 | B24: CT-C-B | C24: Flow account | D24: department-of-resilience-six-root-internal-section-architecture-and-measurement-constitution.md | E24: 219 | F24: DESIGN HYPOTHESIS | G24: five complete trunks; four survive largest loss | H24: root-native | I24: prepare rate ledger | J24: 0 | K24: measured flow available | L24: ADMITTED / UNMEASURED
A25: S019 | B25: CT-C-B | C25: Civil and safe state | D25: department-of-resilience-six-root-internal-section-architecture-and-measurement-constitution.md | E25: 219 | F25: DESIGN HYPOTHESIS | G25: eight occupied safe zones; seven survive largest loss | H25: conjunctive | I25: prepare protected-state protocol | J25: 0 | K25: rights covenant supersession | L25: ADMITTED / UNMEASURED
A26: S020 | B26: CT-C-B | C26: Residual account | D26: department-of-resilience-six-root-internal-section-architecture-and-measurement-constitution.md | E26: 219 | F26: DESIGN HYPOTHESIS | G26: 220 t/day requirement; 231 t/day survivor capacity | H26: root-native | I26: prepare residual ledger | J26: 0 | K26: measured residual available | L26: ADMITTED / UNMEASURED
A27: S021 | B27: CT-C-B | C27: Cold rebuild ceiling | D27: department-of-resilience-six-root-internal-section-architecture-and-measurement-constitution.md | E27: 219 | F27: TEST CEILING | G27: occupied-spine section within 168 h | H27: h | I27: prepare reconstruction event | J27: 0 | K27: clock supersession | L27: ADMITTED / UNMEASURED
A28: S022 | B28: CT-C-B | C28: Dimension envelope | D28: department-of-resilience-six-root-native-dimension-envelope-and-decisive-interface-atlas.md | E28: 224 | F28: PLANNING INTERVAL | G28: 800–2,000 × 12–22 × 45–120 m | H28: interval | I28: bound exploration without midpoint | J28: 0 | K28: surveyed geometry available | L28: ADMITTED / UNMEASURED
A29: S023 | B29: CT-C-B | C29: Fatal event | D29: department-of-resilience-six-root-pre-evidence-form-selection-covenant-and-return.md | E29: 225 | F29: EXPERIMENT SPECIFICATION | G29: release one anchor zone and fault one mixed-utility belt section under occupied load | H29: text | I29: freeze disqualifying test | J29: 0 | K29: event invalidation | L29: ADMITTED / UNMEASURED
A30: S024 | B30: CT-C-B | C30: Form ceiling | D30: department-of-resilience-cohort-one-execution-warrant-and-protected-sibling-reserve.md | E30: 229 | F30: FISCAL CEILING | G30: 25.824674 | H30: USD M | I30: cap five design packages | J30: 0 | K30: fiscal supersession | L30: ADMITTED / UNMEASURED
A31: S025 | B31: HC-A-C | C31: Service denominator | D31: department-of-resilience-six-root-form-giving-candidate-article-requirement-constitution.md | E31: 216 | F31: DESIGN REQUIREMENT | G31: first attributable effect by h6; 1 km by h18; hold 72 h | H31: root-native | I31: size test article and receiver burden | J31: 0 | K31: denominator supersession | L31: ADMITTED / UNMEASURED
A32: S026 | B32: HC-A-C | C32: Article boundary | D32: department-of-resilience-six-root-form-giving-candidate-article-requirement-constitution.md | E32: 216 | F32: DESIGN REQUIREMENT | G32: attributable held-line effect under network denial | H32: text | I32: bound causal interface | J32: 0 | K32: boundary supersession | L32: ADMITTED / UNMEASURED
A33: S027 | B33: HC-A-C | C33: Internal partitions | D33: department-of-resilience-six-root-internal-section-architecture-and-measurement-constitution.md | E33: 219 | F33: DESIGN HYPOTHESIS | G33: five rotor cells with local control | H33: text | I33: define loss-isolated cells | J33: 0 | K33: section supersession | L33: ADMITTED / UNMEASURED
A34: S028 | B34: HC-A-C | C34: Mass account | D34: department-of-resilience-six-root-internal-section-architecture-and-measurement-constitution.md | E34: 219 | F34: DESIGN HYPOTHESIS | G34: 54,000 t requirement; 56,700 t survivor capacity | H34: root-native | I34: prepare mass ledger | J34: 0 | K34: measured mass available | L34: ADMITTED / UNMEASURED
A35: S029 | B35: HC-A-C | C35: Energy account | D35: department-of-resilience-six-root-internal-section-architecture-and-measurement-constitution.md | E35: 219 | F35: DESIGN HYPOTHESIS | G35: 140 MW requirement; 144 MW survivor capacity | H35: MW | I35: prepare energy ledger | J35: 0 | K35: measured power available | L35: ADMITTED / UNMEASURED
A36: S030 | B36: HC-A-C | C36: Flow account | D36: department-of-resilience-six-root-internal-section-architecture-and-measurement-constitution.md | E36: 219 | F36: DESIGN HYPOTHESIS | G36: 103 km/day requirement; 106 km/day survivor capacity | H36: root-native | I36: prepare rate ledger | J36: 0 | K36: measured flow available | L36: ADMITTED / UNMEASURED
A37: S031 | B37: HC-A-C | C37: Civil and safe state | D37: department-of-resilience-six-root-internal-section-architecture-and-measurement-constitution.md | E37: 219 | F37: DESIGN HYPOTHESIS | G37: eight response/avoidance zones; seven survive largest loss | H37: conjunctive | I37: prepare protected-state protocol | J37: 0 | K37: rights covenant supersession | L37: ADMITTED / UNMEASURED
A38: S032 | B38: HC-A-C | C38: Residual account | D38: department-of-resilience-six-root-internal-section-architecture-and-measurement-constitution.md | E38: 219 | F38: DESIGN HYPOTHESIS | G38: 900 t/day requirement; 945 t/day survivor capacity | H38: root-native | I38: prepare residual ledger | J38: 0 | K38: measured residual available | L38: ADMITTED / UNMEASURED
A39: S033 | B39: HC-A-C | C39: Cold rebuild ceiling | D39: department-of-resilience-six-root-internal-section-architecture-and-measurement-constitution.md | E39: 219 | F39: TEST CEILING | G39: sensing-to-runoff section within 168 h | H39: h | I39: prepare reconstruction event | J39: 0 | K39: clock supersession | L39: ADMITTED / UNMEASURED
A40: S034 | B40: HC-A-C | C40: Dimension envelope | D40: department-of-resilience-six-root-native-dimension-envelope-and-decisive-interface-atlas.md | E40: 224 | F40: PLANNING INTERVAL | G40: 1–3 × 5–12 × 0.05–0.5 km intervention field | H40: interval | I40: bound exploration without midpoint | J40: 0 | K40: surveyed geometry available | L40: ADMITTED / UNMEASURED
A41: S035 | B41: HC-A-C | C41: Fatal event | D41: department-of-resilience-six-root-pre-evidence-form-selection-covenant-and-return.md | E41: 225 | F41: EXPERIMENT SPECIFICATION | G41: deny the coordination network and safe one rotor cell inside a plume corridor | H41: text | I41: freeze disqualifying test | J41: 0 | K41: event invalidation | L41: ADMITTED / UNMEASURED
A42: S036 | B42: HC-A-C | C42: Form ceiling | D42: department-of-resilience-cohort-one-execution-warrant-and-protected-sibling-reserve.md | E42: 229 | F42: FISCAL CEILING | G42: 15.361083 | H42: USD M | I42: cap five design packages | J42: 0 | K42: fiscal supersession | L42: ADMITTED / UNMEASURED
A43: S037 | B43: LF-B-A | C43: Service denominator | D43: department-of-resilience-six-root-form-giving-candidate-article-requirement-constitution.md | E43: 216 | F43: DESIGN REQUIREMENT | G43: 25,000 m³/day water; 25 MW electric; 20 MWth by h72; four positions by d21 | H43: root-native | I43: size test article and receiver burden | J43: 0 | K43: denominator supersession | L43: ADMITTED / UNMEASURED
...

Sheet Closure Rules
A2: Baseline closure rules
A4: The rules make missingness, uncertainty, failure and downstream authority explicit.
A6: Rule | B6: Class | C6: Subject | D6: Requirement | E6: Failure disposition | F6: Cannot substitute | G6: Current state | H6: Authority
A7: R01 | B7: CONFIGURATION | C7: one baseline per form | D7: one content-addressed configuration binds all packages | E7: HOLD | F7: package-local drift | G7: CONSTITUTED | H7: EDB-1
A8: R02 | B8: CONFIGURATION | C8: root independence | D8: no shared decisive solver, controller, safeing path or runtime | E8: KILL / REDESIGN | F8: semantic interoperability | G8: CONSTITUTED | H8: EDB-1
A9: R03 | B9: WORLD | C9: nominal | D9: all nine accounts close together | E9: HOLD | F9: favorable subsystem | G9: CONSTITUTED | H9: EDB-1
A10: R04 | B10: WORLD | C10: largest-cell loss | D10: same configuration and receiver; one largest cell absent | E10: HOLD | F10: aggregate reserve | G10: CONSTITUTED | H10: EDB-1
A11: R05 | B11: WORLD | C11: fatal keystone | D11: frozen intervention and disqualifying observation | E11: WITHDRAW after valid failure | F11: simulation | G11: CONSTITUTED | H11: Pass 225
A12: R06 | B12: WORLD | C12: cold rebuild | D12: builder team, runtime, private keys and tacit setup denied | E12: HOLD | F12: vendor service | G12: CONSTITUTED | H12: Pass 219
A13: R07 | B13: ACCOUNT | C13: service | D13: time, duration, receiver and quality are conjunctive | E13: HOLD | F13: gross output | G13: CONSTITUTED | H13: EDB-1
A14: R08 | B14: ACCOUNT | C14: mass | D14: owned inventory and custody close by configuration | E14: HOLD | F14: transport capacity | G14: CONSTITUTED | H14: EDB-1
A15: R09 | B15: ACCOUNT | C15: energy | D15: generation, storage, black start and rejection close by cell | E15: HOLD | F15: nameplate power | G15: CONSTITUTED | H15: EDB-1
A16: R10 | B16: ACCOUNT | C16: flow | D16: source-to-receiver causal rate closes after loss | E16: HOLD | F16: machine throughput | G16: CONSTITUTED | H16: EDB-1
A17: R11 | B17: ACCOUNT | C17: thermal | D17: transient and sustained temperature states remain bounded | E17: HOLD | F17: electrical surplus | G17: CONSTITUTED | H17: EDB-1
... A30: R24 | B30: AUTHORITY | C30: physical work | D30: MAKE requires separate construction warrant | E30: TERMINATE conversion | F30: paid design | G30: CONSTITUTED | H30: Pass 235

Sheet Package Crosswalk
A2: Thirty-package account crosswalk
A4: Five packages divide accountability without allowing one package or office to declare whole-form closure.
A6: Package | B6: Form | C6: Family | D6: Work package | E6: Share | F6: Ceiling (USD M) | G6: SVC | H6: MASS | I6: ENERGY | J6: FLOW | K6: THERMAL | L6: GEOMETRY | M6: RIGHTS | N6: RESIDUAL | O6: REBUILD | P6: Accounts covered | Q6: State
A7: P01 | B7: ET-A-A | C7: METHOD | D7: Event method and denominator | E7: 0.2 | F7: =E7*SUMIFS('Baseline Register'!$M$7:$M$12,'Baseline Register'!$A$7:$A$12,B7) -> 5.0047462 | G7: 1 | H7: 0 | I7: 0 | J7: 1 | K7: 1 | L7: 0 | M7: 1 | N7: 0 | O7: 0 | P7: =SUM(G7:O7) -> 4 | Q7: =IF(P7>=4,"ASSIGNED / WORK OPEN","INCOMPLETE") -> ASSIGNED / WORK OPEN
A8: P02 | B8: ET-A-A | C8: MEASURE | D8: Instrumentation, custody and validity | E8: 0.25 | F8: =E8*SUMIFS('Baseline Register'!$M$7:$M$12,'Baseline Register'!$A$7:$A$12,B8) -> 6.2559327 | G8: 1 | H8: 1 | I8: 1 | J8: 1 | K8: 1 | L8: 1 | M8: 1 | N8: 1 | O8: 1 | P8: =SUM(G8:O8) -> 9 | Q8: =IF(P8>=4,"ASSIGNED / WORK OPEN","INCOMPLETE") -> ASSIGNED / WORK OPEN
A9: P03 | B9: ET-A-A | C9: CIVIL | D9: Rights, receiver and residual closure | E9: 0.15 | F9: =E9*SUMIFS('Baseline Register'!$M$7:$M$12,'Baseline Register'!$A$7:$A$12,B9) -> 3.7535596 | G9: 1 | H9: 0 | I9: 0 | J9: 0 | K9: 0 | L9: 1 | M9: 1 | N9: 1 | O9: 0 | P9: =SUM(G9:O9) -> 4 | Q9: =IF(P9>=4,"ASSIGNED / WORK OPEN","INCOMPLETE") -> ASSIGNED / WORK OPEN
A10: P04 | B10: ET-A-A | C10: ARTICLE | D10: Destructive-article engineering | E10: 0.25 | F10: =E10*SUMIFS('Baseline Register'!$M$7:$M$12,'Baseline Register'!$A$7:$A$12,B10) -> 6.2559327 | G10: 1 | H10: 1 | I10: 1 | J10: 1 | K10: 1 | L10: 1 | M10: 0 | N10: 1 | O10: 0 | P10: =SUM(G10:O10) -> 7 | Q10: =IF(P10>=4,"ASSIGNED / WORK OPEN","INCOMPLETE") -> ASSIGNED / WORK OPEN
A11: P05 | B11: ET-A-A | C11: REBUILD | D11: Cold reconstruction and challenge | E11: 0.15 | F11: =E11*SUMIFS('Baseline Register'!$M$7:$M$12,'Baseline Register'!$A$7:$A$12,B11) -> 3.7535596 | G11: 1 | H11: 1 | I11: 1 | J11: 1 | K11: 1 | L11: 1 | M11: 1 | N11: 1 | O11: 1 | P11: =SUM(G11:O11) -> 9 | Q11: =IF(P11>=4,"ASSIGNED / WORK OPEN","INCOMPLETE") -> ASSIGNED / WORK OPEN
A12: P06 | B12: CT-C-B | C12: METHOD | D12: Event method and denominator | E12: 0.2 | F12: =E12*SUMIFS('Baseline Register'!$M$7:$M$12,'Baseline Register'!$A$7:$A$12,B12) -> 5.1649348 | G12: 1 | H12: 0 | I12: 0 | J12: 1 | K12: 1 | L12: 0 | M12: 1 | N12: 0 | O12: 0 | P12: =SUM(G12:O12) -> 4 | Q12: =IF(P12>=4,"ASSIGNED / WORK OPEN","INCOMPLETE") -> ASSIGNED / WORK OPEN
A13: P07 | B13: CT-C-B | C13: MEASURE | D13: Instrumentation, custody and validity | E13: 0.25 | F13: =E13*SUMIFS('Baseline Register'!$M$7:$M$12,'Baseline Register'!$A$7:$A$12,B13) -> 6.4561685 | G13: 1 | H13: 1 | I13: 1 | J13: 1 | K13: 1 | L13: 1 | M13: 1 | N13: 1 | O13: 1 | P13: =SUM(G13:O13) -> 9 | Q13: =IF(P13>=4,"ASSIGNED / WORK OPEN","INCOMPLETE") -> ASSIGNED / WORK OPEN
A14: P08 | B14: CT-C-B | C14: CIVIL | D14: Rights, receiver and residual closure | E14: 0.15 | F14: =E14*SUMIFS('Baseline Register'!$M$7:$M$12,'Baseline Register'!$A$7:$A$12,B14) -> 3.8737011 | G14: 1 | H14: 0 | I14: 0 | J14: 0 | K14: 0 | L14: 1 | M14: 1 | N14: 1 | O14: 0 | P14: =SUM(G14:O14) -> 4 | Q14: =IF(P14>=4,"ASSIGNED / WORK OPEN","INCOMPLETE") -> ASSIGNED / WORK OPEN
A15: P09 | B15: CT-C-B | C15: ARTICLE | D15: Destructive-article engineering | E15: 0.25 | F15: =E15*SUMIFS('Baseline Register'!$M$7:$M$12,'Baseline Register'!$A$7:$A$12,B15) -> 6.4561685 | G15: 1 | H15: 1 | I15: 1 | J15: 1 | K15: 1 | L15: 1 | M15: 0 | N15: 1 | O15: 0 | P15: =SUM(G15:O15) -> 7 | Q15: =IF(P15>=4,"ASSIGNED / WORK OPEN","INCOMPLETE") -> ASSIGNED / WORK OPEN
A16: P10 | B16: CT-C-B | C16: REBUILD | D16: Cold reconstruction and challenge | E16: 0.15 | F16: =E16*SUMIFS('Baseline Register'!$M$7:$M$12,'Baseline Register'!$A$7:$A$12,B16) -> 3.8737011 | G16: 1 | H16: 1 | I16: 1 | J16: 1 | K16: 1 | L16: 1 | M16: 1 | N16: 1 | O16: 1 | P16: =SUM(G16:O16) -> 9 | Q16: =IF(P16>=4,"ASSIGNED / WORK OPEN","INCOMPLETE") -> ASSIGNED / WORK OPEN
A17: P11 | B17: HC-A-C | C17: METHOD | D17: Event method and denominator | E17: 0.2 | F17: =E17*SUMIFS('Baseline Register'!$M$7:$M$12,'Baseline Register'!$A$7:$A$12,B17) -> 3.0722165 | G17: 1 | H17: 0 | I17: 0 | J17: 1 | K17: 1 | L17: 0 | M17: 1 | N17: 0 | O17: 0 | P17: =SUM(G17:O17) -> 4 | Q17: =IF(P17>=4,"ASSIGNED / WORK OPEN","INCOMPLETE") -> ASSIGNED / WORK OPEN
A18: P12 | B18: HC-A-C | C18: MEASURE | D18: Instrumentation, custody and validity | E18: 0.25 | F18: =E18*SUMIFS('Baseline Register'!$M$7:$M$12,'Baseline Register'!$A$7:$A$12,B18) -> 3.8402707 | G18: 1 | H18: 1 | I18: 1 | J18: 1 | K18: 1 | L18: 1 | M18: 1 | N18: 1 | O18: 1 | P18: =SUM(G18:O18) -> 9 | Q18: =IF(P18>=4,"ASSIGNED / WORK OPEN","INCOMPLETE") -> ASSIGNED / WORK OPEN
... A36: P30 | B36: RT-B-C | C36: REBUILD | D36: Cold reconstruction and challenge | E36: 0.15 | F36: =E36*SUMIFS('Baseline Register'!$M$7:$M$12,'Baseline Register'!$A$7:$A$12,B36) -> 3.7694834 | G36: 1 | H36: 1 | I36: 1 | J36: 1 | K36: 1 | L36: 1 | M36: 1 | N36: 1 | O36: 1 | P36: =SUM(G36:O36) -> 9 | Q36: =IF(P36>=4,"ASSIGNED / WORK OPEN","INCOMPLETE") -> ASSIGNED / WORK OPEN

Sheet Technology Thrusts
A2: Form-induced technology programs
A4: Eighteen advances follow from the active forms. Each ends in a fatal prototype event, not a technology demonstration.
A6: Campaign | B6: Form | C6: Root | D6: Decisive interface | E6: Required advance | F6: Why existing class is insufficient | G6: Fatal prototype event | H6: Evidence | I6: State
A7: T001 | B7: ET-A-A | C7: ET-A | D7: moving-source receiver | E7: active six-axis transfer saddle | F7: ordinary offshore cranes do not preserve two custody-complete paths | G7: remove one saddle at rated transfer; surviving path retains metered custody | H7: 0 | I7: OPEN / UNPROVEN
A8: T002 | B8: ET-A-A | C8: ET-A | D8: wet-dry break | E8: self-forming amphibious shore bridge | F8: fixed ramps cannot follow changing beach and flood profiles | G8: erase one shore segment and cold-build replacement without stopping other path | H8: 0 | I8: OPEN / UNPROVEN
A9: T003 | B9: ET-A-A | C9: ET-A | D9: dry custody | E9: distributed tamper-evident flow metrology | F9: one custody station is a common failure under salt, motion and disconnection | G9: deny network and one meter chain; reconcile wet receipt to dry handoff locally | H9: 0 | I9: OPEN / UNPROVEN
A10: T013 | B10: CT-C-B | C10: CT-C | D10: suspended belt | E10: active-tension anchor zones with passive arrest | F10: façade access systems lack utility mass and fault containment | G10: release one anchor zone and arrest belt without progressive peel | H10: 0 | I10: OPEN / UNPROVEN
A11: T014 | B11: CT-C-B | C11: CT-C | D11: belt break | E11: automatic fluid, electrical and smoke guillotines | F11: existing disconnects do not coordinate all five trunks | G11: fault one trunk and prove no cross-trunk propagation | H11: 0 | I11: OPEN / UNPROVEN
A12: T015 | B12: CT-C-B | C12: CT-C | D12: occupied insertion | E12: contamination-aware climbing robotics | F12: construction robots assume clean evacuated work zones | G12: install through occupied denial zone without deleting egress or consent | H12: 0 | I12: OPEN / UNPROVEN
A13: T025 | B13: HC-A-C | C13: HC-A | D13: rotor cell | E13: cooperative heavy-lift rotors without decisive mesh | F13: swarms usually need central scheduling and positioning | G13: deny coordination network and retain local sector control | H13: 0 | I13: OPEN / UNPROVEN
A14: T026 | B14: HC-A-C | C14: HC-A | D14: refill | E14: hot-zone robotic battery-fluid exchange | F14: airport refill cycles break persistence and expose crews | G14: fault one refill lane and sustain sector from second local lane | H14: 0 | I14: OPEN / UNPROVEN
A15: T027 | B15: HC-A-C | C15: HC-A | D15: edge sensing | E15: self-calibrating particulate and heat tomography | F15: low-cost sensors drift in dense smoke and cannot support attribution | G15: inject correlated drift and force HOLD rather than false effect | H15: 0 | I15: OPEN / UNPROVEN
A16: T028 | B16: LF-B-A | C16: LF-B | D16: reservoir contact | E16: rapid multi-bore subsurface inference | F16: exploration is slow and centralizes uncertainty in one model | G16: blind one bore family and bound drawdown from independent local measurements | H16: 0 | I16: OPEN / UNPROVEN
A17: T029 | B17: LF-B-A | C17: LF-B | D17: radial headers | E17: loss-defined high-temperature fluid switching | F17: geothermal headers centralize separation and brine custody | G17: rupture one header and retain independent product and return paths | H17: 0 | I17: OPEN / UNPROVEN
A18: T030 | B18: LF-B-A | C18: LF-B | D18: mineral custody | E18: continuous brine-to-mineral closed metabolism | F18: commercial plants externalize variable brine chemistry | G18: change chemistry abruptly and reconcile retained, treated and released mass | H18: 0 | I18: OPEN / UNPROVEN
... A24: T054 | B24: RT-B-C | C24: RT-B | D24: cold rebuild | E24: self-describing machines and fixtures | F24: machine tools depend on vendor software, keys and tacit setup | G24: clean team rebuilds one trainlet with vendors and private keys denied | H24: 0 | I24: OPEN / UNPROVEN

Sheet Finance
A2: Cohort-one design finance
A4: The pass allocates no new money and makes no payment. Form ceilings reconcile to the inherited obligation.
A6: Form | B6: Form ceiling | C6: Method 20% | D6: Measure 25% | E6: Civil 15% | F6: Article 25% | G6: Rebuild 15% | H6: Current paid
A7: ET-A-A | B7: ='Baseline Register'!M7 -> 25.023731 | C7: =B7*20% -> 5.0047462 | D7: =B7*25% -> 6.2559327 | E7: =B7*15% -> 3.7535596 | F7: =B7*25% -> 6.2559327 | G7: =B7*15% -> 3.7535596 | H7: 0
A8: CT-C-B | B8: ='Baseline Register'!M8 -> 25.824674 | C8: =B8*20% -> 5.1649348 | D8: =B8*25% -> 6.4561685 | E8: =B8*15% -> 3.8737011 | F8: =B8*25% -> 6.4561685 | G8: =B8*15% -> 3.8737011 | H8: 0
A9: HC-A-C | B9: ='Baseline Register'!M9 -> 15.361083 | C9: =B9*20% -> 3.0722165 | D9: =B9*25% -> 3.8402707 | E9: =B9*15% -> 2.3041624 | F9: =B9*25% -> 3.8402707 | G9: =B9*15% -> 2.3041624 | H9: 0
A10: LF-B-A | B10: ='Baseline Register'!M10 -> 44.970641 | C10: =B10*20% -> 8.9941282 | D10: =B10*25% -> 11.24266 | E10: =B10*15% -> 6.7455961 | F10: =B10*25% -> 11.24266 | G10: =B10*15% -> 6.7455961 | H10: 0
A11: HU-A-B | B11: ='Baseline Register'!M11 -> 43.035623 | C11: =B11*20% -> 8.6071245 | D11: =B11*25% -> 10.758906 | E11: =B11*15% -> 6.4553434 | F11: =B11*25% -> 10.758906 | G11: =B11*15% -> 6.4553434 | H11: 0
A12: RT-B-C | B12: ='Baseline Register'!M12 -> 25.12989 | C12: =B12*20% -> 5.0259779 | D12: =B12*25% -> 6.2824724 | E12: =B12*15% -> 3.7694834 | F12: =B12*25% -> 6.2824724 | G12: =B12*15% -> 3.7694834 | H12: 0
A13: Total | B13: =SUM(B7:B12) -> 179.34564 | C13: =SUM(C7:C12) -> 35.869128 | D13: =SUM(D7:D12) -> 44.83641 | E13: =SUM(E7:E12) -> 26.901846 | F13: =SUM(F7:F12) -> 44.83641 | G13: =SUM(G7:G12) -> 26.901846 | H13: =SUM(H7:H12) -> 0
A16: Conservation controls | B16: Conservation controls | C16: Conservation controls | D16: Conservation controls | E16: Conservation controls | F16: Conservation controls | G16: Conservation controls | H16: Conservation controls
A18: Control | B18: Amount (USD M) | C18: Interpretation
A19: Cohort-one obligation | B19: =Inputs!B19 -> 179.34564 | C19: active design liability
A20: Protected sibling reserve | B20: =Inputs!B20 -> 358.69128 | C20: unavailable to cohort-one overruns
A21: FRAME ceiling | B21: =Inputs!B21 -> 538.03692 | C21: conserved across all forms
A22: Artifact-estate capital ceiling | B22: =Inputs!B22 -> 540 | C22: nested inside public-method reserve
A23: Artifact-estate operating ceiling | B23: =Inputs!B23 -> 41.254333 | C23: inside reconstruction and escrow
A24: Current payments | B24: 0 | C24: cash finality remains zero

Sheet Inputs
A2: Engineering baseline controls
A4: Blue values are inherited controls or explicit zero states. No cell contains a measured physical result.
A6: Constitution controls | B6: Constitution controls | C6: Constitution controls | D6: Constitution controls
A7: Roots | B7: 6 | C7: count | D7: FR-03
A8: Active forms | B8: 6 | C8: count | D8: Pass 227
A9: Accounts per form | B9: 9 | C9: count | D9: FR-03
A10: Load cases per form | B10: 4 | C10: count | D10: FR-03
A11: Active packages | B11: 30 | C11: count | D11: Pass 229
A12: Source records per form | B12: 12 | C12: count | D12: EDB-1
A13: Provenance records | B13: 72 | C13: count | D13: direct arithmetic
A14: Technology thrusts | B14: 18 | C14: count | D14: Pass 224 active forms
A15: Closure rules | B15: 24 | C15: count | D15: EDB-1
A16: Adverse screen | B16: 0.025 | C16: share | D16: Pass 218
A17: Closure threshold | B17: 1 | C17: ratio | D17: Pass 216
A18: Cold rebuild maximum | B18: 168 | C18: h | D18: Pass 219
... A24: Tolerance | B24: 1e-06 | C24: ratio | D24: model control
A27: Current implementation and authority | B27: Current implementation and authority | C27: Current implementation and authority | D27: Current implementation and authority
A29: Measured physical coefficients | B29: 0 | C29: count | D29: source empty
A30: Accepted engineering baselines | B30: 0 | C30: count | D30: held
A31: Valid artifacts | B31: 0 | C31: count | D31: held
A32: Paid claims | B32: 0 | C32: count | D32: held
A33: Accepted observations | B33: 0 | C33: count | D33: held
A34: Selected forms | B34: 0 | C34: count | D34: held
A35: MAKE warrants | B35: 0 | C35: count | D35: held
A36: REP-4 records | B36: 0 | C36: count | D36: held
A37: Capability credit | B37: 0 | C37: count | D37: held
A38: Production credit | B38: 0 | C38: count | D38: held
A39: Renderings authorized | B39: 0 | C39: count | D39: held

Sheet Mutations
A2: Controlled mutation register
A4: Each corruption is applied to the live workbook, detected by a named audit and restored before export.
A6: Mutation | B6: Target | C6: Baseline | D6: Mutated | E6: Expected audit | F6: Detected | G6: Restored
A7: M01 | B7: Inputs!B7 | C7: 6 | D7: 5 | E7: A01 | F7: YES | G7: YES
A8: M02 | B8: Inputs!B8 | C8: 6 | D8: 5 | E8: A02 | F8: YES | G8: YES
A9: M03 | B9: Inputs!B9 | C9: 9 | D9: 8 | E9: A03 | F9: YES | G9: YES
A10: M04 | B10: Inputs!B10 | C10: 4 | D10: 3 | E10: A04 | F10: YES | G10: YES
A11: M05 | B11: Inputs!B11 | C11: 30 | D11: 29 | E11: A05 | F11: YES | G11: YES
A12: M06 | B12: Inputs!B12 | C12: 12 | D12: 11 | E12: A06 | F12: YES | G12: YES
A13: M07 | B13: Inputs!B13 | C13: 72 | D13: 71 | E13: A07 | F13: YES | G13: YES
A14: M08 | B14: Inputs!B14 | C14: 18 | D14: 17 | E14: A08 | F14: YES | G14: YES
A15: M09 | B15: Inputs!B15 | C15: 24 | D15: 23 | E15: A09 | F15: YES | G15: YES
A16: M10 | B16: Inputs!B16 | C16: 0.025 | D16: 0.05 | E16: A10 | F16: YES | G16: YES
A17: M11 | B17: Inputs!B17 | C17: 1 | D17: 0.95 | E17: A11 | F17: YES | G17: YES
A18: M12 | B18: Inputs!B18 | C18: 168 | D18: 200 | E18: A12 | F18: YES | G18: YES
... A28: M22 | B28: Inputs!B39 | C28: 0 | D28: 1 | E28: A57 | F28: YES | G28: YES

Sheet Audit
A2: Terminal audit
A4: Audit is one-way. No engineering, finance or authority result depends on this sheet.
A6: Audit | B6: Test | C6: Observed | D6: Expected | E6: Status
A7: A01 | B7: Root control | C7: =Inputs!B7 -> 6 | D7: 6 | E7: =IF(ABS(C7-D7)<=Inputs!$B$24,"PASS","FAIL") -> PASS
A8: A02 | B8: Form control | C8: =Inputs!B8 -> 6 | D8: 6 | E8: =IF(ABS(C8-D8)<=Inputs!$B$24,"PASS","FAIL") -> PASS
A9: A03 | B9: Account control | C9: =Inputs!B9 -> 9 | D9: 9 | E9: =IF(ABS(C9-D9)<=Inputs!$B$24,"PASS","FAIL") -> PASS
A10: A04 | B10: World control | C10: =Inputs!B10 -> 4 | D10: 4 | E10: =IF(ABS(C10-D10)<=Inputs!$B$24,"PASS","FAIL") -> PASS
A11: A05 | B11: Package control | C11: =Inputs!B11 -> 30 | D11: 30 | E11: =IF(ABS(C11-D11)<=Inputs!$B$24,"PASS","FAIL") -> PASS
A12: A06 | B12: Source records per form | C12: =Inputs!B12 -> 12 | D12: 12 | E12: =IF(ABS(C12-D12)<=Inputs!$B$24,"PASS","FAIL") -> PASS
A13: A07 | B13: Provenance control | C13: =Inputs!B13 -> 72 | D13: 72 | E13: =IF(ABS(C13-D13)<=Inputs!$B$24,"PASS","FAIL") -> PASS
A14: A08 | B14: Technology control | C14: =Inputs!B14 -> 18 | D14: 18 | E14: =IF(ABS(C14-D14)<=Inputs!$B$24,"PASS","FAIL") -> PASS
A15: A09 | B15: Closure-rule control | C15: =Inputs!B15 -> 24 | D15: 24 | E15: =IF(ABS(C15-D15)<=Inputs!$B$24,"PASS","FAIL") -> PASS
A16: A10 | B16: Adverse screen | C16: =Inputs!B16 -> 0.025 | D16: 0.025 | E16: =IF(ABS(C16-D16)<=Inputs!$B$24,"PASS","FAIL") -> PASS
A17: A11 | B17: Closure threshold | C17: =Inputs!B17 -> 1 | D17: 1 | E17: =IF(ABS(C17-D17)<=Inputs!$B$24,"PASS","FAIL") -> PASS
A18: A12 | B18: Rebuild maximum | C18: =Inputs!B18 -> 168 | D18: 168 | E18: =IF(ABS(C18-D18)<=Inputs!$B$24,"PASS","FAIL") -> PASS
... A23: A17 | B23: Operating ceiling | C23: =Inputs!B23 -> 41.254333 | D23: 41.254333 | E23: =IF(ABS(C23-D23)<=Inputs!$B$24,"PASS","FAIL") -> PASS
A24: A18 | B24: Five candidate architectures | C24: =COUNTA('Decision Tests'!A7:A11) -> 5 | D24: 5 | E24: =IF(ABS(C24-D24)<=Inputs!$B$24,"PASS","FAIL") -> PASS
A25: A19 | B25: One selected architecture | C25: =COUNTIFS('Decision Tests'!N7:N11,"SELECT") -> 1 | D25: 1 | E25: =IF(ABS(C25-D25)<=Inputs!$B$24,"PASS","FAIL") -> PASS
A26: A20 | B26: Selected candidate passes ten gates | C26: =SUMIFS('Decision Tests'!M7:M11,'Decision Tests'!N7:N11,"SELECT") -> 10 | D26: 10 | E26: =IF(ABS(C26-D26)<=Inputs!$B$24,"PASS","FAIL") -> PASS
A27: A21 | B27: Six baseline records | C27: =COUNTA('Baseline Register'!A7:A12) -> 6 | D27: 6 | E27: =IF(ABS(C27-D27)<=Inputs!$B$24,"PASS","FAIL") -> PASS
A28: A22 | B28: All baseline states constituted | C28: =COUNTIFS('Baseline Register'!O7:O12,"CONSTITUTED / UNMEASURED") -> 6 | D28: 6 | E28: =IF(ABS(C28-D28)<=Inputs!$B$24,"PASS","FAIL") -> PASS
A29: A23 | B29: Twenty-four load cases | C29: =COUNTA('Load Cases'!A7:A30) -> 24 | D29: 24 | E29: =IF(ABS(C29-D29)<=Inputs!$B$24,"PASS","FAIL") -> PASS
A30: A24 | B30: Six nominal worlds | C30: =COUNTIFS('Load Cases'!C7:C30,"NOMINAL") -> 6 | D30: 6 | E30: =IF(ABS(C30-D30)<=Inputs!$B$24,"PASS","FAIL") -> PASS
A31: A25 | B31: Six loss worlds | C31: =COUNTIFS('Load Cases'!C7:C30,"LARGEST_CELL_LOSS") -> 6 | D31: 6 | E31: =IF(ABS(C31-D31)<=Inputs!$B$24,"PASS","FAIL") -> PASS
A32: A26 | B32: Six fatal worlds | C32: =COUNTIFS('Load Cases'!C7:C30,"FATAL_KEYSTONE") -> 6 | D32: 6 | E32: =IF(ABS(C32-D32)<=Inputs!$B$24,"PASS","FAIL") -> PASS
A33: A27 | B33: Six rebuild worlds | C33: =COUNTIFS('Load Cases'!C7:C30,"COLD_REBUILD") -> 6 | D33: 6 | E33: =IF(ABS(C33-D33)<=Inputs!$B$24,"PASS","FAIL") -> PASS
A34: A28 | B34: Load-case evidence zero | C34: =SUM('Load Cases'!H7:H30) -> 0 | D34: 0 | E34: =IF(ABS(C34-D34)<=Inputs!$B$24,"PASS","FAIL") -> PASS
A35: A29 | B35: Fifty-four account records | C35: =COUNTA('Account Grammar'!A7:A60) -> 54 | D35: 54 | E35: =IF(ABS(C35-D35)<=Inputs!$B$24,"PASS","FAIL") -> PASS
A36: A30 | B36: Six thermal coefficients open | C36: =COUNTIFS('Account Grammar'!G7:G60,"MISSING DESIGN COEFFICIENT") -> 6 | D36: 6 | E36: =IF(ABS(C36-D36)<=Inputs!$B$24,"PASS","FAIL") -> PASS
A37: A31 | B37: Account measurements zero | C37: =COUNTA('Account Grammar'!J7:J60) -> 0 | D37: 0 | E37: =IF(ABS(C37-D37)<=Inputs!$B$24,"PASS","FAIL") -> PASS
A38: A32 | B38: Seventy-two provenance records | C38: =COUNTA('Provenance Ledger'!A7:A78) -> 72 | D38: 72 | E38: =IF(ABS(C38-D38)<=Inputs!$B$24,"PASS","FAIL") -> PASS
A39: A33 | B39: Provenance measurements zero | C39: =SUM('Provenance Ledger'!J7:J78) -> 0 | D39: 0 | E39: =IF(ABS(C39-D39)<=Inputs!$B$24,"PASS","FAIL") -> PASS
A40: A34 | B40: Twelve source records ET | C40: =COUNTIFS('Provenance Ledger'!B7:B78,"ET-A-A") -> 12 | D40: 12 | E40: =IF(ABS(C40-D40)<=Inputs!$B$24,"PASS","FAIL") -> PASS
A41: A35 | B41: Twelve source records RT | C41: =COUNTIFS('Provenance Ledger'!B7:B78,"RT-B-C") -> 12 | D41: 12 | E41: =IF(ABS(C41-D41)<=Inputs!$B$24,"PASS","FAIL") -> PASS
A42: A36 | B42: Twenty-four closure rules | C42: =COUNTA('Closure Rules'!A7:A30) -> 24 | D42: 24 | E42: =IF(ABS(C42-D42)<=Inputs!$B$24,"PASS","FAIL") -> PASS
A43: A37 | B43: All closure rules constituted | C43: =COUNTIFS('Closure Rules'!G7:G30,"CONSTITUTED") -> 24 | D43: 24 | E43: =IF(ABS(C43-D43)<=Inputs!$B$24,"PASS","FAIL") -> PASS
A44: A38 | B44: Thirty package records | C44: =COUNTA('Package Crosswalk'!A7:A36) -> 30 | D44: 30 | E44: =IF(ABS(C44-D44)<=Inputs!$B$24,"PASS","FAIL") -> PASS
A45: A39 | B45: Package shares reconcile ET | C45: =SUMIFS('Package Crosswalk'!E7:E36,'Package Crosswalk'!B7:B36,"ET-A-A") -> 1 | D45: 1 | E45: =IF(ABS(C45-D45)<=Inputs!$B$24,"PASS","FAIL") -> PASS
A46: A40 | B46: Package ceilings reconcile | C46: =SUM('Package Crosswalk'!F7:F36) -> 179.34564 | D46: 179.34564 | E46: =IF(ABS(C46-D46)<=Inputs!$B$24,"PASS","FAIL") -> PASS
A47: A41 | B47: All packages assigned | C47: =COUNTIFS('Package Crosswalk'!Q7:Q36,"ASSIGNED / WORK OPEN") -> 30 | D47: 30 | E47: =IF(ABS(C47-D47)<=Inputs!$B$24,"PASS","FAIL") -> PASS
...

Sheet ReadMe
A2: Model notes and limits
A4: This workbook defines engineering baselines and their closure law. It does not report a completed design or physical result.
A6: Purpose | B6: Purpose | C6: Purpose | D6: Purpose | E6: Purpose | F6: Purpose | G6: Purpose | H6: Purpose | I6: Purpose | J6: Purpose | K6: Purpose | L6: Purpose | M6: Purpose | N6: Purpose
A8: EDB-1 replaces one generic platform model with six source-specific configuration baselines.
A9: The shared semantic kernel covers identity, units, boundaries, provenance, uncertainty, causal trace and civil obligation only.
A10: Each form carries four physical worlds, nine conjunctive accounts, twelve source records and five accountable work packages.
A11: The six thermal rows are intentionally open coefficients. Missing values order HOLD and do not become favorable zeros.
A12: Inherited values are repository design inputs. Measured fields remain blank and all accepted evidence remains zero.
A13: Eighteen technology advances are tied to fatal prototype events. None is a production program or readiness claim.
A14: EDB-1 closes the registered grammar question and opens numerical service, mass, energy, flow and thermal closure next.
A17: Current boundary | B17: Current boundary | C17: Current boundary | D17: Current boundary | E17: Current boundary | F17: Current boundary | G17: Current boundary | H17: Current boundary | I17: Current boundary | J17: Current boundary | K17: Current boundary | L17: Current boundary | M17: Current boundary | N17: Current boundary
A19: Six baseline objects are constituted but unmeasured and unaccepted.
A20: Twenty-four load cases are specified and contain no observations or evidence credit.
A21: Fifty-four account rules exist; six thermal coefficients remain explicitly open.
A22: Thirty packages remain funded design work. No artifact-validity or payment state advances.
A23: The USD179M cohort obligation and USD359M later-sibling reserve remain conserved.
A24: No evidence, selection, MAKE, REP-4, capability, production or rendering authority is created.
A25: The inherited minimum W03 margins are design arithmetic, not reliability or safety estimates.
A28: Sources and precision | B28: Sources and precision | C28: Sources and precision | D28: Sources and precision | E28: Sources and precision | F28: Sources and precision | G28: Sources and precision | H28: Sources and precision | I28: Sources and precision | J28: Sources and precision | K28: Sources and precision | L28: Sources and precision | M28: Sources and precision | N28: Sources and precision
A30: Repository sources: Passes 216, 219, 224, 225, 229, 232, 233 and 235. No external sources were used.
A31: Source artifact filenames, allowed uses and expiry triggers are carried in the Provenance Ledger.
A32: Financial figures preserve predecessor workbook arithmetic. Reader-facing prose rounds to three significant figures.
A33: Intervals remain intervals. The workbook never inserts a midpoint as a measured or preferred design value.
A34: Observed and measured cells are deliberately blank or zero until a separately authorized physical program exists.
A35: Vehicle and facility renderings remain deferred.
