Workbook

Sheet Summary
A2: A2C-2 Sovereign Truth Trains
A4: Verdict: CLOSE. Standardize eight nondecisive public boundaries; keep six physical truth systems sovereign across eighteen role-separated nuclei. No site, firm, serial, event, payment, capability or exterior form exists.
A6: Decision | B6: Result | C6: Unit | D6: State | E6: Why it matters | F6: Current authority | G6: Held conversion | H6: Next object
A7: selected architecture | B7: thin substrate + sovereign truth trains | C7: architecture | D7: CLOSE | E7: prevents common technical root | F7: functional configuration | G7: configuration to facility | H7: competition lots
A8: systems | B8: 6 | C8: count | D8: FROZEN | E8: one truth train per sentinel | F8: six families | G8: family to supplier | H8: industrial firewall
A9: station nuclei | B9: 18 | C9: count | D9: FROZEN | E9: challenge, control and reconstruction separated | F9: functional roles | G9: nucleus to site | H9: site warrants
A10: initial lanes | B10: 36 | C10: count | D10: FROZEN | E10: one active and one regeneration lane per station | F10: functional lanes | G10: lane to serial | H10: build packets
A11: state bays | B11: 72 | C11: count | D11: FROZEN | E11: four public worlds per active lane | F11: receiver worlds | G11: bay to constructed cell | H11: construction acceptance
A12: method realizations | B12: 144 | C12: count | D12: HELD | E12: two unlike lineages per bay | F12: allocation only | G12: allocation to acceptance | H12: lineage admission
A13: regeneration functions | B13: 72 | C13: count | D13: FROZEN | E13: four recovery duties per station | F13: functional duties | G13: duty to tool identity | H13: tool ancestry
A14: public reserve | B14: 12 | C14: USD B | D14: RESERVED | E14: USD 0.667B per nucleus | F14: ceiling only | G14: reserve to obligation | H14: lot competition
A15: private options | B15: 3.5869128 | C15: USD B | D15: GATED | E15: root-specific construction options | F15: ceiling only | G15: option to award | H15: artifact gates
A16: combined wave | B16: 15.586913 | C16: USD B | D16: CONSTITUTED | E16: no new money | F16: ceiling only | G16: authority to spend | H16: construction acceptance
A17: current obligations | B17: 0 | C17: USD B | D17: HELD | E17: no competition awarded | F17: none | G17: schedule to spend | H17: award warrant
A18: valid observations | B18: 0 | C18: count | D18: SOURCE EMPTY | E18: no physical event has run | F18: none | G18: plan to evidence | H18: event warrant
A19: capability credit | B19: 0 | C19: count | D19: HELD | E19: A2 cannot create production | F19: none | G19: configuration to readiness | H19: complete-root proof
A20: rendering authority | B20: 0 | C20: count | D20: HELD | E20: exterior follows stabilized requirements | F20: none | G20: envelope to form | H20: post-requirement rendering
A24: Terminal test | B24: Observed | C24: State | E24: Next competition object | F24: State | G24: Present identity | H24: Authority
A25: eligible architecture | B25: =COUNTIF(Alternatives!P7:P11,"SELECT") -> 1 | C25: =IF(B25=1,"PASS","FAIL") -> PASS | E25: civil substrate lots | F25: TO CONSTITUTE | G25: SOURCE EMPTY | H25: 0
A26: station nuclei | B26: =COUNTA('Station Nuclei'!A7:A24) -> 18 | C26: =IF(B26=18,"PASS","FAIL") -> PASS | E26: six truth-train lots | F26: TO CONSTITUTE | G26: SOURCE EMPTY | H26: 0
A27: state bays | B27: =COUNTA('State Bays'!A7:A78) -> 72 | C27: =IF(B27=72,"PASS","FAIL") -> PASS | E27: eighteen station integration lots | F27: TO CONSTITUTE | G27: SOURCE EMPTY | H27: 0
A28: method realizations | B28: =COUNTA('Method Realizations'!A7:A150) -> 144 | C28: =IF(B28=144,"PASS","FAIL") -> PASS | E28: method-lineage lots | F28: TO CONSTITUTE | G28: SOURCE EMPTY | H28: 0
A29: public reserve | B29: =Finance!B15 -> 12 | C29: =IF(B29=12,"PASS","FAIL") -> PASS | E29: regeneration-tool lots | F29: TO CONSTITUTE | G29: SOURCE EMPTY | H29: 0
A30: combined ceiling | B30: =Finance!E26 -> 15.586913 | C30: =IF(ABS(B30-15.5869128193206)<0.000001,"PASS","FAIL") -> PASS | E30: construction acceptance packets | F30: TO CONSTITUTE | G30: SOURCE EMPTY | H30: 0
A31: audit failures | B31: =COUNTIF(Audit!E7:E67,"FAIL") -> 0 | C31: =IF(B31=0,"PASS","FAIL") -> PASS
A32: rendering authority | B32: =Controls!B23 -> 0 | C32: =IF(B32=0,"PASS","FAIL") -> PASS

Sheet Controls
A2: Authoritative A2C-2 controls
A4: Blue cells are the only mutable controls used by the audit. They are design ceilings and zero-state guards, not evidence or awards.
A6: Control | B6: Value | C6: Unit | D6: Authority | E6: Meaning
A7: public-method reserve | B7: 12 | C7: USD B | D7: A2C-1 | E7: nested in enabling authority
A8: selected private options | B8: 3.5869128 | C8: USD B | D8: A2C-1 | E8: six root-specific option ceilings
A9: mission systems | B9: 6 | C9: count | D9: A2C-1 | E9: all six remain live
A10: station roles/system | B10: 3 | C10: count | D10: A2C-1 | E10: challenge, control, reconstruction
A11: receiver states/system | B11: 4 | C11: count | D11: PFP-4 | E11: route-complete public states
A12: lineages/method card | B12: 2 | C12: count | D12: PFP-4 | E12: physically unlike
A13: active lanes/station | B13: 1 | C13: count | D13: A2C-1 | E13: sentinel lane only
A14: regeneration lanes/station | B14: 1 | C14: count | D14: A2C-2 | E14: non-credit recovery
A15: held expansion lanes | B15: 54 | C15: count | D15: A2C-1 | E15: not built
A16: current sites | B16: 0 | C16: count | D16: A2C-2 | E16: source empty
A17: current firms | B17: 0 | C17: count | D17: A2C-2 | E17: source empty
A18: current serials | B18: 0 | C18: count | D18: A2C-2 | E18: source empty
... A23: rendering authority | B23: 0 | C23: count | D23: A2C-2 | E23: exterior form held

Sheet Alternatives
A2: Physical proving architecture hard-gate test
A4: All twelve gates are conjunctive. Physical independence cannot be recovered by a weighted score.
A6: Architecture | B6: role separation | C6: plural physical methods | D6: no common decisive utility | E6: full causal interface | F6: receiver states | G6: regeneration | H6: portable evidence | I6: source-empty identity | J6: bounded authority | K6: expansion path | L6: public safe stop only | M6: no production inference | N6: Passes | O6: Eligible | P6: Decision
A7: Thin substrate + sovereign truth trains | B7: 1 | C7: 1 | D7: 1 | E7: 1 | F7: 1 | G7: 1 | H7: 1 | I7: 1 | J7: 1 | K7: 1 | L7: 1 | M7: 1 | N7: =SUM(B7:M7) -> 12 | O7: =IF(N7=12,"YES","NO") -> YES | P7: =IF(O7="YES","SELECT","REJECT") -> SELECT
A8: Universal national station shell | B8: 1 | C8: 0 | D8: 0 | E8: 1 | F8: 1 | G8: 1 | H8: 1 | I8: 1 | J8: 1 | K8: 1 | L8: 0 | M8: 1 | N8: =SUM(B8:M8) -> 9 | O8: =IF(N8=12,"YES","NO") -> NO | P8: =IF(O8="YES","SELECT","REJECT") -> REJECT
A9: Six integrated system campuses | B9: 0 | C9: 1 | D9: 0 | E9: 1 | F9: 1 | G9: 1 | H9: 1 | I9: 1 | J9: 1 | K9: 1 | L9: 0 | M9: 1 | N9: =SUM(B9:M9) -> 9 | O9: =IF(N9=12,"YES","NO") -> NO | P9: =IF(O9="YES","SELECT","REJECT") -> REJECT
A10: Eighteen unrelated monoliths | B10: 1 | C10: 1 | D10: 1 | E10: 1 | F10: 1 | G10: 1 | H10: 0 | I10: 1 | J10: 0 | K10: 0 | L10: 1 | M10: 1 | N10: =SUM(B10:M10) -> 9 | O10: =IF(N10=12,"YES","NO") -> NO | P10: =IF(O10="YES","SELECT","REJECT") -> REJECT
A11: Simulation-first digital range | B11: 1 | C11: 0 | D11: 1 | E11: 0 | F11: 1 | G11: 0 | H11: 1 | I11: 1 | J11: 1 | K11: 1 | L11: 1 | M11: 0 | N11: =SUM(B11:M11) -> 8 | O11: =IF(N11=12,"YES","NO") -> NO | P11: =IF(O11="YES","SELECT","REJECT") -> REJECT

Sheet Substrate Law
A2: Thin public substrate: eight nondecisive boundaries
A4: If a common element can improve, measure, control or safe the candidate, it crosses the substrate boundary and must split.
A6: ID | B6: Public boundary | C6: Common physical content | D6: May do | E6: May not do | F6: Failure consequence | G6: Common allowed | H6: State
A7: SUB-01 | B7: surveyed datum field | C7: geodetic marks and externally witnessed reference | D7: locate articles and observations | E7: estimate candidate state | F7: invalidate location chain | G7: 1 | H7: FROZEN
A8: SUB-02 | B8: reversible hardpoints | C8: civil anchors with declared envelopes | D8: protect neighboring property | E8: carry candidate force without native measurement | F8: halt or invalidate event | G8: 1 | H8: FROZEN
A9: SUB-03 | B9: raw-service entries | C9: upstream water, power and data portals with double isolation | D9: offer an unconditioned input boundary | E9: condition, control or safe candidate service | F9: isolate and halt event | G9: 1 | H9: FROZEN
A10: SUB-04 | B10: refuge and rescue ingress | C10: protected human shelter and independent rescue route | D10: protect people and remove them | E10: complete candidate safeing | F10: halt event | G10: 1 | H10: FROZEN
A11: SUB-05 | B11: custody portals | C11: material, sample and native-data transfer boundary | D11: receive sealed custody objects | E11: interpret or transform decisive evidence | F11: hold evidence | G11: 1 | H11: FROZEN
A12: SUB-06 | B12: environmental containment | C12: property-edge capture and monitoring | D12: prevent offsite harm | E12: improve candidate residual score | F12: abort and invalidate | G12: 1 | H12: FROZEN
A13: SUB-07 | B13: residual quarantine | C13: isolated post-event holding boundary | D13: contain rejected material | E13: treat candidate residuals for credit | F13: hold return | G13: 1 | H13: FROZEN
A14: SUB-08 | B14: emergency energy removal | C14: independent public energy isolation | D14: stop escalating public harm | E14: place candidate in claimed safe state | F14: invalidate outcome | G14: 1 | H14: FROZEN

Sheet Station Nuclei
A2: Eighteen separated station nuclei
A4: Role separation is physical. Site and operator identities remain source empty.
A6: Station | B6: System | C6: Root | D6: Role | E6: Owned inquiry | F6: Physical duty | G6: Site | H6: Operator | I6: Active lanes | J6: Regen lanes | K6: State bays | L6: Realizations | M6: Public reserve USD B | N6: State
A7: ST-ET-CHA | B7: MS-ET | C7: ET-A | D7: CHALLENGE | E7: DENIED CONDITION | F7: inject governing loss without supplying candidate control | G7: SOURCE EMPTY | H7: SOURCE EMPTY | I7: =Controls!B13 -> 1 | J7: =Controls!B14 -> 1 | K7: =Controls!B11 -> 4 | L7: =K7*Controls!B12 -> 8 | M7: =Controls!B7/(Controls!B9*Controls!B10) -> 0.66666667 | N7: WARRANT-CONSTITUTED
A8: ST-ET-CON | B8: MS-ET | C8: ET-A | D8: CONTROL | E8: LOAD AND QUALITY | F8: measure useful load and background burden in a matched independent world | G8: SOURCE EMPTY | H8: SOURCE EMPTY | I8: =Controls!B13 -> 1 | J8: =Controls!B14 -> 1 | K8: =Controls!B11 -> 4 | L8: =K8*Controls!B12 -> 8 | M8: =Controls!B7/(Controls!B9*Controls!B10) -> 0.66666667 | N8: WARRANT-CONSTITUTED
A9: ST-ET-REC | B9: MS-ET | C9: ET-A | D9: RECONSTRUCTION | E9: RECOVERY AND BURDEN | F9: cold-build, recalibrate and replay from frozen public records | G9: SOURCE EMPTY | H9: SOURCE EMPTY | I9: =Controls!B13 -> 1 | J9: =Controls!B14 -> 1 | K9: =Controls!B11 -> 4 | L9: =K9*Controls!B12 -> 8 | M9: =Controls!B7/(Controls!B9*Controls!B10) -> 0.66666667 | N9: WARRANT-CONSTITUTED
A10: ST-CT-CHA | B10: MS-CT | C10: CT-C | D10: CHALLENGE | E10: DENIED CONDITION | F10: inject governing loss without supplying candidate control | G10: SOURCE EMPTY | H10: SOURCE EMPTY | I10: =Controls!B13 -> 1 | J10: =Controls!B14 -> 1 | K10: =Controls!B11 -> 4 | L10: =K10*Controls!B12 -> 8 | M10: =Controls!B7/(Controls!B9*Controls!B10) -> 0.66666667 | N10: WARRANT-CONSTITUTED
A11: ST-CT-CON | B11: MS-CT | C11: CT-C | D11: CONTROL | E11: LOAD AND QUALITY | F11: measure useful load and background burden in a matched independent world | G11: SOURCE EMPTY | H11: SOURCE EMPTY | I11: =Controls!B13 -> 1 | J11: =Controls!B14 -> 1 | K11: =Controls!B11 -> 4 | L11: =K11*Controls!B12 -> 8 | M11: =Controls!B7/(Controls!B9*Controls!B10) -> 0.66666667 | N11: WARRANT-CONSTITUTED
A12: ST-CT-REC | B12: MS-CT | C12: CT-C | D12: RECONSTRUCTION | E12: RECOVERY AND BURDEN | F12: cold-build, recalibrate and replay from frozen public records | G12: SOURCE EMPTY | H12: SOURCE EMPTY | I12: =Controls!B13 -> 1 | J12: =Controls!B14 -> 1 | K12: =Controls!B11 -> 4 | L12: =K12*Controls!B12 -> 8 | M12: =Controls!B7/(Controls!B9*Controls!B10) -> 0.66666667 | N12: WARRANT-CONSTITUTED
A13: ST-HC-CHA | B13: MS-HC | C13: HC-A | D13: CHALLENGE | E13: DENIED CONDITION | F13: inject governing loss without supplying candidate control | G13: SOURCE EMPTY | H13: SOURCE EMPTY | I13: =Controls!B13 -> 1 | J13: =Controls!B14 -> 1 | K13: =Controls!B11 -> 4 | L13: =K13*Controls!B12 -> 8 | M13: =Controls!B7/(Controls!B9*Controls!B10) -> 0.66666667 | N13: WARRANT-CONSTITUTED
A14: ST-HC-CON | B14: MS-HC | C14: HC-A | D14: CONTROL | E14: LOAD AND QUALITY | F14: measure useful load and background burden in a matched independent world | G14: SOURCE EMPTY | H14: SOURCE EMPTY | I14: =Controls!B13 -> 1 | J14: =Controls!B14 -> 1 | K14: =Controls!B11 -> 4 | L14: =K14*Controls!B12 -> 8 | M14: =Controls!B7/(Controls!B9*Controls!B10) -> 0.66666667 | N14: WARRANT-CONSTITUTED
A15: ST-HC-REC | B15: MS-HC | C15: HC-A | D15: RECONSTRUCTION | E15: RECOVERY AND BURDEN | F15: cold-build, recalibrate and replay from frozen public records | G15: SOURCE EMPTY | H15: SOURCE EMPTY | I15: =Controls!B13 -> 1 | J15: =Controls!B14 -> 1 | K15: =Controls!B11 -> 4 | L15: =K15*Controls!B12 -> 8 | M15: =Controls!B7/(Controls!B9*Controls!B10) -> 0.66666667 | N15: WARRANT-CONSTITUTED
A16: ST-LF-CHA | B16: MS-LF | C16: LF-B | D16: CHALLENGE | E16: DENIED CONDITION | F16: inject governing loss without supplying candidate control | G16: SOURCE EMPTY | H16: SOURCE EMPTY | I16: =Controls!B13 -> 1 | J16: =Controls!B14 -> 1 | K16: =Controls!B11 -> 4 | L16: =K16*Controls!B12 -> 8 | M16: =Controls!B7/(Controls!B9*Controls!B10) -> 0.66666667 | N16: WARRANT-CONSTITUTED
A17: ST-LF-CON | B17: MS-LF | C17: LF-B | D17: CONTROL | E17: LOAD AND QUALITY | F17: measure useful load and background burden in a matched independent world | G17: SOURCE EMPTY | H17: SOURCE EMPTY | I17: =Controls!B13 -> 1 | J17: =Controls!B14 -> 1 | K17: =Controls!B11 -> 4 | L17: =K17*Controls!B12 -> 8 | M17: =Controls!B7/(Controls!B9*Controls!B10) -> 0.66666667 | N17: WARRANT-CONSTITUTED
A18: ST-LF-REC | B18: MS-LF | C18: LF-B | D18: RECONSTRUCTION | E18: RECOVERY AND BURDEN | F18: cold-build, recalibrate and replay from frozen public records | G18: SOURCE EMPTY | H18: SOURCE EMPTY | I18: =Controls!B13 -> 1 | J18: =Controls!B14 -> 1 | K18: =Controls!B11 -> 4 | L18: =K18*Controls!B12 -> 8 | M18: =Controls!B7/(Controls!B9*Controls!B10) -> 0.66666667 | N18: WARRANT-CONSTITUTED
A19: ST-HU-CHA | B19: MS-HU | C19: HU-A | D19: CHALLENGE | E19: DENIED CONDITION | F19: inject governing loss without supplying candidate control | G19: SOURCE EMPTY | H19: SOURCE EMPTY | I19: =Controls!B13 -> 1 | J19: =Controls!B14 -> 1 | K19: =Controls!B11 -> 4 | L19: =K19*Controls!B12 -> 8 | M19: =Controls!B7/(Controls!B9*Controls!B10) -> 0.66666667 | N19: WARRANT-CONSTITUTED
A20: ST-HU-CON | B20: MS-HU | C20: HU-A | D20: CONTROL | E20: LOAD AND QUALITY | F20: measure useful load and background burden in a matched independent world | G20: SOURCE EMPTY | H20: SOURCE EMPTY | I20: =Controls!B13 -> 1 | J20: =Controls!B14 -> 1 | K20: =Controls!B11 -> 4 | L20: =K20*Controls!B12 -> 8 | M20: =Controls!B7/(Controls!B9*Controls!B10) -> 0.66666667 | N20: WARRANT-CONSTITUTED
A21: ST-HU-REC | B21: MS-HU | C21: HU-A | D21: RECONSTRUCTION | E21: RECOVERY AND BURDEN | F21: cold-build, recalibrate and replay from frozen public records | G21: SOURCE EMPTY | H21: SOURCE EMPTY | I21: =Controls!B13 -> 1 | J21: =Controls!B14 -> 1 | K21: =Controls!B11 -> 4 | L21: =K21*Controls!B12 -> 8 | M21: =Controls!B7/(Controls!B9*Controls!B10) -> 0.66666667 | N21: WARRANT-CONSTITUTED
A22: ST-RT-CHA | B22: MS-RT | C22: RT-B | D22: CHALLENGE | E22: DENIED CONDITION | F22: inject governing loss without supplying candidate control | G22: SOURCE EMPTY | H22: SOURCE EMPTY | I22: =Controls!B13 -> 1 | J22: =Controls!B14 -> 1 | K22: =Controls!B11 -> 4 | L22: =K22*Controls!B12 -> 8 | M22: =Controls!B7/(Controls!B9*Controls!B10) -> 0.66666667 | N22: WARRANT-CONSTITUTED
A23: ST-RT-CON | B23: MS-RT | C23: RT-B | D23: CONTROL | E23: LOAD AND QUALITY | F23: measure useful load and background burden in a matched independent world | G23: SOURCE EMPTY | H23: SOURCE EMPTY | I23: =Controls!B13 -> 1 | J23: =Controls!B14 -> 1 | K23: =Controls!B11 -> 4 | L23: =K23*Controls!B12 -> 8 | M23: =Controls!B7/(Controls!B9*Controls!B10) -> 0.66666667 | N23: WARRANT-CONSTITUTED
A24: ST-RT-REC | B24: MS-RT | C24: RT-B | D24: RECONSTRUCTION | E24: RECOVERY AND BURDEN | F24: cold-build, recalibrate and replay from frozen public records | G24: SOURCE EMPTY | H24: SOURCE EMPTY | I24: =Controls!B13 -> 1 | J24: =Controls!B14 -> 1 | K24: =Controls!B11 -> 4 | L24: =K24*Controls!B12 -> 8 | M24: =Controls!B7/(Controls!B9*Controls!B10) -> 0.66666667 | N24: WARRANT-CONSTITUTED

Sheet State Bays
A2: Seventy-two receiver-state bays
A4: Four receiver worlds per station prevent a machine-boundary pass from substituting for public handoff.
A6: Bay | B6: Station | C6: System | D6: Root | E6: Role | F6: Receiver state | G6: Physical world | H6: Inquiry | I6: Lineages | J6: Realization identities | K6: State
A7: BAY-ET-CHA-1 | B7: ST-ET-CHA | C7: MS-ET | D7: ET-A | E7: CHALLENGE | F7: ET-RS1 | G7: Moving interface | H7: DENIED CONDITION | I7: =Controls!B12 -> 2 | J7: SOURCE EMPTY | K7: HELD
A8: BAY-ET-CHA-2 | B8: ST-ET-CHA | C8: MS-ET | D8: ET-A | E8: CHALLENGE | F8: ET-RS2 | G8: Shore transition | H8: DENIED CONDITION | I8: =Controls!B12 -> 2 | J8: SOURCE EMPTY | K8: HELD
A9: BAY-ET-CHA-3 | B9: ST-ET-CHA | C9: MS-ET | D9: ET-A | E9: CHALLENGE | F9: ET-RS3 | G9: Dry staging | H9: DENIED CONDITION | I9: =Controls!B12 -> 2 | J9: SOURCE EMPTY | K9: HELD
A10: BAY-ET-CHA-4 | B10: ST-ET-CHA | C10: MS-ET | D10: ET-A | E10: CHALLENGE | F10: ET-RS4 | G10: Onward handoff | H10: DENIED CONDITION | I10: =Controls!B12 -> 2 | J10: SOURCE EMPTY | K10: HELD
A11: BAY-ET-CON-1 | B11: ST-ET-CON | C11: MS-ET | D11: ET-A | E11: CONTROL | F11: ET-RS1 | G11: Moving interface | H11: LOAD AND QUALITY | I11: =Controls!B12 -> 2 | J11: SOURCE EMPTY | K11: HELD
A12: BAY-ET-CON-2 | B12: ST-ET-CON | C12: MS-ET | D12: ET-A | E12: CONTROL | F12: ET-RS2 | G12: Shore transition | H12: LOAD AND QUALITY | I12: =Controls!B12 -> 2 | J12: SOURCE EMPTY | K12: HELD
A13: BAY-ET-CON-3 | B13: ST-ET-CON | C13: MS-ET | D13: ET-A | E13: CONTROL | F13: ET-RS3 | G13: Dry staging | H13: LOAD AND QUALITY | I13: =Controls!B12 -> 2 | J13: SOURCE EMPTY | K13: HELD
A14: BAY-ET-CON-4 | B14: ST-ET-CON | C14: MS-ET | D14: ET-A | E14: CONTROL | F14: ET-RS4 | G14: Onward handoff | H14: LOAD AND QUALITY | I14: =Controls!B12 -> 2 | J14: SOURCE EMPTY | K14: HELD
A15: BAY-ET-REC-1 | B15: ST-ET-REC | C15: MS-ET | D15: ET-A | E15: RECONSTRUCTION | F15: ET-RS1 | G15: Moving interface | H15: RECOVERY AND BURDEN | I15: =Controls!B12 -> 2 | J15: SOURCE EMPTY | K15: HELD
A16: BAY-ET-REC-2 | B16: ST-ET-REC | C16: MS-ET | D16: ET-A | E16: RECONSTRUCTION | F16: ET-RS2 | G16: Shore transition | H16: RECOVERY AND BURDEN | I16: =Controls!B12 -> 2 | J16: SOURCE EMPTY | K16: HELD
A17: BAY-ET-REC-3 | B17: ST-ET-REC | C17: MS-ET | D17: ET-A | E17: RECONSTRUCTION | F17: ET-RS3 | G17: Dry staging | H17: RECOVERY AND BURDEN | I17: =Controls!B12 -> 2 | J17: SOURCE EMPTY | K17: HELD
A18: BAY-ET-REC-4 | B18: ST-ET-REC | C18: MS-ET | D18: ET-A | E18: RECONSTRUCTION | F18: ET-RS4 | G18: Onward handoff | H18: RECOVERY AND BURDEN | I18: =Controls!B12 -> 2 | J18: SOURCE EMPTY | K18: HELD
A19: BAY-CT-CHA-1 | B19: ST-CT-CHA | C19: MS-CT | D19: CT-C | E19: CHALLENGE | F19: CT-RS1 | G19: District approach | H19: DENIED CONDITION | I19: =Controls!B12 -> 2 | J19: SOURCE EMPTY | K19: HELD
A20: BAY-CT-CHA-2 | B20: ST-CT-CHA | C20: MS-CT | D20: CT-C | E20: CHALLENGE | F20: CT-RS2 | G20: Occupied low-rise | H20: DENIED CONDITION | I20: =Controls!B12 -> 2 | J20: SOURCE EMPTY | K20: HELD
A21: BAY-CT-CHA-3 | B21: ST-CT-CHA | C21: MS-CT | D21: CT-C | E21: CHALLENGE | F21: CT-RS3 | G21: High-rise vertical | H21: DENIED CONDITION | I21: =Controls!B12 -> 2 | J21: SOURCE EMPTY | K21: HELD
A22: BAY-CT-CHA-4 | B22: ST-CT-CHA | C22: MS-CT | D22: CT-C | E22: CHALLENGE | F22: CT-RS4 | G22: Refuge and egress | H22: DENIED CONDITION | I22: =Controls!B12 -> 2 | J22: SOURCE EMPTY | K22: HELD
A23: BAY-CT-CON-1 | B23: ST-CT-CON | C23: MS-CT | D23: CT-C | E23: CONTROL | F23: CT-RS1 | G23: District approach | H23: LOAD AND QUALITY | I23: =Controls!B12 -> 2 | J23: SOURCE EMPTY | K23: HELD
A24: BAY-CT-CON-2 | B24: ST-CT-CON | C24: MS-CT | D24: CT-C | E24: CONTROL | F24: CT-RS2 | G24: Occupied low-rise | H24: LOAD AND QUALITY | I24: =Controls!B12 -> 2 | J24: SOURCE EMPTY | K24: HELD
A25: BAY-CT-CON-3 | B25: ST-CT-CON | C25: MS-CT | D25: CT-C | E25: CONTROL | F25: CT-RS3 | G25: High-rise vertical | H25: LOAD AND QUALITY | I25: =Controls!B12 -> 2 | J25: SOURCE EMPTY | K25: HELD
A26: BAY-CT-CON-4 | B26: ST-CT-CON | C26: MS-CT | D26: CT-C | E26: CONTROL | F26: CT-RS4 | G26: Refuge and egress | H26: LOAD AND QUALITY | I26: =Controls!B12 -> 2 | J26: SOURCE EMPTY | K26: HELD
A27: BAY-CT-REC-1 | B27: ST-CT-REC | C27: MS-CT | D27: CT-C | E27: RECONSTRUCTION | F27: CT-RS1 | G27: District approach | H27: RECOVERY AND BURDEN | I27: =Controls!B12 -> 2 | J27: SOURCE EMPTY | K27: HELD
A28: BAY-CT-REC-2 | B28: ST-CT-REC | C28: MS-CT | D28: CT-C | E28: RECONSTRUCTION | F28: CT-RS2 | G28: Occupied low-rise | H28: RECOVERY AND BURDEN | I28: =Controls!B12 -> 2 | J28: SOURCE EMPTY | K28: HELD
A29: BAY-CT-REC-3 | B29: ST-CT-REC | C29: MS-CT | D29: CT-C | E29: RECONSTRUCTION | F29: CT-RS3 | G29: High-rise vertical | H29: RECOVERY AND BURDEN | I29: =Controls!B12 -> 2 | J29: SOURCE EMPTY | K29: HELD
A30: BAY-CT-REC-4 | B30: ST-CT-REC | C30: MS-CT | D30: CT-C | E30: RECONSTRUCTION | F30: CT-RS4 | G30: Refuge and egress | H30: RECOVERY AND BURDEN | I30: =Controls!B12 -> 2 | J30: SOURCE EMPTY | K30: HELD
A31: BAY-HC-CHA-1 | B31: ST-HC-CHA | C31: MS-HC | D31: HC-A | E31: CHALLENGE | F31: HC-RS1 | G31: Advancing edge | H31: DENIED CONDITION | I31: =Controls!B12 -> 2 | J31: SOURCE EMPTY | K31: HELD
A32: BAY-HC-CHA-2 | B32: ST-HC-CHA | C32: MS-HC | D32: HC-A | E32: CHALLENGE | F32: HC-RS2 | G32: Ember and interface | H32: DENIED CONDITION | I32: =Controls!B12 -> 2 | J32: SOURCE EMPTY | K32: HELD
A33: BAY-HC-CHA-3 | B33: ST-HC-CHA | C33: MS-HC | D33: HC-A | E33: CHALLENGE | F33: HC-RS3 | G33: Plume and airspace | H33: DENIED CONDITION | I33: =Controls!B12 -> 2 | J33: SOURCE EMPTY | K33: HELD
A34: BAY-HC-CHA-4 | B34: ST-HC-CHA | C34: MS-HC | D34: HC-A | E34: CHALLENGE | F34: HC-RS4 | G34: Residual and re-ignition | H34: DENIED CONDITION | I34: =Controls!B12 -> 2 | J34: SOURCE EMPTY | K34: HELD
A35: BAY-HC-CON-1 | B35: ST-HC-CON | C35: MS-HC | D35: HC-A | E35: CONTROL | F35: HC-RS1 | G35: Advancing edge | H35: LOAD AND QUALITY | I35: =Controls!B12 -> 2 | J35: SOURCE EMPTY | K35: HELD
A36: BAY-HC-CON-2 | B36: ST-HC-CON | C36: MS-HC | D36: HC-A | E36: CONTROL | F36: HC-RS2 | G36: Ember and interface | H36: LOAD AND QUALITY | I36: =Controls!B12 -> 2 | J36: SOURCE EMPTY | K36: HELD
A37: BAY-HC-CON-3 | B37: ST-HC-CON | C37: MS-HC | D37: HC-A | E37: CONTROL | F37: HC-RS3 | G37: Plume and airspace | H37: LOAD AND QUALITY | I37: =Controls!B12 -> 2 | J37: SOURCE EMPTY | K37: HELD
A38: BAY-HC-CON-4 | B38: ST-HC-CON | C38: MS-HC | D38: HC-A | E38: CONTROL | F38: HC-RS4 | G38: Residual and re-ignition | H38: LOAD AND QUALITY | I38: =Controls!B12 -> 2 | J38: SOURCE EMPTY | K38: HELD
A39: BAY-HC-REC-1 | B39: ST-HC-REC | C39: MS-HC | D39: HC-A | E39: RECONSTRUCTION | F39: HC-RS1 | G39: Advancing edge | H39: RECOVERY AND BURDEN | I39: =Controls!B12 -> 2 | J39: SOURCE EMPTY | K39: HELD
A40: BAY-HC-REC-2 | B40: ST-HC-REC | C40: MS-HC | D40: HC-A | E40: RECONSTRUCTION | F40: HC-RS2 | G40: Ember and interface | H40: RECOVERY AND BURDEN | I40: =Controls!B12 -> 2 | J40: SOURCE EMPTY | K40: HELD
A41: BAY-HC-REC-3 | B41: ST-HC-REC | C41: MS-HC | D41: HC-A | E41: RECONSTRUCTION | F41: HC-RS3 | G41: Plume and airspace | H41: RECOVERY AND BURDEN | I41: =Controls!B12 -> 2 | J41: SOURCE EMPTY | K41: HELD
A42: BAY-HC-REC-4 | B42: ST-HC-REC | C42: MS-HC | D42: HC-A | E42: RECONSTRUCTION | F42: HC-RS4 | G42: Residual and re-ignition | H42: RECOVERY AND BURDEN | I42: =Controls!B12 -> 2 | J42: SOURCE EMPTY | K42: HELD
A43: BAY-LF-CHA-1 | B43: ST-LF-CHA | C43: MS-LF | D43: LF-B | E43: CHALLENGE | F43: LF-RS1 | G43: Source admission | H43: DENIED CONDITION | I43: =Controls!B12 -> 2 | J43: SOURCE EMPTY | K43: HELD
...

Sheet Method Realizations
A2: One hundred forty-four unlike method realization paths
A4: Every state bay has two unlike physical lineages. Identity, ancestry, calibration and observations remain empty until later warrants.
A6: Realization | B6: Bay | C6: Station | D6: System | E6: Root | F6: Role | G6: Receiver state | H6: Inquiry | I6: Lineage | J6: Decisive ancestry | K6: Calibration identity | L6: Accepted | M6: State
A7: ="MR-"&'State Bays'!A7&"-L1" -> MR-BAY-ET-CHA-1-L1 | B7: ='State Bays'!A7 -> BAY-ET-CHA-1 | C7: ='State Bays'!B7 -> ST-ET-CHA | D7: ='State Bays'!C7 -> MS-ET | E7: ='State Bays'!D7 -> ET-A | F7: ='State Bays'!E7 -> CHALLENGE | G7: ='State Bays'!F7 -> ET-RS1 | H7: ='State Bays'!H7 -> DENIED CONDITION | I7: L1 | J7: SOURCE EMPTY | K7: SOURCE EMPTY | L7: 0 | M7: HELD
A8: ="MR-"&'State Bays'!A7&"-L2" -> MR-BAY-ET-CHA-1-L2 | B8: ='State Bays'!A7 -> BAY-ET-CHA-1 | C8: ='State Bays'!B7 -> ST-ET-CHA | D8: ='State Bays'!C7 -> MS-ET | E8: ='State Bays'!D7 -> ET-A | F8: ='State Bays'!E7 -> CHALLENGE | G8: ='State Bays'!F7 -> ET-RS1 | H8: ='State Bays'!H7 -> DENIED CONDITION | I8: L2 | J8: SOURCE EMPTY | K8: SOURCE EMPTY | L8: 0 | M8: HELD
A9: ="MR-"&'State Bays'!A8&"-L1" -> MR-BAY-ET-CHA-2-L1 | B9: ='State Bays'!A8 -> BAY-ET-CHA-2 | C9: ='State Bays'!B8 -> ST-ET-CHA | D9: ='State Bays'!C8 -> MS-ET | E9: ='State Bays'!D8 -> ET-A | F9: ='State Bays'!E8 -> CHALLENGE | G9: ='State Bays'!F8 -> ET-RS2 | H9: ='State Bays'!H8 -> DENIED CONDITION | I9: L1 | J9: SOURCE EMPTY | K9: SOURCE EMPTY | L9: 0 | M9: HELD
A10: ="MR-"&'State Bays'!A8&"-L2" -> MR-BAY-ET-CHA-2-L2 | B10: ='State Bays'!A8 -> BAY-ET-CHA-2 | C10: ='State Bays'!B8 -> ST-ET-CHA | D10: ='State Bays'!C8 -> MS-ET | E10: ='State Bays'!D8 -> ET-A | F10: ='State Bays'!E8 -> CHALLENGE | G10: ='State Bays'!F8 -> ET-RS2 | H10: ='State Bays'!H8 -> DENIED CONDITION | I10: L2 | J10: SOURCE EMPTY | K10: SOURCE EMPTY | L10: 0 | M10: HELD
A11: ="MR-"&'State Bays'!A9&"-L1" -> MR-BAY-ET-CHA-3-L1 | B11: ='State Bays'!A9 -> BAY-ET-CHA-3 | C11: ='State Bays'!B9 -> ST-ET-CHA | D11: ='State Bays'!C9 -> MS-ET | E11: ='State Bays'!D9 -> ET-A | F11: ='State Bays'!E9 -> CHALLENGE | G11: ='State Bays'!F9 -> ET-RS3 | H11: ='State Bays'!H9 -> DENIED CONDITION | I11: L1 | J11: SOURCE EMPTY | K11: SOURCE EMPTY | L11: 0 | M11: HELD
A12: ="MR-"&'State Bays'!A9&"-L2" -> MR-BAY-ET-CHA-3-L2 | B12: ='State Bays'!A9 -> BAY-ET-CHA-3 | C12: ='State Bays'!B9 -> ST-ET-CHA | D12: ='State Bays'!C9 -> MS-ET | E12: ='State Bays'!D9 -> ET-A | F12: ='State Bays'!E9 -> CHALLENGE | G12: ='State Bays'!F9 -> ET-RS3 | H12: ='State Bays'!H9 -> DENIED CONDITION | I12: L2 | J12: SOURCE EMPTY | K12: SOURCE EMPTY | L12: 0 | M12: HELD
A13: ="MR-"&'State Bays'!A10&"-L1" -> MR-BAY-ET-CHA-4-L1 | B13: ='State Bays'!A10 -> BAY-ET-CHA-4 | C13: ='State Bays'!B10 -> ST-ET-CHA | D13: ='State Bays'!C10 -> MS-ET | E13: ='State Bays'!D10 -> ET-A | F13: ='State Bays'!E10 -> CHALLENGE | G13: ='State Bays'!F10 -> ET-RS4 | H13: ='State Bays'!H10 -> DENIED CONDITION | I13: L1 | J13: SOURCE EMPTY | K13: SOURCE EMPTY | L13: 0 | M13: HELD
A14: ="MR-"&'State Bays'!A10&"-L2" -> MR-BAY-ET-CHA-4-L2 | B14: ='State Bays'!A10 -> BAY-ET-CHA-4 | C14: ='State Bays'!B10 -> ST-ET-CHA | D14: ='State Bays'!C10 -> MS-ET | E14: ='State Bays'!D10 -> ET-A | F14: ='State Bays'!E10 -> CHALLENGE | G14: ='State Bays'!F10 -> ET-RS4 | H14: ='State Bays'!H10 -> DENIED CONDITION | I14: L2 | J14: SOURCE EMPTY | K14: SOURCE EMPTY | L14: 0 | M14: HELD
A15: ="MR-"&'State Bays'!A11&"-L1" -> MR-BAY-ET-CON-1-L1 | B15: ='State Bays'!A11 -> BAY-ET-CON-1 | C15: ='State Bays'!B11 -> ST-ET-CON | D15: ='State Bays'!C11 -> MS-ET | E15: ='State Bays'!D11 -> ET-A | F15: ='State Bays'!E11 -> CONTROL | G15: ='State Bays'!F11 -> ET-RS1 | H15: ='State Bays'!H11 -> LOAD AND QUALITY | I15: L1 | J15: SOURCE EMPTY | K15: SOURCE EMPTY | L15: 0 | M15: HELD
A16: ="MR-"&'State Bays'!A11&"-L2" -> MR-BAY-ET-CON-1-L2 | B16: ='State Bays'!A11 -> BAY-ET-CON-1 | C16: ='State Bays'!B11 -> ST-ET-CON | D16: ='State Bays'!C11 -> MS-ET | E16: ='State Bays'!D11 -> ET-A | F16: ='State Bays'!E11 -> CONTROL | G16: ='State Bays'!F11 -> ET-RS1 | H16: ='State Bays'!H11 -> LOAD AND QUALITY | I16: L2 | J16: SOURCE EMPTY | K16: SOURCE EMPTY | L16: 0 | M16: HELD
A17: ="MR-"&'State Bays'!A12&"-L1" -> MR-BAY-ET-CON-2-L1 | B17: ='State Bays'!A12 -> BAY-ET-CON-2 | C17: ='State Bays'!B12 -> ST-ET-CON | D17: ='State Bays'!C12 -> MS-ET | E17: ='State Bays'!D12 -> ET-A | F17: ='State Bays'!E12 -> CONTROL | G17: ='State Bays'!F12 -> ET-RS2 | H17: ='State Bays'!H12 -> LOAD AND QUALITY | I17: L1 | J17: SOURCE EMPTY | K17: SOURCE EMPTY | L17: 0 | M17: HELD
A18: ="MR-"&'State Bays'!A12&"-L2" -> MR-BAY-ET-CON-2-L2 | B18: ='State Bays'!A12 -> BAY-ET-CON-2 | C18: ='State Bays'!B12 -> ST-ET-CON | D18: ='State Bays'!C12 -> MS-ET | E18: ='State Bays'!D12 -> ET-A | F18: ='State Bays'!E12 -> CONTROL | G18: ='State Bays'!F12 -> ET-RS2 | H18: ='State Bays'!H12 -> LOAD AND QUALITY | I18: L2 | J18: SOURCE EMPTY | K18: SOURCE EMPTY | L18: 0 | M18: HELD
A19: ="MR-"&'State Bays'!A13&"-L1" -> MR-BAY-ET-CON-3-L1 | B19: ='State Bays'!A13 -> BAY-ET-CON-3 | C19: ='State Bays'!B13 -> ST-ET-CON | D19: ='State Bays'!C13 -> MS-ET | E19: ='State Bays'!D13 -> ET-A | F19: ='State Bays'!E13 -> CONTROL | G19: ='State Bays'!F13 -> ET-RS3 | H19: ='State Bays'!H13 -> LOAD AND QUALITY | I19: L1 | J19: SOURCE EMPTY | K19: SOURCE EMPTY | L19: 0 | M19: HELD
A20: ="MR-"&'State Bays'!A13&"-L2" -> MR-BAY-ET-CON-3-L2 | B20: ='State Bays'!A13 -> BAY-ET-CON-3 | C20: ='State Bays'!B13 -> ST-ET-CON | D20: ='State Bays'!C13 -> MS-ET | E20: ='State Bays'!D13 -> ET-A | F20: ='State Bays'!E13 -> CONTROL | G20: ='State Bays'!F13 -> ET-RS3 | H20: ='State Bays'!H13 -> LOAD AND QUALITY | I20: L2 | J20: SOURCE EMPTY | K20: SOURCE EMPTY | L20: 0 | M20: HELD
A21: ="MR-"&'State Bays'!A14&"-L1" -> MR-BAY-ET-CON-4-L1 | B21: ='State Bays'!A14 -> BAY-ET-CON-4 | C21: ='State Bays'!B14 -> ST-ET-CON | D21: ='State Bays'!C14 -> MS-ET | E21: ='State Bays'!D14 -> ET-A | F21: ='State Bays'!E14 -> CONTROL | G21: ='State Bays'!F14 -> ET-RS4 | H21: ='State Bays'!H14 -> LOAD AND QUALITY | I21: L1 | J21: SOURCE EMPTY | K21: SOURCE EMPTY | L21: 0 | M21: HELD
A22: ="MR-"&'State Bays'!A14&"-L2" -> MR-BAY-ET-CON-4-L2 | B22: ='State Bays'!A14 -> BAY-ET-CON-4 | C22: ='State Bays'!B14 -> ST-ET-CON | D22: ='State Bays'!C14 -> MS-ET | E22: ='State Bays'!D14 -> ET-A | F22: ='State Bays'!E14 -> CONTROL | G22: ='State Bays'!F14 -> ET-RS4 | H22: ='State Bays'!H14 -> LOAD AND QUALITY | I22: L2 | J22: SOURCE EMPTY | K22: SOURCE EMPTY | L22: 0 | M22: HELD
A23: ="MR-"&'State Bays'!A15&"-L1" -> MR-BAY-ET-REC-1-L1 | B23: ='State Bays'!A15 -> BAY-ET-REC-1 | C23: ='State Bays'!B15 -> ST-ET-REC | D23: ='State Bays'!C15 -> MS-ET | E23: ='State Bays'!D15 -> ET-A | F23: ='State Bays'!E15 -> RECONSTRUCTION | G23: ='State Bays'!F15 -> ET-RS1 | H23: ='State Bays'!H15 -> RECOVERY AND BURDEN | I23: L1 | J23: SOURCE EMPTY | K23: SOURCE EMPTY | L23: 0 | M23: HELD
A24: ="MR-"&'State Bays'!A15&"-L2" -> MR-BAY-ET-REC-1-L2 | B24: ='State Bays'!A15 -> BAY-ET-REC-1 | C24: ='State Bays'!B15 -> ST-ET-REC | D24: ='State Bays'!C15 -> MS-ET | E24: ='State Bays'!D15 -> ET-A | F24: ='State Bays'!E15 -> RECONSTRUCTION | G24: ='State Bays'!F15 -> ET-RS1 | H24: ='State Bays'!H15 -> RECOVERY AND BURDEN | I24: L2 | J24: SOURCE EMPTY | K24: SOURCE EMPTY | L24: 0 | M24: HELD
A25: ="MR-"&'State Bays'!A16&"-L1" -> MR-BAY-ET-REC-2-L1 | B25: ='State Bays'!A16 -> BAY-ET-REC-2 | C25: ='State Bays'!B16 -> ST-ET-REC | D25: ='State Bays'!C16 -> MS-ET | E25: ='State Bays'!D16 -> ET-A | F25: ='State Bays'!E16 -> RECONSTRUCTION | G25: ='State Bays'!F16 -> ET-RS2 | H25: ='State Bays'!H16 -> RECOVERY AND BURDEN | I25: L1 | J25: SOURCE EMPTY | K25: SOURCE EMPTY | L25: 0 | M25: HELD
A26: ="MR-"&'State Bays'!A16&"-L2" -> MR-BAY-ET-REC-2-L2 | B26: ='State Bays'!A16 -> BAY-ET-REC-2 | C26: ='State Bays'!B16 -> ST-ET-REC | D26: ='State Bays'!C16 -> MS-ET | E26: ='State Bays'!D16 -> ET-A | F26: ='State Bays'!E16 -> RECONSTRUCTION | G26: ='State Bays'!F16 -> ET-RS2 | H26: ='State Bays'!H16 -> RECOVERY AND BURDEN | I26: L2 | J26: SOURCE EMPTY | K26: SOURCE EMPTY | L26: 0 | M26: HELD
A27: ="MR-"&'State Bays'!A17&"-L1" -> MR-BAY-ET-REC-3-L1 | B27: ='State Bays'!A17 -> BAY-ET-REC-3 | C27: ='State Bays'!B17 -> ST-ET-REC | D27: ='State Bays'!C17 -> MS-ET | E27: ='State Bays'!D17 -> ET-A | F27: ='State Bays'!E17 -> RECONSTRUCTION | G27: ='State Bays'!F17 -> ET-RS3 | H27: ='State Bays'!H17 -> RECOVERY AND BURDEN | I27: L1 | J27: SOURCE EMPTY | K27: SOURCE EMPTY | L27: 0 | M27: HELD
A28: ="MR-"&'State Bays'!A17&"-L2" -> MR-BAY-ET-REC-3-L2 | B28: ='State Bays'!A17 -> BAY-ET-REC-3 | C28: ='State Bays'!B17 -> ST-ET-REC | D28: ='State Bays'!C17 -> MS-ET | E28: ='State Bays'!D17 -> ET-A | F28: ='State Bays'!E17 -> RECONSTRUCTION | G28: ='State Bays'!F17 -> ET-RS3 | H28: ='State Bays'!H17 -> RECOVERY AND BURDEN | I28: L2 | J28: SOURCE EMPTY | K28: SOURCE EMPTY | L28: 0 | M28: HELD
A29: ="MR-"&'State Bays'!A18&"-L1" -> MR-BAY-ET-REC-4-L1 | B29: ='State Bays'!A18 -> BAY-ET-REC-4 | C29: ='State Bays'!B18 -> ST-ET-REC | D29: ='State Bays'!C18 -> MS-ET | E29: ='State Bays'!D18 -> ET-A | F29: ='State Bays'!E18 -> RECONSTRUCTION | G29: ='State Bays'!F18 -> ET-RS4 | H29: ='State Bays'!H18 -> RECOVERY AND BURDEN | I29: L1 | J29: SOURCE EMPTY | K29: SOURCE EMPTY | L29: 0 | M29: HELD
A30: ="MR-"&'State Bays'!A18&"-L2" -> MR-BAY-ET-REC-4-L2 | B30: ='State Bays'!A18 -> BAY-ET-REC-4 | C30: ='State Bays'!B18 -> ST-ET-REC | D30: ='State Bays'!C18 -> MS-ET | E30: ='State Bays'!D18 -> ET-A | F30: ='State Bays'!E18 -> RECONSTRUCTION | G30: ='State Bays'!F18 -> ET-RS4 | H30: ='State Bays'!H18 -> RECOVERY AND BURDEN | I30: L2 | J30: SOURCE EMPTY | K30: SOURCE EMPTY | L30: 0 | M30: HELD
A31: ="MR-"&'State Bays'!A19&"-L1" -> MR-BAY-CT-CHA-1-L1 | B31: ='State Bays'!A19 -> BAY-CT-CHA-1 | C31: ='State Bays'!B19 -> ST-CT-CHA | D31: ='State Bays'!C19 -> MS-CT | E31: ='State Bays'!D19 -> CT-C | F31: ='State Bays'!E19 -> CHALLENGE | G31: ='State Bays'!F19 -> CT-RS1 | H31: ='State Bays'!H19 -> DENIED CONDITION | I31: L1 | J31: SOURCE EMPTY | K31: SOURCE EMPTY | L31: 0 | M31: HELD
A32: ="MR-"&'State Bays'!A19&"-L2" -> MR-BAY-CT-CHA-1-L2 | B32: ='State Bays'!A19 -> BAY-CT-CHA-1 | C32: ='State Bays'!B19 -> ST-CT-CHA | D32: ='State Bays'!C19 -> MS-CT | E32: ='State Bays'!D19 -> CT-C | F32: ='State Bays'!E19 -> CHALLENGE | G32: ='State Bays'!F19 -> CT-RS1 | H32: ='State Bays'!H19 -> DENIED CONDITION | I32: L2 | J32: SOURCE EMPTY | K32: SOURCE EMPTY | L32: 0 | M32: HELD
A33: ="MR-"&'State Bays'!A20&"-L1" -> MR-BAY-CT-CHA-2-L1 | B33: ='State Bays'!A20 -> BAY-CT-CHA-2 | C33: ='State Bays'!B20 -> ST-CT-CHA | D33: ='State Bays'!C20 -> MS-CT | E33: ='State Bays'!D20 -> CT-C | F33: ='State Bays'!E20 -> CHALLENGE | G33: ='State Bays'!F20 -> CT-RS2 | H33: ='State Bays'!H20 -> DENIED CONDITION | I33: L1 | J33: SOURCE EMPTY | K33: SOURCE EMPTY | L33: 0 | M33: HELD
A34: ="MR-"&'State Bays'!A20&"-L2" -> MR-BAY-CT-CHA-2-L2 | B34: ='State Bays'!A20 -> BAY-CT-CHA-2 | C34: ='State Bays'!B20 -> ST-CT-CHA | D34: ='State Bays'!C20 -> MS-CT | E34: ='State Bays'!D20 -> CT-C | F34: ='State Bays'!E20 -> CHALLENGE | G34: ='State Bays'!F20 -> CT-RS2 | H34: ='State Bays'!H20 -> DENIED CONDITION | I34: L2 | J34: SOURCE EMPTY | K34: SOURCE EMPTY | L34: 0 | M34: HELD
A35: ="MR-"&'State Bays'!A21&"-L1" -> MR-BAY-CT-CHA-3-L1 | B35: ='State Bays'!A21 -> BAY-CT-CHA-3 | C35: ='State Bays'!B21 -> ST-CT-CHA | D35: ='State Bays'!C21 -> MS-CT | E35: ='State Bays'!D21 -> CT-C | F35: ='State Bays'!E21 -> CHALLENGE | G35: ='State Bays'!F21 -> CT-RS3 | H35: ='State Bays'!H21 -> DENIED CONDITION | I35: L1 | J35: SOURCE EMPTY | K35: SOURCE EMPTY | L35: 0 | M35: HELD
A36: ="MR-"&'State Bays'!A21&"-L2" -> MR-BAY-CT-CHA-3-L2 | B36: ='State Bays'!A21 -> BAY-CT-CHA-3 | C36: ='State Bays'!B21 -> ST-CT-CHA | D36: ='State Bays'!C21 -> MS-CT | E36: ='State Bays'!D21 -> CT-C | F36: ='State Bays'!E21 -> CHALLENGE | G36: ='State Bays'!F21 -> CT-RS3 | H36: ='State Bays'!H21 -> DENIED CONDITION | I36: L2 | J36: SOURCE EMPTY | K36: SOURCE EMPTY | L36: 0 | M36: HELD
A37: ="MR-"&'State Bays'!A22&"-L1" -> MR-BAY-CT-CHA-4-L1 | B37: ='State Bays'!A22 -> BAY-CT-CHA-4 | C37: ='State Bays'!B22 -> ST-CT-CHA | D37: ='State Bays'!C22 -> MS-CT | E37: ='State Bays'!D22 -> CT-C | F37: ='State Bays'!E22 -> CHALLENGE | G37: ='State Bays'!F22 -> CT-RS4 | H37: ='State Bays'!H22 -> DENIED CONDITION | I37: L1 | J37: SOURCE EMPTY | K37: SOURCE EMPTY | L37: 0 | M37: HELD
A38: ="MR-"&'State Bays'!A22&"-L2" -> MR-BAY-CT-CHA-4-L2 | B38: ='State Bays'!A22 -> BAY-CT-CHA-4 | C38: ='State Bays'!B22 -> ST-CT-CHA | D38: ='State Bays'!C22 -> MS-CT | E38: ='State Bays'!D22 -> CT-C | F38: ='State Bays'!E22 -> CHALLENGE | G38: ='State Bays'!F22 -> CT-RS4 | H38: ='State Bays'!H22 -> DENIED CONDITION | I38: L2 | J38: SOURCE EMPTY | K38: SOURCE EMPTY | L38: 0 | M38: HELD
A39: ="MR-"&'State Bays'!A23&"-L1" -> MR-BAY-CT-CON-1-L1 | B39: ='State Bays'!A23 -> BAY-CT-CON-1 | C39: ='State Bays'!B23 -> ST-CT-CON | D39: ='State Bays'!C23 -> MS-CT | E39: ='State Bays'!D23 -> CT-C | F39: ='State Bays'!E23 -> CONTROL | G39: ='State Bays'!F23 -> CT-RS1 | H39: ='State Bays'!H23 -> LOAD AND QUALITY | I39: L1 | J39: SOURCE EMPTY | K39: SOURCE EMPTY | L39: 0 | M39: HELD
A40: ="MR-"&'State Bays'!A23&"-L2" -> MR-BAY-CT-CON-1-L2 | B40: ='State Bays'!A23 -> BAY-CT-CON-1 | C40: ='State Bays'!B23 -> ST-CT-CON | D40: ='State Bays'!C23 -> MS-CT | E40: ='State Bays'!D23 -> CT-C | F40: ='State Bays'!E23 -> CONTROL | G40: ='State Bays'!F23 -> CT-RS1 | H40: ='State Bays'!H23 -> LOAD AND QUALITY | I40: L2 | J40: SOURCE EMPTY | K40: SOURCE EMPTY | L40: 0 | M40: HELD
A41: ="MR-"&'State Bays'!A24&"-L1" -> MR-BAY-CT-CON-2-L1 | B41: ='State Bays'!A24 -> BAY-CT-CON-2 | C41: ='State Bays'!B24 -> ST-CT-CON | D41: ='State Bays'!C24 -> MS-CT | E41: ='State Bays'!D24 -> CT-C | F41: ='State Bays'!E24 -> CONTROL | G41: ='State Bays'!F24 -> CT-RS2 | H41: ='State Bays'!H24 -> LOAD AND QUALITY | I41: L1 | J41: SOURCE EMPTY | K41: SOURCE EMPTY | L41: 0 | M41: HELD
A42: ="MR-"&'State Bays'!A24&"-L2" -> MR-BAY-CT-CON-2-L2 | B42: ='State Bays'!A24 -> BAY-CT-CON-2 | C42: ='State Bays'!B24 -> ST-CT-CON | D42: ='State Bays'!C24 -> MS-CT | E42: ='State Bays'!D24 -> CT-C | F42: ='State Bays'!E24 -> CONTROL | G42: ='State Bays'!F24 -> CT-RS2 | H42: ='State Bays'!H24 -> LOAD AND QUALITY | I42: L2 | J42: SOURCE EMPTY | K42: SOURCE EMPTY | L42: 0 | M42: HELD
A43: ="MR-"&'State Bays'!A25&"-L1" -> MR-BAY-CT-CON-3-L1 | B43: ='State Bays'!A25 -> BAY-CT-CON-3 | C43: ='State Bays'!B25 -> ST-CT-CON | D43: ='State Bays'!C25 -> MS-CT | E43: ='State Bays'!D25 -> CT-C | F43: ='State Bays'!E25 -> CONTROL | G43: ='State Bays'!F25 -> CT-RS3 | H43: ='State Bays'!H25 -> LOAD AND QUALITY | I43: L1 | J43: SOURCE EMPTY | K43: SOURCE EMPTY | L43: 0 | M43: HELD
...

Sheet Regeneration
A2: Seventy-two regeneration functions in eighteen non-credit lanes
A4: A regeneration lane must recover its own station after one destructive event and may not serve as an alternate event lane.
A6: Function ID | B6: Station | C6: System | D6: Root | E6: Role | F6: Function | G6: Physical duty | H6: Paths recoverable | I6: Event credit | J6: Tool ancestry | K6: State
A7: RG-ET-CHA-ISOLATE | B7: ST-ET-CHA | C7: MS-ET | D7: ET-A | E7: CHALLENGE | F7: ISOLATE | G7: isolate, decontaminate and establish safe work state | H7: 8 | I7: NO | J7: SOURCE EMPTY | K7: HELD
A8: RG-ET-CHA-DIAGNOSE | B8: ST-ET-CHA | C8: MS-ET | D8: ET-A | E8: CHALLENGE | F8: DIAGNOSE | G8: disassemble, measure and identify damage without overwriting ancestry | H8: 8 | I8: NO | J8: SOURCE EMPTY | K8: HELD
A9: RG-ET-CHA-REBUILD | B9: ST-ET-CHA | C9: MS-ET | D9: ET-A | E9: CHALLENGE | F9: REBUILD | G9: repair or reproduce the eight local realization paths and rig boundary | H9: 8 | I9: NO | J9: SOURCE EMPTY | K9: HELD
A10: RG-ET-CHA-RECERTIFY | B10: ST-ET-CHA | C10: MS-ET | D10: ET-A | E10: CHALLENGE | F10: RECERTIFY | G10: recalibrate, independently witness and return to controlled custody | H10: 8 | I10: NO | J10: SOURCE EMPTY | K10: HELD
A11: RG-ET-CON-ISOLATE | B11: ST-ET-CON | C11: MS-ET | D11: ET-A | E11: CONTROL | F11: ISOLATE | G11: isolate, decontaminate and establish safe work state | H11: 8 | I11: NO | J11: SOURCE EMPTY | K11: HELD
A12: RG-ET-CON-DIAGNOSE | B12: ST-ET-CON | C12: MS-ET | D12: ET-A | E12: CONTROL | F12: DIAGNOSE | G12: disassemble, measure and identify damage without overwriting ancestry | H12: 8 | I12: NO | J12: SOURCE EMPTY | K12: HELD
A13: RG-ET-CON-REBUILD | B13: ST-ET-CON | C13: MS-ET | D13: ET-A | E13: CONTROL | F13: REBUILD | G13: repair or reproduce the eight local realization paths and rig boundary | H13: 8 | I13: NO | J13: SOURCE EMPTY | K13: HELD
A14: RG-ET-CON-RECERTIFY | B14: ST-ET-CON | C14: MS-ET | D14: ET-A | E14: CONTROL | F14: RECERTIFY | G14: recalibrate, independently witness and return to controlled custody | H14: 8 | I14: NO | J14: SOURCE EMPTY | K14: HELD
A15: RG-ET-REC-ISOLATE | B15: ST-ET-REC | C15: MS-ET | D15: ET-A | E15: RECONSTRUCTION | F15: ISOLATE | G15: isolate, decontaminate and establish safe work state | H15: 8 | I15: NO | J15: SOURCE EMPTY | K15: HELD
A16: RG-ET-REC-DIAGNOSE | B16: ST-ET-REC | C16: MS-ET | D16: ET-A | E16: RECONSTRUCTION | F16: DIAGNOSE | G16: disassemble, measure and identify damage without overwriting ancestry | H16: 8 | I16: NO | J16: SOURCE EMPTY | K16: HELD
A17: RG-ET-REC-REBUILD | B17: ST-ET-REC | C17: MS-ET | D17: ET-A | E17: RECONSTRUCTION | F17: REBUILD | G17: repair or reproduce the eight local realization paths and rig boundary | H17: 8 | I17: NO | J17: SOURCE EMPTY | K17: HELD
A18: RG-ET-REC-RECERTIFY | B18: ST-ET-REC | C18: MS-ET | D18: ET-A | E18: RECONSTRUCTION | F18: RECERTIFY | G18: recalibrate, independently witness and return to controlled custody | H18: 8 | I18: NO | J18: SOURCE EMPTY | K18: HELD
... A78: RG-RT-REC-RECERTIFY | B78: ST-RT-REC | C78: MS-RT | D78: RT-B | E78: RECONSTRUCTION | F78: RECERTIFY | G78: recalibrate, independently witness and return to controlled custody | H78: 8 | I78: NO | J78: SOURCE EMPTY | K78: HELD

Sheet Rig Families
A2: Six sovereign truth-train families
A4: Full scale attaches to the causal interface. External loads may be emulated only when they do not scale away the physics being judged.
A6: System | B6: Root | C6: Truth train | D6: Limiting account | E6: Full-scale boundary | F6: Challenge denial | G6: Stations | H6: State bays | I6: Realizations | J6: Regen functions | K6: Public USD B | L6: Private USD B | M6: Combined USD B | N6: Build state
A7: MS-ET | B7: ET-A | C7: Pelagic heavy bridge | D7: Route flow | E7: moving load exchange through dry custody | F7: largest connector removed | G7: =Controls!B10 -> 3 | H7: =G7*Controls!B11 -> 12 | I7: =H7*Controls!B12 -> 24 | J7: =G7*4 -> 12 | K7: =Controls!B7/Controls!B9 -> 2 | L7: 0.50047462 | M7: =K7+L7 -> 2.5004746 | N7: FROZEN FOR COMPETITION
A8: MS-CT | B8: CT-C | C8: Building utility spine | D8: Energy | E8: occupied-building connection and utility isolation | F8: one 7 MW cell plus propagation fault | G8: =Controls!B10 -> 3 | H8: =G8*Controls!B11 -> 12 | I8: =H8*Controls!B12 -> 24 | J8: =G8*4 -> 12 | K8: =Controls!B7/Controls!B9 -> 2 | L8: 0.51649348 | M8: =K8+L8 -> 2.5164935 | N8: FROZEN FOR COMPETITION
A9: MS-HC | B9: HC-A | C9: Atmospheric flux wing | D9: Route flow | E9: one-kilometre held atmospheric edge | F9: grid, water, communications and one intervention cell denied | G9: =Controls!B10 -> 3 | H9: =G9*Controls!B11 -> 12 | I9: =H9*Controls!B12 -> 24 | J9: =G9*4 -> 12 | K9: =Controls!B7/Controls!B9 -> 2 | L9: 0.30722165 | M9: =K9+L9 -> 2.3072217 | N9: FROZEN FOR COMPETITION
A10: MS-LF | B10: LF-B | C10: Inland geothermal train | D10: Energy | E10: live subsurface source and closed multi-product train | F10: uncertain geology, source-path loss and receiver refusal | G10: =Controls!B10 -> 3 | H10: =G10*Controls!B11 -> 12 | I10: =H10*Controls!B12 -> 24 | J10: =G10*4 -> 12 | K10: =Controls!B7/Controls!B9 -> 2 | L10: 0.89941282 | M10: =K10+L10 -> 2.8994128 | N10: FROZEN FOR COMPETITION
A11: MS-HU | B11: HU-A | C11: Clinical continuity campus | D11: Mass | E11: complete clinical-island metabolism | F11: utility family, specialist cohort or destination removed | G11: =Controls!B10 -> 3 | H11: =G11*Controls!B11 -> 12 | I11: =H11*Controls!B12 -> 24 | J11: =G11*4 -> 12 | K11: =Controls!B7/Controls!B9 -> 2 | L11: 0.86071245 | M11: =K11+L11 -> 2.8607125 | N11: FROZEN FOR COMPETITION
A12: MS-RT | B12: RT-B | C12: Microfactory mesh | D12: Energy | E12: coupon-to-qualified-part disconnected chain | F12: depot, network, calibration path and one process cell removed | G12: =Controls!B10 -> 3 | H12: =G12*Controls!B11 -> 12 | I12: =H12*Controls!B12 -> 24 | J12: =G12*4 -> 12 | K12: =Controls!B7/Controls!B9 -> 2 | L12: 0.50259779 | M12: =K12+L12 -> 2.5025978 | N12: FROZEN FOR COMPETITION
A13: TOTAL | B13: six | C13: six sovereign families | D13: — | E13: — | F13: — | G13: =SUM(G7:G12) -> 18 | H13: =SUM(H7:H12) -> 72 | I13: =SUM(I7:I12) -> 144 | J13: =SUM(J7:J12) -> 72 | K13: =SUM(K7:K12) -> 12 | L13: =SUM(L7:L12) -> 3.5869128 | M13: =SUM(M7:M12) -> 15.586913 | N13: WARRANT-CONSTITUTED

Sheet ET Rig
A2: ET sovereign physical truth system
A4: Functional envelope only: no site, supplier, serial, observed coefficient or exterior form is admitted.
A6: Zone | B6: Physical article | C6: Full-scale boundary | D6: Role variation | E6: Common implementation | F6: Decisive state | G6: Build status
A7: moving source | B7: programmable wave/current and source-motion field | C7: candidate load and motion envelope | D7: role-native forcing history | E7: NO | F7: motion and force | G7: BUILD REQUIRED
A8: exchange plane | B8: full-interface candidate connection with independent mass custody | C8: 1:1 contact physics | D8: connector loss at challenge | E8: NO | F8: mass across plane | G8: BUILD REQUIRED
A9: transfer reach | B9: compliant floating reach and breakable section | C9: working geometry | D9: matched intact reach at control | E9: NO | F9: stability and throughput | G9: BUILD REQUIRED
A10: shore transition | B10: reconfigurable wet-to-dry ground reaction field | C10: 1:1 bearing and articulation | D10: largest connector denial | E10: NO | F10: ground reaction | G10: BUILD REQUIRED
A11: dry custody | B11: sealed staging, manifest and onward handoff cells | C11: 5,630 t/day denominator | D11: same public record grammar | E11: BOUNDARY ONLY | F11: accepted mass | G11: BUILD REQUIRED
A12: residual and safeing | B12: lost load, fluid and energy capture | C12: full consequence | D12: public abort cannot complete candidate safeing | E12: NO | F12: terminal state | G12: BUILD REQUIRED

Sheet CT Rig
A2: CT sovereign physical truth system
A4: Functional envelope only: no site, supplier, serial, observed coefficient or exterior form is admitted.
A6: Zone | B6: Physical article | C6: Full-scale boundary | D6: Role variation | E6: Common implementation | F6: Decisive state | G6: Build status
A7: building body | B7: reconfigurable full-scale sacrificial structural sector | C7: occupied geometry and damaged stiffness | D7: unlike body construction by role | E7: NO | F7: load path | G7: BUILD REQUIRED
A8: attachment field | B8: robotic reversible façade and interior anchors | C8: 1:1 anchor mechanics | D8: propagation faults at challenge | E8: NO | F8: damage growth | G8: BUILD REQUIRED
A9: vertical service | B9: lift, stair and accessible movement loads | C9: human-scale routes | D9: synthetic occupancy only | E9: NO | F9: safe cases/hour | G9: BUILD REQUIRED
A10: utility trunks | B10: power, water, data and dirty-return trunks | C10: 7 MW cell and 42 MW root boundary | D10: independent load banks | E10: NO | F10: isolation and delivered service | G10: BUILD REQUIRED
A11: hazard insertion | B11: smoke, water, contamination and electrical faults | C11: full interface consequence | D11: challenge-owned insertion | E11: NO | F11: cross-domain propagation | G11: BUILD REQUIRED
A12: receiver state | B12: low-rise, high-rise, refuge and egress emulators | C12: four complete worlds | D12: same public state grammar | E12: BOUNDARY ONLY | F12: accepted disposition | G12: BUILD REQUIRED

Sheet HC Rig
A2: HC sovereign physical truth system
A4: Functional envelope only: no site, supplier, serial, observed coefficient or exterior form is admitted.
A6: Zone | B6: Physical article | C6: Full-scale boundary | D6: Role variation | E6: Common implementation | F6: Decisive state | G6: Build status
A7: boundary corridor | B7: instrumented one-kilometre fire-control edge | C7: 1.00 km causal boundary | D7: unlike terrain and fuel beds | E7: NO | F7: held edge | G7: BUILD REQUIRED
A8: heat-plume field | B8: repeatable thermal, ember and smoke source | C8: full delivery environment | D8: challenge denial and matched control | E8: NO | F8: growth and flux | G8: BUILD REQUIRED
A9: flight duty cell | B9: high-cycle thermal aircraft and propulsion loading | C9: six-to-seventy-two-hour duty chain | D9: role-native control and maintenance | E9: NO | F9: availability and hidden fleet factor | G9: BUILD REQUIRED
A10: deposition field | B10: precision working-fluid delivery and reconstruction | C10: full droplet/particle path | D10: independent tomography lineages | E10: NO | F10: attributed effect | G10: BUILD REQUIRED
A11: denied services | B11: grid, water and communications isolation | C11: zero borrowed infrastructure | D11: challenge enforced | E11: NO | F11: root autonomy | G11: BUILD REQUIRED
A12: runoff and re-ignition | B12: closed water, residue and thermal return | C12: full counterflow | D12: public quarantine only | E12: BOUNDARY ONLY | F12: terminal hold | G12: BUILD REQUIRED

Sheet LF Rig
A2: LF sovereign physical truth system
A4: Functional envelope only: no site, supplier, serial, observed coefficient or exterior form is admitted.
A6: Zone | B6: Physical article | C6: Full-scale boundary | D6: Role variation | E6: Common implementation | F6: Decisive state | G6: Build status
A7: subsurface truth body | B7: qualified geology with independent characterization | C7: live formation physics | D7: unlike characterization lineage | E7: NO | F7: formation state | G7: BUILD REQUIRED
A8: well pair | B8: production and injection bores with rapid construction | C8: one source position | D8: source-path denial | E8: NO | F8: drawdown and induced hazard | G8: BUILD REQUIRED
A9: firm bus | B9: root-native generation, black start and protection | C9: 40 MW firm | D9: one source-cell loss | E9: NO | F9: net deliverable energy | G9: BUILD REQUIRED
A10: water train | B10: brackish separation, treatment and storage | C10: 25,000 m3/day | D10: matched water chemistry | E10: NO | F10: accepted water | G10: BUILD REQUIRED
A11: thermal service | B11: recoverable heat delivery and rejection | C11: 20 MWth at early service | D11: receiver refusal | E11: NO | F11: useful heat and sink | G11: BUILD REQUIRED
A12: corridor and residual | B12: robotic pipe/conductor build plus brine custody | C12: complete point-of-use chain | D12: unlike tools and calibration | E12: NO | F12: route and terminal brine | G12: BUILD REQUIRED

Sheet HU Rig
A2: HU sovereign physical truth system
A4: Functional envelope only: no site, supplier, serial, observed coefficient or exterior form is admitted.
A6: Zone | B6: Physical article | C6: Full-scale boundary | D6: Role variation | E6: Common implementation | F6: Decisive state | G6: Build status
A7: clinical island | B7: complete configurable clinical metabolism | C7: all ten care-line interfaces | D7: second-team cold build | E7: NO | F7: care-line continuity | G7: BUILD REQUIRED
A8: reception and triage | B8: identity-preserving inflow and acuity assignment | C8: physical patient-path loads | D8: standardized nonpatient loads | E8: BOUNDARY ONLY | F8: accepted state transition | G8: BUILD REQUIRED
A9: acute and specialty | B9: critical environments and specialty dependencies | C9: human-scale treatment paths | D9: specialist cohort denial | E9: NO | F9: staffed supplied positions | G9: BUILD REQUIRED
A10: utility metabolism | B10: power, air, water, sterile supply and no-break state | C10: complete island demand | D10: utility-family denial | E10: NO | F10: safe clinical state | G10: BUILD REQUIRED
A11: transfer and discharge | B11: regulated destination and supported-release chain | C11: complete receiver burden | D11: destination denial | E11: NO | F11: accepted handoff | G11: BUILD REQUIRED
A12: dirty counterflow | B12: waste, decontamination and residual custody | C12: complete clinical return | D12: public quarantine only | E12: BOUNDARY ONLY | F12: closed residual | G12: BUILD REQUIRED

Sheet RT Rig
A2: RT sovereign physical truth system
A4: Functional envelope only: no site, supplier, serial, observed coefficient or exterior form is admitted.
A6: Zone | B6: Physical article | C6: Full-scale boundary | D6: Role variation | E6: Common implementation | F6: Decisive state | G6: Build status
A7: dirty return | B7: sealed receipt and configuration-state capture | C7: complete returned article boundary | D7: depot denied | E7: BOUNDARY ONLY | F7: accepted return | G7: BUILD REQUIRED
A8: diagnosis | B8: disassembly, damage imaging and material assay | C8: part-scale causal truth | D8: unlike measurement lineages | E8: NO | F8: damage state | G8: BUILD REQUIRED
A9: feedstock conversion | B9: controlled virgin, recycled and recovered inputs | C9: coupon-to-stock chain | D9: vendor key denied | E9: NO | F9: material ancestry | G9: BUILD REQUIRED
A10: process mesh | B10: islanded additive, subtractive, thermal and joining cells | C10: complete critical-class route | D10: one process cell denied | E10: NO | F10: qualified output/MWh | G10: BUILD REQUIRED
A11: metrology and calibration | B11: portable standards, inspection and witness | C11: release-level uncertainty | D11: primary route denied | E11: NO | F11: equivalence and uncertainty | G11: BUILD REQUIRED
A12: release and residual | B12: signed configuration release plus waste custody | C12: 99 positions/168 h boundary | D12: network and receiver denied | E12: NO | F12: accepted replacement | G12: BUILD REQUIRED

Sheet Independence
A2: Decisive-domain firewall
A4: A common failure may invalidate an event. It may not create a valid outcome.
A6: Domain | B6: Publicly common | C6: Must split by system | D6: Must split by station role | E6: Must split by lineage | F6: Reason | G6: Violation result
A7: units and record fields | B7: YES | C7: NO | D7: NO | E7: NO | F7: meaning must remain portable | G7: none
A8: public connection geometry | B8: BOUNDARY | C8: NO | D8: NO | E8: NO | F8: permits substitutable attachment | G8: review
A9: candidate-facing utilities | B9: NO | C9: YES | D9: YES | E9: YES | F9: conditioning can improve outcome | G9: HOLD
A10: load generation | B10: NO | C10: YES | D10: YES | E10: YES | F10: shared forcing creates correlated truth | G10: HOLD
A11: working fluid or source | B11: NO | C11: YES | D11: YES | E11: YES | F11: material state is causal | G11: HOLD
A12: actuation physics | B12: NO | C12: YES | D12: YES | E12: YES | F12: common actuation selects mechanism | G12: KILL LINEAGE
A13: decisive sensors | B13: NO | C13: YES | D13: YES | E13: YES | F13: one bias can govern all results | G13: HOLD
A14: calibration artifacts | B14: NO | C14: YES | D14: YES | E14: YES | F14: self-consistency is not validation | G14: HOLD
A15: clock and runtime | B15: NO | C15: YES | D15: YES | E15: YES | F15: common timing can align error | G15: HOLD
A16: safeing path | B16: NO | C16: YES | D16: YES | E16: YES | F16: public protection cannot complete candidate duty | G16: KILL LINEAGE
A17: build compiler and signer | B17: NO | C17: YES | D17: YES | E17: YES | F17: software openness does not erase ancestry | G17: KILL LINEAGE
A18: rebuild and recovery tooling | B18: NO | C18: YES | D18: YES | E18: YES | F18: regeneration must survive sibling loss | G18: HOLD

Sheet Technology
A2: Eighteen root-native technology campaigns
A4: These campaigns are physical discovery obligations inside existing authority; no technical success is presumed.
A6: ID | B6: System | C6: Root | D6: Technology objective | E6: Physical embodiment | F6: Fatal result | G6: Authority state
A7: T-ET-1 | B7: MS-ET | C7: ET-A | D7: programmable wave-load and hydrostatic exchange | E7: moving-interface load field | F7: custody or stability breaks below service rate | G7: WARRANT-CONSTITUTED
A8: T-ET-2 | B8: MS-ET | C8: ET-A | D8: self-forming wet-to-dry terminal mechanics | E8: breakable shore and ground-bearing field | F8: connector loss defeats dry handoff | G8: WARRANT-CONSTITUTED
A9: T-ET-3 | B9: MS-ET | C9: ET-A | D9: machine-readable custody under motion | E9: independent physical manifest chain | F9: mass or ownership becomes untraceable | G9: WARRANT-CONSTITUTED
A10: T-CT-1 | B10: MS-CT | C10: CT-C | D10: reversible attachment to damaged façades | E10: full-scale reconfigurable building skin | F10: anchor load propagates damage | G10: WARRANT-CONSTITUTED
A11: T-CT-2 | B11: MS-CT | C11: CT-C | D11: robotic multi-utility insertion | E11: fault-insertable occupied utility block | F11: isolation cannot prevent casualty | G11: WARRANT-CONSTITUTED
A12: T-CT-3 | B12: MS-CT | C12: CT-C | D12: safe temporary lift and utility trunks | E12: instrumented vertical spine | F12: lawful access falls below threshold | G12: WARRANT-CONSTITUTED
A13: T-HC-1 | B13: MS-HC | C13: HC-A | D13: high-duty thermal structures and regenerative flight | E13: thermal-cycle wing and propulsion article | F13: duty requires hidden fleet multiplication | G13: WARRANT-CONSTITUTED
A14: T-HC-2 | B14: MS-HC | C14: HC-A | D14: sparse plume tomography without common autonomy | E14: independent atmospheric state fields | F14: state disagreement prevents attribution | G14: WARRANT-CONSTITUTED
A15: T-HC-3 | B15: MS-HC | C15: HC-A | D15: precision deposition reconstruction | E15: full-scale drop-field metrology | F15: fluid cannot be tied to held edge | G15: WARRANT-CONSTITUTED
A16: T-LF-1 | B16: MS-LF | C16: LF-B | D16: rapid-bore geothermal in uncertain geology | E16: multi-geology bore and circulation field | F16: day-21 output causes drawdown or hazard | G16: WARRANT-CONSTITUTED
A17: T-LF-2 | B17: MS-LF | C17: LF-B | D17: coupled heat-water-brine closure | E17: closed conversion and residual loop | F17: scaling or brine custody breaks service | G17: WARRANT-CONSTITUTED
... A24: T-RT-3 | B24: MS-RT | C24: RT-B | D24: adaptive islanded process control | E24: multi-process production mesh | F24: qualified output/MWh falls below threshold | G24: WARRANT-CONSTITUTED

Sheet Finance
A2: Public reserve allocation and first-wave ceilings
A4: All values are authority reservations in USD billions. Equal station shares contain correlated loss; they are not predicted construction prices.
A6: Public reserve object | B6: Total USD B | C6: Per system | D6: Per station | E6: Per state bay | F6: Per realization
A7: A0 method packages | B7: 1.5 | C7: =B7/Controls!B9 -> 0.25 | D7: =B7/(Controls!B9*Controls!B10) -> 0.083333333 | E7: =B7/(Controls!B9*Controls!B10*Controls!B11) -> 0.020833333 | F7: =B7/(Controls!B9*Controls!B10*Controls!B11*Controls!B12) -> 0.010416667
