Workbook

Sheet Summary
A2: Federated Artifact Estate Topology
A4: Pass 233 decision model. The selected lattice reuses eighteen truth-station sites and survives every modeled single-site or single-region loss.
A6: DECISION: ADOPT FAE-1 AS AN EIGHTEEN-SITE TRIADIC LATTICE
A8: Roots | B8: Existing sites | C8: New sites | D8: Role enclaves | E8: Court seats | F8: Failure worlds | G8: Worlds survived
A9: =Inputs!B7 -> 6 | B9: =COUNTA('Site Lattice'!A7:A24) -> 18 | C9: =Inputs!B14 -> 0 | D9: =COUNTA('Role Enclaves'!A7:A42) -> 36 | E9: =COUNTA('Court Quorum'!A7:A24) -> 18 | F9: =COUNTA('Failure Worlds'!A7:A36) -> 30 | G9: =COUNTIF('Failure Worlds'!L7:L36,"SURVIVE") -> 30
A13: Topology law | B13: Topology law | C13: Topology law | D13: Topology law | E13: Topology law | F13: Topology law | G13: Topology law
A15: 1 | B15: Each root occupies three sites in three different failure domains; no domain contains a complete root.
A16: 2 | B16: Native, Clean and Divergence functions each have an active path and a separately sited standby path.
A17: 3 | B17: Every Root Artifact Court has three distributed seats and requires two seats plus an Exchange witness.
A18: 4 | B18: Six regional Exchange nodes fully mirror public capsules and split protected custody four-of-six.
A19: 5 | B19: One site or one region may fail without losing any root function, court quorum or protected Exchange release capacity.
A20: 6 | B20: Two lost sites in one root, common control, leakage or displaced truth capacity forces HOLD or termination.
A24: Thirty single-loss worlds | B24: Thirty single-loss worlds | C24: Thirty single-loss worlds | D24: Thirty single-loss worlds | E24: Thirty single-loss worlds | F24: Thirty single-loss worlds | G24: Thirty single-loss worlds
A26: Site-loss worlds | B26: 18 | I26: World class | J26: Count
A27: Region-loss worlds | B27: 6 | I27: Site loss | J27: 18
A28: Vendor-exit world | B28: 1 | I28: Region loss | J28: 6
A29: Control and custody compromise worlds | B29: 5 | I29: Vendor exit | J29: 1
A30: Total worlds | B30: 30 | I30: Compromise | J30: 5
A34: Current authority boundary | B34: Current authority boundary | C34: Current authority boundary | D34: Current authority boundary | E34: Current authority boundary | F34: Current authority boundary | G34: Current authority boundary
A36: Named sites | B36: 0 of 18
A37: Named stewards | B37: 0 of 36+
A38: Live keys | B38: 0
A39: Commissioned enclaves | B39: 0 of 36
A40: Artifact validity warrants | B40: 0
A41: Payments and observations | B41: 0 / 0
A42: Selection, MAKE and REP-4 | B42: 0 / 0 / 0
A43: Capital accounting | B43: CO-USE / NO NEW APPROPRIATION

Sheet Inputs
A2: Federated artifact-estate topology inputs
A4: Editable controls are blue. Capital is a co-use ceiling inside the existing public-method reservation; cohort operations remain inside Pass 232.
A6: Constitutional controls | B6: Constitutional controls | C6: Constitutional controls | D6: Constitutional controls
A7: Root count | B7: 6
A8: Sites per root | B8: 3
A9: Failure domains | B9: 6
A10: Court quorum | B10: 2
A11: Role paths per root and function | B11: 2
A12: Exchange release threshold | B12: 4
A13: Exchange regional shares | B13: 6
A14: Maximum new sites | B14: 0
A15: Builder dependency | B15: 0
A16: Current named site identities | B16: 0
A17: Current named stewards | B17: 0
A18: Current live keys | B18: 0
... A26: Tolerance | B26: 1e-06
A29: Existing nested ceilings | B29: Existing nested ceilings | C29: Existing nested ceilings | D29: Existing nested ceilings | E29: Existing nested ceilings | F29: Existing nested ceilings
A31: Account | B31: Ceiling | C31: Use in this topology | D31: Share | E31: Allocated ceiling | F31: Accounting boundary
A32: Public-method replay and cold-run capacity | B32: 540 | C32: Host and failure-domain hardening | D32: 0.35 | E32: =B32*D32 -> 189 | F32: CO-USE / NOT ADDITIVE
A33: Public-method replay and cold-run capacity | B33: 540 | C33: Role-separated enclave compute | D33: 0.25 | E33: =B33*D33 -> 135 | F33: CO-USE / NOT ADDITIVE
A34: Public-method replay and cold-run capacity | B34: 540 | C34: Offline custody and threshold escrow | D34: 0.15 | E34: =B34*D34 -> 81 | F34: CO-USE / NOT ADDITIVE
A35: Public-method replay and cold-run capacity | B35: 540 | C35: Court seats and key ceremony | D35: 0.1 | E35: =B35*D35 -> 54 | F35: CO-USE / NOT ADDITIVE
A36: Public-method replay and cold-run capacity | B36: 540 | C36: Cross-region network and restoration | D36: 0.1 | E36: =B36*D36 -> 54 | F36: CO-USE / NOT ADDITIVE
A37: Public-method replay and cold-run capacity | B37: 540 | C37: Uncommitted recovery reserve | D37: 0.05 | E37: =B37*D37 -> 27 | F37: HELD
A40: Cohort operating accounts from DRG-1 | B40: Cohort operating accounts from DRG-1 | C40: Cohort operating accounts from DRG-1 | D40: Cohort operating accounts from DRG-1 | E40: Cohort operating accounts from DRG-1 | F40: Cohort operating accounts from DRG-1
A42: Account | B42: Ceiling | C42: Function | D42: Share | E42: Function ceiling
A43: Independent reconstruction | B43: 26.905 | C43: Clean-room rebuild cells | D43: 0.55 | E43: =B43*D43 -> 14.79775
A44: Independent reconstruction | B44: 26.905 | C44: Root-native instruments and qualification | D44: 0.25 | E44: =B44*D44 -> 6.72625
A45: Independent reconstruction | B45: 26.905 | C45: Divergence reserve | D45: 0.2 | E45: =B45*D45 -> 5.381
A46: Public source escrow | B46: 14.349333 | C46: Public Artifact Exchange | D46: 0.45 | E46: =B46*D46 -> 6.4572
A47: Public source escrow | B47: 14.349333 | C47: Disconnected archive | D47: 0.3 | E47: =B47*D47 -> 4.3048
A48: Public source escrow | B48: 14.349333 | C48: Cryptographic lineage | D48: 0.15 | E48: =B48*D48 -> 2.1524
A49: Public source escrow | B49: 14.349333 | C49: Semantic kernel stewardship | D49: 0.1 | E49: =B49*D49 -> 1.4349333
A52: Architecture candidates | B52: Architecture candidates | C52: Architecture candidates | D52: Architecture candidates | E52: Architecture candidates | F52: Architecture candidates | G52: Architecture candidates
A54: Candidate | B54: Topology | C54: Sites | D54: Role separation | E54: One-site survival | F54: Common control | G54: Decision
A55: L1 | B55: Single national artifact campus | C55: 1 | D55: 0 | E55: 0 | F55: 1 | G55: REJECT
A56: L2 | B56: Six root monoliths | C56: 6 | D56: 0 | E56: 0 | F56: 0 | G56: REJECT
A57: L3 | B57: Thirty-six dedicated function sites | C57: 36 | D57: 1 | E57: 1 | F57: 0 | G57: REJECT—DUPLICATIVE
A58: L4 | B58: Eighteen-site triadic lattice | C58: 18 | D58: 1 | E58: 1 | F58: 0 | G58: SELECT
A59: L5 | B59: Vendor cloud with public backup | C59: 2 | D59: 0 | E59: 0 | F59: 1 | G59: REJECT

Sheet Site Lattice
A2: Eighteen-site triadic lattice
A4: Each root occupies three different failure domains. Each failure domain hosts three different roots and never an entire truth train.
A6: Site | B6: Root | C6: Form | D6: Failure domain | E6: Root position | F6: Primary role | G6: Standby role | H6: Court seat | I6: Exchange edge | J6: Named identity | K6: Site admitted | L6: Current state | M6: One-site replacement
A7: S01 | B7: ET-A | C7: ET-A-A | D7: FD-A | E7: 1 | F7: Native | G7: Divergence | H7: 1 | I7: 1 | K7: 0 | L7: =IF(AND(J7<>"",K7=1),"ADMITTED","OPEN") -> OPEN | M7: =IF(COUNTIF($B$7:$B$24,B7)=3,"TWO SITES REMAIN","FAIL") -> TWO SITES REMAIN
A8: S02 | B8: ET-A | C8: ET-A-A | D8: FD-C | E8: 2 | F8: Clean | G8: Native | H8: 1 | I8: 1 | K8: 0 | L8: =IF(AND(J8<>"",K8=1),"ADMITTED","OPEN") -> OPEN | M8: =IF(COUNTIF($B$7:$B$24,B8)=3,"TWO SITES REMAIN","FAIL") -> TWO SITES REMAIN
A9: S03 | B9: ET-A | C9: ET-A-A | D9: FD-E | E9: 3 | F9: Divergence | G9: Clean | H9: 1 | I9: 1 | K9: 0 | L9: =IF(AND(J9<>"",K9=1),"ADMITTED","OPEN") -> OPEN | M9: =IF(COUNTIF($B$7:$B$24,B9)=3,"TWO SITES REMAIN","FAIL") -> TWO SITES REMAIN
A10: S04 | B10: CT-C | C10: CT-C-B | D10: FD-B | E10: 1 | F10: Native | G10: Divergence | H10: 1 | I10: 1 | K10: 0 | L10: =IF(AND(J10<>"",K10=1),"ADMITTED","OPEN") -> OPEN | M10: =IF(COUNTIF($B$7:$B$24,B10)=3,"TWO SITES REMAIN","FAIL") -> TWO SITES REMAIN
A11: S05 | B11: CT-C | C11: CT-C-B | D11: FD-D | E11: 2 | F11: Clean | G11: Native | H11: 1 | I11: 1 | K11: 0 | L11: =IF(AND(J11<>"",K11=1),"ADMITTED","OPEN") -> OPEN | M11: =IF(COUNTIF($B$7:$B$24,B11)=3,"TWO SITES REMAIN","FAIL") -> TWO SITES REMAIN
A12: S06 | B12: CT-C | C12: CT-C-B | D12: FD-F | E12: 3 | F12: Divergence | G12: Clean | H12: 1 | I12: 1 | K12: 0 | L12: =IF(AND(J12<>"",K12=1),"ADMITTED","OPEN") -> OPEN | M12: =IF(COUNTIF($B$7:$B$24,B12)=3,"TWO SITES REMAIN","FAIL") -> TWO SITES REMAIN
A13: S07 | B13: HC-A | C13: HC-A-C | D13: FD-A | E13: 1 | F13: Native | G13: Divergence | H13: 1 | I13: 1 | K13: 0 | L13: =IF(AND(J13<>"",K13=1),"ADMITTED","OPEN") -> OPEN | M13: =IF(COUNTIF($B$7:$B$24,B13)=3,"TWO SITES REMAIN","FAIL") -> TWO SITES REMAIN
A14: S08 | B14: HC-A | C14: HC-A-C | D14: FD-D | E14: 2 | F14: Clean | G14: Native | H14: 1 | I14: 1 | K14: 0 | L14: =IF(AND(J14<>"",K14=1),"ADMITTED","OPEN") -> OPEN | M14: =IF(COUNTIF($B$7:$B$24,B14)=3,"TWO SITES REMAIN","FAIL") -> TWO SITES REMAIN
A15: S09 | B15: HC-A | C15: HC-A-C | D15: FD-E | E15: 3 | F15: Divergence | G15: Clean | H15: 1 | I15: 1 | K15: 0 | L15: =IF(AND(J15<>"",K15=1),"ADMITTED","OPEN") -> OPEN | M15: =IF(COUNTIF($B$7:$B$24,B15)=3,"TWO SITES REMAIN","FAIL") -> TWO SITES REMAIN
A16: S10 | B16: LF-B | C16: LF-B-A | D16: FD-B | E16: 1 | F16: Native | G16: Divergence | H16: 1 | I16: 1 | K16: 0 | L16: =IF(AND(J16<>"",K16=1),"ADMITTED","OPEN") -> OPEN | M16: =IF(COUNTIF($B$7:$B$24,B16)=3,"TWO SITES REMAIN","FAIL") -> TWO SITES REMAIN
A17: S11 | B17: LF-B | C17: LF-B-A | D17: FD-C | E17: 2 | F17: Clean | G17: Native | H17: 1 | I17: 1 | K17: 0 | L17: =IF(AND(J17<>"",K17=1),"ADMITTED","OPEN") -> OPEN | M17: =IF(COUNTIF($B$7:$B$24,B17)=3,"TWO SITES REMAIN","FAIL") -> TWO SITES REMAIN
A18: S12 | B18: LF-B | C18: LF-B-A | D18: FD-F | E18: 3 | F18: Divergence | G18: Clean | H18: 1 | I18: 1 | K18: 0 | L18: =IF(AND(J18<>"",K18=1),"ADMITTED","OPEN") -> OPEN | M18: =IF(COUNTIF($B$7:$B$24,B18)=3,"TWO SITES REMAIN","FAIL") -> TWO SITES REMAIN
... A24: S18 | B24: RT-B | C24: RT-B-C | D24: FD-E | E24: 3 | F24: Divergence | G24: Clean | H24: 1 | I24: 1 | K24: 0 | L24: =IF(AND(J24<>"",K24=1),"ADMITTED","OPEN") -> OPEN | M24: =IF(COUNTIF($B$7:$B$24,B24)=3,"TWO SITES REMAIN","FAIL") -> TWO SITES REMAIN

Sheet Role Enclaves
A2: Active and standby reconstruction enclaves
A4: Every root has two separately sited paths for Native, Clean and Divergence functions. Standby activation transfers authority, not personnel or keys.
A6: Enclave | B6: Site | C6: Region | D6: Root | E6: Function | F6: Mode | G6: Control group | H6: Named steward | I6: Live key | J6: Commissioned | K6: Builder dependent | L6: State | M6: Loss role
A7: E01 | B7: S01 | C7: FD-A | D7: ET-A | E7: Native | F7: ACTIVE | G7: ET-A-Native-ACTIVE-S01 | I7: 0 | J7: 0 | K7: 0 | L7: =IF(AND(H7<>"",I7=1,J7=1,K7=0),"READY","OPEN") -> OPEN | M7: =IF(F7="ACTIVE","WARM PATH REMAINS","PRIMARY PATH REMAINS") -> WARM PATH REMAINS
A8: E02 | B8: S01 | C8: FD-A | D8: ET-A | E8: Divergence | F8: STANDBY | G8: ET-A-Divergence-STANDBY-S01 | I8: 0 | J8: 0 | K8: 0 | L8: =IF(AND(H8<>"",I8=1,J8=1,K8=0),"READY","OPEN") -> OPEN | M8: =IF(F8="ACTIVE","WARM PATH REMAINS","PRIMARY PATH REMAINS") -> PRIMARY PATH REMAINS
A9: E03 | B9: S02 | C9: FD-C | D9: ET-A | E9: Clean | F9: ACTIVE | G9: ET-A-Clean-ACTIVE-S02 | I9: 0 | J9: 0 | K9: 0 | L9: =IF(AND(H9<>"",I9=1,J9=1,K9=0),"READY","OPEN") -> OPEN | M9: =IF(F9="ACTIVE","WARM PATH REMAINS","PRIMARY PATH REMAINS") -> WARM PATH REMAINS
A10: E04 | B10: S02 | C10: FD-C | D10: ET-A | E10: Native | F10: STANDBY | G10: ET-A-Native-STANDBY-S02 | I10: 0 | J10: 0 | K10: 0 | L10: =IF(AND(H10<>"",I10=1,J10=1,K10=0),"READY","OPEN") -> OPEN | M10: =IF(F10="ACTIVE","WARM PATH REMAINS","PRIMARY PATH REMAINS") -> PRIMARY PATH REMAINS
A11: E05 | B11: S03 | C11: FD-E | D11: ET-A | E11: Divergence | F11: ACTIVE | G11: ET-A-Divergence-ACTIVE-S03 | I11: 0 | J11: 0 | K11: 0 | L11: =IF(AND(H11<>"",I11=1,J11=1,K11=0),"READY","OPEN") -> OPEN | M11: =IF(F11="ACTIVE","WARM PATH REMAINS","PRIMARY PATH REMAINS") -> WARM PATH REMAINS
A12: E06 | B12: S03 | C12: FD-E | D12: ET-A | E12: Clean | F12: STANDBY | G12: ET-A-Clean-STANDBY-S03 | I12: 0 | J12: 0 | K12: 0 | L12: =IF(AND(H12<>"",I12=1,J12=1,K12=0),"READY","OPEN") -> OPEN | M12: =IF(F12="ACTIVE","WARM PATH REMAINS","PRIMARY PATH REMAINS") -> PRIMARY PATH REMAINS
A13: E07 | B13: S04 | C13: FD-B | D13: CT-C | E13: Native | F13: ACTIVE | G13: CT-C-Native-ACTIVE-S04 | I13: 0 | J13: 0 | K13: 0 | L13: =IF(AND(H13<>"",I13=1,J13=1,K13=0),"READY","OPEN") -> OPEN | M13: =IF(F13="ACTIVE","WARM PATH REMAINS","PRIMARY PATH REMAINS") -> WARM PATH REMAINS
A14: E08 | B14: S04 | C14: FD-B | D14: CT-C | E14: Divergence | F14: STANDBY | G14: CT-C-Divergence-STANDBY-S04 | I14: 0 | J14: 0 | K14: 0 | L14: =IF(AND(H14<>"",I14=1,J14=1,K14=0),"READY","OPEN") -> OPEN | M14: =IF(F14="ACTIVE","WARM PATH REMAINS","PRIMARY PATH REMAINS") -> PRIMARY PATH REMAINS
A15: E09 | B15: S05 | C15: FD-D | D15: CT-C | E15: Clean | F15: ACTIVE | G15: CT-C-Clean-ACTIVE-S05 | I15: 0 | J15: 0 | K15: 0 | L15: =IF(AND(H15<>"",I15=1,J15=1,K15=0),"READY","OPEN") -> OPEN | M15: =IF(F15="ACTIVE","WARM PATH REMAINS","PRIMARY PATH REMAINS") -> WARM PATH REMAINS
A16: E10 | B16: S05 | C16: FD-D | D16: CT-C | E16: Native | F16: STANDBY | G16: CT-C-Native-STANDBY-S05 | I16: 0 | J16: 0 | K16: 0 | L16: =IF(AND(H16<>"",I16=1,J16=1,K16=0),"READY","OPEN") -> OPEN | M16: =IF(F16="ACTIVE","WARM PATH REMAINS","PRIMARY PATH REMAINS") -> PRIMARY PATH REMAINS
A17: E11 | B17: S06 | C17: FD-F | D17: CT-C | E17: Divergence | F17: ACTIVE | G17: CT-C-Divergence-ACTIVE-S06 | I17: 0 | J17: 0 | K17: 0 | L17: =IF(AND(H17<>"",I17=1,J17=1,K17=0),"READY","OPEN") -> OPEN | M17: =IF(F17="ACTIVE","WARM PATH REMAINS","PRIMARY PATH REMAINS") -> WARM PATH REMAINS
A18: E12 | B18: S06 | C18: FD-F | D18: CT-C | E18: Clean | F18: STANDBY | G18: CT-C-Clean-STANDBY-S06 | I18: 0 | J18: 0 | K18: 0 | L18: =IF(AND(H18<>"",I18=1,J18=1,K18=0),"READY","OPEN") -> OPEN | M18: =IF(F18="ACTIVE","WARM PATH REMAINS","PRIMARY PATH REMAINS") -> PRIMARY PATH REMAINS
... A42: E36 | B42: S18 | C42: FD-E | D42: RT-B | E42: Clean | F42: STANDBY | G42: RT-B-Clean-STANDBY-S18 | I42: 0 | J42: 0 | K42: 0 | L42: =IF(AND(H42<>"",I42=1,J42=1,K42=0),"READY","OPEN") -> OPEN | M42: =IF(F42="ACTIVE","WARM PATH REMAINS","PRIMARY PATH REMAINS") -> PRIMARY PATH REMAINS

Sheet Court Quorum
A2: Distributed Root Artifact Courts
A4: A Root Artifact Court is a three-seat legal quorum distributed across the root's three sites. Two seats plus an Exchange witness are required.
A6: Seat | B6: Root | C6: Site | D6: Region | E6: Planned seat | F6: Named adjudicator | G6: Key share | H6: Conflict free | I6: Current ready | J6: Quorum rule | K6: Authority
A7: Q01 | B7: ET-A | C7: S01 | D7: FD-A | E7: 1 | G7: 0 | H7: 0 | I7: =IF(AND(F7<>"",G7=1,H7=1),1,0) -> 0 | J7: =Inputs!$B$10 -> 2 | K7: =IF(I7=1,"SEAT READY","OPEN") -> OPEN
A8: Q02 | B8: ET-A | C8: S02 | D8: FD-C | E8: 1 | G8: 0 | H8: 0 | I8: =IF(AND(F8<>"",G8=1,H8=1),1,0) -> 0 | J8: =Inputs!$B$10 -> 2 | K8: =IF(I8=1,"SEAT READY","OPEN") -> OPEN
A9: Q03 | B9: ET-A | C9: S03 | D9: FD-E | E9: 1 | G9: 0 | H9: 0 | I9: =IF(AND(F9<>"",G9=1,H9=1),1,0) -> 0 | J9: =Inputs!$B$10 -> 2 | K9: =IF(I9=1,"SEAT READY","OPEN") -> OPEN
A10: Q04 | B10: CT-C | C10: S04 | D10: FD-B | E10: 1 | G10: 0 | H10: 0 | I10: =IF(AND(F10<>"",G10=1,H10=1),1,0) -> 0 | J10: =Inputs!$B$10 -> 2 | K10: =IF(I10=1,"SEAT READY","OPEN") -> OPEN
A11: Q05 | B11: CT-C | C11: S05 | D11: FD-D | E11: 1 | G11: 0 | H11: 0 | I11: =IF(AND(F11<>"",G11=1,H11=1),1,0) -> 0 | J11: =Inputs!$B$10 -> 2 | K11: =IF(I11=1,"SEAT READY","OPEN") -> OPEN
A12: Q06 | B12: CT-C | C12: S06 | D12: FD-F | E12: 1 | G12: 0 | H12: 0 | I12: =IF(AND(F12<>"",G12=1,H12=1),1,0) -> 0 | J12: =Inputs!$B$10 -> 2 | K12: =IF(I12=1,"SEAT READY","OPEN") -> OPEN
A13: Q07 | B13: HC-A | C13: S07 | D13: FD-A | E13: 1 | G13: 0 | H13: 0 | I13: =IF(AND(F13<>"",G13=1,H13=1),1,0) -> 0 | J13: =Inputs!$B$10 -> 2 | K13: =IF(I13=1,"SEAT READY","OPEN") -> OPEN
A14: Q08 | B14: HC-A | C14: S08 | D14: FD-D | E14: 1 | G14: 0 | H14: 0 | I14: =IF(AND(F14<>"",G14=1,H14=1),1,0) -> 0 | J14: =Inputs!$B$10 -> 2 | K14: =IF(I14=1,"SEAT READY","OPEN") -> OPEN
A15: Q09 | B15: HC-A | C15: S09 | D15: FD-E | E15: 1 | G15: 0 | H15: 0 | I15: =IF(AND(F15<>"",G15=1,H15=1),1,0) -> 0 | J15: =Inputs!$B$10 -> 2 | K15: =IF(I15=1,"SEAT READY","OPEN") -> OPEN
A16: Q10 | B16: LF-B | C16: S10 | D16: FD-B | E16: 1 | G16: 0 | H16: 0 | I16: =IF(AND(F16<>"",G16=1,H16=1),1,0) -> 0 | J16: =Inputs!$B$10 -> 2 | K16: =IF(I16=1,"SEAT READY","OPEN") -> OPEN
A17: Q11 | B17: LF-B | C17: S11 | D17: FD-C | E17: 1 | G17: 0 | H17: 0 | I17: =IF(AND(F17<>"",G17=1,H17=1),1,0) -> 0 | J17: =Inputs!$B$10 -> 2 | K17: =IF(I17=1,"SEAT READY","OPEN") -> OPEN
A18: Q12 | B18: LF-B | C18: S12 | D18: FD-F | E18: 1 | G18: 0 | H18: 0 | I18: =IF(AND(F18<>"",G18=1,H18=1),1,0) -> 0 | J18: =Inputs!$B$10 -> 2 | K18: =IF(I18=1,"SEAT READY","OPEN") -> OPEN
... A24: Q18 | B24: RT-B | C24: S18 | D24: FD-E | E24: 1 | G24: 0 | H24: 0 | I24: =IF(AND(F24<>"",G24=1,H24=1),1,0) -> 0 | J24: =Inputs!$B$10 -> 2 | K24: =IF(I24=1,"SEAT READY","OPEN") -> OPEN

Sheet Exchange Custody
A2: Six-region Public Artifact Exchange
A4: Public capsules are fully mirrored. Performance and offline archive custody use four-of-six threshold shares; no root or region can release them alone.
A6: Node | B6: Region | C6: Hosted roots | D6: Public mirror | E6: Escrow share | F6: Offline share | G6: Named steward | H6: Live keys | I6: Current ready | J6: Loss world | K6: Shares remaining | L6: Release state
A7: X1 | B7: FD-A | C7: ET-A / HC-A / HU-A | D7: 1 | E7: 1 | F7: 1 | H7: 0 | I7: =IF(AND(G7<>"",H7=1),1,0) -> 0 | J7: LOSS FD-A | K7: =Inputs!$B$13-1 -> 5 | L7: =IF(K7>=Inputs!$B$12,"RELEASE CAPABLE","HOLD") -> RELEASE CAPABLE
A8: X2 | B8: FD-B | C8: CT-C / LF-B / RT-B | D8: 1 | E8: 1 | F8: 1 | H8: 0 | I8: =IF(AND(G8<>"",H8=1),1,0) -> 0 | J8: LOSS FD-B | K8: =Inputs!$B$13-1 -> 5 | L8: =IF(K8>=Inputs!$B$12,"RELEASE CAPABLE","HOLD") -> RELEASE CAPABLE
A9: X3 | B9: FD-C | C9: ET-A / LF-B / RT-B | D9: 1 | E9: 1 | F9: 1 | H9: 0 | I9: =IF(AND(G9<>"",H9=1),1,0) -> 0 | J9: LOSS FD-C | K9: =Inputs!$B$13-1 -> 5 | L9: =IF(K9>=Inputs!$B$12,"RELEASE CAPABLE","HOLD") -> RELEASE CAPABLE
A10: X4 | B10: FD-D | C10: CT-C / HC-A / HU-A | D10: 1 | E10: 1 | F10: 1 | H10: 0 | I10: =IF(AND(G10<>"",H10=1),1,0) -> 0 | J10: LOSS FD-D | K10: =Inputs!$B$13-1 -> 5 | L10: =IF(K10>=Inputs!$B$12,"RELEASE CAPABLE","HOLD") -> RELEASE CAPABLE
A11: X5 | B11: FD-E | C11: ET-A / HC-A / RT-B | D11: 1 | E11: 1 | F11: 1 | H11: 0 | I11: =IF(AND(G11<>"",H11=1),1,0) -> 0 | J11: LOSS FD-E | K11: =Inputs!$B$13-1 -> 5 | L11: =IF(K11>=Inputs!$B$12,"RELEASE CAPABLE","HOLD") -> RELEASE CAPABLE
A12: X6 | B12: FD-F | C12: CT-C / LF-B / HU-A | D12: 1 | E12: 1 | F12: 1 | H12: 0 | I12: =IF(AND(G12<>"",H12=1),1,0) -> 0 | J12: LOSS FD-F | K12: =Inputs!$B$13-1 -> 5 | L12: =IF(K12>=Inputs!$B$12,"RELEASE CAPABLE","HOLD") -> RELEASE CAPABLE

Sheet Failure Worlds
A2: Topology failure worlds
A4: All single-site and single-region losses preserve all three root functions, a two-seat court quorum and at least four Exchange shares.
A6: World | B6: Type | C6: Lost site | D6: Lost region | E6: Compromised role | F6: Vendor exit | G6: Exchange denied | H6: Detail passes | I6: Detail required | J6: Exchange shares | K6: Builder independent | L6: Result
A7: W01 | B7: SITE LOSS | C7: S01 | F7: 0 | G7: 0 | H7: =COUNTIFS('Failure Detail'!$A$7:$A$546,A7,'Failure Detail'!$J$7:$J$546,"PASS") -> 18 | I7: =18 -> 18 | J7: =Inputs!$B$13-G7 -> 6 | K7: =IF(F7+Inputs!$B$15=2,0,1) -> 1 | L7: =IF(H7=I7,IF(J7>=Inputs!$B$12,IF(K7=1,"SURVIVE","FAIL"),"FAIL"),"FAIL") -> SURVIVE
A8: W02 | B8: SITE LOSS | C8: S02 | F8: 0 | G8: 0 | H8: =COUNTIFS('Failure Detail'!$A$7:$A$546,A8,'Failure Detail'!$J$7:$J$546,"PASS") -> 18 | I8: =18 -> 18 | J8: =Inputs!$B$13-G8 -> 6 | K8: =IF(F8+Inputs!$B$15=2,0,1) -> 1 | L8: =IF(H8=I8,IF(J8>=Inputs!$B$12,IF(K8=1,"SURVIVE","FAIL"),"FAIL"),"FAIL") -> SURVIVE
A9: W03 | B9: SITE LOSS | C9: S03 | F9: 0 | G9: 0 | H9: =COUNTIFS('Failure Detail'!$A$7:$A$546,A9,'Failure Detail'!$J$7:$J$546,"PASS") -> 18 | I9: =18 -> 18 | J9: =Inputs!$B$13-G9 -> 6 | K9: =IF(F9+Inputs!$B$15=2,0,1) -> 1 | L9: =IF(H9=I9,IF(J9>=Inputs!$B$12,IF(K9=1,"SURVIVE","FAIL"),"FAIL"),"FAIL") -> SURVIVE
A10: W04 | B10: SITE LOSS | C10: S04 | F10: 0 | G10: 0 | H10: =COUNTIFS('Failure Detail'!$A$7:$A$546,A10,'Failure Detail'!$J$7:$J$546,"PASS") -> 18 | I10: =18 -> 18 | J10: =Inputs!$B$13-G10 -> 6 | K10: =IF(F10+Inputs!$B$15=2,0,1) -> 1 | L10: =IF(H10=I10,IF(J10>=Inputs!$B$12,IF(K10=1,"SURVIVE","FAIL"),"FAIL"),"FAIL") -> SURVIVE
A11: W05 | B11: SITE LOSS | C11: S05 | F11: 0 | G11: 0 | H11: =COUNTIFS('Failure Detail'!$A$7:$A$546,A11,'Failure Detail'!$J$7:$J$546,"PASS") -> 18 | I11: =18 -> 18 | J11: =Inputs!$B$13-G11 -> 6 | K11: =IF(F11+Inputs!$B$15=2,0,1) -> 1 | L11: =IF(H11=I11,IF(J11>=Inputs!$B$12,IF(K11=1,"SURVIVE","FAIL"),"FAIL"),"FAIL") -> SURVIVE
A12: W06 | B12: SITE LOSS | C12: S06 | F12: 0 | G12: 0 | H12: =COUNTIFS('Failure Detail'!$A$7:$A$546,A12,'Failure Detail'!$J$7:$J$546,"PASS") -> 18 | I12: =18 -> 18 | J12: =Inputs!$B$13-G12 -> 6 | K12: =IF(F12+Inputs!$B$15=2,0,1) -> 1 | L12: =IF(H12=I12,IF(J12>=Inputs!$B$12,IF(K12=1,"SURVIVE","FAIL"),"FAIL"),"FAIL") -> SURVIVE
A13: W07 | B13: SITE LOSS | C13: S07 | F13: 0 | G13: 0 | H13: =COUNTIFS('Failure Detail'!$A$7:$A$546,A13,'Failure Detail'!$J$7:$J$546,"PASS") -> 18 | I13: =18 -> 18 | J13: =Inputs!$B$13-G13 -> 6 | K13: =IF(F13+Inputs!$B$15=2,0,1) -> 1 | L13: =IF(H13=I13,IF(J13>=Inputs!$B$12,IF(K13=1,"SURVIVE","FAIL"),"FAIL"),"FAIL") -> SURVIVE
A14: W08 | B14: SITE LOSS | C14: S08 | F14: 0 | G14: 0 | H14: =COUNTIFS('Failure Detail'!$A$7:$A$546,A14,'Failure Detail'!$J$7:$J$546,"PASS") -> 18 | I14: =18 -> 18 | J14: =Inputs!$B$13-G14 -> 6 | K14: =IF(F14+Inputs!$B$15=2,0,1) -> 1 | L14: =IF(H14=I14,IF(J14>=Inputs!$B$12,IF(K14=1,"SURVIVE","FAIL"),"FAIL"),"FAIL") -> SURVIVE
A15: W09 | B15: SITE LOSS | C15: S09 | F15: 0 | G15: 0 | H15: =COUNTIFS('Failure Detail'!$A$7:$A$546,A15,'Failure Detail'!$J$7:$J$546,"PASS") -> 18 | I15: =18 -> 18 | J15: =Inputs!$B$13-G15 -> 6 | K15: =IF(F15+Inputs!$B$15=2,0,1) -> 1 | L15: =IF(H15=I15,IF(J15>=Inputs!$B$12,IF(K15=1,"SURVIVE","FAIL"),"FAIL"),"FAIL") -> SURVIVE
A16: W10 | B16: SITE LOSS | C16: S10 | F16: 0 | G16: 0 | H16: =COUNTIFS('Failure Detail'!$A$7:$A$546,A16,'Failure Detail'!$J$7:$J$546,"PASS") -> 18 | I16: =18 -> 18 | J16: =Inputs!$B$13-G16 -> 6 | K16: =IF(F16+Inputs!$B$15=2,0,1) -> 1 | L16: =IF(H16=I16,IF(J16>=Inputs!$B$12,IF(K16=1,"SURVIVE","FAIL"),"FAIL"),"FAIL") -> SURVIVE
A17: W11 | B17: SITE LOSS | C17: S11 | F17: 0 | G17: 0 | H17: =COUNTIFS('Failure Detail'!$A$7:$A$546,A17,'Failure Detail'!$J$7:$J$546,"PASS") -> 18 | I17: =18 -> 18 | J17: =Inputs!$B$13-G17 -> 6 | K17: =IF(F17+Inputs!$B$15=2,0,1) -> 1 | L17: =IF(H17=I17,IF(J17>=Inputs!$B$12,IF(K17=1,"SURVIVE","FAIL"),"FAIL"),"FAIL") -> SURVIVE
A18: W12 | B18: SITE LOSS | C18: S12 | F18: 0 | G18: 0 | H18: =COUNTIFS('Failure Detail'!$A$7:$A$546,A18,'Failure Detail'!$J$7:$J$546,"PASS") -> 18 | I18: =18 -> 18 | J18: =Inputs!$B$13-G18 -> 6 | K18: =IF(F18+Inputs!$B$15=2,0,1) -> 1 | L18: =IF(H18=I18,IF(J18>=Inputs!$B$12,IF(K18=1,"SURVIVE","FAIL"),"FAIL"),"FAIL") -> SURVIVE
... A24: W18 | B24: SITE LOSS | C24: S18 | F24: 0 | G24: 0 | H24: =COUNTIFS('Failure Detail'!$A$7:$A$546,A24,'Failure Detail'!$J$7:$J$546,"PASS") -> 18 | I24: =18 -> 18 | J24: =Inputs!$B$13-G24 -> 6 | K24: =IF(F24+Inputs!$B$15=2,0,1) -> 1 | L24: =IF(H24=I24,IF(J24>=Inputs!$B$12,IF(K24=1,"SURVIVE","FAIL"),"FAIL"),"FAIL") -> SURVIVE
A25: W19 | B25: REGION LOSS | D25: FD-A | F25: 0 | G25: 1 | H25: =COUNTIFS('Failure Detail'!$A$7:$A$546,A25,'Failure Detail'!$J$7:$J$546,"PASS") -> 18 | I25: =18 -> 18 | J25: =Inputs!$B$13-G25 -> 5 | K25: =IF(F25+Inputs!$B$15=2,0,1) -> 1 | L25: =IF(H25=I25,IF(J25>=Inputs!$B$12,IF(K25=1,"SURVIVE","FAIL"),"FAIL"),"FAIL") -> SURVIVE
A26: W20 | B26: REGION LOSS | D26: FD-B | F26: 0 | G26: 1 | H26: =COUNTIFS('Failure Detail'!$A$7:$A$546,A26,'Failure Detail'!$J$7:$J$546,"PASS") -> 18 | I26: =18 -> 18 | J26: =Inputs!$B$13-G26 -> 5 | K26: =IF(F26+Inputs!$B$15=2,0,1) -> 1 | L26: =IF(H26=I26,IF(J26>=Inputs!$B$12,IF(K26=1,"SURVIVE","FAIL"),"FAIL"),"FAIL") -> SURVIVE
A27: W21 | B27: REGION LOSS | D27: FD-C | F27: 0 | G27: 1 | H27: =COUNTIFS('Failure Detail'!$A$7:$A$546,A27,'Failure Detail'!$J$7:$J$546,"PASS") -> 18 | I27: =18 -> 18 | J27: =Inputs!$B$13-G27 -> 5 | K27: =IF(F27+Inputs!$B$15=2,0,1) -> 1 | L27: =IF(H27=I27,IF(J27>=Inputs!$B$12,IF(K27=1,"SURVIVE","FAIL"),"FAIL"),"FAIL") -> SURVIVE
A28: W22 | B28: REGION LOSS | D28: FD-D | F28: 0 | G28: 1 | H28: =COUNTIFS('Failure Detail'!$A$7:$A$546,A28,'Failure Detail'!$J$7:$J$546,"PASS") -> 18 | I28: =18 -> 18 | J28: =Inputs!$B$13-G28 -> 5 | K28: =IF(F28+Inputs!$B$15=2,0,1) -> 1 | L28: =IF(H28=I28,IF(J28>=Inputs!$B$12,IF(K28=1,"SURVIVE","FAIL"),"FAIL"),"FAIL") -> SURVIVE
A29: W23 | B29: REGION LOSS | D29: FD-E | F29: 0 | G29: 1 | H29: =COUNTIFS('Failure Detail'!$A$7:$A$546,A29,'Failure Detail'!$J$7:$J$546,"PASS") -> 18 | I29: =18 -> 18 | J29: =Inputs!$B$13-G29 -> 5 | K29: =IF(F29+Inputs!$B$15=2,0,1) -> 1 | L29: =IF(H29=I29,IF(J29>=Inputs!$B$12,IF(K29=1,"SURVIVE","FAIL"),"FAIL"),"FAIL") -> SURVIVE
A30: W24 | B30: REGION LOSS | D30: FD-F | F30: 0 | G30: 1 | H30: =COUNTIFS('Failure Detail'!$A$7:$A$546,A30,'Failure Detail'!$J$7:$J$546,"PASS") -> 18 | I30: =18 -> 18 | J30: =Inputs!$B$13-G30 -> 5 | K30: =IF(F30+Inputs!$B$15=2,0,1) -> 1 | L30: =IF(H30=I30,IF(J30>=Inputs!$B$12,IF(K30=1,"SURVIVE","FAIL"),"FAIL"),"FAIL") -> SURVIVE
A31: W25 | B31: VENDOR EXIT | F31: 1 | G31: 0 | H31: =COUNTIFS('Failure Detail'!$A$7:$A$546,A31,'Failure Detail'!$J$7:$J$546,"PASS") -> 18 | I31: =18 -> 18 | J31: =Inputs!$B$13-G31 -> 6 | K31: =IF(F31+Inputs!$B$15=2,0,1) -> 1 | L31: =IF(H31=I31,IF(J31>=Inputs!$B$12,IF(K31=1,"SURVIVE","FAIL"),"FAIL"),"FAIL") -> SURVIVE
A32: W26 | B32: NATIVE ENCLAVE COMPROMISE | E32: Native | F32: 0 | G32: 0 | H32: =COUNTIFS('Failure Detail'!$A$7:$A$546,A32,'Failure Detail'!$J$7:$J$546,"PASS") -> 18 | I32: =18 -> 18 | J32: =Inputs!$B$13-G32 -> 6 | K32: =IF(F32+Inputs!$B$15=2,0,1) -> 1 | L32: =IF(H32=I32,IF(J32>=Inputs!$B$12,IF(K32=1,"SURVIVE","FAIL"),"FAIL"),"FAIL") -> SURVIVE
A33: W27 | B33: CLEAN ENCLAVE COMPROMISE | E33: Clean | F33: 0 | G33: 0 | H33: =COUNTIFS('Failure Detail'!$A$7:$A$546,A33,'Failure Detail'!$J$7:$J$546,"PASS") -> 18 | I33: =18 -> 18 | J33: =Inputs!$B$13-G33 -> 6 | K33: =IF(F33+Inputs!$B$15=2,0,1) -> 1 | L33: =IF(H33=I33,IF(J33>=Inputs!$B$12,IF(K33=1,"SURVIVE","FAIL"),"FAIL"),"FAIL") -> SURVIVE
A34: W28 | B34: DIVERGENCE ENCLAVE COMPROMISE | E34: Divergence | F34: 0 | G34: 0 | H34: =COUNTIFS('Failure Detail'!$A$7:$A$546,A34,'Failure Detail'!$J$7:$J$546,"PASS") -> 18 | I34: =18 -> 18 | J34: =Inputs!$B$13-G34 -> 6 | K34: =IF(F34+Inputs!$B$15=2,0,1) -> 1 | L34: =IF(H34=I34,IF(J34>=Inputs!$B$12,IF(K34=1,"SURVIVE","FAIL"),"FAIL"),"FAIL") -> SURVIVE
A35: W29 | B35: COURT-SEAT COMPROMISE | E35: Court | F35: 0 | G35: 0 | H35: =COUNTIFS('Failure Detail'!$A$7:$A$546,A35,'Failure Detail'!$J$7:$J$546,"PASS") -> 18 | I35: =18 -> 18 | J35: =Inputs!$B$13-G35 -> 6 | K35: =IF(F35+Inputs!$B$15=2,0,1) -> 1 | L35: =IF(H35=I35,IF(J35>=Inputs!$B$12,IF(K35=1,"SURVIVE","FAIL"),"FAIL"),"FAIL") -> SURVIVE
A36: W30 | B36: EXCHANGE-SHARE COMPROMISE | F36: 0 | G36: 1 | H36: =COUNTIFS('Failure Detail'!$A$7:$A$546,A36,'Failure Detail'!$J$7:$J$546,"PASS") -> 18 | I36: =18 -> 18 | J36: =Inputs!$B$13-G36 -> 5 | K36: =IF(F36+Inputs!$B$15=2,0,1) -> 1 | L36: =IF(H36=I36,IF(J36>=Inputs!$B$12,IF(K36=1,"SURVIVE","FAIL"),"FAIL"),"FAIL") -> SURVIVE

Sheet Failure Detail
A2: Root-function survival detail
A4: Each world tests six roots across Native, Clean and Divergence paths. A passing cell also requires two surviving court seats.
A6: World | B6: Root | C6: Function | D6: Lost site | E6: Lost region | F6: Compromised role | G6: Surviving enclaves | H6: Court seats | I6: Required quorum | J6: State
A7: W01 | B7: ET-A | C7: Native | D7: S01 | G7: =COUNTIFS('Role Enclaves'!$D$7:$D$42,B7,'Role Enclaves'!$E$7:$E$42,C7,'Role Enclaves'!$B$7:$B$42,"<>"&D7,'Role Enclaves'!$C$7:$C$42,"<>"&E7)-IF(F7=C7,1,0) -> 1 | H7: =COUNTIFS('Court Quorum'!$B$7:$B$24,B7,'Court Quorum'!$C$7:$C$24,"<>"&D7,'Court Quorum'!$D$7:$D$24,"<>"&E7)-IF(F7="Court",1,0) -> 2 | I7: =Inputs!$B$10 -> 2 | J7: =IF(AND(G7>=1,H7>=I7),"PASS","FAIL") -> PASS
A8: W01 | B8: ET-A | C8: Clean | D8: S01 | G8: =COUNTIFS('Role Enclaves'!$D$7:$D$42,B8,'Role Enclaves'!$E$7:$E$42,C8,'Role Enclaves'!$B$7:$B$42,"<>"&D8,'Role Enclaves'!$C$7:$C$42,"<>"&E8)-IF(F8=C8,1,0) -> 2 | H8: =COUNTIFS('Court Quorum'!$B$7:$B$24,B8,'Court Quorum'!$C$7:$C$24,"<>"&D8,'Court Quorum'!$D$7:$D$24,"<>"&E8)-IF(F8="Court",1,0) -> 2 | I8: =Inputs!$B$10 -> 2 | J8: =IF(AND(G8>=1,H8>=I8),"PASS","FAIL") -> PASS
A9: W01 | B9: ET-A | C9: Divergence | D9: S01 | G9: =COUNTIFS('Role Enclaves'!$D$7:$D$42,B9,'Role Enclaves'!$E$7:$E$42,C9,'Role Enclaves'!$B$7:$B$42,"<>"&D9,'Role Enclaves'!$C$7:$C$42,"<>"&E9)-IF(F9=C9,1,0) -> 1 | H9: =COUNTIFS('Court Quorum'!$B$7:$B$24,B9,'Court Quorum'!$C$7:$C$24,"<>"&D9,'Court Quorum'!$D$7:$D$24,"<>"&E9)-IF(F9="Court",1,0) -> 2 | I9: =Inputs!$B$10 -> 2 | J9: =IF(AND(G9>=1,H9>=I9),"PASS","FAIL") -> PASS
A10: W01 | B10: CT-C | C10: Native | D10: S01 | G10: =COUNTIFS('Role Enclaves'!$D$7:$D$42,B10,'Role Enclaves'!$E$7:$E$42,C10,'Role Enclaves'!$B$7:$B$42,"<>"&D10,'Role Enclaves'!$C$7:$C$42,"<>"&E10)-IF(F10=C10,1,0) -> 2 | H10: =COUNTIFS('Court Quorum'!$B$7:$B$24,B10,'Court Quorum'!$C$7:$C$24,"<>"&D10,'Court Quorum'!$D$7:$D$24,"<>"&E10)-IF(F10="Court",1,0) -> 3 | I10: =Inputs!$B$10 -> 2 | J10: =IF(AND(G10>=1,H10>=I10),"PASS","FAIL") -> PASS
A11: W01 | B11: CT-C | C11: Clean | D11: S01 | G11: =COUNTIFS('Role Enclaves'!$D$7:$D$42,B11,'Role Enclaves'!$E$7:$E$42,C11,'Role Enclaves'!$B$7:$B$42,"<>"&D11,'Role Enclaves'!$C$7:$C$42,"<>"&E11)-IF(F11=C11,1,0) -> 2 | H11: =COUNTIFS('Court Quorum'!$B$7:$B$24,B11,'Court Quorum'!$C$7:$C$24,"<>"&D11,'Court Quorum'!$D$7:$D$24,"<>"&E11)-IF(F11="Court",1,0) -> 3 | I11: =Inputs!$B$10 -> 2 | J11: =IF(AND(G11>=1,H11>=I11),"PASS","FAIL") -> PASS
A12: W01 | B12: CT-C | C12: Divergence | D12: S01 | G12: =COUNTIFS('Role Enclaves'!$D$7:$D$42,B12,'Role Enclaves'!$E$7:$E$42,C12,'Role Enclaves'!$B$7:$B$42,"<>"&D12,'Role Enclaves'!$C$7:$C$42,"<>"&E12)-IF(F12=C12,1,0) -> 2 | H12: =COUNTIFS('Court Quorum'!$B$7:$B$24,B12,'Court Quorum'!$C$7:$C$24,"<>"&D12,'Court Quorum'!$D$7:$D$24,"<>"&E12)-IF(F12="Court",1,0) -> 3 | I12: =Inputs!$B$10 -> 2 | J12: =IF(AND(G12>=1,H12>=I12),"PASS","FAIL") -> PASS
A13: W01 | B13: HC-A | C13: Native | D13: S01 | G13: =COUNTIFS('Role Enclaves'!$D$7:$D$42,B13,'Role Enclaves'!$E$7:$E$42,C13,'Role Enclaves'!$B$7:$B$42,"<>"&D13,'Role Enclaves'!$C$7:$C$42,"<>"&E13)-IF(F13=C13,1,0) -> 2 | H13: =COUNTIFS('Court Quorum'!$B$7:$B$24,B13,'Court Quorum'!$C$7:$C$24,"<>"&D13,'Court Quorum'!$D$7:$D$24,"<>"&E13)-IF(F13="Court",1,0) -> 3 | I13: =Inputs!$B$10 -> 2 | J13: =IF(AND(G13>=1,H13>=I13),"PASS","FAIL") -> PASS
A14: W01 | B14: HC-A | C14: Clean | D14: S01 | G14: =COUNTIFS('Role Enclaves'!$D$7:$D$42,B14,'Role Enclaves'!$E$7:$E$42,C14,'Role Enclaves'!$B$7:$B$42,"<>"&D14,'Role Enclaves'!$C$7:$C$42,"<>"&E14)-IF(F14=C14,1,0) -> 2 | H14: =COUNTIFS('Court Quorum'!$B$7:$B$24,B14,'Court Quorum'!$C$7:$C$24,"<>"&D14,'Court Quorum'!$D$7:$D$24,"<>"&E14)-IF(F14="Court",1,0) -> 3 | I14: =Inputs!$B$10 -> 2 | J14: =IF(AND(G14>=1,H14>=I14),"PASS","FAIL") -> PASS
A15: W01 | B15: HC-A | C15: Divergence | D15: S01 | G15: =COUNTIFS('Role Enclaves'!$D$7:$D$42,B15,'Role Enclaves'!$E$7:$E$42,C15,'Role Enclaves'!$B$7:$B$42,"<>"&D15,'Role Enclaves'!$C$7:$C$42,"<>"&E15)-IF(F15=C15,1,0) -> 2 | H15: =COUNTIFS('Court Quorum'!$B$7:$B$24,B15,'Court Quorum'!$C$7:$C$24,"<>"&D15,'Court Quorum'!$D$7:$D$24,"<>"&E15)-IF(F15="Court",1,0) -> 3 | I15: =Inputs!$B$10 -> 2 | J15: =IF(AND(G15>=1,H15>=I15),"PASS","FAIL") -> PASS
A16: W01 | B16: LF-B | C16: Native | D16: S01 | G16: =COUNTIFS('Role Enclaves'!$D$7:$D$42,B16,'Role Enclaves'!$E$7:$E$42,C16,'Role Enclaves'!$B$7:$B$42,"<>"&D16,'Role Enclaves'!$C$7:$C$42,"<>"&E16)-IF(F16=C16,1,0) -> 2 | H16: =COUNTIFS('Court Quorum'!$B$7:$B$24,B16,'Court Quorum'!$C$7:$C$24,"<>"&D16,'Court Quorum'!$D$7:$D$24,"<>"&E16)-IF(F16="Court",1,0) -> 3 | I16: =Inputs!$B$10 -> 2 | J16: =IF(AND(G16>=1,H16>=I16),"PASS","FAIL") -> PASS
A17: W01 | B17: LF-B | C17: Clean | D17: S01 | G17: =COUNTIFS('Role Enclaves'!$D$7:$D$42,B17,'Role Enclaves'!$E$7:$E$42,C17,'Role Enclaves'!$B$7:$B$42,"<>"&D17,'Role Enclaves'!$C$7:$C$42,"<>"&E17)-IF(F17=C17,1,0) -> 2 | H17: =COUNTIFS('Court Quorum'!$B$7:$B$24,B17,'Court Quorum'!$C$7:$C$24,"<>"&D17,'Court Quorum'!$D$7:$D$24,"<>"&E17)-IF(F17="Court",1,0) -> 3 | I17: =Inputs!$B$10 -> 2 | J17: =IF(AND(G17>=1,H17>=I17),"PASS","FAIL") -> PASS
A18: W01 | B18: LF-B | C18: Divergence | D18: S01 | G18: =COUNTIFS('Role Enclaves'!$D$7:$D$42,B18,'Role Enclaves'!$E$7:$E$42,C18,'Role Enclaves'!$B$7:$B$42,"<>"&D18,'Role Enclaves'!$C$7:$C$42,"<>"&E18)-IF(F18=C18,1,0) -> 2 | H18: =COUNTIFS('Court Quorum'!$B$7:$B$24,B18,'Court Quorum'!$C$7:$C$24,"<>"&D18,'Court Quorum'!$D$7:$D$24,"<>"&E18)-IF(F18="Court",1,0) -> 3 | I18: =Inputs!$B$10 -> 2 | J18: =IF(AND(G18>=1,H18>=I18),"PASS","FAIL") -> PASS
... A330: W18 | B330: RT-B | C330: Divergence | D330: S18 | G330: =COUNTIFS('Role Enclaves'!$D$7:$D$42,B330,'Role Enclaves'!$E$7:$E$42,C330,'Role Enclaves'!$B$7:$B$42,"<>"&D330,'Role Enclaves'!$C$7:$C$42,"<>"&E330)-IF(F330=C330,1,0) -> 1 | H330: =COUNTIFS('Court Quorum'!$B$7:$B$24,B330,'Court Quorum'!$C$7:$C$24,"<>"&D330,'Court Quorum'!$D$7:$D$24,"<>"&E330)-IF(F330="Court",1,0) -> 2 | I330: =Inputs!$B$10 -> 2 | J330: =IF(AND(G330>=1,H330>=I330),"PASS","FAIL") -> PASS
A331: W19 | B331: ET-A | C331: Native | E331: FD-A | G331: =COUNTIFS('Role Enclaves'!$D$7:$D$42,B331,'Role Enclaves'!$E$7:$E$42,C331,'Role Enclaves'!$B$7:$B$42,"<>"&D331,'Role Enclaves'!$C$7:$C$42,"<>"&E331)-IF(F331=C331,1,0) -> 1 | H331: =COUNTIFS('Court Quorum'!$B$7:$B$24,B331,'Court Quorum'!$C$7:$C$24,"<>"&D331,'Court Quorum'!$D$7:$D$24,"<>"&E331)-IF(F331="Court",1,0) -> 2 | I331: =Inputs!$B$10 -> 2 | J331: =IF(AND(G331>=1,H331>=I331),"PASS","FAIL") -> PASS
A332: W19 | B332: ET-A | C332: Clean | E332: FD-A | G332: =COUNTIFS('Role Enclaves'!$D$7:$D$42,B332,'Role Enclaves'!$E$7:$E$42,C332,'Role Enclaves'!$B$7:$B$42,"<>"&D332,'Role Enclaves'!$C$7:$C$42,"<>"&E332)-IF(F332=C332,1,0) -> 2 | H332: =COUNTIFS('Court Quorum'!$B$7:$B$24,B332,'Court Quorum'!$C$7:$C$24,"<>"&D332,'Court Quorum'!$D$7:$D$24,"<>"&E332)-IF(F332="Court",1,0) -> 2 | I332: =Inputs!$B$10 -> 2 | J332: =IF(AND(G332>=1,H332>=I332),"PASS","FAIL") -> PASS
A333: W19 | B333: ET-A | C333: Divergence | E333: FD-A | G333: =COUNTIFS('Role Enclaves'!$D$7:$D$42,B333,'Role Enclaves'!$E$7:$E$42,C333,'Role Enclaves'!$B$7:$B$42,"<>"&D333,'Role Enclaves'!$C$7:$C$42,"<>"&E333)-IF(F333=C333,1,0) -> 1 | H333: =COUNTIFS('Court Quorum'!$B$7:$B$24,B333,'Court Quorum'!$C$7:$C$24,"<>"&D333,'Court Quorum'!$D$7:$D$24,"<>"&E333)-IF(F333="Court",1,0) -> 2 | I333: =Inputs!$B$10 -> 2 | J333: =IF(AND(G333>=1,H333>=I333),"PASS","FAIL") -> PASS
A334: W19 | B334: CT-C | C334: Native | E334: FD-A | G334: =COUNTIFS('Role Enclaves'!$D$7:$D$42,B334,'Role Enclaves'!$E$7:$E$42,C334,'Role Enclaves'!$B$7:$B$42,"<>"&D334,'Role Enclaves'!$C$7:$C$42,"<>"&E334)-IF(F334=C334,1,0) -> 2 | H334: =COUNTIFS('Court Quorum'!$B$7:$B$24,B334,'Court Quorum'!$C$7:$C$24,"<>"&D334,'Court Quorum'!$D$7:$D$24,"<>"&E334)-IF(F334="Court",1,0) -> 3 | I334: =Inputs!$B$10 -> 2 | J334: =IF(AND(G334>=1,H334>=I334),"PASS","FAIL") -> PASS
A335: W19 | B335: CT-C | C335: Clean | E335: FD-A | G335: =COUNTIFS('Role Enclaves'!$D$7:$D$42,B335,'Role Enclaves'!$E$7:$E$42,C335,'Role Enclaves'!$B$7:$B$42,"<>"&D335,'Role Enclaves'!$C$7:$C$42,"<>"&E335)-IF(F335=C335,1,0) -> 2 | H335: =COUNTIFS('Court Quorum'!$B$7:$B$24,B335,'Court Quorum'!$C$7:$C$24,"<>"&D335,'Court Quorum'!$D$7:$D$24,"<>"&E335)-IF(F335="Court",1,0) -> 3 | I335: =Inputs!$B$10 -> 2 | J335: =IF(AND(G335>=1,H335>=I335),"PASS","FAIL") -> PASS
A336: W19 | B336: CT-C | C336: Divergence | E336: FD-A | G336: =COUNTIFS('Role Enclaves'!$D$7:$D$42,B336,'Role Enclaves'!$E$7:$E$42,C336,'Role Enclaves'!$B$7:$B$42,"<>"&D336,'Role Enclaves'!$C$7:$C$42,"<>"&E336)-IF(F336=C336,1,0) -> 2 | H336: =COUNTIFS('Court Quorum'!$B$7:$B$24,B336,'Court Quorum'!$C$7:$C$24,"<>"&D336,'Court Quorum'!$D$7:$D$24,"<>"&E336)-IF(F336="Court",1,0) -> 3 | I336: =Inputs!$B$10 -> 2 | J336: =IF(AND(G336>=1,H336>=I336),"PASS","FAIL") -> PASS
A337: W19 | B337: HC-A | C337: Native | E337: FD-A | G337: =COUNTIFS('Role Enclaves'!$D$7:$D$42,B337,'Role Enclaves'!$E$7:$E$42,C337,'Role Enclaves'!$B$7:$B$42,"<>"&D337,'Role Enclaves'!$C$7:$C$42,"<>"&E337)-IF(F337=C337,1,0) -> 1 | H337: =COUNTIFS('Court Quorum'!$B$7:$B$24,B337,'Court Quorum'!$C$7:$C$24,"<>"&D337,'Court Quorum'!$D$7:$D$24,"<>"&E337)-IF(F337="Court",1,0) -> 2 | I337: =Inputs!$B$10 -> 2 | J337: =IF(AND(G337>=1,H337>=I337),"PASS","FAIL") -> PASS
A338: W19 | B338: HC-A | C338: Clean | E338: FD-A | G338: =COUNTIFS('Role Enclaves'!$D$7:$D$42,B338,'Role Enclaves'!$E$7:$E$42,C338,'Role Enclaves'!$B$7:$B$42,"<>"&D338,'Role Enclaves'!$C$7:$C$42,"<>"&E338)-IF(F338=C338,1,0) -> 2 | H338: =COUNTIFS('Court Quorum'!$B$7:$B$24,B338,'Court Quorum'!$C$7:$C$24,"<>"&D338,'Court Quorum'!$D$7:$D$24,"<>"&E338)-IF(F338="Court",1,0) -> 2 | I338: =Inputs!$B$10 -> 2 | J338: =IF(AND(G338>=1,H338>=I338),"PASS","FAIL") -> PASS
A339: W19 | B339: HC-A | C339: Divergence | E339: FD-A | G339: =COUNTIFS('Role Enclaves'!$D$7:$D$42,B339,'Role Enclaves'!$E$7:$E$42,C339,'Role Enclaves'!$B$7:$B$42,"<>"&D339,'Role Enclaves'!$C$7:$C$42,"<>"&E339)-IF(F339=C339,1,0) -> 1 | H339: =COUNTIFS('Court Quorum'!$B$7:$B$24,B339,'Court Quorum'!$C$7:$C$24,"<>"&D339,'Court Quorum'!$D$7:$D$24,"<>"&E339)-IF(F339="Court",1,0) -> 2 | I339: =Inputs!$B$10 -> 2 | J339: =IF(AND(G339>=1,H339>=I339),"PASS","FAIL") -> PASS
A340: W19 | B340: LF-B | C340: Native | E340: FD-A | G340: =COUNTIFS('Role Enclaves'!$D$7:$D$42,B340,'Role Enclaves'!$E$7:$E$42,C340,'Role Enclaves'!$B$7:$B$42,"<>"&D340,'Role Enclaves'!$C$7:$C$42,"<>"&E340)-IF(F340=C340,1,0) -> 2 | H340: =COUNTIFS('Court Quorum'!$B$7:$B$24,B340,'Court Quorum'!$C$7:$C$24,"<>"&D340,'Court Quorum'!$D$7:$D$24,"<>"&E340)-IF(F340="Court",1,0) -> 3 | I340: =Inputs!$B$10 -> 2 | J340: =IF(AND(G340>=1,H340>=I340),"PASS","FAIL") -> PASS
A341: W19 | B341: LF-B | C341: Clean | E341: FD-A | G341: =COUNTIFS('Role Enclaves'!$D$7:$D$42,B341,'Role Enclaves'!$E$7:$E$42,C341,'Role Enclaves'!$B$7:$B$42,"<>"&D341,'Role Enclaves'!$C$7:$C$42,"<>"&E341)-IF(F341=C341,1,0) -> 2 | H341: =COUNTIFS('Court Quorum'!$B$7:$B$24,B341,'Court Quorum'!$C$7:$C$24,"<>"&D341,'Court Quorum'!$D$7:$D$24,"<>"&E341)-IF(F341="Court",1,0) -> 3 | I341: =Inputs!$B$10 -> 2 | J341: =IF(AND(G341>=1,H341>=I341),"PASS","FAIL") -> PASS
A342: W19 | B342: LF-B | C342: Divergence | E342: FD-A | G342: =COUNTIFS('Role Enclaves'!$D$7:$D$42,B342,'Role Enclaves'!$E$7:$E$42,C342,'Role Enclaves'!$B$7:$B$42,"<>"&D342,'Role Enclaves'!$C$7:$C$42,"<>"&E342)-IF(F342=C342,1,0) -> 2 | H342: =COUNTIFS('Court Quorum'!$B$7:$B$24,B342,'Court Quorum'!$C$7:$C$24,"<>"&D342,'Court Quorum'!$D$7:$D$24,"<>"&E342)-IF(F342="Court",1,0) -> 3 | I342: =Inputs!$B$10 -> 2 | J342: =IF(AND(G342>=1,H342>=I342),"PASS","FAIL") -> PASS
... A438: W24 | B438: RT-B | C438: Divergence | E438: FD-F | G438: =COUNTIFS('Role Enclaves'!$D$7:$D$42,B438,'Role Enclaves'!$E$7:$E$42,C438,'Role Enclaves'!$B$7:$B$42,"<>"&D438,'Role Enclaves'!$C$7:$C$42,"<>"&E438)-IF(F438=C438,1,0) -> 2 | H438: =COUNTIFS('Court Quorum'!$B$7:$B$24,B438,'Court Quorum'!$C$7:$C$24,"<>"&D438,'Court Quorum'!$D$7:$D$24,"<>"&E438)-IF(F438="Court",1,0) -> 3 | I438: =Inputs!$B$10 -> 2 | J438: =IF(AND(G438>=1,H438>=I438),"PASS","FAIL") -> PASS
A439: W25 | B439: ET-A | C439: Native | G439: =COUNTIFS('Role Enclaves'!$D$7:$D$42,B439,'Role Enclaves'!$E$7:$E$42,C439,'Role Enclaves'!$B$7:$B$42,"<>"&D439,'Role Enclaves'!$C$7:$C$42,"<>"&E439)-IF(F439=C439,1,0) -> 2 | H439: =COUNTIFS('Court Quorum'!$B$7:$B$24,B439,'Court Quorum'!$C$7:$C$24,"<>"&D439,'Court Quorum'!$D$7:$D$24,"<>"&E439)-IF(F439="Court",1,0) -> 3 | I439: =Inputs!$B$10 -> 2 | J439: =IF(AND(G439>=1,H439>=I439),"PASS","FAIL") -> PASS
A440: W25 | B440: ET-A | C440: Clean | G440: =COUNTIFS('Role Enclaves'!$D$7:$D$42,B440,'Role Enclaves'!$E$7:$E$42,C440,'Role Enclaves'!$B$7:$B$42,"<>"&D440,'Role Enclaves'!$C$7:$C$42,"<>"&E440)-IF(F440=C440,1,0) -> 2 | H440: =COUNTIFS('Court Quorum'!$B$7:$B$24,B440,'Court Quorum'!$C$7:$C$24,"<>"&D440,'Court Quorum'!$D$7:$D$24,"<>"&E440)-IF(F440="Court",1,0) -> 3 | I440: =Inputs!$B$10 -> 2 | J440: =IF(AND(G440>=1,H440>=I440),"PASS","FAIL") -> PASS
A441: W25 | B441: ET-A | C441: Divergence | G441: =COUNTIFS('Role Enclaves'!$D$7:$D$42,B441,'Role Enclaves'!$E$7:$E$42,C441,'Role Enclaves'!$B$7:$B$42,"<>"&D441,'Role Enclaves'!$C$7:$C$42,"<>"&E441)-IF(F441=C441,1,0) -> 2 | H441: =COUNTIFS('Court Quorum'!$B$7:$B$24,B441,'Court Quorum'!$C$7:$C$24,"<>"&D441,'Court Quorum'!$D$7:$D$24,"<>"&E441)-IF(F441="Court",1,0) -> 3 | I441: =Inputs!$B$10 -> 2 | J441: =IF(AND(G441>=1,H441>=I441),"PASS","FAIL") -> PASS
A442: W25 | B442: CT-C | C442: Native | G442: =COUNTIFS('Role Enclaves'!$D$7:$D$42,B442,'Role Enclaves'!$E$7:$E$42,C442,'Role Enclaves'!$B$7:$B$42,"<>"&D442,'Role Enclaves'!$C$7:$C$42,"<>"&E442)-IF(F442=C442,1,0) -> 2 | H442: =COUNTIFS('Court Quorum'!$B$7:$B$24,B442,'Court Quorum'!$C$7:$C$24,"<>"&D442,'Court Quorum'!$D$7:$D$24,"<>"&E442)-IF(F442="Court",1,0) -> 3 | I442: =Inputs!$B$10 -> 2 | J442: =IF(AND(G442>=1,H442>=I442),"PASS","FAIL") -> PASS
A443: W25 | B443: CT-C | C443: Clean | G443: =COUNTIFS('Role Enclaves'!$D$7:$D$42,B443,'Role Enclaves'!$E$7:$E$42,C443,'Role Enclaves'!$B$7:$B$42,"<>"&D443,'Role Enclaves'!$C$7:$C$42,"<>"&E443)-IF(F443=C443,1,0) -> 2 | H443: =COUNTIFS('Court Quorum'!$B$7:$B$24,B443,'Court Quorum'!$C$7:$C$24,"<>"&D443,'Court Quorum'!$D$7:$D$24,"<>"&E443)-IF(F443="Court",1,0) -> 3 | I443: =Inputs!$B$10 -> 2 | J443: =IF(AND(G443>=1,H443>=I443),"PASS","FAIL") -> PASS
A444: W25 | B444: CT-C | C444: Divergence | G444: =COUNTIFS('Role Enclaves'!$D$7:$D$42,B444,'Role Enclaves'!$E$7:$E$42,C444,'Role Enclaves'!$B$7:$B$42,"<>"&D444,'Role Enclaves'!$C$7:$C$42,"<>"&E444)-IF(F444=C444,1,0) -> 2 | H444: =COUNTIFS('Court Quorum'!$B$7:$B$24,B444,'Court Quorum'!$C$7:$C$24,"<>"&D444,'Court Quorum'!$D$7:$D$24,"<>"&E444)-IF(F444="Court",1,0) -> 3 | I444: =Inputs!$B$10 -> 2 | J444: =IF(AND(G444>=1,H444>=I444),"PASS","FAIL") -> PASS
A445: W25 | B445: HC-A | C445: Native | G445: =COUNTIFS('Role Enclaves'!$D$7:$D$42,B445,'Role Enclaves'!$E$7:$E$42,C445,'Role Enclaves'!$B$7:$B$42,"<>"&D445,'Role Enclaves'!$C$7:$C$42,"<>"&E445)-IF(F445=C445,1,0) -> 2 | H445: =COUNTIFS('Court Quorum'!$B$7:$B$24,B445,'Court Quorum'!$C$7:$C$24,"<>"&D445,'Court Quorum'!$D$7:$D$24,"<>"&E445)-IF(F445="Court",1,0) -> 3 | I445: =Inputs!$B$10 -> 2 | J445: =IF(AND(G445>=1,H445>=I445),"PASS","FAIL") -> PASS
A446: W25 | B446: HC-A | C446: Clean | G446: =COUNTIFS('Role Enclaves'!$D$7:$D$42,B446,'Role Enclaves'!$E$7:$E$42,C446,'Role Enclaves'!$B$7:$B$42,"<>"&D446,'Role Enclaves'!$C$7:$C$42,"<>"&E446)-IF(F446=C446,1,0) -> 2 | H446: =COUNTIFS('Court Quorum'!$B$7:$B$24,B446,'Court Quorum'!$C$7:$C$24,"<>"&D446,'Court Quorum'!$D$7:$D$24,"<>"&E446)-IF(F446="Court",1,0) -> 3 | I446: =Inputs!$B$10 -> 2 | J446: =IF(AND(G446>=1,H446>=I446),"PASS","FAIL") -> PASS
A447: W25 | B447: HC-A | C447: Divergence | G447: =COUNTIFS('Role Enclaves'!$D$7:$D$42,B447,'Role Enclaves'!$E$7:$E$42,C447,'Role Enclaves'!$B$7:$B$42,"<>"&D447,'Role Enclaves'!$C$7:$C$42,"<>"&E447)-IF(F447=C447,1,0) -> 2 | H447: =COUNTIFS('Court Quorum'!$B$7:$B$24,B447,'Court Quorum'!$C$7:$C$24,"<>"&D447,'Court Quorum'!$D$7:$D$24,"<>"&E447)-IF(F447="Court",1,0) -> 3 | I447: =Inputs!$B$10 -> 2 | J447: =IF(AND(G447>=1,H447>=I447),"PASS","FAIL") -> PASS
A448: W25 | B448: LF-B | C448: Native | G448: =COUNTIFS('Role Enclaves'!$D$7:$D$42,B448,'Role Enclaves'!$E$7:$E$42,C448,'Role Enclaves'!$B$7:$B$42,"<>"&D448,'Role Enclaves'!$C$7:$C$42,"<>"&E448)-IF(F448=C448,1,0) -> 2 | H448: =COUNTIFS('Court Quorum'!$B$7:$B$24,B448,'Court Quorum'!$C$7:$C$24,"<>"&D448,'Court Quorum'!$D$7:$D$24,"<>"&E448)-IF(F448="Court",1,0) -> 3 | I448: =Inputs!$B$10 -> 2 | J448: =IF(AND(G448>=1,H448>=I448),"PASS","FAIL") -> PASS
A449: W25 | B449: LF-B | C449: Clean | G449: =COUNTIFS('Role Enclaves'!$D$7:$D$42,B449,'Role Enclaves'!$E$7:$E$42,C449,'Role Enclaves'!$B$7:$B$42,"<>"&D449,'Role Enclaves'!$C$7:$C$42,"<>"&E449)-IF(F449=C449,1,0) -> 2 | H449: =COUNTIFS('Court Quorum'!$B$7:$B$24,B449,'Court Quorum'!$C$7:$C$24,"<>"&D449,'Court Quorum'!$D$7:$D$24,"<>"&E449)-IF(F449="Court",1,0) -> 3 | I449: =Inputs!$B$10 -> 2 | J449: =IF(AND(G449>=1,H449>=I449),"PASS","FAIL") -> PASS
...

Sheet Control Separation
A2: Control and key-separation constitution
A4: Co-location does not merge control. No actor may author, replay, reconstruct, adjudicate, release escrow and pay the same package.
A6: Control | B6: Producer | C6: Forbidden second role | D6: Physical boundary | E6: Key boundary | F6: Current conflict | G6: Disposition | H6: State
A7: C01 | B7: Builder | C7: Native operator | D7: separate enclave | E7: separate keys | F7: 0 | G7: TERMINATE CELL | H7: =IF(F7=0,"PASS","FAIL") -> PASS
A8: C02 | B8: Builder | C8: Clean constructor | D8: separate control | E8: no builder key | F8: 0 | G8: TERMINATE CELL | H8: =IF(F8=0,"PASS","FAIL") -> PASS
A9: C03 | B9: Native operator | C9: Clean constructor | D9: different active site | E9: nonintersecting key sets | F9: 0 | G9: INVALIDATE | H9: =IF(F9=0,"PASS","FAIL") -> PASS
A10: C04 | B10: Native operator | C10: Artifact Court | D10: separate institution | E10: court threshold key | F10: 0 | G10: INVALIDATE | H10: =IF(F10=0,"PASS","FAIL") -> PASS
A11: C05 | B11: Clean constructor | C11: Artifact Court | D11: separate institution | E11: court threshold key | F11: 0 | G11: INVALIDATE | H11: =IF(F11=0,"PASS","FAIL") -> PASS
A12: C06 | B12: Artifact Court | C12: Exchange release | D12: regional threshold | E12: four-of-six key | F12: 0 | G12: HOLD | H12: =IF(F12=0,"PASS","FAIL") -> PASS
A13: C07 | B13: Artifact Court | C13: Finance authority | D13: separate warrant office | E13: no finance technical key | F13: 0 | G13: HOLD | H13: =IF(F13=0,"PASS","FAIL") -> PASS
A14: C08 | B14: Exchange steward | C14: Evidence Court | D14: separate institution | E14: event evidence separate | F14: 0 | G14: HOLD | H14: =IF(F14=0,"PASS","FAIL") -> PASS
A15: C09 | B15: Sibling form cell | C15: Performance escrow | D15: denied network | E15: no decryption share | F15: 0 | G15: TERMINATE CELL | H15: =IF(F15=0,"PASS","FAIL") -> PASS
A16: C10 | B16: Vendor | C16: Recovery authority | D16: public step-in | E16: escrow survives exit | F16: 0 | G16: HOLD | H16: =IF(F16=0,"PASS","FAIL") -> PASS
A17: C11 | B17: Site steward | C17: Court adjudicator | D17: separate employment | E17: separate signing key | F17: 0 | G17: HOLD | H17: =IF(F17=0,"PASS","FAIL") -> PASS
A18: C12 | B18: National office | C18: Root technical owner | D18: no technical ownership | E18: no root execution key | F18: 0 | G18: KILL TOPOLOGY | H18: =IF(F18=0,"PASS","FAIL") -> PASS

Sheet Capacity and Cost
A2: Nested capacity and cost boundary
A4: The selected lattice adds no sites. It overlays the eighteen already-authorized nuclei and cannot displace their physical-proof duties.
A6: Topology counts | B6: Topology counts | C6: Topology counts | D6: Topology counts | E6: Topology counts | F6: Topology counts | G6: Topology counts
A8: Existing sites | B8: 18
A9: New sites | B9: 0
A10: Failure domains | B10: 6
A11: Role enclaves | B11: 36
A12: Court seats | B12: 18
A13: Exchange regional nodes | B13: 6
A14: Public mirrors | B14: 6
A15: Escrow threshold | B15: 4
A16: Single-loss worlds | B16: 30
A19: Capital co-use ceiling (USD millions) | B19: Capital co-use ceiling (USD millions) | C19: Capital co-use ceiling (USD millions) | D19: Capital co-use ceiling (USD millions) | E19: Capital co-use ceiling (USD millions) | F19: Capital co-use ceiling (USD millions)
A21: Function | B21: Allocation | C21: Boundary
A22: =Inputs!C32 -> Host and failure-domain hardening | B22: =Inputs!E32 -> 189 | C22: =Inputs!F32 -> CO-USE / NOT ADDITIVE
A23: =Inputs!C33 -> Role-separated enclave compute | B23: =Inputs!E33 -> 135 | C23: =Inputs!F33 -> CO-USE / NOT ADDITIVE
A24: =Inputs!C34 -> Offline custody and threshold escrow | B24: =Inputs!E34 -> 81 | C24: =Inputs!F34 -> CO-USE / NOT ADDITIVE
A25: =Inputs!C35 -> Court seats and key ceremony | B25: =Inputs!E35 -> 54 | C25: =Inputs!F35 -> CO-USE / NOT ADDITIVE
A26: =Inputs!C36 -> Cross-region network and restoration | B26: =Inputs!E36 -> 54 | C26: =Inputs!F36 -> CO-USE / NOT ADDITIVE
A27: =Inputs!C37 -> Uncommitted recovery reserve | B27: =Inputs!E37 -> 27 | C27: =Inputs!F37 -> HELD
A28: Total | B28: =SUM(B22:B27) -> 540
A31: Cohort operating ceiling (USD millions) | B31: Cohort operating ceiling (USD millions) | C31: Cohort operating ceiling (USD millions) | D31: Cohort operating ceiling (USD millions) | E31: Cohort operating ceiling (USD millions) | F31: Cohort operating ceiling (USD millions)
A33: Function | B33: Allocation
A34: =Inputs!C43 -> Clean-room rebuild cells | B34: =Inputs!E43 -> 14.79775
A35: =Inputs!C44 -> Root-native instruments and qualification | B35: =Inputs!E44 -> 6.72625
A36: =Inputs!C45 -> Divergence reserve | B36: =Inputs!E45 -> 5.381
A37: =Inputs!C46 -> Public Artifact Exchange | B37: =Inputs!E46 -> 6.4572
A38: =Inputs!C47 -> Disconnected archive | B38: =Inputs!E47 -> 4.3048
A39: =Inputs!C48 -> Cryptographic lineage | B39: =Inputs!E48 -> 2.1524
A40: =Inputs!C49 -> Semantic kernel stewardship | B40: =Inputs!E49 -> 1.4349333
A41: Total | B41: =SUM(B34:B40) -> 41.254333

Sheet State Law
A2: Artifact-estate continuity and nonconversion law
A4: Continuity preserves custody and lawful authority. It does not promise uninterrupted acceptance or convert a drill into a valid package.
A6: State | B6: Entry | C6: Permitted action | D6: Forbidden conversion | E6: Loss response | F6: Exit | G6: Authority
A7: PLANNED | B7: Topology selected | C7: register charters | D7: plan to site fact | E7: no effect | F7: IDENTIFIED | G7: Research compact
A8: IDENTIFIED | B8: sites and stewards named | C8: qualify control | D8: identity to independence | E8: revoke identity | F8: SEPARATED | G8: Control registrar
A9: SEPARATED | B9: all control gates pass | C9: issue keys | D9: keys to readiness | E9: rekey | F9: KEYED | G9: Key authority
A10: KEYED | B10: threshold ceremonies complete | C10: commission enclaves | D10: key to artifact validity | E10: destroy compromised share | F10: COMMISSIONED | G10: Commissioning authority
A11: COMMISSIONED | B11: loss drills accepted | C11: accept capsule work | D11: drill to AVW | E11: fail over one role path | F11: AVAILABLE | G11: Artifact Court
A12: AVAILABLE | B12: two-seat quorum and four shares | C12: issue AVW if DRG-1 passes | D12: availability to evidence | E12: hold on second root-site loss | F12: DEGRADED | G12: Artifact Court
A13: DEGRADED | B13: one loss absorbed | C13: continue with alternate paths | D13: degraded state to normal claim | E13: reconstitute before expiry | F13: AVAILABLE | G13: Continuity authority
A14: HELD | B14: quorum or function absent | C14: preserve custody | D14: custody to acceptance | E14: no new AVW | F14: COMMISSIONED | G14: Artifact Court
A15: TERMINATED | B15: common control or leakage | C15: return authority | D15: standby to successor | E15: seal all outputs | F15: PLANNED | G15: Constitution
A16: SUPERSEDED | B16: new epoch accepted | C16: retain lineage | D16: new record to overwrite | E16: archive old epoch | F16: PLANNED | G16: Exchange custodian
A19: Twelve nonconversions | B19: Twelve nonconversions | C19: Twelve nonconversions | D19: Twelve nonconversions | E19: Twelve nonconversions | F19: Twelve nonconversions
A21: Rule | B21: Source | C21: Forbidden result | D21: Required act | E21: Disposition
A22: N01 | B22: Site charter | C22: Site identity | D22: Physical Site Court admission | E22: Open
A23: N02 | B23: Co-location | C23: Common control | D23: Beneficial-control proof | E23: Terminate
A24: N03 | B24: Replica | C24: Independent root | D24: Separate people, keys and ancestry | E24: Invalidate
A25: N04 | B25: Standby | C25: Readiness | D25: Commissioned failover drill | E25: Hold
A26: N05 | B26: Court quorum | C26: Technical truth | D26: DRG-1 reconstruction | E26: Hold
A27: N06 | B27: Exchange threshold | C27: Release authority | D27: Purpose-specific warrant | E27: Hold
A28: N07 | B28: Loss drill | C28: Artifact acceptance | D28: Package-specific AVW | E28: Zero credit
A29: N08 | B29: Vendor exit | C29: Physical evidence | D29: Destructive event | E29: Zero credit
A30: N09 | B30: Public mirror | C30: Performance disclosure | D30: Four-of-six release | E30: Terminate
A31: N10 | B31: Capital co-use | C31: New appropriation | D31: Non-displacement warrant | E31: Hold
A32: N11 | B32: One-site survival | C32: Two-site survival | D32: Reconstitution | E32: Hold
A33: N12 | B33: Availability | C33: Payment or selection | D33: Separate FDW or selection warrant | E33: Zero credit

Sheet Mutations
A2: Controlled mutation register
A4: Each corruption is applied to the live topology, detected by a named terminal audit and restored before export.
A6: Mutation | B6: Target | C6: Baseline | D6: Mutated | E6: Expected audit | F6: Detected | G6: Restored
A7: M01 Root count erosion | B7: Inputs!B7 | C7: 6 | D7: 5 | E7: A01 | F7: YES | G7: YES
A8: M02 Site replication erosion | B8: Inputs!B8 | C8: 3 | D8: 2 | E8: A04 | F8: YES | G8: YES
A9: M03 Region count erosion | B9: Inputs!B9 | C9: 6 | D9: 5 | E9: A03 | F9: YES | G9: YES
A10: M04 Court quorum erosion | B10: Inputs!B10 | C10: 2 | D10: 3 | E10: A22 | F10: YES | G10: YES
A11: M05 Role-path erosion | B11: Inputs!B11 | C11: 2 | D11: 1 | E11: A08 | F11: YES | G11: YES
A12: M06 Exchange threshold inflation | B12: Inputs!B12 | C12: 4 | D12: 6 | E12: A23 | F12: YES | G12: YES
A13: M07 Exchange share erosion | B13: Inputs!B13 | C13: 6 | D13: 5 | E13: A24 | F13: YES | G13: YES
A14: M08 New-site growth | B14: Inputs!B14 | C14: 0 | D14: 1 | E14: A34 | F14: YES | G14: YES
A15: M09 Builder dependency | B15: Inputs!B15 | C15: 0 | D15: 1 | E15: A25 | F15: YES | G15: YES
A16: M10 Named site claim | B16: Inputs!B16 | C16: 0 | D16: 1 | E16: A26 | F16: YES | G16: YES
A17: M11 Steward claim | B17: Inputs!B17 | C17: 0 | D17: 1 | E17: A27 | F17: YES | G17: YES
A18: M12 Live key claim | B18: Inputs!B18 | C18: 0 | D18: 1 | E18: A28 | F18: YES | G18: YES
... A24: M18 Control conflict | B24: Control Separation!F7 | C24: 0 | D24: 1 | E24: A19 | F24: YES | G24: YES

Sheet Audit
A2: Terminal audit
A4: Checks observe the topology and never feed site, role, court, Exchange, finance or artifact states.
A6: Audit | B6: Test | C6: Observed | D6: Expected | E6: Status
A7: A01 | B7: Six roots | C7: =Inputs!B7 -> 6 | D7: 6 | E7: =IF(ABS(C7-D7)<=Inputs!$B$26,"PASS","FAIL") -> PASS
A8: A02 | B8: Eighteen sites | C8: =COUNTA('Site Lattice'!A7:A24) -> 18 | D8: 18 | E8: =IF(ABS(C8-D8)<=Inputs!$B$26,"PASS","FAIL") -> PASS
A9: A03 | B9: Six failure domains | C9: =Inputs!B9 -> 6 | D9: 6 | E9: =IF(ABS(C9-D9)<=Inputs!$B$26,"PASS","FAIL") -> PASS
A10: A04 | B10: Three sites per root control | C10: =Inputs!B8 -> 3 | D10: 3 | E10: =IF(ABS(C10-D10)<=Inputs!$B$26,"PASS","FAIL") -> PASS
A11: A05 | B11: Three ET-A sites | C11: =COUNTIF('Site Lattice'!B7:B24,"ET-A") -> 3 | D11: 3 | E11: =IF(ABS(C11-D11)<=Inputs!$B$26,"PASS","FAIL") -> PASS
A12: A06 | B12: Three roots per FD-A | C12: =COUNTIF('Site Lattice'!D7:D24,"FD-A") -> 3 | D12: 3 | E12: =IF(ABS(C12-D12)<=Inputs!$B$26,"PASS","FAIL") -> PASS
A13: A07 | B13: Thirty-six role enclaves | C13: =COUNTA('Role Enclaves'!A7:A42) -> 36 | D13: 36 | E13: =IF(ABS(C13-D13)<=Inputs!$B$26,"PASS","FAIL") -> PASS
A14: A08 | B14: Two role paths required | C14: =Inputs!B11 -> 2 | D14: 2 | E14: =IF(ABS(C14-D14)<=Inputs!$B$26,"PASS","FAIL") -> PASS
A15: A09 | B15: Twelve Native paths | C15: =COUNTIF('Role Enclaves'!E7:E42,"Native") -> 12 | D15: 12 | E15: =IF(ABS(C15-D15)<=Inputs!$B$26,"PASS","FAIL") -> PASS
A16: A10 | B16: Twelve Clean paths | C16: =COUNTIF('Role Enclaves'!E7:E42,"Clean") -> 12 | D16: 12 | E16: =IF(ABS(C16-D16)<=Inputs!$B$26,"PASS","FAIL") -> PASS
A17: A11 | B17: Twelve Divergence paths | C17: =COUNTIF('Role Enclaves'!E7:E42,"Divergence") -> 12 | D17: 12 | E17: =IF(ABS(C17-D17)<=Inputs!$B$26,"PASS","FAIL") -> PASS
A18: A12 | B18: Eighteen court seats | C18: =COUNTA('Court Quorum'!A7:A24) -> 18 | D18: 18 | E18: =IF(ABS(C18-D18)<=Inputs!$B$26,"PASS","FAIL") -> PASS
A19: A13 | B19: Three seats per ET-A court | C19: =COUNTIF('Court Quorum'!B7:B24,"ET-A") -> 3 | D19: 3 | E19: =IF(ABS(C19-D19)<=Inputs!$B$26,"PASS","FAIL") -> PASS
A20: A14 | B20: Six Exchange nodes | C20: =COUNTA('Exchange Custody'!A7:A12) -> 6 | D20: 6 | E20: =IF(ABS(C20-D20)<=Inputs!$B$26,"PASS","FAIL") -> PASS
A21: A15 | B21: Six public mirrors | C21: =SUM('Exchange Custody'!D7:D12) -> 6 | D21: 6 | E21: =IF(ABS(C21-D21)<=Inputs!$B$26,"PASS","FAIL") -> PASS
A22: A16 | B22: Six escrow shares | C22: =SUM('Exchange Custody'!E7:E12) -> 6 | D22: 6 | E22: =IF(ABS(C22-D22)<=Inputs!$B$26,"PASS","FAIL") -> PASS
A23: A17 | B23: Six offline shares | C23: =SUM('Exchange Custody'!F7:F12) -> 6 | D23: 6 | E23: =IF(ABS(C23-D23)<=Inputs!$B$26,"PASS","FAIL") -> PASS
A24: A18 | B24: Thirty failure worlds | C24: =COUNTA('Failure Worlds'!A7:A36) -> 30 | D24: 30 | E24: =IF(ABS(C24-D24)<=Inputs!$B$26,"PASS","FAIL") -> PASS
A25: A19 | B25: No control conflicts | C25: =COUNTIF('Control Separation'!H7:H18,"FAIL") -> 0 | D25: 0 | E25: =IF(ABS(C25-D25)<=Inputs!$B$26,"PASS","FAIL") -> PASS
A26: A20 | B26: All failure details pass | C26: =COUNTIF('Failure Detail'!J7:J546,"PASS") -> 540 | D26: 540 | E26: =IF(ABS(C26-D26)<=Inputs!$B$26,"PASS","FAIL") -> PASS
A27: A21 | B27: All failure worlds survive | C27: =COUNTIF('Failure Worlds'!L7:L36,"SURVIVE") -> 30 | D27: 30 | E27: =IF(ABS(C27-D27)<=Inputs!$B$26,"PASS","FAIL") -> PASS
A28: A22 | B28: Court quorum is two | C28: =Inputs!B10 -> 2 | D28: 2 | E28: =IF(ABS(C28-D28)<=Inputs!$B$26,"PASS","FAIL") -> PASS
A29: A23 | B29: Exchange threshold is four | C29: =Inputs!B12 -> 4 | D29: 4 | E29: =IF(ABS(C29-D29)<=Inputs!$B$26,"PASS","FAIL") -> PASS
A30: A24 | B30: Exchange shares are six | C30: =Inputs!B13 -> 6 | D30: 6 | E30: =IF(ABS(C30-D30)<=Inputs!$B$26,"PASS","FAIL") -> PASS
A31: A25 | B31: Builder dependency zero | C31: =Inputs!B15 -> 0 | D31: 0 | E31: =IF(ABS(C31-D31)<=Inputs!$B$26,"PASS","FAIL") -> PASS
A32: A26 | B32: Named sites remain zero | C32: =Inputs!B16 -> 0 | D32: 0 | E32: =IF(ABS(C32-D32)<=Inputs!$B$26,"PASS","FAIL") -> PASS
A33: A27 | B33: Named stewards remain zero | C33: =Inputs!B17 -> 0 | D33: 0 | E33: =IF(ABS(C33-D33)<=Inputs!$B$26,"PASS","FAIL") -> PASS
A34: A28 | B34: Live keys remain zero | C34: =Inputs!B18 -> 0 | D34: 0 | E34: =IF(ABS(C34-D34)<=Inputs!$B$26,"PASS","FAIL") -> PASS
A35: A29 | B35: Commissioned enclaves remain zero | C35: =Inputs!B19 -> 0 | D35: 0 | E35: =IF(ABS(C35-D35)<=Inputs!$B$26,"PASS","FAIL") -> PASS
A36: A30 | B36: AVW records remain zero | C36: =Inputs!B20 -> 0 | D36: 0 | E36: =IF(ABS(C36-D36)<=Inputs!$B$26,"PASS","FAIL") -> PASS
A37: A31 | B37: Payments remain zero | C37: =Inputs!B21 -> 0 | D37: 0 | E37: =IF(ABS(C37-D37)<=Inputs!$B$26,"PASS","FAIL") -> PASS
A38: A32 | B38: Observations remain zero | C38: =Inputs!B22 -> 0 | D38: 0 | E38: =IF(ABS(C38-D38)<=Inputs!$B$26,"PASS","FAIL") -> PASS
A39: A33 | B39: Selected forms remain zero | C39: =Inputs!B23 -> 0 | D39: 0 | E39: =IF(ABS(C39-D39)<=Inputs!$B$26,"PASS","FAIL") -> PASS
