Workbook

Sheet Summary
A2: A2C-5 National First Sentinel Construction Compact
A4: Verdict: RETURN. One eighteen-warrant campaign integrates six sentinels, eighteen stations, 102 lots, eighteen site charters and an N-1 bid pool without a master authority. All implementation and evidence states remain empty.
A6: Decision | B6: Result | C6: Unit | D6: State | E6: Why it matters | F6: Current authority | G6: Held conversion | H6: Parent return
A7: integration architecture | B7: warranted construction campaign | C7: architecture | D7: RETURN | E7: integration by typed artifacts, not hierarchy | F7: constitutional compact | G7: compact to execution | H7: six candidate requirements
A8: serial warrants | B8: 18 | C8: count | D8: FROZEN | E8: one producer and acceptor per transition | F8: state machine | G8: warrant to evidence | H8: form-giving loads
A9: selected roots | B9: 6 | C9: count | D9: HOLD | E9: one falsifiable sentinel per system | F9: inquiry only | G9: selection to promise | H9: candidate articles
A10: station nuclei | B10: 18 | C10: count | D10: FROZEN | E10: three epistemic roles per root | F10: functional configuration | G10: station to site | H10: truth infrastructure
A11: construction lots | B11: 102 | C11: count | D11: CONSTITUTED | E11: complete but severable build objects | F11: lot grammar | G11: lot to award | H11: future source records
A12: site charters | B12: 18 | C12: count | D12: CLASS-CONSTITUTED | E12: one nucleus per causal site | F12: class grammar | G12: class to place | H12: future source records
A13: bid positions | B13: 204 | C13: count | D13: OPEN | E13: whole pool must survive one group removal | F13: position grammar | G13: position to bidder | H13: future source records
A14: construction packets | B14: 510 | C14: count | D14: OPEN | E14: as-built evidence remains separate | F14: packet grammar | G14: packet to event | H14: physical records
A15: event packages | B15: 360 | C15: count | D15: SOURCE EMPTY | E15: causal evidence remains separate | F15: event grammar | G15: event to favorable claim | H15: physical events
A16: combined ceiling | B16: 15.586913 | C16: USD B | D16: UNCHANGED | E16: public and private accounts add once | F16: ceiling | G16: ceiling to payment | H16: accepted stages
A17: through MAKE exposure | B17: 10.793456 | C17: USD B | D17: CEILING | E17: bounds pre-event loss | F17: schedule | G17: ceiling to obligation | H17: accepted stages
A18: all-six kill unreleased | B18: 3.5380369 | C18: USD B | D18: PROTECTED | E18: valid failure returns transfer money | F18: schedule | G18: failure to production | H18: root disposition
A19: current awards | B19: 0 | C19: count | D19: HELD | E19: no bidder or site exists | F19: none | G19: slate to contract | H19: external source records
... A22: rendering authority | B22: 0 | C22: count | D22: HELD | E22: form follows controlled loads | F22: none | G22: envelope to exterior | H22: requirement packages
A25: Terminal test | B25: Observed | C25: State
A26: eligible architecture | B26: =COUNTIF(Alternatives!P7:P12,"SELECT") -> 1 | C26: =IF(ABS(B26-1)<0.000001,"PASS","FAIL") -> PASS
A27: warrants | B27: =COUNTA(Warrants!A7:A24) -> 18 | C27: =IF(ABS(B27-18)<0.000001,"PASS","FAIL") -> PASS
A28: lot crosswalk | B28: =COUNTA('Object Crosswalk'!A7:A108) -> 102 | C28: =IF(ABS(B28-102)<0.000001,"PASS","FAIL") -> PASS
A29: construction packets | B29: =COUNTA('Construction Packets'!A7:A516) -> 510 | C29: =IF(ABS(B29-510)<0.000001,"PASS","FAIL") -> PASS
A30: event packages | B30: =COUNTA('Event Evidence'!A7:A366) -> 360 | C30: =IF(ABS(B30-360)<0.000001,"PASS","FAIL") -> PASS
A31: payment stages | B31: =COUNTA('Payment Ledger'!A7:A414) -> 408 | C31: =IF(ABS(B31-408)<0.000001,"PASS","FAIL") -> PASS
A32: authority ceiling | B32: =Finance!E13 -> 15.586913 | C32: =IF(ABS(B32-15.5869128193206)<0.000001,"PASS","FAIL") -> PASS
A33: audit failures | B33: =COUNTIF(Audit!E7:E93,"FAIL") -> 0 | C33: =IF(ABS(B33-0)<0.000001,"PASS","FAIL") -> PASS
A34: awards | B34: =Controls!B34 -> 0 | C34: =IF(ABS(B34-0)<0.000001,"PASS","FAIL") -> PASS
A35: capability | B35: =Controls!B38 -> 0 | C35: =IF(ABS(B35-0)<0.000001,"PASS","FAIL") -> PASS
A36: rendering | B36: =Controls!B40 -> 0 | C36: =IF(ABS(B36-0)<0.000001,"PASS","FAIL") -> PASS

Sheet Controls
A2: Authoritative A2C-5 controls
A4: Blue controls reconcile inherited objects and deliberate zero states. They are not evidence, award or permission to build.
A6: Control | B6: Value | C6: Unit | D6: Authority | E6: Meaning
A7: public construction reserve | B7: 12 | C7: USD B | D7: A2C-3 | E7: inherited or integrated boundary
A8: private candidate options | B8: 3.5869128 | C8: USD B | D8: A2C-1 | E8: inherited or integrated boundary
A9: mission systems | B9: 6 | C9: count | D9: PFP | E9: inherited or integrated boundary
A10: selected roots | B10: 6 | C10: count | D10: A2C-1 | E10: inherited or integrated boundary
A11: endpoints | B11: 12 | C11: count | D11: A2C-1 | E11: inherited or integrated boundary
A12: station nuclei | B12: 18 | C12: count | D12: A2C-2 | E12: inherited or integrated boundary
A13: initial lanes | B13: 36 | C13: count | D13: A2C-2 | E13: inherited or integrated boundary
A14: receiver-state bays | B14: 72 | C14: count | D14: A2C-2 | E14: inherited or integrated boundary
A15: method realizations | B15: 144 | C15: count | D15: A2C-2 | E15: inherited or integrated boundary
A16: regeneration functions | B16: 72 | C16: count | D16: A2C-2 | E16: inherited or integrated boundary
A17: construction lots | B17: 102 | C17: count | D17: A2C-3 | E17: inherited or integrated boundary
A18: minimum control groups | B18: 48 | C18: count | D18: A2C-3 | E18: inherited or integrated boundary
... A40: rendering authority | B40: 0 | C40: count | D40: A2C-5 | E40: source empty or held

Sheet Alternatives
A2: Construction-integration hard-gate test
A4: Only typed artifact succession can integrate the campaign without creating a super-authority or turning administrative completion into physical truth.
A6: Architecture | B6: object conservation | C6: authority separation | D6: typed succession | E6: site independence | F6: industrial separation | G6: whole-slate award | H6: bounded money | I6: valid failure | J6: local rollback | K6: cold return | L6: no capability inference | M6: parent return | N6: Passes | O6: Eligible | P6: Decision
A7: warranted construction campaign | B7: 1 | C7: 1 | D7: 1 | E7: 1 | F7: 1 | G7: 1 | H7: 1 | I7: 1 | J7: 1 | K7: 1 | L7: 1 | M7: 1 | N7: =SUM(B7:M7) -> 12 | O7: =IF(N7=12,"YES","NO") -> YES | P7: =IF(O7="YES","SELECT","REJECT") -> SELECT
A8: one master program baseline | B8: 1 | C8: 0 | D8: 0 | E8: 1 | F8: 0 | G8: 1 | H8: 1 | I8: 1 | J8: 0 | K8: 1 | L8: 0 | M8: 1 | N8: =SUM(B8:M8) -> 7 | O8: =IF(N8=12,"YES","NO") -> NO | P8: =IF(O8="YES","SELECT","REJECT") -> REJECT
A9: central integration office | B9: 1 | C9: 0 | D9: 0 | E9: 1 | F9: 0 | G9: 1 | H9: 1 | I9: 1 | J9: 0 | K9: 1 | L9: 0 | M9: 1 | N9: =SUM(B9:M9) -> 7 | O9: =IF(N9=12,"YES","NO") -> NO | P9: =IF(O9="YES","SELECT","REJECT") -> REJECT
A10: enterprise digital twin | B10: 1 | C10: 0 | D10: 0 | E10: 0 | F10: 0 | G10: 1 | H10: 1 | I10: 0 | J10: 0 | K10: 0 | L10: 0 | M10: 1 | N10: =SUM(B10:M10) -> 4 | O10: =IF(N10=12,"YES","NO") -> NO | P10: =IF(O10="YES","SELECT","REJECT") -> REJECT
A11: four adjacent constitutions | B11: 0 | C11: 1 | D11: 0 | E11: 1 | F11: 1 | G11: 1 | H11: 1 | I11: 1 | J11: 0 | K11: 1 | L11: 1 | M11: 0 | N11: =SUM(B11:M11) -> 8 | O11: =IF(N11=12,"YES","NO") -> NO | P11: =IF(O11="YES","SELECT","REJECT") -> REJECT
A12: sequential station release | B12: 1 | C12: 1 | D12: 1 | E12: 1 | F12: 1 | G12: 0 | H12: 1 | I12: 1 | J12: 1 | K12: 1 | L12: 0 | M12: 0 | N12: =SUM(B12:M12) -> 9 | O12: =IF(N12=12,"YES","NO") -> NO | P12: =IF(O12="YES","SELECT","REJECT") -> REJECT

Sheet Inherited Objects
A2: Conserved objects across the four-pass A2C branch
A4: Counts describe different ontologies. Similar numbers and shared campaigns do not authorize addition, substitution or state conversion.
A6: Layer | B6: Object | C6: Count | D6: Unit | E6: Authority | F6: State | G6: Cannot infer
A7: candidate inquiry | B7: selected sentinels | C7: 6 | D7: roots | E7: A2C-1 | F7: HELD | G7: production preference
A8: candidate inquiry | B8: balance and keystone endpoints | C8: 12 | D8: endpoints | E8: A2C-1 | F8: FROZEN | G8: physical result
A9: physical truth | B9: station nuclei | C9: 18 | D9: stations | E9: A2C-2 | F9: FROZEN | G9: site identity
A10: physical truth | B10: initial active and regeneration lanes | C10: 36 | D10: lanes | E10: A2C-2 | F10: FROZEN | G10: constructed capacity
A11: physical truth | B11: receiver-state bays | C11: 72 | D11: bays | E11: A2C-2 | F11: FROZEN | G11: accepted receiver
A12: physical truth | B12: method realizations | C12: 144 | D12: paths | E12: A2C-2 | F12: HELD | G12: 144 procurements
A13: physical truth | B13: regeneration functions | C13: 72 | D13: functions | E13: A2C-2 | F13: FROZEN | G13: event credit
A14: construction | B14: severable lots | C14: 102 | D14: lots | E14: A2C-3 | F14: CONSTITUTED | G14: award
A15: construction | B15: minimum beneficial-control groups | C15: 48 | D15: groups | E15: A2C-3 | F15: FROZEN | G15: firm identities
A16: construction | B16: construction packets | C16: 510 | D16: packets | E16: A2C-3 | F16: OPEN | G16: event evidence
A17: construction | B17: construction decisions | C17: 714 | D17: decisions | E17: A2C-3 | F17: OPEN | G17: acceptance
A18: site | B18: site charters | C18: 18 | D18: charters | E18: A2C-4 | F18: CLASS-CONSTITUTED | G18: locations
... A28: integration | B28: serial warrants | C28: 18 | D28: warrants | E28: A2C-5 | F28: FROZEN | G28: implementation

Sheet Contradictions
A2: Twelve apparent contradictions closed by the compact
A4: A closed contradiction receives one authoritative interpretation; later work may overturn it only through the supersession record.
A6: ID | B6: Apparent conflict | C6: Closure | D6: Consequence | E6: State
A7: C01 | B7: six candidates versus eighteen stations | C7: each root requires challenge, control and reconstruction | D7: three epistemic roles; not three candidates | E7: CLOSED
A8: C02 | B8: twelve endpoints versus eighteen stations | C8: each endpoint crosses roles and unlike lineages | D8: endpoint count is not station count | E8: CLOSED
A9: C03 | B9: seventy-two cards versus 144 realizations versus thirty-six method lots | C9: two physical lineages per card are bundled into one lineage lot per station | D9: paths are not contracts | E9: CLOSED
A10: C04 | B10: seventy-two regeneration functions versus eighteen lots | C10: four duties form one complete regeneration lot per station | D10: functions are not awards | E10: CLOSED
A11: C05 | B11: 102 lots versus eighteen sites | C11: only station-bearing work shares eighteen charters; candidate and substrate scopes reference them | D11: lots are not locations | E11: CLOSED
A12: C06 | B12: 204 bid positions versus forty-eight control groups | C12: positions are applications; beneficial control is a separate graph | D12: positions are not firms | E12: CLOSED
A13: C07 | B13: six three-site substrate contracts versus one nucleus/site | C13: contract packaging does not authorize co-location or common technical control | D13: economic bundle is not physical site | E13: CLOSED
A14: C08 | B14: 510 construction packets versus 360 event packages | C14: construction proves as-built state; events prove causal performance | D14: evidence types never substitute | E14: CLOSED
A15: C09 | B15: 714 construction, 216 site and 2,856 bid decisions | C15: each gate family has a distinct object and authority | D15: decisions are not pooled scores | E15: CLOSED
A16: C10 | B16: site admission before award | C16: access fitness creates no construction or commercial preference | D16: site fact is not award | E16: CLOSED
A17: C11 | B17: valid candidate failure with valuable public estate | C17: adverse evidence disposes root while truth train remains reusable | D17: failure is a program product | E17: CLOSED
A18: C12 | B18: USD 12.0B public plus USD 3.59B private | C18: two exclusive accounts sum once to the USD 15.6B ceiling | D18: nested values are not re-added | E18: CLOSED

Sheet Object Crosswalk
A2: One hundred two lot-to-campaign crosswalk records
A4: Every lot maps to one role in the campaign while shared site, packet, bid and payment references retain their own ledgers.
A6: Lot | B6: Class | C6: Funding | D6: System | E6: Root | F6: Role | G6: Station scope | H6: Site scope | I6: Ceiling USD B | J6: Construction packets | K6: Construction gates | L6: Bid positions | M6: Payment stages | N6: Site identity | O6: Firm identity | P6: Award | Q6: Obligation USD B | R6: Payment USD B | S6: Capability | T6: State
A7: SUB-01 | B7: Civil substrate | C7: Public | D7: MULTI | E7: — | F7: ROTATED | G7: 3-SITE PACKAGE | H7: 3 CHARTERS | I7: 0.12 | J7: 5 | K7: 7 | L7: 2 | M7: 4 | N7: SOURCE EMPTY | O7: SOURCE EMPTY | P7: =Controls!B34 -> 0 | Q7: =Controls!B35 -> 0 | R7: =Controls!B36 -> 0 | S7: =Controls!B38 -> 0 | T7: =IF(P7=1,"AWARDED","CONSTITUTED") -> CONSTITUTED
A8: SUB-02 | B8: Civil substrate | C8: Public | D8: MULTI | E8: — | F8: ROTATED | G8: 3-SITE PACKAGE | H8: 3 CHARTERS | I8: 0.12 | J8: 5 | K8: 7 | L8: 2 | M8: 4 | N8: SOURCE EMPTY | O8: SOURCE EMPTY | P8: =Controls!B34 -> 0 | Q8: =Controls!B35 -> 0 | R8: =Controls!B36 -> 0 | S8: =Controls!B38 -> 0 | T8: =IF(P8=1,"AWARDED","CONSTITUTED") -> CONSTITUTED
A9: SUB-03 | B9: Civil substrate | C9: Public | D9: MULTI | E9: — | F9: ROTATED | G9: 3-SITE PACKAGE | H9: 3 CHARTERS | I9: 0.12 | J9: 5 | K9: 7 | L9: 2 | M9: 4 | N9: SOURCE EMPTY | O9: SOURCE EMPTY | P9: =Controls!B34 -> 0 | Q9: =Controls!B35 -> 0 | R9: =Controls!B36 -> 0 | S9: =Controls!B38 -> 0 | T9: =IF(P9=1,"AWARDED","CONSTITUTED") -> CONSTITUTED
A10: SUB-04 | B10: Civil substrate | C10: Public | D10: MULTI | E10: — | F10: ROTATED | G10: 3-SITE PACKAGE | H10: 3 CHARTERS | I10: 0.12 | J10: 5 | K10: 7 | L10: 2 | M10: 4 | N10: SOURCE EMPTY | O10: SOURCE EMPTY | P10: =Controls!B34 -> 0 | Q10: =Controls!B35 -> 0 | R10: =Controls!B36 -> 0 | S10: =Controls!B38 -> 0 | T10: =IF(P10=1,"AWARDED","CONSTITUTED") -> CONSTITUTED
A11: SUB-05 | B11: Civil substrate | C11: Public | D11: MULTI | E11: — | F11: ROTATED | G11: 3-SITE PACKAGE | H11: 3 CHARTERS | I11: 0.12 | J11: 5 | K11: 7 | L11: 2 | M11: 4 | N11: SOURCE EMPTY | O11: SOURCE EMPTY | P11: =Controls!B34 -> 0 | Q11: =Controls!B35 -> 0 | R11: =Controls!B36 -> 0 | S11: =Controls!B38 -> 0 | T11: =IF(P11=1,"AWARDED","CONSTITUTED") -> CONSTITUTED
A12: SUB-06 | B12: Civil substrate | C12: Public | D12: MULTI | E12: — | F12: ROTATED | G12: 3-SITE PACKAGE | H12: 3 CHARTERS | I12: 0.12 | J12: 5 | K12: 7 | L12: 2 | M12: 4 | N12: SOURCE EMPTY | O12: SOURCE EMPTY | P12: =Controls!B34 -> 0 | Q12: =Controls!B35 -> 0 | R12: =Controls!B36 -> 0 | S12: =Controls!B38 -> 0 | T12: =IF(P12=1,"AWARDED","CONSTITUTED") -> CONSTITUTED
A13: RIG-ET-CHA | B13: Root-native rig | C13: Public | D13: MS-ET | E13: ET-A | F13: CHALLENGE | G13: ST-ET-CHA | H13: CHR-ET-CHA | I13: 0.31666667 | J13: 5 | K13: 7 | L13: 2 | M13: 4 | N13: SOURCE EMPTY | O13: SOURCE EMPTY | P13: =Controls!B34 -> 0 | Q13: =Controls!B35 -> 0 | R13: =Controls!B36 -> 0 | S13: =Controls!B38 -> 0 | T13: =IF(P13=1,"AWARDED","CONSTITUTED") -> CONSTITUTED
A14: MTH-ET-CHA-L1 | B14: Method lineage | C14: Public | D14: MS-ET | E14: ET-A | F14: CHALLENGE | G14: ST-ET-CHA | H14: CHR-ET-CHA | I14: 0.09 | J14: 5 | K14: 7 | L14: 2 | M14: 4 | N14: SOURCE EMPTY | O14: SOURCE EMPTY | P14: =Controls!B34 -> 0 | Q14: =Controls!B35 -> 0 | R14: =Controls!B36 -> 0 | S14: =Controls!B38 -> 0 | T14: =IF(P14=1,"AWARDED","CONSTITUTED") -> CONSTITUTED
A15: MTH-ET-CHA-L2 | B15: Method lineage | C15: Public | D15: MS-ET | E15: ET-A | F15: CHALLENGE | G15: ST-ET-CHA | H15: CHR-ET-CHA | I15: 0.09 | J15: 5 | K15: 7 | L15: 2 | M15: 4 | N15: SOURCE EMPTY | O15: SOURCE EMPTY | P15: =Controls!B34 -> 0 | Q15: =Controls!B35 -> 0 | R15: =Controls!B36 -> 0 | S15: =Controls!B38 -> 0 | T15: =IF(P15=1,"AWARDED","CONSTITUTED") -> CONSTITUTED
A16: REG-ET-CHA | B16: Regeneration tool | C16: Public | D16: MS-ET | E16: ET-A | F16: CHALLENGE | G16: ST-ET-CHA | H16: CHR-ET-CHA | I16: 0.066666667 | J16: 5 | K16: 7 | L16: 2 | M16: 4 | N16: SOURCE EMPTY | O16: SOURCE EMPTY | P16: =Controls!B34 -> 0 | Q16: =Controls!B35 -> 0 | R16: =Controls!B36 -> 0 | S16: =Controls!B38 -> 0 | T16: =IF(P16=1,"AWARDED","CONSTITUTED") -> CONSTITUTED
A17: INT-ET-CHA | B17: Station integration | C17: Public | D17: MS-ET | E17: ET-A | F17: CHALLENGE | G17: ST-ET-CHA | H17: CHR-ET-CHA | I17: 0.063333333 | J17: 5 | K17: 7 | L17: 2 | M17: 4 | N17: SOURCE EMPTY | O17: SOURCE EMPTY | P17: =Controls!B34 -> 0 | Q17: =Controls!B35 -> 0 | R17: =Controls!B36 -> 0 | S17: =Controls!B38 -> 0 | T17: =IF(P17=1,"AWARDED","CONSTITUTED") -> CONSTITUTED
A18: RIG-ET-CON | B18: Root-native rig | C18: Public | D18: MS-ET | E18: ET-A | F18: CONTROL | G18: ST-ET-CON | H18: CHR-ET-CON | I18: 0.31666667 | J18: 5 | K18: 7 | L18: 2 | M18: 4 | N18: SOURCE EMPTY | O18: SOURCE EMPTY | P18: =Controls!B34 -> 0 | Q18: =Controls!B35 -> 0 | R18: =Controls!B36 -> 0 | S18: =Controls!B38 -> 0 | T18: =IF(P18=1,"AWARDED","CONSTITUTED") -> CONSTITUTED
A19: MTH-ET-CON-L1 | B19: Method lineage | C19: Public | D19: MS-ET | E19: ET-A | F19: CONTROL | G19: ST-ET-CON | H19: CHR-ET-CON | I19: 0.09 | J19: 5 | K19: 7 | L19: 2 | M19: 4 | N19: SOURCE EMPTY | O19: SOURCE EMPTY | P19: =Controls!B34 -> 0 | Q19: =Controls!B35 -> 0 | R19: =Controls!B36 -> 0 | S19: =Controls!B38 -> 0 | T19: =IF(P19=1,"AWARDED","CONSTITUTED") -> CONSTITUTED
A20: MTH-ET-CON-L2 | B20: Method lineage | C20: Public | D20: MS-ET | E20: ET-A | F20: CONTROL | G20: ST-ET-CON | H20: CHR-ET-CON | I20: 0.09 | J20: 5 | K20: 7 | L20: 2 | M20: 4 | N20: SOURCE EMPTY | O20: SOURCE EMPTY | P20: =Controls!B34 -> 0 | Q20: =Controls!B35 -> 0 | R20: =Controls!B36 -> 0 | S20: =Controls!B38 -> 0 | T20: =IF(P20=1,"AWARDED","CONSTITUTED") -> CONSTITUTED
A21: REG-ET-CON | B21: Regeneration tool | C21: Public | D21: MS-ET | E21: ET-A | F21: CONTROL | G21: ST-ET-CON | H21: CHR-ET-CON | I21: 0.066666667 | J21: 5 | K21: 7 | L21: 2 | M21: 4 | N21: SOURCE EMPTY | O21: SOURCE EMPTY | P21: =Controls!B34 -> 0 | Q21: =Controls!B35 -> 0 | R21: =Controls!B36 -> 0 | S21: =Controls!B38 -> 0 | T21: =IF(P21=1,"AWARDED","CONSTITUTED") -> CONSTITUTED
A22: INT-ET-CON | B22: Station integration | C22: Public | D22: MS-ET | E22: ET-A | F22: CONTROL | G22: ST-ET-CON | H22: CHR-ET-CON | I22: 0.063333333 | J22: 5 | K22: 7 | L22: 2 | M22: 4 | N22: SOURCE EMPTY | O22: SOURCE EMPTY | P22: =Controls!B34 -> 0 | Q22: =Controls!B35 -> 0 | R22: =Controls!B36 -> 0 | S22: =Controls!B38 -> 0 | T22: =IF(P22=1,"AWARDED","CONSTITUTED") -> CONSTITUTED
A23: RIG-ET-REC | B23: Root-native rig | C23: Public | D23: MS-ET | E23: ET-A | F23: RECONSTRUCTION | G23: ST-ET-REC | H23: CHR-ET-REC | I23: 0.31666667 | J23: 5 | K23: 7 | L23: 2 | M23: 4 | N23: SOURCE EMPTY | O23: SOURCE EMPTY | P23: =Controls!B34 -> 0 | Q23: =Controls!B35 -> 0 | R23: =Controls!B36 -> 0 | S23: =Controls!B38 -> 0 | T23: =IF(P23=1,"AWARDED","CONSTITUTED") -> CONSTITUTED
A24: MTH-ET-REC-L1 | B24: Method lineage | C24: Public | D24: MS-ET | E24: ET-A | F24: RECONSTRUCTION | G24: ST-ET-REC | H24: CHR-ET-REC | I24: 0.09 | J24: 5 | K24: 7 | L24: 2 | M24: 4 | N24: SOURCE EMPTY | O24: SOURCE EMPTY | P24: =Controls!B34 -> 0 | Q24: =Controls!B35 -> 0 | R24: =Controls!B36 -> 0 | S24: =Controls!B38 -> 0 | T24: =IF(P24=1,"AWARDED","CONSTITUTED") -> CONSTITUTED
A25: MTH-ET-REC-L2 | B25: Method lineage | C25: Public | D25: MS-ET | E25: ET-A | F25: RECONSTRUCTION | G25: ST-ET-REC | H25: CHR-ET-REC | I25: 0.09 | J25: 5 | K25: 7 | L25: 2 | M25: 4 | N25: SOURCE EMPTY | O25: SOURCE EMPTY | P25: =Controls!B34 -> 0 | Q25: =Controls!B35 -> 0 | R25: =Controls!B36 -> 0 | S25: =Controls!B38 -> 0 | T25: =IF(P25=1,"AWARDED","CONSTITUTED") -> CONSTITUTED
A26: REG-ET-REC | B26: Regeneration tool | C26: Public | D26: MS-ET | E26: ET-A | F26: RECONSTRUCTION | G26: ST-ET-REC | H26: CHR-ET-REC | I26: 0.066666667 | J26: 5 | K26: 7 | L26: 2 | M26: 4 | N26: SOURCE EMPTY | O26: SOURCE EMPTY | P26: =Controls!B34 -> 0 | Q26: =Controls!B35 -> 0 | R26: =Controls!B36 -> 0 | S26: =Controls!B38 -> 0 | T26: =IF(P26=1,"AWARDED","CONSTITUTED") -> CONSTITUTED
A27: INT-ET-REC | B27: Station integration | C27: Public | D27: MS-ET | E27: ET-A | F27: RECONSTRUCTION | G27: ST-ET-REC | H27: CHR-ET-REC | I27: 0.063333333 | J27: 5 | K27: 7 | L27: 2 | M27: 4 | N27: SOURCE EMPTY | O27: SOURCE EMPTY | P27: =Controls!B34 -> 0 | Q27: =Controls!B35 -> 0 | R27: =Controls!B36 -> 0 | S27: =Controls!B38 -> 0 | T27: =IF(P27=1,"AWARDED","CONSTITUTED") -> CONSTITUTED
A28: RIG-CT-CHA | B28: Root-native rig | C28: Public | D28: MS-CT | E28: CT-C | F28: CHALLENGE | G28: ST-CT-CHA | H28: CHR-CT-CHA | I28: 0.31666667 | J28: 5 | K28: 7 | L28: 2 | M28: 4 | N28: SOURCE EMPTY | O28: SOURCE EMPTY | P28: =Controls!B34 -> 0 | Q28: =Controls!B35 -> 0 | R28: =Controls!B36 -> 0 | S28: =Controls!B38 -> 0 | T28: =IF(P28=1,"AWARDED","CONSTITUTED") -> CONSTITUTED
A29: MTH-CT-CHA-L1 | B29: Method lineage | C29: Public | D29: MS-CT | E29: CT-C | F29: CHALLENGE | G29: ST-CT-CHA | H29: CHR-CT-CHA | I29: 0.09 | J29: 5 | K29: 7 | L29: 2 | M29: 4 | N29: SOURCE EMPTY | O29: SOURCE EMPTY | P29: =Controls!B34 -> 0 | Q29: =Controls!B35 -> 0 | R29: =Controls!B36 -> 0 | S29: =Controls!B38 -> 0 | T29: =IF(P29=1,"AWARDED","CONSTITUTED") -> CONSTITUTED
A30: MTH-CT-CHA-L2 | B30: Method lineage | C30: Public | D30: MS-CT | E30: CT-C | F30: CHALLENGE | G30: ST-CT-CHA | H30: CHR-CT-CHA | I30: 0.09 | J30: 5 | K30: 7 | L30: 2 | M30: 4 | N30: SOURCE EMPTY | O30: SOURCE EMPTY | P30: =Controls!B34 -> 0 | Q30: =Controls!B35 -> 0 | R30: =Controls!B36 -> 0 | S30: =Controls!B38 -> 0 | T30: =IF(P30=1,"AWARDED","CONSTITUTED") -> CONSTITUTED
A31: REG-CT-CHA | B31: Regeneration tool | C31: Public | D31: MS-CT | E31: CT-C | F31: CHALLENGE | G31: ST-CT-CHA | H31: CHR-CT-CHA | I31: 0.066666667 | J31: 5 | K31: 7 | L31: 2 | M31: 4 | N31: SOURCE EMPTY | O31: SOURCE EMPTY | P31: =Controls!B34 -> 0 | Q31: =Controls!B35 -> 0 | R31: =Controls!B36 -> 0 | S31: =Controls!B38 -> 0 | T31: =IF(P31=1,"AWARDED","CONSTITUTED") -> CONSTITUTED
A32: INT-CT-CHA | B32: Station integration | C32: Public | D32: MS-CT | E32: CT-C | F32: CHALLENGE | G32: ST-CT-CHA | H32: CHR-CT-CHA | I32: 0.063333333 | J32: 5 | K32: 7 | L32: 2 | M32: 4 | N32: SOURCE EMPTY | O32: SOURCE EMPTY | P32: =Controls!B34 -> 0 | Q32: =Controls!B35 -> 0 | R32: =Controls!B36 -> 0 | S32: =Controls!B38 -> 0 | T32: =IF(P32=1,"AWARDED","CONSTITUTED") -> CONSTITUTED
A33: RIG-CT-CON | B33: Root-native rig | C33: Public | D33: MS-CT | E33: CT-C | F33: CONTROL | G33: ST-CT-CON | H33: CHR-CT-CON | I33: 0.31666667 | J33: 5 | K33: 7 | L33: 2 | M33: 4 | N33: SOURCE EMPTY | O33: SOURCE EMPTY | P33: =Controls!B34 -> 0 | Q33: =Controls!B35 -> 0 | R33: =Controls!B36 -> 0 | S33: =Controls!B38 -> 0 | T33: =IF(P33=1,"AWARDED","CONSTITUTED") -> CONSTITUTED
A34: MTH-CT-CON-L1 | B34: Method lineage | C34: Public | D34: MS-CT | E34: CT-C | F34: CONTROL | G34: ST-CT-CON | H34: CHR-CT-CON | I34: 0.09 | J34: 5 | K34: 7 | L34: 2 | M34: 4 | N34: SOURCE EMPTY | O34: SOURCE EMPTY | P34: =Controls!B34 -> 0 | Q34: =Controls!B35 -> 0 | R34: =Controls!B36 -> 0 | S34: =Controls!B38 -> 0 | T34: =IF(P34=1,"AWARDED","CONSTITUTED") -> CONSTITUTED
A35: MTH-CT-CON-L2 | B35: Method lineage | C35: Public | D35: MS-CT | E35: CT-C | F35: CONTROL | G35: ST-CT-CON | H35: CHR-CT-CON | I35: 0.09 | J35: 5 | K35: 7 | L35: 2 | M35: 4 | N35: SOURCE EMPTY | O35: SOURCE EMPTY | P35: =Controls!B34 -> 0 | Q35: =Controls!B35 -> 0 | R35: =Controls!B36 -> 0 | S35: =Controls!B38 -> 0 | T35: =IF(P35=1,"AWARDED","CONSTITUTED") -> CONSTITUTED
A36: REG-CT-CON | B36: Regeneration tool | C36: Public | D36: MS-CT | E36: CT-C | F36: CONTROL | G36: ST-CT-CON | H36: CHR-CT-CON | I36: 0.066666667 | J36: 5 | K36: 7 | L36: 2 | M36: 4 | N36: SOURCE EMPTY | O36: SOURCE EMPTY | P36: =Controls!B34 -> 0 | Q36: =Controls!B35 -> 0 | R36: =Controls!B36 -> 0 | S36: =Controls!B38 -> 0 | T36: =IF(P36=1,"AWARDED","CONSTITUTED") -> CONSTITUTED
A37: INT-CT-CON | B37: Station integration | C37: Public | D37: MS-CT | E37: CT-C | F37: CONTROL | G37: ST-CT-CON | H37: CHR-CT-CON | I37: 0.063333333 | J37: 5 | K37: 7 | L37: 2 | M37: 4 | N37: SOURCE EMPTY | O37: SOURCE EMPTY | P37: =Controls!B34 -> 0 | Q37: =Controls!B35 -> 0 | R37: =Controls!B36 -> 0 | S37: =Controls!B38 -> 0 | T37: =IF(P37=1,"AWARDED","CONSTITUTED") -> CONSTITUTED
A38: RIG-CT-REC | B38: Root-native rig | C38: Public | D38: MS-CT | E38: CT-C | F38: RECONSTRUCTION | G38: ST-CT-REC | H38: CHR-CT-REC | I38: 0.31666667 | J38: 5 | K38: 7 | L38: 2 | M38: 4 | N38: SOURCE EMPTY | O38: SOURCE EMPTY | P38: =Controls!B34 -> 0 | Q38: =Controls!B35 -> 0 | R38: =Controls!B36 -> 0 | S38: =Controls!B38 -> 0 | T38: =IF(P38=1,"AWARDED","CONSTITUTED") -> CONSTITUTED
A39: MTH-CT-REC-L1 | B39: Method lineage | C39: Public | D39: MS-CT | E39: CT-C | F39: RECONSTRUCTION | G39: ST-CT-REC | H39: CHR-CT-REC | I39: 0.09 | J39: 5 | K39: 7 | L39: 2 | M39: 4 | N39: SOURCE EMPTY | O39: SOURCE EMPTY | P39: =Controls!B34 -> 0 | Q39: =Controls!B35 -> 0 | R39: =Controls!B36 -> 0 | S39: =Controls!B38 -> 0 | T39: =IF(P39=1,"AWARDED","CONSTITUTED") -> CONSTITUTED
A40: MTH-CT-REC-L2 | B40: Method lineage | C40: Public | D40: MS-CT | E40: CT-C | F40: RECONSTRUCTION | G40: ST-CT-REC | H40: CHR-CT-REC | I40: 0.09 | J40: 5 | K40: 7 | L40: 2 | M40: 4 | N40: SOURCE EMPTY | O40: SOURCE EMPTY | P40: =Controls!B34 -> 0 | Q40: =Controls!B35 -> 0 | R40: =Controls!B36 -> 0 | S40: =Controls!B38 -> 0 | T40: =IF(P40=1,"AWARDED","CONSTITUTED") -> CONSTITUTED
A41: REG-CT-REC | B41: Regeneration tool | C41: Public | D41: MS-CT | E41: CT-C | F41: RECONSTRUCTION | G41: ST-CT-REC | H41: CHR-CT-REC | I41: 0.066666667 | J41: 5 | K41: 7 | L41: 2 | M41: 4 | N41: SOURCE EMPTY | O41: SOURCE EMPTY | P41: =Controls!B34 -> 0 | Q41: =Controls!B35 -> 0 | R41: =Controls!B36 -> 0 | S41: =Controls!B38 -> 0 | T41: =IF(P41=1,"AWARDED","CONSTITUTED") -> CONSTITUTED
A42: INT-CT-REC | B42: Station integration | C42: Public | D42: MS-CT | E42: CT-C | F42: RECONSTRUCTION | G42: ST-CT-REC | H42: CHR-CT-REC | I42: 0.063333333 | J42: 5 | K42: 7 | L42: 2 | M42: 4 | N42: SOURCE EMPTY | O42: SOURCE EMPTY | P42: =Controls!B34 -> 0 | Q42: =Controls!B35 -> 0 | R42: =Controls!B36 -> 0 | S42: =Controls!B38 -> 0 | T42: =IF(P42=1,"AWARDED","CONSTITUTED") -> CONSTITUTED
A43: RIG-HC-CHA | B43: Root-native rig | C43: Public | D43: MS-HC | E43: HC-A | F43: CHALLENGE | G43: ST-HC-CHA | H43: CHR-HC-CHA | I43: 0.31666667 | J43: 5 | K43: 7 | L43: 2 | M43: 4 | N43: SOURCE EMPTY | O43: SOURCE EMPTY | P43: =Controls!B34 -> 0 | Q43: =Controls!B35 -> 0 | R43: =Controls!B36 -> 0 | S43: =Controls!B38 -> 0 | T43: =IF(P43=1,"AWARDED","CONSTITUTED") -> CONSTITUTED
...

Sheet Warrants
A2: Eighteen serial construction warrants
A4: Integration is artifact succession. A receiving authority obtains one bounded record, never the producer's power.
A6: Warrant | B6: State | C6: Artifact | D6: Producer | E6: Acceptor / consumer | F6: Next state | G6: Current value | H6: Expiry or rollback
A7: W01 | B7: NEED | C7: public-service deficit and noncompensatory vector | D7: Civic requirement authority | E7: Root portfolio court | F7: SENTINEL | G7: NEED | H7: same-scope return; no forward inference
A8: W02 | B8: SENTINEL | C8: one deliberately fragile root per system | D8: Root portfolio court | E8: Public method authority | F8: METHOD | G8: ROOT HOLD | H8: same-scope return; no forward inference
A9: W03 | B9: METHOD | C9: receiver states, endpoints and denial grammar | D9: Public method authority | E9: Proving Service | F9: RIG | G9: METHOD FROZEN | H9: same-scope return; no forward inference
A10: W04 | B10: RIG | C10: root-native truth train and station configuration | D10: Proving Service | E10: Industrial constitution | F10: LOT | G10: RIG FROZEN | H10: same-scope return; no forward inference
A11: W05 | B11: LOT | C11: 102 severable construction objects and ceilings | D11: Industrial constitution | E11: Site stewardship authority | F11: SITE CLASS | G11: LOT CONSTITUTED | H11: same-scope return; no forward inference
A12: W06 | B12: SITE CLASS | C12: eighteen source-independent causal envelopes | D12: Site stewardship authority | E12: Physical Site Court | F12: SITE ADMISSION | G12: CLASS CONSTITUTED | H12: same-scope return; no forward inference
A13: W07 | B13: SITE ADMISSION | C13: named rights, conditions and causal independence | D13: Physical Site Court | E13: Technical bid panel | F13: TECHNICAL ADMISSION | G13: SOURCE EMPTY | H13: source absent
A14: W08 | B14: TECHNICAL ADMISSION | C14: pseudonymous complete-lot method | D14: Technical bid panel | E14: Control registrar | F14: CONTROL ADMISSION | G14: SOURCE EMPTY | H14: source absent
A15: W09 | B15: CONTROL ADMISSION | C15: ownership, debt, subtier, tool, key and personnel graph | D15: Control registrar | E15: Optimization custodian | F15: SLATE PROOF | G15: SOURCE EMPTY | H15: source absent
A16: W10 | B16: SLATE PROOF | C16: complete primary slate plus forty-eight N-1 solves | D16: Optimization custodian | E16: Comptroller | F16: PRICE ADMISSION | G16: OPEN | H16: same-scope return; no forward inference
A17: W11 | B17: PRICE ADMISSION | C17: lot-local sealed price within ceiling | D17: Comptroller | E17: Award authority | F17: AWARD | G17: SOURCE EMPTY | H17: source absent
... A24: W18 | B24: TRANSFER RETURN | C24: accepted technical record returned to parent portfolio | D24: Evidence Court | E24: Root portfolio court | F24: FORM-GIVING REQUIREMENT | G24: HELD | H24: same-scope return; no forward inference

Sheet State Machine
A2: Eighteen-state construction campaign
A4: Only NEED through SITE CLASS are presently constituted or frozen. Every identity-, award- and evidence-bearing state remains blocked or source empty.
A6: Order | B6: Warrant | C6: State | D6: Current artifact | E6: Transition state | F6: Required predecessor | G6: Successor | H6: Physical observation? | I6: Capability credit | J6: Nonconversion
A7: 1 | B7: W01 | C7: NEED | D7: NEED | E7: CONSTITUTED | F7: parent need warrant | G7: SENTINEL | H7: NO | I7: 0 | J7: NO FORWARD INFERENCE
A8: 2 | B8: W02 | C8: SENTINEL | D8: ROOT HOLD | E8: BLOCKED | F8: NEED | G8: METHOD | H8: NO | I8: 0 | J8: NO FORWARD INFERENCE
A9: 3 | B9: W03 | C9: METHOD | D9: METHOD FROZEN | E9: BLOCKED | F9: SENTINEL | G9: RIG | H9: NO | I9: 0 | J9: NO FORWARD INFERENCE
A10: 4 | B10: W04 | C10: RIG | D10: RIG FROZEN | E10: BLOCKED | F10: METHOD | G10: LOT | H10: NO | I10: 0 | J10: NO FORWARD INFERENCE
A11: 5 | B11: W05 | C11: LOT | D11: LOT CONSTITUTED | E11: BLOCKED | F11: RIG | G11: SITE CLASS | H11: NO | I11: 0 | J11: NO FORWARD INFERENCE
A12: 6 | B12: W06 | C12: SITE CLASS | D12: CLASS CONSTITUTED | E12: BLOCKED | F12: LOT | G12: SITE ADMISSION | H12: NO | I12: 0 | J12: NO FORWARD INFERENCE
A13: 7 | B13: W07 | C13: SITE ADMISSION | D13: SOURCE EMPTY | E13: BLOCKED | F13: SITE CLASS | G13: TECHNICAL ADMISSION | H13: NO | I13: 0 | J13: NO FORWARD INFERENCE
A14: 8 | B14: W08 | C14: TECHNICAL ADMISSION | D14: SOURCE EMPTY | E14: BLOCKED | F14: SITE ADMISSION | G14: CONTROL ADMISSION | H14: NO | I14: 0 | J14: NO FORWARD INFERENCE
A15: 9 | B15: W09 | C15: CONTROL ADMISSION | D15: SOURCE EMPTY | E15: BLOCKED | F15: TECHNICAL ADMISSION | G15: SLATE PROOF | H15: NO | I15: 0 | J15: NO FORWARD INFERENCE
A16: 10 | B16: W10 | C16: SLATE PROOF | D16: OPEN | E16: BLOCKED | F16: CONTROL ADMISSION | G16: PRICE ADMISSION | H16: NO | I16: 0 | J16: NO FORWARD INFERENCE
A17: 11 | B17: W11 | C17: PRICE ADMISSION | D17: SOURCE EMPTY | E17: BLOCKED | F17: SLATE PROOF | G17: AWARD | H17: NO | I17: 0 | J17: NO FORWARD INFERENCE
A18: 12 | B18: W12 | C18: AWARD | D18: HELD | E18: BLOCKED | F18: PRICE ADMISSION | G18: FRAME | H18: NO | I18: 0 | J18: NO FORWARD INFERENCE
... A24: 18 | B24: W18 | C24: TRANSFER RETURN | D24: HELD | E24: BLOCKED | F24: COLD RETURN | G24: FORM-GIVING REQUIREMENT | H24: NO | I24: 0 | J24: NO FORWARD INFERENCE

Sheet Release Graph
A2: Seventeen typed handoffs between warrants
A4: Every edge is one-way and typed. Return moves to a named predecessor; it does not transfer authority upstream or downstream.
A6: Edge | B6: From | C6: To | D6: Transferred artifact | E6: Receiver may do | F6: Receiver may not do | G6: Rollback target | H6: State
A7: E01 | B7: NEED | C7: SENTINEL | D7: public-service deficit and noncompensatory vector | E7: test or consume only for SENTINEL | F7: rewrite NEED or manufacture METHOD | G7: NEED | H7: FROZEN
A8: E02 | B8: SENTINEL | C8: METHOD | D8: one deliberately fragile root per system | E8: test or consume only for METHOD | F8: rewrite SENTINEL or manufacture RIG | G8: SENTINEL | H8: FROZEN
A9: E03 | B9: METHOD | C9: RIG | D9: receiver states, endpoints and denial grammar | E9: test or consume only for RIG | F9: rewrite METHOD or manufacture LOT | G9: METHOD | H9: FROZEN
A10: E04 | B10: RIG | C10: LOT | D10: root-native truth train and station configuration | E10: test or consume only for LOT | F10: rewrite RIG or manufacture SITE CLASS | G10: RIG | H10: FROZEN
A11: E05 | B11: LOT | C11: SITE CLASS | D11: 102 severable construction objects and ceilings | E11: test or consume only for SITE CLASS | F11: rewrite LOT or manufacture SITE ADMISSION | G11: LOT | H11: FROZEN
A12: E06 | B12: SITE CLASS | C12: SITE ADMISSION | D12: eighteen source-independent causal envelopes | E12: test or consume only for SITE ADMISSION | F12: rewrite SITE CLASS or manufacture TECHNICAL ADMISSION | G12: SITE CLASS | H12: FROZEN
A13: E07 | B13: SITE ADMISSION | C13: TECHNICAL ADMISSION | D13: named rights, conditions and causal independence | E13: test or consume only for TECHNICAL ADMISSION | F13: rewrite SITE ADMISSION or manufacture CONTROL ADMISSION | G13: SITE ADMISSION | H13: HELD
A14: E08 | B14: TECHNICAL ADMISSION | C14: CONTROL ADMISSION | D14: pseudonymous complete-lot method | E14: test or consume only for CONTROL ADMISSION | F14: rewrite TECHNICAL ADMISSION or manufacture SLATE PROOF | G14: TECHNICAL ADMISSION | H14: HELD
A15: E09 | B15: CONTROL ADMISSION | C15: SLATE PROOF | D15: ownership, debt, subtier, tool, key and personnel graph | E15: test or consume only for SLATE PROOF | F15: rewrite CONTROL ADMISSION or manufacture PRICE ADMISSION | G15: CONTROL ADMISSION | H15: HELD
A16: E10 | B16: SLATE PROOF | C16: PRICE ADMISSION | D16: complete primary slate plus forty-eight N-1 solves | E16: test or consume only for PRICE ADMISSION | F16: rewrite SLATE PROOF or manufacture AWARD | G16: SLATE PROOF | H16: HELD
A17: E11 | B17: PRICE ADMISSION | C17: AWARD | D17: lot-local sealed price within ceiling | E17: test or consume only for AWARD | F17: rewrite PRICE ADMISSION or manufacture FRAME | G17: PRICE ADMISSION | H17: HELD
... A23: E17 | B23: COLD RETURN | C23: TRANSFER RETURN | D23: outside-team rebuild, calibration and replay | E23: test or consume only for TRANSFER RETURN | F23: rewrite COLD RETURN or manufacture FORM-GIVING REQUIREMENT | G23: COLD RETURN | H23: HELD

Sheet Authority Matrix
A2: Sixteen authorities across eighteen warrants
A4: CREATE and ACCEPT remain distinct. All other cells are NONE; no authority acquires a universal view or override through integration.
A6: Authority | B6: W01 | C6: W02 | D6: W03 | E6: W04 | F6: W05 | G6: W06 | H6: W07 | I6: W08 | J6: W09 | K6: W10 | L6: W11 | M6: W12 | N6: W13 | O6: W14 | P6: W15 | Q6: W16 | R6: W17 | S6: W18 | T6: Create count
A7: Civic requirement authority | B7: CREATE | C7: NONE | D7: NONE | E7: NONE | F7: NONE | G7: NONE | H7: NONE | I7: NONE | J7: NONE | K7: NONE | L7: NONE | M7: NONE | N7: NONE | O7: NONE | P7: NONE | Q7: NONE | R7: NONE | S7: NONE | T7: =COUNTIF(B7:S7,"CREATE") -> 1
A8: Root portfolio court | B8: ACCEPT | C8: CREATE | D8: NONE | E8: NONE | F8: NONE | G8: NONE | H8: NONE | I8: NONE | J8: NONE | K8: NONE | L8: NONE | M8: NONE | N8: NONE | O8: NONE | P8: NONE | Q8: NONE | R8: NONE | S8: ACCEPT | T8: =COUNTIF(B8:S8,"CREATE") -> 1
A9: Public method authority | B9: NONE | C9: ACCEPT | D9: CREATE | E9: NONE | F9: NONE | G9: NONE | H9: NONE | I9: NONE | J9: NONE | K9: NONE | L9: NONE | M9: NONE | N9: NONE | O9: NONE | P9: NONE | Q9: NONE | R9: NONE | S9: NONE | T9: =COUNTIF(B9:S9,"CREATE") -> 1
A10: Proving Service | B10: NONE | C10: NONE | D10: ACCEPT | E10: CREATE | F10: NONE | G10: NONE | H10: NONE | I10: NONE | J10: NONE | K10: NONE | L10: NONE | M10: NONE | N10: NONE | O10: NONE | P10: NONE | Q10: NONE | R10: NONE | S10: NONE | T10: =COUNTIF(B10:S10,"CREATE") -> 1
A11: Industrial constitution | B11: NONE | C11: NONE | D11: NONE | E11: ACCEPT | F11: CREATE | G11: NONE | H11: NONE | I11: NONE | J11: NONE | K11: NONE | L11: NONE | M11: NONE | N11: NONE | O11: NONE | P11: NONE | Q11: NONE | R11: NONE | S11: NONE | T11: =COUNTIF(B11:S11,"CREATE") -> 1
A12: Site stewardship authority | B12: NONE | C12: NONE | D12: NONE | E12: NONE | F12: ACCEPT | G12: CREATE | H12: NONE | I12: NONE | J12: NONE | K12: NONE | L12: NONE | M12: NONE | N12: NONE | O12: NONE | P12: NONE | Q12: NONE | R12: NONE | S12: NONE | T12: =COUNTIF(B12:S12,"CREATE") -> 1
A13: Physical Site Court | B13: NONE | C13: NONE | D13: NONE | E13: NONE | F13: NONE | G13: ACCEPT | H13: CREATE | I13: NONE | J13: NONE | K13: NONE | L13: NONE | M13: NONE | N13: NONE | O13: NONE | P13: NONE | Q13: NONE | R13: NONE | S13: NONE | T13: =COUNTIF(B13:S13,"CREATE") -> 1
A14: Technical bid panel | B14: NONE | C14: NONE | D14: NONE | E14: NONE | F14: NONE | G14: NONE | H14: ACCEPT | I14: CREATE | J14: NONE | K14: NONE | L14: NONE | M14: NONE | N14: NONE | O14: NONE | P14: NONE | Q14: NONE | R14: NONE | S14: NONE | T14: =COUNTIF(B14:S14,"CREATE") -> 1
A15: Control registrar | B15: NONE | C15: NONE | D15: NONE | E15: NONE | F15: NONE | G15: NONE | H15: NONE | I15: ACCEPT | J15: CREATE | K15: NONE | L15: NONE | M15: NONE | N15: NONE | O15: NONE | P15: NONE | Q15: NONE | R15: NONE | S15: NONE | T15: =COUNTIF(B15:S15,"CREATE") -> 1
A16: Optimization custodian | B16: NONE | C16: NONE | D16: NONE | E16: NONE | F16: NONE | G16: NONE | H16: NONE | I16: NONE | J16: ACCEPT | K16: CREATE | L16: NONE | M16: NONE | N16: NONE | O16: NONE | P16: NONE | Q16: NONE | R16: NONE | S16: NONE | T16: =COUNTIF(B16:S16,"CREATE") -> 1
A17: Comptroller | B17: NONE | C17: NONE | D17: NONE | E17: NONE | F17: NONE | G17: NONE | H17: NONE | I17: NONE | J17: NONE | K17: ACCEPT | L17: CREATE | M17: NONE | N17: NONE | O17: NONE | P17: NONE | Q17: NONE | R17: NONE | S17: NONE | T17: =COUNTIF(B17:S17,"CREATE") -> 1
A18: Award authority | B18: NONE | C18: NONE | D18: NONE | E18: NONE | F18: NONE | G18: NONE | H18: NONE | I18: NONE | J18: NONE | K18: NONE | L18: ACCEPT | M18: CREATE | N18: NONE | O18: NONE | P18: NONE | Q18: NONE | R18: NONE | S18: NONE | T18: =COUNTIF(B18:S18,"CREATE") -> 1
... A22: Cold reconstruction authority | B22: NONE | C22: NONE | D22: NONE | E22: NONE | F22: NONE | G22: NONE | H22: NONE | I22: NONE | J22: NONE | K22: NONE | L22: NONE | M22: NONE | N22: NONE | O22: NONE | P22: NONE | Q22: ACCEPT | R22: CREATE | S22: NONE | T22: =COUNTIF(B22:S22,"CREATE") -> 1

Sheet Nonconversions
A2: Eighteen prohibited state conversions
A4: A nonconversion is an enforceable denial rule, not explanatory prose. Its violation rolls back the claiming state.
A6: ID | B6: False conversion | C6: Why invalid | D6: Required intervening warrant | E6: Violation response | F6: State
A7: N01 | B7: selection → promise | C7: sentinel is chosen for falsifiability, not production merit | D7: ROOT DISPOSITION | E7: hold claim | F7: FROZEN
A8: N02 | B8: method → observation | C8: a protocol contains no physical fact | D8: EVENT VALIDITY | E8: reject claim | F8: FROZEN
A9: N03 | B9: configuration → article | C9: paper geometry has no as-built identity | D9: MAKE | E9: reject claim | F9: FROZEN
A10: N04 | B10: lot → award | C10: a procurement object has no winner | D10: AWARD | E10: reject claim | F10: FROZEN
A11: N05 | B11: site class → place | C11: a causal envelope names no land | D11: SITE ADMISSION | E11: reject claim | F11: FROZEN
A12: N06 | B12: distance → independence | C12: mileage cannot expose shared causal ancestry | D12: SITE ADMISSION | E12: repeat basin proof | F12: FROZEN
A13: N07 | B13: bid position → bidder | C13: a required slot is not a submission | D13: TECHNICAL ADMISSION | E13: reject claim | F13: FROZEN
A14: N08 | B14: two bids → N-1 resilience | C14: slot depth does not prove whole-pool recomposition | D14: SLATE PROOF | E14: repeat solve | F14: FROZEN
A15: N09 | B15: low price → admission | C15: money cannot cure technical or control failure | D15: PRICE ADMISSION | E15: reject bid | F15: FROZEN
A16: N10 | B16: provisional → contract | C16: pre-effect selection creates no entitlement | D16: AWARD | E16: revoke without liability | F16: FROZEN
A17: N11 | B17: obligation → acceptance | C17: fund reservation contains no accepted artifact | D17: FRAME or MAKE | E17: hold payment | F17: FROZEN
... A24: N18 | B24: functional envelope → exterior | C24: form remains unselected until article requirements close | D24: FORM-GIVING REQUIREMENT | E24: hold rendering | F24: FROZEN

Sheet Construction Packets
A2: Five hundred ten construction packet references
A4: Construction packets prove configuration and as-built state. They cannot satisfy event-evidence packages.
A6: Packet | B6: Lot | C6: Class | D6: System | E6: Root | F6: Role | G6: Packet type | H6: Source identity | I6: Accepted | J6: Event substitute? | K6: State
A7: ="PKT-"&B7&"-CONFIGURATION" -> PKT-SUB-01-CONFIGURATION | B7: ='Object Crosswalk'!A7 -> SUB-01 | C7: ='Object Crosswalk'!B7 -> Civil substrate | D7: ='Object Crosswalk'!D7 -> MULTI | E7: ='Object Crosswalk'!E7 -> — | F7: ='Object Crosswalk'!F7 -> ROTATED | G7: CONFIGURATION | H7: SOURCE EMPTY | I7: =0 -> 0 | J7: NO | K7: =IF(I7=1,"ACCEPTED","OPEN") -> OPEN
A8: ="PKT-"&B8&"-CONTROL" -> PKT-SUB-01-CONTROL | B8: ='Object Crosswalk'!A7 -> SUB-01 | C8: ='Object Crosswalk'!B7 -> Civil substrate | D8: ='Object Crosswalk'!D7 -> MULTI | E8: ='Object Crosswalk'!E7 -> — | F8: ='Object Crosswalk'!F7 -> ROTATED | G8: CONTROL | H8: SOURCE EMPTY | I8: =0 -> 0 | J8: NO | K8: =IF(I8=1,"ACCEPTED","OPEN") -> OPEN
A9: ="PKT-"&B9&"-METROLOGY" -> PKT-SUB-01-METROLOGY | B9: ='Object Crosswalk'!A7 -> SUB-01 | C9: ='Object Crosswalk'!B7 -> Civil substrate | D9: ='Object Crosswalk'!D7 -> MULTI | E9: ='Object Crosswalk'!E7 -> — | F9: ='Object Crosswalk'!F7 -> ROTATED | G9: METROLOGY | H9: SOURCE EMPTY | I9: =0 -> 0 | J9: NO | K9: =IF(I9=1,"ACCEPTED","OPEN") -> OPEN
A10: ="PKT-"&B10&"-SAFETY" -> PKT-SUB-01-SAFETY | B10: ='Object Crosswalk'!A7 -> SUB-01 | C10: ='Object Crosswalk'!B7 -> Civil substrate | D10: ='Object Crosswalk'!D7 -> MULTI | E10: ='Object Crosswalk'!E7 -> — | F10: ='Object Crosswalk'!F7 -> ROTATED | G10: SAFETY | H10: SOURCE EMPTY | I10: =0 -> 0 | J10: NO | K10: =IF(I10=1,"ACCEPTED","OPEN") -> OPEN
A11: ="PKT-"&B11&"-RECONSTRUCTION" -> PKT-SUB-01-RECONSTRUCTION | B11: ='Object Crosswalk'!A7 -> SUB-01 | C11: ='Object Crosswalk'!B7 -> Civil substrate | D11: ='Object Crosswalk'!D7 -> MULTI | E11: ='Object Crosswalk'!E7 -> — | F11: ='Object Crosswalk'!F7 -> ROTATED | G11: RECONSTRUCTION | H11: SOURCE EMPTY | I11: =0 -> 0 | J11: NO | K11: =IF(I11=1,"ACCEPTED","OPEN") -> OPEN
A12: ="PKT-"&B12&"-CONFIGURATION" -> PKT-SUB-02-CONFIGURATION | B12: ='Object Crosswalk'!A8 -> SUB-02 | C12: ='Object Crosswalk'!B8 -> Civil substrate | D12: ='Object Crosswalk'!D8 -> MULTI | E12: ='Object Crosswalk'!E8 -> — | F12: ='Object Crosswalk'!F8 -> ROTATED | G12: CONFIGURATION | H12: SOURCE EMPTY | I12: =0 -> 0 | J12: NO | K12: =IF(I12=1,"ACCEPTED","OPEN") -> OPEN
A13: ="PKT-"&B13&"-CONTROL" -> PKT-SUB-02-CONTROL | B13: ='Object Crosswalk'!A8 -> SUB-02 | C13: ='Object Crosswalk'!B8 -> Civil substrate | D13: ='Object Crosswalk'!D8 -> MULTI | E13: ='Object Crosswalk'!E8 -> — | F13: ='Object Crosswalk'!F8 -> ROTATED | G13: CONTROL | H13: SOURCE EMPTY | I13: =0 -> 0 | J13: NO | K13: =IF(I13=1,"ACCEPTED","OPEN") -> OPEN
A14: ="PKT-"&B14&"-METROLOGY" -> PKT-SUB-02-METROLOGY | B14: ='Object Crosswalk'!A8 -> SUB-02 | C14: ='Object Crosswalk'!B8 -> Civil substrate | D14: ='Object Crosswalk'!D8 -> MULTI | E14: ='Object Crosswalk'!E8 -> — | F14: ='Object Crosswalk'!F8 -> ROTATED | G14: METROLOGY | H14: SOURCE EMPTY | I14: =0 -> 0 | J14: NO | K14: =IF(I14=1,"ACCEPTED","OPEN") -> OPEN
A15: ="PKT-"&B15&"-SAFETY" -> PKT-SUB-02-SAFETY | B15: ='Object Crosswalk'!A8 -> SUB-02 | C15: ='Object Crosswalk'!B8 -> Civil substrate | D15: ='Object Crosswalk'!D8 -> MULTI | E15: ='Object Crosswalk'!E8 -> — | F15: ='Object Crosswalk'!F8 -> ROTATED | G15: SAFETY | H15: SOURCE EMPTY | I15: =0 -> 0 | J15: NO | K15: =IF(I15=1,"ACCEPTED","OPEN") -> OPEN
A16: ="PKT-"&B16&"-RECONSTRUCTION" -> PKT-SUB-02-RECONSTRUCTION | B16: ='Object Crosswalk'!A8 -> SUB-02 | C16: ='Object Crosswalk'!B8 -> Civil substrate | D16: ='Object Crosswalk'!D8 -> MULTI | E16: ='Object Crosswalk'!E8 -> — | F16: ='Object Crosswalk'!F8 -> ROTATED | G16: RECONSTRUCTION | H16: SOURCE EMPTY | I16: =0 -> 0 | J16: NO | K16: =IF(I16=1,"ACCEPTED","OPEN") -> OPEN
A17: ="PKT-"&B17&"-CONFIGURATION" -> PKT-SUB-03-CONFIGURATION | B17: ='Object Crosswalk'!A9 -> SUB-03 | C17: ='Object Crosswalk'!B9 -> Civil substrate | D17: ='Object Crosswalk'!D9 -> MULTI | E17: ='Object Crosswalk'!E9 -> — | F17: ='Object Crosswalk'!F9 -> ROTATED | G17: CONFIGURATION | H17: SOURCE EMPTY | I17: =0 -> 0 | J17: NO | K17: =IF(I17=1,"ACCEPTED","OPEN") -> OPEN
A18: ="PKT-"&B18&"-CONTROL" -> PKT-SUB-03-CONTROL | B18: ='Object Crosswalk'!A9 -> SUB-03 | C18: ='Object Crosswalk'!B9 -> Civil substrate | D18: ='Object Crosswalk'!D9 -> MULTI | E18: ='Object Crosswalk'!E9 -> — | F18: ='Object Crosswalk'!F9 -> ROTATED | G18: CONTROL | H18: SOURCE EMPTY | I18: =0 -> 0 | J18: NO | K18: =IF(I18=1,"ACCEPTED","OPEN") -> OPEN
A19: ="PKT-"&B19&"-METROLOGY" -> PKT-SUB-03-METROLOGY | B19: ='Object Crosswalk'!A9 -> SUB-03 | C19: ='Object Crosswalk'!B9 -> Civil substrate | D19: ='Object Crosswalk'!D9 -> MULTI | E19: ='Object Crosswalk'!E9 -> — | F19: ='Object Crosswalk'!F9 -> ROTATED | G19: METROLOGY | H19: SOURCE EMPTY | I19: =0 -> 0 | J19: NO | K19: =IF(I19=1,"ACCEPTED","OPEN") -> OPEN
A20: ="PKT-"&B20&"-SAFETY" -> PKT-SUB-03-SAFETY | B20: ='Object Crosswalk'!A9 -> SUB-03 | C20: ='Object Crosswalk'!B9 -> Civil substrate | D20: ='Object Crosswalk'!D9 -> MULTI | E20: ='Object Crosswalk'!E9 -> — | F20: ='Object Crosswalk'!F9 -> ROTATED | G20: SAFETY | H20: SOURCE EMPTY | I20: =0 -> 0 | J20: NO | K20: =IF(I20=1,"ACCEPTED","OPEN") -> OPEN
A21: ="PKT-"&B21&"-RECONSTRUCTION" -> PKT-SUB-03-RECONSTRUCTION | B21: ='Object Crosswalk'!A9 -> SUB-03 | C21: ='Object Crosswalk'!B9 -> Civil substrate | D21: ='Object Crosswalk'!D9 -> MULTI | E21: ='Object Crosswalk'!E9 -> — | F21: ='Object Crosswalk'!F9 -> ROTATED | G21: RECONSTRUCTION | H21: SOURCE EMPTY | I21: =0 -> 0 | J21: NO | K21: =IF(I21=1,"ACCEPTED","OPEN") -> OPEN
A22: ="PKT-"&B22&"-CONFIGURATION" -> PKT-SUB-04-CONFIGURATION | B22: ='Object Crosswalk'!A10 -> SUB-04 | C22: ='Object Crosswalk'!B10 -> Civil substrate | D22: ='Object Crosswalk'!D10 -> MULTI | E22: ='Object Crosswalk'!E10 -> — | F22: ='Object Crosswalk'!F10 -> ROTATED | G22: CONFIGURATION | H22: SOURCE EMPTY | I22: =0 -> 0 | J22: NO | K22: =IF(I22=1,"ACCEPTED","OPEN") -> OPEN
A23: ="PKT-"&B23&"-CONTROL" -> PKT-SUB-04-CONTROL | B23: ='Object Crosswalk'!A10 -> SUB-04 | C23: ='Object Crosswalk'!B10 -> Civil substrate | D23: ='Object Crosswalk'!D10 -> MULTI | E23: ='Object Crosswalk'!E10 -> — | F23: ='Object Crosswalk'!F10 -> ROTATED | G23: CONTROL | H23: SOURCE EMPTY | I23: =0 -> 0 | J23: NO | K23: =IF(I23=1,"ACCEPTED","OPEN") -> OPEN
A24: ="PKT-"&B24&"-METROLOGY" -> PKT-SUB-04-METROLOGY | B24: ='Object Crosswalk'!A10 -> SUB-04 | C24: ='Object Crosswalk'!B10 -> Civil substrate | D24: ='Object Crosswalk'!D10 -> MULTI | E24: ='Object Crosswalk'!E10 -> — | F24: ='Object Crosswalk'!F10 -> ROTATED | G24: METROLOGY | H24: SOURCE EMPTY | I24: =0 -> 0 | J24: NO | K24: =IF(I24=1,"ACCEPTED","OPEN") -> OPEN
A25: ="PKT-"&B25&"-SAFETY" -> PKT-SUB-04-SAFETY | B25: ='Object Crosswalk'!A10 -> SUB-04 | C25: ='Object Crosswalk'!B10 -> Civil substrate | D25: ='Object Crosswalk'!D10 -> MULTI | E25: ='Object Crosswalk'!E10 -> — | F25: ='Object Crosswalk'!F10 -> ROTATED | G25: SAFETY | H25: SOURCE EMPTY | I25: =0 -> 0 | J25: NO | K25: =IF(I25=1,"ACCEPTED","OPEN") -> OPEN
A26: ="PKT-"&B26&"-RECONSTRUCTION" -> PKT-SUB-04-RECONSTRUCTION | B26: ='Object Crosswalk'!A10 -> SUB-04 | C26: ='Object Crosswalk'!B10 -> Civil substrate | D26: ='Object Crosswalk'!D10 -> MULTI | E26: ='Object Crosswalk'!E10 -> — | F26: ='Object Crosswalk'!F10 -> ROTATED | G26: RECONSTRUCTION | H26: SOURCE EMPTY | I26: =0 -> 0 | J26: NO | K26: =IF(I26=1,"ACCEPTED","OPEN") -> OPEN
A27: ="PKT-"&B27&"-CONFIGURATION" -> PKT-SUB-05-CONFIGURATION | B27: ='Object Crosswalk'!A11 -> SUB-05 | C27: ='Object Crosswalk'!B11 -> Civil substrate | D27: ='Object Crosswalk'!D11 -> MULTI | E27: ='Object Crosswalk'!E11 -> — | F27: ='Object Crosswalk'!F11 -> ROTATED | G27: CONFIGURATION | H27: SOURCE EMPTY | I27: =0 -> 0 | J27: NO | K27: =IF(I27=1,"ACCEPTED","OPEN") -> OPEN
A28: ="PKT-"&B28&"-CONTROL" -> PKT-SUB-05-CONTROL | B28: ='Object Crosswalk'!A11 -> SUB-05 | C28: ='Object Crosswalk'!B11 -> Civil substrate | D28: ='Object Crosswalk'!D11 -> MULTI | E28: ='Object Crosswalk'!E11 -> — | F28: ='Object Crosswalk'!F11 -> ROTATED | G28: CONTROL | H28: SOURCE EMPTY | I28: =0 -> 0 | J28: NO | K28: =IF(I28=1,"ACCEPTED","OPEN") -> OPEN
A29: ="PKT-"&B29&"-METROLOGY" -> PKT-SUB-05-METROLOGY | B29: ='Object Crosswalk'!A11 -> SUB-05 | C29: ='Object Crosswalk'!B11 -> Civil substrate | D29: ='Object Crosswalk'!D11 -> MULTI | E29: ='Object Crosswalk'!E11 -> — | F29: ='Object Crosswalk'!F11 -> ROTATED | G29: METROLOGY | H29: SOURCE EMPTY | I29: =0 -> 0 | J29: NO | K29: =IF(I29=1,"ACCEPTED","OPEN") -> OPEN
A30: ="PKT-"&B30&"-SAFETY" -> PKT-SUB-05-SAFETY | B30: ='Object Crosswalk'!A11 -> SUB-05 | C30: ='Object Crosswalk'!B11 -> Civil substrate | D30: ='Object Crosswalk'!D11 -> MULTI | E30: ='Object Crosswalk'!E11 -> — | F30: ='Object Crosswalk'!F11 -> ROTATED | G30: SAFETY | H30: SOURCE EMPTY | I30: =0 -> 0 | J30: NO | K30: =IF(I30=1,"ACCEPTED","OPEN") -> OPEN
A31: ="PKT-"&B31&"-RECONSTRUCTION" -> PKT-SUB-05-RECONSTRUCTION | B31: ='Object Crosswalk'!A11 -> SUB-05 | C31: ='Object Crosswalk'!B11 -> Civil substrate | D31: ='Object Crosswalk'!D11 -> MULTI | E31: ='Object Crosswalk'!E11 -> — | F31: ='Object Crosswalk'!F11 -> ROTATED | G31: RECONSTRUCTION | H31: SOURCE EMPTY | I31: =0 -> 0 | J31: NO | K31: =IF(I31=1,"ACCEPTED","OPEN") -> OPEN
A32: ="PKT-"&B32&"-CONFIGURATION" -> PKT-SUB-06-CONFIGURATION | B32: ='Object Crosswalk'!A12 -> SUB-06 | C32: ='Object Crosswalk'!B12 -> Civil substrate | D32: ='Object Crosswalk'!D12 -> MULTI | E32: ='Object Crosswalk'!E12 -> — | F32: ='Object Crosswalk'!F12 -> ROTATED | G32: CONFIGURATION | H32: SOURCE EMPTY | I32: =0 -> 0 | J32: NO | K32: =IF(I32=1,"ACCEPTED","OPEN") -> OPEN
A33: ="PKT-"&B33&"-CONTROL" -> PKT-SUB-06-CONTROL | B33: ='Object Crosswalk'!A12 -> SUB-06 | C33: ='Object Crosswalk'!B12 -> Civil substrate | D33: ='Object Crosswalk'!D12 -> MULTI | E33: ='Object Crosswalk'!E12 -> — | F33: ='Object Crosswalk'!F12 -> ROTATED | G33: CONTROL | H33: SOURCE EMPTY | I33: =0 -> 0 | J33: NO | K33: =IF(I33=1,"ACCEPTED","OPEN") -> OPEN
A34: ="PKT-"&B34&"-METROLOGY" -> PKT-SUB-06-METROLOGY | B34: ='Object Crosswalk'!A12 -> SUB-06 | C34: ='Object Crosswalk'!B12 -> Civil substrate | D34: ='Object Crosswalk'!D12 -> MULTI | E34: ='Object Crosswalk'!E12 -> — | F34: ='Object Crosswalk'!F12 -> ROTATED | G34: METROLOGY | H34: SOURCE EMPTY | I34: =0 -> 0 | J34: NO | K34: =IF(I34=1,"ACCEPTED","OPEN") -> OPEN
A35: ="PKT-"&B35&"-SAFETY" -> PKT-SUB-06-SAFETY | B35: ='Object Crosswalk'!A12 -> SUB-06 | C35: ='Object Crosswalk'!B12 -> Civil substrate | D35: ='Object Crosswalk'!D12 -> MULTI | E35: ='Object Crosswalk'!E12 -> — | F35: ='Object Crosswalk'!F12 -> ROTATED | G35: SAFETY | H35: SOURCE EMPTY | I35: =0 -> 0 | J35: NO | K35: =IF(I35=1,"ACCEPTED","OPEN") -> OPEN
A36: ="PKT-"&B36&"-RECONSTRUCTION" -> PKT-SUB-06-RECONSTRUCTION | B36: ='Object Crosswalk'!A12 -> SUB-06 | C36: ='Object Crosswalk'!B12 -> Civil substrate | D36: ='Object Crosswalk'!D12 -> MULTI | E36: ='Object Crosswalk'!E12 -> — | F36: ='Object Crosswalk'!F12 -> ROTATED | G36: RECONSTRUCTION | H36: SOURCE EMPTY | I36: =0 -> 0 | J36: NO | K36: =IF(I36=1,"ACCEPTED","OPEN") -> OPEN
A37: ="PKT-"&B37&"-CONFIGURATION" -> PKT-RIG-ET-CHA-CONFIGURATION | B37: ='Object Crosswalk'!A13 -> RIG-ET-CHA | C37: ='Object Crosswalk'!B13 -> Root-native rig | D37: ='Object Crosswalk'!D13 -> MS-ET | E37: ='Object Crosswalk'!E13 -> ET-A | F37: ='Object Crosswalk'!F13 -> CHALLENGE | G37: CONFIGURATION | H37: SOURCE EMPTY | I37: =0 -> 0 | J37: NO | K37: =IF(I37=1,"ACCEPTED","OPEN") -> OPEN
A38: ="PKT-"&B38&"-CONTROL" -> PKT-RIG-ET-CHA-CONTROL | B38: ='Object Crosswalk'!A13 -> RIG-ET-CHA | C38: ='Object Crosswalk'!B13 -> Root-native rig | D38: ='Object Crosswalk'!D13 -> MS-ET | E38: ='Object Crosswalk'!E13 -> ET-A | F38: ='Object Crosswalk'!F13 -> CHALLENGE | G38: CONTROL | H38: SOURCE EMPTY | I38: =0 -> 0 | J38: NO | K38: =IF(I38=1,"ACCEPTED","OPEN") -> OPEN
A39: ="PKT-"&B39&"-METROLOGY" -> PKT-RIG-ET-CHA-METROLOGY | B39: ='Object Crosswalk'!A13 -> RIG-ET-CHA | C39: ='Object Crosswalk'!B13 -> Root-native rig | D39: ='Object Crosswalk'!D13 -> MS-ET | E39: ='Object Crosswalk'!E13 -> ET-A | F39: ='Object Crosswalk'!F13 -> CHALLENGE | G39: METROLOGY | H39: SOURCE EMPTY | I39: =0 -> 0 | J39: NO | K39: =IF(I39=1,"ACCEPTED","OPEN") -> OPEN
A40: ="PKT-"&B40&"-SAFETY" -> PKT-RIG-ET-CHA-SAFETY | B40: ='Object Crosswalk'!A13 -> RIG-ET-CHA | C40: ='Object Crosswalk'!B13 -> Root-native rig | D40: ='Object Crosswalk'!D13 -> MS-ET | E40: ='Object Crosswalk'!E13 -> ET-A | F40: ='Object Crosswalk'!F13 -> CHALLENGE | G40: SAFETY | H40: SOURCE EMPTY | I40: =0 -> 0 | J40: NO | K40: =IF(I40=1,"ACCEPTED","OPEN") -> OPEN
A41: ="PKT-"&B41&"-RECONSTRUCTION" -> PKT-RIG-ET-CHA-RECONSTRUCTION | B41: ='Object Crosswalk'!A13 -> RIG-ET-CHA | C41: ='Object Crosswalk'!B13 -> Root-native rig | D41: ='Object Crosswalk'!D13 -> MS-ET | E41: ='Object Crosswalk'!E13 -> ET-A | F41: ='Object Crosswalk'!F13 -> CHALLENGE | G41: RECONSTRUCTION | H41: SOURCE EMPTY | I41: =0 -> 0 | J41: NO | K41: =IF(I41=1,"ACCEPTED","OPEN") -> OPEN
A42: ="PKT-"&B42&"-CONFIGURATION" -> PKT-MTH-ET-CHA-L1-CONFIGURATION | B42: ='Object Crosswalk'!A14 -> MTH-ET-CHA-L1 | C42: ='Object Crosswalk'!B14 -> Method lineage | D42: ='Object Crosswalk'!D14 -> MS-ET | E42: ='Object Crosswalk'!E14 -> ET-A | F42: ='Object Crosswalk'!F14 -> CHALLENGE | G42: CONFIGURATION | H42: SOURCE EMPTY | I42: =0 -> 0 | J42: NO | K42: =IF(I42=1,"ACCEPTED","OPEN") -> OPEN
A43: ="PKT-"&B43&"-CONTROL" -> PKT-MTH-ET-CHA-L1-CONTROL | B43: ='Object Crosswalk'!A14 -> MTH-ET-CHA-L1 | C43: ='Object Crosswalk'!B14 -> Method lineage | D43: ='Object Crosswalk'!D14 -> MS-ET | E43: ='Object Crosswalk'!E14 -> ET-A | F43: ='Object Crosswalk'!F14 -> CHALLENGE | G43: CONTROL | H43: SOURCE EMPTY | I43: =0 -> 0 | J43: NO | K43: =IF(I43=1,"ACCEPTED","OPEN") -> OPEN
...

Sheet Event Evidence
A2: Three hundred sixty event-evidence package references
A4: Five evidence packages accompany each of seventy-two valid-event positions. All observations, validity and outcomes remain source empty.
A6: Package | B6: Event | C6: System | D6: Root | E6: Endpoint | F6: Role | G6: Lineage | H6: Evidence plane | I6: Observation identity | J6: Validity | K6: Outcome | L6: State
A7: EVD-EV-ET-BAL-CHA-L1-EVENT | B7: EV-ET-BAL-CHA-L1 | C7: MS-ET | D7: ET-A | E7: BALANCE | F7: CHALLENGE | G7: L1 | H7: EVENT INTEGRITY | I7: SOURCE EMPTY | J7: SOURCE EMPTY | K7: SOURCE EMPTY | L7: =IF(J7="VALID","ADJUDICATE","OPEN") -> OPEN
A8: EVD-EV-ET-BAL-CHA-L1-MECHANISM | B8: EV-ET-BAL-CHA-L1 | C8: MS-ET | D8: ET-A | E8: BALANCE | F8: CHALLENGE | G8: L1 | H8: MECHANISM | I8: SOURCE EMPTY | J8: SOURCE EMPTY | K8: SOURCE EMPTY | L8: =IF(J8="VALID","ADJUDICATE","OPEN") -> OPEN
A9: EVD-EV-ET-BAL-CHA-L1-PUBLIC | B9: EV-ET-BAL-CHA-L1 | C9: MS-ET | D9: ET-A | E9: BALANCE | F9: CHALLENGE | G9: L1 | H9: PUBLIC EFFECT | I9: SOURCE EMPTY | J9: SOURCE EMPTY | K9: SOURCE EMPTY | L9: =IF(J9="VALID","ADJUDICATE","OPEN") -> OPEN
A10: EVD-EV-ET-BAL-CHA-L1-RIGHTS | B10: EV-ET-BAL-CHA-L1 | C10: MS-ET | D10: ET-A | E10: BALANCE | F10: CHALLENGE | G10: L1 | H10: RIGHTS / RESIDUAL | I10: SOURCE EMPTY | J10: SOURCE EMPTY | K10: SOURCE EMPTY | L10: =IF(J10="VALID","ADJUDICATE","OPEN") -> OPEN
A11: EVD-EV-ET-BAL-CHA-L1-CUSTODY | B11: EV-ET-BAL-CHA-L1 | C11: MS-ET | D11: ET-A | E11: BALANCE | F11: CHALLENGE | G11: L1 | H11: CUSTODY / REPLAY | I11: SOURCE EMPTY | J11: SOURCE EMPTY | K11: SOURCE EMPTY | L11: =IF(J11="VALID","ADJUDICATE","OPEN") -> OPEN
A12: EVD-EV-ET-BAL-CHA-L2-EVENT | B12: EV-ET-BAL-CHA-L2 | C12: MS-ET | D12: ET-A | E12: BALANCE | F12: CHALLENGE | G12: L2 | H12: EVENT INTEGRITY | I12: SOURCE EMPTY | J12: SOURCE EMPTY | K12: SOURCE EMPTY | L12: =IF(J12="VALID","ADJUDICATE","OPEN") -> OPEN
A13: EVD-EV-ET-BAL-CHA-L2-MECHANISM | B13: EV-ET-BAL-CHA-L2 | C13: MS-ET | D13: ET-A | E13: BALANCE | F13: CHALLENGE | G13: L2 | H13: MECHANISM | I13: SOURCE EMPTY | J13: SOURCE EMPTY | K13: SOURCE EMPTY | L13: =IF(J13="VALID","ADJUDICATE","OPEN") -> OPEN
A14: EVD-EV-ET-BAL-CHA-L2-PUBLIC | B14: EV-ET-BAL-CHA-L2 | C14: MS-ET | D14: ET-A | E14: BALANCE | F14: CHALLENGE | G14: L2 | H14: PUBLIC EFFECT | I14: SOURCE EMPTY | J14: SOURCE EMPTY | K14: SOURCE EMPTY | L14: =IF(J14="VALID","ADJUDICATE","OPEN") -> OPEN
A15: EVD-EV-ET-BAL-CHA-L2-RIGHTS | B15: EV-ET-BAL-CHA-L2 | C15: MS-ET | D15: ET-A | E15: BALANCE | F15: CHALLENGE | G15: L2 | H15: RIGHTS / RESIDUAL | I15: SOURCE EMPTY | J15: SOURCE EMPTY | K15: SOURCE EMPTY | L15: =IF(J15="VALID","ADJUDICATE","OPEN") -> OPEN
A16: EVD-EV-ET-BAL-CHA-L2-CUSTODY | B16: EV-ET-BAL-CHA-L2 | C16: MS-ET | D16: ET-A | E16: BALANCE | F16: CHALLENGE | G16: L2 | H16: CUSTODY / REPLAY | I16: SOURCE EMPTY | J16: SOURCE EMPTY | K16: SOURCE EMPTY | L16: =IF(J16="VALID","ADJUDICATE","OPEN") -> OPEN
A17: EVD-EV-ET-BAL-CON-L1-EVENT | B17: EV-ET-BAL-CON-L1 | C17: MS-ET | D17: ET-A | E17: BALANCE | F17: CONTROL | G17: L1 | H17: EVENT INTEGRITY | I17: SOURCE EMPTY | J17: SOURCE EMPTY | K17: SOURCE EMPTY | L17: =IF(J17="VALID","ADJUDICATE","OPEN") -> OPEN
A18: EVD-EV-ET-BAL-CON-L1-MECHANISM | B18: EV-ET-BAL-CON-L1 | C18: MS-ET | D18: ET-A | E18: BALANCE | F18: CONTROL | G18: L1 | H18: MECHANISM | I18: SOURCE EMPTY | J18: SOURCE EMPTY | K18: SOURCE EMPTY | L18: =IF(J18="VALID","ADJUDICATE","OPEN") -> OPEN
... A366: EVD-EV-RT-KEY-REC-L2-CUSTODY | B366: EV-RT-KEY-REC-L2 | C366: MS-RT | D366: RT-B | E366: KEYSTONE | F366: RECONSTRUCTION | G366: L2 | H366: CUSTODY / REPLAY | I366: SOURCE EMPTY | J366: SOURCE EMPTY | K366: SOURCE EMPTY | L366: =IF(J366="VALID","ADJUDICATE","OPEN") -> OPEN

Sheet Finance
A2: Conserved USD 15.6B authority and stage exposure
A4: Public and private accounts are exclusive and add once. No nested reserve, site or test value is added again.
A6: Code | B6: Class | C6: Funding | D6: Lots | E6: Authority USD B | F6: FRAME % | G6: MAKE % | H6: BREAK % | I6: TRANSFER % | J6: Through MAKE USD B | K6: Through BREAK USD B | L6: Unreleased after BREAK
A7: SUB | B7: Civil substrate | C7: Public | D7: 6 | E7: 0.72 | F7: 0.25 | G7: 0.5 | H7: 0 | I7: 0.25 | J7: =E7*(F7+G7) -> 0.54 | K7: =E7*(F7+G7+H7) -> 0.54 | L7: =E7-K7 -> 0.18
A8: RIG | B8: Root-native rig | C8: Public | D8: 18 | E8: 5.7 | F8: 0.25 | G8: 0.5 | H8: 0 | I8: 0.25 | J8: =E8*(F8+G8) -> 4.275 | K8: =E8*(F8+G8+H8) -> 4.275 | L8: =E8-K8 -> 1.425
