Workbook

Sheet Summary
A2: FGR-1 Six-Root Form-Giving Candidate Requirements
A4: Verdict: CLOSE. Six asymmetric causal-interface articles now have controlled loads, interfaces, denial worlds and technology campaigns. Internal architecture is next; exterior form remains held.
A6: Decision | B6: Result | C6: Unit | D6: State | E6: Why it matters | F6: Current authority | G6: Held conversion | H6: Next parent question
A7: requirement architecture | B7: causal-interface packages | C7: architecture | D7: SELECTED | E7: full nonlinear interface; open exterior | F7: FGR-1 | G7: requirement to platform | H7: internal section grammar
A8: candidate packages | B8: 6 | C8: count | D8: CONSTITUTED | E8: one asymmetric article per sentinel | F8: FGR-1 | G8: package to article | H8: mass-energy closure
A9: package clauses | B9: 96 | C9: count | D9: CONSTITUTED | E9: sixteen obligations per package | F9: FGR-1 | G9: field to evidence | H9: controlled sections
A10: form-load records | B10: 72 | C10: count | D10: FROZEN | E10: shape follows explicit burdens | F10: FGR-1 | G10: target to result | H10: root-native balances
A11: interfaces | B11: 48 | C11: count | D11: FROZEN | E11: causal boundaries stay root native | F11: FGR-1 | G11: public seam to common tech | H11: interface drawings
A12: denial worlds | B12: 72 | C12: count | D12: FROZEN | E12: failure remains designed evidence | F12: FGR-1 | G12: denial to likelihood | H12: safe-state sections
A13: endpoint rules | B13: 12 | C13: count | D13: FROZEN | E13: balance resizes; keystone kills | F13: A2C-1 | G13: subsystem surplus to pass | H13: measurement sections
A14: technology campaigns | B14: 24 | C14: count | D14: FROZEN | E14: innovation follows limiting physics | F14: FGR-1 | G14: program to success | H14: root-native work
A15: private option ceiling | B15: 3.5869128 | C15: USD B | D15: UNCHANGED | E15: workstreams and stages cross-classify once | F15: A2C-5 | G15: authority to cost | H15: accepted artifacts
A16: release gates | B16: 72 | C16: count | D16: 30 CONSTITUTED / 42 OPEN | E16: requirements precede evidence | F16: FGR-1 | G16: gate to capability | H16: seven evidence gates
A17: observations | B17: 0 | C17: count | D17: SOURCE EMPTY | E17: no physical article exists | F17: none | G17: model to evidence | H17: representative events
A18: capability credit | B18: 0 | C18: count | D18: HELD | E18: article architecture is not readiness | F18: none | G18: architecture to force | H18: later proof
A19: production authority | B19: 0 | C19: count | D19: HELD | E19: six sentinels retain sibling roots | F19: none | G19: survival to winner | H19: complete-root proof
A20: rendering authority | B20: 0 | C20: count | D20: HELD | E20: exterior follows internal closure | F20: none | G20: envelope to image | H20: separate form warrant
A23: Terminal test | B23: Observed | C23: State
A24: eligible architecture | B24: =COUNTIF(Alternatives!P7:P11,"SELECT") -> 1 | C24: =IF(ABS(B24-1)<0.000001,"PASS","FAIL") -> PASS
A25: packages | B25: =COUNTA('Candidate Articles'!A7:A12) -> 6 | C25: =IF(ABS(B25-6)<0.000001,"PASS","FAIL") -> PASS
A26: form loads | B26: =COUNTA('Form Loads'!A7:A78) -> 72 | C26: =IF(ABS(B26-72)<0.000001,"PASS","FAIL") -> PASS
A27: interfaces | B27: =COUNTA(Interfaces!A7:A54) -> 48 | C27: =IF(ABS(B27-48)<0.000001,"PASS","FAIL") -> PASS
A28: denial worlds | B28: =COUNTA('Denial Worlds'!A7:A78) -> 72 | C28: =IF(ABS(B28-72)<0.000001,"PASS","FAIL") -> PASS
A29: technology campaigns | B29: =COUNTA('Technology Campaigns'!A7:A30) -> 24 | C29: =IF(ABS(B29-24)<0.000001,"PASS","FAIL") -> PASS
A30: release gates | B30: =COUNTA('Release Gates'!A7:A78) -> 72 | C30: =IF(ABS(B30-72)<0.000001,"PASS","FAIL") -> PASS
A31: audit failures | B31: =COUNTIF(Audit!E7:E79,"FAIL") -> 0 | C31: =IF(ABS(B31-0)<0.000001,"PASS","FAIL") -> PASS
A32: observations | B32: =Controls!B36 -> 0 | C32: =IF(ABS(B32-0)<0.000001,"PASS","FAIL") -> PASS
A33: capability | B33: =Controls!B37 -> 0 | C33: =IF(ABS(B33-0)<0.000001,"PASS","FAIL") -> PASS
A34: rendering | B34: =Controls!B39 -> 0 | C34: =IF(ABS(B34-0)<0.000001,"PASS","FAIL") -> PASS

Sheet Controls
A2: Authoritative FGR-1 controls
A4: Blue cells are planning controls. They preserve prior authority and deliberate zero states; they are not physical evidence.
A6: Control | B6: Value | C6: Unit | D6: Authority | E6: Meaning
A7: mission systems | B7: 6 | C7: count | D7: FGR-1 | E7: constituted planning boundary
A8: requirement packages | B8: 6 | C8: count | D8: FGR-1 | E8: constituted planning boundary
A9: clauses per package | B9: 16 | C9: count | D9: FGR-1 | E9: constituted planning boundary
A10: package clauses | B10: 96 | C10: count | D10: FGR-1 | E10: constituted planning boundary
A11: form loads per package | B11: 12 | C11: count | D11: FGR-1 | E11: constituted planning boundary
A12: form-load records | B12: 72 | C12: count | D12: FGR-1 | E12: constituted planning boundary
A13: interfaces per package | B13: 8 | C13: count | D13: FGR-1 | E13: constituted planning boundary
A14: interface records | B14: 48 | C14: count | D14: FGR-1 | E14: constituted planning boundary
A15: denial worlds per package | B15: 12 | C15: count | D15: FGR-1 | E15: constituted planning boundary
A16: denial-world records | B16: 72 | C16: count | D16: FGR-1 | E16: constituted planning boundary
A17: endpoint rules | B17: 12 | C17: count | D17: FGR-1 | E17: constituted planning boundary
A18: technology campaigns | B18: 24 | C18: count | D18: FGR-1 | E18: constituted planning boundary
... A39: rendering authority | B39: 0 | C39: count | D39: HELD | E39: implementation state held

Sheet Alternatives
A2: Candidate-requirement architecture hard-gate test
A4: The selected architecture fixes public burdens and causal interfaces without choosing a common vehicle, contractor-defined test or complete-root build.
A6: Architecture | B6: public denominator | C6: root-native boundary | D6: full-scale causal interface | E6: no hidden host support | F6: unlike mechanisms | G6: denial explicit | H6: fatal result | I6: safe state | J6: residual custody | K6: cold reconstruction | L6: bounded money | M6: exterior held | N6: Passes | O6: Eligible | P6: Decision
A7: causal-interface requirement packages | B7: 1 | C7: 1 | D7: 1 | E7: 1 | F7: 1 | G7: 1 | H7: 1 | I7: 1 | J7: 1 | K7: 1 | L7: 1 | M7: 1 | N7: =SUM(B7:M7) -> 12 | O7: =IF(N7=12,"YES","NO") -> YES | P7: =IF(O7="YES","SELECT","REJECT") -> SELECT
A8: common platform outline | B8: 1 | C8: 0 | D8: 0 | E8: 0 | F8: 0 | G8: 1 | H8: 0 | I8: 1 | J8: 0 | K8: 0 | L8: 1 | M8: 0 | N8: =SUM(B8:M8) -> 4 | O8: =IF(N8=12,"YES","NO") -> NO | P8: =IF(O8="YES","SELECT","REJECT") -> REJECT
A9: output-only service contract | B9: 1 | C9: 0 | D9: 0 | E9: 0 | F9: 1 | G9: 0 | H9: 0 | I9: 0 | J9: 0 | K9: 0 | L9: 1 | M9: 1 | N9: =SUM(B9:M9) -> 4 | O9: =IF(N9=12,"YES","NO") -> NO | P9: =IF(O9="YES","SELECT","REJECT") -> REJECT
A10: contractor-authored specification | B10: 1 | C10: 0 | D10: 1 | E10: 0 | F10: 1 | G10: 1 | H10: 0 | I10: 1 | J10: 1 | K10: 0 | L10: 1 | M10: 0 | N10: =SUM(B10:M10) -> 7 | O10: =IF(N10=12,"YES","NO") -> NO | P10: =IF(O10="YES","SELECT","REJECT") -> REJECT
A11: complete-root first article | B11: 1 | C11: 1 | D11: 1 | E11: 1 | F11: 1 | G11: 1 | H11: 1 | I11: 1 | J11: 1 | K11: 1 | L11: 0 | M11: 1 | N11: =SUM(B11:M11) -> 11 | O11: =IF(N11=12,"YES","NO") -> NO | P11: =IF(O11="YES","SELECT","REJECT") -> REJECT

Sheet Package Grammar
A2: Ninety-six clauses across six requirement packages
A4: A common field grammar makes obligations legible. It does not make candidate physics, control or structure common.
A6: Record | B6: System | C6: Root | D6: Clause | E6: Requirement field | F6: Article | G6: Root-native content | H6: State | I6: Observed? | J6: Cannot infer
A7: ET-A-C01 | B7: MS-ET | C7: ET-A | D7: C01 | E7: Public denominator | F7: Pelagic exchange cell | G7: moving source through dry custody and onward handoff | H7: CONSTITUTED | I7: NO | J7: architecture or evidence
A8: ET-A-C02 | B8: MS-ET | C8: ET-A | D8: C02 | E8: Article boundary | F8: Pelagic exchange cell | G8: moving source through dry custody and onward handoff | H8: CONSTITUTED | I8: NO | J8: architecture or evidence
A9: ET-A-C03 | B9: MS-ET | C9: ET-A | D9: C03 | E9: Full-scale causal interface | F9: Pelagic exchange cell | G9: moving source through dry custody and onward handoff | H9: CONSTITUTED | I9: NO | J9: architecture or evidence
A10: ET-A-C04 | B10: MS-ET | C10: ET-A | D10: C04 | E10: Parent-root scale context | F10: Pelagic exchange cell | G10: moving source through dry custody and onward handoff | H10: CONSTITUTED | I10: NO | J10: architecture or evidence
A11: ET-A-C05 | B11: MS-ET | C11: ET-A | D11: C05 | E11: Load histories | F11: Pelagic exchange cell | G11: moving source through dry custody and onward handoff | H11: CONSTITUTED | I11: NO | J11: architecture or evidence
A12: ET-A-C06 | B12: MS-ET | C12: ET-A | D12: C06 | E12: Receiver states | F12: Pelagic exchange cell | G12: moving source through dry custody and onward handoff | H12: CONSTITUTED | I12: NO | J12: architecture or evidence
A13: ET-A-C07 | B13: MS-ET | C13: ET-A | D13: C07 | E13: Denied dependencies | F13: Pelagic exchange cell | G13: moving source through dry custody and onward handoff | H13: CONSTITUTED | I13: NO | J13: architecture or evidence
A14: ET-A-C08 | B14: MS-ET | C14: ET-A | D14: C08 | E14: Largest-cell loss | F14: Pelagic exchange cell | G14: moving source through dry custody and onward handoff | H14: CONSTITUTED | I14: NO | J14: architecture or evidence
A15: ET-A-C09 | B15: MS-ET | C15: ET-A | D15: C09 | E15: Balance endpoint | F15: Pelagic exchange cell | G15: moving source through dry custody and onward handoff | H15: CONSTITUTED | I15: NO | J15: architecture or evidence
A16: ET-A-C10 | B16: MS-ET | C16: ET-A | D16: C10 | E16: Fatal keystone | F16: Pelagic exchange cell | G16: moving source through dry custody and onward handoff | H16: CONSTITUTED | I16: NO | J16: architecture or evidence
A17: ET-A-C11 | B17: MS-ET | C17: ET-A | D17: C11 | E17: Safe state | F17: Pelagic exchange cell | G17: moving source through dry custody and onward handoff | H17: CONSTITUTED | I17: NO | J17: architecture or evidence
... A102: RT-B-C16 | B102: MS-RT | C102: RT-B | D102: C16 | E102: Architecture-unlock rule | F102: Disconnected microfactory mesh | G102: dirty return through manufacture, qualification and signed release | H102: CONSTITUTED | I102: NO | J102: architecture or evidence

Sheet Candidate Articles
A2: Six asymmetric full-scale causal-interface articles
A4: The first article is not a uniformly scaled root. Full scale attaches only to the mechanism whose nonlinear behavior decides the root.
A6: System | B6: Root | C6: Package | D6: Article | E6: Owned causal boundary | F6: Limiting account | G6: Parent loss margin | H6: Fatal result | I6: Option USD B | J6: Requirement state | K6: Exterior state
A7: MS-ET | B7: ET-A | C7: FG-ET-A | D7: Pelagic exchange cell | E7: moving source through dry custody and onward handoff | F7: Route flow | G7: 1.024 | H7: motion compensation, shore transition or custody loss breaks complete flow | I7: 0.50047462 | J7: CONSTITUTED | K7: HELD
A8: MS-CT | B8: CT-C | C8: FG-CT-C | D8: Occupied-building utility-spine sector | E8: reversible attachment through isolated utility and dirty-return trunks | F8: Energy | G8: 1 | H8: insertion propagates structural, utility or contamination failure | I8: 0.51649348 | J8: CONSTITUTED | K8: HELD
A9: MS-HC | B9: HC-A | C9: FG-HC-A | D9: Atmospheric intervention cell | E9: heat-plume field through deposition, held edge and runoff custody | F9: Route flow | G9: 1.024 | H9: delivered fluid cannot be attributed to held effect or transfers risk | I9: 0.30722165 | J9: CONSTITUTED | K9: HELD
A10: MS-LF | B10: LF-B | C10: FG-LF-B | D10: IGT-50 geothermal source position | E10: subsurface production and injection through water-energy-thermal release | F10: Energy | G10: 1.066 | H10: drawdown, induced hazard or unclosed residual defeats the source position | I10: 0.89941282 | J10: CONSTITUTED | K10: HELD
A11: MS-HU | B11: HU-A | C11: FG-HU-A | D11: Complete clinical island | E11: relationship-bearing reception through definitive care and supported discharge | F11: Mass | G11: 1.008 | H11: mass, sterile metabolism, specialist or destination loss breaks an episode | I11: 0.86071245 | J11: CONSTITUTED | K11: HELD
A12: MS-RT | B12: RT-B | C12: FG-RT-B | D12: Disconnected microfactory mesh | E12: dirty return through manufacture, qualification and signed release | F12: Energy | G12: 1.0064516 | H12: output lacks reproducible ancestry, material state, calibration or release | I12: 0.50259779 | J12: CONSTITUTED | K12: HELD

Sheet Parent Burdens
A2: Inherited complete-root scale context
A4: Parent burdens prove the consequence of scale. They are not silently assigned to the first causal-interface article.
A6: System | B6: Root | C6: Deployment mass t | D6: Peak MW | E6: Deployed roles | F6: Residual rate | G6: Residual unit | H6: Receiver interfaces | I6: Limiting account | J6: Loss margin | K6: State | L6: Article target?
A7: MS-ET | B7: ET-A | C7: 102000 | D7: 96 | E7: 4200 | F7: 1200 | G7: t/day | H7: 6 | I7: Route flow | J7: 1.024 | K7: CONTROLLED HYPOTHESIS | L7: NO
A8: MS-CT | B8: CT-C | C8: 31000 | D8: 42 | E8: 5200 | F8: 220 | G8: t/day | H8: 8 | I8: Energy | J8: 1 | K8: CONTROLLED HYPOTHESIS | L8: NO
A9: MS-HC | B9: HC-A | C9: 54000 | D9: 140 | E9: 12300 | F9: 900 | G9: t/day | H9: 8 | I9: Route flow | J9: 1.024 | K9: CONTROLLED HYPOTHESIS | L9: NO
A10: MS-LF | B10: LF-B | C10: 124300 | D10: 40 | E10: 5330 | F10: 80000 | G10: m3/day | H10: 8 | I10: Energy | J10: 1.066 | K10: CONTROLLED HYPOTHESIS | L10: NO
A11: MS-HU | B11: HU-A | C11: 50000 | D11: 52 | E11: 8500 | F11: 350 | G11: t/day | H11: 8 | I11: Mass | J11: 1.008 | K11: CONTROLLED HYPOTHESIS | L11: NO
A12: MS-RT | B12: RT-B | C12: 72000 | D12: 155 | E12: 8300 | F12: 1200 | G12: t/day | H12: 9 | I12: Energy | J12: 1.0064516 | K12: CONTROLLED HYPOTHESIS | L12: NO

Sheet Form Loads
A2: Seventy-two form-driving load records
A4: Targets are controlled acquisition hypotheses. Parent-context rows shape the scale path but do not become first-article mass or capacity by division.
A6: Load | B6: Root | C6: Family | D6: Metric | E6: Target | F6: Unit | G6: Comparator | H6: Scope | I6: Form consequence | J6: Requirement state | K6: Observation | L6: Credit
A7: ET-A-L01 | B7: ET-A | C7: PUBLIC EFFECT | D7: complete route flow | E7: 5630 | F7: t/day | G7: >= | H7: PARENT | I7: carrier count, queue and shore capacity | J7: FROZEN | K7: SOURCE EMPTY | L7: 0
A8: ET-A-L02 | B8: ET-A | C8: RATE | D8: rated exchange | E8: 600 | F8: t/h | G8: >= | H8: ARTICLE | I8: connector, handling and deck reaction | J8: FROZEN | K8: SOURCE EMPTY | L8: 0
A9: ET-A-L03 | B9: ET-A | C9: LOSS RATE | D9: flow after largest connector loss | E9: 234.58333 | F9: t/h | G9: >= | H9: ARTICLE | I9: two separable transfer paths | J9: FROZEN | K9: SOURCE EMPTY | L9: 0
A10: ET-A-L04 | B10: ET-A | C10: LATENCY | D10: service entry | E10: 72 | F10: h | G10: <= | H10: PARENT | I10: deployment and self-installation | J10: FROZEN | K10: SOURCE EMPTY | L10: 0
A11: ET-A-L05 | B11: ET-A | C11: DURATION | D11: continuous service | E11: 30 | F11: day | G11: >= | H11: PARENT | I11: fatigue, stores and maintenance | J11: FROZEN | K11: SOURCE EMPTY | L11: 0
A12: ET-A-L06 | B12: ET-A | C12: MASS | D12: parent deployment burden | E12: 102000 | F12: t | G12: <= | H12: PARENT CONTEXT | I12: scale path; not article mass | J12: FROZEN | K12: SOURCE EMPTY | L12: 0
A13: ET-A-L07 | B13: ET-A | C13: ENERGY | D13: parent peak electrical load | E13: 96 | F13: MW | G13: <= | H13: PARENT CONTEXT | I13: generation and black start | J13: FROZEN | K13: SOURCE EMPTY | L13: 0
A14: ET-A-L08 | B14: ET-A | C14: WORKFRONTS | D14: simultaneous temporary works | E14: 3 | F14: count | G14: >= | H14: PARENT | I14: shore formation and onward routes | J14: FROZEN | K14: SOURCE EMPTY | L14: 0
A15: ET-A-L09 | B15: ET-A | C15: RECEIVER | D15: independent receiver interfaces | E15: 6 | F15: count | G15: >= | H15: PARENT | I15: custody and route release | J15: FROZEN | K15: SOURCE EMPTY | L15: 0
A16: ET-A-L10 | B16: ET-A | C16: RESIDUAL | D16: treated residual burden | E16: 1200 | F16: t/day | G16: >= | H16: PARENT | I16: containment and reverse flow | J16: FROZEN | K16: SOURCE EMPTY | L16: 0
A17: ET-A-L11 | B17: ET-A | C17: BLACK START | D17: critical endurance | E17: 12 | F17: h | G17: >= | H17: PARENT | I17: islanded exchange control | J17: FROZEN | K17: SOURCE EMPTY | L17: 0
A18: ET-A-L12 | B18: ET-A | C18: RETURN | D18: cold reconstruction ceiling | E18: 168 | F18: h | G18: <= | H18: ARTICLE | I18: sectional replaceability and replay | J18: FROZEN | K18: SOURCE EMPTY | L18: 0
... A78: RT-B-L12 | B78: RT-B | C78: LOSS | D78: denied primary dependencies | E78: 4 | F78: classes | G78: >= | H78: ARTICLE | I78: depot, network, calibration and process | J78: FROZEN | K78: SOURCE EMPTY | L78: 0

Sheet Interfaces
A2: Forty-eight root-native article interfaces
A4: Public meanings may be common. Geometry, actuation, safeing, measurement and repair remain root native.
A6: Interface | B6: System | C6: Root | D6: Boundary | E6: Article chain | F6: Causal role | G6: Implementation | H6: Requirement state | I6: Observation | J6: Credit
A7: ET-A-I01 | B7: MS-ET | C7: ET-A | D7: moving-source datum | E7: moving source through dry custody and onward handoff | F7: DECISIVE | G7: root-native | H7: FROZEN | I7: SOURCE EMPTY | J7: 0
A8: ET-A-I02 | B8: MS-ET | C8: ET-A | D8: dynamic transfer connector | E8: moving source through dry custody and onward handoff | F8: DECISIVE | G8: root-native | H8: FROZEN | I8: SOURCE EMPTY | J8: 0
A9: ET-A-I03 | B9: MS-ET | C9: ET-A | D9: wet-side cargo custody | E9: moving source through dry custody and onward handoff | F9: ROUTE-COMPLETE | G9: root-native | H9: FROZEN | I9: SOURCE EMPTY | J9: 0
A10: ET-A-I04 | B10: MS-ET | C10: ET-A | D10: breakable shore transition | E10: moving source through dry custody and onward handoff | F10: ROUTE-COMPLETE | G10: root-native | H10: FROZEN | I10: SOURCE EMPTY | J10: 0
A11: ET-A-I05 | B11: MS-ET | C11: ET-A | D11: dry staging reaction | E11: moving source through dry custody and onward handoff | F11: ROUTE-COMPLETE | G11: root-native | H11: FROZEN | I11: SOURCE EMPTY | J11: 0
A12: ET-A-I06 | B12: MS-ET | C12: ET-A | D12: onward handoff | E12: moving source through dry custody and onward handoff | F12: ROUTE-COMPLETE | G12: root-native | H12: FROZEN | I12: SOURCE EMPTY | J12: 0
A13: ET-A-I07 | B13: MS-ET | C13: ET-A | D13: residual return | E13: moving source through dry custody and onward handoff | F13: ROUTE-COMPLETE | G13: root-native | H13: FROZEN | I13: SOURCE EMPTY | J13: 0
A14: ET-A-I08 | B14: MS-ET | C14: ET-A | D14: causal-time and mass record | E14: moving source through dry custody and onward handoff | F14: ROUTE-COMPLETE | G14: root-native | H14: FROZEN | I14: SOURCE EMPTY | J14: 0
A15: CT-C-I01 | B15: MS-CT | C15: CT-C | D15: reversible structure attachment | E15: reversible attachment through isolated utility and dirty-return trunks | F15: DECISIVE | G15: root-native | H15: FROZEN | I15: SOURCE EMPTY | J15: 0
A16: CT-C-I02 | B16: MS-CT | C16: CT-C | D16: electrical trunk | E16: reversible attachment through isolated utility and dirty-return trunks | F16: DECISIVE | G16: root-native | H16: FROZEN | I16: SOURCE EMPTY | J16: 0
A17: CT-C-I03 | B17: MS-CT | C17: CT-C | D17: potable-water trunk | E17: reversible attachment through isolated utility and dirty-return trunks | F17: ROUTE-COMPLETE | G17: root-native | H17: FROZEN | I17: SOURCE EMPTY | J17: 0
A18: CT-C-I04 | B18: MS-CT | C18: CT-C | D18: communications trunk | E18: reversible attachment through isolated utility and dirty-return trunks | F18: ROUTE-COMPLETE | G18: root-native | H18: FROZEN | I18: SOURCE EMPTY | J18: 0
... A54: RT-B-I08 | B54: MS-RT | C54: RT-B | D54: evidence custody | E54: dirty return through manufacture, qualification and signed release | F54: ROUTE-COMPLETE | G54: root-native | H54: FROZEN | I54: SOURCE EMPTY | J54: 0

Sheet Denial Worlds
A2: Seventy-two root-native denial worlds
A4: Denial is a controlled test condition, not a claim about likelihood. A missing or invalid result remains distinct from adverse evidence.
A6: World | B6: System | C6: Root | D6: Denied condition | E6: Required response | F6: Role | G6: Permitted disposition | H6: Requirement state | I6: Observation | J6: Credit
A7: ET-A-D01 | B7: MS-ET | C7: ET-A | D7: principal mechanism source removed | E7: motion compensation, shore transition or custody loss breaks complete flow | F7: CHALLENGE | G7: KILL OR RESIZE | H7: FROZEN | I7: SOURCE EMPTY | J7: 0
A8: ET-A-D02 | B8: MS-ET | C8: ET-A | D8: largest independent cell or connector removed | E8: motion compensation, shore transition or custody loss breaks complete flow | F8: CHALLENGE | G8: KILL OR RESIZE | H8: FROZEN | I8: SOURCE EMPTY | J8: 0
A9: ET-A-D03 | B9: MS-ET | C9: ET-A | D9: external power absent | E9: safe stop, truthful hold or continued bounded service | F9: CHALLENGE | G9: HOLD OR SAFE CONTINUE | H9: FROZEN | I9: SOURCE EMPTY | J9: 0
A10: ET-A-D04 | B10: MS-ET | C10: ET-A | D10: wide-area network and time absent | E10: safe stop, truthful hold or continued bounded service | F10: CHALLENGE | G10: HOLD OR SAFE CONTINUE | H10: FROZEN | I10: SOURCE EMPTY | J10: 0
A11: ET-A-D05 | B11: MS-ET | C11: ET-A | D11: primary workforce lineage unavailable | E11: safe stop, truthful hold or continued bounded service | F11: CHALLENGE | G11: HOLD OR SAFE CONTINUE | H11: FROZEN | I11: SOURCE EMPTY | J11: 0
A12: ET-A-D06 | B12: MS-ET | C12: ET-A | D12: receiver refuses service | E12: safe stop, truthful hold or continued bounded service | F12: CHALLENGE | G12: HOLD OR SAFE CONTINUE | H12: FROZEN | I12: SOURCE EMPTY | J12: 0
A13: ET-A-D07 | B13: MS-ET | C13: ET-A | D13: residual receiver refuses return | E13: safe stop, truthful hold or continued bounded service | F13: CHALLENGE | G13: HOLD OR SAFE CONTINUE | H13: FROZEN | I13: SOURCE EMPTY | J13: 0
A14: ET-A-D08 | B14: MS-ET | C14: ET-A | D14: primary depot unavailable | E14: safe stop, truthful hold or continued bounded service | F14: CHALLENGE | G14: HOLD OR SAFE CONTINUE | H14: FROZEN | I14: SOURCE EMPTY | J14: 0
A15: ET-A-D09 | B15: MS-ET | C15: ET-A | D15: vendor key or operations center unavailable | E15: safe stop, truthful hold or continued bounded service | F15: CHALLENGE | G15: HOLD OR SAFE CONTINUE | H15: FROZEN | I15: SOURCE EMPTY | J15: 0
A16: ET-A-D10 | B16: MS-ET | C16: ET-A | D16: primary measurement route unavailable | E16: safe stop, truthful hold or continued bounded service | F16: CHALLENGE | G16: HOLD OR SAFE CONTINUE | H16: FROZEN | I16: SOURCE EMPTY | J16: 0
A17: ET-A-D11 | B17: MS-ET | C17: ET-A | D17: civil authority revoked | E17: safe stop, truthful hold or continued bounded service | F17: CHALLENGE | G17: HOLD OR SAFE CONTINUE | H17: FROZEN | I17: SOURCE EMPTY | J17: 0
A18: ET-A-D12 | B18: MS-ET | C18: ET-A | D18: outside team receives frozen records only | E18: safe stop, truthful hold or continued bounded service | F18: CHALLENGE | G18: HOLD OR SAFE CONTINUE | H18: FROZEN | I18: SOURCE EMPTY | J18: 0
... A78: RT-B-D12 | B78: MS-RT | C78: RT-B | D78: outside team receives frozen records only | E78: safe stop, truthful hold or continued bounded service | F78: CHALLENGE | G78: HOLD OR SAFE CONTINUE | H78: FROZEN | I78: SOURCE EMPTY | J78: 0

Sheet Endpoint Rules
A2: Twelve balance and causal-keystone endpoint rules
A4: A favorable subsystem cannot compensate for a failed balance or keystone. Valid adverse evidence is payable and terminal for the tested claim.
A6: Endpoint | B6: System | C6: Root | D6: Type | E6: Claim | F6: Estimator | G6: Comparator | H6: Threshold | I6: Decision rule | J6: Observation | K6: Disposition | L6: Credit
A7: ET-A-BAL | B7: MS-ET | C7: ET-A | D7: BALANCE | E7: Route flow | F7: lower confidence bound / requirement | G7: >= | H7: 1 | I7: RESIZE if below; HOLD if interval crosses | J7: SOURCE EMPTY | K7: HOLD | L7: 0
A8: ET-A-KEY | B8: MS-ET | C8: ET-A | D8: KEYSTONE | E8: motion compensation, shore transition or custody loss breaks complete flow | F8: binary causal survival | G8: EQUALS | H8: 1 | I8: KILL if validly failed | J8: SOURCE EMPTY | K8: HOLD | L8: 0
A9: CT-C-BAL | B9: MS-CT | C9: CT-C | D9: BALANCE | E9: Energy | F9: lower confidence bound / requirement | G9: >= | H9: 1 | I9: RESIZE if below; HOLD if interval crosses | J9: SOURCE EMPTY | K9: HOLD | L9: 0
A10: CT-C-KEY | B10: MS-CT | C10: CT-C | D10: KEYSTONE | E10: insertion propagates structural, utility or contamination failure | F10: binary causal survival | G10: EQUALS | H10: 1 | I10: KILL if validly failed | J10: SOURCE EMPTY | K10: HOLD | L10: 0
A11: HC-A-BAL | B11: MS-HC | C11: HC-A | D11: BALANCE | E11: Route flow | F11: lower confidence bound / requirement | G11: >= | H11: 1 | I11: RESIZE if below; HOLD if interval crosses | J11: SOURCE EMPTY | K11: HOLD | L11: 0
A12: HC-A-KEY | B12: MS-HC | C12: HC-A | D12: KEYSTONE | E12: delivered fluid cannot be attributed to held effect or transfers risk | F12: binary causal survival | G12: EQUALS | H12: 1 | I12: KILL if validly failed | J12: SOURCE EMPTY | K12: HOLD | L12: 0
A13: LF-B-BAL | B13: MS-LF | C13: LF-B | D13: BALANCE | E13: Energy | F13: lower confidence bound / requirement | G13: >= | H13: 1 | I13: RESIZE if below; HOLD if interval crosses | J13: SOURCE EMPTY | K13: HOLD | L13: 0
A14: LF-B-KEY | B14: MS-LF | C14: LF-B | D14: KEYSTONE | E14: drawdown, induced hazard or unclosed residual defeats the source position | F14: binary causal survival | G14: EQUALS | H14: 1 | I14: KILL if validly failed | J14: SOURCE EMPTY | K14: HOLD | L14: 0
A15: HU-A-BAL | B15: MS-HU | C15: HU-A | D15: BALANCE | E15: Mass | F15: lower confidence bound / requirement | G15: >= | H15: 1 | I15: RESIZE if below; HOLD if interval crosses | J15: SOURCE EMPTY | K15: HOLD | L15: 0
A16: HU-A-KEY | B16: MS-HU | C16: HU-A | D16: KEYSTONE | E16: mass, sterile metabolism, specialist or destination loss breaks an episode | F16: binary causal survival | G16: EQUALS | H16: 1 | I16: KILL if validly failed | J16: SOURCE EMPTY | K16: HOLD | L16: 0
A17: RT-B-BAL | B17: MS-RT | C17: RT-B | D17: BALANCE | E17: Energy | F17: lower confidence bound / requirement | G17: >= | H17: 1 | I17: RESIZE if below; HOLD if interval crosses | J17: SOURCE EMPTY | K17: HOLD | L17: 0
A18: RT-B-KEY | B18: MS-RT | C18: RT-B | D18: KEYSTONE | E18: output lacks reproducible ancestry, material state, calibration or release | F18: binary causal survival | G18: EQUALS | H18: 1 | I18: KILL if validly failed | J18: SOURCE EMPTY | K18: HOLD | L18: 0

Sheet Technology Campaigns
A2: Twenty-four root-native technology campaigns
A4: Technology authority buys rival causal mechanisms and their failure. It does not buy a predetermined component catalog.
A6: Campaign | B6: System | C6: Root | D6: Workstream | E6: Technology objective | F6: Share | G6: Root option USD B | H6: Campaign ceiling USD B | I6: Endpoint | J6: Fatal result | K6: Program state | L6: Evidence state | M6: Disposition
A7: ET-A-T1 | B7: MS-ET | C7: ET-A | D7: DECISIVE PHYSICS | E7: moving-base load transfer | F7: 0.35 | G7: 0.50047462 | H7: =F7*G7 -> 0.17516612 | I7: ET-A-BAL | J7: motion compensation, shore transition or custody loss breaks complete flow | K7: FROZEN PROGRAM | L7: OPEN | M7: HOLD
A8: ET-A-T2 | B8: MS-ET | C8: ET-A | D8: COMPLETE ARTICLE | E8: self-forming wet-to-dry terminal | F8: 0.3 | G8: 0.50047462 | H8: =F8*G8 -> 0.15014239 | I8: ET-A-KEY | J8: motion compensation, shore transition or custody loss breaks complete flow | K8: FROZEN PROGRAM | L8: OPEN | M8: HOLD
A9: ET-A-T3 | B9: MS-ET | C9: ET-A | D9: INDEPENDENT PROVING | E9: high-rate custody metrology | F9: 0.2 | G9: 0.50047462 | H9: =F9*G9 -> 0.10009492 | I9: ET-A-KEY | J9: motion compensation, shore transition or custody loss breaks complete flow | K9: FROZEN PROGRAM | L9: OPEN | M9: HOLD
A10: ET-A-T4 | B10: MS-ET | C10: ET-A | D10: REPRODUCTION | E10: reconstructable connector system | F10: 0.15 | G10: 0.50047462 | H10: =F10*G10 -> 0.075071193 | I10: ET-A-KEY | J10: motion compensation, shore transition or custody loss breaks complete flow | K10: FROZEN PROGRAM | L10: OPEN | M10: HOLD
A11: CT-C-T1 | B11: MS-CT | C11: CT-C | D11: DECISIVE PHYSICS | E11: reversible occupied-structure attachment | F11: 0.35 | G11: 0.51649348 | H11: =F11*G11 -> 0.18077272 | I11: CT-C-BAL | J11: insertion propagates structural, utility or contamination failure | K11: FROZEN PROGRAM | L11: OPEN | M11: HOLD
A12: CT-C-T2 | B12: MS-CT | C12: CT-C | D12: COMPLETE ARTICLE | E12: fault-contained multi-utility trunk | F12: 0.3 | G12: 0.51649348 | H12: =F12*G12 -> 0.15494804 | I12: CT-C-KEY | J12: insertion propagates structural, utility or contamination failure | K12: FROZEN PROGRAM | L12: OPEN | M12: HOLD
A13: CT-C-T3 | B13: MS-CT | C13: CT-C | D13: INDEPENDENT PROVING | E13: contamination-aware installation robotics | F13: 0.2 | G13: 0.51649348 | H13: =F13*G13 -> 0.1032987 | I13: CT-C-KEY | J13: insertion propagates structural, utility or contamination failure | K13: FROZEN PROGRAM | L13: OPEN | M13: HOLD
A14: CT-C-T4 | B14: MS-CT | C14: CT-C | D14: REPRODUCTION | E14: offline human release and repair | F14: 0.15 | G14: 0.51649348 | H14: =F14*G14 -> 0.077474022 | I14: CT-C-KEY | J14: insertion propagates structural, utility or contamination failure | K14: FROZEN PROGRAM | L14: OPEN | M14: HOLD
A15: HC-A-T1 | B15: MS-HC | C15: HC-A | D15: DECISIVE PHYSICS | E15: all-weather plume tomography | F15: 0.35 | G15: 0.30722165 | H15: =F15*G15 -> 0.10752758 | I15: HC-A-BAL | J15: delivered fluid cannot be attributed to held effect or transfers risk | K15: FROZEN PROGRAM | L15: OPEN | M15: HOLD
A16: HC-A-T2 | B16: MS-HC | C16: HC-A | D16: COMPLETE ARTICLE | E16: high-duty thermal atmospheric article | F16: 0.3 | G16: 0.30722165 | H16: =F16*G16 -> 0.092166496 | I16: HC-A-KEY | J16: delivered fluid cannot be attributed to held effect or transfers risk | K16: FROZEN PROGRAM | L16: OPEN | M16: HOLD
A17: HC-A-T3 | B17: MS-HC | C17: HC-A | D17: INDEPENDENT PROVING | E17: causal precision deposition | F17: 0.2 | G17: 0.30722165 | H17: =F17*G17 -> 0.061444331 | I17: HC-A-KEY | J17: delivered fluid cannot be attributed to held effect or transfers risk | K17: FROZEN PROGRAM | L17: OPEN | M17: HOLD
A18: HC-A-T4 | B18: MS-HC | C18: HC-A | D18: REPRODUCTION | E18: closed refill and runoff metabolism | F18: 0.15 | G18: 0.30722165 | H18: =F18*G18 -> 0.046083248 | I18: HC-A-KEY | J18: delivered fluid cannot be attributed to held effect or transfers risk | K18: FROZEN PROGRAM | L18: OPEN | M18: HOLD
... A30: RT-B-T4 | B30: MS-RT | C30: RT-B | D30: REPRODUCTION | E30: robotic disassembly and cold reconstruction | F30: 0.15 | G30: 0.50259779 | H30: =F30*G30 -> 0.075389669 | I30: RT-B-KEY | J30: output lacks reproducible ancestry, material state, calibration or release | K30: FROZEN PROGRAM | L30: OPEN | M30: HOLD

Sheet Finance
A2: Conserved candidate-option authority
A4: The four workstream views and four payment stages cross-classify the same USD 3.59B. Neither view adds authority.
A6: System | B6: Root | C6: Article | D6: Option USD B | E6: Decisive physics | F6: Complete article | G6: Independent proving | H6: Reproduction | I6: Cross-classified total | J6: Difference
A7: MS-ET | B7: ET-A | C7: Pelagic exchange cell | D7: 0.50047462 | E7: =D7*Controls!$B$23 -> 0.17516612 | F7: =D7*Controls!$B$24 -> 0.15014239 | G7: =D7*Controls!$B$25 -> 0.10009492 | H7: =D7*Controls!$B$26 -> 0.075071193 | I7: =SUM(E7:H7) -> 0.50047462 | J7: =I7-D7 -> 0
A8: MS-CT | B8: CT-C | C8: Occupied-building utility-spine sector | D8: 0.51649348 | E8: =D8*Controls!$B$23 -> 0.18077272 | F8: =D8*Controls!$B$24 -> 0.15494804 | G8: =D8*Controls!$B$25 -> 0.1032987 | H8: =D8*Controls!$B$26 -> 0.077474022 | I8: =SUM(E8:H8) -> 0.51649348 | J8: =I8-D8 -> -1.110223e-16
A9: MS-HC | B9: HC-A | C9: Atmospheric intervention cell | D9: 0.30722165 | E9: =D9*Controls!$B$23 -> 0.10752758 | F9: =D9*Controls!$B$24 -> 0.092166496 | G9: =D9*Controls!$B$25 -> 0.061444331 | H9: =D9*Controls!$B$26 -> 0.046083248 | I9: =SUM(E9:H9) -> 0.30722165 | J9: =I9-D9 -> 0
A10: MS-LF | B10: LF-B | C10: IGT-50 geothermal source position | D10: 0.89941282 | E10: =D10*Controls!$B$23 -> 0.31479449 | F10: =D10*Controls!$B$24 -> 0.26982385 | G10: =D10*Controls!$B$25 -> 0.17988256 | H10: =D10*Controls!$B$26 -> 0.13491192 | I10: =SUM(E10:H10) -> 0.89941282 | J10: =I10-D10 -> 0
A11: MS-HU | B11: HU-A | C11: Complete clinical island | D11: 0.86071245 | E11: =D11*Controls!$B$23 -> 0.30124936 | F11: =D11*Controls!$B$24 -> 0.25821374 | G11: =D11*Controls!$B$25 -> 0.17214249 | H11: =D11*Controls!$B$26 -> 0.12910687 | I11: =SUM(E11:H11) -> 0.86071245 | J11: =I11-D11 -> 0
A12: MS-RT | B12: RT-B | C12: Disconnected microfactory mesh | D12: 0.50259779 | E12: =D12*Controls!$B$23 -> 0.17590923 | F12: =D12*Controls!$B$24 -> 0.15077934 | G12: =D12*Controls!$B$25 -> 0.10051956 | H12: =D12*Controls!$B$26 -> 0.075389669 | I12: =SUM(E12:H12) -> 0.50259779 | J12: =I12-D12 -> -1.110223e-16
A13: TOTAL | B13: six roots | C13: all candidate articles | D13: =SUM(D7:D12) -> 3.5869128 | E13: =SUM(E7:E12) -> 1.2554195 | F13: =SUM(F7:F12) -> 1.0760738 | G13: =SUM(G7:G12) -> 0.71738256 | H13: =SUM(H7:H12) -> 0.53803692 | I13: =SUM(I7:I12) -> 3.5869128 | J13: =SUM(J7:J12) -> -2.220446e-16

Sheet Payment Stages
A2: Twenty-four held candidate payment stages
A4: Requirement authority is not award, obligation, acceptance or payment. Stage ceilings remain held until their inherited warrants close.
A6: Record | B6: System | C6: Root | D6: Stage | E6: Option USD B | F6: Stage share | G6: Stage ceiling USD B | H6: Accepted | I6: Obligated USD B | J6: State
A7: ET-A-FRAME | B7: MS-ET | C7: ET-A | D7: FRAME | E7: 0.50047462 | F7: 0.15 | G7: =E7*F7 -> 0.075071193 | H7: 0 | I7: =IF(H7=1,G7,0) -> 0 | J7: HELD
A8: ET-A-MAKE | B8: MS-ET | C8: ET-A | D8: MAKE | E8: 0.50047462 | F8: 0.35 | G8: =E8*F8 -> 0.17516612 | H8: 0 | I8: =IF(H8=1,G8,0) -> 0 | J8: HELD
A9: ET-A-BREAK | B9: MS-ET | C9: ET-A | D9: BREAK | E9: 0.50047462 | F9: 0.35 | G9: =E9*F9 -> 0.17516612 | H9: 0 | I9: =IF(H9=1,G9,0) -> 0 | J9: HELD
A10: ET-A-TRANSFER | B10: MS-ET | C10: ET-A | D10: TRANSFER | E10: 0.50047462 | F10: 0.15 | G10: =E10*F10 -> 0.075071193 | H10: 0 | I10: =IF(H10=1,G10,0) -> 0 | J10: HELD
A11: CT-C-FRAME | B11: MS-CT | C11: CT-C | D11: FRAME | E11: 0.51649348 | F11: 0.15 | G11: =E11*F11 -> 0.077474022 | H11: 0 | I11: =IF(H11=1,G11,0) -> 0 | J11: HELD
A12: CT-C-MAKE | B12: MS-CT | C12: CT-C | D12: MAKE | E12: 0.51649348 | F12: 0.35 | G12: =E12*F12 -> 0.18077272 | H12: 0 | I12: =IF(H12=1,G12,0) -> 0 | J12: HELD
A13: CT-C-BREAK | B13: MS-CT | C13: CT-C | D13: BREAK | E13: 0.51649348 | F13: 0.35 | G13: =E13*F13 -> 0.18077272 | H13: 0 | I13: =IF(H13=1,G13,0) -> 0 | J13: HELD
A14: CT-C-TRANSFER | B14: MS-CT | C14: CT-C | D14: TRANSFER | E14: 0.51649348 | F14: 0.15 | G14: =E14*F14 -> 0.077474022 | H14: 0 | I14: =IF(H14=1,G14,0) -> 0 | J14: HELD
A15: HC-A-FRAME | B15: MS-HC | C15: HC-A | D15: FRAME | E15: 0.30722165 | F15: 0.15 | G15: =E15*F15 -> 0.046083248 | H15: 0 | I15: =IF(H15=1,G15,0) -> 0 | J15: HELD
A16: HC-A-MAKE | B16: MS-HC | C16: HC-A | D16: MAKE | E16: 0.30722165 | F16: 0.35 | G16: =E16*F16 -> 0.10752758 | H16: 0 | I16: =IF(H16=1,G16,0) -> 0 | J16: HELD
A17: HC-A-BREAK | B17: MS-HC | C17: HC-A | D17: BREAK | E17: 0.30722165 | F17: 0.35 | G17: =E17*F17 -> 0.10752758 | H17: 0 | I17: =IF(H17=1,G17,0) -> 0 | J17: HELD
A18: HC-A-TRANSFER | B18: MS-HC | C18: HC-A | D18: TRANSFER | E18: 0.30722165 | F18: 0.15 | G18: =E18*F18 -> 0.046083248 | H18: 0 | I18: =IF(H18=1,G18,0) -> 0 | J18: HELD
... A30: RT-B-TRANSFER | B30: MS-RT | C30: RT-B | D30: TRANSFER | E30: 0.50259779 | F30: 0.15 | G30: =E30*F30 -> 0.075389669 | H30: 0 | I30: =IF(H30=1,G30,0) -> 0 | J30: HELD

Sheet Release Gates
A2: Seventy-two requirement-to-architecture release gates
A4: The first five gates are constituted requirements. Seven evidence-bearing gates remain open. Even G12 permits internal architecture, not exterior form.
A6: Gate | B6: System | C6: Root | D6: Order | E6: Gate claim | F6: State | G6: Authority basis | H6: Requirement closed | I6: Evidence accepted | J6: If closed | K6: Exterior authority
A7: ET-A-G01 | B7: MS-ET | C7: ET-A | D7: 1 | E7: denominator | F7: CONSTITUTED | G7: requirement package | H7: 1 | I7: 0 | J7: NEXT GATE | K7: n.a.
A8: ET-A-G02 | B8: MS-ET | C8: ET-A | D8: 2 | E8: article boundary | F8: CONSTITUTED | G8: requirement package | H8: 1 | I8: 0 | J8: NEXT GATE | K8: n.a.
A9: ET-A-G03 | B9: MS-ET | C9: ET-A | D9: 3 | E9: form loads | F9: CONSTITUTED | G9: requirement package | H9: 1 | I9: 0 | J9: NEXT GATE | K9: n.a.
A10: ET-A-G04 | B10: MS-ET | C10: ET-A | D10: 4 | E10: interfaces | F10: CONSTITUTED | G10: requirement package | H10: 1 | I10: 0 | J10: NEXT GATE | K10: n.a.
A11: ET-A-G05 | B11: MS-ET | C11: ET-A | D11: 5 | E11: denial set | F11: CONSTITUTED | G11: requirement package | H11: 1 | I11: 0 | J11: NEXT GATE | K11: n.a.
A12: ET-A-G06 | B12: MS-ET | C12: ET-A | D12: 6 | E12: paper closure | F12: OPEN | G12: future source record | H12: 0 | I12: 0 | J12: NEXT GATE | K12: n.a.
A13: ET-A-G07 | B13: MS-ET | C13: ET-A | D13: 7 | E13: safety and rights | F13: OPEN | G13: future source record | H13: 0 | I13: 0 | J13: NEXT GATE | K13: n.a.
A14: ET-A-G08 | B14: MS-ET | C14: ET-A | D14: 8 | E14: ancestry | F14: OPEN | G14: future source record | H14: 0 | I14: 0 | J14: NEXT GATE | K14: n.a.
A15: ET-A-G09 | B15: MS-ET | C15: ET-A | D15: 9 | E15: executable build record | F15: OPEN | G15: future source record | H15: 0 | I15: 0 | J15: NEXT GATE | K15: n.a.
A16: ET-A-G10 | B16: MS-ET | C16: ET-A | D16: 10 | E16: representative event | F16: OPEN | G16: future source record | H16: 0 | I16: 0 | J16: NEXT GATE | K16: n.a.
A17: ET-A-G11 | B17: MS-ET | C17: ET-A | D17: 11 | E17: cold reconstruction | F17: OPEN | G17: future source record | H17: 0 | I17: 0 | J17: NEXT GATE | K17: n.a.
A18: ET-A-G12 | B18: MS-ET | C18: ET-A | D18: 12 | E18: architecture warrant | F18: OPEN | G18: future source record | H18: 0 | I18: 0 | J18: INTERNAL ARCHITECTURE ONLY | K18: HELD
... A78: RT-B-G12 | B78: MS-RT | C78: RT-B | D78: 12 | E78: architecture warrant | F78: OPEN | G78: future source record | H78: 0 | I78: 0 | J78: INTERNAL ARCHITECTURE ONLY | K78: HELD

Sheet Nonconversions
A2: Eighteen prohibited requirement conversions
A4: These are hard type boundaries, not review preferences. Crossing one invalidates the claimed downstream state.
A6: Rule | B6: From | C6: Must not become | D6: Reason | E6: State
A7: N01 | B7: requirement package | C7: candidate architecture | D7: a bounded planning or evidence state cannot manufacture a downstream authority | E7: FROZEN
A8: N02 | B8: article boundary | C8: exterior form | D8: a bounded planning or evidence state cannot manufacture a downstream authority | E8: FROZEN
A9: N03 | B9: full-scale interface | C9: complete operational root | D9: a bounded planning or evidence state cannot manufacture a downstream authority | E9: FROZEN
A10: N04 | B10: parent-root burden | C10: first-article mass | D10: a bounded planning or evidence state cannot manufacture a downstream authority | E10: FROZEN
A11: N05 | B11: load target | C11: observed performance | D11: a bounded planning or evidence state cannot manufacture a downstream authority | E11: FROZEN
A12: N06 | B12: receiver emulator | C12: candidate subsystem | D12: a bounded planning or evidence state cannot manufacture a downstream authority | E12: FROZEN
A13: N07 | B13: public field name | C13: common technical implementation | D13: a bounded planning or evidence state cannot manufacture a downstream authority | E13: FROZEN
A14: N08 | B14: denial world | C14: mission likelihood | D14: a bounded planning or evidence state cannot manufacture a downstream authority | E14: FROZEN
A15: N09 | B15: paper balance | C15: physical margin | D15: a bounded planning or evidence state cannot manufacture a downstream authority | E15: FROZEN
A16: N10 | B16: private option | C16: award | D16: a bounded planning or evidence state cannot manufacture a downstream authority | E16: FROZEN
A17: N11 | B17: stage ceiling | C17: obligation | D17: a bounded planning or evidence state cannot manufacture a downstream authority | E17: FROZEN
... A24: N18 | B24: one selected sentinel | C24: cancellation of three sibling roots | D24: a bounded planning or evidence state cannot manufacture a downstream authority | E24: FROZEN

Sheet Requirement Crosswalk
A2: Six package-to-evidence crosswalk records
A4: Each package is complete as a requirement object while every implementation, evidence, capability and exterior state remains empty or held.
A6: System | B6: Root | C6: Package | D6: Clauses | E6: Form loads | F6: Interfaces | G6: Denial worlds | H6: Endpoints | I6: Technology campaigns | J6: Release gates | K6: Option USD B | L6: Constituted gates | M6: Open evidence gates | N6: Requirement state | O6: Site | P6: Firm | Q6: Award | R6: Capability | S6: Rendering
A7: MS-ET | B7: ET-A | C7: FG-ET-A | D7: 16 | E7: 12 | F7: 8 | G7: 12 | H7: 2 | I7: 4 | J7: 12 | K7: 0.50047462 | L7: 5 | M7: 7 | N7: CONSTITUTED | O7: 0 | P7: 0 | Q7: 0 | R7: 0 | S7: 0
A8: MS-CT | B8: CT-C | C8: FG-CT-C | D8: 16 | E8: 12 | F8: 8 | G8: 12 | H8: 2 | I8: 4 | J8: 12 | K8: 0.51649348 | L8: 5 | M8: 7 | N8: CONSTITUTED | O8: 0 | P8: 0 | Q8: 0 | R8: 0 | S8: 0
A9: MS-HC | B9: HC-A | C9: FG-HC-A | D9: 16 | E9: 12 | F9: 8 | G9: 12 | H9: 2 | I9: 4 | J9: 12 | K9: 0.30722165 | L9: 5 | M9: 7 | N9: CONSTITUTED | O9: 0 | P9: 0 | Q9: 0 | R9: 0 | S9: 0
A10: MS-LF | B10: LF-B | C10: FG-LF-B | D10: 16 | E10: 12 | F10: 8 | G10: 12 | H10: 2 | I10: 4 | J10: 12 | K10: 0.89941282 | L10: 5 | M10: 7 | N10: CONSTITUTED | O10: 0 | P10: 0 | Q10: 0 | R10: 0 | S10: 0
A11: MS-HU | B11: HU-A | C11: FG-HU-A | D11: 16 | E11: 12 | F11: 8 | G11: 12 | H11: 2 | I11: 4 | J11: 12 | K11: 0.86071245 | L11: 5 | M11: 7 | N11: CONSTITUTED | O11: 0 | P11: 0 | Q11: 0 | R11: 0 | S11: 0
A12: MS-RT | B12: RT-B | C12: FG-RT-B | D12: 16 | E12: 12 | F12: 8 | G12: 12 | H12: 2 | I12: 4 | J12: 12 | K12: 0.50259779 | L12: 5 | M12: 7 | N12: CONSTITUTED | O12: 0 | P12: 0 | Q12: 0 | R12: 0 | S12: 0

Sheet Stress Tests
A2: Sixteen requirement-constitution stress cases
A4: The constitution must preserve radical technical freedom while denying every shortcut from a requirement or promising mechanism to a finished platform.
A6: ID | B6: Disturbance | C6: Required response | D6: Forbidden conversion | E6: Disposition | F6: State
A7: S01 | B7: designer proposes one common carrier outline | C7: retain six causal boundaries | D7: common form to unlike physics | E7: REJECT | F7: PASS
A8: S02 | B8: supplier rewrites its denominator | C8: return to public requirement authority | D8: candidate to test owner | E8: INVALID | F8: PASS
A9: S03 | B9: host power closes an article balance | C9: remove host contribution | D9: borrowed support to capability | E9: FAIL | F9: PASS
A10: S04 | B10: scaled model omits nonlinear interface | C10: require full-scale causal boundary | D10: model similarity to physical truth | E10: HOLD | F10: PASS
A11: S05 | B11: parent-root mass is divided into article mass | C11: retain context-only scope | D11: portfolio arithmetic to geometry | E11: REJECT | F11: PASS
A12: S06 | B12: receiver emulator controls the candidate | C12: split actuation and measurement | D12: public method to candidate root | E12: INVALID | F12: PASS
A13: S07 | B13: one load exceeds target but another fails | C13: apply conjunctive endpoints | D13: surplus to compensation | E13: RESIZE | F13: PASS
A14: S08 | B14: valid keystone failure is repeated | C14: bind result and kill claim | D14: adverse evidence to schedule delay | E14: KILL | F14: PASS
A15: S09 | B15: uncertainty interval crosses one | C15: retain hold | D15: uncertainty to pass | E15: HOLD | F15: PASS
A16: S10 | B16: technology campaign converges on sibling root | C16: redeclare ancestry or end root | D16: program label to diversity | E16: RETURN | F16: PASS
A17: S11 | B17: option ceiling is treated as cost estimate | C17: retain authority-only meaning | D17: reservation to price | E17: REJECT | F17: PASS
... A22: S16 | B22: exterior rendering is requested | C22: require G12 plus separate form warrant | D22: internal authority to rendering | E22: HELD | F22: PASS

Sheet Mutations
A2: Live mutation and restoration log
A4: Each mutation changes one authoritative control, trips at least one terminal audit and restores the passing baseline before export.
A6: ID | B6: Control cell | C6: Baseline | D6: Mutated | E6: Audit failures | F6: Mutation detected | G6: Baseline restored
A7: M01 | B7: Controls!B7 | C7: 6 | D7: 5 | E7: 1 | F7: YES | G7: YES
A8: M02 | B8: Controls!B8 | C8: 6 | D8: 5 | E8: 1 | F8: YES | G8: YES
A9: M03 | B9: Controls!B9 | C9: 16 | D9: 15 | E9: 1 | F9: YES | G9: YES
A10: M04 | B10: Controls!B10 | C10: 96 | D10: 95 | E10: 1 | F10: YES | G10: YES
A11: M05 | B11: Controls!B11 | C11: 12 | D11: 11 | E11: 1 | F11: YES | G11: YES
A12: M06 | B12: Controls!B12 | C12: 72 | D12: 71 | E12: 1 | F12: YES | G12: YES
A13: M07 | B13: Controls!B13 | C13: 8 | D13: 7 | E13: 1 | F13: YES | G13: YES
A14: M08 | B14: Controls!B14 | C14: 48 | D14: 47 | E14: 1 | F14: YES | G14: YES
A15: M09 | B15: Controls!B15 | C15: 12 | D15: 11 | E15: 1 | F15: YES | G15: YES
A16: M10 | B16: Controls!B16 | C16: 72 | D16: 71 | E16: 1 | F16: YES | G16: YES
A17: M11 | B17: Controls!B17 | C17: 12 | D17: 11 | E17: 1 | F17: YES | G17: YES
A18: M12 | B18: Controls!B18 | C18: 24 | D18: 23 | E18: 1 | F18: YES | G18: YES
... A26: M20 | B26: Controls!B39 | C26: 0 | D26: 1 | E26: 1 | F26: YES | G26: YES

Sheet Audit
A2: Terminal candidate-requirement audit
A4: Passing checks prove internal completeness and conservation only. They create no firm, article, evidence, capability, production or exterior authority.
A6: Audit | B6: Observed | C6: Expected | D6: Difference | E6: State
A7: systems | B7: =Controls!B7 -> 6 | C7: 6 | D7: =B7-C7 -> 0 | E7: =IF(ABS(D7)<0.000001,"PASS","FAIL") -> PASS
A8: packages control | B8: =Controls!B8 -> 6 | C8: 6 | D8: =B8-C8 -> 0 | E8: =IF(ABS(D8)<0.000001,"PASS","FAIL") -> PASS
A9: package rows | B9: =COUNTA('Candidate Articles'!A7:A12) -> 6 | C9: 6 | D9: =B9-C9 -> 0 | E9: =IF(ABS(D9)<0.000001,"PASS","FAIL") -> PASS
A10: clauses per package | B10: =Controls!B9 -> 16 | C10: 16 | D10: =B10-C10 -> 0 | E10: =IF(ABS(D10)<0.000001,"PASS","FAIL") -> PASS
A11: package clauses control | B11: =Controls!B10 -> 96 | C11: 96 | D11: =B11-C11 -> 0 | E11: =IF(ABS(D11)<0.000001,"PASS","FAIL") -> PASS
A12: package clause rows | B12: =COUNTA('Package Grammar'!A7:A102) -> 96 | C12: 96 | D12: =B12-C12 -> 0 | E12: =IF(ABS(D12)<0.000001,"PASS","FAIL") -> PASS
A13: loads per package | B13: =Controls!B11 -> 12 | C13: 12 | D13: =B13-C13 -> 0 | E13: =IF(ABS(D13)<0.000001,"PASS","FAIL") -> PASS
A14: form-load control | B14: =Controls!B12 -> 72 | C14: 72 | D14: =B14-C14 -> 0 | E14: =IF(ABS(D14)<0.000001,"PASS","FAIL") -> PASS
A15: form-load rows | B15: =COUNTA('Form Loads'!A7:A78) -> 72 | C15: 72 | D15: =B15-C15 -> 0 | E15: =IF(ABS(D15)<0.000001,"PASS","FAIL") -> PASS
A16: form-load observations empty | B16: =COUNTIF('Form Loads'!K7:K78,"SOURCE EMPTY") -> 72 | C16: 72 | D16: =B16-C16 -> 0 | E16: =IF(ABS(D16)<0.000001,"PASS","FAIL") -> PASS
A17: form-load credit zero | B17: =SUM('Form Loads'!L7:L78) -> 0 | C17: 0 | D17: =B17-C17 -> 0 | E17: =IF(ABS(D17)<0.000001,"PASS","FAIL") -> PASS
A18: interfaces per package | B18: =Controls!B13 -> 8 | C18: 8 | D18: =B18-C18 -> 0 | E18: =IF(ABS(D18)<0.000001,"PASS","FAIL") -> PASS
A19: interface control | B19: =Controls!B14 -> 48 | C19: 48 | D19: =B19-C19 -> 0 | E19: =IF(ABS(D19)<0.000001,"PASS","FAIL") -> PASS
A20: interface rows | B20: =COUNTA(Interfaces!A7:A54) -> 48 | C20: 48 | D20: =B20-C20 -> 0 | E20: =IF(ABS(D20)<0.000001,"PASS","FAIL") -> PASS
A21: interface observations empty | B21: =COUNTIF(Interfaces!I7:I54,"SOURCE EMPTY") -> 48 | C21: 48 | D21: =B21-C21 -> 0 | E21: =IF(ABS(D21)<0.000001,"PASS","FAIL") -> PASS
A22: interface credit zero | B22: =SUM(Interfaces!J7:J54) -> 0 | C22: 0 | D22: =B22-C22 -> 0 | E22: =IF(ABS(D22)<0.000001,"PASS","FAIL") -> PASS
A23: denials per package | B23: =Controls!B15 -> 12 | C23: 12 | D23: =B23-C23 -> 0 | E23: =IF(ABS(D23)<0.000001,"PASS","FAIL") -> PASS
A24: denial control | B24: =Controls!B16 -> 72 | C24: 72 | D24: =B24-C24 -> 0 | E24: =IF(ABS(D24)<0.000001,"PASS","FAIL") -> PASS
A25: denial rows | B25: =COUNTA('Denial Worlds'!A7:A78) -> 72 | C25: 72 | D25: =B25-C25 -> 0 | E25: =IF(ABS(D25)<0.000001,"PASS","FAIL") -> PASS
A26: denial observations empty | B26: =COUNTIF('Denial Worlds'!I7:I78,"SOURCE EMPTY") -> 72 | C26: 72 | D26: =B26-C26 -> 0 | E26: =IF(ABS(D26)<0.000001,"PASS","FAIL") -> PASS
A27: denial credit zero | B27: =SUM('Denial Worlds'!J7:J78) -> 0 | C27: 0 | D27: =B27-C27 -> 0 | E27: =IF(ABS(D27)<0.000001,"PASS","FAIL") -> PASS
A28: endpoint control | B28: =Controls!B17 -> 12 | C28: 12 | D28: =B28-C28 -> 0 | E28: =IF(ABS(D28)<0.000001,"PASS","FAIL") -> PASS
A29: endpoint rows | B29: =COUNTA('Endpoint Rules'!A7:A18) -> 12 | C29: 12 | D29: =B29-C29 -> 0 | E29: =IF(ABS(D29)<0.000001,"PASS","FAIL") -> PASS
A30: balance endpoints | B30: =COUNTIF('Endpoint Rules'!D7:D18,"BALANCE") -> 6 | C30: 6 | D30: =B30-C30 -> 0 | E30: =IF(ABS(D30)<0.000001,"PASS","FAIL") -> PASS
A31: keystone endpoints | B31: =COUNTIF('Endpoint Rules'!D7:D18,"KEYSTONE") -> 6 | C31: 6 | D31: =B31-C31 -> 0 | E31: =IF(ABS(D31)<0.000001,"PASS","FAIL") -> PASS
A32: endpoint evidence empty | B32: =COUNTIF('Endpoint Rules'!J7:J18,"SOURCE EMPTY") -> 12 | C32: 12 | D32: =B32-C32 -> 0 | E32: =IF(ABS(D32)<0.000001,"PASS","FAIL") -> PASS
A33: endpoint credit zero | B33: =SUM('Endpoint Rules'!L7:L18) -> 0 | C33: 0 | D33: =B33-C33 -> 0 | E33: =IF(ABS(D33)<0.000001,"PASS","FAIL") -> PASS
A34: technology control | B34: =Controls!B18 -> 24 | C34: 24 | D34: =B34-C34 -> 0 | E34: =IF(ABS(D34)<0.000001,"PASS","FAIL") -> PASS
A35: technology rows | B35: =COUNTA('Technology Campaigns'!A7:A30) -> 24 | C35: 24 | D35: =B35-C35 -> 0 | E35: =IF(ABS(D35)<0.000001,"PASS","FAIL") -> PASS
A36: technology ceiling | B36: =SUM('Technology Campaigns'!H7:H30) -> 3.5869128 | C36: 3.5869128 | D36: =B36-C36 -> 0 | E36: =IF(ABS(D36)<0.000001,"PASS","FAIL") -> PASS
A37: technology evidence open | B37: =COUNTIF('Technology Campaigns'!L7:L30,"OPEN") -> 24 | C37: 24 | D37: =B37-C37 -> 0 | E37: =IF(ABS(D37)<0.000001,"PASS","FAIL") -> PASS
A38: release gate control | B38: =Controls!B19 -> 72 | C38: 72 | D38: =B38-C38 -> 0 | E38: =IF(ABS(D38)<0.000001,"PASS","FAIL") -> PASS
A39: release gate rows | B39: =COUNTA('Release Gates'!A7:A78) -> 72 | C39: 72 | D39: =B39-C39 -> 0 | E39: =IF(ABS(D39)<0.000001,"PASS","FAIL") -> PASS
A40: constituted gate control | B40: =Controls!B20 -> 30 | C40: 30 | D40: =B40-C40 -> 0 | E40: =IF(ABS(D40)<0.000001,"PASS","FAIL") -> PASS
A41: constituted gate rows | B41: =COUNTIF('Release Gates'!F7:F78,"CONSTITUTED") -> 30 | C41: 30 | D41: =B41-C41 -> 0 | E41: =IF(ABS(D41)<0.000001,"PASS","FAIL") -> PASS
A42: open gate control | B42: =Controls!B21 -> 42 | C42: 42 | D42: =B42-C42 -> 0 | E42: =IF(ABS(D42)<0.000001,"PASS","FAIL") -> PASS
A43: open gate rows | B43: =COUNTIF('Release Gates'!F7:F78,"OPEN") -> 42 | C43: 42 | D43: =B43-C43 -> 0 | E43: =IF(ABS(D43)<0.000001,"PASS","FAIL") -> PASS
...

Sheet Sources & Limits
A2: Internal authorities and model limits
A4: Only internal repository authorities are used. Every physical coefficient remains a controlled hypothesis until representative evidence closes it.
A6: Source | B6: Repository artifact | C6: Use | D6: Status | E6: Limitation
A7: A2C-5 | B7: National First Sentinel Construction Compact | C7: returned authority and private options | D7: authoritative | E7: no implementation records
A8: PFP-3 | B8: First Six-System Requirement Cohort | C8: public denominators and selected problem fields | D8: authoritative | E8: no candidate performance
A9: A2C-1 | B9: Six-Root Sentinel Wave | C9: selected roots, endpoints and cancellation law | D9: authoritative | E9: selection is not promise
A10: A2C-2 | B10: Sovereign Truth Trains | C10: full-scale causal interfaces and denied conditions | D10: authoritative | E10: rig configuration is not article form
A11: C3-SPW-3 | B11: Twenty Non-Lifeline Root Physical Balances | C11: parent mass, energy, labor, receiver and residual context | D11: controlled hypothesis | E11: coefficients unobserved
A12: C3-LFG3-1 | B12: Lifeline Four-Root Configuration | C12: IGT-50 source, water, power, thermal and corridor balances | D12: controlled hypothesis | E12: geology and rates unobserved
A13: Model boundary | B13: this workbook | C13: requirement completeness, finance and release checks | D13: planning only | E13: no sites used; no exterior produced
A14: Evidence boundary | B14: all observation fields | C14: deliberate source-empty state | D14: not available | E14: no physical event has run
