Workbook

Sheet Summary
A2: Six-root representation boundary and form-authority return
A4: Decision | B4: Value | C4: Unit | D4: State
A5: representation classes | B5: =COUNTA('Representation Ladder'!A7:A14) -> 8 | C5: count | D5: CONSTITUTED | F5: Decision The blanket prohibition on rendering has completed its purpose. Before performance evidence, the Department may publish service maps, causal diagrams, instrumented test sections and one equal-salience set of three mechanically divergent whole-form hypotheses per root. Every hypothesis must expose uncertainty and remain unselected. As-built records, evidence-qualified candidate exteriors, mission configurations and fleet imagery remain held.
A6: root-class records | B6: =COUNTA('Representation Register'!A7:A54) -> 48 | C6: count | D6: COMPLETE
A7: currently authorized records | B7: =SUM('Representation Register'!H7:H54) -> 24 | C7: count | D7: NOT ISSUED
A8: held records | B8: =COUNTIFS('Representation Register'!M7:M54,"HELD") -> 24 | C8: count | D8: EVIDENCE OR WARRANT REQUIRED
A9: rival form hypotheses | B9: =COUNTA('Hypothesis Sets'!A7:A24) -> 18 | C9: count | D9: AUTHORIZED / NOT ISSUED
A10: selected hypotheses | B10: =SUM('Hypothesis Sets'!K7:K24) -> 0 | C10: count | D10: ZERO
A11: incremental ceiling | B11: =Finance!G13 -> 0 | C11: USD B | D11: ZERO
A12: physical observations | B12: =Controls!B22 -> 0 | C12: count | D12: ZERO
A15: Class | B15: Artifact | C15: Minimum variants | D15: Eligible roots | E15: Issued | F15: Claim ceiling
A16: ='Representation Ladder'!A7 -> REP-0 | B16: ='Representation Ladder'!C7 -> Service condition record | C16: ='Representation Ladder'!E7 -> 1 | D16: ='Representation Ladder'!N7 -> 6 | E16: ='Representation Ladder'!O7 -> 0 | F16: ='Representation Ladder'!M7 -> service need only
A17: ='Representation Ladder'!A8 -> REP-1 | B17: ='Representation Ladder'!C8 -> Causal topology | C17: ='Representation Ladder'!E8 -> 1 | D17: ='Representation Ladder'!N8 -> 6 | E17: ='Representation Ladder'!O8 -> 0 | F17: ='Representation Ladder'!M8 -> relationships and flows
A18: ='Representation Ladder'!A9 -> REP-2 | B18: ='Representation Ladder'!C9 -> Instrumented falsification section | C18: ='Representation Ladder'!E9 -> 1 | D18: ='Representation Ladder'!N9 -> 6 | E18: ='Representation Ladder'!O9 -> 0 | F18: ='Representation Ladder'!M9 -> test geometry only
A19: ='Representation Ladder'!A10 -> REP-3 | B19: ='Representation Ladder'!C10 -> Equal-salience rival form set | C19: ='Representation Ladder'!E10 -> 3 | D19: ='Representation Ladder'!N10 -> 6 | E19: ='Representation Ladder'!O10 -> 0 | F19: ='Representation Ladder'!M10 -> whole form as unselected hypothesis
A20: ='Representation Ladder'!A11 -> REP-4 | B20: ='Representation Ladder'!C11 -> As-built experimental record | C20: ='Representation Ladder'!E11 -> 1 | D20: ='Representation Ladder'!N11 -> 0 | E20: ='Representation Ladder'!O11 -> 0 | F20: ='Representation Ladder'!M11 -> actual test article only
A21: ='Representation Ladder'!A12 -> REP-5 | B21: ='Representation Ladder'!C12 -> Evidence-qualified candidate form | C21: ='Representation Ladder'!E12 -> 1 | D21: ='Representation Ladder'!N12 -> 0 | E21: ='Representation Ladder'!O12 -> 0 | F21: ='Representation Ladder'!M12 -> one supported root configuration
A22: ='Representation Ladder'!A13 -> REP-6 | B22: ='Representation Ladder'!C13 -> Complete mission configuration | C22: ='Representation Ladder'!E13 -> 1 | D22: ='Representation Ladder'!N13 -> 0 | E22: ='Representation Ladder'!O13 -> 0 | F22: ='Representation Ladder'!M13 -> one supported mission chain
A23: ='Representation Ladder'!A14 -> REP-7 | B23: ='Representation Ladder'!C14 -> Production and fleet exterior | C23: ='Representation Ladder'!E14 -> 1 | D23: ='Representation Ladder'!N14 -> 0 | E23: ='Representation Ladder'!O14 -> 0 | F23: ='Representation Ladder'!M14 -> produced and ready configuration

Sheet Controls
A2: Representation and authority controls
A4: Blue values are controlled constitutional inputs. Zero evidence and implementation states are real holds, not missing values converted to zero.
A6: Control | B6: Value | C6: Unit | D6: Authority
A7: roots | B7: 6 | C7: count | D7: Pass 216
A8: accounts per root | B8: 6 | C8: count | D8: Pass 217
A9: worlds per account | B9: 4 | C9: count | D9: Pass 217
A10: cells required per root | B10: 24 | C10: count | D10: direct arithmetic
A11: design-close cells | B11: 60 | C11: count | D11: Pass 219
A12: measurement-ready cells | B12: 84 | C12: count | D12: Pass 219
A13: measurement specifications | B13: 85 | C13: count | D13: Pass 219
A14: minimum rival hypotheses per root | B14: 3 | C14: count | D14: Pass 220 decision
A15: hypothesis representation authority | B15: 1 | C15: binary | D15: Pass 220 narrow release
A16: selected exterior authority | B16: 0 | C16: binary | D16: held
A17: production exterior authority | B17: 0 | C17: binary | D17: held
A18: representation artifacts issued | B18: 0 | C18: count | D18: none created in this pass
... A30: paid authority | B30: 0 | C30: USD B | D30: held

Sheet Root Register
A2: Six root states at the form boundary
A4: The first four predicates authorize hypothesis work. Every physical, evidentiary, production and readiness predicate remains empty.
A6: System | B6: Root | C6: Article | D6: Option ceiling USD B | E6: Requirement constituted | F6: Section frozen | G6: Protocols complete | H6: Rival-set grammar | I6: Built serial | J6: As-built metrology | K6: Accepted cells | L6: Cells required | M6: SURVIVE disposition | N6: Cold return | O6: Mission evidence | P6: Production warrant | Q6: Readiness warrant | R6: Controlling section
A7: MS-ET | B7: ET-A | C7: Pelagic exchange cell | D7: 0.50047462 | E7: 1 | F7: 1 | G7: 1 | H7: 1 | I7: 0 | J7: 0 | K7: 0 | L7: 24 | M7: 0 | N7: 0 | O7: 0 | P7: 0 | Q7: 0 | R7: two complete motion-decoupled exchange paths
A8: MS-CT | B8: CT-C | C8: Occupied-building utility-spine sector | D8: 0.51649348 | E8: 1 | F8: 1 | G8: 1 | H8: 1 | I8: 0 | J8: 0 | K8: 0 | L8: 24 | M8: 0 | N8: 0 | O8: 0 | P8: 0 | Q8: 0 | R8: seven isolated energy cells and five fault-contained trunks
A9: MS-HC | B9: HC-A | C9: Atmospheric intervention cell | D9: 0.30722165 | E9: 1 | F9: 1 | G9: 1 | H9: 1 | I9: 0 | J9: 0 | K9: 0 | L9: 24 | M9: 0 | N9: 0 | O9: 0 | P9: 0 | Q9: 0 | R9: five attributable held-line sectors and eight energy cells
A10: MS-LF | B10: LF-B | C10: Geothermal source position | D10: 0.89941282 | E10: 1 | F10: 1 | G10: 1 | H10: 1 | I10: 0 | J10: 0 | K10: 0 | L10: 24 | M10: 0 | N10: 0 | O10: 0 | P10: 0 | Q10: 0 | R10: nine access slots, four conversion cells, two water paths and paired three-cell trains
A11: MS-HU | B11: HU-A | C11: Complete clinical island | D11: 0.86071245 | E11: 1 | F11: 1 | G11: 1 | H11: 1 | I11: 0 | J11: 0 | K11: 0 | L11: 24 | M11: 0 | N11: 0 | O11: 0 | P11: 0 | Q11: 0 | R11: eight access cells, ten care lines and six utility cells
A12: MS-RT | B12: RT-B | C12: Disconnected microfactory mesh | D12: 0.50259779 | E12: 1 | F12: 1 | G12: 1 | H12: 1 | I12: 0 | J12: 0 | K12: 0 | L12: 24 | M12: 0 | N12: 0 | O12: 0 | P12: 0 | Q12: 0 | R12: seven process-energy cells and five complete process meshes

Sheet Representation Ladder
A2: Eight representation classes and their claim ceilings
A4: The blanket rendering ban ends only for equal-salience hypothesis sets. A supported exterior still requires evidence and cold reconstruction.
A6: Class | B6: Rank | C6: Artifact | D6: Permitted before performance evidence | E6: Minimum variants | F6: Complete outline | G6: Test geometry claim | H6: Performance claim | I6: Mission capacity claim | J6: Production or fleet claim | K6: Entry rule | L6: Rollback trigger | M6: Maximum claim | N6: Eligible roots | O6: Issued artifacts
A7: REP-0 | B7: 0 | C7: Service condition record | D7: 1 | E7: 1 | F7: 0 | G7: 0 | H7: 0 | I7: 0 | J7: 0 | K7: constituted public-service denominator | L7: requirement changes | M7: service need only | N7: =COUNTIFS('Representation Register'!$D$7:$D$54,A7,'Representation Register'!$H$7:$H$54,1) -> 6 | O7: =SUMIFS('Representation Register'!$J$7:$J$54,'Representation Register'!$D$7:$D$54,A7) -> 0
A8: REP-1 | B8: 1 | C8: Causal topology | D8: 1 | E8: 1 | F8: 0 | G8: 0 | H8: 0 | I8: 0 | J8: 0 | K8: frozen boundary, loads, interfaces and denial set | L8: causal section changes | M8: relationships and flows | N8: =COUNTIFS('Representation Register'!$D$7:$D$54,A8,'Representation Register'!$H$7:$H$54,1) -> 6 | O8: =SUMIFS('Representation Register'!$J$7:$J$54,'Representation Register'!$D$7:$D$54,A8) -> 0
A9: REP-2 | B9: 2 | C9: Instrumented falsification section | D9: 1 | E9: 1 | F9: 0 | G9: 1 | H9: 0 | I9: 0 | J9: 0 | K9: complete section bills and executable protocols | L9: section bill or protocol changes | M9: test geometry only | N9: =COUNTIFS('Representation Register'!$D$7:$D$54,A9,'Representation Register'!$H$7:$H$54,1) -> 6 | O9: =SUMIFS('Representation Register'!$J$7:$J$54,'Representation Register'!$D$7:$D$54,A9) -> 0
A10: REP-3 | B10: 3 | C10: Equal-salience rival form set | D10: 1 | E10: 3 | F10: 1 | G10: 1 | H10: 0 | I10: 0 | J10: 0 | K10: REP-2 plus three mechanically divergent hypotheses | L10: set loses plurality, equality or uncertainty marking | M10: whole form as unselected hypothesis | N10: =COUNTIFS('Representation Register'!$D$7:$D$54,A10,'Representation Register'!$H$7:$H$54,1) -> 6 | O10: =SUMIFS('Representation Register'!$J$7:$J$54,'Representation Register'!$D$7:$D$54,A10) -> 0
A11: REP-4 | B11: 4 | C11: As-built experimental record | D11: 0 | E11: 1 | F11: 1 | G11: 1 | H11: 0 | I11: 0 | J11: 0 | K11: serialized article and accepted as-built metrology | L11: article changes after record | M11: actual test article only | N11: =COUNTIFS('Representation Register'!$D$7:$D$54,A11,'Representation Register'!$H$7:$H$54,1) -> 0 | O11: =SUMIFS('Representation Register'!$J$7:$J$54,'Representation Register'!$D$7:$D$54,A11) -> 0
A12: REP-5 | B12: 5 | C12: Evidence-qualified candidate form | D12: 0 | E12: 1 | F12: 1 | G12: 1 | H12: 1 | I12: 0 | J12: 0 | K12: 24 accepted cells, SURVIVE disposition and cold return | L12: evidence or independence reverses | M12: one supported root configuration | N12: =COUNTIFS('Representation Register'!$D$7:$D$54,A12,'Representation Register'!$H$7:$H$54,1) -> 0 | O12: =SUMIFS('Representation Register'!$J$7:$J$54,'Representation Register'!$D$7:$D$54,A12) -> 0
A13: REP-6 | B13: 6 | C13: Complete mission configuration | D13: 0 | E13: 1 | F13: 1 | G13: 1 | H13: 1 | I13: 1 | J13: 0 | K13: REP-5 plus route-complete mission evidence | L13: receiver or interface evidence reverses | M13: one supported mission chain | N13: =COUNTIFS('Representation Register'!$D$7:$D$54,A13,'Representation Register'!$H$7:$H$54,1) -> 0 | O13: =SUMIFS('Representation Register'!$J$7:$J$54,'Representation Register'!$D$7:$D$54,A13) -> 0
A14: REP-7 | B14: 7 | C14: Production and fleet exterior | D14: 0 | E14: 1 | F14: 1 | G14: 1 | H14: 1 | I14: 1 | J14: 1 | K14: REP-6 plus production and readiness warrants | L14: baseline or readiness warrant rolls back | M14: produced and ready configuration | N14: =COUNTIFS('Representation Register'!$D$7:$D$54,A14,'Representation Register'!$H$7:$H$54,1) -> 0 | O14: =SUMIFS('Representation Register'!$J$7:$J$54,'Representation Register'!$D$7:$D$54,A14) -> 0

Sheet Representation Register
A2: Forty-eight root-by-class authority records
A4: Authorization allows a bounded artifact to be commissioned. It does not mean an artifact exists, has been accepted or can support a higher claim.
A6: Record | B6: System | C6: Root | D6: Class | E6: Artifact | F6: Rank | G6: Prerequisites satisfied | H6: Current authorization | I6: Minimum variants | J6: Issued | K6: Accepted | L6: Maximum claim | M6: State | N6: Rollback
A7: ET-A-REP-0 | B7: MS-ET | C7: ET-A | D7: REP-0 | E7: Service condition record | F7: 0 | G7: ='Root Register'!E7 -> 1 | H7: =G7 -> 1 | I7: 1 | J7: 0 | K7: 0 | L7: service need only | M7: =IF(H7=1,IF(J7=0,"AUTHORIZED / NOT ISSUED",IF(K7=J7,"ISSUED / ACCEPTED","ISSUED / REVIEW")),"HELD") -> AUTHORIZED / NOT ISSUED | N7: requirement changes
A8: ET-A-REP-1 | B8: MS-ET | C8: ET-A | D8: REP-1 | E8: Causal topology | F8: 1 | G8: =MIN('Root Register'!E7:F7) -> 1 | H8: =G8 -> 1 | I8: 1 | J8: 0 | K8: 0 | L8: relationships and flows | M8: =IF(H8=1,IF(J8=0,"AUTHORIZED / NOT ISSUED",IF(K8=J8,"ISSUED / ACCEPTED","ISSUED / REVIEW")),"HELD") -> AUTHORIZED / NOT ISSUED | N8: causal section changes
A9: ET-A-REP-2 | B9: MS-ET | C9: ET-A | D9: REP-2 | E9: Instrumented falsification section | F9: 2 | G9: =MIN('Root Register'!E7:G7) -> 1 | H9: =G9 -> 1 | I9: 1 | J9: 0 | K9: 0 | L9: test geometry only | M9: =IF(H9=1,IF(J9=0,"AUTHORIZED / NOT ISSUED",IF(K9=J9,"ISSUED / ACCEPTED","ISSUED / REVIEW")),"HELD") -> AUTHORIZED / NOT ISSUED | N9: section bill or protocol changes
A10: ET-A-REP-3 | B10: MS-ET | C10: ET-A | D10: REP-3 | E10: Equal-salience rival form set | F10: 3 | G10: =MIN('Root Register'!E7:H7) -> 1 | H10: =G10 -> 1 | I10: 3 | J10: 0 | K10: 0 | L10: whole form as unselected hypothesis | M10: =IF(H10=1,IF(J10=0,"AUTHORIZED / NOT ISSUED",IF(K10=J10,"ISSUED / ACCEPTED","ISSUED / REVIEW")),"HELD") -> AUTHORIZED / NOT ISSUED | N10: set loses plurality, equality or uncertainty marking
A11: ET-A-REP-4 | B11: MS-ET | C11: ET-A | D11: REP-4 | E11: As-built experimental record | F11: 4 | G11: =MIN('Root Register'!I7:J7) -> 0 | H11: =G11 -> 0 | I11: 1 | J11: 0 | K11: 0 | L11: actual test article only | M11: =IF(H11=1,IF(J11=0,"AUTHORIZED / NOT ISSUED",IF(K11=J11,"ISSUED / ACCEPTED","ISSUED / REVIEW")),"HELD") -> HELD | N11: article changes after record
A12: ET-A-REP-5 | B12: MS-ET | C12: ET-A | D12: REP-5 | E12: Evidence-qualified candidate form | F12: 5 | G12: =IF(AND('Root Register'!K7='Root Register'!L7,'Root Register'!M7=1,'Root Register'!N7=1),1,0) -> 0 | H12: =G12 -> 0 | I12: 1 | J12: 0 | K12: 0 | L12: one supported root configuration | M12: =IF(H12=1,IF(J12=0,"AUTHORIZED / NOT ISSUED",IF(K12=J12,"ISSUED / ACCEPTED","ISSUED / REVIEW")),"HELD") -> HELD | N12: evidence or independence reverses
A13: ET-A-REP-6 | B13: MS-ET | C13: ET-A | D13: REP-6 | E13: Complete mission configuration | F13: 6 | G13: =IF(AND('Root Register'!K7='Root Register'!L7,'Root Register'!M7=1,'Root Register'!N7=1,'Root Register'!O7=1),1,0) -> 0 | H13: =G13 -> 0 | I13: 1 | J13: 0 | K13: 0 | L13: one supported mission chain | M13: =IF(H13=1,IF(J13=0,"AUTHORIZED / NOT ISSUED",IF(K13=J13,"ISSUED / ACCEPTED","ISSUED / REVIEW")),"HELD") -> HELD | N13: receiver or interface evidence reverses
A14: ET-A-REP-7 | B14: MS-ET | C14: ET-A | D14: REP-7 | E14: Production and fleet exterior | F14: 7 | G14: =IF(AND('Root Register'!K7='Root Register'!L7,'Root Register'!M7=1,'Root Register'!N7=1,'Root Register'!O7=1,'Root Register'!P7=1,'Root Register'!Q7=1),1,0) -> 0 | H14: =G14 -> 0 | I14: 1 | J14: 0 | K14: 0 | L14: produced and ready configuration | M14: =IF(H14=1,IF(J14=0,"AUTHORIZED / NOT ISSUED",IF(K14=J14,"ISSUED / ACCEPTED","ISSUED / REVIEW")),"HELD") -> HELD | N14: baseline or readiness warrant rolls back
A15: CT-C-REP-0 | B15: MS-CT | C15: CT-C | D15: REP-0 | E15: Service condition record | F15: 0 | G15: ='Root Register'!E8 -> 1 | H15: =G15 -> 1 | I15: 1 | J15: 0 | K15: 0 | L15: service need only | M15: =IF(H15=1,IF(J15=0,"AUTHORIZED / NOT ISSUED",IF(K15=J15,"ISSUED / ACCEPTED","ISSUED / REVIEW")),"HELD") -> AUTHORIZED / NOT ISSUED | N15: requirement changes
A16: CT-C-REP-1 | B16: MS-CT | C16: CT-C | D16: REP-1 | E16: Causal topology | F16: 1 | G16: =MIN('Root Register'!E8:F8) -> 1 | H16: =G16 -> 1 | I16: 1 | J16: 0 | K16: 0 | L16: relationships and flows | M16: =IF(H16=1,IF(J16=0,"AUTHORIZED / NOT ISSUED",IF(K16=J16,"ISSUED / ACCEPTED","ISSUED / REVIEW")),"HELD") -> AUTHORIZED / NOT ISSUED | N16: causal section changes
A17: CT-C-REP-2 | B17: MS-CT | C17: CT-C | D17: REP-2 | E17: Instrumented falsification section | F17: 2 | G17: =MIN('Root Register'!E8:G8) -> 1 | H17: =G17 -> 1 | I17: 1 | J17: 0 | K17: 0 | L17: test geometry only | M17: =IF(H17=1,IF(J17=0,"AUTHORIZED / NOT ISSUED",IF(K17=J17,"ISSUED / ACCEPTED","ISSUED / REVIEW")),"HELD") -> AUTHORIZED / NOT ISSUED | N17: section bill or protocol changes
A18: CT-C-REP-3 | B18: MS-CT | C18: CT-C | D18: REP-3 | E18: Equal-salience rival form set | F18: 3 | G18: =MIN('Root Register'!E8:H8) -> 1 | H18: =G18 -> 1 | I18: 3 | J18: 0 | K18: 0 | L18: whole form as unselected hypothesis | M18: =IF(H18=1,IF(J18=0,"AUTHORIZED / NOT ISSUED",IF(K18=J18,"ISSUED / ACCEPTED","ISSUED / REVIEW")),"HELD") -> AUTHORIZED / NOT ISSUED | N18: set loses plurality, equality or uncertainty marking
A19: CT-C-REP-4 | B19: MS-CT | C19: CT-C | D19: REP-4 | E19: As-built experimental record | F19: 4 | G19: =MIN('Root Register'!I8:J8) -> 0 | H19: =G19 -> 0 | I19: 1 | J19: 0 | K19: 0 | L19: actual test article only | M19: =IF(H19=1,IF(J19=0,"AUTHORIZED / NOT ISSUED",IF(K19=J19,"ISSUED / ACCEPTED","ISSUED / REVIEW")),"HELD") -> HELD | N19: article changes after record
A20: CT-C-REP-5 | B20: MS-CT | C20: CT-C | D20: REP-5 | E20: Evidence-qualified candidate form | F20: 5 | G20: =IF(AND('Root Register'!K8='Root Register'!L8,'Root Register'!M8=1,'Root Register'!N8=1),1,0) -> 0 | H20: =G20 -> 0 | I20: 1 | J20: 0 | K20: 0 | L20: one supported root configuration | M20: =IF(H20=1,IF(J20=0,"AUTHORIZED / NOT ISSUED",IF(K20=J20,"ISSUED / ACCEPTED","ISSUED / REVIEW")),"HELD") -> HELD | N20: evidence or independence reverses
A21: CT-C-REP-6 | B21: MS-CT | C21: CT-C | D21: REP-6 | E21: Complete mission configuration | F21: 6 | G21: =IF(AND('Root Register'!K8='Root Register'!L8,'Root Register'!M8=1,'Root Register'!N8=1,'Root Register'!O8=1),1,0) -> 0 | H21: =G21 -> 0 | I21: 1 | J21: 0 | K21: 0 | L21: one supported mission chain | M21: =IF(H21=1,IF(J21=0,"AUTHORIZED / NOT ISSUED",IF(K21=J21,"ISSUED / ACCEPTED","ISSUED / REVIEW")),"HELD") -> HELD | N21: receiver or interface evidence reverses
A22: CT-C-REP-7 | B22: MS-CT | C22: CT-C | D22: REP-7 | E22: Production and fleet exterior | F22: 7 | G22: =IF(AND('Root Register'!K8='Root Register'!L8,'Root Register'!M8=1,'Root Register'!N8=1,'Root Register'!O8=1,'Root Register'!P8=1,'Root Register'!Q8=1),1,0) -> 0 | H22: =G22 -> 0 | I22: 1 | J22: 0 | K22: 0 | L22: produced and ready configuration | M22: =IF(H22=1,IF(J22=0,"AUTHORIZED / NOT ISSUED",IF(K22=J22,"ISSUED / ACCEPTED","ISSUED / REVIEW")),"HELD") -> HELD | N22: baseline or readiness warrant rolls back
A23: HC-A-REP-0 | B23: MS-HC | C23: HC-A | D23: REP-0 | E23: Service condition record | F23: 0 | G23: ='Root Register'!E9 -> 1 | H23: =G23 -> 1 | I23: 1 | J23: 0 | K23: 0 | L23: service need only | M23: =IF(H23=1,IF(J23=0,"AUTHORIZED / NOT ISSUED",IF(K23=J23,"ISSUED / ACCEPTED","ISSUED / REVIEW")),"HELD") -> AUTHORIZED / NOT ISSUED | N23: requirement changes
A24: HC-A-REP-1 | B24: MS-HC | C24: HC-A | D24: REP-1 | E24: Causal topology | F24: 1 | G24: =MIN('Root Register'!E9:F9) -> 1 | H24: =G24 -> 1 | I24: 1 | J24: 0 | K24: 0 | L24: relationships and flows | M24: =IF(H24=1,IF(J24=0,"AUTHORIZED / NOT ISSUED",IF(K24=J24,"ISSUED / ACCEPTED","ISSUED / REVIEW")),"HELD") -> AUTHORIZED / NOT ISSUED | N24: causal section changes
A25: HC-A-REP-2 | B25: MS-HC | C25: HC-A | D25: REP-2 | E25: Instrumented falsification section | F25: 2 | G25: =MIN('Root Register'!E9:G9) -> 1 | H25: =G25 -> 1 | I25: 1 | J25: 0 | K25: 0 | L25: test geometry only | M25: =IF(H25=1,IF(J25=0,"AUTHORIZED / NOT ISSUED",IF(K25=J25,"ISSUED / ACCEPTED","ISSUED / REVIEW")),"HELD") -> AUTHORIZED / NOT ISSUED | N25: section bill or protocol changes
A26: HC-A-REP-3 | B26: MS-HC | C26: HC-A | D26: REP-3 | E26: Equal-salience rival form set | F26: 3 | G26: =MIN('Root Register'!E9:H9) -> 1 | H26: =G26 -> 1 | I26: 3 | J26: 0 | K26: 0 | L26: whole form as unselected hypothesis | M26: =IF(H26=1,IF(J26=0,"AUTHORIZED / NOT ISSUED",IF(K26=J26,"ISSUED / ACCEPTED","ISSUED / REVIEW")),"HELD") -> AUTHORIZED / NOT ISSUED | N26: set loses plurality, equality or uncertainty marking
A27: HC-A-REP-4 | B27: MS-HC | C27: HC-A | D27: REP-4 | E27: As-built experimental record | F27: 4 | G27: =MIN('Root Register'!I9:J9) -> 0 | H27: =G27 -> 0 | I27: 1 | J27: 0 | K27: 0 | L27: actual test article only | M27: =IF(H27=1,IF(J27=0,"AUTHORIZED / NOT ISSUED",IF(K27=J27,"ISSUED / ACCEPTED","ISSUED / REVIEW")),"HELD") -> HELD | N27: article changes after record
A28: HC-A-REP-5 | B28: MS-HC | C28: HC-A | D28: REP-5 | E28: Evidence-qualified candidate form | F28: 5 | G28: =IF(AND('Root Register'!K9='Root Register'!L9,'Root Register'!M9=1,'Root Register'!N9=1),1,0) -> 0 | H28: =G28 -> 0 | I28: 1 | J28: 0 | K28: 0 | L28: one supported root configuration | M28: =IF(H28=1,IF(J28=0,"AUTHORIZED / NOT ISSUED",IF(K28=J28,"ISSUED / ACCEPTED","ISSUED / REVIEW")),"HELD") -> HELD | N28: evidence or independence reverses
A29: HC-A-REP-6 | B29: MS-HC | C29: HC-A | D29: REP-6 | E29: Complete mission configuration | F29: 6 | G29: =IF(AND('Root Register'!K9='Root Register'!L9,'Root Register'!M9=1,'Root Register'!N9=1,'Root Register'!O9=1),1,0) -> 0 | H29: =G29 -> 0 | I29: 1 | J29: 0 | K29: 0 | L29: one supported mission chain | M29: =IF(H29=1,IF(J29=0,"AUTHORIZED / NOT ISSUED",IF(K29=J29,"ISSUED / ACCEPTED","ISSUED / REVIEW")),"HELD") -> HELD | N29: receiver or interface evidence reverses
A30: HC-A-REP-7 | B30: MS-HC | C30: HC-A | D30: REP-7 | E30: Production and fleet exterior | F30: 7 | G30: =IF(AND('Root Register'!K9='Root Register'!L9,'Root Register'!M9=1,'Root Register'!N9=1,'Root Register'!O9=1,'Root Register'!P9=1,'Root Register'!Q9=1),1,0) -> 0 | H30: =G30 -> 0 | I30: 1 | J30: 0 | K30: 0 | L30: produced and ready configuration | M30: =IF(H30=1,IF(J30=0,"AUTHORIZED / NOT ISSUED",IF(K30=J30,"ISSUED / ACCEPTED","ISSUED / REVIEW")),"HELD") -> HELD | N30: baseline or readiness warrant rolls back
A31: LF-B-REP-0 | B31: MS-LF | C31: LF-B | D31: REP-0 | E31: Service condition record | F31: 0 | G31: ='Root Register'!E10 -> 1 | H31: =G31 -> 1 | I31: 1 | J31: 0 | K31: 0 | L31: service need only | M31: =IF(H31=1,IF(J31=0,"AUTHORIZED / NOT ISSUED",IF(K31=J31,"ISSUED / ACCEPTED","ISSUED / REVIEW")),"HELD") -> AUTHORIZED / NOT ISSUED | N31: requirement changes
A32: LF-B-REP-1 | B32: MS-LF | C32: LF-B | D32: REP-1 | E32: Causal topology | F32: 1 | G32: =MIN('Root Register'!E10:F10) -> 1 | H32: =G32 -> 1 | I32: 1 | J32: 0 | K32: 0 | L32: relationships and flows | M32: =IF(H32=1,IF(J32=0,"AUTHORIZED / NOT ISSUED",IF(K32=J32,"ISSUED / ACCEPTED","ISSUED / REVIEW")),"HELD") -> AUTHORIZED / NOT ISSUED | N32: causal section changes
A33: LF-B-REP-2 | B33: MS-LF | C33: LF-B | D33: REP-2 | E33: Instrumented falsification section | F33: 2 | G33: =MIN('Root Register'!E10:G10) -> 1 | H33: =G33 -> 1 | I33: 1 | J33: 0 | K33: 0 | L33: test geometry only | M33: =IF(H33=1,IF(J33=0,"AUTHORIZED / NOT ISSUED",IF(K33=J33,"ISSUED / ACCEPTED","ISSUED / REVIEW")),"HELD") -> AUTHORIZED / NOT ISSUED | N33: section bill or protocol changes
A34: LF-B-REP-3 | B34: MS-LF | C34: LF-B | D34: REP-3 | E34: Equal-salience rival form set | F34: 3 | G34: =MIN('Root Register'!E10:H10) -> 1 | H34: =G34 -> 1 | I34: 3 | J34: 0 | K34: 0 | L34: whole form as unselected hypothesis | M34: =IF(H34=1,IF(J34=0,"AUTHORIZED / NOT ISSUED",IF(K34=J34,"ISSUED / ACCEPTED","ISSUED / REVIEW")),"HELD") -> AUTHORIZED / NOT ISSUED | N34: set loses plurality, equality or uncertainty marking
A35: LF-B-REP-4 | B35: MS-LF | C35: LF-B | D35: REP-4 | E35: As-built experimental record | F35: 4 | G35: =MIN('Root Register'!I10:J10) -> 0 | H35: =G35 -> 0 | I35: 1 | J35: 0 | K35: 0 | L35: actual test article only | M35: =IF(H35=1,IF(J35=0,"AUTHORIZED / NOT ISSUED",IF(K35=J35,"ISSUED / ACCEPTED","ISSUED / REVIEW")),"HELD") -> HELD | N35: article changes after record
A36: LF-B-REP-5 | B36: MS-LF | C36: LF-B | D36: REP-5 | E36: Evidence-qualified candidate form | F36: 5 | G36: =IF(AND('Root Register'!K10='Root Register'!L10,'Root Register'!M10=1,'Root Register'!N10=1),1,0) -> 0 | H36: =G36 -> 0 | I36: 1 | J36: 0 | K36: 0 | L36: one supported root configuration | M36: =IF(H36=1,IF(J36=0,"AUTHORIZED / NOT ISSUED",IF(K36=J36,"ISSUED / ACCEPTED","ISSUED / REVIEW")),"HELD") -> HELD | N36: evidence or independence reverses
A37: LF-B-REP-6 | B37: MS-LF | C37: LF-B | D37: REP-6 | E37: Complete mission configuration | F37: 6 | G37: =IF(AND('Root Register'!K10='Root Register'!L10,'Root Register'!M10=1,'Root Register'!N10=1,'Root Register'!O10=1),1,0) -> 0 | H37: =G37 -> 0 | I37: 1 | J37: 0 | K37: 0 | L37: one supported mission chain | M37: =IF(H37=1,IF(J37=0,"AUTHORIZED / NOT ISSUED",IF(K37=J37,"ISSUED / ACCEPTED","ISSUED / REVIEW")),"HELD") -> HELD | N37: receiver or interface evidence reverses
A38: LF-B-REP-7 | B38: MS-LF | C38: LF-B | D38: REP-7 | E38: Production and fleet exterior | F38: 7 | G38: =IF(AND('Root Register'!K10='Root Register'!L10,'Root Register'!M10=1,'Root Register'!N10=1,'Root Register'!O10=1,'Root Register'!P10=1,'Root Register'!Q10=1),1,0) -> 0 | H38: =G38 -> 0 | I38: 1 | J38: 0 | K38: 0 | L38: produced and ready configuration | M38: =IF(H38=1,IF(J38=0,"AUTHORIZED / NOT ISSUED",IF(K38=J38,"ISSUED / ACCEPTED","ISSUED / REVIEW")),"HELD") -> HELD | N38: baseline or readiness warrant rolls back
A39: HU-A-REP-0 | B39: MS-HU | C39: HU-A | D39: REP-0 | E39: Service condition record | F39: 0 | G39: ='Root Register'!E11 -> 1 | H39: =G39 -> 1 | I39: 1 | J39: 0 | K39: 0 | L39: service need only | M39: =IF(H39=1,IF(J39=0,"AUTHORIZED / NOT ISSUED",IF(K39=J39,"ISSUED / ACCEPTED","ISSUED / REVIEW")),"HELD") -> AUTHORIZED / NOT ISSUED | N39: requirement changes
A40: HU-A-REP-1 | B40: MS-HU | C40: HU-A | D40: REP-1 | E40: Causal topology | F40: 1 | G40: =MIN('Root Register'!E11:F11) -> 1 | H40: =G40 -> 1 | I40: 1 | J40: 0 | K40: 0 | L40: relationships and flows | M40: =IF(H40=1,IF(J40=0,"AUTHORIZED / NOT ISSUED",IF(K40=J40,"ISSUED / ACCEPTED","ISSUED / REVIEW")),"HELD") -> AUTHORIZED / NOT ISSUED | N40: causal section changes
A41: HU-A-REP-2 | B41: MS-HU | C41: HU-A | D41: REP-2 | E41: Instrumented falsification section | F41: 2 | G41: =MIN('Root Register'!E11:G11) -> 1 | H41: =G41 -> 1 | I41: 1 | J41: 0 | K41: 0 | L41: test geometry only | M41: =IF(H41=1,IF(J41=0,"AUTHORIZED / NOT ISSUED",IF(K41=J41,"ISSUED / ACCEPTED","ISSUED / REVIEW")),"HELD") -> AUTHORIZED / NOT ISSUED | N41: section bill or protocol changes
A42: HU-A-REP-3 | B42: MS-HU | C42: HU-A | D42: REP-3 | E42: Equal-salience rival form set | F42: 3 | G42: =MIN('Root Register'!E11:H11) -> 1 | H42: =G42 -> 1 | I42: 3 | J42: 0 | K42: 0 | L42: whole form as unselected hypothesis | M42: =IF(H42=1,IF(J42=0,"AUTHORIZED / NOT ISSUED",IF(K42=J42,"ISSUED / ACCEPTED","ISSUED / REVIEW")),"HELD") -> AUTHORIZED / NOT ISSUED | N42: set loses plurality, equality or uncertainty marking
A43: HU-A-REP-4 | B43: MS-HU | C43: HU-A | D43: REP-4 | E43: As-built experimental record | F43: 4 | G43: =MIN('Root Register'!I11:J11) -> 0 | H43: =G43 -> 0 | I43: 1 | J43: 0 | K43: 0 | L43: actual test article only | M43: =IF(H43=1,IF(J43=0,"AUTHORIZED / NOT ISSUED",IF(K43=J43,"ISSUED / ACCEPTED","ISSUED / REVIEW")),"HELD") -> HELD | N43: article changes after record
...

Sheet Hypothesis Sets
A2: Eighteen rival form hypotheses authorized but not issued
A4: Each root must be represented by all three mechanically divergent hypotheses with equal visual salience. Selection before evidence invalidates the set.
A6: Hypothesis | B6: System | C6: Root | D6: Variant | E6: Form hypothesis | F6: Governing variation axis | G6: Mandatory causal content | H6: Intentionally unresolved | I6: Commission authority | J6: Issued | K6: Selected | L6: State
A7: ET-A-H1 | B7: MS-ET | C7: ET-A | D7: 1 | E7: distributed twin-body exchange | F7: buoyancy and exchange-path separation | G7: full separation of both 241 t/h paths | H7: mission bridge, accommodation and fairing | I7: ='Representation Register'!H10 -> 1 | J7: 0 | K7: 0 | L7: =IF(K7>0,"INVALID SELECTION",IF(I7=1,IF(J7=0,"AUTHORIZED / NOT ISSUED","ISSUED / UNSELECTED"),"HELD")) -> AUTHORIZED / NOT ISSUED
A8: ET-A-H2 | B8: MS-ET | C8: ET-A | D8: 2 | E8: articulated offshore spine | F8: relative-motion accommodation | G8: independent transition heads and custody meters | H8: propulsion, transit and whole-body closure | I8: ='Representation Register'!H10 -> 1 | J8: 0 | K8: 0 | L8: =IF(K8>0,"INVALID SELECTION",IF(I8=1,IF(J8=0,"AUTHORIZED / NOT ISSUED","ISSUED / UNSELECTED"),"HELD")) -> AUTHORIZED / NOT ISSUED
A9: ET-A-H3 | B9: MS-ET | C9: ET-A | D9: 3 | E9: semi-submersible exchange lattice | F9: wave-response and dry-custody geometry | G9: two complete wet-to-dry causal routes | H9: stationkeeping and production structure | I9: ='Representation Register'!H10 -> 1 | J9: 0 | K9: 0 | L9: =IF(K9>0,"INVALID SELECTION",IF(I9=1,IF(J9=0,"AUTHORIZED / NOT ISSUED","ISSUED / UNSELECTED"),"HELD")) -> AUTHORIZED / NOT ISSUED
A10: CT-C-H1 | B10: MS-CT | C10: CT-C | D10: 1 | E10: ground-supported telescoping spine | F10: reaction path and vertical reach | G10: five separately isolatable utility trunks | H10: road package and whole-building circulation | I10: ='Representation Register'!H18 -> 1 | J10: 0 | K10: 0 | L10: =IF(K10>0,"INVALID SELECTION",IF(I10=1,IF(J10=0,"AUTHORIZED / NOT ISSUED","ISSUED / UNSELECTED"),"HELD")) -> AUTHORIZED / NOT ISSUED
A11: CT-C-H2 | B11: MS-CT | C11: CT-C | D11: 2 | E11: suspended facade utility belt | F11: occupied-boundary attachment | G11: reversible attachment and fault containment | H11: carrier, roof support and operational enclosure | I11: ='Representation Register'!H18 -> 1 | J11: 0 | K11: 0 | L11: =IF(K11>0,"INVALID SELECTION",IF(I11=1,IF(J11=0,"AUTHORIZED / NOT ISSUED","ISSUED / UNSELECTED"),"HELD")) -> AUTHORIZED / NOT ISSUED
A12: CT-C-H3 | B12: MS-CT | C12: CT-C | D12: 3 | E12: mast-and-bridge insertion grid | F12: segmented reach and egress | G12: seven energy cells and complete trunk crossings | H12: deployment choreography and fleet package | I12: ='Representation Register'!H18 -> 1 | J12: 0 | K12: 0 | L12: =IF(K12>0,"INVALID SELECTION",IF(I12=1,IF(J12=0,"AUTHORIZED / NOT ISSUED","ISSUED / UNSELECTED"),"HELD")) -> AUTHORIZED / NOT ISSUED
A13: HC-A-H1 | B13: MS-HC | C13: HC-A | D13: 1 | E13: high-endurance winged array | F13: carrier persistence and release geometry | G13: five attributable sectors with independent sensing | H13: airframe closure and operational basing | I13: ='Representation Register'!H26 -> 1 | J13: 0 | K13: 0 | L13: =IF(K13>0,"INVALID SELECTION",IF(I13=1,IF(J13=0,"AUTHORIZED / NOT ISSUED","ISSUED / UNSELECTED"),"HELD")) -> AUTHORIZED / NOT ISSUED
A14: HC-A-H2 | B14: MS-HC | C14: HC-A | D14: 2 | E14: aerostat intervention train | F14: stationary persistence and plume observation | G14: delivery-to-protected-edge causal chain | H14: mooring estate and weather survival form | I14: ='Representation Register'!H26 -> 1 | J14: 0 | K14: 0 | L14: =IF(K14>0,"INVALID SELECTION",IF(I14=1,IF(J14=0,"AUTHORIZED / NOT ISSUED","ISSUED / UNSELECTED"),"HELD")) -> AUTHORIZED / NOT ISSUED
A15: HC-A-H3 | B15: MS-HC | C15: HC-A | D15: 3 | E15: distributed rotorborne cells | F15: local control and sector isolation | G15: eight energy cells and five held-line sectors | H15: recovery, transit and fleet packaging | I15: ='Representation Register'!H26 -> 1 | J15: 0 | K15: 0 | L15: =IF(K15>0,"INVALID SELECTION",IF(I15=1,IF(J15=0,"AUTHORIZED / NOT ISSUED","ISSUED / UNSELECTED"),"HELD")) -> AUTHORIZED / NOT ISSUED
A16: LF-B-H1 | B16: MS-LF | C16: LF-B | D16: 1 | E16: radial multi-bore source field | F16: well separation and central conversion | G16: nine access slots and four isolated converters | H16: permanent civil works and production campus | I16: ='Representation Register'!H34 -> 1 | J16: 0 | K16: 0 | L16: =IF(K16>0,"INVALID SELECTION",IF(I16=1,IF(J16=0,"AUTHORIZED / NOT ISSUED","ISSUED / UNSELECTED"),"HELD")) -> AUTHORIZED / NOT ISSUED
A17: LF-B-H2 | B17: MS-LF | C17: LF-B | D17: 2 | E17: linear roadless source train | F17: distributed access along constrained terrain | G17: two independent water paths and three residual paths | H17: mobility system and whole-route enclosure | I17: ='Representation Register'!H34 -> 1 | J17: 0 | K17: 0 | L17: =IF(K17>0,"INVALID SELECTION",IF(I17=1,IF(J17=0,"AUTHORIZED / NOT ISSUED","ISSUED / UNSELECTED"),"HELD")) -> AUTHORIZED / NOT ISSUED
A18: LF-B-H3 | B18: MS-LF | C18: LF-B | D18: 3 | E18: nearshore supported source island | F18: water access and subsurface reach | G18: separate bore, power, product and injection sections | H18: marine support form and operating habitat | I18: ='Representation Register'!H34 -> 1 | J18: 0 | K18: 0 | L18: =IF(K18>0,"INVALID SELECTION",IF(I18=1,IF(J18=0,"AUTHORIZED / NOT ISSUED","ISSUED / UNSELECTED"),"HELD")) -> AUTHORIZED / NOT ISSUED
A19: HU-A-H1 | B19: MS-HU | C19: HU-A | D19: 1 | E19: distributed clinical courtyards | F19: care-line separation and patient flow | G19: all ten care lines across eight access cells | H19: staff habitat and complete logistics envelope | I19: ='Representation Register'!H42 -> 1 | J19: 0 | K19: 0 | L19: =IF(K19>0,"INVALID SELECTION",IF(I19=1,IF(J19=0,"AUTHORIZED / NOT ISSUED","ISSUED / UNSELECTED"),"HELD")) -> AUTHORIZED / NOT ISSUED
A20: HU-A-H2 | B20: MS-HU | C20: HU-A | D20: 2 | E20: linear plug-through care spine | F20: clean-dirty counterflow | G20: six utility cells and separated residual zones | H20: transport shell and receiver architecture | I20: ='Representation Register'!H42 -> 1 | J20: 0 | K20: 0 | L20: =IF(K20>0,"INVALID SELECTION",IF(I20=1,IF(J20=0,"AUTHORIZED / NOT ISSUED","ISSUED / UNSELECTED"),"HELD")) -> AUTHORIZED / NOT ISSUED
A21: HU-A-H3 | B21: MS-HU | C21: HU-A | D21: 3 | E21: stacked clinical metabolism tower | F21: vertical access and utility zoning | G21: complete care-line scope after access-cell loss | H21: foundation, wind and full occupancy form | I21: ='Representation Register'!H42 -> 1 | J21: 0 | K21: 0 | L21: =IF(K21>0,"INVALID SELECTION",IF(I21=1,IF(J21=0,"AUTHORIZED / NOT ISSUED","ISSUED / UNSELECTED"),"HELD")) -> AUTHORIZED / NOT ISSUED
A22: RT-B-H1 | B22: MS-RT | C22: RT-B | D22: 1 | E22: distributed container process mesh | F22: node independence and field replacement | G22: five complete dirty-return-to-release meshes | H22: carrier allocation and fleet arrangement | I22: ='Representation Register'!H50 -> 1 | J22: 0 | K22: 0 | L22: =IF(K22>0,"INVALID SELECTION",IF(I22=1,IF(J22=0,"AUTHORIZED / NOT ISSUED","ISSUED / UNSELECTED"),"HELD")) -> AUTHORIZED / NOT ISSUED
A23: RT-B-H2 | B23: MS-RT | C23: RT-B | D23: 2 | E23: radial clean-core process hub | F23: clean-dirty flow and release control | G23: nine release envelopes and seven energy cells | H23: operational enclosure and site circulation | I23: ='Representation Register'!H50 -> 1 | J23: 0 | K23: 0 | L23: =IF(K23>0,"INVALID SELECTION",IF(I23=1,IF(J23=0,"AUTHORIZED / NOT ISSUED","ISSUED / UNSELECTED"),"HELD")) -> AUTHORIZED / NOT ISSUED
A24: RT-B-H3 | B24: MS-RT | C24: RT-B | D24: 3 | E24: linear mobile process train | F24: serial process access and disconnection | G24: complete metrology and material-ancestry route | H24: traction, roadability and production package | I24: ='Representation Register'!H50 -> 1 | J24: 0 | K24: 0 | L24: =IF(K24>0,"INVALID SELECTION",IF(I24=1,IF(J24=0,"AUTHORIZED / NOT ISSUED","ISSUED / UNSELECTED"),"HELD")) -> AUTHORIZED / NOT ISSUED

Sheet View Grammar
A2: Fourteen rules for technical and form representations
A4: A comparative technical plate may expose form hypotheses. A single polished hero image may not create a favored configuration.
A6: Rule | B6: Requirement | C6: Failure test | D6: Applies to | E6: Disposition
A7: VG-01 | B7: show all three hypotheses together | C7: one omission withdraws the full root set | D7: REP-3 | E7: WITHDRAW SET
A8: VG-02 | B8: use identical scale, view angle, lighting and image area | C8: salience differs across hypotheses | D8: REP-3 | E8: WITHDRAW SET
A9: VG-03 | B9: include plan, elevation and causal section | C9: a view needed to inspect a boundary is absent | D9: REP-2 to REP-7 | E9: RETURN
A10: VG-04 | B10: tag every visible object as candidate, public rig, receiver, surrogate or unresolved | C10: one object lacks a type | D10: REP-2 to REP-7 | E10: RETURN
A11: VG-05 | B11: distinguish measured, calculated, assumed and unresolved geometry | C11: an assumption appears measured | D11: REP-2 to REP-7 | E11: ROLL BACK
A12: VG-06 | B12: hatch or make transparent every unresolved closure | C12: unknown form appears finished | D12: REP-2 to REP-4 | E12: DOWNGRADE
A13: VG-07 | B13: display root, representation class, version and evidence state | C13: identity or state is missing | D13: all classes | E13: WITHDRAW
A14: VG-08 | B14: show causal-account boundaries and decisive isolation | C14: a shared path is visually hidden | D14: REP-1 to REP-7 | E14: RETURN
A15: VG-09 | B15: omit livery, brand marks and promotional color | C15: presentation implies institutional selection | D15: REP-3 to REP-6 | E15: WITHDRAW
A16: VG-10 | B16: omit people, named places and dramatic mission scenes | C16: context implies usability or acceptance | D16: REP-3 | E16: WITHDRAW
A17: VG-11 | B17: show requirements separately from observed results | C17: a target appears as achieved performance | D17: all classes | E17: ROLL BACK
... A20: VG-14 | B20: depict exterior surface before evidence only when the surface is itself a registered causal variable. | C20: decorative closure completes the silhouette | D20: REP-2 to REP-4 | E20: DOWNGRADE

Sheet Claim Matrix
A2: Sixty-four representation-to-claim decisions
A4: Higher representation classes may carry lower-order claims, but only with the qualifier appropriate to the physical and evidentiary source.
A6: Decision | B6: Class | C6: Class rank | D6: Claim | E6: Claim type | F6: Minimum rank | G6: Authorized by class | H6: Required qualifier | I6: State
A7: REP-0-C01 | B7: REP-0 | C7: 0 | D7: C01 | E7: service requirement | F7: 0 | G7: =IF(C7>=F7,1,0) -> 1 | H7: requirement only | I7: =IF(G7=1,"PERMITTED","PROHIBITED") -> PERMITTED
A8: REP-0-C02 | B8: REP-0 | C8: 0 | D8: C02 | E8: causal relationship | F8: 1 | G8: =IF(C8>=F8,1,0) -> 0 | H8: topology and flow only | I8: =IF(G8=1,"PERMITTED","PROHIBITED") -> PROHIBITED
A9: REP-0-C03 | B9: REP-0 | C9: 0 | D9: C03 | E9: test geometry | F9: 2 | G9: =IF(C9>=F9,1,0) -> 0 | H9: registered experimental geometry | I9: =IF(G9=1,"PERMITTED","PROHIBITED") -> PROHIBITED
A10: REP-0-C04 | B10: REP-0 | C10: 0 | D10: C04 | E10: whole-form hypothesis | F10: 3 | G10: =IF(C10>=F10,1,0) -> 0 | H10: explicitly unselected and plural | I10: =IF(G10=1,"PERMITTED","PROHIBITED") -> PROHIBITED
A11: REP-0-C05 | B11: REP-0 | C11: 0 | D11: C05 | E11: as-built geometry | F11: 4 | G11: =IF(C11>=F11,1,0) -> 0 | H11: one serialized physical article | I11: =IF(G11=1,"PERMITTED","PROHIBITED") -> PROHIBITED
A12: REP-0-C06 | B12: REP-0 | C12: 0 | D12: C06 | E12: performance result | F12: 5 | G12: =IF(C12>=F12,1,0) -> 0 | H12: accepted cells and surviving root | I12: =IF(G12=1,"PERMITTED","PROHIBITED") -> PROHIBITED
A13: REP-0-C07 | B13: REP-0 | C13: 0 | D13: C07 | E13: mission capacity | F13: 6 | G13: =IF(C13>=F13,1,0) -> 0 | H13: route-complete mission evidence | I13: =IF(G13=1,"PERMITTED","PROHIBITED") -> PROHIBITED
A14: REP-0-C08 | B14: REP-0 | C14: 0 | D14: C08 | E14: production or fleet state | F14: 7 | G14: =IF(C14>=F14,1,0) -> 0 | H14: production and readiness warrants | I14: =IF(G14=1,"PERMITTED","PROHIBITED") -> PROHIBITED
A15: REP-1-C01 | B15: REP-1 | C15: 1 | D15: C01 | E15: service requirement | F15: 0 | G15: =IF(C15>=F15,1,0) -> 1 | H15: requirement only | I15: =IF(G15=1,"PERMITTED","PROHIBITED") -> PERMITTED
A16: REP-1-C02 | B16: REP-1 | C16: 1 | D16: C02 | E16: causal relationship | F16: 1 | G16: =IF(C16>=F16,1,0) -> 1 | H16: topology and flow only | I16: =IF(G16=1,"PERMITTED","PROHIBITED") -> PERMITTED
A17: REP-1-C03 | B17: REP-1 | C17: 1 | D17: C03 | E17: test geometry | F17: 2 | G17: =IF(C17>=F17,1,0) -> 0 | H17: registered experimental geometry | I17: =IF(G17=1,"PERMITTED","PROHIBITED") -> PROHIBITED
A18: REP-1-C04 | B18: REP-1 | C18: 1 | D18: C04 | E18: whole-form hypothesis | F18: 3 | G18: =IF(C18>=F18,1,0) -> 0 | H18: explicitly unselected and plural | I18: =IF(G18=1,"PERMITTED","PROHIBITED") -> PROHIBITED
... A70: REP-7-C08 | B70: REP-7 | C70: 7 | D70: C08 | E70: production or fleet state | F70: 7 | G70: =IF(C70>=F70,1,0) -> 1 | H70: production and readiness warrants | I70: =IF(G70=1,"PERMITTED","PROHIBITED") -> PERMITTED

Sheet Construction Boundary
A2: Forty-eight physical-object boundary decisions
A4: Design authority does not create a site, firm, award or serial. Any actual build still follows the eighteen-warrant construction compact.
A6: Object record | B6: System | C6: Root | D6: Object | E6: Design authority | F6: Physical meaning | G6: Limit | H6: Serials built | I6: State
A7: ET-A-B1 | B7: MS-ET | C7: ET-A | D7: full-scale causal article | E7: 1 | F7: complete account-bound experimental object | G7: may be built only through the separate eighteen-warrant construction chain | H7: 0 | I7: =IF(E7=1,IF(H7=0,"DESIGN AUTHORIZED / NO SERIAL","SERIAL EXISTS"),"HELD") -> DESIGN AUTHORIZED / NO SERIAL
A8: ET-A-B2 | B8: MS-ET | C8: ET-A | D8: instrumented account section | E8: 1 | F8: section bill, sensors, custody and safeing | G8: must expose rather than hide the decisive boundary | H8: 0 | I8: =IF(E8=1,IF(H8=0,"DESIGN AUTHORIZED / NO SERIAL","SERIAL EXISTS"),"HELD") -> DESIGN AUTHORIZED / NO SERIAL
A9: ET-A-B3 | B9: MS-ET | C9: ET-A | D9: public interface fixture | E9: 1 | F9: candidate-neutral receiver or challenge boundary | G9: cannot supply decisive candidate capacity | H9: 0 | I9: =IF(E9=1,IF(H9=0,"DESIGN AUTHORIZED / NO SERIAL","SERIAL EXISTS"),"HELD") -> DESIGN AUTHORIZED / NO SERIAL
A10: ET-A-B4 | B10: MS-ET | C10: ET-A | D10: surrogate burden set | E10: 1 | F10: registered mass, heat, flow, occupancy or residual surrogate | G10: must remain visibly distinct from candidate hardware | H10: 0 | I10: =IF(E10=1,IF(H10=0,"DESIGN AUTHORIZED / NO SERIAL","SERIAL EXISTS"),"HELD") -> DESIGN AUTHORIZED / NO SERIAL
A11: ET-A-B5 | B11: MS-ET | C11: ET-A | D11: causal exterior surface | E11: 1 | F11: only the bounded surface whose geometry changes the tested mechanism | G11: unregistered closure remains absent or unresolved | H11: 0 | I11: =IF(E11=1,IF(H11=0,"DESIGN AUTHORIZED / NO SERIAL","SERIAL EXISTS"),"HELD") -> DESIGN AUTHORIZED / NO SERIAL
A12: ET-A-B6 | B12: MS-ET | C12: ET-A | D12: operational packaging | E12: 0 | F12: whole transit, habitat, control and mission enclosure | G12: held pending route-complete evidence | H12: 0 | I12: =IF(E12=1,IF(H12=0,"DESIGN AUTHORIZED / NO SERIAL","SERIAL EXISTS"),"HELD") -> HELD
A13: ET-A-B7 | B13: MS-ET | C13: ET-A | D13: production tooling | E13: 0 | F13: repeatable production baseline and rate tooling | G13: held pending production warrant | H13: 0 | I13: =IF(E13=1,IF(H13=0,"DESIGN AUTHORIZED / NO SERIAL","SERIAL EXISTS"),"HELD") -> HELD
A14: ET-A-B8 | B14: MS-ET | C14: ET-A | D14: fleet unit | E14: 0 | F14: fieldable, crewed, supplied and readiness-qualified configuration | G14: held pending readiness warrant | H14: 0 | I14: =IF(E14=1,IF(H14=0,"DESIGN AUTHORIZED / NO SERIAL","SERIAL EXISTS"),"HELD") -> HELD
A15: CT-C-B1 | B15: MS-CT | C15: CT-C | D15: full-scale causal article | E15: 1 | F15: complete account-bound experimental object | G15: may be built only through the separate eighteen-warrant construction chain | H15: 0 | I15: =IF(E15=1,IF(H15=0,"DESIGN AUTHORIZED / NO SERIAL","SERIAL EXISTS"),"HELD") -> DESIGN AUTHORIZED / NO SERIAL
A16: CT-C-B2 | B16: MS-CT | C16: CT-C | D16: instrumented account section | E16: 1 | F16: section bill, sensors, custody and safeing | G16: must expose rather than hide the decisive boundary | H16: 0 | I16: =IF(E16=1,IF(H16=0,"DESIGN AUTHORIZED / NO SERIAL","SERIAL EXISTS"),"HELD") -> DESIGN AUTHORIZED / NO SERIAL
A17: CT-C-B3 | B17: MS-CT | C17: CT-C | D17: public interface fixture | E17: 1 | F17: candidate-neutral receiver or challenge boundary | G17: cannot supply decisive candidate capacity | H17: 0 | I17: =IF(E17=1,IF(H17=0,"DESIGN AUTHORIZED / NO SERIAL","SERIAL EXISTS"),"HELD") -> DESIGN AUTHORIZED / NO SERIAL
A18: CT-C-B4 | B18: MS-CT | C18: CT-C | D18: surrogate burden set | E18: 1 | F18: registered mass, heat, flow, occupancy or residual surrogate | G18: must remain visibly distinct from candidate hardware | H18: 0 | I18: =IF(E18=1,IF(H18=0,"DESIGN AUTHORIZED / NO SERIAL","SERIAL EXISTS"),"HELD") -> DESIGN AUTHORIZED / NO SERIAL
... A54: RT-B-B8 | B54: MS-RT | C54: RT-B | D54: fleet unit | E54: 0 | F54: fieldable, crewed, supplied and readiness-qualified configuration | G54: held pending readiness warrant | H54: 0 | I54: =IF(E54=1,IF(H54=0,"DESIGN AUTHORIZED / NO SERIAL","SERIAL EXISTS"),"HELD") -> HELD

Sheet Nonconversion Laws
A2: Eighteen representation nonconversion laws
A4: These laws prevent an image from advancing evidence, procurement, production, readiness or strategic-effect state.
A6: Law | B6: Proposition | C6: Consequence
A7: NC-01 | B7: a representation is not evidence | C7: no image closes a cell or gate
A8: NC-02 | B8: a dimension is not tolerance acceptance | C8: only accepted metrology creates as-built truth
A9: NC-03 | B9: a test article is not a candidate form | C9: experimental geometry cannot become the operational baseline by reuse
A10: NC-04 | B10: a complete outline is not a selected form | C10: REP-3 requires three equal alternatives
A11: NC-05 | B11: visual plausibility is not causal closure | C11: appearance cannot cure a missing account
A12: NC-06 | B12: a requirement is not observed performance | C12: targets and results remain separate layers
A13: NC-07 | B13: an as-built record is not performance evidence | C13: REP-4 records existence and geometry only
A14: NC-08 | B14: one passing cell is not a surviving root | C14: all twenty-four cells and disposition remain noncompensatory
A15: NC-09 | B15: root survival is not a mission configuration | C15: receiver and adjacent-system evidence remain separate
A16: NC-10 | B16: mission configuration is not production | C16: repeatability and baseline control remain separate
A17: NC-11 | B17: production is not readiness | C17: crew, receiver, sustainment and allocation warrants remain separate
... A24: NC-18 | B24: livery is not institutional identity | C24: branding waits for an authorized operational configuration

Sheet Rollback
A2: Twelve representation rollback triggers
A4: Rollback is local unless the same defect contaminates a root set, comparison, decision or descendant representation.
A6: Trigger | B6: Failure | C6: Affected state | D6: Mandatory response
A7: RB-01 | B7: one REP-3 hypothesis is omitted | C7: all three form studies | D7: withdraw the entire root set
A8: RB-02 | B8: scale, detail or viewpoint creates unequal salience | C8: all three form studies | D8: reissue under identical grammar
A9: RB-03 | B9: unresolved geometry appears resolved | C9: affected representation | D9: downgrade to REP-2
A10: RB-04 | B10: target performance is labeled as observed | C10: affected representation and downstream citations | D10: withdraw and correct the claim layer
A11: RB-05 | B11: a visual enters bid scoring or root disposition | C11: affected decision | D11: void and repeat without the visual
A12: RB-06 | B12: an as-built article changes after metrology | C12: REP-4 record | D12: invalidate and remeasure the serial
A13: RB-07 | B13: a cell acceptance is reversed | C13: REP-5 and every descendant | D13: return to REP-4 or lower
A14: RB-08 | B14: cold reconstruction fails | C14: REP-5 and every descendant | D14: return to REP-4 and reopen ancestry
A15: RB-09 | B15: shared decisive dependency is discovered | C15: affected root and paired comparisons | D15: return to REP-1 and rebuild independence
A16: RB-10 | B16: receiver or interface evidence reverses | C16: REP-6 and REP-7 | D16: return to REP-5
A17: RB-11 | B17: production baseline diverges from evidence-qualified form | C17: REP-7 | D17: invalidate production representation
A18: RB-12 | B18: readiness warrant expires or rolls back | C18: fleet depiction and readiness claim | D18: remove REP-7 fleet context

Sheet Finance
A2: Representation work adds no program ceiling
A4: All representation deliverables sit inside the existing FRAME stage. No image, drawing or hypothesis set creates a separate appropriation or payment claim.
A6: System | B6: Root | C6: Article | D6: Option ceiling USD B | E6: FRAME share | F6: Maximum FRAME USD B | G6: Incremental representation ceiling USD B | H6: Accepted USD B | I6: Paid USD B | J6: State
A7: MS-ET | B7: ET-A | C7: Pelagic exchange cell | D7: 0.50047462 | E7: =Controls!$B$27 -> 0.15 | F7: =D7*E7 -> 0.075071193 | G7: 0 | H7: 0 | I7: 0 | J7: HELD
A8: MS-CT | B8: CT-C | C8: Occupied-building utility-spine sector | D8: 0.51649348 | E8: =Controls!$B$27 -> 0.15 | F8: =D8*E8 -> 0.077474022 | G8: 0 | H8: 0 | I8: 0 | J8: HELD
A9: MS-HC | B9: HC-A | C9: Atmospheric intervention cell | D9: 0.30722165 | E9: =Controls!$B$27 -> 0.15 | F9: =D9*E9 -> 0.046083248 | G9: 0 | H9: 0 | I9: 0 | J9: HELD
A10: MS-LF | B10: LF-B | C10: Geothermal source position | D10: 0.89941282 | E10: =Controls!$B$27 -> 0.15 | F10: =D10*E10 -> 0.13491192 | G10: 0 | H10: 0 | I10: 0 | J10: HELD
A11: MS-HU | B11: HU-A | C11: Complete clinical island | D11: 0.86071245 | E11: =Controls!$B$27 -> 0.15 | F11: =D11*E11 -> 0.12910687 | G11: 0 | H11: 0 | I11: 0 | J11: HELD
A12: MS-RT | B12: RT-B | C12: Disconnected microfactory mesh | D12: 0.50259779 | E12: =Controls!$B$27 -> 0.15 | F12: =D12*E12 -> 0.075389669 | G12: 0 | H12: 0 | I12: 0 | J12: HELD
A13: TOTAL | B13: six roots | C13: representation boundary | D13: =SUM(D7:D12) -> 3.5869128 | F13: =SUM(F7:F12) -> 0.53803692 | G13: =SUM(G7:G12) -> 0 | H13: =SUM(H7:H12) -> 0 | I13: =SUM(I7:I12) -> 0 | J13: HELD

Sheet Release Gates
A2: Seventy-two requirement-to-form gates
A4: Pass 220 closes the representation rule, not an evidence gate. G06 remains specified but open; every selected exterior remains held.
A6: Gate | B6: System | C6: Root | D6: Order | E6: Gate claim | F6: State | G6: Constituted | H6: Evidence accepted | I6: Representation effect | J6: Selected exterior authority
A7: ET-A-G01 | B7: MS-ET | C7: ET-A | D7: 1 | E7: denominator | F7: CONSTITUTED | G7: 1 | H7: 0 | I7: REP-0 through REP-3 only | J7: n.a.
A8: ET-A-G02 | B8: MS-ET | C8: ET-A | D8: 2 | E8: article boundary | F8: CONSTITUTED | G8: 1 | H8: 0 | I8: REP-0 through REP-3 only | J8: n.a.
A9: ET-A-G03 | B9: MS-ET | C9: ET-A | D9: 3 | E9: form loads | F9: CONSTITUTED | G9: 1 | H9: 0 | I9: REP-0 through REP-3 only | J9: n.a.
A10: ET-A-G04 | B10: MS-ET | C10: ET-A | D10: 4 | E10: interfaces | F10: CONSTITUTED | G10: 1 | H10: 0 | I10: REP-0 through REP-3 only | J10: n.a.
A11: ET-A-G05 | B11: MS-ET | C11: ET-A | D11: 5 | E11: denial set | F11: CONSTITUTED | G11: 1 | H11: 0 | I11: REP-0 through REP-3 only | J11: n.a.
A12: ET-A-G06 | B12: MS-ET | C12: ET-A | D12: 6 | E12: paper section | F12: SPECIFIED / NOT CLOSED | G12: 0 | H12: 0 | I12: REP-0 through REP-3 only | J12: n.a.
A13: ET-A-G07 | B13: MS-ET | C13: ET-A | D13: 7 | E13: safety and rights | F13: OPEN | G13: 0 | H13: 0 | I13: NO NEW AUTHORITY | J13: n.a.
A14: ET-A-G08 | B14: MS-ET | C14: ET-A | D14: 8 | E14: ancestry | F14: OPEN | G14: 0 | H14: 0 | I14: NO NEW AUTHORITY | J14: n.a.
A15: ET-A-G09 | B15: MS-ET | C15: ET-A | D15: 9 | E15: executable build record | F15: OPEN | G15: 0 | H15: 0 | I15: NO NEW AUTHORITY | J15: n.a.
A16: ET-A-G10 | B16: MS-ET | C16: ET-A | D16: 10 | E16: representative event | F16: OPEN | G16: 0 | H16: 0 | I16: NO NEW AUTHORITY | J16: n.a.
A17: ET-A-G11 | B17: MS-ET | C17: ET-A | D17: 11 | E17: cold reconstruction | F17: OPEN | G17: 0 | H17: 0 | I17: NO NEW AUTHORITY | J17: n.a.
A18: ET-A-G12 | B18: MS-ET | C18: ET-A | D18: 12 | E18: architecture warrant | F18: OPEN | G18: 0 | H18: 0 | I18: NO NEW AUTHORITY | J18: HELD
... A78: RT-B-G12 | B78: MS-RT | C78: RT-B | D78: 12 | E78: architecture warrant | F78: OPEN | G78: 0 | H78: 0 | I78: NO NEW AUTHORITY | J78: HELD

Sheet Mutations
A2: Restored control-mutation register
A4: The verifier applies each mutation in memory, recalculates, observes the named audit and restores the baseline.
A6: Mutation | B6: Counterfactual edit | C6: Expected propagation
A7: M01 | B7: minimum rival set reduced below three | C7: rival-set minimum audit fails
A8: M02 | B8: hypothesis authority removed | C8: hypothesis-authority audit fails
A9: M03 | B9: selected exterior authority entered | C9: exterior-zero audit fails
A10: M04 | B10: production exterior authority entered | C10: production-zero audit fails
A11: M05 | B11: representation issued without artifact | C11: issued-zero audit fails
A12: M06 | B12: one root requirement removed | C12: representation authorization falls
A13: M07 | B13: one section freeze removed | C13: representation authorization falls
A14: M08 | B14: one protocol coverage removed | C14: representation authorization falls
A15: M09 | B15: one rival-set grammar removed | C15: REP-3 authorization falls
A16: M10 | B16: one built serial entered | C16: as-built state changes
A17: M11 | B17: one accepted cell entered | C17: evidence-zero audit fails
... A24: M18 | B24: accepted money entered | C24: authority-held audit fails

Sheet Audit
A2: Terminal representation-boundary audits
A4: Audits observe the model and do not feed representation, construction, finance or release state.
A6: Audit | B6: Check | C6: Actual | D6: Expected | E6: State
A7: A01 | B7: root count | C7: =COUNTA('Root Register'!B7:B12) -> 6 | D7: 6 | E7: =IF(ABS(C7-D7)<0.000001,"PASS","FAIL") -> PASS
A8: A02 | B8: representation classes | C8: =COUNTA('Representation Ladder'!A7:A14) -> 8 | D8: 8 | E8: =IF(ABS(C8-D8)<0.000001,"PASS","FAIL") -> PASS
A9: A03 | B9: representation records | C9: =COUNTA('Representation Register'!A7:A54) -> 48 | D9: 48 | E9: =IF(ABS(C9-D9)<0.000001,"PASS","FAIL") -> PASS
A10: A04 | B10: currently authorized records | C10: =SUM('Representation Register'!H7:H54) -> 24 | D10: 24 | E10: =IF(ABS(C10-D10)<0.000001,"PASS","FAIL") -> PASS
A11: A05 | B11: currently held records | C11: =COUNTIFS('Representation Register'!M7:M54,"HELD") -> 24 | D11: 24 | E11: =IF(ABS(C11-D11)<0.000001,"PASS","FAIL") -> PASS
A12: A06 | B12: issued representations | C12: =SUM('Representation Register'!J7:J54) -> 0 | D12: 0 | E12: =IF(ABS(C12-D12)<0.000001,"PASS","FAIL") -> PASS
A13: A07 | B13: accepted representations | C13: =SUM('Representation Register'!K7:K54) -> 0 | D13: 0 | E13: =IF(ABS(C13-D13)<0.000001,"PASS","FAIL") -> PASS
A14: A08 | B14: rival hypotheses | C14: =COUNTA('Hypothesis Sets'!A7:A24) -> 18 | D14: 18 | E14: =IF(ABS(C14-D14)<0.000001,"PASS","FAIL") -> PASS
A15: A09 | B15: minimum hypotheses per root | C15: =Controls!B14 -> 3 | D15: 3 | E15: =IF(ABS(C15-D15)<0.000001,"PASS","FAIL") -> PASS
A16: A10 | B16: hypothesis commission permissions | C16: =SUM('Hypothesis Sets'!I7:I24) -> 18 | D16: 18 | E16: =IF(ABS(C16-D16)<0.000001,"PASS","FAIL") -> PASS
A17: A11 | B17: hypotheses issued | C17: =SUM('Hypothesis Sets'!J7:J24) -> 0 | D17: 0 | E17: =IF(ABS(C17-D17)<0.000001,"PASS","FAIL") -> PASS
A18: A12 | B18: hypotheses selected | C18: =SUM('Hypothesis Sets'!K7:K24) -> 0 | D18: 0 | E18: =IF(ABS(C18-D18)<0.000001,"PASS","FAIL") -> PASS
A19: A13 | B19: invalid hypothesis selections | C19: =COUNTIFS('Hypothesis Sets'!L7:L24,"INVALID SELECTION") -> 0 | D19: 0 | E19: =IF(ABS(C19-D19)<0.000001,"PASS","FAIL") -> PASS
A20: A14 | B20: view-grammar rules | C20: =COUNTA('View Grammar'!A7:A20) -> 14 | D20: 14 | E20: =IF(ABS(C20-D20)<0.000001,"PASS","FAIL") -> PASS
A21: A15 | B21: claim decisions | C21: =COUNTA('Claim Matrix'!A7:A70) -> 64 | D21: 64 | E21: =IF(ABS(C21-D21)<0.000001,"PASS","FAIL") -> PASS
A22: A16 | B22: construction decisions | C22: =COUNTA('Construction Boundary'!A7:A54) -> 48 | D22: 48 | E22: =IF(ABS(C22-D22)<0.000001,"PASS","FAIL") -> PASS
A23: A17 | B23: design-authorized objects | C23: =SUM('Construction Boundary'!E7:E54) -> 30 | D23: 30 | E23: =IF(ABS(C23-D23)<0.000001,"PASS","FAIL") -> PASS
A24: A18 | B24: held physical objects | C24: =COUNTIFS('Construction Boundary'!I7:I54,"HELD") -> 18 | D24: 18 | E24: =IF(ABS(C24-D24)<0.000001,"PASS","FAIL") -> PASS
A25: A19 | B25: built serials | C25: =SUM('Construction Boundary'!H7:H54) -> 0 | D25: 0 | E25: =IF(ABS(C25-D25)<0.000001,"PASS","FAIL") -> PASS
A26: A20 | B26: nonconversion laws | C26: =COUNTA('Nonconversion Laws'!A7:A24) -> 18 | D26: 18 | E26: =IF(ABS(C26-D26)<0.000001,"PASS","FAIL") -> PASS
A27: A21 | B27: rollback triggers | C27: =COUNTA(Rollback!A7:A18) -> 12 | D27: 12 | E27: =IF(ABS(C27-D27)<0.000001,"PASS","FAIL") -> PASS
A28: A22 | B28: release gates | C28: =COUNTA('Release Gates'!A7:A78) -> 72 | D28: 72 | E28: =IF(ABS(C28-D28)<0.000001,"PASS","FAIL") -> PASS
A29: A23 | B29: gate evidence accepted | C29: =SUM('Release Gates'!H7:H78) -> 0 | D29: 0 | E29: =IF(ABS(C29-D29)<0.000001,"PASS","FAIL") -> PASS
A30: A24 | B30: selected exterior authority at gates | C30: =SUM('Release Gates'!J7:J78) -> 0 | D30: 0 | E30: =IF(ABS(C30-D30)<0.000001,"PASS","FAIL") -> PASS
A31: A25 | B31: accepted cells | C31: =SUM('Root Register'!K7:K12) -> 0 | D31: 0 | E31: =IF(ABS(C31-D31)<0.000001,"PASS","FAIL") -> PASS
A32: A26 | B32: surviving roots | C32: =SUM('Root Register'!M7:M12) -> 0 | D32: 0 | E32: =IF(ABS(C32-D32)<0.000001,"PASS","FAIL") -> PASS
A33: A27 | B33: cold returns | C33: =SUM('Root Register'!N7:N12) -> 0 | D33: 0 | E33: =IF(ABS(C33-D33)<0.000001,"PASS","FAIL") -> PASS
A34: A28 | B34: mission evidence | C34: =SUM('Root Register'!O7:O12) -> 0 | D34: 0 | E34: =IF(ABS(C34-D34)<0.000001,"PASS","FAIL") -> PASS
A35: A29 | B35: production warrants | C35: =SUM('Root Register'!P7:P12) -> 0 | D35: 0 | E35: =IF(ABS(C35-D35)<0.000001,"PASS","FAIL") -> PASS
A36: A30 | B36: readiness warrants | C36: =SUM('Root Register'!Q7:Q12) -> 0 | D36: 0 | E36: =IF(ABS(C36-D36)<0.000001,"PASS","FAIL") -> PASS
A37: A31 | B37: option ceiling conserved | C37: =Finance!D13 -> 3.5869128 | D37: 3.5869128 | E37: =IF(ABS(C37-D37)<0.000001,"PASS","FAIL") -> PASS
A38: A32 | B38: FRAME ceiling conserved | C38: =Finance!F13 -> 0.53803692 | D38: 0.53803692 | E38: =IF(ABS(C38-D38)<0.000001,"PASS","FAIL") -> PASS
A39: A33 | B39: incremental representation ceiling | C39: =Finance!G13 -> 0 | D39: 0 | E39: =IF(ABS(C39-D39)<0.000001,"PASS","FAIL") -> PASS
A40: A34 | B40: accepted money | C40: =Finance!H13 -> 0 | D40: 0 | E40: =IF(ABS(C40-D40)<0.000001,"PASS","FAIL") -> PASS
A41: A35 | B41: paid money | C41: =Finance!I13 -> 0 | D41: 0 | E41: =IF(ABS(C41-D41)<0.000001,"PASS","FAIL") -> PASS
A42: A36 | B42: hypothesis authority | C42: =Controls!B15 -> 1 | D42: 1 | E42: =IF(ABS(C42-D42)<0.000001,"PASS","FAIL") -> PASS
A43: A37 | B43: selected exterior authority | C43: =Controls!B16 -> 0 | D43: 0 | E43: =IF(ABS(C43-D43)<0.000001,"PASS","FAIL") -> PASS
...

Sheet Sources & Limits
A2: Internal sources and decision limits
A4: This workbook integrates repository-controlled results. It introduces representation law, not physical observations.
A6: ID | B6: Source or limit | C6: Repository path or statement | D6: Use
A7: S01 | B7: Pass 219 internal-section architecture | C7: research/force/generation/department-of-resilience-six-root-internal-section-architecture-and-measurement-constitution.md | D7: six sections, 85 specifications and evidence holds
A8: S02 | B8: Pass 218 quantitative triage | C8: research/force/generation/department-of-resilience-six-root-quantitative-causal-section-triage-and-resize-constitution.md | D8: 144 cells, resize law and missing-is-not-zero rule
A9: S03 | B9: Pass 217 causal-section closure | C9: research/force/generation/department-of-resilience-concurrent-six-root-causal-section-closure-constitution.md | D9: six accounts, four worlds and independent root lanes
