Workbook

Sheet Summary
A2: Six-root internal-section architecture
A4: Decision | B4: Value | C4: Unit | D4: State | F4: Interpretation
A5: root-native sections | B5: =COUNTA('Root Architecture'!B7:B12) -> 6 | C5: count | D5: FROZEN FOR FALSIFICATION | F5: Decision Freeze six different internal falsification sections. Sixty nominal and largest-cell-loss cells close under the selected screen. Eighty-four cells now have executable, root-native protocols but no observations. The sections may be built for hostile proof; they may not be treated as validated platforms, production designs or exterior-rendering authority.
A6: cell decisions | B6: =COUNTA('Cell Register'!A7:A150) -> 144 | C6: count | D6: COMPLETE
A7: design-close cells | B7: =COUNTIFS('Cell Register'!S7:S150,"DESIGN CLOSE") -> 60 | C7: count | D7: CONTROLLED HYPOTHESIS
A8: measurement-ready cells | B8: =COUNTIFS('Cell Register'!S7:S150,"MEASUREMENT READY") -> 84 | C8: count | D8: EVIDENCE EMPTY
A9: unscoped cells | B9: =COUNTIFS('Cell Register'!S7:S150,"UNSCOPED") -> 0 | C9: count | D9: ZERO
A10: legacy gaps with successor | B10: =SUM('Gap Migration'!J7:J91) -> 85 | C10: count | D10: COMPLETE
A11: physical observations | B11: =Controls!B19 -> 0 | C11: count | D11: ZERO
A12: G06 credits | B12: =SUM('Root Architecture'!J7:J12) -> 0 | C12: count | D12: ZERO
A14: System | B14: Root | C14: Article | D14: Design close | E14: Measurement ready | F14: Unscoped | G14: Minimum W03 margin | H14: G06 | I14: Disposition | J14: Governing architecture
A15: MS-ET | B15: ET-A | C15: Pelagic exchange cell | D15: ='Root Architecture'!D7 -> 10 | E15: ='Root Architecture'!E7 -> 14 | F15: ='Root Architecture'!G7 -> 0 | G15: ='Root Architecture'!I7 -> 0.001669627 | H15: ='Root Architecture'!J7 -> 0 | I15: ='Root Architecture'!K7 -> SECTION FROZEN / EVIDENCE HOLD | J15: two complete exchange paths and motion-decoupled custody
A16: MS-CT | B16: CT-C | C16: Occupied-building utility-spine sector | D16: ='Root Architecture'!D8 -> 10 | E16: ='Root Architecture'!E8 -> 14 | F16: ='Root Architecture'!G8 -> 0 | G16: ='Root Architecture'!I8 -> 0.0028571429 | H16: ='Root Architecture'!J8 -> 0 | I16: ='Root Architecture'!K8 -> SECTION FROZEN / EVIDENCE HOLD | J16: seven isolated energy cells and five fault-contained service trunks
A17: MS-HC | B17: HC-A | C17: Atmospheric intervention cell | D17: ='Root Architecture'!D9 -> 10 | E17: ='Root Architecture'!E9 -> 14 | F17: ='Root Architecture'!G9 -> 0 | G17: ='Root Architecture'!I9 -> 0.0033980583 | H17: ='Root Architecture'!J9 -> 0 | I17: ='Root Architecture'!K9 -> SECTION FROZEN / EVIDENCE HOLD | J17: five attributable held-line sectors and eight energy cells
A18: MS-LF | B18: LF-B | C18: Geothermal source position | D18: ='Root Architecture'!D10 -> 10 | E18: ='Root Architecture'!E10 -> 14 | F18: ='Root Architecture'!G10 -> 0 | G18: ='Root Architecture'!I10 -> 0.0015124698 | H18: ='Root Architecture'!J10 -> 0 | I18: ='Root Architecture'!K10 -> SECTION FROZEN / EVIDENCE HOLD | J18: loss-separable access, conversion, route, buffer and residual sections
A19: MS-HU | B19: HU-A | C19: Complete clinical island | D19: ='Root Architecture'!D11 -> 10 | E19: ='Root Architecture'!E11 -> 14 | F19: ='Root Architecture'!G11 -> 0 | G19: ='Root Architecture'!I11 -> 0.003275 | H19: ='Root Architecture'!J11 -> 0 | I19: ='Root Architecture'!K11 -> SECTION FROZEN / EVIDENCE HOLD | J19: eight access cells without deleting ten indivisible care lines
A20: MS-RT | B20: RT-B | C20: Disconnected microfactory mesh | D20: ='Root Architecture'!D12 -> 10 | E20: ='Root Architecture'!E12 -> 14 | F20: ='Root Architecture'!G12 -> 0 | G20: ='Root Architecture'!I12 -> 0.00016129032 | H20: ='Root Architecture'!J12 -> 0 | I20: ='Root Architecture'!K12 -> SECTION FROZEN / EVIDENCE HOLD | J20: seven process-energy cells and five complete process meshes

Sheet Controls
A2: Internal-section architecture controls
A4: Blue cells are controlled design inputs. Physical observations remain empty and every release state remains held.
A6: Control | B6: Value | C6: Unit | D6: Authority
A7: adverse coefficient screen | B7: 0.025 | C7: share | D7: Pass 218 selected screen
A8: closure threshold | B8: 1 | C8: ratio | D8: Pass 216 endpoint rule
A9: roots | B9: 6 | C9: count | D9: Pass 211 / 216
A10: accounts | B10: 6 | C10: count | D10: Pass 217
A11: worlds | B11: 4 | C11: count | D11: Pass 217
A12: closure cells | B12: 144 | C12: count | D12: direct arithmetic
A13: legacy gaps | B13: 85 | C13: count | D13: Pass 218
A14: option ceiling | B14: 3.5869128 | C14: USD B | D14: Pass 215
A15: FRAME share | B15: 0.15 | C15: share | D15: Pass 215
A16: FRAME ceiling | B16: 0.53803692 | C16: USD B | D16: direct arithmetic
A17: accepted authority | B17: 0 | C17: USD B | D17: held
A18: paid authority | B18: 0 | C18: USD B | D18: held
... A22: rendering authority | B22: 0 | C22: count | D22: held

Sheet Root Architecture
A2: Six internal sections frozen for falsification
A4: A frozen falsification section says what must be built and measured. It does not claim evidence, platform form or production readiness.
A6: System | B6: Root | C6: Article | D6: Design-close cells | E6: Measurement-ready cells | F6: Negative cells | G6: Unscoped cells | H6: All 24 specified | I6: Minimum W03 margin | J6: G06 credit | K6: Disposition | L6: Governing architecture
A7: MS-ET | B7: ET-A | C7: Pelagic exchange cell | D7: =COUNTIFS('Cell Register'!$C$7:$C$150,B7,'Cell Register'!$S$7:$S$150,"DESIGN CLOSE") -> 10 | E7: =COUNTIFS('Cell Register'!$C$7:$C$150,B7,'Cell Register'!$S$7:$S$150,"MEASUREMENT READY") -> 14 | F7: =COUNTIFS('Cell Register'!$C$7:$C$150,B7,'Cell Register'!$S$7:$S$150,"NEGATIVE") -> 0 | G7: =COUNTIFS('Cell Register'!$C$7:$C$150,B7,'Cell Register'!$S$7:$S$150,"UNSCOPED") -> 0 | H7: =IF(D7+E7=24,1,0) -> 1 | I7: =MIN('Cell Register'!N7:N30)-Controls!$B$8 -> 0.001669627 | J7: =SUM('Cell Register'!R7:R30) -> 0 | K7: =IF(AND(D7=10,E7=14,F7=0,G7=0,H7=1,J7=0),"SECTION FROZEN / EVIDENCE HOLD","RETURN") -> SECTION FROZEN / EVIDENCE HOLD | L7: two complete exchange paths and motion-decoupled custody
A8: MS-CT | B8: CT-C | C8: Occupied-building utility-spine sector | D8: =COUNTIFS('Cell Register'!$C$7:$C$150,B8,'Cell Register'!$S$7:$S$150,"DESIGN CLOSE") -> 10 | E8: =COUNTIFS('Cell Register'!$C$7:$C$150,B8,'Cell Register'!$S$7:$S$150,"MEASUREMENT READY") -> 14 | F8: =COUNTIFS('Cell Register'!$C$7:$C$150,B8,'Cell Register'!$S$7:$S$150,"NEGATIVE") -> 0 | G8: =COUNTIFS('Cell Register'!$C$7:$C$150,B8,'Cell Register'!$S$7:$S$150,"UNSCOPED") -> 0 | H8: =IF(D8+E8=24,1,0) -> 1 | I8: =MIN('Cell Register'!N31:N54)-Controls!$B$8 -> 0.0028571429 | J8: =SUM('Cell Register'!R31:R54) -> 0 | K8: =IF(AND(D8=10,E8=14,F8=0,G8=0,H8=1,J8=0),"SECTION FROZEN / EVIDENCE HOLD","RETURN") -> SECTION FROZEN / EVIDENCE HOLD | L8: seven isolated energy cells and five fault-contained service trunks
A9: MS-HC | B9: HC-A | C9: Atmospheric intervention cell | D9: =COUNTIFS('Cell Register'!$C$7:$C$150,B9,'Cell Register'!$S$7:$S$150,"DESIGN CLOSE") -> 10 | E9: =COUNTIFS('Cell Register'!$C$7:$C$150,B9,'Cell Register'!$S$7:$S$150,"MEASUREMENT READY") -> 14 | F9: =COUNTIFS('Cell Register'!$C$7:$C$150,B9,'Cell Register'!$S$7:$S$150,"NEGATIVE") -> 0 | G9: =COUNTIFS('Cell Register'!$C$7:$C$150,B9,'Cell Register'!$S$7:$S$150,"UNSCOPED") -> 0 | H9: =IF(D9+E9=24,1,0) -> 1 | I9: =MIN('Cell Register'!N55:N78)-Controls!$B$8 -> 0.0033980583 | J9: =SUM('Cell Register'!R55:R78) -> 0 | K9: =IF(AND(D9=10,E9=14,F9=0,G9=0,H9=1,J9=0),"SECTION FROZEN / EVIDENCE HOLD","RETURN") -> SECTION FROZEN / EVIDENCE HOLD | L9: five attributable held-line sectors and eight energy cells
A10: MS-LF | B10: LF-B | C10: Geothermal source position | D10: =COUNTIFS('Cell Register'!$C$7:$C$150,B10,'Cell Register'!$S$7:$S$150,"DESIGN CLOSE") -> 10 | E10: =COUNTIFS('Cell Register'!$C$7:$C$150,B10,'Cell Register'!$S$7:$S$150,"MEASUREMENT READY") -> 14 | F10: =COUNTIFS('Cell Register'!$C$7:$C$150,B10,'Cell Register'!$S$7:$S$150,"NEGATIVE") -> 0 | G10: =COUNTIFS('Cell Register'!$C$7:$C$150,B10,'Cell Register'!$S$7:$S$150,"UNSCOPED") -> 0 | H10: =IF(D10+E10=24,1,0) -> 1 | I10: =MIN('Cell Register'!N79:N102)-Controls!$B$8 -> 0.0015124698 | J10: =SUM('Cell Register'!R79:R102) -> 0 | K10: =IF(AND(D10=10,E10=14,F10=0,G10=0,H10=1,J10=0),"SECTION FROZEN / EVIDENCE HOLD","RETURN") -> SECTION FROZEN / EVIDENCE HOLD | L10: loss-separable access, conversion, route, buffer and residual sections
A11: MS-HU | B11: HU-A | C11: Complete clinical island | D11: =COUNTIFS('Cell Register'!$C$7:$C$150,B11,'Cell Register'!$S$7:$S$150,"DESIGN CLOSE") -> 10 | E11: =COUNTIFS('Cell Register'!$C$7:$C$150,B11,'Cell Register'!$S$7:$S$150,"MEASUREMENT READY") -> 14 | F11: =COUNTIFS('Cell Register'!$C$7:$C$150,B11,'Cell Register'!$S$7:$S$150,"NEGATIVE") -> 0 | G11: =COUNTIFS('Cell Register'!$C$7:$C$150,B11,'Cell Register'!$S$7:$S$150,"UNSCOPED") -> 0 | H11: =IF(D11+E11=24,1,0) -> 1 | I11: =MIN('Cell Register'!N103:N126)-Controls!$B$8 -> 0.003275 | J11: =SUM('Cell Register'!R103:R126) -> 0 | K11: =IF(AND(D11=10,E11=14,F11=0,G11=0,H11=1,J11=0),"SECTION FROZEN / EVIDENCE HOLD","RETURN") -> SECTION FROZEN / EVIDENCE HOLD | L11: eight access cells without deleting ten indivisible care lines
A12: MS-RT | B12: RT-B | C12: Disconnected microfactory mesh | D12: =COUNTIFS('Cell Register'!$C$7:$C$150,B12,'Cell Register'!$S$7:$S$150,"DESIGN CLOSE") -> 10 | E12: =COUNTIFS('Cell Register'!$C$7:$C$150,B12,'Cell Register'!$S$7:$S$150,"MEASUREMENT READY") -> 14 | F12: =COUNTIFS('Cell Register'!$C$7:$C$150,B12,'Cell Register'!$S$7:$S$150,"NEGATIVE") -> 0 | G12: =COUNTIFS('Cell Register'!$C$7:$C$150,B12,'Cell Register'!$S$7:$S$150,"UNSCOPED") -> 0 | H12: =IF(D12+E12=24,1,0) -> 1 | I12: =MIN('Cell Register'!N127:N150)-Controls!$B$8 -> 0.00016129032 | J12: =SUM('Cell Register'!R127:R150) -> 0 | K12: =IF(AND(D12=10,E12=14,F12=0,G12=0,H12=1,J12=0),"SECTION FROZEN / EVIDENCE HOLD","RETURN") -> SECTION FROZEN / EVIDENCE HOLD | L12: seven process-energy cells and five complete process meshes

Sheet Section Bills
A2: Six root-native internal section bills
A4: These are minimum falsification configurations. They select internal partitions and test boundaries, not exterior geometry or a production design.
A6: System | B6: Root | C6: Account | D6: Closure account | E6: Internal section | F6: Unit | G6: Installed cells | H6: Cells after loss | I6: Cell rating | J6: W01 owned capacity | K6: W01 requirement | L6: W03 survivor capacity | M6: W03 requirement | N6: Causal isolation | O6: Cold-rebuild object | P6: Basis | Q6: Adverse screen | R6: W01 lower ratio | S6: W03 lower ratio | T6: Minimum margin | U6: Section state
A7: MS-ET | B7: ET-A | C7: A01 | D7: Mass and material custody | E7: 8 independent access cells | F7: t | G7: 8 | H7: 7 | I7: 16000 | J7: 128000 | K7: 102000 | L7: 112000 | M7: 102000 | N7: separate lift, handling and custody path per cell | O7: rebuild access cell and serial custody from frozen bill | P7: Pass 182 plus Pass 218 screen | Q7: =Controls!$B$7 -> 0.025 | R7: =IF(AND(ISNUMBER(J7),ISNUMBER(K7),K7>0),J7/K7*(1-Q7),"") -> 1.2235294 | S7: =IF(AND(ISNUMBER(L7),ISNUMBER(M7),M7>0),L7/M7*(1-Q7),"") -> 1.0705882 | T7: =IF(AND(ISNUMBER(R7),ISNUMBER(S7)),MIN(R7,S7)-Controls!$B$8,"") -> 0.070588235 | U7: FROZEN FOR FALSIFICATION
A8: MS-ET | B8: ET-A | C8: A02 | D8: Energy and heat | E8: 6 black-start generation cells | F8: MW | G8: 6 | H8: 5 | I8: 20 | J8: 120 | K8: 96 | L8: 100 | M8: 96 | N8: cell-local breaker, start source and heat rejection | O8: rebuild generator, switchgear and heat path | P8: Pass 182 retained | Q8: =Controls!$B$7 -> 0.025 | R8: =IF(AND(ISNUMBER(J8),ISNUMBER(K8),K8>0),J8/K8*(1-Q8),"") -> 1.21875 | S8: =IF(AND(ISNUMBER(L8),ISNUMBER(M8),M8>0),L8/M8*(1-Q8),"") -> 1.015625 | T8: =IF(AND(ISNUMBER(R8),ISNUMBER(S8)),MIN(R8,S8)-Controls!$B$8,"") -> 0.015625 | U8: FROZEN FOR FALSIFICATION
A9: MS-ET | B9: ET-A | C9: A03 | D9: Geometry and load path | E9: 2 complete motion-decoupled exchange paths | F9: t/h | G9: 2 | H9: 1 | I9: 241 | J9: 482 | K9: 234.58333 | L9: 241 | M9: 234.58333 | N9: either path crosses moving source, transition, custody and handoff | O9: rebuild connector, transition and metering chain | P9: RZ-01 | Q9: =Controls!$B$7 -> 0.025 | R9: =IF(AND(ISNUMBER(J9),ISNUMBER(K9),K9>0),J9/K9*(1-Q9),"") -> 2.0033393 | S9: =IF(AND(ISNUMBER(L9),ISNUMBER(M9),M9>0),L9/M9*(1-Q9),"") -> 1.0016696 | T9: =IF(AND(ISNUMBER(R9),ISNUMBER(S9)),MIN(R9,S9)-Controls!$B$8,"") -> 0.001669627 | U9: FROZEN FOR FALSIFICATION
A10: MS-ET | B10: ET-A | C10: A04 | D10: Safe state and human boundary | E10: 6 independent refuge and receiver zones | F10: ratio | G10: 6 | H10: 5 | I10: 0.21 | J10: 1.26 | K10: 1 | L10: 1.05 | M10: 1 | N10: each zone has detection, refuge, egress and manual safeing | O10: rebuild safe-state chain and prove lawful egress | P10: Pass 182 retained | Q10: =Controls!$B$7 -> 0.025 | R10: =IF(AND(ISNUMBER(J10),ISNUMBER(K10),K10>0),J10/K10*(1-Q10),"") -> 1.2285 | S10: =IF(AND(ISNUMBER(L10),ISNUMBER(M10),M10>0),L10/M10*(1-Q10),"") -> 1.02375 | T10: =IF(AND(ISNUMBER(R10),ISNUMBER(S10)),MIN(R10,S10)-Controls!$B$8,"") -> 0.02375 | U10: FROZEN FOR FALSIFICATION
A11: MS-ET | B11: ET-A | C11: A05 | D11: Residual and environmental custody | E11: 6 contained residual cells | F11: t/day | G11: 6 | H11: 5 | I11: 252 | J11: 1512 | K11: 1200 | L11: 1260 | M11: 1200 | N11: each cell owns treatment, buffer and discharge custody | O11: rebuild residual cell and reconcile inventory | P11: Pass 182 retained | Q11: =Controls!$B$7 -> 0.025 | R11: =IF(AND(ISNUMBER(J11),ISNUMBER(K11),K11>0),J11/K11*(1-Q11),"") -> 1.2285 | S11: =IF(AND(ISNUMBER(L11),ISNUMBER(M11),M11>0),L11/M11*(1-Q11),"") -> 1.02375 | T11: =IF(AND(ISNUMBER(R11),ISNUMBER(S11)),MIN(R11,S11)-Controls!$B$8,"") -> 0.02375 | U11: FROZEN FOR FALSIFICATION
A12: MS-ET | B12: ET-A | C12: A06 | D12: Removal and cold reconstruction | E12: sealed exchange-section reconstruction chain | F12: h | G12: 1 | H12: 1 | N12: records, tools, calibration and clean team remain outside candidate runtime | O12: outside team rebuilds complete causal section within 168 h | P12: Pass 219 protocol | Q12: =Controls!$B$7 -> 0.025 | R12: =IF(AND(ISNUMBER(J12),ISNUMBER(K12),K12>0),J12/K12*(1-Q12),"") | S12: =IF(AND(ISNUMBER(L12),ISNUMBER(M12),M12>0),L12/M12*(1-Q12),"") | T12: =IF(AND(ISNUMBER(R12),ISNUMBER(S12)),MIN(R12,S12)-Controls!$B$8,"") | U12: FROZEN FOR FALSIFICATION
A13: MS-CT | B13: CT-C | C13: A01 | D13: Mass and material custody | E13: 10 independently admitted insertion cells | F13: t | G13: 10 | H13: 9 | I13: 3600 | J13: 36000 | K13: 31000 | L13: 32400 | M13: 31000 | N13: each cell owns lifting, reversible attachment and removal custody | O13: rebuild one insertion cell at occupied receiver | P13: Pass 182 retained | Q13: =Controls!$B$7 -> 0.025 | R13: =IF(AND(ISNUMBER(J13),ISNUMBER(K13),K13>0),J13/K13*(1-Q13),"") -> 1.1322581 | S13: =IF(AND(ISNUMBER(L13),ISNUMBER(M13),M13>0),L13/M13*(1-Q13),"") -> 1.0190323 | T13: =IF(AND(ISNUMBER(R13),ISNUMBER(S13)),MIN(R13,S13)-Controls!$B$8,"") -> 0.019032258 | U13: FROZEN FOR FALSIFICATION
A14: MS-CT | B14: CT-C | C14: A02 | D14: Energy and heat | E14: 7 isolated generation cells | F14: MW | G14: 7 | H14: 6 | I14: 7.2 | J14: 50.4 | K14: 42 | L14: 43.2 | M14: 42 | N14: cell-local breaker, black start and thermal containment | O14: rebuild one 7.2 MW cell and isolation boundary | P14: RZ-02 | Q14: =Controls!$B$7 -> 0.025 | R14: =IF(AND(ISNUMBER(J14),ISNUMBER(K14),K14>0),J14/K14*(1-Q14),"") -> 1.17 | S14: =IF(AND(ISNUMBER(L14),ISNUMBER(M14),M14>0),L14/M14*(1-Q14),"") -> 1.0028571 | T14: =IF(AND(ISNUMBER(R14),ISNUMBER(S14)),MIN(R14,S14)-Controls!$B$8,"") -> 0.0028571429 | U14: FROZEN FOR FALSIFICATION
A15: MS-CT | B15: CT-C | C15: A03 | D15: Geometry and load path | E15: 5 complete multi-utility trunk corridors | F15: ratio | G15: 5 | H15: 4 | I15: 0.264 | J15: 1.32 | K15: 1 | L15: 1.056 | M15: 1 | N15: each corridor carries isolated power, water, communications, smoke and dirty return | O15: rebuild reversible attachment and five service boundaries | P15: Pass 182 retained | Q15: =Controls!$B$7 -> 0.025 | R15: =IF(AND(ISNUMBER(J15),ISNUMBER(K15),K15>0),J15/K15*(1-Q15),"") -> 1.287 | S15: =IF(AND(ISNUMBER(L15),ISNUMBER(M15),M15>0),L15/M15*(1-Q15),"") -> 1.0296 | T15: =IF(AND(ISNUMBER(R15),ISNUMBER(S15)),MIN(R15,S15)-Controls!$B$8,"") -> 0.0296 | U15: FROZEN FOR FALSIFICATION
A16: MS-CT | B16: CT-C | C16: A04 | D16: Safe state and human boundary | E16: 8 separately safe occupied zones | F16: ratio | G16: 8 | H16: 7 | I16: 0.15 | J16: 1.2 | K16: 1 | L16: 1.05 | M16: 1 | N16: smoke, contamination, egress and manual control do not cross zones | O16: rebuild one safe zone without displacing the receiver | P16: Pass 182 retained | Q16: =Controls!$B$7 -> 0.025 | R16: =IF(AND(ISNUMBER(J16),ISNUMBER(K16),K16>0),J16/K16*(1-Q16),"") -> 1.17 | S16: =IF(AND(ISNUMBER(L16),ISNUMBER(M16),M16>0),L16/M16*(1-Q16),"") -> 1.02375 | T16: =IF(AND(ISNUMBER(R16),ISNUMBER(S16)),MIN(R16,S16)-Controls!$B$8,"") -> 0.02375 | U16: FROZEN FOR FALSIFICATION
A17: MS-CT | B17: CT-C | C17: A05 | D17: Residual and environmental custody | E17: 6 dirty-return treatment cells | F17: t/day | G17: 6 | H17: 5 | I17: 46.2 | J17: 277.2 | K17: 220 | L17: 231 | M17: 220 | N17: valved return, contained buffer and sampled discharge per cell | O17: rebuild dirty-return cell and reconcile building inventory | P17: Pass 182 retained | Q17: =Controls!$B$7 -> 0.025 | R17: =IF(AND(ISNUMBER(J17),ISNUMBER(K17),K17>0),J17/K17*(1-Q17),"") -> 1.2285 | S17: =IF(AND(ISNUMBER(L17),ISNUMBER(M17),M17>0),L17/M17*(1-Q17),"") -> 1.02375 | T17: =IF(AND(ISNUMBER(R17),ISNUMBER(S17)),MIN(R17,S17)-Controls!$B$8,"") -> 0.02375 | U17: FROZEN FOR FALSIFICATION
A18: MS-CT | B18: CT-C | C18: A06 | D18: Removal and cold reconstruction | E18: sealed occupied-spine reconstruction chain | F18: h | G18: 1 | H18: 1 | N18: public attachment datum and clean tools survive loss of candidate runtime | O18: outside team removes and rebuilds section within 168 h | P18: Pass 219 protocol | Q18: =Controls!$B$7 -> 0.025 | R18: =IF(AND(ISNUMBER(J18),ISNUMBER(K18),K18>0),J18/K18*(1-Q18),"") | S18: =IF(AND(ISNUMBER(L18),ISNUMBER(M18),M18>0),L18/M18*(1-Q18),"") | T18: =IF(AND(ISNUMBER(R18),ISNUMBER(S18)),MIN(R18,S18)-Controls!$B$8,"") | U18: FROZEN FOR FALSIFICATION
A19: MS-HC | B19: HC-A | C19: A01 | D19: Mass and material custody | E19: 10 independently admitted intervention cells | F19: t | G19: 10 | H19: 9 | I19: 6300 | J19: 63000 | K19: 54000 | L19: 56700 | M19: 54000 | N19: carrier, refill and working-fluid custody remain serially separate | O19: rebuild intervention cell and custody record | P19: Pass 182 retained | Q19: =Controls!$B$7 -> 0.025 | R19: =IF(AND(ISNUMBER(J19),ISNUMBER(K19),K19>0),J19/K19*(1-Q19),"") -> 1.1375 | S19: =IF(AND(ISNUMBER(L19),ISNUMBER(M19),M19>0),L19/M19*(1-Q19),"") -> 1.02375 | T19: =IF(AND(ISNUMBER(R19),ISNUMBER(S19)),MIN(R19,S19)-Controls!$B$8,"") -> 0.02375 | U19: FROZEN FOR FALSIFICATION
A20: MS-HC | B20: HC-A | C20: A02 | D20: Energy and heat | E20: 8 isolated intervention-energy cells | F20: MW | G20: 8 | H20: 7 | I20: 20.6 | J20: 164.8 | K20: 140 | L20: 144.2 | M20: 140 | N20: cell-local conversion, start source and heat rejection | O20: rebuild one 20.6 MW energy cell | P20: RZ-04 | Q20: =Controls!$B$7 -> 0.025 | R20: =IF(AND(ISNUMBER(J20),ISNUMBER(K20),K20>0),J20/K20*(1-Q20),"") -> 1.1477143 | S20: =IF(AND(ISNUMBER(L20),ISNUMBER(M20),M20>0),L20/M20*(1-Q20),"") -> 1.00425 | T20: =IF(AND(ISNUMBER(R20),ISNUMBER(S20)),MIN(R20,S20)-Controls!$B$8,"") -> 0.00425 | U20: FROZEN FOR FALSIFICATION
A21: MS-HC | B21: HC-A | C21: A03 | D21: Geometry and load path | E21: 5 independently attributable held-line sectors | F21: km/day | G21: 5 | H21: 4 | I21: 26.5 | J21: 132.5 | K21: 103 | L21: 106 | M21: 103 | N21: each sector joins plume observation, delivery and protected edge | O21: rebuild one kilometre-scale causal sector | P21: RZ-03 | Q21: =Controls!$B$7 -> 0.025 | R21: =IF(AND(ISNUMBER(J21),ISNUMBER(K21),K21>0),J21/K21*(1-Q21),"") -> 1.2542476 | S21: =IF(AND(ISNUMBER(L21),ISNUMBER(M21),M21>0),L21/M21*(1-Q21),"") -> 1.0033981 | T21: =IF(AND(ISNUMBER(R21),ISNUMBER(S21)),MIN(R21,S21)-Controls!$B$8,"") -> 0.0033980583 | U21: FROZEN FOR FALSIFICATION
A22: MS-HC | B22: HC-A | C22: A04 | D22: Safe state and human boundary | E22: 8 protected response and avoidance zones | F22: ratio | G22: 8 | H22: 7 | I22: 0.15 | J22: 1.2 | K22: 1 | L22: 1.05 | M22: 1 | N22: independent avoidance, responder refuge and manual termination | O22: rebuild one protected zone and its public release | P22: Pass 182 retained | Q22: =Controls!$B$7 -> 0.025 | R22: =IF(AND(ISNUMBER(J22),ISNUMBER(K22),K22>0),J22/K22*(1-Q22),"") -> 1.17 | S22: =IF(AND(ISNUMBER(L22),ISNUMBER(M22),M22>0),L22/M22*(1-Q22),"") -> 1.02375 | T22: =IF(AND(ISNUMBER(R22),ISNUMBER(S22)),MIN(R22,S22)-Controls!$B$8,"") -> 0.02375 | U22: FROZEN FOR FALSIFICATION
A23: MS-HC | B23: HC-A | C23: A05 | D23: Residual and environmental custody | E23: 6 runoff and working-fluid custody cells | F23: t/day | G23: 6 | H23: 5 | I23: 189 | J23: 1134 | K23: 900 | L23: 945 | M23: 900 | N23: source, deposition, runoff and recovered material reconcile per cell | O23: rebuild fluid and runoff custody chain | P23: Pass 182 retained | Q23: =Controls!$B$7 -> 0.025 | R23: =IF(AND(ISNUMBER(J23),ISNUMBER(K23),K23>0),J23/K23*(1-Q23),"") -> 1.2285 | S23: =IF(AND(ISNUMBER(L23),ISNUMBER(M23),M23>0),L23/M23*(1-Q23),"") -> 1.02375 | T23: =IF(AND(ISNUMBER(R23),ISNUMBER(S23)),MIN(R23,S23)-Controls!$B$8,"") -> 0.02375 | U23: FROZEN FOR FALSIFICATION
A24: MS-HC | B24: HC-A | C24: A06 | D24: Removal and cold reconstruction | E24: sealed atmospheric-section reconstruction chain | F24: h | G24: 1 | H24: 1 | N24: public plume record and calibration survive deletion of mission runtime | O24: outside team recreates sensing-to-runoff section within 168 h | P24: Pass 219 protocol | Q24: =Controls!$B$7 -> 0.025 | R24: =IF(AND(ISNUMBER(J24),ISNUMBER(K24),K24>0),J24/K24*(1-Q24),"") | S24: =IF(AND(ISNUMBER(L24),ISNUMBER(M24),M24>0),L24/M24*(1-Q24),"") | T24: =IF(AND(ISNUMBER(R24),ISNUMBER(S24)),MIN(R24,S24)-Controls!$B$8,"") | U24: FROZEN FOR FALSIFICATION
A25: MS-LF | B25: LF-B | C25: A01 | D25: Mass and material custody | E25: 9 independent 3.99 kt access slots; 8 required | F25: kt | G25: 9 | H25: 8 | I25: 3.99 | J25: 35.91 | K25: 31.075 | L25: 31.92 | M25: 31.075 | N25: one access slot may disappear without deleting credited source hardware | O25: rebuild access schedule and custody for all required source sections | P25: RZ-05 decomposition | Q25: =Controls!$B$7 -> 0.025 | R25: =IF(AND(ISNUMBER(J25),ISNUMBER(K25),K25>0),J25/K25*(1-Q25),"") -> 1.1267015 | S25: =IF(AND(ISNUMBER(L25),ISNUMBER(M25),M25>0),L25/M25*(1-Q25),"") -> 1.0015125 | T25: =IF(AND(ISNUMBER(R25),ISNUMBER(S25)),MIN(R25,S25)-Controls!$B$8,"") -> 0.0015124698 | U25: FROZEN FOR FALSIFICATION
A26: MS-LF | B26: LF-B | C26: A02 | D26: Energy and heat | E26: 4 isolated conversion cells | F26: MW | G26: 4 | H26: 3 | I26: 13 | J26: 52 | K26: 37.351042 | L26: 39 | M26: 37.351042 | N26: separate conversion, breaker, black start and heat rejection per cell | O26: rebuild one 13 MW conversion cell | P26: RZ-06 | Q26: =Controls!$B$7 -> 0.025 | R26: =IF(AND(ISNUMBER(J26),ISNUMBER(K26),K26>0),J26/K26*(1-Q26),"") -> 1.3573919 | S26: =IF(AND(ISNUMBER(L26),ISNUMBER(M26),M26>0),L26/M26*(1-Q26),"") -> 1.0180439 | T26: =IF(AND(ISNUMBER(R26),ISNUMBER(S26)),MIN(R26,S26)-Controls!$B$8,"") -> 0.018043897 | U26: FROZEN FOR FALSIFICATION
A27: MS-LF | B27: LF-B | C27: A03 | D27: Geometry and load path | E27: 2 independently usable 15.5 km water paths | F27: pipe-km | G27: 2 | H27: 1 | I27: 15.5 | J27: 31 | K27: 30 | L27: 15.5 | M27: 15 | N27: either surveyed path reaches the lawful receiver without a shared active junction | O27: rebuild one buried route and verify alignment | P27: RZ-07 | Q27: =Controls!$B$7 -> 0.025 | R27: =IF(AND(ISNUMBER(J27),ISNUMBER(K27),K27>0),J27/K27*(1-Q27),"") -> 1.0075 | S27: =IF(AND(ISNUMBER(L27),ISNUMBER(M27),M27>0),L27/M27*(1-Q27),"") -> 1.0075 | T27: =IF(AND(ISNUMBER(R27),ISNUMBER(S27)),MIN(R27,S27)-Controls!$B$8,"") -> 0.0075 | U27: FROZEN FOR FALSIFICATION
A28: MS-LF | B28: LF-B | C28: A04 | D28: Safe state and human boundary | E28: 3 isolated 13,000 m3 product-water cells | F28: thousand m3 | G28: 3 | H28: 2 | I28: 13 | J28: 39 | K28: 25 | L28: 26 | M28: 25 | N28: buffer cells have separate valves, sensing and safe discharge | O28: rebuild one buffer cell and black-start boundary | P28: RZ-08 | Q28: =Controls!$B$7 -> 0.025 | R28: =IF(AND(ISNUMBER(J28),ISNUMBER(K28),K28>0),J28/K28*(1-Q28),"") -> 1.521 | S28: =IF(AND(ISNUMBER(L28),ISNUMBER(M28),M28>0),L28/M28*(1-Q28),"") -> 1.014 | T28: =IF(AND(ISNUMBER(R28),ISNUMBER(S28)),MIN(R28,S28)-Controls!$B$8,"") -> 0.014 | U28: FROZEN FOR FALSIFICATION
A29: MS-LF | B29: LF-B | C29: A05 | D29: Residual and environmental custody | E29: 3 isolated 10,300 m3/day injection paths | F29: thousand m3/day | G29: 3 | H29: 2 | I29: 10.3 | J29: 30.9 | K29: 20 | L29: 20.6 | M29: 20 | N29: production, brine treatment, injection and hazard sensing separate by path | O29: rebuild injection path and subsurface custody | P29: RZ-09 | Q29: =Controls!$B$7 -> 0.025 | R29: =IF(AND(ISNUMBER(J29),ISNUMBER(K29),K29>0),J29/K29*(1-Q29),"") -> 1.506375 | S29: =IF(AND(ISNUMBER(L29),ISNUMBER(M29),M29>0),L29/M29*(1-Q29),"") -> 1.00425 | T29: =IF(AND(ISNUMBER(R29),ISNUMBER(S29)),MIN(R29,S29)-Controls!$B$8,"") -> 0.00425 | U29: FROZEN FOR FALSIFICATION
A30: MS-LF | B30: LF-B | C30: A06 | D30: Removal and cold reconstruction | E30: sealed geothermal-position reconstruction chain | F30: h | G30: 1 | H30: 1 | N30: public subsurface truth and bore registry survive loss of source-house runtime | O30: outside team recreates bores-to-injection section within 168 h | P30: Pass 219 protocol | Q30: =Controls!$B$7 -> 0.025 | R30: =IF(AND(ISNUMBER(J30),ISNUMBER(K30),K30>0),J30/K30*(1-Q30),"") | S30: =IF(AND(ISNUMBER(L30),ISNUMBER(M30),M30>0),L30/M30*(1-Q30),"") | T30: =IF(AND(ISNUMBER(R30),ISNUMBER(S30)),MIN(R30,S30)-Controls!$B$8,"") | U30: FROZEN FOR FALSIFICATION
A31: MS-HU | B31: HU-A | C31: A01 | D31: Mass and material custody | E31: 8 independent 7.35 kt access cells | F31: kt | G31: 8 | H31: 7 | I31: 7.35 | J31: 58.8 | K31: 50 | L31: 51.45 | M31: 50 | N31: access loss cannot remove a care line or relationship record | O31: rebuild access cell while preserving clinical custody | P31: RZ-10 | Q31: =Controls!$B$7 -> 0.025 | R31: =IF(AND(ISNUMBER(J31),ISNUMBER(K31),K31>0),J31/K31*(1-Q31),"") -> 1.1466 | S31: =IF(AND(ISNUMBER(L31),ISNUMBER(M31),M31>0),L31/M31*(1-Q31),"") -> 1.003275 | T31: =IF(AND(ISNUMBER(R31),ISNUMBER(S31)),MIN(R31,S31)-Controls!$B$8,"") -> 0.003275 | U31: FROZEN FOR FALSIFICATION
A32: MS-HU | B32: HU-A | C32: A02 | D32: Energy and heat | E32: 6 isolated clinical-utility cells | F32: MW | G32: 6 | H32: 5 | I32: 11 | J32: 66 | K32: 52 | L32: 55 | M32: 52 | N32: each cell owns black start, sterile heat and cold-chain rejection | O32: rebuild one 11 MW utility cell | P32: Pass 182 retained | Q32: =Controls!$B$7 -> 0.025 | R32: =IF(AND(ISNUMBER(J32),ISNUMBER(K32),K32>0),J32/K32*(1-Q32),"") -> 1.2375 | S32: =IF(AND(ISNUMBER(L32),ISNUMBER(M32),M32>0),L32/M32*(1-Q32),"") -> 1.03125 | T32: =IF(AND(ISNUMBER(R32),ISNUMBER(S32)),MIN(R32,S32)-Controls!$B$8,"") -> 0.03125 | U32: FROZEN FOR FALSIFICATION
A33: MS-HU | B33: HU-A | C33: A03 | D33: Geometry and load path | E33: 10 indivisible care lines over separated transfer routes | F33: ratio | G33: 10 | H33: 10 | J33: 1.28 | K33: 1 | L33: 1.032 | M33: 1 | N33: care-line completeness survives access loss; transfer routes fail independently | O33: rebuild one care-route interface without deleting episode scope | P33: Pass 182 retained | Q33: =Controls!$B$7 -> 0.025 | R33: =IF(AND(ISNUMBER(J33),ISNUMBER(K33),K33>0),J33/K33*(1-Q33),"") -> 1.248 | S33: =IF(AND(ISNUMBER(L33),ISNUMBER(M33),M33>0),L33/M33*(1-Q33),"") -> 1.0062 | T33: =IF(AND(ISNUMBER(R33),ISNUMBER(S33)),MIN(R33,S33)-Controls!$B$8,"") -> 0.0062 | U33: FROZEN FOR FALSIFICATION
A34: MS-HU | B34: HU-A | C34: A04 | D34: Safe state and human boundary | E34: 8 separately safe clinical and refuge zones | F34: ratio | G34: 8 | H34: 7 | I34: 0.15 | J34: 1.2 | K34: 1 | L34: 1.05 | M34: 1 | N34: sterile isolation, refuge, egress and patient rights remain zone-local | O34: rebuild one safe clinical zone | P34: Pass 182 retained | Q34: =Controls!$B$7 -> 0.025 | R34: =IF(AND(ISNUMBER(J34),ISNUMBER(K34),K34>0),J34/K34*(1-Q34),"") -> 1.17 | S34: =IF(AND(ISNUMBER(L34),ISNUMBER(M34),M34>0),L34/M34*(1-Q34),"") -> 1.02375 | T34: =IF(AND(ISNUMBER(R34),ISNUMBER(S34)),MIN(R34,S34)-Controls!$B$8,"") -> 0.02375 | U34: FROZEN FOR FALSIFICATION
A35: MS-HU | B35: HU-A | C35: A05 | D35: Residual and environmental custody | E35: 6 clinical residual cells | F35: t/day | G35: 6 | H35: 5 | I35: 73.5 | J35: 441 | K35: 350 | L35: 367.5 | M35: 350 | N35: sterile and dirty counterflow, quarantine and disposal remain separate | O35: rebuild residual cell and signed disposition | P35: Pass 182 retained | Q35: =Controls!$B$7 -> 0.025 | R35: =IF(AND(ISNUMBER(J35),ISNUMBER(K35),K35>0),J35/K35*(1-Q35),"") -> 1.2285 | S35: =IF(AND(ISNUMBER(L35),ISNUMBER(M35),M35>0),L35/M35*(1-Q35),"") -> 1.02375 | T35: =IF(AND(ISNUMBER(R35),ISNUMBER(S35)),MIN(R35,S35)-Controls!$B$8,"") -> 0.02375 | U35: FROZEN FOR FALSIFICATION
A36: MS-HU | B36: HU-A | C36: A06 | D36: Removal and cold reconstruction | E36: sealed clinical-island reconstruction chain | F36: h | G36: 1 | H36: 1 | N36: lawful person and relationship records remain public while candidate runtime is absent | O36: outside team recreates all ten care-line interfaces within 168 h | P36: Pass 219 protocol | Q36: =Controls!$B$7 -> 0.025 | R36: =IF(AND(ISNUMBER(J36),ISNUMBER(K36),K36>0),J36/K36*(1-Q36),"") | S36: =IF(AND(ISNUMBER(L36),ISNUMBER(M36),M36>0),L36/M36*(1-Q36),"") | T36: =IF(AND(ISNUMBER(R36),ISNUMBER(S36)),MIN(R36,S36)-Controls!$B$8,"") | U36: FROZEN FOR FALSIFICATION
A37: MS-RT | B37: RT-B | C37: A01 | D37: Mass and material custody | E37: 10 independent 8.40 kt process-access cells | F37: t | G37: 10 | H37: 9 | I37: 8400 | J37: 84000 | K37: 72000 | L37: 75600 | M37: 72000 | N37: feedstock, tooling, product and rejected material remain serially attributable | O37: rebuild one process-access cell | P37: Pass 182 retained | Q37: =Controls!$B$7 -> 0.025 | R37: =IF(AND(ISNUMBER(J37),ISNUMBER(K37),K37>0),J37/K37*(1-Q37),"") -> 1.1375 | S37: =IF(AND(ISNUMBER(L37),ISNUMBER(M37),M37>0),L37/M37*(1-Q37),"") -> 1.02375 | T37: =IF(AND(ISNUMBER(R37),ISNUMBER(S37)),MIN(R37,S37)-Controls!$B$8,"") -> 0.02375 | U37: FROZEN FOR FALSIFICATION
A38: MS-RT | B38: RT-B | C38: A02 | D38: Energy and heat | E38: 7 isolated process-energy cells | F38: MW | G38: 7 | H38: 6 | I38: 26.5 | J38: 185.5 | K38: 155 | L38: 159 | M38: 155 | N38: cell-local conversion, black start and process heat rejection | O38: rebuild one 26.5 MW process-energy cell | P38: RZ-11 | Q38: =Controls!$B$7 -> 0.025 | R38: =IF(AND(ISNUMBER(J38),ISNUMBER(K38),K38>0),J38/K38*(1-Q38),"") -> 1.1668548 | S38: =IF(AND(ISNUMBER(L38),ISNUMBER(M38),M38>0),L38/M38*(1-Q38),"") -> 1.0001613 | T38: =IF(AND(ISNUMBER(R38),ISNUMBER(S38)),MIN(R38,S38)-Controls!$B$8,"") -> 0.00016129032 | U38: FROZEN FOR FALSIFICATION
A39: MS-RT | B39: RT-B | C39: A03 | D39: Geometry and load path | E39: 5 complete disconnected process meshes | F39: ratio | G39: 5 | H39: 4 | I39: 0.26 | J39: 1.3 | K39: 1 | L39: 1.04 | M39: 1 | N39: each mesh spans dirty return, diagnosis, manufacture, inspection and release | O39: rebuild one complete mesh from public interfaces | P39: Pass 182 retained | Q39: =Controls!$B$7 -> 0.025 | R39: =IF(AND(ISNUMBER(J39),ISNUMBER(K39),K39>0),J39/K39*(1-Q39),"") -> 1.2675 | S39: =IF(AND(ISNUMBER(L39),ISNUMBER(M39),M39>0),L39/M39*(1-Q39),"") -> 1.014 | T39: =IF(AND(ISNUMBER(R39),ISNUMBER(S39)),MIN(R39,S39)-Controls!$B$8,"") -> 0.014 | U39: FROZEN FOR FALSIFICATION
A40: MS-RT | B40: RT-B | C40: A04 | D40: Safe state and human boundary | E40: 9 independent release and receiver envelopes | F40: ratio | G40: 9 | H40: 8 | I40: 0.13125 | J40: 1.18125 | K40: 1 | L40: 1.05 | M40: 1 | N40: quarantine, manual stop and signed release remain locally enforceable | O40: rebuild one receiver/release envelope | P40: Pass 182 retained | Q40: =Controls!$B$7 -> 0.025 | R40: =IF(AND(ISNUMBER(J40),ISNUMBER(K40),K40>0),J40/K40*(1-Q40),"") -> 1.1517187 | S40: =IF(AND(ISNUMBER(L40),ISNUMBER(M40),M40>0),L40/M40*(1-Q40),"") -> 1.02375 | T40: =IF(AND(ISNUMBER(R40),ISNUMBER(S40)),MIN(R40,S40)-Controls!$B$8,"") -> 0.02375 | U40: FROZEN FOR FALSIFICATION
A41: MS-RT | B41: RT-B | C41: A05 | D41: Residual and environmental custody | E41: 6 rejected-material treatment cells | F41: t/day | G41: 6 | H41: 5 | I41: 252 | J41: 1512 | K41: 1200 | L41: 1260 | M41: 1200 | N41: dirty input, reject, recovery and disposal balance per cell | O41: rebuild residual treatment and reconcile material ancestry | P41: Pass 182 retained | Q41: =Controls!$B$7 -> 0.025 | R41: =IF(AND(ISNUMBER(J41),ISNUMBER(K41),K41>0),J41/K41*(1-Q41),"") -> 1.2285 | S41: =IF(AND(ISNUMBER(L41),ISNUMBER(M41),M41>0),L41/M41*(1-Q41),"") -> 1.02375 | T41: =IF(AND(ISNUMBER(R41),ISNUMBER(S41)),MIN(R41,S41)-Controls!$B$8,"") -> 0.02375 | U41: FROZEN FOR FALSIFICATION
A42: MS-RT | B42: RT-B | C42: A06 | D42: Removal and cold reconstruction | E42: sealed microfactory reconstruction chain | F42: h | G42: 1 | H42: 1 | N42: public material and calibration standards survive loss of process planner | O42: outside team recreates dirty-return-to-release mesh within 168 h | P42: Pass 219 protocol | Q42: =Controls!$B$7 -> 0.025 | R42: =IF(AND(ISNUMBER(J42),ISNUMBER(K42),K42>0),J42/K42*(1-Q42),"") | S42: =IF(AND(ISNUMBER(L42),ISNUMBER(M42),M42>0),L42/M42*(1-Q42),"") | T42: =IF(AND(ISNUMBER(R42),ISNUMBER(S42)),MIN(R42,S42)-Controls!$B$8,"") | U42: FROZEN FOR FALSIFICATION

Sheet Cell Register
A2: One hundred forty-four section-account-world decisions
A4: Sixty cells close by design arithmetic. Eighty-four have executable protocols but require observations. No specification is evidence and no root earns G06.
A6: Cell | B6: System | C6: Root | D6: Account | E6: Closure account | F6: World | G6: World state | H6: Section row | I6: Internal section | J6: Unit | K6: Capacity / limit | L6: Requirement / burden | M6: Adverse screen | N6: Lower-bound ratio | O6: Successor specification | P6: Specification executable | Q6: Evidence accepted | R6: G06 credit | S6: Disposition | T6: Basis | U6: Host contribution
A7: ET-A-A01-W01 | B7: MS-ET | C7: ET-A | D7: A01 | E7: Mass and material custody | F7: W01 | G7: Nominal mission | H7: 7 | I7: 8 independent access cells | J7: t | K7: =IF(ISNUMBER('Section Bills'!J7),'Section Bills'!J7,"") -> 128000 | L7: =IF(ISNUMBER('Section Bills'!K7),'Section Bills'!K7,"") -> 102000 | M7: =Controls!$B$7 -> 0.025 | N7: =IF(AND(ISNUMBER(K7),ISNUMBER(L7),L7>0),K7/L7*(1-M7),"") -> 1.2235294 | P7: =IF(O7="",0,COUNTIFS('Gap Migration'!$G$7:$G$91,O7,'Gap Migration'!$J$7:$J$91,1)) -> 0 | Q7: 0 | R7: 0 | S7: =IF(ISNUMBER(N7),IF(N7>=Controls!$B$8,"DESIGN CLOSE","NEGATIVE"),IF(P7=1,"MEASUREMENT READY","UNSCOPED")) -> DESIGN CLOSE | T7: =IF(S7="DESIGN CLOSE","root-native section bill",IF(S7="MEASUREMENT READY","executable protocol; observation empty","return to architecture")) -> root-native section bill | U7: 0
A8: ET-A-A01-W02 | B8: MS-ET | C8: ET-A | D8: A01 | E8: Mass and material custody | F8: W02 | G8: Fatal-keystone challenge | H8: 7 | I8: 8 independent access cells | J8: t | M8: =Controls!$B$7 -> 0.025 | N8: =IF(AND(ISNUMBER(K8),ISNUMBER(L8),L8>0),K8/L8*(1-M8),"") | O8: KX-ET-A-A01 | P8: =IF(O8="",0,COUNTIFS('Gap Migration'!$G$7:$G$91,O8,'Gap Migration'!$J$7:$J$91,1)) -> 1 | Q8: 0 | R8: 0 | S8: =IF(ISNUMBER(N8),IF(N8>=Controls!$B$8,"DESIGN CLOSE","NEGATIVE"),IF(P8=1,"MEASUREMENT READY","UNSCOPED")) -> MEASUREMENT READY | T8: =IF(S8="DESIGN CLOSE","root-native section bill",IF(S8="MEASUREMENT READY","executable protocol; observation empty","return to architecture")) -> executable protocol; observation empty | U8: 0
A9: ET-A-A01-W03 | B9: MS-ET | C9: ET-A | D9: A01 | E9: Mass and material custody | F9: W03 | G9: Largest-independent-cell loss | H9: 7 | I9: 8 independent access cells | J9: t | K9: =IF(ISNUMBER('Section Bills'!L7),'Section Bills'!L7,"") -> 112000 | L9: =IF(ISNUMBER('Section Bills'!M7),'Section Bills'!M7,"") -> 102000 | M9: =Controls!$B$7 -> 0.025 | N9: =IF(AND(ISNUMBER(K9),ISNUMBER(L9),L9>0),K9/L9*(1-M9),"") -> 1.0705882 | P9: =IF(O9="",0,COUNTIFS('Gap Migration'!$G$7:$G$91,O9,'Gap Migration'!$J$7:$J$91,1)) -> 0 | Q9: 0 | R9: 0 | S9: =IF(ISNUMBER(N9),IF(N9>=Controls!$B$8,"DESIGN CLOSE","NEGATIVE"),IF(P9=1,"MEASUREMENT READY","UNSCOPED")) -> DESIGN CLOSE | T9: =IF(S9="DESIGN CLOSE","root-native section bill",IF(S9="MEASUREMENT READY","executable protocol; observation empty","return to architecture")) -> root-native section bill | U9: 0
A10: ET-A-A01-W04 | B10: MS-ET | C10: ET-A | D10: A01 | E10: Mass and material custody | F10: W04 | G10: Cold reconstruction | H10: 7 | I10: 8 independent access cells | J10: t | M10: =Controls!$B$7 -> 0.025 | N10: =IF(AND(ISNUMBER(K10),ISNUMBER(L10),L10>0),K10/L10*(1-M10),"") | O10: RC-ET-A-A01 | P10: =IF(O10="",0,COUNTIFS('Gap Migration'!$G$7:$G$91,O10,'Gap Migration'!$J$7:$J$91,1)) -> 1 | Q10: 0 | R10: 0 | S10: =IF(ISNUMBER(N10),IF(N10>=Controls!$B$8,"DESIGN CLOSE","NEGATIVE"),IF(P10=1,"MEASUREMENT READY","UNSCOPED")) -> MEASUREMENT READY | T10: =IF(S10="DESIGN CLOSE","root-native section bill",IF(S10="MEASUREMENT READY","executable protocol; observation empty","return to architecture")) -> executable protocol; observation empty | U10: 0
A11: ET-A-A02-W01 | B11: MS-ET | C11: ET-A | D11: A02 | E11: Energy and heat | F11: W01 | G11: Nominal mission | H11: 8 | I11: 6 black-start generation cells | J11: MW | K11: =IF(ISNUMBER('Section Bills'!J8),'Section Bills'!J8,"") -> 120 | L11: =IF(ISNUMBER('Section Bills'!K8),'Section Bills'!K8,"") -> 96 | M11: =Controls!$B$7 -> 0.025 | N11: =IF(AND(ISNUMBER(K11),ISNUMBER(L11),L11>0),K11/L11*(1-M11),"") -> 1.21875 | P11: =IF(O11="",0,COUNTIFS('Gap Migration'!$G$7:$G$91,O11,'Gap Migration'!$J$7:$J$91,1)) -> 0 | Q11: 0 | R11: 0 | S11: =IF(ISNUMBER(N11),IF(N11>=Controls!$B$8,"DESIGN CLOSE","NEGATIVE"),IF(P11=1,"MEASUREMENT READY","UNSCOPED")) -> DESIGN CLOSE | T11: =IF(S11="DESIGN CLOSE","root-native section bill",IF(S11="MEASUREMENT READY","executable protocol; observation empty","return to architecture")) -> root-native section bill | U11: 0
A12: ET-A-A02-W02 | B12: MS-ET | C12: ET-A | D12: A02 | E12: Energy and heat | F12: W02 | G12: Fatal-keystone challenge | H12: 8 | I12: 6 black-start generation cells | J12: MW | M12: =Controls!$B$7 -> 0.025 | N12: =IF(AND(ISNUMBER(K12),ISNUMBER(L12),L12>0),K12/L12*(1-M12),"") | O12: KX-ET-A-A02 | P12: =IF(O12="",0,COUNTIFS('Gap Migration'!$G$7:$G$91,O12,'Gap Migration'!$J$7:$J$91,1)) -> 1 | Q12: 0 | R12: 0 | S12: =IF(ISNUMBER(N12),IF(N12>=Controls!$B$8,"DESIGN CLOSE","NEGATIVE"),IF(P12=1,"MEASUREMENT READY","UNSCOPED")) -> MEASUREMENT READY | T12: =IF(S12="DESIGN CLOSE","root-native section bill",IF(S12="MEASUREMENT READY","executable protocol; observation empty","return to architecture")) -> executable protocol; observation empty | U12: 0
A13: ET-A-A02-W03 | B13: MS-ET | C13: ET-A | D13: A02 | E13: Energy and heat | F13: W03 | G13: Largest-independent-cell loss | H13: 8 | I13: 6 black-start generation cells | J13: MW | K13: =IF(ISNUMBER('Section Bills'!L8),'Section Bills'!L8,"") -> 100 | L13: =IF(ISNUMBER('Section Bills'!M8),'Section Bills'!M8,"") -> 96 | M13: =Controls!$B$7 -> 0.025 | N13: =IF(AND(ISNUMBER(K13),ISNUMBER(L13),L13>0),K13/L13*(1-M13),"") -> 1.015625 | P13: =IF(O13="",0,COUNTIFS('Gap Migration'!$G$7:$G$91,O13,'Gap Migration'!$J$7:$J$91,1)) -> 0 | Q13: 0 | R13: 0 | S13: =IF(ISNUMBER(N13),IF(N13>=Controls!$B$8,"DESIGN CLOSE","NEGATIVE"),IF(P13=1,"MEASUREMENT READY","UNSCOPED")) -> DESIGN CLOSE | T13: =IF(S13="DESIGN CLOSE","root-native section bill",IF(S13="MEASUREMENT READY","executable protocol; observation empty","return to architecture")) -> root-native section bill | U13: 0
A14: ET-A-A02-W04 | B14: MS-ET | C14: ET-A | D14: A02 | E14: Energy and heat | F14: W04 | G14: Cold reconstruction | H14: 8 | I14: 6 black-start generation cells | J14: MW | M14: =Controls!$B$7 -> 0.025 | N14: =IF(AND(ISNUMBER(K14),ISNUMBER(L14),L14>0),K14/L14*(1-M14),"") | O14: RC-ET-A-A02 | P14: =IF(O14="",0,COUNTIFS('Gap Migration'!$G$7:$G$91,O14,'Gap Migration'!$J$7:$J$91,1)) -> 1 | Q14: 0 | R14: 0 | S14: =IF(ISNUMBER(N14),IF(N14>=Controls!$B$8,"DESIGN CLOSE","NEGATIVE"),IF(P14=1,"MEASUREMENT READY","UNSCOPED")) -> MEASUREMENT READY | T14: =IF(S14="DESIGN CLOSE","root-native section bill",IF(S14="MEASUREMENT READY","executable protocol; observation empty","return to architecture")) -> executable protocol; observation empty | U14: 0
A15: ET-A-A03-W01 | B15: MS-ET | C15: ET-A | D15: A03 | E15: Geometry and load path | F15: W01 | G15: Nominal mission | H15: 9 | I15: 2 complete motion-decoupled exchange paths | J15: t/h | K15: =IF(ISNUMBER('Section Bills'!J9),'Section Bills'!J9,"") -> 482 | L15: =IF(ISNUMBER('Section Bills'!K9),'Section Bills'!K9,"") -> 234.58333 | M15: =Controls!$B$7 -> 0.025 | N15: =IF(AND(ISNUMBER(K15),ISNUMBER(L15),L15>0),K15/L15*(1-M15),"") -> 2.0033393 | P15: =IF(O15="",0,COUNTIFS('Gap Migration'!$G$7:$G$91,O15,'Gap Migration'!$J$7:$J$91,1)) -> 0 | Q15: 0 | R15: 0 | S15: =IF(ISNUMBER(N15),IF(N15>=Controls!$B$8,"DESIGN CLOSE","NEGATIVE"),IF(P15=1,"MEASUREMENT READY","UNSCOPED")) -> DESIGN CLOSE | T15: =IF(S15="DESIGN CLOSE","root-native section bill",IF(S15="MEASUREMENT READY","executable protocol; observation empty","return to architecture")) -> root-native section bill | U15: 0
A16: ET-A-A03-W02 | B16: MS-ET | C16: ET-A | D16: A03 | E16: Geometry and load path | F16: W02 | G16: Fatal-keystone challenge | H16: 9 | I16: 2 complete motion-decoupled exchange paths | J16: t/h | M16: =Controls!$B$7 -> 0.025 | N16: =IF(AND(ISNUMBER(K16),ISNUMBER(L16),L16>0),K16/L16*(1-M16),"") | O16: KX-ET-A-A03 | P16: =IF(O16="",0,COUNTIFS('Gap Migration'!$G$7:$G$91,O16,'Gap Migration'!$J$7:$J$91,1)) -> 1 | Q16: 0 | R16: 0 | S16: =IF(ISNUMBER(N16),IF(N16>=Controls!$B$8,"DESIGN CLOSE","NEGATIVE"),IF(P16=1,"MEASUREMENT READY","UNSCOPED")) -> MEASUREMENT READY | T16: =IF(S16="DESIGN CLOSE","root-native section bill",IF(S16="MEASUREMENT READY","executable protocol; observation empty","return to architecture")) -> executable protocol; observation empty | U16: 0
A17: ET-A-A03-W03 | B17: MS-ET | C17: ET-A | D17: A03 | E17: Geometry and load path | F17: W03 | G17: Largest-independent-cell loss | H17: 9 | I17: 2 complete motion-decoupled exchange paths | J17: t/h | K17: =IF(ISNUMBER('Section Bills'!L9),'Section Bills'!L9,"") -> 241 | L17: =IF(ISNUMBER('Section Bills'!M9),'Section Bills'!M9,"") -> 234.58333 | M17: =Controls!$B$7 -> 0.025 | N17: =IF(AND(ISNUMBER(K17),ISNUMBER(L17),L17>0),K17/L17*(1-M17),"") -> 1.0016696 | P17: =IF(O17="",0,COUNTIFS('Gap Migration'!$G$7:$G$91,O17,'Gap Migration'!$J$7:$J$91,1)) -> 0 | Q17: 0 | R17: 0 | S17: =IF(ISNUMBER(N17),IF(N17>=Controls!$B$8,"DESIGN CLOSE","NEGATIVE"),IF(P17=1,"MEASUREMENT READY","UNSCOPED")) -> DESIGN CLOSE | T17: =IF(S17="DESIGN CLOSE","root-native section bill",IF(S17="MEASUREMENT READY","executable protocol; observation empty","return to architecture")) -> root-native section bill | U17: 0
A18: ET-A-A03-W04 | B18: MS-ET | C18: ET-A | D18: A03 | E18: Geometry and load path | F18: W04 | G18: Cold reconstruction | H18: 9 | I18: 2 complete motion-decoupled exchange paths | J18: t/h | M18: =Controls!$B$7 -> 0.025 | N18: =IF(AND(ISNUMBER(K18),ISNUMBER(L18),L18>0),K18/L18*(1-M18),"") | O18: RC-ET-A-A03 | P18: =IF(O18="",0,COUNTIFS('Gap Migration'!$G$7:$G$91,O18,'Gap Migration'!$J$7:$J$91,1)) -> 1 | Q18: 0 | R18: 0 | S18: =IF(ISNUMBER(N18),IF(N18>=Controls!$B$8,"DESIGN CLOSE","NEGATIVE"),IF(P18=1,"MEASUREMENT READY","UNSCOPED")) -> MEASUREMENT READY | T18: =IF(S18="DESIGN CLOSE","root-native section bill",IF(S18="MEASUREMENT READY","executable protocol; observation empty","return to architecture")) -> executable protocol; observation empty | U18: 0
A19: ET-A-A04-W01 | B19: MS-ET | C19: ET-A | D19: A04 | E19: Safe state and human boundary | F19: W01 | G19: Nominal mission | H19: 10 | I19: 6 independent refuge and receiver zones | J19: ratio | K19: =IF(ISNUMBER('Section Bills'!J10),'Section Bills'!J10,"") -> 1.26 | L19: =IF(ISNUMBER('Section Bills'!K10),'Section Bills'!K10,"") -> 1 | M19: =Controls!$B$7 -> 0.025 | N19: =IF(AND(ISNUMBER(K19),ISNUMBER(L19),L19>0),K19/L19*(1-M19),"") -> 1.2285 | P19: =IF(O19="",0,COUNTIFS('Gap Migration'!$G$7:$G$91,O19,'Gap Migration'!$J$7:$J$91,1)) -> 0 | Q19: 0 | R19: 0 | S19: =IF(ISNUMBER(N19),IF(N19>=Controls!$B$8,"DESIGN CLOSE","NEGATIVE"),IF(P19=1,"MEASUREMENT READY","UNSCOPED")) -> DESIGN CLOSE | T19: =IF(S19="DESIGN CLOSE","root-native section bill",IF(S19="MEASUREMENT READY","executable protocol; observation empty","return to architecture")) -> root-native section bill | U19: 0
A20: ET-A-A04-W02 | B20: MS-ET | C20: ET-A | D20: A04 | E20: Safe state and human boundary | F20: W02 | G20: Fatal-keystone challenge | H20: 10 | I20: 6 independent refuge and receiver zones | J20: ratio | M20: =Controls!$B$7 -> 0.025 | N20: =IF(AND(ISNUMBER(K20),ISNUMBER(L20),L20>0),K20/L20*(1-M20),"") | O20: KX-ET-A-A04 | P20: =IF(O20="",0,COUNTIFS('Gap Migration'!$G$7:$G$91,O20,'Gap Migration'!$J$7:$J$91,1)) -> 1 | Q20: 0 | R20: 0 | S20: =IF(ISNUMBER(N20),IF(N20>=Controls!$B$8,"DESIGN CLOSE","NEGATIVE"),IF(P20=1,"MEASUREMENT READY","UNSCOPED")) -> MEASUREMENT READY | T20: =IF(S20="DESIGN CLOSE","root-native section bill",IF(S20="MEASUREMENT READY","executable protocol; observation empty","return to architecture")) -> executable protocol; observation empty | U20: 0
A21: ET-A-A04-W03 | B21: MS-ET | C21: ET-A | D21: A04 | E21: Safe state and human boundary | F21: W03 | G21: Largest-independent-cell loss | H21: 10 | I21: 6 independent refuge and receiver zones | J21: ratio | K21: =IF(ISNUMBER('Section Bills'!L10),'Section Bills'!L10,"") -> 1.05 | L21: =IF(ISNUMBER('Section Bills'!M10),'Section Bills'!M10,"") -> 1 | M21: =Controls!$B$7 -> 0.025 | N21: =IF(AND(ISNUMBER(K21),ISNUMBER(L21),L21>0),K21/L21*(1-M21),"") -> 1.02375 | P21: =IF(O21="",0,COUNTIFS('Gap Migration'!$G$7:$G$91,O21,'Gap Migration'!$J$7:$J$91,1)) -> 0 | Q21: 0 | R21: 0 | S21: =IF(ISNUMBER(N21),IF(N21>=Controls!$B$8,"DESIGN CLOSE","NEGATIVE"),IF(P21=1,"MEASUREMENT READY","UNSCOPED")) -> DESIGN CLOSE | T21: =IF(S21="DESIGN CLOSE","root-native section bill",IF(S21="MEASUREMENT READY","executable protocol; observation empty","return to architecture")) -> root-native section bill | U21: 0
A22: ET-A-A04-W04 | B22: MS-ET | C22: ET-A | D22: A04 | E22: Safe state and human boundary | F22: W04 | G22: Cold reconstruction | H22: 10 | I22: 6 independent refuge and receiver zones | J22: ratio | M22: =Controls!$B$7 -> 0.025 | N22: =IF(AND(ISNUMBER(K22),ISNUMBER(L22),L22>0),K22/L22*(1-M22),"") | O22: RC-ET-A-A04 | P22: =IF(O22="",0,COUNTIFS('Gap Migration'!$G$7:$G$91,O22,'Gap Migration'!$J$7:$J$91,1)) -> 1 | Q22: 0 | R22: 0 | S22: =IF(ISNUMBER(N22),IF(N22>=Controls!$B$8,"DESIGN CLOSE","NEGATIVE"),IF(P22=1,"MEASUREMENT READY","UNSCOPED")) -> MEASUREMENT READY | T22: =IF(S22="DESIGN CLOSE","root-native section bill",IF(S22="MEASUREMENT READY","executable protocol; observation empty","return to architecture")) -> executable protocol; observation empty | U22: 0
A23: ET-A-A05-W01 | B23: MS-ET | C23: ET-A | D23: A05 | E23: Residual and environmental custody | F23: W01 | G23: Nominal mission | H23: 11 | I23: 6 contained residual cells | J23: t/day | K23: =IF(ISNUMBER('Section Bills'!J11),'Section Bills'!J11,"") -> 1512 | L23: =IF(ISNUMBER('Section Bills'!K11),'Section Bills'!K11,"") -> 1200 | M23: =Controls!$B$7 -> 0.025 | N23: =IF(AND(ISNUMBER(K23),ISNUMBER(L23),L23>0),K23/L23*(1-M23),"") -> 1.2285 | P23: =IF(O23="",0,COUNTIFS('Gap Migration'!$G$7:$G$91,O23,'Gap Migration'!$J$7:$J$91,1)) -> 0 | Q23: 0 | R23: 0 | S23: =IF(ISNUMBER(N23),IF(N23>=Controls!$B$8,"DESIGN CLOSE","NEGATIVE"),IF(P23=1,"MEASUREMENT READY","UNSCOPED")) -> DESIGN CLOSE | T23: =IF(S23="DESIGN CLOSE","root-native section bill",IF(S23="MEASUREMENT READY","executable protocol; observation empty","return to architecture")) -> root-native section bill | U23: 0
A24: ET-A-A05-W02 | B24: MS-ET | C24: ET-A | D24: A05 | E24: Residual and environmental custody | F24: W02 | G24: Fatal-keystone challenge | H24: 11 | I24: 6 contained residual cells | J24: t/day | M24: =Controls!$B$7 -> 0.025 | N24: =IF(AND(ISNUMBER(K24),ISNUMBER(L24),L24>0),K24/L24*(1-M24),"") | O24: KX-ET-A-A05 | P24: =IF(O24="",0,COUNTIFS('Gap Migration'!$G$7:$G$91,O24,'Gap Migration'!$J$7:$J$91,1)) -> 1 | Q24: 0 | R24: 0 | S24: =IF(ISNUMBER(N24),IF(N24>=Controls!$B$8,"DESIGN CLOSE","NEGATIVE"),IF(P24=1,"MEASUREMENT READY","UNSCOPED")) -> MEASUREMENT READY | T24: =IF(S24="DESIGN CLOSE","root-native section bill",IF(S24="MEASUREMENT READY","executable protocol; observation empty","return to architecture")) -> executable protocol; observation empty | U24: 0
A25: ET-A-A05-W03 | B25: MS-ET | C25: ET-A | D25: A05 | E25: Residual and environmental custody | F25: W03 | G25: Largest-independent-cell loss | H25: 11 | I25: 6 contained residual cells | J25: t/day | K25: =IF(ISNUMBER('Section Bills'!L11),'Section Bills'!L11,"") -> 1260 | L25: =IF(ISNUMBER('Section Bills'!M11),'Section Bills'!M11,"") -> 1200 | M25: =Controls!$B$7 -> 0.025 | N25: =IF(AND(ISNUMBER(K25),ISNUMBER(L25),L25>0),K25/L25*(1-M25),"") -> 1.02375 | P25: =IF(O25="",0,COUNTIFS('Gap Migration'!$G$7:$G$91,O25,'Gap Migration'!$J$7:$J$91,1)) -> 0 | Q25: 0 | R25: 0 | S25: =IF(ISNUMBER(N25),IF(N25>=Controls!$B$8,"DESIGN CLOSE","NEGATIVE"),IF(P25=1,"MEASUREMENT READY","UNSCOPED")) -> DESIGN CLOSE | T25: =IF(S25="DESIGN CLOSE","root-native section bill",IF(S25="MEASUREMENT READY","executable protocol; observation empty","return to architecture")) -> root-native section bill | U25: 0
A26: ET-A-A05-W04 | B26: MS-ET | C26: ET-A | D26: A05 | E26: Residual and environmental custody | F26: W04 | G26: Cold reconstruction | H26: 11 | I26: 6 contained residual cells | J26: t/day | M26: =Controls!$B$7 -> 0.025 | N26: =IF(AND(ISNUMBER(K26),ISNUMBER(L26),L26>0),K26/L26*(1-M26),"") | O26: RC-ET-A-A05 | P26: =IF(O26="",0,COUNTIFS('Gap Migration'!$G$7:$G$91,O26,'Gap Migration'!$J$7:$J$91,1)) -> 1 | Q26: 0 | R26: 0 | S26: =IF(ISNUMBER(N26),IF(N26>=Controls!$B$8,"DESIGN CLOSE","NEGATIVE"),IF(P26=1,"MEASUREMENT READY","UNSCOPED")) -> MEASUREMENT READY | T26: =IF(S26="DESIGN CLOSE","root-native section bill",IF(S26="MEASUREMENT READY","executable protocol; observation empty","return to architecture")) -> executable protocol; observation empty | U26: 0
A27: ET-A-A06-W01 | B27: MS-ET | C27: ET-A | D27: A06 | E27: Removal and cold reconstruction | F27: W01 | G27: Nominal mission | H27: 12 | I27: sealed exchange-section reconstruction chain | J27: h | M27: =Controls!$B$7 -> 0.025 | N27: =IF(AND(ISNUMBER(K27),ISNUMBER(L27),L27>0),K27/L27*(1-M27),"") | O27: RB-ET-A-W01 | P27: =IF(O27="",0,COUNTIFS('Gap Migration'!$G$7:$G$91,O27,'Gap Migration'!$J$7:$J$91,1)) -> 1 | Q27: 0 | R27: 0 | S27: =IF(ISNUMBER(N27),IF(N27>=Controls!$B$8,"DESIGN CLOSE","NEGATIVE"),IF(P27=1,"MEASUREMENT READY","UNSCOPED")) -> MEASUREMENT READY | T27: =IF(S27="DESIGN CLOSE","root-native section bill",IF(S27="MEASUREMENT READY","executable protocol; observation empty","return to architecture")) -> executable protocol; observation empty | U27: 0
A28: ET-A-A06-W02 | B28: MS-ET | C28: ET-A | D28: A06 | E28: Removal and cold reconstruction | F28: W02 | G28: Fatal-keystone challenge | H28: 12 | I28: sealed exchange-section reconstruction chain | J28: h | M28: =Controls!$B$7 -> 0.025 | N28: =IF(AND(ISNUMBER(K28),ISNUMBER(L28),L28>0),K28/L28*(1-M28),"") | O28: KX-ET-A-A06 | P28: =IF(O28="",0,COUNTIFS('Gap Migration'!$G$7:$G$91,O28,'Gap Migration'!$J$7:$J$91,1)) -> 1 | Q28: 0 | R28: 0 | S28: =IF(ISNUMBER(N28),IF(N28>=Controls!$B$8,"DESIGN CLOSE","NEGATIVE"),IF(P28=1,"MEASUREMENT READY","UNSCOPED")) -> MEASUREMENT READY | T28: =IF(S28="DESIGN CLOSE","root-native section bill",IF(S28="MEASUREMENT READY","executable protocol; observation empty","return to architecture")) -> executable protocol; observation empty | U28: 0
A29: ET-A-A06-W03 | B29: MS-ET | C29: ET-A | D29: A06 | E29: Removal and cold reconstruction | F29: W03 | G29: Largest-independent-cell loss | H29: 12 | I29: sealed exchange-section reconstruction chain | J29: h | M29: =Controls!$B$7 -> 0.025 | N29: =IF(AND(ISNUMBER(K29),ISNUMBER(L29),L29>0),K29/L29*(1-M29),"") | O29: RB-ET-A-W03 | P29: =IF(O29="",0,COUNTIFS('Gap Migration'!$G$7:$G$91,O29,'Gap Migration'!$J$7:$J$91,1)) -> 1 | Q29: 0 | R29: 0 | S29: =IF(ISNUMBER(N29),IF(N29>=Controls!$B$8,"DESIGN CLOSE","NEGATIVE"),IF(P29=1,"MEASUREMENT READY","UNSCOPED")) -> MEASUREMENT READY | T29: =IF(S29="DESIGN CLOSE","root-native section bill",IF(S29="MEASUREMENT READY","executable protocol; observation empty","return to architecture")) -> executable protocol; observation empty | U29: 0
A30: ET-A-A06-W04 | B30: MS-ET | C30: ET-A | D30: A06 | E30: Removal and cold reconstruction | F30: W04 | G30: Cold reconstruction | H30: 12 | I30: sealed exchange-section reconstruction chain | J30: h | M30: =Controls!$B$7 -> 0.025 | N30: =IF(AND(ISNUMBER(K30),ISNUMBER(L30),L30>0),K30/L30*(1-M30),"") | O30: RC-ET-A-A06 | P30: =IF(O30="",0,COUNTIFS('Gap Migration'!$G$7:$G$91,O30,'Gap Migration'!$J$7:$J$91,1)) -> 1 | Q30: 0 | R30: 0 | S30: =IF(ISNUMBER(N30),IF(N30>=Controls!$B$8,"DESIGN CLOSE","NEGATIVE"),IF(P30=1,"MEASUREMENT READY","UNSCOPED")) -> MEASUREMENT READY | T30: =IF(S30="DESIGN CLOSE","root-native section bill",IF(S30="MEASUREMENT READY","executable protocol; observation empty","return to architecture")) -> executable protocol; observation empty | U30: 0
A31: CT-C-A01-W01 | B31: MS-CT | C31: CT-C | D31: A01 | E31: Mass and material custody | F31: W01 | G31: Nominal mission | H31: 13 | I31: 10 independently admitted insertion cells | J31: t | K31: =IF(ISNUMBER('Section Bills'!J13),'Section Bills'!J13,"") -> 36000 | L31: =IF(ISNUMBER('Section Bills'!K13),'Section Bills'!K13,"") -> 31000 | M31: =Controls!$B$7 -> 0.025 | N31: =IF(AND(ISNUMBER(K31),ISNUMBER(L31),L31>0),K31/L31*(1-M31),"") -> 1.1322581 | P31: =IF(O31="",0,COUNTIFS('Gap Migration'!$G$7:$G$91,O31,'Gap Migration'!$J$7:$J$91,1)) -> 0 | Q31: 0 | R31: 0 | S31: =IF(ISNUMBER(N31),IF(N31>=Controls!$B$8,"DESIGN CLOSE","NEGATIVE"),IF(P31=1,"MEASUREMENT READY","UNSCOPED")) -> DESIGN CLOSE | T31: =IF(S31="DESIGN CLOSE","root-native section bill",IF(S31="MEASUREMENT READY","executable protocol; observation empty","return to architecture")) -> root-native section bill | U31: 0
A32: CT-C-A01-W02 | B32: MS-CT | C32: CT-C | D32: A01 | E32: Mass and material custody | F32: W02 | G32: Fatal-keystone challenge | H32: 13 | I32: 10 independently admitted insertion cells | J32: t | M32: =Controls!$B$7 -> 0.025 | N32: =IF(AND(ISNUMBER(K32),ISNUMBER(L32),L32>0),K32/L32*(1-M32),"") | O32: KX-CT-C-A01 | P32: =IF(O32="",0,COUNTIFS('Gap Migration'!$G$7:$G$91,O32,'Gap Migration'!$J$7:$J$91,1)) -> 1 | Q32: 0 | R32: 0 | S32: =IF(ISNUMBER(N32),IF(N32>=Controls!$B$8,"DESIGN CLOSE","NEGATIVE"),IF(P32=1,"MEASUREMENT READY","UNSCOPED")) -> MEASUREMENT READY | T32: =IF(S32="DESIGN CLOSE","root-native section bill",IF(S32="MEASUREMENT READY","executable protocol; observation empty","return to architecture")) -> executable protocol; observation empty | U32: 0
A33: CT-C-A01-W03 | B33: MS-CT | C33: CT-C | D33: A01 | E33: Mass and material custody | F33: W03 | G33: Largest-independent-cell loss | H33: 13 | I33: 10 independently admitted insertion cells | J33: t | K33: =IF(ISNUMBER('Section Bills'!L13),'Section Bills'!L13,"") -> 32400 | L33: =IF(ISNUMBER('Section Bills'!M13),'Section Bills'!M13,"") -> 31000 | M33: =Controls!$B$7 -> 0.025 | N33: =IF(AND(ISNUMBER(K33),ISNUMBER(L33),L33>0),K33/L33*(1-M33),"") -> 1.0190323 | P33: =IF(O33="",0,COUNTIFS('Gap Migration'!$G$7:$G$91,O33,'Gap Migration'!$J$7:$J$91,1)) -> 0 | Q33: 0 | R33: 0 | S33: =IF(ISNUMBER(N33),IF(N33>=Controls!$B$8,"DESIGN CLOSE","NEGATIVE"),IF(P33=1,"MEASUREMENT READY","UNSCOPED")) -> DESIGN CLOSE | T33: =IF(S33="DESIGN CLOSE","root-native section bill",IF(S33="MEASUREMENT READY","executable protocol; observation empty","return to architecture")) -> root-native section bill | U33: 0
A34: CT-C-A01-W04 | B34: MS-CT | C34: CT-C | D34: A01 | E34: Mass and material custody | F34: W04 | G34: Cold reconstruction | H34: 13 | I34: 10 independently admitted insertion cells | J34: t | M34: =Controls!$B$7 -> 0.025 | N34: =IF(AND(ISNUMBER(K34),ISNUMBER(L34),L34>0),K34/L34*(1-M34),"") | O34: RC-CT-C-A01 | P34: =IF(O34="",0,COUNTIFS('Gap Migration'!$G$7:$G$91,O34,'Gap Migration'!$J$7:$J$91,1)) -> 1 | Q34: 0 | R34: 0 | S34: =IF(ISNUMBER(N34),IF(N34>=Controls!$B$8,"DESIGN CLOSE","NEGATIVE"),IF(P34=1,"MEASUREMENT READY","UNSCOPED")) -> MEASUREMENT READY | T34: =IF(S34="DESIGN CLOSE","root-native section bill",IF(S34="MEASUREMENT READY","executable protocol; observation empty","return to architecture")) -> executable protocol; observation empty | U34: 0
A35: CT-C-A02-W01 | B35: MS-CT | C35: CT-C | D35: A02 | E35: Energy and heat | F35: W01 | G35: Nominal mission | H35: 14 | I35: 7 isolated generation cells | J35: MW | K35: =IF(ISNUMBER('Section Bills'!J14),'Section Bills'!J14,"") -> 50.4 | L35: =IF(ISNUMBER('Section Bills'!K14),'Section Bills'!K14,"") -> 42 | M35: =Controls!$B$7 -> 0.025 | N35: =IF(AND(ISNUMBER(K35),ISNUMBER(L35),L35>0),K35/L35*(1-M35),"") -> 1.17 | P35: =IF(O35="",0,COUNTIFS('Gap Migration'!$G$7:$G$91,O35,'Gap Migration'!$J$7:$J$91,1)) -> 0 | Q35: 0 | R35: 0 | S35: =IF(ISNUMBER(N35),IF(N35>=Controls!$B$8,"DESIGN CLOSE","NEGATIVE"),IF(P35=1,"MEASUREMENT READY","UNSCOPED")) -> DESIGN CLOSE | T35: =IF(S35="DESIGN CLOSE","root-native section bill",IF(S35="MEASUREMENT READY","executable protocol; observation empty","return to architecture")) -> root-native section bill | U35: 0
A36: CT-C-A02-W02 | B36: MS-CT | C36: CT-C | D36: A02 | E36: Energy and heat | F36: W02 | G36: Fatal-keystone challenge | H36: 14 | I36: 7 isolated generation cells | J36: MW | M36: =Controls!$B$7 -> 0.025 | N36: =IF(AND(ISNUMBER(K36),ISNUMBER(L36),L36>0),K36/L36*(1-M36),"") | O36: KX-CT-C-A02 | P36: =IF(O36="",0,COUNTIFS('Gap Migration'!$G$7:$G$91,O36,'Gap Migration'!$J$7:$J$91,1)) -> 1 | Q36: 0 | R36: 0 | S36: =IF(ISNUMBER(N36),IF(N36>=Controls!$B$8,"DESIGN CLOSE","NEGATIVE"),IF(P36=1,"MEASUREMENT READY","UNSCOPED")) -> MEASUREMENT READY | T36: =IF(S36="DESIGN CLOSE","root-native section bill",IF(S36="MEASUREMENT READY","executable protocol; observation empty","return to architecture")) -> executable protocol; observation empty | U36: 0
A37: CT-C-A02-W03 | B37: MS-CT | C37: CT-C | D37: A02 | E37: Energy and heat | F37: W03 | G37: Largest-independent-cell loss | H37: 14 | I37: 7 isolated generation cells | J37: MW | K37: =IF(ISNUMBER('Section Bills'!L14),'Section Bills'!L14,"") -> 43.2 | L37: =IF(ISNUMBER('Section Bills'!M14),'Section Bills'!M14,"") -> 42 | M37: =Controls!$B$7 -> 0.025 | N37: =IF(AND(ISNUMBER(K37),ISNUMBER(L37),L37>0),K37/L37*(1-M37),"") -> 1.0028571 | P37: =IF(O37="",0,COUNTIFS('Gap Migration'!$G$7:$G$91,O37,'Gap Migration'!$J$7:$J$91,1)) -> 0 | Q37: 0 | R37: 0 | S37: =IF(ISNUMBER(N37),IF(N37>=Controls!$B$8,"DESIGN CLOSE","NEGATIVE"),IF(P37=1,"MEASUREMENT READY","UNSCOPED")) -> DESIGN CLOSE | T37: =IF(S37="DESIGN CLOSE","root-native section bill",IF(S37="MEASUREMENT READY","executable protocol; observation empty","return to architecture")) -> root-native section bill | U37: 0
