Workbook

Sheet Decision
A2: First-tranche industrial transaction
A3: Pass 207 | PFP-2 | separated option-and-proof market | Verdict: CLOSE
A6: Selected constitution
A7: Constitute twenty-four bankruptcy-remote Root Houses, each liable for one complete system root, but award only cancelable evidence-bearing options. Ninety-six root-field assignments remain traceable; twelve decisive domains remain root-exclusive; shared providers may touch at most two roots. Public authorities own service denominators, proof, foreground step-in rights and termination. Valid failure is paid; favorable evidence earns no production credit.
A12: First-tranche control | B12: Value | C12: Unit | E12: Control diagnostic | F12: Value | G12: Unit
A13: Root Houses | B13: =COUNTA('Root Options'!A7:A30) -> 24 | C13: firms | E13: Root-control HHI | F13: ='Root Options'!M31 -> 0.04624968 | G13: share squared
A14: Root-field assignments | B14: =COUNTA('Field Awards'!A7:A102) -> 96 | C14: opportunities | E14: Effective control groups | F14: =1/F13 -> 21.621771 | G14: groups
A15: Decisive ancestry cells | B15: =COUNTA('Ancestry Register'!A7:A294) -> 288 | C15: declarations | E15: Six-prime HHI | F15: ='Industry Shape'!C8 -> 0.18499872 | G15: share squared
A16: Shared dependency records | B16: =COUNTA('Shared Dependencies'!A7:A78) -> 72 | C16: records | E16: Six-prime effective groups | F16: ='Industry Shape'!D8 -> 5.4054428 | G16: groups
A17: Mission authority | B17: ='Account Control'!B7 -> 110 | C17: USD billions | E17: Active mission share | F17: ='Root Options'!F31/'Account Control'!B7 -> 0.52173277 | G17: percent
A18: Stageable root options | B18: ='Root Options'!F31 -> 57.390605 | C18: USD billions | E18: Root option payment phases | F18: =COUNTA('Payment Ladder'!A7:A10) -> 4 | G18: phases
A19: Mission options held | B19: ='Root Options'!G31 -> 52.609395 | C19: USD billions | E19: Transaction states | F19: =COUNTA('Transaction States'!A7:A14) -> 8 | G19: states
A20: Public and enabling accounts | B20: ='Account Control'!F18 -> 80 | C20: USD billions | E20: Failure dispositions | F20: =COUNTA('Failure & Exit'!A7:A16) -> 10 | G20: rules
A21: Production credit | B21: =SUM('Root Options'!L7:L30) -> 0 | C21: USD billions | E21: Current awarded roots | F21: =COUNTIFS('Root Options'!H7:H30,"<>SOURCE EMPTY") -> 0 | G21: roots
A23: Candidate constitutions
A24: Candidate | B24: Passed gates | C24: Result | D24: Complete-root liability | E24: Root independence | F24: Independent proof | G24: Paid failure | H24: Public step-in | I24: New entry | J24: No production inference | K24: Control HHI | L24: Reason
A25: ='Architecture Test'!A7 -> Separated option-and-proof market | B25: ='Architecture Test'!N7 -> 12 | C25: ='Architecture Test'!O7 -> SELECT | D25: ='Architecture Test'!C7 -> 1 | E25: ='Architecture Test'!D7 -> 1 | F25: ='Architecture Test'!G7 -> 1 | G25: ='Architecture Test'!H7 -> 1 | H25: ='Architecture Test'!I7 -> 1 | I25: ='Architecture Test'!L7 -> 1 | J25: ='Architecture Test'!M7 -> 1 | K25: ='Industry Shape'!C7 -> 0.04624968 | L25: ='Architecture Test'!P7 -> One cancelable root option per independent house; public proof and step-in remain separate.
A26: ='Architecture Test'!A8 -> Six lead system integrators | B26: ='Architecture Test'!N8 -> 8 | C26: ='Architecture Test'!O8 -> REJECT | D26: ='Architecture Test'!C8 -> 1 | E26: ='Architecture Test'!D8 -> 0 | F26: ='Architecture Test'!G8 -> 1 | G26: ='Architecture Test'!H8 -> 1 | H26: ='Architecture Test'!I8 -> 1 | I26: ='Architecture Test'!L8 -> 0 | J26: ='Architecture Test'!M8 -> 1 | K26: ='Industry Shape'!C8 -> 0.18499872 | L26: ='Architecture Test'!P8 -> One balance sheet, key chain and integration authority can remove four roots together.
A27: ='Architecture Test'!A9 -> Ninety-six independent prize cells | B27: ='Architecture Test'!N9 -> 9 | C27: ='Architecture Test'!O9 -> REJECT | D27: ='Architecture Test'!C9 -> 0 | E27: ='Architecture Test'!D9 -> 1 | F27: ='Architecture Test'!G9 -> 1 | G27: ='Architecture Test'!H9 -> 1 | H27: ='Architecture Test'!I9 -> 1 | I27: ='Architecture Test'!L9 -> 1 | J27: ='Architecture Test'!M9 -> 0 | K27: ='Industry Shape'!C9 -> 0.01156242 | L27: ='Architecture Test'!P9 -> Excellent mechanism diversity leaves no actor liable for a complete root or executable service.
A28: ='Architecture Test'!A10 -> Twenty-four perpetual franchises | B28: ='Architecture Test'!N10 -> 7 | C28: ='Architecture Test'!O10 -> REJECT | D28: ='Architecture Test'!C10 -> 1 | E28: ='Architecture Test'!D10 -> 1 | F28: ='Architecture Test'!G10 -> 0 | G28: ='Architecture Test'!H10 -> 0 | H28: ='Architecture Test'!I10 -> 0 | I28: ='Architecture Test'!L10 -> 0 | J28: ='Architecture Test'!M10 -> 1 | K28: ='Industry Shape'!C10 -> 0.04624968 | L28: ='Architecture Test'!P10 -> Protected incumbency makes adverse evidence and replacement nonbinding.
A29: ='Architecture Test'!A11 -> Sovereign public arsenal | B29: ='Architecture Test'!N11 -> 7 | C29: ='Architecture Test'!O11 -> REJECT | D29: ='Architecture Test'!C11 -> 1 | E29: ='Architecture Test'!D11 -> 0 | F29: ='Architecture Test'!G11 -> 0 | G29: ='Architecture Test'!H11 -> 1 | H29: ='Architecture Test'!I11 -> 1 | I29: ='Architecture Test'!L11 -> 0 | J29: ='Architecture Test'!M11 -> 1 | K29: ='Industry Shape'!C11 -> 1 | L29: ='Architecture Test'!P11 -> One public toolchain becomes the national common root and judges its own reconstruction.

Sheet Architecture Test
A2: Industrial architecture test
A3: Selection requires all twelve gates. Concentration diagnostics inform the test but cannot compensate for a failed constitutional condition.
A6: Candidate | B6: Public denominator | C6: Complete-root liability | D6: 24 control groups | E6: Exclusive ancestry | F6: Provider cap | G6: Independent proof | H6: Paid valid failure | I6: Public step-in | J6: Fiscal conservation | K6: No production inference | L6: Replacement entry | M6: Executable in T1 | N6: Passed gates | O6: Result | P6: Governing reason
A7: Separated option-and-proof market | B7: 1 | C7: 1 | D7: 1 | E7: 1 | F7: 1 | G7: 1 | H7: 1 | I7: 1 | J7: 1 | K7: 1 | L7: 1 | M7: 1 | N7: =SUM(B7:M7) -> 12 | O7: =IF(N7=12,"SELECT","REJECT") -> SELECT | P7: One cancelable root option per independent house; public proof and step-in remain separate.
A8: Six lead system integrators | B8: 1 | C8: 1 | D8: 0 | E8: 0 | F8: 0 | G8: 1 | H8: 1 | I8: 1 | J8: 1 | K8: 1 | L8: 0 | M8: 1 | N8: =SUM(B8:M8) -> 8 | O8: =IF(N8=12,"SELECT","REJECT") -> REJECT | P8: One balance sheet, key chain and integration authority can remove four roots together.
A9: Ninety-six independent prize cells | B9: 1 | C9: 0 | D9: 1 | E9: 0 | F9: 1 | G9: 1 | H9: 1 | I9: 1 | J9: 1 | K9: 1 | L9: 1 | M9: 0 | N9: =SUM(B9:M9) -> 9 | O9: =IF(N9=12,"SELECT","REJECT") -> REJECT | P9: Excellent mechanism diversity leaves no actor liable for a complete root or executable service.
A10: Twenty-four perpetual franchises | B10: 1 | C10: 1 | D10: 1 | E10: 1 | F10: 1 | G10: 0 | H10: 0 | I10: 0 | J10: 1 | K10: 0 | L10: 0 | M10: 1 | N10: =SUM(B10:M10) -> 7 | O10: =IF(N10=12,"SELECT","REJECT") -> REJECT | P10: Protected incumbency makes adverse evidence and replacement nonbinding.
A11: Sovereign public arsenal | B11: 1 | C11: 1 | D11: 0 | E11: 0 | F11: 0 | G11: 0 | H11: 1 | I11: 1 | J11: 1 | K11: 1 | L11: 0 | M11: 1 | N11: =SUM(B11:M11) -> 7 | O11: =IF(N11=12,"SELECT","REJECT") -> REJECT | P11: One public toolchain becomes the national common root and judges its own reconstruction.

Sheet Account Control
A2: First-tranche account control
A3: Appropriation, public capability and private root options remain separate. No displayed amount is an awarded contract.
A6: Account | B6: Authority (USD B) | C6: Share | D6: First-tranche owner | E6: Private root award | F6: Public or enabling use | G6: Held | H6: May move to another account | I6: Production credit
A7: Mission systems | B7: 110 | C7: =B7/$B$12 -> 0.55 | D7: Six Mission System Commands | E7: Cancelable root options only | F7: None | G7: Unexercised balance stays in owning system | H7: No | I7: 0
A8: Service technical bases | B8: 30 | C8: =B8/$B$12 -> 0.15 | D8: Seven Generating Services | E8: None | F8: Methods, safety and configuration standards | G8: Gate-held | H8: No | I8: 0
A9: Common capacity | B9: 30 | C9: =B9/$B$12 -> 0.15 | D9: Capital Board and public owners | E9: None | F9: Public seams, receiver emulators and common fixtures | G9: Gate-held | H9: No | I9: 0
A10: Sovereign technical estate | B10: 20 | C10: =B10/$B$12 -> 0.1 | D10: Resilience Proving Service | E10: None | F10: Challenge, control, reconstruction and evidence custody | G10: Gate-held | H10: No | I10: 0
A11: Failure reserve | B11: 10 | C11: =B11/$B$12 -> 0.05 | D11: Program Comptroller | E11: None | F11: Invalid-attempt replay, clean replacement entry and continuity | G11: Protected in full | H11: No | I11: 0
A12: Total | B12: =SUM(B7:B11) -> 200 | C12: =SUM(C7:C11) -> 1 | D12: Five exclusive accounts | E12: No whole-root award | F12: Public powers remain separate | G12: No cross-account substitution | H12: No | I12: 0
A14: Mission option disposition
A15: Disposition | B15: Authority (USD B) | C15: Meaning | E15: Program view | F15: Authority (USD B)
A16: Non-lifeline endpoint options | B16: 43 | C16: May stage paired endpoint work | E16: Stageable Root House options | F16: ='Root Options'!F31 -> 57.390605
A17: Lifeline first-wave options | B17: 14.390605 | C17: May stage method and root-native sector work | E17: Mission options held | F17: ='Root Options'!G31 -> 52.609395
A18: Mission options retained | B18: 52.609395 | C18: Cannot be awarded before evidence | E18: Public and enabling accounts | F18: =SUM(B8:B10) -> 80
A19: Total mission authority | B19: =SUM(B16:B18) -> 110 | C19: Reconciles to the mission account | E19: Protected failure reserve | F19: =B11 -> 10

Sheet Root Options
A2: Twenty-four cancelable root options
A3: Each Root House may control one complete root. The first award is an option for evidence-bearing work, not a franchise or production contract.
A6: Root | B6: System | C6: Mission system | D6: Root thesis | E6: Full program option (USD B) | F6: T1 stageable (USD B) | G6: T1 held (USD B) | H6: Control identity | I6: Decisive domains | J6: Field assignments | K6: Current release | L6: Production credit | M6: Control HHI contribution
A7: ET-A | B7: MS-ET | C7: Enter a broken theater | D7: Oceanic mass bridge | E7: 22.255849 | F7: =IF(B7="MS-LF",E7*20%,E7*20%*'Account Control'!$B$16/('Account Control'!$B$7-'Account Control'!$B$17)) -> 2.0018985 | G7: =E7*20%-F7 -> 2.4492713 | H7: SOURCE EMPTY | I7: 12 | J7: 4 | K7: UNAWARDED | L7: 0 | M7: =(E7*20%/($E$31*20%))^2 -> 0.0016374308
A8: ET-B | B8: MS-ET | C8: Enter a broken theater | D8: Buoyant air bridge | E8: 22.255849 | F8: =IF(B8="MS-LF",E8*20%,E8*20%*'Account Control'!$B$16/('Account Control'!$B$7-'Account Control'!$B$17)) -> 2.0018985 | G8: =E8*20%-F8 -> 2.4492713 | H8: SOURCE EMPTY | I8: 12 | J8: 4 | K8: UNAWARDED | L8: 0 | M8: =(E8*20%/($E$31*20%))^2 -> 0.0016374308
A9: ET-C | B9: MS-ET | C9: Enter a broken theater | D9: Austere surface bridge | E9: 22.255849 | F9: =IF(B9="MS-LF",E9*20%,E9*20%*'Account Control'!$B$16/('Account Control'!$B$7-'Account Control'!$B$17)) -> 2.0018985 | G9: =E9*20%-F9 -> 2.4492713 | H9: SOURCE EMPTY | I9: 12 | J9: 4 | K9: UNAWARDED | L9: 0 | M9: =(E9*20%/($E$31*20%))^2 -> 0.0016374308
A10: ET-D | B10: MS-ET | C10: Enter a broken theater | D10: Amphibious autonomous mesh | E10: 22.255849 | F10: =IF(B10="MS-LF",E10*20%,E10*20%*'Account Control'!$B$16/('Account Control'!$B$7-'Account Control'!$B$17)) -> 2.0018985 | G10: =E10*20%-F10 -> 2.4492713 | H10: SOURCE EMPTY | I10: 12 | J10: 4 | K10: UNAWARDED | L10: 0 | M10: =(E10*20%/($E$31*20%))^2 -> 0.0016374308
A11: CT-A | B11: MS-CT | C11: Reach occupied civil terrain | D11: Civic edge grid | E11: 22.9682 | F11: =IF(B11="MS-LF",E11*20%,E11*20%*'Account Control'!$B$16/('Account Control'!$B$7-'Account Control'!$B$17)) -> 2.0659739 | G11: =E11*20%-F11 -> 2.527666 | H11: SOURCE EMPTY | I11: 12 | J11: 4 | K11: UNAWARDED | L11: 0 | M11: =(E11*20%/($E$31*20%))^2 -> 0.0017439279
A12: CT-B | B12: MS-CT | C12: Reach occupied civil terrain | D12: Air-and-skin reach | E12: 22.9682 | F12: =IF(B12="MS-LF",E12*20%,E12*20%*'Account Control'!$B$16/('Account Control'!$B$7-'Account Control'!$B$17)) -> 2.0659739 | G12: =E12*20%-F12 -> 2.527666 | H12: SOURCE EMPTY | I12: 12 | J12: 4 | K12: UNAWARDED | L12: 0 | M12: =(E12*20%/($E$31*20%))^2 -> 0.0017439279
A13: CT-C | B13: MS-CT | C13: Reach occupied civil terrain | D13: Building utility spine | E13: 22.9682 | F13: =IF(B13="MS-LF",E13*20%,E13*20%*'Account Control'!$B$16/('Account Control'!$B$7-'Account Control'!$B$17)) -> 2.0659739 | G13: =E13*20%-F13 -> 2.527666 | H13: SOURCE EMPTY | I13: 12 | J13: 4 | K13: UNAWARDED | L13: 0 | M13: =(E13*20%/($E$31*20%))^2 -> 0.0017439279
A14: CT-D | B14: MS-CT | C14: Reach occupied civil terrain | D14: Neighborhood machine swarm | E14: 22.9682 | F14: =IF(B14="MS-LF",E14*20%,E14*20%*'Account Control'!$B$16/('Account Control'!$B$7-'Account Control'!$B$17)) -> 2.0659739 | G14: =E14*20%-F14 -> 2.527666 | H14: SOURCE EMPTY | I14: 12 | J14: 4 | K14: UNAWARDED | L14: 0 | M14: =(E14*20%/($E$31*20%))^2 -> 0.0017439279
A15: HC-A | B15: MS-HC | C15: Control an active hazard | D15: Atmospheric control wing | E15: 13.661989 | F15: =IF(B15="MS-LF",E15*20%,E15*20%*'Account Control'!$B$16/('Account Control'!$B$7-'Account Control'!$B$17)) -> 1.2288866 | G15: =E15*20%-F15 -> 1.5035112 | H15: SOURCE EMPTY | I15: 12 | J15: 4 | K15: UNAWARDED | L15: 0 | M15: =(E15*20%/($E$31*20%))^2 -> 0.00061702461
A16: HC-B | B16: MS-HC | C16: Control an active hazard | D16: Fluid intervention lattice | E16: 13.661989 | F16: =IF(B16="MS-LF",E16*20%,E16*20%*'Account Control'!$B$16/('Account Control'!$B$7-'Account Control'!$B$17)) -> 1.2288866 | G16: =E16*20%-F16 -> 1.5035112 | H16: SOURCE EMPTY | I16: 12 | J16: 4 | K16: UNAWARDED | L16: 0 | M16: =(E16*20%/($E$31*20%))^2 -> 0.00061702461
A17: HC-C | B17: MS-HC | C17: Control an active hazard | D17: Autonomous terrain corps | E17: 13.661989 | F17: =IF(B17="MS-LF",E17*20%,E17*20%*'Account Control'!$B$16/('Account Control'!$B$7-'Account Control'!$B$17)) -> 1.2288866 | G17: =E17*20%-F17 -> 1.5035112 | H17: SOURCE EMPTY | I17: 12 | J17: 4 | K17: UNAWARDED | L17: 0 | M17: =(E17*20%/($E$31*20%))^2 -> 0.00061702461
A18: HC-D | B18: MS-HC | C18: Control an active hazard | D18: Distributed control field | E18: 13.661989 | F18: =IF(B18="MS-LF",E18*20%,E18*20%*'Account Control'!$B$16/('Account Control'!$B$7-'Account Control'!$B$17)) -> 1.2288866 | G18: =E18*20%-F18 -> 1.5035112 | H18: SOURCE EMPTY | I18: 12 | J18: 4 | K18: UNAWARDED | L18: 0 | M18: =(E18*20%/($E$31*20%))^2 -> 0.00061702461
... A30: RT-D | B30: MS-RT | C30: Sustain, transfer and regenerate | D30: Closed-loop sustainment fleet | E30: 22.350266 | F30: =IF(B30="MS-LF",E30*20%,E30*20%*'Account Control'!$B$16/('Account Control'!$B$7-'Account Control'!$B$17)) -> 2.0103912 | G30: =E30*20%-F30 -> 2.4596619 | H30: SOURCE EMPTY | I30: 12 | J30: 4 | K30: UNAWARDED | L30: 0 | M30: =(E30*20%/($E$31*20%))^2 -> 0.0016513533
A31: Total | B31: 6 systems | C31: 24 roots | D31: One root per control group | E31: =SUM(E7:E30) -> 550 | F31: =SUM(F7:F30) -> 57.390605 | G31: =SUM(G7:G30) -> 52.609395 | H31: 0 accepted identities | I31: 288 | J31: 96 | K31: No award | L31: 0 | M31: =SUM(M7:M30) -> 0.04624968

Sheet Field Awards
A2: Ninety-six root-field assignments
A3: Four field assignments compose each root. They are severable for falsification but cannot earn complete-root credit independently.
A6: Opportunity | B6: Root | C6: System | D6: Problem field | E6: Root thesis | F6: T1 ceiling (USD B) | G6: Stageable option (USD B) | H6: Held (USD B) | I6: Control identity | J6: State | K6: Root credit | L6: Production credit
A7: ET-A-F1 | B7: ET-A | C7: MS-ET | D7: No-pier heavy transfer | E7: Oceanic mass bridge | F7: ='Root Options'!E7*20%/4 -> 1.1127925 | G7: ='Root Options'!F7/4 -> 0.50047462 | H7: ='Root Options'!G7/4 -> 0.61231783 | I7: SOURCE EMPTY | J7: UNAWARDED | K7: 0 | L7: 0
A8: ET-A-F2 | B8: ET-A | C8: MS-ET | D8: Austere strategic lift | E8: Oceanic mass bridge | F8: ='Root Options'!E7*20%/4 -> 1.1127925 | G8: ='Root Options'!F7/4 -> 0.50047462 | H8: ='Root Options'!G7/4 -> 0.61231783 | I8: SOURCE EMPTY | J8: UNAWARDED | K8: 0 | L8: 0
A9: ET-A-F3 | B9: ET-A | C9: MS-ET | D9: Autonomous node opening | E9: Oceanic mass bridge | F9: ='Root Options'!E7*20%/4 -> 1.1127925 | G9: ='Root Options'!F7/4 -> 0.50047462 | H9: ='Root Options'!G7/4 -> 0.61231783 | I9: SOURCE EMPTY | J9: UNAWARDED | K9: 0 | L9: 0
A10: ET-A-F4 | B10: ET-A | C10: MS-ET | D10: Distributed operating bases | E10: Oceanic mass bridge | F10: ='Root Options'!E7*20%/4 -> 1.1127925 | G10: ='Root Options'!F7/4 -> 0.50047462 | H10: ='Root Options'!G7/4 -> 0.61231783 | I10: SOURCE EMPTY | J10: UNAWARDED | K10: 0 | L10: 0
A11: ET-B-F1 | B11: ET-B | C11: MS-ET | D11: No-pier heavy transfer | E11: Buoyant air bridge | F11: ='Root Options'!E8*20%/4 -> 1.1127925 | G11: ='Root Options'!F8/4 -> 0.50047462 | H11: ='Root Options'!G8/4 -> 0.61231783 | I11: SOURCE EMPTY | J11: UNAWARDED | K11: 0 | L11: 0
A12: ET-B-F2 | B12: ET-B | C12: MS-ET | D12: Austere strategic lift | E12: Buoyant air bridge | F12: ='Root Options'!E8*20%/4 -> 1.1127925 | G12: ='Root Options'!F8/4 -> 0.50047462 | H12: ='Root Options'!G8/4 -> 0.61231783 | I12: SOURCE EMPTY | J12: UNAWARDED | K12: 0 | L12: 0
A13: ET-B-F3 | B13: ET-B | C13: MS-ET | D13: Autonomous node opening | E13: Buoyant air bridge | F13: ='Root Options'!E8*20%/4 -> 1.1127925 | G13: ='Root Options'!F8/4 -> 0.50047462 | H13: ='Root Options'!G8/4 -> 0.61231783 | I13: SOURCE EMPTY | J13: UNAWARDED | K13: 0 | L13: 0
A14: ET-B-F4 | B14: ET-B | C14: MS-ET | D14: Distributed operating bases | E14: Buoyant air bridge | F14: ='Root Options'!E8*20%/4 -> 1.1127925 | G14: ='Root Options'!F8/4 -> 0.50047462 | H14: ='Root Options'!G8/4 -> 0.61231783 | I14: SOURCE EMPTY | J14: UNAWARDED | K14: 0 | L14: 0
A15: ET-C-F1 | B15: ET-C | C15: MS-ET | D15: No-pier heavy transfer | E15: Austere surface bridge | F15: ='Root Options'!E9*20%/4 -> 1.1127925 | G15: ='Root Options'!F9/4 -> 0.50047462 | H15: ='Root Options'!G9/4 -> 0.61231783 | I15: SOURCE EMPTY | J15: UNAWARDED | K15: 0 | L15: 0
A16: ET-C-F2 | B16: ET-C | C16: MS-ET | D16: Austere strategic lift | E16: Austere surface bridge | F16: ='Root Options'!E9*20%/4 -> 1.1127925 | G16: ='Root Options'!F9/4 -> 0.50047462 | H16: ='Root Options'!G9/4 -> 0.61231783 | I16: SOURCE EMPTY | J16: UNAWARDED | K16: 0 | L16: 0
A17: ET-C-F3 | B17: ET-C | C17: MS-ET | D17: Autonomous node opening | E17: Austere surface bridge | F17: ='Root Options'!E9*20%/4 -> 1.1127925 | G17: ='Root Options'!F9/4 -> 0.50047462 | H17: ='Root Options'!G9/4 -> 0.61231783 | I17: SOURCE EMPTY | J17: UNAWARDED | K17: 0 | L17: 0
A18: ET-C-F4 | B18: ET-C | C18: MS-ET | D18: Distributed operating bases | E18: Austere surface bridge | F18: ='Root Options'!E9*20%/4 -> 1.1127925 | G18: ='Root Options'!F9/4 -> 0.50047462 | H18: ='Root Options'!G9/4 -> 0.61231783 | I18: SOURCE EMPTY | J18: UNAWARDED | K18: 0 | L18: 0
A19: ET-D-F1 | B19: ET-D | C19: MS-ET | D19: No-pier heavy transfer | E19: Amphibious autonomous mesh | F19: ='Root Options'!E10*20%/4 -> 1.1127925 | G19: ='Root Options'!F10/4 -> 0.50047462 | H19: ='Root Options'!G10/4 -> 0.61231783 | I19: SOURCE EMPTY | J19: UNAWARDED | K19: 0 | L19: 0
A20: ET-D-F2 | B20: ET-D | C20: MS-ET | D20: Austere strategic lift | E20: Amphibious autonomous mesh | F20: ='Root Options'!E10*20%/4 -> 1.1127925 | G20: ='Root Options'!F10/4 -> 0.50047462 | H20: ='Root Options'!G10/4 -> 0.61231783 | I20: SOURCE EMPTY | J20: UNAWARDED | K20: 0 | L20: 0
A21: ET-D-F3 | B21: ET-D | C21: MS-ET | D21: Autonomous node opening | E21: Amphibious autonomous mesh | F21: ='Root Options'!E10*20%/4 -> 1.1127925 | G21: ='Root Options'!F10/4 -> 0.50047462 | H21: ='Root Options'!G10/4 -> 0.61231783 | I21: SOURCE EMPTY | J21: UNAWARDED | K21: 0 | L21: 0
A22: ET-D-F4 | B22: ET-D | C22: MS-ET | D22: Distributed operating bases | E22: Amphibious autonomous mesh | F22: ='Root Options'!E10*20%/4 -> 1.1127925 | G22: ='Root Options'!F10/4 -> 0.50047462 | H22: ='Root Options'!G10/4 -> 0.61231783 | I22: SOURCE EMPTY | J22: UNAWARDED | K22: 0 | L22: 0
A23: CT-A-F1 | B23: CT-A | C23: MS-CT | D23: Disconnected civil state | E23: Civic edge grid | F23: ='Root Options'!E11*20%/4 -> 1.14841 | G23: ='Root Options'!F11/4 -> 0.51649348 | H23: ='Root Options'!G11/4 -> 0.6319165 | I23: SOURCE EMPTY | J23: UNAWARDED | K23: 0 | L23: 0
A24: CT-A-F2 | B24: CT-A | C24: MS-CT | D24: Building and vertical access | E24: Civic edge grid | F24: ='Root Options'!E11*20%/4 -> 1.14841 | G24: ='Root Options'!F11/4 -> 0.51649348 | H24: ='Root Options'!G11/4 -> 0.6319165 | I24: SOURCE EMPTY | J24: UNAWARDED | K24: 0 | L24: 0
A25: CT-A-F3 | B25: CT-A | C25: MS-CT | D25: Accessible collection | E25: Civic edge grid | F25: ='Root Options'!E11*20%/4 -> 1.14841 | G25: ='Root Options'!F11/4 -> 0.51649348 | H25: ='Root Options'!G11/4 -> 0.6319165 | I25: SOURCE EMPTY | J25: UNAWARDED | K25: 0 | L25: 0
A26: CT-A-F4 | B26: CT-A | C26: MS-CT | D26: Degraded public communications | E26: Civic edge grid | F26: ='Root Options'!E11*20%/4 -> 1.14841 | G26: ='Root Options'!F11/4 -> 0.51649348 | H26: ='Root Options'!G11/4 -> 0.6319165 | I26: SOURCE EMPTY | J26: UNAWARDED | K26: 0 | L26: 0
A27: CT-B-F1 | B27: CT-B | C27: MS-CT | D27: Disconnected civil state | E27: Air-and-skin reach | F27: ='Root Options'!E12*20%/4 -> 1.14841 | G27: ='Root Options'!F12/4 -> 0.51649348 | H27: ='Root Options'!G12/4 -> 0.6319165 | I27: SOURCE EMPTY | J27: UNAWARDED | K27: 0 | L27: 0
A28: CT-B-F2 | B28: CT-B | C28: MS-CT | D28: Building and vertical access | E28: Air-and-skin reach | F28: ='Root Options'!E12*20%/4 -> 1.14841 | G28: ='Root Options'!F12/4 -> 0.51649348 | H28: ='Root Options'!G12/4 -> 0.6319165 | I28: SOURCE EMPTY | J28: UNAWARDED | K28: 0 | L28: 0
A29: CT-B-F3 | B29: CT-B | C29: MS-CT | D29: Accessible collection | E29: Air-and-skin reach | F29: ='Root Options'!E12*20%/4 -> 1.14841 | G29: ='Root Options'!F12/4 -> 0.51649348 | H29: ='Root Options'!G12/4 -> 0.6319165 | I29: SOURCE EMPTY | J29: UNAWARDED | K29: 0 | L29: 0
A30: CT-B-F4 | B30: CT-B | C30: MS-CT | D30: Degraded public communications | E30: Air-and-skin reach | F30: ='Root Options'!E12*20%/4 -> 1.14841 | G30: ='Root Options'!F12/4 -> 0.51649348 | H30: ='Root Options'!G12/4 -> 0.6319165 | I30: SOURCE EMPTY | J30: UNAWARDED | K30: 0 | L30: 0
A31: CT-C-F1 | B31: CT-C | C31: MS-CT | D31: Disconnected civil state | E31: Building utility spine | F31: ='Root Options'!E13*20%/4 -> 1.14841 | G31: ='Root Options'!F13/4 -> 0.51649348 | H31: ='Root Options'!G13/4 -> 0.6319165 | I31: SOURCE EMPTY | J31: UNAWARDED | K31: 0 | L31: 0
A32: CT-C-F2 | B32: CT-C | C32: MS-CT | D32: Building and vertical access | E32: Building utility spine | F32: ='Root Options'!E13*20%/4 -> 1.14841 | G32: ='Root Options'!F13/4 -> 0.51649348 | H32: ='Root Options'!G13/4 -> 0.6319165 | I32: SOURCE EMPTY | J32: UNAWARDED | K32: 0 | L32: 0
A33: CT-C-F3 | B33: CT-C | C33: MS-CT | D33: Accessible collection | E33: Building utility spine | F33: ='Root Options'!E13*20%/4 -> 1.14841 | G33: ='Root Options'!F13/4 -> 0.51649348 | H33: ='Root Options'!G13/4 -> 0.6319165 | I33: SOURCE EMPTY | J33: UNAWARDED | K33: 0 | L33: 0
A34: CT-C-F4 | B34: CT-C | C34: MS-CT | D34: Degraded public communications | E34: Building utility spine | F34: ='Root Options'!E13*20%/4 -> 1.14841 | G34: ='Root Options'!F13/4 -> 0.51649348 | H34: ='Root Options'!G13/4 -> 0.6319165 | I34: SOURCE EMPTY | J34: UNAWARDED | K34: 0 | L34: 0
A35: CT-D-F1 | B35: CT-D | C35: MS-CT | D35: Disconnected civil state | E35: Neighborhood machine swarm | F35: ='Root Options'!E14*20%/4 -> 1.14841 | G35: ='Root Options'!F14/4 -> 0.51649348 | H35: ='Root Options'!G14/4 -> 0.6319165 | I35: SOURCE EMPTY | J35: UNAWARDED | K35: 0 | L35: 0
A36: CT-D-F2 | B36: CT-D | C36: MS-CT | D36: Building and vertical access | E36: Neighborhood machine swarm | F36: ='Root Options'!E14*20%/4 -> 1.14841 | G36: ='Root Options'!F14/4 -> 0.51649348 | H36: ='Root Options'!G14/4 -> 0.6319165 | I36: SOURCE EMPTY | J36: UNAWARDED | K36: 0 | L36: 0
A37: CT-D-F3 | B37: CT-D | C37: MS-CT | D37: Accessible collection | E37: Neighborhood machine swarm | F37: ='Root Options'!E14*20%/4 -> 1.14841 | G37: ='Root Options'!F14/4 -> 0.51649348 | H37: ='Root Options'!G14/4 -> 0.6319165 | I37: SOURCE EMPTY | J37: UNAWARDED | K37: 0 | L37: 0
A38: CT-D-F4 | B38: CT-D | C38: MS-CT | D38: Degraded public communications | E38: Neighborhood machine swarm | F38: ='Root Options'!E14*20%/4 -> 1.14841 | G38: ='Root Options'!F14/4 -> 0.51649348 | H38: ='Root Options'!G14/4 -> 0.6319165 | I38: SOURCE EMPTY | J38: UNAWARDED | K38: 0 | L38: 0
A39: HC-A-F1 | B39: HC-A | C39: MS-HC | D39: Persistent fire control | E39: Atmospheric control wing | F39: ='Root Options'!E15*20%/4 -> 0.68309945 | G39: ='Root Options'!F15/4 -> 0.30722165 | H39: ='Root Options'!G15/4 -> 0.3758778 | I39: SOURCE EMPTY | J39: UNAWARDED | K39: 0 | L39: 0
A40: HC-A-F2 | B40: HC-A | C40: MS-HC | D40: Megaflow hydraulic control | E40: Atmospheric control wing | F40: ='Root Options'!E15*20%/4 -> 0.68309945 | G40: ='Root Options'!F15/4 -> 0.30722165 | H40: ='Root Options'!G15/4 -> 0.3758778 | I40: SOURCE EMPTY | J40: UNAWARDED | K40: 0 | L40: 0
A41: HC-A-F3 | B41: HC-A | C41: MS-HC | D41: Autonomous earth and debris work | E41: Atmospheric control wing | F41: ='Root Options'!E15*20%/4 -> 0.68309945 | G41: ='Root Options'!F15/4 -> 0.30722165 | H41: ='Root Options'!G15/4 -> 0.3758778 | I41: SOURCE EMPTY | J41: UNAWARDED | K41: 0 | L41: 0
A42: HC-A-F4 | B42: HC-A | C42: MS-HC | D42: Environmental consequence control | E42: Atmospheric control wing | F42: ='Root Options'!E15*20%/4 -> 0.68309945 | G42: ='Root Options'!F15/4 -> 0.30722165 | H42: ='Root Options'!G15/4 -> 0.3758778 | I42: SOURCE EMPTY | J42: UNAWARDED | K42: 0 | L42: 0
A43: HC-B-F1 | B43: HC-B | C43: MS-HC | D43: Persistent fire control | E43: Fluid intervention lattice | F43: ='Root Options'!E16*20%/4 -> 0.68309945 | G43: ='Root Options'!F16/4 -> 0.30722165 | H43: ='Root Options'!G16/4 -> 0.3758778 | I43: SOURCE EMPTY | J43: UNAWARDED | K43: 0 | L43: 0
...

Sheet Ancestry Register
A2: Ancestry Register
A3: Every decisive execution domain is exclusive to one root. A legal name, open-source label or interface standard does not establish independence.
A6: Root | B6: System | C6: Decisive domain | D6: Declared identity | E6: Maximum root exposure | F6: Accepted exposure | G6: Status | H6: Production credit
A7: ET-A | B7: MS-ET | C7: Root integrator | D7: SOURCE EMPTY | E7: 1 | F7: 0 | G7: HOLD | H7: 0
A8: ET-A | B8: MS-ET | C8: Prime work physics | D8: SOURCE EMPTY | E8: 1 | F8: 0 | G8: HOLD | H8: 0
A9: ET-A | B9: MS-ET | C9: Energy conversion | D9: SOURCE EMPTY | E9: 1 | F9: 0 | G9: HOLD | H9: 0
A10: ET-A | B10: MS-ET | C10: Structural process | D10: SOURCE EMPTY | E10: 1 | F10: 0 | G10: HOLD | H10: 0
A11: ET-A | B11: MS-ET | C11: Critical-feedstock conversion | D11: SOURCE EMPTY | E11: 1 | F11: 0 | G11: HOLD | H11: 0
A12: ET-A | B12: MS-ET | C12: Control keys | D12: SOURCE EMPTY | E12: 1 | F12: 0 | G12: HOLD | H12: 0
A13: ET-A | B13: MS-ET | C13: Communications and time | D13: SOURCE EMPTY | E13: 1 | F13: 0 | G13: HOLD | H13: 0
A14: ET-A | B14: MS-ET | C14: Calibration chain | D14: SOURCE EMPTY | E14: 1 | F14: 0 | G14: HOLD | H14: 0
A15: ET-A | B15: MS-ET | C15: Production tooling | D15: SOURCE EMPTY | E15: 1 | F15: 0 | G15: HOLD | H15: 0
A16: ET-A | B16: MS-ET | C16: Final assembly cell | D16: SOURCE EMPTY | E16: 1 | F16: 0 | G16: HOLD | H16: 0
A17: ET-A | B17: MS-ET | C17: Repair route | D17: SOURCE EMPTY | E17: 1 | F17: 0 | G17: HOLD | H17: 0
A18: ET-A | B18: MS-ET | C18: Evidence chain | D18: SOURCE EMPTY | E18: 1 | F18: 0 | G18: HOLD | H18: 0
... A294: RT-D | B294: MS-RT | C294: Evidence chain | D294: SOURCE EMPTY | E294: 1 | F294: 0 | G294: HOLD | H294: 0

Sheet Shared Dependencies
A2: Shared Dependencies
A3: A shared provider, region or toolchain may support no more than two roots and every exposure requires an unrelated qualified alternate.
A6: Root | B6: System | C6: Dependency class | D6: Provider identity | E6: Maximum root exposure | F6: Current root exposure | G6: Alternate required | H6: Accepted alternates | I6: Status | J6: Credit
A7: ET-A | B7: MS-ET | C7: Critical feedstock | D7: SOURCE EMPTY | E7: 2 | F7: 0 | G7: 1 | H7: 0 | I7: HOLD | J7: 0
A8: ET-A | B8: MS-ET | C8: Interface component | D8: SOURCE EMPTY | E8: 2 | F8: 0 | G8: 1 | H8: 0 | I8: HOLD | J8: 0
A9: ET-A | B9: MS-ET | C9: Production service | D9: SOURCE EMPTY | E9: 2 | F9: 0 | G9: 1 | H9: 0 | I9: HOLD | J9: 0
A10: ET-B | B10: MS-ET | C10: Critical feedstock | D10: SOURCE EMPTY | E10: 2 | F10: 0 | G10: 1 | H10: 0 | I10: HOLD | J10: 0
A11: ET-B | B11: MS-ET | C11: Interface component | D11: SOURCE EMPTY | E11: 2 | F11: 0 | G11: 1 | H11: 0 | I11: HOLD | J11: 0
A12: ET-B | B12: MS-ET | C12: Production service | D12: SOURCE EMPTY | E12: 2 | F12: 0 | G12: 1 | H12: 0 | I12: HOLD | J12: 0
A13: ET-C | B13: MS-ET | C13: Critical feedstock | D13: SOURCE EMPTY | E13: 2 | F13: 0 | G13: 1 | H13: 0 | I13: HOLD | J13: 0
A14: ET-C | B14: MS-ET | C14: Interface component | D14: SOURCE EMPTY | E14: 2 | F14: 0 | G14: 1 | H14: 0 | I14: HOLD | J14: 0
A15: ET-C | B15: MS-ET | C15: Production service | D15: SOURCE EMPTY | E15: 2 | F15: 0 | G15: 1 | H15: 0 | I15: HOLD | J15: 0
A16: ET-D | B16: MS-ET | C16: Critical feedstock | D16: SOURCE EMPTY | E16: 2 | F16: 0 | G16: 1 | H16: 0 | I16: HOLD | J16: 0
A17: ET-D | B17: MS-ET | C17: Interface component | D17: SOURCE EMPTY | E17: 2 | F17: 0 | G17: 1 | H17: 0 | I17: HOLD | J17: 0
A18: ET-D | B18: MS-ET | C18: Production service | D18: SOURCE EMPTY | E18: 2 | F18: 0 | G18: 1 | H18: 0 | I18: HOLD | J18: 0
... A78: RT-D | B78: MS-RT | C78: Production service | D78: SOURCE EMPTY | E78: 2 | F78: 0 | G78: 1 | H78: 0 | I78: HOLD | J78: 0

Sheet Payment Ladder
A2: Cancelable option payment ladder
A3: Only USD 57.4B of mission authority may stage initially. Every payment requires an accepted artifact; a valid adverse result remains payable and binding.
A6: Phase | B6: Share of stageable option | C6: Portfolio authority (USD B) | D6: Accepted artifact | E6: Positive result required | F6: Independent acceptance | G6: If adverse | H6: If invalid | I6: Production credit
A7: FRAME | B7: 0.15 | C7: =B7*'Root Options'!$F$31 -> 8.6085908 | D7: Charter, service baseline, rights schedule and ancestry plan | E7: No | F7: Capital Board plus Mission System Command | G7: Keep accepted frame; resize or stop | H7: Correct record before exercise | I7: 0
A8: MAKE | B8: 0.35 | C8: =B8*'Root Options'!$F$31 -> 20.086712 | D8: Four measured mechanism articles and controlled bills | E8: No | F8: Generating Service plus public metrology | G8: Pay accepted work; proceed to disposition | H8: Rebuild invalid article within option | I8: 0
A9: BREAK | B9: 0.35 | C9: =B9*'Root Options'!$F$31 -> 20.086712 | D9: Endpoint challenge, control and valid evidence packet | E9: No | F9: Proving Service and Protection Inspectorate | G9: Pay evidence; RESIZE or KILL | H9: One exact-event replay may use reserve | I9: 0
A10: TRANSFER | B10: 0.15 | C10: =B10*'Root Options'!$F$31 -> 8.6085908 | D10: Cold build package, public custody and disposition record | E10: No | F10: Root Disposition Board plus Comptroller | G10: Vest step-in rights; return unearned option | H10: No favorable inference | I10: 0
A11: Total | B11: =SUM(B7:B10) -> 1 | C11: =SUM(C7:C10) -> 57.390605 | D11: Four evidence-bearing releases | E11: Never | F11: Separate acceptance | G11: Failure stays public | H11: No retry to improve outcome | I11: 0
A13: Portfolio cancellation exposure
A14: Termination point | B14: Cumulative paid share | C14: Paid authority (USD B) | D14: Unexercised stageable option (USD B) | E14: Mission options still held (USD B) | F14: Failure meaning
A15: Before FRAME | B15: 0 | C15: =B15*$C$11 -> 0 | D15: =$C$11-C15 -> 57.390605 | E15: ='Root Options'!$G$31 -> 52.609395 | F15: No private award
A16: After FRAME | B16: 0.15 | C16: =B16*$C$11 -> 8.6085908 | D16: =$C$11-C16 -> 48.782014 | E16: ='Root Options'!$G$31 -> 52.609395 | F16: Control or baseline defect
A17: After MAKE | B17: 0.5 | C17: =B17*$C$11 -> 28.695303 | D17: =$C$11-C17 -> 28.695303 | E17: ='Root Options'!$G$31 -> 52.609395 | F17: Article failure or withdrawal
A18: After BREAK | B18: 0.85 | C18: =B18*$C$11 -> 48.782014 | D18: =$C$11-C18 -> 8.6085908 | E18: ='Root Options'!$G$31 -> 52.609395 | F18: Valid endpoint disposition
A19: After TRANSFER | B19: 1 | C19: =B19*$C$11 -> 57.390605 | D19: =$C$11-C19 -> 0 | E19: ='Root Options'!$G$31 -> 52.609395 | F19: T2 proof option may be considered

Sheet Transaction States
A2: Transaction States
A3: The transaction creates bounded artifacts and cancelable rights. No contract state can be inferred from spending or schedule.
A6: State | B6: Object | C6: Required entrant | D6: Release owner | E6: Independent blocker | F6: Permitted fiscal action | G6: Failure transition | H6: Next state | I6: Production credit
A7: S0 | B7: Unawarded opportunity | C7: Public denominator | D7: Mission System Command | E7: Civil and rights trustees | F7: Publish competition | G7: Revise denominator | H7: S1 | I7: 0
A8: S1 | B8: Admissible control group | C8: Beneficial-control and finance graph | D8: Capital Board | E8: Independent control auditor | F8: Reserve option | G8: Reject or require clean control | H8: S2 | I8: 0
A9: S2 | B9: Cancelable root option | C9: Complete-root liability and rights schedule | D9: Capital Board | E9: Mission System Command | F9: Release FRAME | G9: Cancel and return to owning account | H9: S3 | I9: 0
A10: S3 | B10: A0 public method | C10: Qualified denominator and interfaces | D10: Generating Service | E10: Proving Service | F10: Release MAKE | G10: Hold invalid method | H10: S4 | I10: 0
A11: S4 | B11: A1 mechanism articles | C11: Four unlike measured field articles | D11: Generating Service | E11: Safety authority | F11: Release BREAK | G11: Resize or withdraw | H11: S5 | I11: 0
A12: S5 | B12: A2 endpoint rig | C12: Challenge, control and custody packet | D12: Proving Service | E12: Protection Inspectorate | F12: Accept evidence | G12: Invalid replay or valid disposition | H12: S6 | I12: 0
A13: S6 | B13: Root disposition | C13: Valid balance and keystone evidence | D13: Root Disposition Board | E13: Program Comptroller | F13: Pay accepted work; return unearned balance | G13: BUILD PROOF, RESIZE or KILL | H13: S7 | I13: 0
A14: S7 | B14: T2 proof option | C14: New appropriation gate and complete proof plan | D14: Capital Board | E14: All-six portfolio barrier | F14: Consider A3 construction | G14: Cancel or recharter | H14: Later tranche | I14: 0

Sheet Authority
A2: Authority
A3: No acquisition executive can own mission, money, design, truth and termination. Integration occurs through signed artifact succession.
A6: Authority | B6: Exclusive power | C6: Issues | D6: May stop | E6: Cannot infer | F6: Required alternate | G6: Public record | H6: Current authority
A7: Civil Resilience Authority | B7: Public guarantee | C7: Need and rights warrant | D7: Unlawful objective | E7: Priority → technical truth | F7: Independent civil trustee | G7: Guarantee and appeal | H7: 0
A8: Mission System Commands | B8: Complete service baseline | C8: Field and root denominator | D8: Incomplete route | E8: Mission ownership → evidence | F8: Alternate system office | G8: Baseline and change | H8: 0
A9: Capital Board | B9: Fiscal option | C9: FRAME and later option exercise | D9: Control or account breach | E9: Spending → capability | F9: Independent fiscal panel | G9: Option and cancellation | H9: 0
A10: Generating Services | B10: Technical and professional release | C10: A0 and A1 technical state | D10: Unsafe article | E10: Article → root | F10: Unlike service authority | G10: Configuration release | H10: 0
A11: Root Houses | B11: Complete candidate liability | C11: Design claim and build package | D11: Own withdrawal | E11: Industry → public warrant | F11: Clean entrant | G11: Bill and ancestry | H11: 0
A12: Resilience Proving Service | B12: Challenge, control and custody | C12: Valid evidence packet | D12: Invalid method or event | E12: Test output → disposition | F12: Separated station classes | G12: Evidence packet | H12: 0
A13: Protection Inspectorate | B13: Safety and rights stop | C13: Independent intervention | D13: Unsafe or unlawful work | E13: Stop → preferred rival | F13: Outside inspectorate | G13: Stop record | H13: 0
A14: Root Disposition Board | B14: Adverse meaning | C14: BUILD PROOF, RESIZE or KILL | D14: Incomplete dossier | E14: Score → release | F14: Independent panel | G14: Reasoned disposition | H14: 0
A15: Program Comptroller | B15: Stage execution and return | C15: Payment and returned balance | D15: Missing acceptance | E15: Payment → success | F15: Independent account audit | G15: Payment ledger | H15: 0
A16: Continuity Receiver | B16: Public step-in custody | C16: Recharter and clean transfer | D16: Control collision | E16: Possession → readiness | F16: Clean replacement house | G16: Custody and transfer | H16: 0

Sheet Failure & Exit
A2: Failure & Exit
A3: Termination preserves useful work, adverse evidence, public rights and mission-account ownership without rewarding the apparent leader.
A6: Trigger | B6: Decision | C6: Paid work | D6: Unexercised mission option | E6: Failure reserve | F6: Public rights | G6: Successor condition | H6: Evidence treatment | I6: Production credit
A7: Voluntary withdrawal | B7: CANCEL | C7: Accepted artifacts only | D7: Return to owning system | E7: No automatic draw | F7: Vest accepted foreground | G7: Clean entrant | H7: Retain all records | I7: 0
A8: Balance endpoint fails | B8: RESIZE | C8: Valid evidence paid | D8: Remain with owning system | E8: Only approved new endpoint | F8: Vest measured configuration | G8: Same house or clean entrant | H8: Adverse result permanent | I8: 0
A9: Keystone endpoint fails | B9: KILL | C9: Valid evidence paid | D9: Return to owning system | E9: May fund clean replacement entry | F9: Vest all accepted foreground | G9: Cannot control a live root | H9: Adverse result permanent | I9: 0
A10: Invalid trial | B10: HOLD | C10: No evidentiary milestone | D10: Remain with owning system | E10: One exact-event replay | F10: No disposition change | G10: Same candidate allowed | H10: Replace invalid record only | I10: 0
A11: Outcome-aware repeat requested | B11: DENY | C11: No additional payment | D11: Remain held | E11: No draw | F11: No change | G11: Not applicable | H11: Preserve valid adverse event | I11: 0
A12: Beneficial-control collision | B12: SUSPEND | C12: Accepted work retained | D12: Return if not cured | E12: May fund receivership | F12: Vest on unresolved breach | G12: Bankruptcy-remote clean owner | H12: Publish collision | I12: 0
A13: Cross-default or collateral breach | B13: RECEIVERSHIP | C13: Accepted work retained | D13: Freeze pending transfer | E13: Continuity only | F13: Immediate step-in | G13: No other live root | H13: Preserve history | I13: 0
A14: Provider supports three roots | B14: DISALLOW DEPENDENCY | C14: Unrelated accepted work | D14: No cross-system transfer | E14: Alternate qualification only | F14: Interface rights retained | G14: Unrelated provider | H14: Expose cap breach | I14: 0
A15: Cold reconstruction fails | B15: REMOVE REPRODUCTION CLAIM | C15: Accepted evidence paid | D15: Hold later option | E15: May preserve tooling | F15: Full build package vests | G15: New build team required | H15: Failure remains public | I15: 0
A16: Cost exceeds root option | B16: REDUCE OR CANCEL | C16: Accepted artifacts only | D16: No raid on another root | E16: No overrun rescue | F16: Accepted foreground retained | G16: Recompete within system | H16: Publish cost and scope | I16: 0

Sheet Public Rights
A2: Public Rights
A3: Foreground rights make termination physically executable while firms retain unrelated background knowledge and commercial markets.
A6: Public asset | B6: Right at award | C6: Private right retained | D6: Step-in trigger | E6: Required physical object | F6: Custodian | G6: May create readiness | H6: Current status
A7: Foreground configuration | B7: Irrevocable mission-limited use | C7: Unrelated background designs | D7: Continuity or concentration breach | E7: Controlled build package | F7: Public technical commons | G7: No | H7: SOURCE EMPTY
A8: Unique funded tooling | B8: Possession or perfected access | C8: Commercial use subject to continuity | D8: Refusal, insolvency or seizure | E8: Tool and fixture genealogy | F8: Industrial administration | G8: No | H8: SOURCE EMPTY
A9: Root tooling capsule | B9: Cold reconstruction license | C9: Background process know-how | D9: Failed private recovery | E9: Portable tooling set | F9: Continuity Receiver | G9: No | H9: SOURCE EMPTY
A10: Reference articles | B10: Destructive test and reproduction | C10: Commercial sales | D10: Evidence or rebuild need | E10: Serialized articles | F10: Proving Service | G10: No | H10: SOURCE EMPTY
A11: Material genealogy | B11: Full funded-chain custody | C11: Unrelated supplier data | D11: Safety, drift or source loss | E11: Lot and process record | F11: Standards and Custody | G11: No | H11: SOURCE EMPTY
A12: Signing roots and keys | B12: Escrowed alternate authority | C12: Ordinary private operations | D12: Control loss or refusal | E12: Offline public signer | F12: Public software custodian | G12: No | H12: SOURCE EMPTY
A13: Repair patterns | B13: Mission repair and training | C13: Background service methods | D13: Field continuity failure | E13: Validated repair corpus | F13: Generating Service | G13: No | H13: SOURCE EMPTY
A14: Portable credentials | B14: Worker-owned transfer | C14: Employer work assignment | D14: Employer loss or mobilization | E14: Public task credential | F14: Labor Commonwealth | G14: No | H14: SOURCE EMPTY
A15: Critical material buffers | B15: Call right under warrant | C15: Ordinary inventory | D15: Qualified source loss | E15: Identified protected lots | F15: Strategic Sustainment | G15: No | H15: SOURCE EMPTY
A16: Receiver interfaces | B16: Open implementation right | C16: Proprietary internal design | D16: Access or host conversion | E16: Interface emulator | F16: Public receiver commons | G16: No | H16: SOURCE EMPTY
A17: Measurement methods | B17: Open replay and audit | C17: Unrelated instrumentation IP | D17: Disputed result | E17: Reference method and calibration | F17: Proving Service | G17: No | H17: SOURCE EMPTY
A18: Evidence archive | B18: Permanent public custody | C18: Protected unrelated trade data | D18: Always at valid event | E18: Signed packet and samples | F18: Evidence vault | G18: No | H18: SOURCE EMPTY

Sheet Industry Shape
A2: Industrial control concentration
A3: Budget-weighted HHI exposes control aggregation. It does not excuse a failed complete-service or public-truth gate.
A6: Candidate | B6: Independent control groups | C6: Budget-weighted HHI | D6: Effective control groups | E6: Complete-root liability | F6: Replacement entry | G6: Selection | H6: Consequence | J6: Candidate | K6: Control HHI
A7: Separated option-and-proof market | B7: 24 | C7: ='Root Options'!M31 -> 0.04624968 | D7: =1/C7 -> 21.621771 | E7: Yes | F7: Yes | G7: SELECT | H7: One independent control group per complete root | J7: =A7 -> Separated option-and-proof market | K7: =C7 -> 0.04624968
A8: Six lead system integrators | B8: 6 | C8: ='Root Options'!M31*4 -> 0.18499872 | D8: =1/C8 -> 5.4054428 | E8: Yes | F8: No | G8: REJECT | H8: System failure removes four roots | J8: =A8 -> Six lead system integrators | K8: =C8 -> 0.18499872
A9: Ninety-six independent prize cells | B9: 96 | C9: ='Root Options'!M31/4 -> 0.01156242 | D9: =1/C9 -> 86.487085 | E9: No | F9: Yes | G9: REJECT | H9: Low concentration without root liability | J9: =A9 -> Ninety-six independent prize cells | K9: =C9 -> 0.01156242
A10: Twenty-four perpetual franchises | B10: 24 | C10: ='Root Options'!M31 -> 0.04624968 | D10: =1/C10 -> 21.621771 | E10: Yes | F10: No | G10: REJECT | H10: Control is diverse but not contestable | J10: =A10 -> Twenty-four perpetual franchises | K10: =C10 -> 0.04624968
A11: Sovereign public arsenal | B11: 1 | C11: =1 -> 1 | D11: =1/C11 -> 1 | E11: Yes | F11: No | G11: REJECT | H11: One public common root | J11: =A11 -> Sovereign public arsenal | K11: =C11 -> 1

Sheet Stress Tests
A2: Stress Tests
A3: Each world asks whether the first tranche can preserve rivalry, truth and useful failure without manufacturing production authority.
A6: # | B6: Stress world | C6: Required response | D6: Held authority | E6: Forbidden shortcut | F6: Result | G6: Reason
A7: 1 | B7: One investor acquires two Root Houses | C7: Suspend both control warrants and require clean ownership | E7: Legal names → independence | F7: PASS | G7: Beneficial control governs
A8: 2 | B8: A system prime offers four cheaper roots | C8: Reject control aggregation | E8: Lowest price → survivable portfolio | F8: PASS | G8: Four roots need four control groups
A9: 3 | B9: A prize cell wins one field | C9: Retain zero complete-root credit | E9: Mechanism → service | F9: PASS | G9: Root liability remains missing
A10: 4 | B10: Keystone endpoint fails | C10: Pay valid evidence, kill lineage and return unearned option | E10: Failure → nonpayment or retry | F10: PASS | G10: Truth is economically producible
A11: 5 | B11: Trial is invalid | C11: Permit one exact-event replay from protected reserve | D11: 10 | E11: Invalidity → favorable outcome | F11: PASS | G11: Outcome cannot choose repetition
A12: 6 | B12: Shared provider reaches three roots | C12: Disallow third dependency and qualify alternate | E12: Commodity label → independence | F12: PASS | G12: Two-root cap binds
A13: 7 | B13: Root House refuses foreground data | C13: Trigger step-in and suspend option | E13: Trade secret → public captivity | F13: PASS | G13: Mission-limited public rights already vest
A14: 8 | B14: Proving Service requests candidate money | C14: Use sovereign technical account only | D14: 20 | E14: Judge → portfolio sponsor | F14: PASS | G14: Proof budget remains separate
A15: 9 | B15: Popular prototype is demanded in disaster | C15: Use ready force and keep article outside readiness | E15: Urgency → production credit | F15: PASS | G15: Contract state is not force state
A16: 10 | B16: Human-continuity option overruns | C16: Reduce or cancel within MS-HU | E16: Largest need → raid another system | F16: PASS | G16: Owning-account conservation survives
A17: 11 | B17: Root House becomes insolvent | C17: Open continuity receivership and clean recharter | D17: 10 | E17: Firm survival → root survival | F17: PASS | G17: Capability outlives vendor
A18: 12 | B18: Cold team shares a decisive toolchain | C18: Reject reproduction claim | E18: Second team name → independence | F18: PASS | G18: Physical ancestry governs
A19: 13 | B19: Replacement bidder controls another live root | C19: Reject bidder and preserve open entry | D19: 10 | E19: Speed → control collision | F19: PASS | G19: One-root control remains binding
A20: 14 | B20: One root from five systems reaches G4 | C20: Hold every production option | D20: 150 | E20: Near-complete mission → scale | F20: PASS | G20: All-six barrier remains conjunctive

Sheet Mutations
A2: Mutations
A3: Deliberate invalid states must fail and restore with no private award, root credit or production credit.
A6: # | B6: Mutation | C6: Broken law | D6: Expected | E6: Observed | F6: Restoration | G6: Restored | H6: Production credit
A7: 1 | B7: Consolidate four roots under one system prime | C7: One-root control | D7: FAIL | E7: FAIL | F7: Restore four bankruptcy-remote houses | G7: YES | H7: 0
A8: 2 | B8: Award a mechanism without complete-root liability | C8: Complete service | D8: FAIL | E8: FAIL | F8: Bind cell to one root option | G8: YES | H8: 0
A9: 3 | B9: Let a Root House select its challenge world | C9: Independent proof | D9: FAIL | E9: FAIL | F9: Restore Proving Service authority | G9: YES | H9: 0
A10: 4 | B10: Make payment conditional on a favorable result | C10: Paid valid failure | D10: FAIL | E10: FAIL | F10: Pay accepted evidence artifact | G10: YES | H10: 0
A11: 5 | B11: Move unused MS-HU option to MS-HC | C11: Account conservation | D11: FAIL | E11: FAIL | F11: Return to owning mission account | G11: YES | H11: 0
A12: 6 | B12: Assign one supplier to three roots | C12: Provider cap | D12: FAIL | E12: FAIL | F12: Qualify unrelated alternate | G12: YES | H12: 0
A13: 7 | B13: Leave funded tooling outside step-in rights | C13: Public continuity | D13: FAIL | E13: FAIL | F13: Perfect mission-limited public right | G13: YES | H13: 0
A14: 8 | B14: Rebrand a killed root and repeat its valid trial | C14: Permanent evidence | D14: FAIL | E14: FAIL | F14: Constitute clean replacement lineage | G14: YES | H14: 0
A15: 9 | B15: Count T1 option as production readiness | C15: State separation | D15: FAIL | E15: FAIL | F15: Restore zero production credit | G15: YES | H15: 0
A16: 10 | B16: Let the public arsenal build and judge one root | C16: No common root | D16: FAIL | E16: FAIL | F16: Separate builder and evidence custody | G16: YES | H16: 0

Sheet Audit
A2: Terminal audit
A3: Checks observe the industrial transaction and do not feed options, evidence, dispositions or authority.
A6: # | B6: Audit | C6: Actual | D6: Required | E6: Status | F6: Interpretation
A7: 1 | B7: Selected architecture gates | C7: ='Architecture Test'!N7 -> 12 | D7: 12 | E7: =IF(ABS(C7-D7)<0.01,"PASS","FAIL") -> PASS | F7: All hard gates
A8: 2 | B8: Selected architecture count | C8: =COUNTIFS('Architecture Test'!O7:O11,"SELECT") -> 1 | D8: 1 | E8: =IF(ABS(C8-D8)<0.01,"PASS","FAIL") -> PASS | F8: Exactly one selected
A9: 3 | B9: First-tranche accounts | C9: =COUNTA('Account Control'!A7:A11) -> 5 | D9: 5 | E9: =IF(ABS(C9-D9)<0.01,"PASS","FAIL") -> PASS | F9: Exclusive accounts
A10: 4 | B10: First-tranche authority | C10: ='Account Control'!B12 -> 200 | D10: 200 | E10: =IF(ABS(C10-D10)<0.01,"PASS","FAIL") -> PASS | F10: Portfolio ceiling
A11: 5 | B11: Account shares | C11: ='Account Control'!C12 -> 1 | D11: 1 | E11: =IF(ABS(C11-D11)<0.01,"PASS","FAIL") -> PASS | F11: Conserved
A12: 6 | B12: Mission authority | C12: ='Account Control'!B19 -> 110 | D12: 110 | E12: =IF(ABS(C12-D12)<0.01,"PASS","FAIL") -> PASS | F12: Mission account
A13: 7 | B13: Stageable mission options | C13: ='Root Options'!F31 -> 57.390605 | D13: 57.390605 | E13: =IF(ABS(C13-D13)<0.01,"PASS","FAIL") -> PASS | F13: Inherited active ceiling
A14: 8 | B14: Mission options held | C14: ='Root Options'!G31 -> 52.609395 | D14: 52.609395 | E14: =IF(ABS(C14-D14)<0.01,"PASS","FAIL") -> PASS | F14: Evidence-held
A15: 9 | B15: Public enabling accounts | C15: ='Account Control'!F18 -> 80 | D15: 80 | E15: =IF(ABS(C15-D15)<0.01,"PASS","FAIL") -> PASS | F15: No private root award
A16: 10 | B16: Failure reserve | C16: ='Account Control'!F19 -> 10 | D16: 10 | E16: =IF(ABS(C16-D16)<0.01,"PASS","FAIL") -> PASS | F16: Protected
A17: 11 | B17: Root count | C17: =COUNTA('Root Options'!A7:A30) -> 24 | D17: 24 | E17: =IF(ABS(C17-D17)<0.01,"PASS","FAIL") -> PASS | F17: One per control group
A18: 12 | B18: System count | C18: =COUNTA('Root Options'!B7:B30)/4 -> 6 | D18: 6 | E18: =IF(ABS(C18-D18)<0.01,"PASS","FAIL") -> PASS | F18: All systems
A19: 13 | B19: Full mission options | C19: ='Root Options'!E31 -> 550 | D19: 550 | E19: =IF(ABS(C19-D19)<0.01,"PASS","FAIL") -> PASS | F19: Full mission program
A20: 14 | B20: Root first tranche | C20: =SUM('Root Options'!F31:G31) -> 110 | D20: 110 | E20: =IF(ABS(C20-D20)<0.01,"PASS","FAIL") -> PASS | F20: Mission first wave
A21: 15 | B21: Root production credit | C21: ='Root Options'!L31 -> 0 | D21: 0 | E21: =IF(ABS(C21-D21)<0.01,"PASS","FAIL") -> PASS | F21: No production
A22: 16 | B22: Root control HHI | C22: ='Root Options'!M31 -> 0.04624968 | D22: 0.04624968 | E22: =IF(ABS(C22-D22)<0.01,"PASS","FAIL") -> PASS | F22: Twenty-four independent groups
A23: 17 | B23: Effective root controls | C23: =1/'Root Options'!M31 -> 21.621771 | D23: 21.621771 | E23: =IF(ABS(C23-D23)<0.01,"PASS","FAIL") -> PASS | F23: Budget weighted
A24: 18 | B24: Six-prime HHI | C24: ='Industry Shape'!C8 -> 0.18499872 | D24: 0.18499872 | E24: =IF(ABS(C24-D24)<0.01,"PASS","FAIL") -> PASS | F24: Fourfold concentration
A25: 19 | B25: Field assignments | C25: =COUNTA('Field Awards'!A7:A102) -> 96 | D25: 96 | E25: =IF(ABS(C25-D25)<0.01,"PASS","FAIL") -> PASS | F25: Four per root
A26: 20 | B26: Field stageable sum | C26: ='Field Awards'!G103 -> 57.390605 | D26: 57.390605 | E26: =IF(ABS(C26-D26)<0.01,"PASS","FAIL") -> PASS | F26: Traces root options
A27: 21 | B27: Field held sum | C27: ='Field Awards'!H103 -> 52.609395 | D27: 52.609395 | E27: =IF(ABS(C27-D27)<0.01,"PASS","FAIL") -> PASS | F27: Traces held options
A28: 22 | B28: Field root credit | C28: ='Field Awards'!K103 -> 0 | D28: 0 | E28: =IF(ABS(C28-D28)<0.01,"PASS","FAIL") -> PASS | F28: No mechanism-to-root inference
A29: 23 | B29: Field production credit | C29: ='Field Awards'!L103 -> 0 | D29: 0 | E29: =IF(ABS(C29-D29)<0.01,"PASS","FAIL") -> PASS | F29: No production
A30: 24 | B30: Ancestry declarations | C30: =COUNTA('Ancestry Register'!A7:A294) -> 288 | D30: 288 | E30: =IF(ABS(C30-D30)<0.01,"PASS","FAIL") -> PASS | F30: Twelve per root
A31: 25 | B31: Empty ancestry identities | C31: =COUNTIFS('Ancestry Register'!D7:D294,"SOURCE EMPTY") -> 288 | D31: 288 | E31: =IF(ABS(C31-D31)<0.01,"PASS","FAIL") -> PASS | F31: No accepted control facts
A32: 26 | B32: Ancestry production credit | C32: =SUM('Ancestry Register'!H7:H294) -> 0 | D32: 0 | E32: =IF(ABS(C32-D32)<0.01,"PASS","FAIL") -> PASS | F32: No production
A33: 27 | B33: Dependency records | C33: =COUNTA('Shared Dependencies'!A7:A78) -> 72 | D33: 72 | E33: =IF(ABS(C33-D33)<0.01,"PASS","FAIL") -> PASS | F33: Three per root
A34: 28 | B34: Empty dependency identities | C34: =COUNTIFS('Shared Dependencies'!D7:D78,"SOURCE EMPTY") -> 72 | D34: 72 | E34: =IF(ABS(C34-D34)<0.01,"PASS","FAIL") -> PASS | F34: No accepted providers
A35: 29 | B35: Accepted dependency alternates | C35: =SUM('Shared Dependencies'!H7:H78) -> 0 | D35: 0 | E35: =IF(ABS(C35-D35)<0.01,"PASS","FAIL") -> PASS | F35: No qualification
A36: 30 | B36: Payment phases | C36: =COUNTA('Payment Ladder'!A7:A10) -> 4 | D36: 4 | E36: =IF(ABS(C36-D36)<0.01,"PASS","FAIL") -> PASS | F36: FRAME through TRANSFER
A37: 31 | B37: Payment shares | C37: ='Payment Ladder'!B11 -> 1 | D37: 1 | E37: =IF(ABS(C37-D37)<0.01,"PASS","FAIL") -> PASS | F37: Complete active option
A38: 32 | B38: Payment authority | C38: ='Payment Ladder'!C11 -> 57.390605 | D38: 57.390605 | E38: =IF(ABS(C38-D38)<0.01,"PASS","FAIL") -> PASS | F38: Stageable ceiling
A39: 33 | B39: Payment production credit | C39: =SUM('Payment Ladder'!I7:I10) -> 0 | D39: 0 | E39: =IF(ABS(C39-D39)<0.01,"PASS","FAIL") -> PASS | F39: Failure can be paid without production
A40: 34 | B40: Transaction states | C40: =COUNTA('Transaction States'!A7:A14) -> 8 | D40: 8 | E40: =IF(ABS(C40-D40)<0.01,"PASS","FAIL") -> PASS | F40: S0 through S7
A41: 35 | B41: Authority classes | C41: =COUNTA(Authority!A7:A16) -> 10 | D41: 10 | E41: =IF(ABS(C41-D41)<0.01,"PASS","FAIL") -> PASS | F41: Separated powers
A42: 36 | B42: Public rights | C42: =COUNTA('Public Rights'!A7:A18) -> 12 | D42: 12 | E42: =IF(ABS(C42-D42)<0.01,"PASS","FAIL") -> PASS | F42: Step-in assets
A43: 37 | B43: Stress tests | C43: =COUNTIFS('Stress Tests'!F7:F20,"PASS") -> 14 | D43: 14 | E43: =IF(ABS(C43-D43)<0.01,"PASS","FAIL") -> PASS | F43: All worlds pass
...

Sheet Sources & Limits
A2: Sources & Limits
A3: Repository-internal sources only. This workbook specifies a first-tranche planning constitution, not an executed procurement or observed industrial market.
A6: Source or limit | B6: Title | C6: Claims used | D6: Status
A7: Pass 175 | B7: Twenty-Four-Root Diversity Constitution | C7: 24 roots, 96 root-field assignments and 288 decisive domains | D7: Authoritative
A8: Pass 183 | B8: Pre-Article Falsification | C8: USD 43.0B non-lifeline endpoint ceiling and paid failure meaning | D8: Authoritative
A9: Pass 184 | B9: Resilience Proving Service | C9: Independent challenge, control, reconstruction and disposition | D9: Authoritative
A10: Pass 185 | B10: Industrial Command Constitution | C10: Ten authorities, warrants, account separation and rollback | D10: Authoritative
A11: Pass 186 | B11: Chartered Root-House Commonwealth | C11: One-root control, 72 dependencies, public rights and recharter | D11: Authoritative
A12: Pass 190 | B12: Productive Commonwealth Return | C12: Industrial availability is not readiness | D12: Integrated
A13: Pass 206 | B13: National First Article Portfolio | C13: USD 200B first tranche, 96 opportunities and all-six G4 barrier | D13: Authoritative
A14: Source status | B14: All firms, owners, providers, tools, sites and events | C14: No implementation identity or observation is accepted | D14: Source-empty
A15: Fiscal status | B15: Authority is not obligation | C15: Only USD 57.4B of mission options may stage after gates | D15: Zero awarded
A16: Control status | B16: HHI is a design diagnostic | C16: No beneficial-control graph is populated | D16: Unobserved
A17: Production status | B17: No all-six G4 evidence exists | C17: No first-tranche object may create production credit | D17: Zero
... A19: Next decision | B19: First synchronized requirement cohort | C19: Select one problem field per mission system for parallel first-principles requirement closure | D19: Frontier
