Workbook

Sheet Decision
A2: Formation and joint-readiness conversion constitution
A4: Pass 191 | DFG-1 | industry is a regeneration source; only separately warranted formation serials enter the force
M5: State | N5: Credit
A6: Decision metric | B6: Value | M6: Industrial | N6: 0
A7: Verdict | B7: CLOSE | M7: Equipment | N7: 0
A8: Deepest branch | B8: DFG-1, first of five | M8: Service ready | N8: 5251
A9: Selected architecture | B9: Serial conversion lattice | M9: Joint admitted | N9: 2420
A10: Formation states | B10: 5 | M10: Released now | N10: 0
A11: Formation warrants | B11: 10
A12: Owned formation equivalents | B12: 5251
A13: Ready obligation | B13: ='Family Readiness'!I55 -> 3667
A14: Formation-warrant evidence cells | B14: 52510
A15: Joint mission-world cells | B15: 60
A16: Concurrent joint contributions | B16: 2420
A17: Actual service-ready formations | B17: ='Family Readiness'!J55 -> 0
A18: Actual joint campaign credit | B18: ='Joint Stack'!H67 -> 0
A19: Formation capital USD B | B19: 9410.56
A20: Initial formations account USD B | B20: 230
A21: Capital beyond initial account USD B | B21: ='Finance Crosswalk'!B10 -> 9180.56
A22: Direct affiliated billets | B22: 11465213
A23: Released readiness authority | B23: 0
A24: Evidence state | B24: SOURCE EMPTY / HOLD

Sheet Controls
A2: Formation-conversion controls
A4: Blue cells are inherited or transparent planning controls; none can release authority.
A6: Control | B6: Value | C6: Unit | D6: Status
A7: Owned formation equivalents | B7: 5251 | C7: formations | D7: CONSTITUTIVE / PLANNING
A8: Concurrent demand | B8: 2420 | C8: formations | D8: CONSTITUTIVE / PLANNING
A9: Protected reserve | B9: 0.2 | C9: share | D9: CONSTITUTIVE / PLANNING
A10: Readiness districts | B10: 7 | C10: districts | D10: CONSTITUTIVE / PLANNING
A11: District concentration ceiling | B11: 0.2 | C11: share | D11: CONSTITUTIVE / PLANNING
A12: Mission systems | B12: 6 | C12: systems | D12: CONSTITUTIVE / PLANNING
A13: Campaign worlds | B13: 10 | C13: worlds | D13: CONSTITUTIVE / PLANNING
A14: Formation warrants | B14: 10 | C14: warrants | D14: CONSTITUTIVE / PLANNING
A15: Canonical families | B15: 48 | C15: families | D15: CONSTITUTIVE / PLANNING
A16: Formation capital | B16: 9410.56 | C16: USD B | D16: CONSTITUTIVE / PLANNING
A17: Mature 25-year capital screen | B17: 17400 | C17: USD B | D17: CONSTITUTIVE / PLANNING
A18: Initial formations account | B18: 230 | C18: USD B | D18: CONSTITUTIVE / PLANNING
... A22: Released joint campaign credit | B22: 0 | C22: formations | D22: CONSTITUTIVE / PLANNING

Sheet Architecture Gates
A2: Five rival readiness-accounting architectures
A4: Ten gates are conjunctive; convenience and apparent output cannot compensate for missing authority.
A6: Architecture | B6: Distinct states | C6: Named serial | D6: Complete crew | E6: Complete sustainment | F6: Receiver closure | G6: Independent trial | H6: Exclusive reservation | I6: Regeneration | J6: N−1 family law | K6: Joint-world proof | L6: Decision
A7: Industrial-equivalent accounting | B7: PASS | C7: FAIL | D7: FAIL | E7: FAIL | F7: FAIL | G7: FAIL | H7: FAIL | I7: FAIL | J7: FAIL | K7: FAIL | L7: REJECT
A8: Accepted-equipment inventory | B8: PASS | C8: PASS | D8: FAIL | E8: FAIL | F8: FAIL | G8: FAIL | H8: FAIL | I8: FAIL | J8: FAIL | K8: FAIL | L8: REJECT
A9: Service self-certification | B9: PASS | C9: PASS | D9: PASS | E9: PASS | F9: FAIL | G9: FAIL | H9: FAIL | I9: FAIL | J9: FAIL | K9: FAIL | L9: REJECT
A10: Paper joint aggregation | B10: PASS | C10: PASS | D10: PASS | E10: PASS | F10: PASS | G10: PASS | H10: FAIL | I10: FAIL | J10: FAIL | K10: FAIL | L10: REJECT
A11: Serial conversion lattice | B11: PASS | C11: PASS | D11: PASS | E11: PASS | F11: PASS | G11: PASS | H11: PASS | I11: PASS | J11: PASS | K11: PASS | L11: SELECT

Sheet Conversion Law
A2: The serial conversion constitution
A4: Industry regenerates the force; it is never itself booked as deployed force.
A6: Law | B6: Rule | C6: Positive requirement | D6: Failure consequence
A7: L01 | B7: Industrial availability is a source | C7: Factory, tooling, supplier option or cold lot is never a deployable formation | D7: Zero force credit
A8: L02 | B8: Formation is conjunctive | C8: All ten warrants belong to one formation serial; no averaging across units | D8: Any missing warrant = HOLD
A9: L03 | B9: Service and joint states differ | C9: A service-ready formation is not a tested campaign contribution | D9: Joint credit remains zero
A10: L04 | B10: Reservation is physical | C10: People, articles, stocks, mobility and receivers share one exclusive claim graph | D10: Collision removes both claims
A11: L05 | B11: Readiness is instantaneous | C11: Inventory ownership does not imply the required ready fraction is available now | D11: Only current serial states count
A12: L06 | B12: N−1 is family-specific | C12: Every family retains protected demand after any readiness-district loss | D12: No cross-family substitution
A13: L07 | B13: Evidence is authority-separated | C13: Builder, service, proving, capacity and civil authorities cannot self-compose credit | D13: Missing signer = HOLD
A14: L08 | B14: Adverse states persist | C14: Drift, crew loss, reservation conflict, failed trial or regeneration failure rolls back credit | D14: History cannot be erased
A15: L09 | B15: Capital creates no state | C15: USD 230B initial formations and USD 9.41T formation capital are expenditure screens | D15: Spend earns zero authority
A16: L10 | B16: Campaign credit is bounded | C16: Credit attaches to one mission-system × campaign world and its exact interval | D16: No universal readiness claim

Sheet State Machine
A2: Ten formation warrants plus separate joint admission
A4: Each warrant has a single accountable issuer. A later state cannot cure an earlier absence.
A6: Warrant | B6: State | C6: Exit condition | D6: Issuing authority
A7: W1 | B7: Accepted article | C7: Controlled equipment set carries technical acceptance and genealogy | D7: Operating service + Root House
A8: W2 | B8: Complete crew | C8: Named, current, household-supported personnel fill every critical role | D8: Operating service
A9: W3 | B9: Technical release | C9: Configuration, safety, licensing and professional release are current | D9: Operating service
A10: W4 | B10: Sustainment set | C10: Stocks, maintenance, spares, waste and replenishment close the occupied interval | D10: Strategic Sustainment Command
A11: W5 | B11: Mobility and access | C11: Formation reaches and operates through its declared theater-entry envelope | D11: Mission System Command
A12: W6 | B12: Receiver interface | C12: Named receiving capacity, transfer terms and civil admission are proved | D12: Civil Resilience Authority
A13: W7 | B13: Lawful command | C13: Activation, public priority, rights and stop authority are executable | D13: Civil Resilience Authority
A14: W8 | B14: No-notice formation trial | C14: Complete formation produces its service under denial without borrowed credit | D14: Resilience Proving Service
A15: W9 | B15: Exclusive reservation | C15: Serial, people, stocks, lift and receiver claims are not promised elsewhere | D15: Joint Capacity Authority
A16: W10 | B16: Regeneration path | C16: Replacement people, stocks, repair and production restore the exact formation | D16: Strategic Sustainment Command
A19: Joint J1 | B19: Mission interface | C19: Complete formation mapped to one mission-system/campaign stack | D19: Mission System Command
... A21: Joint J3 | B21: Civil admission | C21: Public effects, rights and transfer conditions are accepted | D21: Civil Resilience Authority

Sheet Formation Ledger
A2: Five thousand two hundred fifty-one formation serials
A4: Amber fields are source-empty evidence. Planned obligation is not actual readiness.
A6: Formation serial | B6: Family | C6: Formation | D6: Service | E6: Mission | F6: Generator district | G6: Reach lane | H6: Direct billets | I6: Capital USD B | J6: Planned ready obligation | K6: W1 | L6: W2 | M6: W3 | N6: W4 | O6: W5 | P6: W6 | Q6: W7 | R6: W8 | S6: W9 | T6: W10 | U6: Service state | V6: Service credit
A7: J-CIE-0001 | B7: J-CIE | C7: Civil integration and effects group | D7: Joint | E7: MS-CT | F7: RD-01 | G7: IRN-A | H7: 300 | I7: 0.25 | J7: 1 | U7: =IF(COUNT(K7:T7)=0,"SOURCE EMPTY / INDUSTRIAL ONLY",IF(MIN(K7:T7)=1,"SERVICE READY","HOLD")) -> SOURCE EMPTY / INDUSTRIAL ONLY | V7: =IF(U7="SERVICE READY",1,0) -> 0
A8: J-CIE-0002 | B8: J-CIE | C8: Civil integration and effects group | D8: Joint | E8: MS-CT | F8: RD-02 | G8: IRN-B | H8: 300 | I8: 0.25 | J8: 1 | U8: =IF(COUNT(K8:T8)=0,"SOURCE EMPTY / INDUSTRIAL ONLY",IF(MIN(K8:T8)=1,"SERVICE READY","HOLD")) -> SOURCE EMPTY / INDUSTRIAL ONLY | V8: =IF(U8="SERVICE READY",1,0) -> 0
A9: J-CIE-0003 | B9: J-CIE | C9: Civil integration and effects group | D9: Joint | E9: MS-CT | F9: RD-03 | G9: IRN-A | H9: 300 | I9: 0.25 | J9: 1 | U9: =IF(COUNT(K9:T9)=0,"SOURCE EMPTY / INDUSTRIAL ONLY",IF(MIN(K9:T9)=1,"SERVICE READY","HOLD")) -> SOURCE EMPTY / INDUSTRIAL ONLY | V9: =IF(U9="SERVICE READY",1,0) -> 0
A10: J-CIE-0004 | B10: J-CIE | C10: Civil integration and effects group | D10: Joint | E10: MS-CT | F10: RD-04 | G10: IRN-B | H10: 300 | I10: 0.25 | J10: 1 | U10: =IF(COUNT(K10:T10)=0,"SOURCE EMPTY / INDUSTRIAL ONLY",IF(MIN(K10:T10)=1,"SERVICE READY","HOLD")) -> SOURCE EMPTY / INDUSTRIAL ONLY | V10: =IF(U10="SERVICE READY",1,0) -> 0
A11: J-CIE-0005 | B11: J-CIE | C11: Civil integration and effects group | D11: Joint | E11: MS-CT | F11: RD-05 | G11: IRN-A | H11: 300 | I11: 0.25 | J11: 1 | U11: =IF(COUNT(K11:T11)=0,"SOURCE EMPTY / INDUSTRIAL ONLY",IF(MIN(K11:T11)=1,"SERVICE READY","HOLD")) -> SOURCE EMPTY / INDUSTRIAL ONLY | V11: =IF(U11="SERVICE READY",1,0) -> 0
A12: J-CIE-0006 | B12: J-CIE | C12: Civil integration and effects group | D12: Joint | E12: MS-CT | F12: RD-06 | G12: IRN-B | H12: 300 | I12: 0.25 | J12: 1 | U12: =IF(COUNT(K12:T12)=0,"SOURCE EMPTY / INDUSTRIAL ONLY",IF(MIN(K12:T12)=1,"SERVICE READY","HOLD")) -> SOURCE EMPTY / INDUSTRIAL ONLY | V12: =IF(U12="SERVICE READY",1,0) -> 0
A13: J-CIE-0007 | B13: J-CIE | C13: Civil integration and effects group | D13: Joint | E13: MS-CT | F13: RD-07 | G13: IRN-A | H13: 300 | I13: 0.25 | J13: 1 | U13: =IF(COUNT(K13:T13)=0,"SOURCE EMPTY / INDUSTRIAL ONLY",IF(MIN(K13:T13)=1,"SERVICE READY","HOLD")) -> SOURCE EMPTY / INDUSTRIAL ONLY | V13: =IF(U13="SERVICE READY",1,0) -> 0
A14: J-CIE-0008 | B14: J-CIE | C14: Civil integration and effects group | D14: Joint | E14: MS-CT | F14: RD-01 | G14: IRN-B | H14: 300 | I14: 0.25 | J14: 1 | U14: =IF(COUNT(K14:T14)=0,"SOURCE EMPTY / INDUSTRIAL ONLY",IF(MIN(K14:T14)=1,"SERVICE READY","HOLD")) -> SOURCE EMPTY / INDUSTRIAL ONLY | V14: =IF(U14="SERVICE READY",1,0) -> 0
A15: J-CIE-0009 | B15: J-CIE | C15: Civil integration and effects group | D15: Joint | E15: MS-CT | F15: RD-02 | G15: IRN-A | H15: 300 | I15: 0.25 | J15: 1 | U15: =IF(COUNT(K15:T15)=0,"SOURCE EMPTY / INDUSTRIAL ONLY",IF(MIN(K15:T15)=1,"SERVICE READY","HOLD")) -> SOURCE EMPTY / INDUSTRIAL ONLY | V15: =IF(U15="SERVICE READY",1,0) -> 0
A16: J-CIE-0010 | B16: J-CIE | C16: Civil integration and effects group | D16: Joint | E16: MS-CT | F16: RD-03 | G16: IRN-B | H16: 300 | I16: 0.25 | J16: 1 | U16: =IF(COUNT(K16:T16)=0,"SOURCE EMPTY / INDUSTRIAL ONLY",IF(MIN(K16:T16)=1,"SERVICE READY","HOLD")) -> SOURCE EMPTY / INDUSTRIAL ONLY | V16: =IF(U16="SERVICE READY",1,0) -> 0
A17: J-CIE-0011 | B17: J-CIE | C17: Civil integration and effects group | D17: Joint | E17: MS-CT | F17: RD-04 | G17: IRN-A | H17: 300 | I17: 0.25 | J17: 1 | U17: =IF(COUNT(K17:T17)=0,"SOURCE EMPTY / INDUSTRIAL ONLY",IF(MIN(K17:T17)=1,"SERVICE READY","HOLD")) -> SOURCE EMPTY / INDUSTRIAL ONLY | V17: =IF(U17="SERVICE READY",1,0) -> 0
A18: J-CIE-0012 | B18: J-CIE | C18: Civil integration and effects group | D18: Joint | E18: MS-CT | F18: RD-05 | G18: IRN-B | H18: 300 | I18: 0.25 | J18: 1 | U18: =IF(COUNT(K18:T18)=0,"SOURCE EMPTY / INDUSTRIAL ONLY",IF(MIN(K18:T18)=1,"SERVICE READY","HOLD")) -> SOURCE EMPTY / INDUSTRIAL ONLY | V18: =IF(U18="SERVICE READY",1,0) -> 0
... A5257: CM-RDC-0116 | B5257: CM-RDC | C5257: Return and durable-continuity group | D5257: Civil Mobility and Continuity | E5257: MS-RT | F5257: RD-04 | G5257: DOMESTIC | H5257: 1000 | I5257: 0.4 | J5257: 0 | U5257: =IF(COUNT(K5257:T5257)=0,"SOURCE EMPTY / INDUSTRIAL ONLY",IF(MIN(K5257:T5257)=1,"SERVICE READY","HOLD")) -> SOURCE EMPTY / INDUSTRIAL ONLY | V5257: =IF(U5257="SERVICE READY",1,0) -> 0

Sheet Family Readiness
A2: Family-level readiness and authority
A4: Every family must independently meet its ready fraction and protected demand after one district loss.
A6: Family | B6: Formation | C6: Service | D6: Mission | E6: Demand | F6: Protected demand | G6: Owned inventory | H6: Planning readiness | I6: Ready obligation | J6: Actual service-ready | K6: Gap | L6: Capital USD B | M6: Direct billets | N6: State
A7: J-CIE | B7: Civil integration and effects group | C7: Joint | D7: MS-CT | E7: 34 | F7: 40.8 | G7: 66 | H7: 0.78 | I7: 52 | J7: =COUNTIFS('Formation Ledger'!$B$7:$B$5257,A7,'Formation Ledger'!$V$7:$V$5257,1) -> 0 | K7: =I7-J7 -> 52 | L7: 16.5 | M7: 19800 | N7: =IF(J7>=I7,"READY","HOLD") -> HOLD
A8: J-TOC | B8: Theater-opening command | C8: Joint | D8: MS-ET | E8: 23 | F8: 27.6 | G8: 45 | H8: 0.78 | I8: 36 | J8: =COUNTIFS('Formation Ledger'!$B$7:$B$5257,A8,'Formation Ledger'!$V$7:$V$5257,1) -> 0 | K8: =I8-J8 -> 36 | L8: 54 | M8: 67500 | N8: =IF(J8>=I8,"READY","HOLD") -> HOLD
A9: J-TSC | B9: Theater sustainment command | C9: Joint | D9: MS-RT | E9: 33 | F9: 39.6 | G9: 64 | H9: 0.78 | I9: 50 | J9: =COUNTIFS('Formation Ledger'!$B$7:$B$5257,A9,'Formation Ledger'!$V$7:$V$5257,1) -> 0 | K9: =I9-J9 -> 50 | L9: 96 | M9: 144000 | N9: =IF(J9>=I9,"READY","HOLD") -> HOLD
A10: J-RIG | B10: Resilience information group | C10: Joint | D10: MS-CT | E10: 59 | F10: 70.8 | G10: 114 | H10: 0.78 | I10: 89 | J10: =COUNTIFS('Formation Ledger'!$B$7:$B$5257,A10,'Formation Ledger'!$V$7:$V$5257,1) -> 0 | K10: =I10-J10 -> 89 | L10: 102.6 | M10: 102600 | N10: =IF(J10>=I10,"READY","HOLD") -> HOLD
A11: J-RRG | B11: Replacement and reconstitution group | C11: Joint | D11: MS-RT | E11: 33 | F11: 39.6 | G11: 64 | H11: 0.78 | I11: 50 | J11: =COUNTIFS('Formation Ledger'!$B$7:$B$5257,A11,'Formation Ledger'!$V$7:$V$5257,1) -> 0 | K11: =I11-J11 -> 50 | L11: 51.2 | M11: 64000 | N11: =IF(J11>=I11,"READY","HOLD") -> HOLD
A12: J-TDG | B12: Transfer and demobilization group | C12: Joint | D12: MS-RT | E12: 23 | F12: 27.6 | G12: 45 | H12: 0.78 | I12: 36 | J12: =COUNTIFS('Formation Ledger'!$B$7:$B$5257,A12,'Formation Ledger'!$V$7:$V$5257,1) -> 0 | K12: =I12-J12 -> 36 | L12: 13.5 | M12: 16875 | N12: =IF(J12>=I12,"READY","HOLD") -> HOLD
A13: L-ROG | B13: Access and route-opening group | C13: Land Engineering | D13: MS-ET | E13: 70 | F13: 84 | G13: 151 | H13: 0.7 | I13: 106 | J13: =COUNTIFS('Formation Ledger'!$B$7:$B$5257,A13,'Formation Ledger'!$V$7:$V$5257,1) -> 0 | K13: =I13-J13 -> 106 | L13: 181.2 | M13: 137410 | N13: =IF(J13>=I13,"READY","HOLD") -> HOLD
A14: L-HCG | B14: Flood and hydraulic-control group | C14: Land Engineering | D14: MS-HC | E14: 50 | F14: 60 | G14: 108 | H14: 0.7 | I14: 76 | J14: =COUNTIFS('Formation Ledger'!$B$7:$B$5257,A14,'Formation Ledger'!$V$7:$V$5257,1) -> 0 | K14: =I14-J14 -> 76 | L14: 194.4 | M14: 140400 | N14: =IF(J14>=I14,"READY","HOLD") -> HOLD
A15: L-DMG | B15: Debris and materials group | C15: Land Engineering | D15: MS-HC | E15: 65 | F15: 78 | G15: 140 | H15: 0.7 | I15: 98 | J15: =COUNTIFS('Formation Ledger'!$B$7:$B$5257,A15,'Formation Ledger'!$V$7:$V$5257,1) -> 0 | K15: =I15-J15 -> 98 | L15: 196 | M15: 145600 | N15: =IF(J15>=I15,"READY","HOLD") -> HOLD
A16: L-TWG | B16: Temporary works and crossing group | C16: Land Engineering | D16: MS-ET | E16: 53 | F16: 63.6 | G16: 114 | H16: 0.7 | I16: 80 | J16: =COUNTIFS('Formation Ledger'!$B$7:$B$5257,A16,'Formation Ledger'!$V$7:$V$5257,1) -> 0 | K16: =I16-J16 -> 80 | L16: 136.8 | M16: 103740 | N16: =IF(J16>=I16,"READY","HOLD") -> HOLD
A17: L-GFG | B17: Ground fire and landscape group | C17: Land Engineering | D17: MS-HC | E17: 33 | F17: 39.6 | G17: 71 | H17: 0.7 | I17: 50 | J17: =COUNTIFS('Formation Ledger'!$B$7:$B$5257,A17,'Formation Ledger'!$V$7:$V$5257,1) -> 0 | K17: =I17-J17 -> 50 | L17: 71 | M17: 83070 | N17: =IF(J17>=I17,"READY","HOLD") -> HOLD
A18: A-SMW | B18: Strategic mobility wing | C18: Air Response | D18: MS-ET | E18: 31 | F18: 37.2 | G18: 72 | H18: 0.65 | I18: 47 | J18: =COUNTIFS('Formation Ledger'!$B$7:$B$5257,A18,'Formation Ledger'!$V$7:$V$5257,1) -> 0 | K18: =I18-J18 -> 47 | L18: 576 | M18: 194400 | N18: =IF(J18>=I18,"READY","HOLD") -> HOLD
... A54: CM-RDC | B54: Return and durable-continuity group | C54: Civil Mobility and Continuity | D54: MS-RT | E54: 58 | F54: 69.6 | G54: 116 | H54: 0.75 | I54: 87 | J54: =COUNTIFS('Formation Ledger'!$B$7:$B$5257,A54,'Formation Ledger'!$V$7:$V$5257,1) -> 0 | K54: =I54-J54 -> 87 | L54: 46.4 | M54: 116000 | N54: =IF(J54>=I54,"READY","HOLD") -> HOLD
A55: Total | E55: 2420 | F55: 2904 | G55: 5251 | I55: =SUM(I7:I54) -> 3667 | J55: =SUM(J7:J54) -> 0 | K55: =SUM(K7:K54) -> 3667 | L55: 9410.56 | M55: 11465213 | N55: HOLD

Sheet Service Summary
A2: Generating-service conversion burden
A4: Services own professions, technical release and formation generation; they do not award joint campaign credit.
A6: Generating service | B6: Families | C6: Concurrent demand | D6: Owned inventory | E6: Ready obligation | F6: Direct billets | G6: Capital USD B | H6: Actual service-ready | I6: State
A7: Joint | B7: 6 | C7: 205 | D7: 398 | E7: 313 | F7: 414775 | G7: 333.8 | H7: =SUMIFS('Formation Ledger'!$V$7:$V$5257,'Formation Ledger'!$D$7:$D$5257,A7) -> 0 | I7: =IF(H7>=E7,"READY","HOLD") -> HOLD
A8: Land Engineering | B8: 5 | C8: 271 | D8: 584 | E8: 410 | F8: 610220 | G8: 779.4 | H8: =SUMIFS('Formation Ledger'!$V$7:$V$5257,'Formation Ledger'!$D$7:$D$5257,A8) -> 0 | I8: =IF(H8>=E8,"READY","HOLD") -> HOLD
A9: Air Response | B9: 6 | C9: 218 | D9: 506 | E9: 332 | F9: 670320 | G9: 1785.6 | H9: =SUMIFS('Formation Ledger'!$V$7:$V$5257,'Formation Ledger'!$D$7:$D$5257,A9) -> 0 | I9: =IF(H9>=E9,"READY","HOLD") -> HOLD
A10: Maritime Response | B10: 6 | C10: 188 | D10: 436 | E10: 287 | F10: 705150 | G10: 1776 | H10: =SUMIFS('Formation Ledger'!$V$7:$V$5257,'Formation Ledger'!$D$7:$D$5257,A10) -> 0 | I10: =IF(H10>=E10,"READY","HOLD") -> HOLD
A11: Infrastructure Restoration | B11: 6 | C11: 360 | D11: 773 | E11: 544 | F11: 2469810 | G11: 1147.5 | H11: =SUMIFS('Formation Ledger'!$V$7:$V$5257,'Formation Ledger'!$D$7:$D$5257,A11) -> 0 | I11: =IF(H11>=E11,"READY","HOLD") -> HOLD
A12: Health Protection | B12: 6 | C12: 318 | D12: 738 | E12: 485 | F12: 1309510 | G12: 941.5 | H12: =SUMIFS('Formation Ledger'!$V$7:$V$5257,'Formation Ledger'!$D$7:$D$5257,A12) -> 0 | I12: =IF(H12>=E12,"READY","HOLD") -> HOLD
A13: Community Stabilization | B13: 6 | C13: 498 | D13: 996 | E13: 748 | F13: 803050 | G13: 441.3 | H13: =SUMIFS('Formation Ledger'!$V$7:$V$5257,'Formation Ledger'!$D$7:$D$5257,A13) -> 0 | I13: =IF(H13>=E13,"READY","HOLD") -> HOLD
A14: Civil Mobility and Continuity | B14: 7 | C14: 362 | D14: 820 | E14: 548 | F14: 4482378 | G14: 2205.46 | H14: =SUMIFS('Formation Ledger'!$V$7:$V$5257,'Formation Ledger'!$D$7:$D$5257,A14) -> 0 | I14: =IF(H14>=E14,"READY","HOLD") -> HOLD
A15: Total | B15: 48 | C15: 2420 | D15: 5251 | E15: =SUM(E7:E14) -> 3667 | F15: 11465213 | G15: 9410.56 | H15: =SUM(H7:H14) -> 0 | I15: HOLD

Sheet Mission Summary
A2: Mission-system formation burden
A4: Mission systems integrate complete public-service chains; they cannot manufacture service readiness.
A6: Mission | B6: Mission system | C6: Families | D6: Concurrent demand | E6: Owned inventory | F6: Direct billets | G6: Capital USD B | H6: Service-ready supply | I6: Joint campaign credit
A7: MS-ET | B7: Enter a broken theater | C7: 9 | D7: 369 | E7: 827 | F7: 1012600 | G7: 2054.5 | H7: =SUMIFS('Formation Ledger'!$V$7:$V$5257,'Formation Ledger'!$E$7:$E$5257,A7) -> 0 | I7: 0
A8: MS-CT | B8: Reach occupied civil terrain | C8: 6 | D8: 343 | E8: 724 | F8: 3380998 | G8: 1505.46 | H8: =SUMIFS('Formation Ledger'!$V$7:$V$5257,'Formation Ledger'!$E$7:$E$5257,A8) -> 0 | I8: 0
A9: MS-HC | B9: Control an active hazard | C9: 4 | D9: 170 | E9: 370 | F9: 460870 | G9: 767.4 | H9: =SUMIFS('Formation Ledger'!$V$7:$V$5257,'Formation Ledger'!$E$7:$E$5257,A9) -> 0 | I9: 0
A10: MS-LF | B10: Produce and distribute lifelines | C10: 5 | D10: 256 | E10: 554 | F10: 2338110 | G10: 804 | H10: =SUMIFS('Formation Ledger'!$V$7:$V$5257,'Formation Ledger'!$E$7:$E$5257,A10) -> 0 | I10: 0
A11: MS-HU | B11: Preserve care and human continuity | C11: 15 | D11: 879 | E11: 1944 | F11: 3251860 | G11: 2482.8 | H11: =SUMIFS('Formation Ledger'!$V$7:$V$5257,'Formation Ledger'!$E$7:$E$5257,A11) -> 0 | I11: 0
A12: MS-RT | B12: Sustain, transfer and regenerate | C12: 9 | D12: 403 | E12: 832 | F12: 1020775 | G12: 1796.4 | H12: =SUMIFS('Formation Ledger'!$V$7:$V$5257,'Formation Ledger'!$E$7:$E$5257,A12) -> 0 | I12: 0
A13: Total | C13: 48 | D13: 2420 | E13: 5251 | F13: 11465213 | G13: 9410.56 | H13: =SUM(H7:H12) -> 0 | I13: 0

Sheet Joint Stack
A2: Sixty mission-system × campaign admission cells
A4: A ready formation pool earns no campaign credit until interface, concurrent trial and civil admission all exist.
A6: Joint cell | B6: Mission | C6: Campaign world | D6: Required contributions | E6: Interface evidence | F6: Concurrent trial | G6: Civil admission | H6: Joint credit
A7: MS-ET-01 | B7: MS-ET | C7: C1 Grid and temperature | D7: 37 | E7: SOURCE EMPTY | F7: SOURCE EMPTY | G7: SOURCE EMPTY | H7: =IF(AND(E7="PASS",F7="PASS",G7="PASS"),D7,0) -> 0
A8: MS-ET-02 | B8: MS-ET | C8: C2 Sequential hurricanes | D8: 37 | E8: SOURCE EMPTY | F8: SOURCE EMPTY | G8: SOURCE EMPTY | H8: =IF(AND(E8="PASS",F8="PASS",G8="PASS"),D8,0) -> 0
A9: MS-ET-03 | B9: MS-ET | C9: C3 Cascadia rupture | D9: 37 | E9: SOURCE EMPTY | F9: SOURCE EMPTY | G9: SOURCE EMPTY | H9: =IF(AND(E9="PASS",F9="PASS",G9="PASS"),D9,0) -> 0
A10: MS-ET-04 | B10: MS-ET | C10: M1 Wildfire heat smoke | D10: 37 | E10: SOURCE EMPTY | F10: SOURCE EMPTY | G10: SOURCE EMPTY | H10: =IF(AND(E10="PASS",F10="PASS",G10="PASS"),D10,0) -> 0
A11: MS-ET-05 | B11: MS-ET | C11: M2 Urban heat | D11: 37 | E11: SOURCE EMPTY | F11: SOURCE EMPTY | G11: SOURCE EMPTY | H11: =IF(AND(E11="PASS",F11="PASS",G11="PASS"),D11,0) -> 0
A12: MS-ET-06 | B12: MS-ET | C12: M3 Inland flood | D12: 37 | E12: SOURCE EMPTY | F12: SOURCE EMPTY | G12: SOURCE EMPTY | H12: =IF(AND(E12="PASS",F12="PASS",G12="PASS"),D12,0) -> 0
A13: MS-ET-07 | B13: MS-ET | C13: M4 Tornado corridor | D13: 37 | E13: SOURCE EMPTY | F13: SOURCE EMPTY | G13: SOURCE EMPTY | H13: =IF(AND(E13="PASS",F13="PASS",G13="PASS"),D13,0) -> 0
A14: MS-ET-08 | B14: MS-ET | C14: M5 Territorial drought | D14: 37 | E14: SOURCE EMPTY | F14: SOURCE EMPTY | G14: SOURCE EMPTY | H14: =IF(AND(E14="PASS",F14="PASS",G14="PASS"),D14,0) -> 0
A15: MS-ET-09 | B15: MS-ET | C15: I1 Indo-Pacific invitation | D15: 37 | E15: SOURCE EMPTY | F15: SOURCE EMPTY | G15: SOURCE EMPTY | H15: =IF(AND(E15="PASS",F15="PASS",G15="PASS"),D15,0) -> 0
A16: MS-ET-10 | B16: MS-ET | C16: I2 Atlantic/Americas invitation | D16: 36 | E16: SOURCE EMPTY | F16: SOURCE EMPTY | G16: SOURCE EMPTY | H16: =IF(AND(E16="PASS",F16="PASS",G16="PASS"),D16,0) -> 0
A17: MS-CT-01 | B17: MS-CT | C17: C1 Grid and temperature | D17: 35 | E17: SOURCE EMPTY | F17: SOURCE EMPTY | G17: SOURCE EMPTY | H17: =IF(AND(E17="PASS",F17="PASS",G17="PASS"),D17,0) -> 0
A18: MS-CT-02 | B18: MS-CT | C18: C2 Sequential hurricanes | D18: 35 | E18: SOURCE EMPTY | F18: SOURCE EMPTY | G18: SOURCE EMPTY | H18: =IF(AND(E18="PASS",F18="PASS",G18="PASS"),D18,0) -> 0
... A66: MS-RT-10 | B66: MS-RT | C66: I2 Atlantic/Americas invitation | D66: 40 | E66: SOURCE EMPTY | F66: SOURCE EMPTY | G66: SOURCE EMPTY | H66: =IF(AND(E66="PASS",F66="PASS",G66="PASS"),D66,0) -> 0
A67: Total | D67: 2420 | H67: =SUM(H7:H66) -> 0

Sheet Denial Worlds
A2: Family-by-district N−1 planning test
A4: Planning obligations are distributed, but actual credit remains zero until formation evidence exists.
A6: Family | B6: World | C6: Protected demand | D6: Owned inventory | E6: Ready obligation | F6: Lost district | G6: Planned ready lost | H6: Planned ready remaining | I6: Actual ready remaining | J6: Planning result | K6: Authority result
A7: J-CIE | B7: INTACT | C7: 40.8 | D7: 66 | E7: 52 | F7: — | G7: 0 | H7: 52 | I7: =MAX(0,'Family Readiness'!J7-G7) -> 0 | J7: =IF(H7>=C7,"PASS","FAIL") -> PASS | K7: =IF(I7>=C7,"PASS","HOLD") -> HOLD
A8: J-CIE | B8: LOSS RD-01 | C8: 40.8 | D8: 66 | E8: 52 | F8: 1 | G8: 8 | H8: 44 | I8: =MAX(0,'Family Readiness'!J7-G8) -> 0 | J8: =IF(H8>=C8,"PASS","FAIL") -> PASS | K8: =IF(I8>=C8,"PASS","HOLD") -> HOLD
A9: J-CIE | B9: LOSS RD-02 | C9: 40.8 | D9: 66 | E9: 52 | F9: 2 | G9: 8 | H9: 44 | I9: =MAX(0,'Family Readiness'!J7-G9) -> 0 | J9: =IF(H9>=C9,"PASS","FAIL") -> PASS | K9: =IF(I9>=C9,"PASS","HOLD") -> HOLD
A10: J-CIE | B10: LOSS RD-03 | C10: 40.8 | D10: 66 | E10: 52 | F10: 3 | G10: 8 | H10: 44 | I10: =MAX(0,'Family Readiness'!J7-G10) -> 0 | J10: =IF(H10>=C10,"PASS","FAIL") -> PASS | K10: =IF(I10>=C10,"PASS","HOLD") -> HOLD
A11: J-CIE | B11: LOSS RD-04 | C11: 40.8 | D11: 66 | E11: 52 | F11: 4 | G11: 7 | H11: 45 | I11: =MAX(0,'Family Readiness'!J7-G11) -> 0 | J11: =IF(H11>=C11,"PASS","FAIL") -> PASS | K11: =IF(I11>=C11,"PASS","HOLD") -> HOLD
A12: J-CIE | B12: LOSS RD-05 | C12: 40.8 | D12: 66 | E12: 52 | F12: 5 | G12: 7 | H12: 45 | I12: =MAX(0,'Family Readiness'!J7-G12) -> 0 | J12: =IF(H12>=C12,"PASS","FAIL") -> PASS | K12: =IF(I12>=C12,"PASS","HOLD") -> HOLD
A13: J-CIE | B13: LOSS RD-06 | C13: 40.8 | D13: 66 | E13: 52 | F13: 6 | G13: 7 | H13: 45 | I13: =MAX(0,'Family Readiness'!J7-G13) -> 0 | J13: =IF(H13>=C13,"PASS","FAIL") -> PASS | K13: =IF(I13>=C13,"PASS","HOLD") -> HOLD
A14: J-CIE | B14: LOSS RD-07 | C14: 40.8 | D14: 66 | E14: 52 | F14: 7 | G14: 7 | H14: 45 | I14: =MAX(0,'Family Readiness'!J7-G14) -> 0 | J14: =IF(H14>=C14,"PASS","FAIL") -> PASS | K14: =IF(I14>=C14,"PASS","HOLD") -> HOLD
A15: J-TOC | B15: INTACT | C15: 27.6 | D15: 45 | E15: 36 | F15: — | G15: 0 | H15: 36 | I15: =MAX(0,'Family Readiness'!J8-G15) -> 0 | J15: =IF(H15>=C15,"PASS","FAIL") -> PASS | K15: =IF(I15>=C15,"PASS","HOLD") -> HOLD
A16: J-TOC | B16: LOSS RD-01 | C16: 27.6 | D16: 45 | E16: 36 | F16: 1 | G16: 6 | H16: 30 | I16: =MAX(0,'Family Readiness'!J8-G16) -> 0 | J16: =IF(H16>=C16,"PASS","FAIL") -> PASS | K16: =IF(I16>=C16,"PASS","HOLD") -> HOLD
A17: J-TOC | B17: LOSS RD-02 | C17: 27.6 | D17: 45 | E17: 36 | F17: 2 | G17: 5 | H17: 31 | I17: =MAX(0,'Family Readiness'!J8-G17) -> 0 | J17: =IF(H17>=C17,"PASS","FAIL") -> PASS | K17: =IF(I17>=C17,"PASS","HOLD") -> HOLD
A18: J-TOC | B18: LOSS RD-03 | C18: 27.6 | D18: 45 | E18: 36 | F18: 3 | G18: 5 | H18: 31 | I18: =MAX(0,'Family Readiness'!J8-G18) -> 0 | J18: =IF(H18>=C18,"PASS","FAIL") -> PASS | K18: =IF(I18>=C18,"PASS","HOLD") -> HOLD
A19: J-TOC | B19: LOSS RD-04 | C19: 27.6 | D19: 45 | E19: 36 | F19: 4 | G19: 5 | H19: 31 | I19: =MAX(0,'Family Readiness'!J8-G19) -> 0 | J19: =IF(H19>=C19,"PASS","FAIL") -> PASS | K19: =IF(I19>=C19,"PASS","HOLD") -> HOLD
A20: J-TOC | B20: LOSS RD-05 | C20: 27.6 | D20: 45 | E20: 36 | F20: 5 | G20: 5 | H20: 31 | I20: =MAX(0,'Family Readiness'!J8-G20) -> 0 | J20: =IF(H20>=C20,"PASS","FAIL") -> PASS | K20: =IF(I20>=C20,"PASS","HOLD") -> HOLD
A21: J-TOC | B21: LOSS RD-06 | C21: 27.6 | D21: 45 | E21: 36 | F21: 6 | G21: 5 | H21: 31 | I21: =MAX(0,'Family Readiness'!J8-G21) -> 0 | J21: =IF(H21>=C21,"PASS","FAIL") -> PASS | K21: =IF(I21>=C21,"PASS","HOLD") -> HOLD
A22: J-TOC | B22: LOSS RD-07 | C22: 27.6 | D22: 45 | E22: 36 | F22: 7 | G22: 5 | H22: 31 | I22: =MAX(0,'Family Readiness'!J8-G22) -> 0 | J22: =IF(H22>=C22,"PASS","FAIL") -> PASS | K22: =IF(I22>=C22,"PASS","HOLD") -> HOLD
A23: J-TSC | B23: INTACT | C23: 39.6 | D23: 64 | E23: 50 | F23: — | G23: 0 | H23: 50 | I23: =MAX(0,'Family Readiness'!J9-G23) -> 0 | J23: =IF(H23>=C23,"PASS","FAIL") -> PASS | K23: =IF(I23>=C23,"PASS","HOLD") -> HOLD
A24: J-TSC | B24: LOSS RD-01 | C24: 39.6 | D24: 64 | E24: 50 | F24: 1 | G24: 8 | H24: 42 | I24: =MAX(0,'Family Readiness'!J9-G24) -> 0 | J24: =IF(H24>=C24,"PASS","FAIL") -> PASS | K24: =IF(I24>=C24,"PASS","HOLD") -> HOLD
A25: J-TSC | B25: LOSS RD-02 | C25: 39.6 | D25: 64 | E25: 50 | F25: 2 | G25: 7 | H25: 43 | I25: =MAX(0,'Family Readiness'!J9-G25) -> 0 | J25: =IF(H25>=C25,"PASS","FAIL") -> PASS | K25: =IF(I25>=C25,"PASS","HOLD") -> HOLD
A26: J-TSC | B26: LOSS RD-03 | C26: 39.6 | D26: 64 | E26: 50 | F26: 3 | G26: 7 | H26: 43 | I26: =MAX(0,'Family Readiness'!J9-G26) -> 0 | J26: =IF(H26>=C26,"PASS","FAIL") -> PASS | K26: =IF(I26>=C26,"PASS","HOLD") -> HOLD
A27: J-TSC | B27: LOSS RD-04 | C27: 39.6 | D27: 64 | E27: 50 | F27: 4 | G27: 7 | H27: 43 | I27: =MAX(0,'Family Readiness'!J9-G27) -> 0 | J27: =IF(H27>=C27,"PASS","FAIL") -> PASS | K27: =IF(I27>=C27,"PASS","HOLD") -> HOLD
A28: J-TSC | B28: LOSS RD-05 | C28: 39.6 | D28: 64 | E28: 50 | F28: 5 | G28: 7 | H28: 43 | I28: =MAX(0,'Family Readiness'!J9-G28) -> 0 | J28: =IF(H28>=C28,"PASS","FAIL") -> PASS | K28: =IF(I28>=C28,"PASS","HOLD") -> HOLD
A29: J-TSC | B29: LOSS RD-06 | C29: 39.6 | D29: 64 | E29: 50 | F29: 6 | G29: 7 | H29: 43 | I29: =MAX(0,'Family Readiness'!J9-G29) -> 0 | J29: =IF(H29>=C29,"PASS","FAIL") -> PASS | K29: =IF(I29>=C29,"PASS","HOLD") -> HOLD
A30: J-TSC | B30: LOSS RD-07 | C30: 39.6 | D30: 64 | E30: 50 | F30: 7 | G30: 7 | H30: 43 | I30: =MAX(0,'Family Readiness'!J9-G30) -> 0 | J30: =IF(H30>=C30,"PASS","FAIL") -> PASS | K30: =IF(I30>=C30,"PASS","HOLD") -> HOLD
A31: J-RIG | B31: INTACT | C31: 70.8 | D31: 114 | E31: 89 | F31: — | G31: 0 | H31: 89 | I31: =MAX(0,'Family Readiness'!J10-G31) -> 0 | J31: =IF(H31>=C31,"PASS","FAIL") -> PASS | K31: =IF(I31>=C31,"PASS","HOLD") -> HOLD
A32: J-RIG | B32: LOSS RD-01 | C32: 70.8 | D32: 114 | E32: 89 | F32: 1 | G32: 13 | H32: 76 | I32: =MAX(0,'Family Readiness'!J10-G32) -> 0 | J32: =IF(H32>=C32,"PASS","FAIL") -> PASS | K32: =IF(I32>=C32,"PASS","HOLD") -> HOLD
A33: J-RIG | B33: LOSS RD-02 | C33: 70.8 | D33: 114 | E33: 89 | F33: 2 | G33: 13 | H33: 76 | I33: =MAX(0,'Family Readiness'!J10-G33) -> 0 | J33: =IF(H33>=C33,"PASS","FAIL") -> PASS | K33: =IF(I33>=C33,"PASS","HOLD") -> HOLD
A34: J-RIG | B34: LOSS RD-03 | C34: 70.8 | D34: 114 | E34: 89 | F34: 3 | G34: 13 | H34: 76 | I34: =MAX(0,'Family Readiness'!J10-G34) -> 0 | J34: =IF(H34>=C34,"PASS","FAIL") -> PASS | K34: =IF(I34>=C34,"PASS","HOLD") -> HOLD
A35: J-RIG | B35: LOSS RD-04 | C35: 70.8 | D35: 114 | E35: 89 | F35: 4 | G35: 13 | H35: 76 | I35: =MAX(0,'Family Readiness'!J10-G35) -> 0 | J35: =IF(H35>=C35,"PASS","FAIL") -> PASS | K35: =IF(I35>=C35,"PASS","HOLD") -> HOLD
A36: J-RIG | B36: LOSS RD-05 | C36: 70.8 | D36: 114 | E36: 89 | F36: 5 | G36: 13 | H36: 76 | I36: =MAX(0,'Family Readiness'!J10-G36) -> 0 | J36: =IF(H36>=C36,"PASS","FAIL") -> PASS | K36: =IF(I36>=C36,"PASS","HOLD") -> HOLD
A37: J-RIG | B37: LOSS RD-06 | C37: 70.8 | D37: 114 | E37: 89 | F37: 6 | G37: 12 | H37: 77 | I37: =MAX(0,'Family Readiness'!J10-G37) -> 0 | J37: =IF(H37>=C37,"PASS","FAIL") -> PASS | K37: =IF(I37>=C37,"PASS","HOLD") -> HOLD
A38: J-RIG | B38: LOSS RD-07 | C38: 70.8 | D38: 114 | E38: 89 | F38: 7 | G38: 12 | H38: 77 | I38: =MAX(0,'Family Readiness'!J10-G38) -> 0 | J38: =IF(H38>=C38,"PASS","FAIL") -> PASS | K38: =IF(I38>=C38,"PASS","HOLD") -> HOLD
A39: J-RRG | B39: INTACT | C39: 39.6 | D39: 64 | E39: 50 | F39: — | G39: 0 | H39: 50 | I39: =MAX(0,'Family Readiness'!J11-G39) -> 0 | J39: =IF(H39>=C39,"PASS","FAIL") -> PASS | K39: =IF(I39>=C39,"PASS","HOLD") -> HOLD
A40: J-RRG | B40: LOSS RD-01 | C40: 39.6 | D40: 64 | E40: 50 | F40: 1 | G40: 8 | H40: 42 | I40: =MAX(0,'Family Readiness'!J11-G40) -> 0 | J40: =IF(H40>=C40,"PASS","FAIL") -> PASS | K40: =IF(I40>=C40,"PASS","HOLD") -> HOLD
A41: J-RRG | B41: LOSS RD-02 | C41: 39.6 | D41: 64 | E41: 50 | F41: 2 | G41: 7 | H41: 43 | I41: =MAX(0,'Family Readiness'!J11-G41) -> 0 | J41: =IF(H41>=C41,"PASS","FAIL") -> PASS | K41: =IF(I41>=C41,"PASS","HOLD") -> HOLD
A42: J-RRG | B42: LOSS RD-03 | C42: 39.6 | D42: 64 | E42: 50 | F42: 3 | G42: 7 | H42: 43 | I42: =MAX(0,'Family Readiness'!J11-G42) -> 0 | J42: =IF(H42>=C42,"PASS","FAIL") -> PASS | K42: =IF(I42>=C42,"PASS","HOLD") -> HOLD
A43: J-RRG | B43: LOSS RD-04 | C43: 39.6 | D43: 64 | E43: 50 | F43: 4 | G43: 7 | H43: 43 | I43: =MAX(0,'Family Readiness'!J11-G43) -> 0 | J43: =IF(H43>=C43,"PASS","FAIL") -> PASS | K43: =IF(I43>=C43,"PASS","HOLD") -> HOLD
...

Sheet Reservation Graph
A2: Five claims that must resolve to one formation serial
A4: A reservation is invalid if any constituent is absent, overlapping, expired or tied to another interval.
A6: Claim | B6: Exclusive object | C6: Collision test | D6: Issuer | E6: Required records | F6: Released records | G6: State
A7: Accepted article set | B7: Article genealogy | C7: No same serial/time claim elsewhere | D7: Operating service | E7: 5251 | F7: 0 | G7: HOLD
A8: Named crew and relief | B8: Personnel/task authority | C8: No same serial/time claim elsewhere | D8: Operating service | E8: 5251 | F8: 0 | G8: HOLD
A9: Sustainment stock | B9: Lots and replenishment | C9: No same serial/time claim elsewhere | D9: Strategic Sustainment | E9: 5251 | F9: 0 | G9: HOLD
A10: Movement/access slot | B10: Route/carrier/node | C10: No same serial/time claim elsewhere | D10: Joint Capacity Authority | E10: 5251 | F10: 0 | G10: HOLD
A11: Receiver/admission slot | B11: Host capacity and rights | C11: No same serial/time claim elsewhere | D11: Civil Resilience Authority | E11: 5251 | F11: 0 | G11: HOLD
A12: Formation reservations | B12: All five claims | C12: All five must bind one serial | D12: Joint Capacity Authority | E12: 26255 | F12: 0 | G12: HOLD

Sheet Replacement Screen
A2: Replacement and regeneration sensitivity
A4: This screen exposes annual industrial burden; it does not select service lives or award readiness.
A6: Service life years | B6: Annual formation replacement | C6: Annual formation capital USD B | D6: Annual billet retraining | E6: State
A7: 15 | B7: =ROUNDUP(Controls!$B$7/A7,0) -> 351 | C7: =Controls!$B$16/A7 -> 627.37067 | D7: =ROUNDUP(Controls!$B$19/A7,0) -> 764348 | E7: PLANNING ONLY
A8: 20 | B8: =ROUNDUP(Controls!$B$7/A8,0) -> 263 | C8: =Controls!$B$16/A8 -> 470.528 | D8: =ROUNDUP(Controls!$B$19/A8,0) -> 573261 | E8: PLANNING ONLY
A9: 25 | B9: =ROUNDUP(Controls!$B$7/A9,0) -> 211 | C9: =Controls!$B$16/A9 -> 376.4224 | D9: =ROUNDUP(Controls!$B$19/A9,0) -> 458609 | E9: PLANNING ONLY
A10: 30 | B10: =ROUNDUP(Controls!$B$7/A10,0) -> 176 | C10: =Controls!$B$16/A10 -> 313.68533 | D10: =ROUNDUP(Controls!$B$19/A10,0) -> 382174 | E10: PLANNING ONLY

Sheet Personnel Capital
A2: Formation burden by family
A4: Capital and billets belong to formation families; they are not interchangeable readiness units.
A6: Family | B6: Service | C6: Mission | D6: Inventory | E6: Direct billets | F6: Billets / formation | G6: Capital USD B | H6: Capital / formation USD B | I6: Ready obligation
A7: J-CIE | B7: Joint | C7: MS-CT | D7: 66 | E7: 19800 | F7: 300 | G7: 16.5 | H7: 0.25 | I7: 52
A8: J-TOC | B8: Joint | C8: MS-ET | D8: 45 | E8: 67500 | F8: 1500 | G8: 54 | H8: 1.2 | I8: 36
A9: J-TSC | B9: Joint | C9: MS-RT | D9: 64 | E9: 144000 | F9: 2250 | G9: 96 | H9: 1.5 | I9: 50
A10: J-RIG | B10: Joint | C10: MS-CT | D10: 114 | E10: 102600 | F10: 900 | G10: 102.6 | H10: 0.9 | I10: 89
A11: J-RRG | B11: Joint | C11: MS-RT | D11: 64 | E11: 64000 | F11: 1000 | G11: 51.2 | H11: 0.8 | I11: 50
A12: J-TDG | B12: Joint | C12: MS-RT | D12: 45 | E12: 16875 | F12: 375 | G12: 13.5 | H12: 0.3 | I12: 36
A13: L-ROG | B13: Land Engineering | C13: MS-ET | D13: 151 | E13: 137410 | F13: 910 | G13: 181.2 | H13: 1.2 | I13: 106
A14: L-HCG | B14: Land Engineering | C14: MS-HC | D14: 108 | E14: 140400 | F14: 1300 | G14: 194.4 | H14: 1.8 | I14: 76
A15: L-DMG | B15: Land Engineering | C15: MS-HC | D15: 140 | E15: 145600 | F15: 1040 | G15: 196 | H15: 1.4 | I15: 98
A16: L-TWG | B16: Land Engineering | C16: MS-ET | D16: 114 | E16: 103740 | F16: 910 | G16: 136.8 | H16: 1.2 | I16: 80
A17: L-GFG | B17: Land Engineering | C17: MS-HC | D17: 71 | E17: 83070 | F17: 1170 | G17: 71 | H17: 1 | I17: 50
A18: A-SMW | B18: Air Response | C18: MS-ET | D18: 72 | E18: 194400 | F18: 2700 | G18: 576 | H18: 8 | I18: 47
... A54: CM-RDC | B54: Civil Mobility and Continuity | C54: MS-RT | D54: 116 | E54: 116000 | F54: 1000 | G54: 46.4 | H54: 0.4 | I54: 87
A55: Total | D55: 5251 | E55: 11465213 | G55: 9410.56 | I55: =SUM(I7:I54) -> 3667

Sheet Finance Crosswalk
A2: Program authority versus mature-force capital
A4: The USD 1.00T technology program and the USD 17.4T mature screen are different ledgers.
A6: Ledger | B6: USD B | C6: What it buys | D6: Force-credit rule
A7: USD 1.00T technology and proving program | B7: 1000 | C7: Contest, proof, public estate, initial formations, availability | D7: No expenditure credit
A8: Initial formations subaccount | B8: 230 | C8: Early complete articles, crews, trials and learning | D8: Credit only after all warrants
A9: Formation capital screen | B9: 9410.56 | C9: Capital for 5,251 heterogeneous formations | D9: Planning screen
A10: Formation capital beyond initial account | B10: =B9-B8 -> 9180.56 | C10: Mature formation build not financed by the USD 1.00T envelope | D10: Requires separate authorization
A11: Common capital and program reserve | B11: =B12-B9 -> 7989.44 | C11: Common nodes, bases, projection and screen reserve | D11: Cannot substitute for formations
A12: Mature 25-year capital screen | B12: 17400 | C12: Formation plus common capital and reserve | D12: Planning screen

Sheet Scenario Analysis
A2: Counterfactual readiness states
A4: Scenarios demonstrate the non-fungible state boundaries; they do not alter the source-empty ledger.
A6: Scenario | B6: Industrial available | C6: Article accepted | D6: All service warrants | E6: Reservation | F6: Joint interfaces | G6: Joint trials | H6: Civil admission | I6: Service credits | J6: Joint campaign credits | K6: Meaning
A7: Source-empty baseline | B7: 1 | C7: 0 | D7: 0 | E7: 0 | F7: 0 | G7: 0 | H7: 0 | I7: 0 | J7: 0 | K7: Industrial availability only
A8: Equipment-book readiness | B8: 1 | C8: 1 | D8: 0 | E8: 0 | F8: 0 | G8: 0 | H8: 0 | I8: 0 | J8: 0 | K8: Accepted articles; no formation
A9: Complete except reservation | B9: 1 | C9: 1 | D9: 1 | E9: 0 | F9: 0 | G9: 0 | H9: 0 | I9: 0 | J9: 0 | K9: Double-use risk; no formation
A10: Service-ready only | B10: 1 | C10: 1 | D10: 1 | E10: 1 | F10: 0 | G10: 0 | H10: 0 | I10: 5251 | J10: 0 | K10: Service pool; no campaign proof
A11: Joint trial without civil admission | B11: 1 | C11: 1 | D11: 1 | E11: 1 | F11: 1 | G11: 1 | H11: 0 | I11: 5251 | J11: 0 | K11: Output without lawful acceptance
A12: Full serial conversion | B12: 1 | C12: 1 | D12: 1 | E12: 1 | F12: 1 | G12: 1 | H12: 1 | I12: 5251 | J12: 2420 | K12: Planning maximum after all evidence

Sheet Innovation Program
A2: Technology program for formation truth and joint readiness
A4: The military analogue is not a dashboard; it is a physical evidence and mobilization infrastructure.
A6: Program | B6: Technology | C6: Capability sought | D6: Fatal criterion
A7: I01 | B7: Formation truth twin | C7: Bind article, crew, stock, receiver and mission state to one reconstructable serial | D7: Twin cannot be independently rebuilt after network loss
A8: I02 | B8: Dynamic reservation graph | C8: Detect cross-program claims on people, lift, stocks, receivers and time | D8: A deliberate collision remains credited
A9: I03 | B9: Autonomous acceptance cell | C9: Instrument complete formation trials at operational scale without vendor custody | D9: Cell cannot expose hidden support
A10: I04 | B10: Synthetic receiving society | C10: Exercise hospitals, utilities, ports, households and rights under controlled denial | D10: Synthetic receiver predicts no real bottleneck
A11: I05 | B11: No-notice mission worlds | C11: Recompose ten campaign conditions faster than organizations can rehearse answers | D11: Challenge leaks permit scripted success
A12: I06 | B12: Portable crew authority | C12: Carry competence, fatigue, licensing and household continuity across employers and districts | D12: Identity loss breaks lawful task assignment
A13: I07 | B13: Self-describing sustainment set | C13: Machine-readable stocks state their ancestry, depletion, substitutes and residuals | D13: Set reports completeness while a critical chain is absent
A14: I08 | B14: Receiver-interface compiler | C14: Prove mechanical, data, legal, clinical and transfer closure before movement | D14: Compiler accepts an interface that fails at load
A15: I09 | B15: Regeneration digital thread | C15: Cold-rebuild the exact deployed configuration from public rights and distributed routes | D15: Rebuild changes the accepted service boundary
A16: I10 | B16: Rights-aware command runtime | C16: Make civil priority, stop authority, consent and audit survive degraded communications | D16: Runtime centralizes a sovereign judgment
A17: I11 | B17: Formation-scale fatigue observatory | C17: Predict crew and maintenance collapse across 56–281 day occupations | D17: Model hides rare-skill exhaustion
A18: I12 | B18: Adversarial joint-stack compiler | C18: Generate unlike, coupled interface failures across all six mission systems | D18: Compiler rewards local success while public service fails

Sheet Audit
A2: Terminal model audit
A4: One-way checks never feed readiness authority.
A6: Audit ID | B6: Scope | C6: Object | D6: Test | E6: Result | F6: Expected
A7: A-C-01 | B7: Control | C7: Owned formation equivalents | D7: equals 5251 | E7: =IF(Controls!B7=5251,"PASS","FAIL") -> PASS | F7: PASS
A8: A-C-02 | B8: Control | C8: Concurrent demand | D8: equals 2420 | E8: =IF(Controls!B8=2420,"PASS","FAIL") -> PASS | F8: PASS
A9: A-C-03 | B9: Control | C9: Protected reserve | D9: equals 0.2 | E9: =IF(Controls!B9=0.2,"PASS","FAIL") -> PASS | F9: PASS
A10: A-C-04 | B10: Control | C10: Readiness districts | D10: equals 7 | E10: =IF(Controls!B10=7,"PASS","FAIL") -> PASS | F10: PASS
A11: A-C-05 | B11: Control | C11: District concentration ceiling | D11: equals 0.2 | E11: =IF(Controls!B11=0.2,"PASS","FAIL") -> PASS | F11: PASS
A12: A-C-06 | B12: Control | C12: Mission systems | D12: equals 6 | E12: =IF(Controls!B12=6,"PASS","FAIL") -> PASS | F12: PASS
A13: A-C-07 | B13: Control | C13: Campaign worlds | D13: equals 10 | E13: =IF(Controls!B13=10,"PASS","FAIL") -> PASS | F13: PASS
A14: A-C-08 | B14: Control | C14: Formation warrants | D14: equals 10 | E14: =IF(Controls!B14=10,"PASS","FAIL") -> PASS | F14: PASS
A15: A-C-09 | B15: Control | C15: Canonical families | D15: equals 48 | E15: =IF(Controls!B15=48,"PASS","FAIL") -> PASS | F15: PASS
A16: A-C-10 | B16: Control | C16: Formation capital | D16: equals 9410.56 | E16: =IF(Controls!B16=9410.56,"PASS","FAIL") -> PASS | F16: PASS
A17: A-C-11 | B17: Control | C17: Mature 25-year capital screen | D17: equals 17400 | E17: =IF(Controls!B17=17400,"PASS","FAIL") -> PASS | F17: PASS
A18: A-C-12 | B18: Control | C18: Initial formations account | D18: equals 230 | E18: =IF(Controls!B18=230,"PASS","FAIL") -> PASS | F18: PASS
A19: A-C-13 | B19: Control | C19: Direct affiliated billets | D19: equals 11465213 | E19: =IF(Controls!B19=11465213,"PASS","FAIL") -> PASS | F19: PASS
A20: A-C-14 | B20: Control | C20: Joint mission-world cells | D20: equals 60 | E20: =IF(Controls!B20=60,"PASS","FAIL") -> PASS | F20: PASS
A21: A-C-15 | B21: Control | C21: Released service formations | D21: equals 0 | E21: =IF(Controls!B21=0,"PASS","FAIL") -> PASS | F21: PASS
A22: A-C-16 | B22: Control | C22: Released joint campaign credit | D22: equals 0 | E22: =IF(Controls!B22=0,"PASS","FAIL") -> PASS | F22: PASS
A23: A-F-01 | B23: Source | C23: Families | D23: 48 families | E23: =IF(COUNTA('Family Readiness'!A7:A54)=48,"PASS","FAIL") -> PASS | F23: PASS
A24: A-F-02 | B24: Source | C24: Inventory | D24: 5,251 serials | E24: =IF(COUNTA('Formation Ledger'!A7:A5257)=5251,"PASS","FAIL") -> PASS | F24: PASS
A25: A-F-03 | B25: Source | C25: Demand | D25: 2,420 concurrent contributions | E25: =IF(SUM('Family Readiness'!E7:E54)=2420,"PASS","FAIL") -> PASS | F25: PASS
A26: A-F-04 | B26: Source | C26: Capital | D26: USD 9,410.56B | E26: =IF(ABS(SUM('Formation Ledger'!I7:I5257)-9410.56)<0.01,"PASS","FAIL") -> PASS | F26: PASS
A27: A-F-05 | B27: Source | C27: Billets | D27: 11,465,213 | E27: =IF(SUM('Formation Ledger'!H7:H5257)=11465213,"PASS","FAIL") -> PASS | F27: PASS
A28: A-S-0001 | B28: Serial | C28: J-CIE-0001 | D28: Serial populated and zero unsupported credit | E28: =IF(AND('Formation Ledger'!A7<>"",'Formation Ledger'!V7=0),"PASS","FAIL") -> PASS | F28: PASS
A29: A-S-0002 | B29: Serial | C29: J-CIE-0002 | D29: Serial populated and zero unsupported credit | E29: =IF(AND('Formation Ledger'!A8<>"",'Formation Ledger'!V8=0),"PASS","FAIL") -> PASS | F29: PASS
A30: A-S-0003 | B30: Serial | C30: J-CIE-0003 | D30: Serial populated and zero unsupported credit | E30: =IF(AND('Formation Ledger'!A9<>"",'Formation Ledger'!V9=0),"PASS","FAIL") -> PASS | F30: PASS
A31: A-S-0004 | B31: Serial | C31: J-CIE-0004 | D31: Serial populated and zero unsupported credit | E31: =IF(AND('Formation Ledger'!A10<>"",'Formation Ledger'!V10=0),"PASS","FAIL") -> PASS | F31: PASS
A32: A-S-0005 | B32: Serial | C32: J-CIE-0005 | D32: Serial populated and zero unsupported credit | E32: =IF(AND('Formation Ledger'!A11<>"",'Formation Ledger'!V11=0),"PASS","FAIL") -> PASS | F32: PASS
A33: A-S-0006 | B33: Serial | C33: J-CIE-0006 | D33: Serial populated and zero unsupported credit | E33: =IF(AND('Formation Ledger'!A12<>"",'Formation Ledger'!V12=0),"PASS","FAIL") -> PASS | F33: PASS
A34: A-S-0007 | B34: Serial | C34: J-CIE-0007 | D34: Serial populated and zero unsupported credit | E34: =IF(AND('Formation Ledger'!A13<>"",'Formation Ledger'!V13=0),"PASS","FAIL") -> PASS | F34: PASS
A35: A-S-0008 | B35: Serial | C35: J-CIE-0008 | D35: Serial populated and zero unsupported credit | E35: =IF(AND('Formation Ledger'!A14<>"",'Formation Ledger'!V14=0),"PASS","FAIL") -> PASS | F35: PASS
A36: A-S-0009 | B36: Serial | C36: J-CIE-0009 | D36: Serial populated and zero unsupported credit | E36: =IF(AND('Formation Ledger'!A15<>"",'Formation Ledger'!V15=0),"PASS","FAIL") -> PASS | F36: PASS
A37: A-S-0010 | B37: Serial | C37: J-CIE-0010 | D37: Serial populated and zero unsupported credit | E37: =IF(AND('Formation Ledger'!A16<>"",'Formation Ledger'!V16=0),"PASS","FAIL") -> PASS | F37: PASS
A38: A-S-0011 | B38: Serial | C38: J-CIE-0011 | D38: Serial populated and zero unsupported credit | E38: =IF(AND('Formation Ledger'!A17<>"",'Formation Ledger'!V17=0),"PASS","FAIL") -> PASS | F38: PASS
A39: A-S-0012 | B39: Serial | C39: J-CIE-0012 | D39: Serial populated and zero unsupported credit | E39: =IF(AND('Formation Ledger'!A18<>"",'Formation Ledger'!V18=0),"PASS","FAIL") -> PASS | F39: PASS
... A5278: A-S-5251 | B5278: Serial | C5278: CM-RDC-0116 | D5278: Serial populated and zero unsupported credit | E5278: =IF(AND('Formation Ledger'!A5257<>"",'Formation Ledger'!V5257=0),"PASS","FAIL") -> PASS | F5278: PASS
A5279: A-N1-001 | B5279: N-1 planning | C5279: J-CIE INTACT | D5279: Planning ready remains protected | E5279: =IF('Denial Worlds'!J7="PASS","PASS","FAIL") -> PASS | F5279: PASS
A5280: A-N1-002 | B5280: N-1 planning | C5280: J-CIE LOSS RD-01 | D5280: Planning ready remains protected | E5280: =IF('Denial Worlds'!J8="PASS","PASS","FAIL") -> PASS | F5280: PASS
A5281: A-N1-003 | B5281: N-1 planning | C5281: J-CIE LOSS RD-02 | D5281: Planning ready remains protected | E5281: =IF('Denial Worlds'!J9="PASS","PASS","FAIL") -> PASS | F5281: PASS
...

Sheet Mutation Tests
A2: Restored mutation tests
A4: Four decision controls fail their exact terminal audit and restore cleanly.
A6: Test | B6: Control | C6: Baseline | D6: Mutation | E6: Audit ID | F6: Mutated | G6: Restored
A7: M-01 | B7: Owned formation equivalents | C7: 5251 | D7: 5252 | E7: A-C-01 | F7: FAIL | G7: PASS
A8: M-02 | B8: Concurrent demand | C8: 2420 | D8: 2421 | E8: A-C-02 | F8: FAIL | G8: PASS
A9: M-10 | B9: Formation capital | C9: 9410.56 | D9: 9411.56 | E9: A-C-10 | F9: FAIL | G9: PASS
A10: M-15 | B10: Released service formations | C10: 0 | D10: 1 | E10: A-C-15 | F10: FAIL | G10: PASS

Sheet Sources
A2: Internal source lineage
A4: No external sites or datasets are used. Counts are exact; fiscal and lifecycle values are planning screens.
A6: Source | B6: Repository artifact | C6: Claims used | D6: Limit
A7: Pass 190 | B7: research/force/generation/department-of-resilience-productive-commonwealth-sustaining-economy-and-return.md | C7: Industry returns as availability, not formation | D7: All identities source-empty
A8: Pass 185 | B8: research/force/generation/department-of-resilience-industrial-command-constitution-and-capability-warrant-state-machine.md | C8: Exclusive authorities and twelve capability warrants | D8: Root capability, not formation serial
A9: Pass 168 | B9: research/force/generation/department-of-resilience-six-mission-system-portfolio-topology-and-technology-competition-constitution.md | C9: 48 families, six mission systems, capital and billets | D9: Portfolio planning hypotheses
A10: Pass 167 | B10: research/force/generation/department-of-resilience-national-and-invited-international-concurrency-geography-and-force-sizing-constitution.md | C10: 2,420 demand, 5,251 inventory, readiness and N−1 | D10: No procurement authority
A11: Force composition | B11: research/force/generation/force-composition.md | C11: Complete mission-package doctrine and seven services | D11: Conceptual composition
A12: National registry | B12: research/force/generation/national-formation-registry.md | C12: Canonical family grammar | D12: No source-verified article bill

Sheet Read Me
A2: Model use and limits
A4: This model separates industrial availability, article acceptance, service formation, joint contribution and campaign credit.
A6: Topic | B6: Guidance
A7: Purpose | B7: Constitute the conversion boundary between the Productive Commonwealth and the operational force.
A8: Five states | B8: Industrial availability → accepted equipment set → service-ready formation → joint mission contribution → campaign credit.
A9: Formation ledger | B9: 5,251 serials reproduce the Pass 167 inventory. Ten amber evidence fields per serial remain source-empty.
A10: Ready obligation | B10: 3,667 is the sum of family-specific ceiling(inventory × planning readiness); it is not current readiness.
A11: N−1 | B11: 384 family-world tests distribute the planning obligation across seven districts. Planning passage does not create authority.
A12: Joint stack | B12: Sixty cells represent six mission systems in ten campaign worlds. Interfaces, concurrent trials and civil admission are empty.
A13: Finance | B13: USD 230B initial formations is a subaccount of the USD 1.00T program; USD 9.41T is the separate full formation-capital screen.
A14: Replacement | B14: 15–30 year sensitivities expose industrial and workforce regeneration burdens but select no service life.
A15: Innovation | B15: Twelve technology programs treat truth, reservation, receivers and regeneration as physical capabilities.
A16: Evidence | B16: Every actual service and joint credit remains zero. Source-empty cells must not be edited without governed evidence.
A17: Rendering | B17: No vehicle, facility, map or exterior rendering is authorized.
A18: Next resolution | B18: Specify the formation-generation campaign: build, crew, trial, reserve and replacement waves without counting partial states.
