Workbook

Sheet ReadMe
A2: RBW-1 model guide
A5: Model | B5: NCFC-1 National Common Force Constitution
A7: Purpose | B7: Decompose the conserved C24 fire-control force into five jurisdictions; define warrants and prevent one article from satisfying two obligations.
A8: Decision | B8: Select the assured common-force architecture while admitting no cross-portfolio capital reduction.
A9: Boundary | B9: 24 groups, 192 operational sets, 256 system bodies, USD 3.6412016T initial capital.
A10: Currency | B10: Constant 2026 USD billions unless a sheet states another unit.
A11: Evidence | B11: Internal research lineage only; no external sources or observed physical results.
A12: Editable cells | B12: Amber fill and blue type.
A13: Formula cells | B13: Black for same-sheet formulas; green for cross-sheet links in working sheets.
A14: Interpretation | B14: Capital jurisdiction is not an expenditure saving. Capacity is conserved until compound demand is proved.
A15: Rendering | B15: Blocked until common-family quantity, geometry and receiver topology are admitted.
A17: Navigation
A18: Sheet | B18: Role | C18: Primary use
A19: Executive | B19: output | C19: selected architecture and top result
A20: Control | B20: input | C20: parent boundary and sensitivity
A21: Family_Ledger | B21: build | C21: family class, quantity and body capital
A22: Reserve_Ledger | B22: build | C22: exact group reserve cost
A23: Capital_Attrib | B23: output/build | C23: five-ledger initial capital
A24: Quantity_Registry | B24: output | C24: national holdings by family
A25: Warrant_Schema | B25: constitution | C25: required availability fields
A26: Warrant_States | B26: constitution | C26: state and readiness eligibility
A27: Demand_Worlds | B27: research | C27: compound worlds for next pass
A28: Capacity_Compiler | B28: build | C28: coincidence sensitivity and conservation
A29: Collision_Rules | B29: constitution | C29: priority and recall law
... A37: Audit | B37: audit | C37: formula and denial checks

Sheet Control
A2: Control panel
A5: Input | B5: Value | C5: Unit / rule | E5: Case | F5: Admissible | G5: Reason
A6: Selected architecture | B6: D | C6: A-D; D selected | E6: A | F6: NO | G6: separate service fleets duplicate common functions
A7: Groups | B7: 24 | C7: one-line groups | E7: B | F7: NO | G7: central pool has no unique reservations
A8: Operational sets | B8: 192 | C8: 8 per group | E8: C | F8: NO | G8: market capacity has no protected baseline
A9: System bodies | B9: 256 | C9: all fleet accounts | E9: D | F9: YES | G9: warrants preserve complete service and conservation
A10: Prime movers | B10: 84480 | C10: national holdings
A11: Load frames | B11: 79200 | C11: national holdings
A12: Launch stations | B12: 48 | C12: 2 per group
A13: Arsenals | B13: 18 | C13: national sites
A14: Arsenal bays | B14: 180 | C14: 10 per arsenal
A15: Public personnel | B15: 429440 | C15: all public positions
A16: Coincident share | B16: 1 | C16: illustrative second portfolio
A17: Years | B17: 25 | C17: lifecycle horizon
A18: Technology authority | B18: 250 | C18: USD B
A19: Parent force capital | B19: 15179 | C19: USD B; research boundary

Sheet Family_Ledger
A2: Family jurisdiction and national quantity ledger
A5: ID | B5: Function | C5: Class | D5: Set qty | E5: Unit cost USD M | F5: Set cost USD M | G5: Reserve/group | H5: Reserve cost/group USD B | I5: Installed in bodies | J5: National reserve | K5: National holdings | L5: Body capital USD B | M5: Reserve capital USD B | N5: Total traced capital USD B | O5: Reason
A6: EFF-16 | B6: intervention cells | C6: D | D6: 16 | E6: 120 | F6: =D6*E6 -> 1920 | G6: 32 | H6: =G6*E6/1000 -> 3.84 | I6: =Control!$B$9*D6 -> 4096 | J6: =Control!$B$7*G6 -> 768 | K6: =I6+J6 -> 4864 | L6: =Control!$B$9*F6/1000 -> 491.52 | M6: =Control!$B$7*H6 -> 92.16 | N6: =L6+M6 -> 583.68 | O6: distinctive hazard intervention
A7: WPT-500 | B7: treatment trains | C7: P | D7: 6 | E7: 180 | F7: =D7*E7 -> 1080 | G7: 12 | H7: =G7*E7/1000 -> 2.16 | I7: =Control!$B$9*D7 -> 1536 | J7: =Control!$B$7*G7 -> 288 | K7: =I7+J7 -> 1824 | L7: =Control!$B$9*F7/1000 -> 276.48 | M7: =Control!$B$7*H7 -> 51.84 | N7: =L7+M7 -> 328.32 | O7: hazard-water chemistry
A8: RAW-1000 | B8: raw-water intake paths | C8: P | D8: 3 | E8: 60 | F8: =D8*E8 -> 180 | G8: 6 | H8: =G8*E8/1000 -> 0.36 | I8: =Control!$B$9*D8 -> 768 | J8: =Control!$B$7*G8 -> 144 | K8: =I8+J8 -> 912 | L8: =Control!$B$9*F8/1000 -> 46.08 | M8: =Control!$B$7*H8 -> 8.64 | N8: =L8+M8 -> 54.72 | O8: source acquisition
A9: RTL-100 | B9: trunkline sections | C9: P | D9: 120 | E9: 1.5 | F9: =D9*E9 -> 180 | G9: 240 | H9: =G9*E9/1000 -> 0.36 | I9: =Control!$B$9*D9 -> 30720 | J9: =Control!$B$7*G9 -> 5760 | K9: =I9+J9 -> 36480 | L9: =Control!$B$9*F9/1000 -> 46.08 | M9: =Control!$B$7*H9 -> 8.64 | N9: =L9+M9 -> 54.72 | O9: sanitary high-flow conveyance
A10: RTR-12 | B10: route and repair robots | C10: P | D10: 24 | E10: 12 | F10: =D10*E10 -> 288 | G10: 48 | H10: =G10*E10/1000 -> 0.576 | I10: =Control!$B$9*D10 -> 6144 | J10: =Control!$B$7*G10 -> 1152 | K10: =I10+J10 -> 7296 | L10: =Control!$B$9*F10/1000 -> 73.728 | M10: =Control!$B$7*H10 -> 13.824 | N10: =L10+M10 -> 87.552 | O10: route and pipe restoration
A11: BUF-100 | B11: ready-storage cells | C11: P | D11: 15 | E11: 5 | F11: =D11*E11 -> 75 | G11: 30 | H11: =G11*E11/1000 -> 0.15 | I11: =Control!$B$9*D11 -> 3840 | J11: =Control!$B$7*G11 -> 720 | K11: =I11+J11 -> 4560 | L11: =Control!$B$9*F11/1000 -> 19.2 | M11: =Control!$B$7*H11 -> 3.6 | N11: =L11+M11 -> 22.8 | O11: ready-water custody
A12: REC-185 | B12: recovery trains | C12: P | D12: 4 | E12: 120 | F12: =D12*E12 -> 480 | G12: 12 | H12: =G12*E12/1000 -> 1.44 | I12: =Control!$B$9*D12 -> 1024 | J12: =Control!$B$7*G12 -> 288 | K12: =I12+J12 -> 1312 | L12: =Control!$B$9*F12/1000 -> 122.88 | M12: =Control!$B$7*H12 -> 34.56 | N12: =L12+M12 -> 157.44 | O12: source-bearing liquid recovery
A13: SUR-100 | B13: surge-custody cells | C13: P | D13: 36 | E13: 4 | F13: =D13*E13 -> 144 | G13: 72 | H13: =G13*E13/1000 -> 0.288 | I13: =Control!$B$9*D13 -> 9216 | J13: =Control!$B$7*G13 -> 1728 | K13: =I13+J13 -> 10944 | L13: =Control!$B$9*F13/1000 -> 36.864 | M13: =Control!$B$7*H13 -> 6.912 | N13: =L13+M13 -> 43.776 | O13: isolated liquid custody
A14: ENG-5/7 | B14: energy islands | C14: N | D14: 6 | E14: 180 | F14: =D14*E14 -> 1080 | G14: 12 | H14: =G14*E14/1000 -> 2.16 | I14: =Control!$B$9*D14 -> 1536 | J14: =Control!$B$7*G14 -> 288 | K14: =I14+J14 -> 1824 | L14: =Control!$B$9*F14/1000 -> 276.48 | M14: =Control!$B$7*H14 -> 51.84 | N14: =L14+M14 -> 328.32 | O14: deployable energy service
A15: PWR-20 | B15: field distribution units | C15: N | D15: 20 | E15: 20 | F15: =D15*E15 -> 400 | G15: 40 | H15: =G15*E15/1000 -> 0.8 | I15: =Control!$B$9*D15 -> 5120 | J15: =Control!$B$7*G15 -> 960 | K15: =I15+J15 -> 6080 | L15: =Control!$B$9*F15/1000 -> 102.4 | M15: =Control!$B$7*H15 -> 19.2 | N15: =L15+M15 -> 121.6 | O15: protected field distribution
A16: LCN-12 | B16: local command nodes | C16: N | D16: 12 | E16: 8 | F16: =D16*E16 -> 96 | G16: 24 | H16: =G16*E16/1000 -> 0.192 | I16: =Control!$B$9*D16 -> 3072 | J16: =Control!$B$7*G16 -> 576 | K16: =I16+J16 -> 3648 | L16: =Control!$B$9*F16/1000 -> 24.576 | M16: =Control!$B$7*H16 -> 4.608 | N16: =L16+M16 -> 29.184 | O16: disconnected local control
A17: SCN-2 | B17: set coordination nodes | C17: N | D17: 2 | E17: 60 | F17: =D17*E17 -> 120 | G17: 4 | H17: =G17*E17/1000 -> 0.24 | I17: =Control!$B$9*D17 -> 512 | J17: =Control!$B$7*G17 -> 96 | K17: =I17+J17 -> 608 | L17: =Control!$B$9*F17/1000 -> 30.72 | M17: =Control!$B$7*H17 -> 5.76 | N17: =L17+M17 -> 36.48 | O17: unlike coordination
... A25: TES-300 | B25: transit-energy stock | C25: Stock | D25: 1 | E25: 30 | F25: =D25*E25 -> 30 | G25: 0 | H25: =G25*E25/1000 -> 0 | I25: =Control!$B$9*D25 -> 256 | J25: =Control!$B$7*G25 -> 0 | K25: =I25+J25 -> 256 | L25: =Control!$B$9*F25/1000 -> 7.68 | M25: =Control!$B$7*H25 -> 0 | N25: =L25+M25 -> 7.68 | O25: transit consumable screen
A26: TOTAL | F26: =SUM(F6:F25) -> 7611.1 | H26: =SUM(H6:H25) -> 13.706 | I26: =SUM(I6:I25) -> 91392 | J26: =SUM(J6:J25) -> 14640 | K26: =SUM(K6:K25) -> 106032 | L26: =SUM(L6:L25) -> 1948.4416 | M26: =SUM(M6:M25) -> 328.944 | N26: =SUM(N6:N25) -> 2277.3856

Sheet Reserve_Ledger
A2: Exact group reserve bill
A5: ID | B5: Class | C5: Units/group | D5: Unit cost USD M | E5: Cost/group USD B | F5: Groups | G5: National units | H5: National cost USD B
A6: EFF-16 | B6: D | C6: 32 | D6: 120 | E6: =C6*D6/1000 -> 3.84 | F6: =Control!$B$7 -> 24 | G6: =C6*F6 -> 768 | H6: =E6*F6 -> 92.16
A7: WPT-500 | B7: P | C7: 12 | D7: 180 | E7: =C7*D7/1000 -> 2.16 | F7: =Control!$B$7 -> 24 | G7: =C7*F7 -> 288 | H7: =E7*F7 -> 51.84
A8: RAW-1000 | B8: P | C8: 6 | D8: 60 | E8: =C8*D8/1000 -> 0.36 | F8: =Control!$B$7 -> 24 | G8: =C8*F8 -> 144 | H8: =E8*F8 -> 8.64
A9: RTL-100 | B9: P | C9: 240 | D9: 1.5 | E9: =C9*D9/1000 -> 0.36 | F9: =Control!$B$7 -> 24 | G9: =C9*F9 -> 5760 | H9: =E9*F9 -> 8.64
A10: RTR-12 | B10: P | C10: 48 | D10: 12 | E10: =C10*D10/1000 -> 0.576 | F10: =Control!$B$7 -> 24 | G10: =C10*F10 -> 1152 | H10: =E10*F10 -> 13.824
A11: BUF-100 | B11: P | C11: 30 | D11: 5 | E11: =C11*D11/1000 -> 0.15 | F11: =Control!$B$7 -> 24 | G11: =C11*F11 -> 720 | H11: =E11*F11 -> 3.6
A12: REC-185 | B12: P | C12: 12 | D12: 120 | E12: =C12*D12/1000 -> 1.44 | F12: =Control!$B$7 -> 24 | G12: =C12*F12 -> 288 | H12: =E12*F12 -> 34.56
A13: SUR-100 | B13: P | C13: 72 | D13: 4 | E13: =C13*D13/1000 -> 0.288 | F13: =Control!$B$7 -> 24 | G13: =C13*F13 -> 1728 | H13: =E13*F13 -> 6.912
A14: ENG-5/7 | B14: N | C14: 12 | D14: 180 | E14: =C14*D14/1000 -> 2.16 | F14: =Control!$B$7 -> 24 | G14: =C14*F14 -> 288 | H14: =E14*F14 -> 51.84
A15: PWR-20 | B15: N | C15: 40 | D15: 20 | E15: =C15*D15/1000 -> 0.8 | F15: =Control!$B$7 -> 24 | G15: =C15*F15 -> 960 | H15: =E15*F15 -> 19.2
A16: LCN-12 | B16: N | C16: 24 | D16: 8 | E16: =C16*D16/1000 -> 0.192 | F16: =Control!$B$7 -> 24 | G16: =C16*F16 -> 576 | H16: =E16*F16 -> 4.608
A17: SCN-2 | B17: N | C17: 4 | D17: 60 | E17: =C17*D17/1000 -> 0.24 | F17: =Control!$B$7 -> 24 | G17: =C17*F17 -> 96 | H17: =E17*F17 -> 5.76
... A20: TIA-30 | B20: N | C20: 60 | D20: 6 | E20: =C20*D20/1000 -> 0.36 | F20: =Control!$B$7 -> 24 | G20: =C20*F20 -> 1440 | H20: =E20*F20 -> 8.64
A21: TOTAL | E21: =SUM(E6:E20) -> 13.706 | G21: =SUM(G6:G20) -> 14640 | H21: =SUM(H6:H20) -> 328.944

Sheet Capital_Attrib
A2: Initial capital attribution — jurisdiction is not a saving
B4: D | C4: P | D4: N | E4: Stock | F4: S
A5: Parent capital element | B5: D mission | C5: P portfolio | D5: N national | E5: Stocks | F5: S sovereign | G5: Total USD B
A6: 256 system bodies | B6: =SUMIF(Family_Ledger!$C$6:$C$25,B$4,Family_Ledger!$L$6:$L$25) -> 491.52 | C6: =SUMIF(Family_Ledger!$C$6:$C$25,C$4,Family_Ledger!$L$6:$L$25) -> 621.312 | D6: =SUMIF(Family_Ledger!$C$6:$C$25,D$4,Family_Ledger!$L$6:$L$25) -> 815.104 | E6: =SUMIF(Family_Ledger!$C$6:$C$25,"Stock",Family_Ledger!$L$6:$L$25) -> 20.5056 | F6: 0 | G6: =SUM(B6:F6) -> 1948.4416
A7: service movers and frames | B7: 0 | C7: 0 | D7: 274.56 | E7: 0 | F7: 0 | G7: =SUM(B7:F7) -> 274.56
A8: destructive transport | B8: 0 | C8: 0 | D8: 0 | E8: 0 | F8: 0.256 | G8: =SUM(B8:F8) -> 0.256
A9: group module reserves | B9: 92.16 | C9: 128.016 | D9: 108.768 | E9: 0 | F9: 0 | G9: =SUM(B9:F9) -> 328.944
A10: arsenal bays | B10: 0 | C10: 300 | D10: 0 | E10: 0 | F10: 0 | G10: =SUM(B10:F10) -> 300
A11: launch and receiver stations | B11: 0 | C11: 0 | D11: 144 | E11: 0 | F11: 0 | G11: =SUM(B11:F11) -> 144
A12: production enlargement | B12: =300*1.92/7.531 -> 76.483867 | C12: =300*2.427/7.531 -> 96.680388 | D12: =300*3.184/7.531 -> 126.83575 | E12: 0 | F12: 0 | G12: =SUM(B12:F12) -> 300
A13: strategic interfaces | B13: 0 | C13: 0 | D13: 180 | E13: 0 | F13: 0 | G13: =SUM(B13:F13) -> 180
A14: training, evaluation and reference | B14: 0 | C14: 0 | D14: 0 | E14: 0 | F14: 90 | G14: =SUM(B14:F14) -> 90
A15: command, evidence and configuration | B15: 0 | C15: 0 | D15: 0 | E15: 0 | F15: 75 | G15: =SUM(B15:F15) -> 75
A16: JURISDICTION TOTAL | B16: =SUM(B6:B15) -> 660.16387 | C16: =SUM(C6:C15) -> 1146.0084 | D16: =SUM(D6:D15) -> 1649.2677 | E16: =SUM(E6:E15) -> 20.5056 | F16: =SUM(F6:F15) -> 165.256 | G16: =SUM(G6:G15) -> 3641.2016
A18: Share of C24 | B18: =B16/$G$16 -> 0.18130385 | C18: =C16/$G$16 -> 0.31473357 | D18: =D16/$G$16 -> 0.45294601 | E18: =E16/$G$16 -> 0.0056315476 | F18: =F16/$G$16 -> 0.045385018 | G18: =SUM(B18:F18) -> 1
A20: Interpretation | B20: Value USD B
A21: Fire Service titled capital plus stocks | B21: =B16+E16 -> 680.66947
A22: Capital reserved to C24 | B22: =G16 -> 3641.2016
A23: Admitted national saving | B23: 0

Sheet Quantity_Registry
A2: National common-force quantity registry
A5: ID | B5: Class | C5: Installed in bodies | D5: Group reserve | E5: Separate national pool | F5: National holdings | G5: Readiness rule
A6: EFF-16 | B6: D | C6: =Family_Ledger!I6 -> 4096 | D6: =Family_Ledger!J6 -> 768 | E6: 0 | F6: =SUM(C6:E6) -> 4864 | G6: Unique warrant; no second readiness claim
A7: WPT-500 | B7: P | C7: =Family_Ledger!I7 -> 1536 | D7: =Family_Ledger!J7 -> 288 | E7: 0 | F7: =SUM(C7:E7) -> 1824 | G7: Unique warrant; no second readiness claim
A8: RAW-1000 | B8: P | C8: =Family_Ledger!I8 -> 768 | D8: =Family_Ledger!J8 -> 144 | E8: 0 | F8: =SUM(C8:E8) -> 912 | G8: Unique warrant; no second readiness claim
A9: RTL-100 | B9: P | C9: =Family_Ledger!I9 -> 30720 | D9: =Family_Ledger!J9 -> 5760 | E9: 0 | F9: =SUM(C9:E9) -> 36480 | G9: Unique warrant; no second readiness claim
A10: RTR-12 | B10: P | C10: =Family_Ledger!I10 -> 6144 | D10: =Family_Ledger!J10 -> 1152 | E10: 0 | F10: =SUM(C10:E10) -> 7296 | G10: Unique warrant; no second readiness claim
A11: BUF-100 | B11: P | C11: =Family_Ledger!I11 -> 3840 | D11: =Family_Ledger!J11 -> 720 | E11: 0 | F11: =SUM(C11:E11) -> 4560 | G11: Unique warrant; no second readiness claim
A12: REC-185 | B12: P | C12: =Family_Ledger!I12 -> 1024 | D12: =Family_Ledger!J12 -> 288 | E12: 0 | F12: =SUM(C12:E12) -> 1312 | G12: Unique warrant; no second readiness claim
A13: SUR-100 | B13: P | C13: =Family_Ledger!I13 -> 9216 | D13: =Family_Ledger!J13 -> 1728 | E13: 0 | F13: =SUM(C13:E13) -> 10944 | G13: Unique warrant; no second readiness claim
A14: ENG-5/7 | B14: N | C14: =Family_Ledger!I14 -> 1536 | D14: =Family_Ledger!J14 -> 288 | E14: 0 | F14: =SUM(C14:E14) -> 1824 | G14: Unique warrant; no second readiness claim
A15: PWR-20 | B15: N | C15: =Family_Ledger!I15 -> 5120 | D15: =Family_Ledger!J15 -> 960 | E15: 0 | F15: =SUM(C15:E15) -> 6080 | G15: Unique warrant; no second readiness claim
A16: LCN-12 | B16: N | C16: =Family_Ledger!I16 -> 3072 | D16: =Family_Ledger!J16 -> 576 | E16: 0 | F16: =SUM(C16:E16) -> 3648 | G16: Unique warrant; no second readiness claim
A17: SCN-2 | B17: N | C17: =Family_Ledger!I17 -> 512 | D17: =Family_Ledger!J17 -> 96 | E17: 0 | F17: =SUM(C17:E17) -> 608 | G17: Unique warrant; no second readiness claim
... A22: TIA-30 | B22: N | C22: =Family_Ledger!I22 -> 7680 | D22: =Family_Ledger!J22 -> 1440 | E22: 0 | F22: =SUM(C22:E22) -> 9120 | G22: Unique warrant; no second readiness claim
A23: PM-30 | B23: N | C23: 0 | D23: 0 | E23: 84480 | F23: =SUM(C23:E23) -> 84480 | G23: Unique warrant; packet and crew required
A24: LF-30 | B24: N | C24: 0 | D24: 0 | E24: 79200 | F24: =SUM(C24:E24) -> 79200 | G24: Unique warrant; accepted restraint state

Sheet Warrant_Schema
A2: Service Availability Warrant schema
A5: Field | B5: Required content | C5: Omission effect | D5: Authority | E5: Machine required
A6: warrant identity | B6: immutable public identifier | C6: no valid obligation record | D6: Configuration | E6: YES
A7: service obligation | B7: population, service, time, duration, damage | C7: no measurable claim | D7: Civil authority | E7: YES
A8: claimant | B8: readiness-bearing formation | C8: no accountable holder | D8: Mission service | E8: YES
A9: article serials | B9: exact serials or accepted substitution set | C9: double counting possible | D9: Common Force | E9: YES
A10: family/configuration | B10: family, root and baseline | C10: unsafe substitution | D10: Technical authority | E10: YES
A11: quantity/capacity | B11: units and service rate | C11: inventory cannot reconcile | D11: Common Force | E11: YES
A12: reservation interval | B12: start, irrevocability and release | C12: overlap cannot be tested | D12: Allocation Center | E12: YES
A13: assignment location | B13: launch, arsenal or receiver | C13: launch clock unproved | D13: Common Force | E13: YES
A14: launch ceiling | B14: tested packet assembly maximum | C14: service time unproved | D14: Mission service | E14: YES
A15: crew warrant | B15: qualified watches and relief | C15: article not operable | D15: Generating command | E15: YES
A16: transport warrant | B16: movers, frames, route and custody | C16: packet incomplete | D16: Mobility Command | E16: YES
... A25: release signatures | B25: service, common, configuration, evidence | C25: no lawful issue | D25: Four authorities | E25: YES

Sheet Warrant_States
A2: Warrant state machine
A5: State | B5: Meaning | C5: Prospective readiness | D5: Active obligation | E5: Recall | F5: Allowed next | G5: Denial rule
A6: W0 | B6: candidate | C6: 0 | D6: 0 | E6: n.a. | F6: W1 | G6: no serial commitment
A7: W1 | B7: reserved | C7: 0 | D7: 0 | E7: before seal | F7: W2,W7 | G7: conditional only; packet incomplete
A8: W2 | B8: packet assigned | C8: 1 | D8: 0 | E8: before seal under rule | F8: W3,W7 | G8: complete packet required
A9: W3 | B9: alert sealed | C9: 1 | D9: 0 | E9: NO | F9: W4,W7 | G9: substitutions closed
A10: W4 | B10: committed transit | C10: 0 | D10: 1 | E10: NO | F10: W5,W6,W7 | G10: cannot support second future claim
A11: W5 | B11: operating | C11: 0 | D11: 1 | E11: NO | F11: W6,W7 | G11: active service only
A12: W6 | B12: regenerating | C12: 0 | D12: 0 | E12: n.a. | F12: W2,W7 | G12: no credit before accepted return
A13: W7 | B13: quarantine/casualty | C13: 0 | D13: 0 | E13: n.a. | F13: W6,W8 | G13: discrepancy open
A14: W8 | B14: reference/destructive | C14: 0 | D14: 0 | E14: NEVER | F14: W8 | G14: outside operational credit

Sheet Demand_Worlds
A2: Compound demand worlds required for RBX-1
A5: World | B5: Fire | C5: Flood/water | D5: Medical | E5: Power/thermal | F5: Access/logistics | G5: Required test
A6: CW0 | B6: readiness | C6: readiness | D6: readiness | E6: readiness | F6: readiness | G6: unique warrants; training excluded
A7: CW1 | B7: national campaign | C7: regional | D7: support | E7: heat failure | F7: high | G7: energy reservations coexist
A8: CW2 | B8: regional | C8: two-coast storm | D8: evacuation | E8: regional loss | F8: high | G8: mobility, treatment and rescue compete
A9: CW3 | B9: urban fire | C9: water loss | D9: hospital loss | E9: grid loss | F9: earthquake denial | G9: all common families concurrent
A10: CW4 | B10: domestic compound | C10: regional | D10: regional | E10: regional | F10: invited mission committed | G10: international capacity nonrecallable
A11: CW5 | B11: CW3 + root loss | C11: CW3 + root loss | D11: CW3 + root loss | E11: CW3 + root loss | F11: CW3 + root loss | G11: surviving root closes retained claims
A12: CW6 | B12: regeneration peak | C12: regional | D12: regional | E12: regional | F12: arsenal cell denied | G12: queue and reserve remain within capacity
A13: CW7 | B13: offline | C13: offline | D13: offline | E13: offline | F13: offline | G13: local warrant and serial authority

Sheet Capacity_Compiler
A2: Common-capacity compiler — illustrative coincidence only
A5: Class N coincidence sensitivity for one hypothetical identical second portfolio
A6: Case | B6: Coincident share | C6: Second portfolio standalone USD B | D6: Incremental common capacity USD B | E6: Conditional duplicate capital avoided USD B
A7: S1 | B7: 1 | C7: =Capital_Attrib!$D$16 -> 1649.2677 | D7: =B7*C7 -> 1649.2677 | E7: =C7-D7 -> 0
A8: S2 | B8: 0.75 | C8: =Capital_Attrib!$D$16 -> 1649.2677 | D8: =B8*C8 -> 1236.9508 | E8: =C8-D8 -> 412.31694
A9: S3 | B9: 0.5 | C9: =Capital_Attrib!$D$16 -> 1649.2677 | D9: =B9*C9 -> 824.63387 | E9: =C9-D9 -> 824.63387
A10: S4 | B10: 0.25 | C10: =Capital_Attrib!$D$16 -> 1649.2677 | D10: =B10*C10 -> 412.31694 | E10: =C10-D10 -> 1236.9508
A11: S5 | B11: 0 | C11: =Capital_Attrib!$D$16 -> 1649.2677 | D11: =B11*C11 -> 0 | E11: =C11-D11 -> 1649.2677
A13: Selected live sensitivity | B13: Value | C13: Unit | D13: Status | E13: Interpretation
A14: Coincident share | B14: =Control!B16 -> 1 | C14: percent | D14: INPUT | E14: diagnostic only
A15: Incremental common capacity | B15: =B14*Capital_Attrib!D16 -> 1649.2677 | C15: USD B | D15: CALC | E15: not an estimate
A16: Conditional avoided duplicate | B16: =Capital_Attrib!D16-B15 -> 0 | C16: USD B | D16: UNPROVED | E16: not admitted
A18: Conservation equation
A19: Installed accepted capacity | B19: I_f
A20: Unique reserved demand | B20: max_w sum_p R_pfw
A21: Overhaul occupancy | B21: O_fw
A22: Quarantine/casualty exclusion | B22: Q_fw
A23: Regeneration/uncertainty margin | B23: G_fw
A24: Required test | B24: I_f >= R + O + Q + G
A25: Admitted cross-portfolio saving | B25: 0

Sheet Collision_Rules
A2: Allocation conflict and recall constitution
A5: Tier | B5: Condition | C5: Recall | D5: Allocator | E5: Required public record | F5: Can displace | G5: Hard prohibition
A6: T0 | B6: active public service | C6: NO | D6: none | E6: active population and service | F6: none | G6: no recall
A7: T1 | B7: committed transit / sealed onset | C7: NO | D7: none | E7: committed obligation | F7: none | G7: no recall
A8: T2 | B8: domestic protected onset reserve | C8: exception only | D8: Civil authority | E8: new uncovered obligation | F8: T3-T5 | G8: cannot hide uncovered interval
A9: T3 | B9: compound domestic reserve | C9: YES before seal | D9: Allocation board | E9: denial consequence | F9: T4-T5 | G9: root and launch floors remain
A10: T4 | B10: invited international, uncommitted | C10: treaty-dependent | D10: Civil authority | E10: host and cancellation terms | F10: T5 | G10: committed mission becomes T1
A11: T5 | B11: training / exercise / trial | C11: YES | D11: Generating command | E11: schedule consequence | F11: none | G11: evidence already created is retained
A13: Allocation record minimum
A14: 1 | B14: obligations in conflict
A15: 2 | B15: populations and service bundles
A16: 3 | B16: time to irreversible harm
A17: 4 | B17: accepted substitutions and local capacity
A18: 5 | B18: transport and regeneration consequences
A19: 6 | B19: uncertainty and dissent
A20: 7 | B20: selected allocation
A21: 8 | B21: obligation left uncovered
A22: 9 | B22: capacity restoration action

Sheet Workforce
A2: Conserved public workforce by assignment
A5: Assignment | B5: Base positions | C5: Reserve rate | D5: Reserve positions | E5: Industrial positions | F5: Total positions
A6: fire formations | B6: 283200 | C6: 0.15 | D6: =B6*C6 -> 42480 | E6: 0 | F6: =B6+D6+E6 -> 325680
A7: portfolio arsenals | B7: 25200 | C7: 0.15 | D7: =B7*C7 -> 3780 | E7: 0 | F7: =B7+D7+E7 -> 28980
A8: national common nodes | B8: 16800 | C8: 0.15 | D8: =B8*C8 -> 2520 | E8: 0 | F8: =B8+D8+E8 -> 19320
A9: sovereign technical estate | B9: 20400 | C9: 0.15 | D9: =B9*C9 -> 3060 | E9: 4000 | F9: =B9+D9+E9 -> 27460
A10: public industry not yet occupation-split | B10: 0 | C10: 0 | D10: 0 | E10: 28000 | F10: =B10+D10+E10 -> 28000
A11: TOTAL | B11: =SUM(B6:B10) -> 345600 | D11: =SUM(D6:D10) -> 51840 | E11: =SUM(E6:E10) -> 32000 | F11: =SUM(F6:F10) -> 429440
A13: Control | B13: Calculated | C13: Parent | D13: Difference | E13: Status | F13: Meaning
A14: operating establishment | B14: =SUM(B6:B10) -> 345600 | C14: 345600 | D14: =B14-C14 -> 0 | E14: =IF(ABS(D14)<0.01,"PASS","FAIL") -> PASS | F14: before reserve and industry
A15: qualified reserve | B15: =SUM(D6:D10) -> 51840 | C15: 51840 | D15: =B15-C15 -> 0 | E15: =IF(ABS(D15)<0.01,"PASS","FAIL") -> PASS | F15: 15% of operating establishment
A16: all public personnel | B16: =F11 -> 429440 | C16: =Control!B15 -> 429440 | D16: =B16-C16 -> 0 | E16: =IF(ABS(D16)<0.01,"PASS","FAIL") -> PASS | F16: capital reclassification does not remove labor

Sheet Annual_Support
A2: Mature annual support — conserved parent account
A5: Element | B5: Basis | C5: USD B/year | D5: Attribution status
A6: public personnel | B6: 429,440 × USD 250,000 | C6: 107.36 | D6: not occupation-split
A7: system-body readiness | B7: 3% of body capital | C7: =Capital_Attrib!G6*3% -> 58.453248 | D7: formula
A8: transport readiness | B8: 4% of mover/frame capital | C8: =Capital_Attrib!G7*4% -> 10.9824 | D8: N
A9: fixed-estate operations | B9: 3% of USD 1.089T | C9: =1089*3% -> 32.67 | D9: mixed
A10: exercises and mission consumables | B10: 24 groups × USD 1.5B | C10: 36 | D10: mission/portfolio
A11: two-root industrial retainers | B11: parent allowance | C11: 25 | D11: mixed
A12: standards, evidence and research | B12: parent allowance | C12: 12 | D12: S
A13: international interfaces | B13: parent allowance | C13: 8 | D13: N
A14: TOTAL | C14: =SUM(C6:C13) -> 290.46565
A16: Parent total | B16: 290.46565 | C16: Difference | D16: =C14-B16 -> 0
A17: Status | B17: =IF(ABS(D16)<0.000001,"PASS","FAIL") -> PASS

Sheet Lifecycle
A2: Twenty-five-year public cost — conserved parent account
A5: Element | B5: Basis | C5: USD B | D5: Jurisdiction note
A6: initial capital | B6: Capital_Attrib total | C6: =Capital_Attrib!G16 -> 3641.2016 | D6: five ledgers
A7: technology authority | B7: Control input | C7: =Control!B18 -> 250 | D7: P/N/S allocation
A8: 25 years mature support | B8: Annual_Support × years | C8: =Annual_Support!C14*Control!B17 -> 7261.6412 | D8: mixed
A9: two mover replacement cycles | B9: parent | C9: 422.4 | D9: N
A10: one frame replacement cycle | B10: parent | C10: 63.36 | D10: N
A11: system midlife modernization | B11: 20% body capital | C11: =Capital_Attrib!G6*20% -> 389.68832 | D11: D/P/N/stocks
A12: facility recapitalization | B12: 15% fixed estate | C12: =1089*15% -> 163.35 | D12: D/P/N/S
A13: TOTAL | C13: =SUM(C6:C12) -> 12191.641
A15: Parent total | B15: 12191.641 | C15: Difference | D15: =C13-B15 -> 0
A16: Status | B16: =IF(ABS(D15)<0.000001,"PASS","FAIL") -> PASS

Sheet Technology
A2: Inherited technology authority by common-force jurisdiction
A5: Campaign | B5: Class | C5: USD B | D5: Required change | F5: Class | G5: USD B
A6: autonomous logistics and load exchange | B6: N | C6: 55 | D6: fewer exposed driving hours; verified custody | F6: D | G6: =SUMIF($B$6:$B$13,F6,$C$6:$C$13) -> 0
A7: arsenal process intensification | B7: P | C7: 45 | D7: faster accepted regeneration | F7: P | G7: =SUMIF($B$6:$B$13,F7,$C$6:$C$13) -> 110
A8: public configuration and attestation | B8: S | C8: 40 | D8: machine-verifiable identity | F8: N | G8: =SUMIF($B$6:$B$13,F8,$C$6:$C$13) -> 75
A9: independent water, energy and thermal systems | B9: P | C9: 35 | D9: reduced damaged-utility dependence | F9: S | G9: =SUMIF($B$6:$B$13,F9,$C$6:$C$13) -> 65
A10: advanced materials, joining and field repair | B10: P | C10: 30 | D10: certified local restoration
A11: receiver-interface systems | B11: N | C11: 20 | D11: prepared civilian service nodes
A12: synthetic training and simulation | B12: S | C12: 15 | D12: rare-task qualification
A13: metrology, safety and forensic automation | B13: S | C13: 10 | D13: independent observation
A14: TOTAL | C14: =SUM(C6:C13) -> 250

Sheet Architecture_Cases
A2: Rival common-force architectures
A5: Case | B5: Architecture | C5: Exclusive warrant | D5: Co-present packet | E5: Root law | F5: Public technical estate | G5: Capital conservation | H5: Disposition
A6: A | B6: vertically integrated services | C6: 1 | D6: 1 | E6: 1 | F6: 1 | G6: 0 | H6: REJECT
A7: B | B7: administrative central pool | C7: 0 | D7: 0 | E7: 0 | F7: 0 | G7: 0 | H7: REJECT
A8: C | B8: market mobilization | C8: 0 | D8: 0 | E8: 0 | F8: 0 | G8: 0 | H8: REJECT
A9: D | B9: assured common force | C9: 1 | D9: 1 | E9: 1 | F9: 1 | G9: 1 | H9: SELECT
A11: Decision rule | B11: All five conjuncts must equal 1
A12: Selected case | B12: =Control!B6 -> D
A13: Eligible score | B13: =SUM(C9:G9) -> 5
A14: Required score | B14: 5
A15: Status | B15: =IF(AND(B12="D",B13=B14),"PASS","FAIL") -> PASS

Sheet Schedule
A2: Twelve-year common-force transition
A5: Phase | B5: Start year | C5: End year | D5: Duration | E5: Required output | F5: Readiness credit | G5: Gate
A6: constitutional design | B6: 0 | C6: 2 | D6: =C6-B6 -> 2 | E6: warrant law and obligation ledger | F6: 0 | G6: planning
A7: common interface competition | B7: 1 | C7: 4 | D7: =C7-B7 -> 3 | E7: rival transport, energy, command and repair roots | F7: 0 | G7: physical
A8: cross-portfolio article trials | B8: 3 | C8: 6 | D8: =C8-B8 -> 3 | E8: equivalence and non-equivalence evidence | F8: 0 | G8: physical
A9: multi-portfolio compiler trials | B9: 4 | C9: 7 | D9: =C9-B9 -> 3 | E9: article-level compilation | F9: 0 | G9: physical
A10: first warranted formations | B10: 5 | C10: 8 | D10: =C10-B10 -> 3 | E10: complete groups using common-titled packets | F10: 0 | G10: release
A11: root/network loss exercises | B11: 6 | C11: 10 | D11: =C11-B11 -> 4 | E11: continuing service under denial | F11: 0 | G11: physical
A12: national warrant conversion | B12: 8 | C12: 12 | D12: =C12-B12 -> 4 | E12: all claims tied to unique serials and slots | F12: 0 | G12: release

Sheet Gate_Register
A2: Gate register
A5: Gate ID | B5: Type | C5: Proposition | D5: Status | E5: Evidence basis | F5: Exterior implication
A6: P01 | B6: planning | C6: common title requires exclusive reservation | D6: CLOSED | E6: RBW-1 model and constitution | F6: none
A7: P02 | B7: planning | C7: nineteen families classified | D7: CLOSED | E7: RBW-1 model and constitution | F7: none
A8: P03 | B8: planning | C8: body and reserve costs reconcile | D8: CLOSED | E8: RBW-1 model and constitution | F8: none
A9: P04 | B9: planning | C9: attribution separated from savings | D9: CLOSED | E9: RBW-1 model and constitution | F9: none
A10: P05 | B10: planning | C10: one article-one obligation law | D10: CLOSED | E10: RBW-1 model and constitution | F10: none
A11: P06 | B11: planning | C11: complete warrant is conjunctive | D11: CLOSED | E11: RBW-1 model and constitution | F11: none
A12: P07 | B12: planning | C12: priority uses service consequence | D12: CLOSED | E12: RBW-1 model and constitution | F12: none
A13: P08 | B13: planning | C13: committed articles nonrecallable | D13: CLOSED | E13: RBW-1 model and constitution | F13: none
A14: P09 | B14: planning | C14: sovereign estate excluded | D14: CLOSED | E14: RBW-1 model and constitution | F14: none
A15: P10 | B15: planning | C15: joint worlds required for savings | D15: CLOSED | E15: RBW-1 model and constitution | F15: none
A16: X01 | B16: physical | C16: mission-variant equivalence | D16: OPEN | E16: physical campaign absent | F16: rendering blocked
... A34: R09 | B34: release | C34: exterior rendering | D34: BLOCKED | E34: parent authority withheld | F34: rendering blocked

Sheet Audit
A2: Terminal audit and denial checks
A5: Check ID | B5: Category | C5: Expected | D5: Actual | E5: Difference / rule | F5: Status
A6: A01 | B6: parent | C6: 24 | D6: =Control!B7 -> 24 | E6: =D6-C6 -> 0 | F6: =IF(ABS(E6)<0.01,"PASS","FAIL") -> PASS
A7: A02 | B7: parent | C7: 192 | D7: =Control!B8 -> 192 | E7: =D7-C7 -> 0 | F7: =IF(ABS(E7)<0.01,"PASS","FAIL") -> PASS
A8: A03 | B8: parent | C8: 256 | D8: =Control!B9 -> 256 | E8: =D8-C8 -> 0 | F8: =IF(ABS(E8)<0.01,"PASS","FAIL") -> PASS
A9: A04 | B9: parent | C9: 84480 | D9: =Control!B10 -> 84480 | E9: =D9-C9 -> 0 | F9: =IF(ABS(E9)<0.01,"PASS","FAIL") -> PASS
A10: A05 | B10: parent | C10: 79200 | D10: =Control!B11 -> 79200 | E10: =D10-C10 -> 0 | F10: =IF(ABS(E10)<0.01,"PASS","FAIL") -> PASS
A11: A06 | B11: parent | C11: 48 | D11: =Control!B12 -> 48 | E11: =D11-C11 -> 0 | F11: =IF(ABS(E11)<0.01,"PASS","FAIL") -> PASS
A12: A07 | B12: parent | C12: 18 | D12: =Control!B13 -> 18 | E12: =D12-C12 -> 0 | F12: =IF(ABS(E12)<0.01,"PASS","FAIL") -> PASS
A13: A08 | B13: parent | C13: 180 | D13: =Control!B14 -> 180 | E13: =D13-C13 -> 0 | F13: =IF(ABS(E13)<0.01,"PASS","FAIL") -> PASS
A14: A09 | B14: parent | C14: 429440 | D14: =Control!B15 -> 429440 | E14: =D14-C14 -> 0 | F14: =IF(ABS(E14)<0.01,"PASS","FAIL") -> PASS
A15: A10 | B15: family | C15: 7611.1 | D15: =Family_Ledger!F26 -> 7611.1 | E15: =D15-C15 -> 0 | F15: =IF(ABS(E15)<0.0001,"PASS","FAIL") -> PASS
A16: A11 | B16: reserve | C16: 13.706 | D16: =Reserve_Ledger!E21 -> 13.706 | E16: =D16-C16 -> 3.5527137e-15 | F16: =IF(ABS(E16)<0.0001,"PASS","FAIL") -> PASS
A17: A12 | B17: reserve | C17: 328.944 | D17: =Reserve_Ledger!H21 -> 328.944 | E17: =D17-C17 -> -1.1368684e-13 | F17: =IF(ABS(E17)<0.0001,"PASS","FAIL") -> PASS
A18: A13 | B18: capital | C18: 1948.4416 | D18: =Capital_Attrib!G6 -> 1948.4416 | E18: =D18-C18 -> -2.2737368e-13 | F18: =IF(ABS(E18)<0.0001,"PASS","FAIL") -> PASS
A19: A14 | B19: capital | C19: 274.56 | D19: =Capital_Attrib!G7 -> 274.56 | E19: =D19-C19 -> 0 | F19: =IF(ABS(E19)<0.0001,"PASS","FAIL") -> PASS
A20: A15 | B20: capital | C20: 0.256 | D20: =Capital_Attrib!G8 -> 0.256 | E20: =D20-C20 -> 0 | F20: =IF(ABS(E20)<0.0001,"PASS","FAIL") -> PASS
A21: A16 | B21: capital | C21: 328.944 | D21: =Capital_Attrib!G9 -> 328.944 | E21: =D21-C21 -> -5.6843419e-14 | F21: =IF(ABS(E21)<0.0001,"PASS","FAIL") -> PASS
A22: A17 | B22: capital | C22: 300 | D22: =Capital_Attrib!G10 -> 300 | E22: =D22-C22 -> 0 | F22: =IF(ABS(E22)<0.0001,"PASS","FAIL") -> PASS
A23: A18 | B23: capital | C23: 144 | D23: =Capital_Attrib!G11 -> 144 | E23: =D23-C23 -> 0 | F23: =IF(ABS(E23)<0.0001,"PASS","FAIL") -> PASS
A24: A19 | B24: capital | C24: 300 | D24: =Capital_Attrib!G12 -> 300 | E24: =D24-C24 -> 0 | F24: =IF(ABS(E24)<0.0001,"PASS","FAIL") -> PASS
A25: A20 | B25: capital | C25: 180 | D25: =Capital_Attrib!G13 -> 180 | E25: =D25-C25 -> 0 | F25: =IF(ABS(E25)<0.0001,"PASS","FAIL") -> PASS
A26: A21 | B26: capital | C26: 90 | D26: =Capital_Attrib!G14 -> 90 | E26: =D26-C26 -> 0 | F26: =IF(ABS(E26)<0.0001,"PASS","FAIL") -> PASS
A27: A22 | B27: capital | C27: 75 | D27: =Capital_Attrib!G15 -> 75 | E27: =D27-C27 -> 0 | F27: =IF(ABS(E27)<0.0001,"PASS","FAIL") -> PASS
A28: A23 | B28: capital | C28: 3641.2016 | D28: =Capital_Attrib!G16 -> 3641.2016 | E28: =D28-C28 -> 0 | F28: =IF(ABS(E28)<0.0001,"PASS","FAIL") -> PASS
A29: A24 | B29: capital | C29: 660.16387 | D29: =Capital_Attrib!B16 -> 660.16387 | E29: =D29-C29 -> 0 | F29: =IF(ABS(E29)<0.0001,"PASS","FAIL") -> PASS
A30: A25 | B30: capital | C30: 1146.0084 | D30: =Capital_Attrib!C16 -> 1146.0084 | E30: =D30-C30 -> 2.2737368e-13 | F30: =IF(ABS(E30)<0.0001,"PASS","FAIL") -> PASS
A31: A26 | B31: capital | C31: 1649.2677 | D31: =Capital_Attrib!D16 -> 1649.2677 | E31: =D31-C31 -> 0 | F31: =IF(ABS(E31)<0.0001,"PASS","FAIL") -> PASS
A32: A27 | B32: capital | C32: 20.5056 | D32: =Capital_Attrib!E16 -> 20.5056 | E32: =D32-C32 -> 0 | F32: =IF(ABS(E32)<0.0001,"PASS","FAIL") -> PASS
A33: A28 | B33: capital | C33: 165.256 | D33: =Capital_Attrib!F16 -> 165.256 | E33: =D33-C33 -> 0 | F33: =IF(ABS(E33)<0.0001,"PASS","FAIL") -> PASS
A34: A29 | B34: shares | C34: 1 | D34: =Capital_Attrib!G18 -> 1 | E34: =D34-C34 -> 0 | F34: =IF(ABS(E34)<0.000001,"PASS","FAIL") -> PASS
A35: A30 | B35: technology | C35: 250 | D35: =Technology!C14 -> 250 | E35: =D35-C35 -> 0 | F35: =IF(ABS(E35)<0.0001,"PASS","FAIL") -> PASS
A36: A31 | B36: annual | C36: 290.46565 | D36: =Annual_Support!C14 -> 290.46565 | E36: =D36-C36 -> 0 | F36: =IF(ABS(E36)<0.0001,"PASS","FAIL") -> PASS
A37: A32 | B37: lifecycle | C37: 12191.641 | D37: =Lifecycle!C13 -> 12191.641 | E37: =D37-C37 -> 0 | F37: =IF(ABS(E37)<0.0001,"PASS","FAIL") -> PASS
A38: A33 | B38: workforce | C38: 345600 | D38: =Workforce!B14 -> 345600 | E38: =D38-C38 -> 0 | F38: =IF(ABS(E38)<0.01,"PASS","FAIL") -> PASS
A39: A34 | B39: workforce | C39: 51840 | D39: =Workforce!B15 -> 51840 | E39: =D39-C39 -> 0 | F39: =IF(ABS(E39)<0.01,"PASS","FAIL") -> PASS
A40: A35 | B40: workforce | C40: 429440 | D40: =Workforce!B16 -> 429440 | E40: =D40-C40 -> 0 | F40: =IF(ABS(E40)<0.01,"PASS","FAIL") -> PASS
A41: A36 | B41: architecture | C41: 5 | D41: =Architecture_Cases!B13 -> 5 | E41: =D41-C41 -> 0 | F41: =IF(ABS(E41)<0.01,"PASS","FAIL") -> PASS
A42: A37 | B42: admission | C42: 0 | D42: =Capital_Attrib!B23 -> 0 | E42: =D42-C42 -> 0 | F42: =IF(ABS(E42)<0.000001,"PASS","FAIL") -> PASS
A43: A38 | B43: sensitivity | C43: 0 | D43: =Capacity_Compiler!E7 -> 0 | E43: =D43-C43 -> 0 | F43: =IF(ABS(E43)<0.0001,"PASS","FAIL") -> PASS
...

Sheet Executive
A2: NCFC-1 — assured common force without false capacity
A5: Case selected | B5: =Control!B6 -> D
A6: Fire-control groups | B6: =Control!B7 -> 24
A7: National initial capital USD B | B7: =Capital_Attrib!G16 -> 3641.2016
A8: Admitted saving USD B | B8: =Capital_Attrib!B23 -> 0
A9: Exterior rendering | B9: BLOCKED
A11: C24 initial capital by jurisdiction | E11: Decision
A12: Jurisdiction | B12: USD B | C12: Share | E12: Select Architecture D. Common ownership is compatible with self-contained operations only when every readiness claim holds a unique Service Availability Warrant covering exact articles, configuration, crew, transport, spares, command, receiver and regeneration. The current fire-control force remains USD 3.6412016T. USD 0 of cross-portfolio saving is admitted until RBX-1 compiles joint demand worlds.
A13: Fire-mission dedicated | B13: =Capital_Attrib!B16 -> 660.16387 | C13: =B13/Capital_Attrib!$G$16 -> 0.18130385
A14: Hazard-control portfolio common | B14: =Capital_Attrib!C16 -> 1146.0084 | C14: =B14/Capital_Attrib!$G$16 -> 0.31473357
A15: National Common Force | B15: =Capital_Attrib!D16 -> 1649.2677 | C15: =B15/Capital_Attrib!$G$16 -> 0.45294601
A16: Mission-loaded stocks | B16: =Capital_Attrib!E16 -> 20.5056 | C16: =B16/Capital_Attrib!$G$16 -> 0.0056315476
A17: Sovereign technical estate | B17: =Capital_Attrib!F16 -> 165.256 | C17: =B17/Capital_Attrib!$G$16 -> 0.045385018
A20: Capital interpretation | E20: Method correction
A21: Quantity | B21: USD B | C21: Status | E21: Title, technical family, reservation and physical assignment are recorded separately. One serialized article may support at most one prospective or active obligation in the same interval. A central pool, commercial catalog or aggregate megawatt count does not create a ready formation.
A22: Fire Service title + stocks | B22: =Capital_Attrib!B21 -> 680.66947 | C22: jurisdiction
A23: Capital reserved to C24 | B23: =Capital_Attrib!B22 -> 3641.2016 | C23: physical boundary
A24: National saving admitted | B24: =Capital_Attrib!B23 -> 0 | C24: unproved
A27: Next research object
A28: RBX-1: build a National Multi-Portfolio Concurrent-Service Compiler across fire, flood-water, medical, power/thermal and access-logistics. Installed common capacity must equal the maximum complete demand across compound worlds plus overhaul, quarantine and regeneration margins. Rendering remains blocked.
